{"stream":"btcusdt@depth@100ms","data":{"e":"depthUpdate","E":1784410667490,"T":1784410667489,"s":"BTCUSDT","ps":"BTCUSDT","U":11079104901873,"u":11079104906718,"pu":11079104901850,"b":[["14149.90","0.868"],["14249.90","1.932"],["14349.90","0.756"],["14449.90","0.644"],["58184.90","0.002"],["61417.40","0.010"],["62063.90","1.383"],["62151.50","1.286"],["63357.00","0.014"],["63903.90","0.000"],["64003.40","0.000"],["64463.70","0.043"],["64535.90","0.000"],["64537.40","0.491"],["64538.90","0.004"],["64540.40","0.000"],["64541.90","1.187"],["64547.90","0.000"],["64596.50","0.004"],["64598.70","21.344"],["64600.90","0.146"],["64603.30","0.002"],["64610.40","0.576"],["64613.30","0.556"],["64613.50","2.068"],["64614.00","10.741"],["64614.20","0.010"],["64614.30","1.078"],["64614.40","0.330"],["64614.60","0.312"],["64614.70","0.002"],["64614.80","0.006"],["64617.60","1.188"],["64618.30","0.573"],["64625.30","0.392"],["64626.20","0.000"],["64630.10","0.385"],["64630.20","0.053"],["64630.30","0.387"],["64630.50","0.067"],["64630.60","1.291"],["64631.20","0.010"],["64633.00","0.061"],["64633.80","4.516"],["64634.50","0.471"],["64634.90","0.155"],["64636.10","0.155"],["64636.80","1.499"],["64637.00","1.613"],["64637.40","0.001"],["64637.70","0.493"],["64639.00","0.066"],["64641.50","0.310"],["64641.60","0.009"],["64642.00","0.010"],["64642.20","0.000"],["64643.80","0.002"],["64644.20","0.769"],["64645.40","0.107"],["64645.50","0.137"],["64645.60","0.001"],["64647.00","0.001"],["64647.10","1.239"],["64647.20","1.603"],["64647.30","1.915"],["64647.40","0.217"],["64649.50","0.062"],["64649.60","0.865"],["64649.90","7.411"]],"a":[["64650.00","3.036"],["64654.40","0.004"],["64654.60","0.050"],["64656.40","0.696"],["64656.50","0.018"],["64656.60","0.599"],["64656.80","0.012"],["64657.60","0.507"],["64658.10","0.065"],["64658.20","0.067"],["64658.60","0.000"],["64659.00","0.312"],["64659.70","0.029"],["64659.80","0.017"],["64660.00","0.100"],["64660.30","0.177"],["64660.50","0.049"],["64666.50","0.542"],["64668.80","2.165"],["64669.60","0.000"],["64669.80","0.930"],["64670.20","10.003"],["64671.40","0.003"],["64671.50","0.469"],["64672.30","0.033"],["64672.90","0.001"],["64675.00","0.113"],["64681.60","0.004"],["64683.10","0.000"],["64684.60","0.060"],["64686.90","24.116"],["64689.50","0.000"],["64690.70","10.054"],["64710.60","4.258"],["64722.50","0.000"],["64725.00","0.011"],["65296.50","0.032"],["65458.10","10.144"],["65942.90","0.654"]],"st":1}}
{"stream":"btcusdt@depth@100ms","data":{"e":"depthUpdate","E":1784410667592,"T":1784410667590,"s":"BTCUSDT","ps":"BTCUSDT","U":11079104906769,"u":11079104910521,"pu":11079104906718,"b":[["1000.00","50.241"],["14149.90","1.106"],["14249.90","1.694"],["14349.90","0.868"],["14449.90","0.532"],["58184.90","0.002"],["61417.40","0.010"],["64003.40","0.000"],["64092.20","1.092"],["64326.60","3.576"],["64326.70","0.934"],["64421.30","0.833"],["64449.90","0.000"],["64535.90","0.000"],["64537.40","0.491"],["64538.90","1.280"],["64540.40","1.276"],["64543.40","1.276"],["64579.30","0.000"],["64579.70","0.155"],["64580.00","0.105"],["64580.30","0.003"],["64580.60","2.086"],["64598.80","0.000"],["64599.10","0.000"],["64599.40","0.013"],["64599.70","0.026"],["64600.00","1.026"],["64606.00","0.034"],["64612.50","0.033"],["64614.30","0.400"],["64614.40","0.018"],["64614.60","0.000"],["64614.90","0.038"],["64615.00","1.004"],["64615.60","0.003"],["64618.20","0.032"],["64618.30","0.393"],["64635.60","0.913"],["64637.00","0.394"],["64637.10","0.177"],["64637.30","0.001"],["64637.60","0.032"],["64637.70","0.007"],["64637.90","0.005"],["64638.20","0.048"],["64638.30","0.002"],["64638.60","0.622"],["64638.90","0.890"],["64646.60","0.023"]],"a":[["64650.00","2.986"],["64653.70","0.007"],["64656.30","0.003"],["64656.40","0.001"],["64656.60","0.062"],["64656.70","1.276"],["64657.00","0.008"],["64657.30","0.002"],["64657.60","0.175"],["64657.70","0.312"],["64658.00","0.001"],["64658.10","0.005"],["64658.20","0.007"],["64658.30","0.004"],["64659.80","0.722"],["64660.30","0.176"],["64660.50","0.050"],["64675.70","0.000"],["64676.10","0.299"],["64676.40","0.082"],["64676.70","0.015"],["64677.10","0.039"],["64678.40","0.470"],["64679.60","1.205"],["64679.70","0.010"],["64680.20","1.790"],["64680.30","0.048"],["64680.70","0.000"],["64680.90","0.000"],["64681.00","0.002"],["64695.20","0.029"],["64695.50","0.312"],["64695.80","0.000"],["64696.10","0.001"],["64696.50","0.325"],["64778.30","0.000"],["64973.30","1.692"],["65296.50","0.032"],["65425.80","29.572"],["65587.40","20.974"]],"st":1}}
{"stream":"btcusdt@depth@100ms","data":{"e":"depthUpdate","E":1784410667694,"T":1784410667693,"s":"BTCUSDT","ps":"BTCUSDT","U":11079104910592,"u":11079104916261,"pu":11079104910521,"b":[["1000.00","50.241"],["14149.90","1.344"],["14249.90","1.456"],["14349.90","0.994"],["14449.90","0.406"],["58184.90","0.002"],["61417.40","0.024"],["61417.50","0.011"],["62063.90","1.380"],["63502.40","0.000"],["63712.50","24.758"],["63853.40","0.782"],["64003.40","0.000"],["64326.60","3.577"],["64349.90","0.051"],["64449.90","0.000"],["64538.90","0.004"],["64544.90","1.276"],["64600.50","0.069"],["64613.10","0.050"],["64633.00","0.215"],["64633.70","0.121"],["64634.50","0.355"],["64636.20","1.079"],["64636.80","0.942"],["64636.90","0.007"],["64638.20","0.198"],["64638.30","0.182"],["64638.50","0.123"],["64639.80","0.842"],["64640.00","0.420"],["64643.40","0.005"],["64649.90","7.309"]],"a":[["64655.60","0.002"],["64656.60","0.062"],["64656.90","0.036"],["64657.30","0.122"],["64659.20","0.005"],["64675.90","1.007"],["64676.30","0.214"],["64681.60","0.081"],["64900.00","50.651"],["65296.50","0.032"],["65613.20","0.003"],["65749.00","3.343"],["65942.90","0.651"]],"st":1}}
{"stream":"btcusdt@depth@100ms","data":{"e":"depthUpdate","E":1784410667796,"T":1784410667793,"s":"BTCUSDT","ps":"BTCUSDT","U":11079104916262,"u":11079104930669,"pu":11079104916261,"b":[["14149.90","1.582"],["14249.90","1.218"],["14349.90","1.106"],["14449.90","0.294"],["58184.90","0.002"],["61417.40","0.008"],["62063.90","1.383"],["63771.30","2.822"],["63824.90","3.126"],["64003.40","0.000"],["64297.30","0.023"],["64326.60","3.732"],["64540.40","0.000"],["64541.90","0.000"],["64600.20","0.074"],["64600.80","0.061"],["64601.20","0.074"],["64601.50","0.077"],["64636.10","1.081"],["64636.80","0.016"],["64637.60","0.554"],["64637.70","0.199"],["64637.90","0.161"],["64638.20","0.428"],["64638.30","0.320"],["64638.80","0.154"],["64639.20","0.077"],["64639.50","0.182"],["64647.20","1.443"],["64649.90","7.304"]],"a":[["64650.00","2.986"],["64650.40","0.006"],["64650.50","0.051"],["64655.90","0.033"],["64656.30","0.035"],["64656.60","0.094"],["64657.20","0.062"],["64657.30","0.214"],["64657.60","0.235"],["64657.90","0.421"],["64674.90","0.034"],["64675.30","0.033"],["64675.60","0.747"],["64676.30","0.246"],["64679.10","0.177"],["64679.50","0.373"],["64679.70","0.070"],["64679.80","0.300"],["64681.60","0.004"],["65296.50","0.032"]],"st":1}}
{"stream":"btcusdt@depth@100ms","data":{"e":"depthUpdate","E":1784410667898,"T":1784410667896,"s":"BTCUSDT","ps":"BTCUSDT","U":11079104930997,"u":11079104937977,"pu":11079104930669,"b":[["1000.00","50.241"],["14149.90","1.820"],["14249.90","0.980"],["14349.90","1.232"],["14449.90","0.168"],["58184.90","0.002"],["61417.40","0.008"],["62063.90","1.380"],["62125.20","1.367"],["63726.10","7.059"],["64003.40","0.000"],["64067.90","2.182"],["64326.70","0.934"],["64601.60","0.037"],["64629.70","0.000"],["64633.00","0.061"],["64636.20","1.079"],["64636.90","0.727"],["64637.60","0.710"],["64637.90","0.317"],["64638.30","0.626"],["64638.90","1.028"],["64640.00","0.945"],["64649.90","7.102"]],"a":[["64650.50","0.004"],["64650.70","0.003"],["64651.00","0.047"],["64654.40","0.025"],["64656.50","0.018"],["64656.60","0.741"],["64657.20","0.182"],["64657.60","0.295"],["64657.90","0.481"],["64658.00","0.265"],["64659.70","0.193"],["64659.80","0.558"],["64668.70","0.005"],["64678.50","0.107"],["64679.10","0.297"],["64679.40","0.072"],["64679.80","0.360"],["64681.60","0.081"],["65296.50","0.032"],["65855.30","0.000"],["65942.90","0.648"],["66102.20","0.000"]],"st":1}}
{"stream":"btcusdt@depth@100ms","data":{"e":"depthUpdate","E":1784410668000,"T":1784410667997,"s":"BTCUSDT","ps":"BTCUSDT","U":11079104938062,"u":11079104943559,"pu":11079104937977,"b":[["1000.00","50.241"],["14149.90","2.002"],["14249.90","0.770"],["14349.90","1.344"],["14449.90","0.056"],["14549.90","0.028"],["51720.00","0.004"],["58184.90","0.002"],["61417.40","0.008"],["62063.90","1.383"],["63971.80","1.871"],["64003.40","0.000"],["64495.60","0.809"],["64535.90","0.000"],["64537.40","0.491"],["64538.90","0.004"],["64540.40","0.000"],["64541.90","0.000"],["64543.40","0.000"],["64544.90","0.000"],["64581.50","0.070"],["64614.20","0.012"],["64614.30","0.402"],["64614.40","0.020"],["64614.60","0.002"],["64614.70","0.004"],["64614.80","0.008"],["64617.00","0.465"],["64630.10","0.387"],["64630.20","0.055"],["64630.30","0.389"],["64631.40","1.192"],["64632.60","0.117"],["64633.00","0.215"],["64633.70","0.005"],["64635.70","0.557"],["64636.20","0.522"],["64637.70","0.319"],["64647.50","0.080"],["64647.80","0.062"],["64647.90","0.061"],["64648.10","0.047"],["64648.30","0.001"],["64649.90","7.426"]],"a":[["64650.00","2.984"],["64650.30","0.004"],["64650.50","0.004"],["64650.70","0.003"],["64650.90","0.047"],["64651.00","0.000"],["64653.70","0.007"],["64655.10","0.635"],["64656.30","0.035"],["64656.40","0.001"],["64656.50","0.018"],["64656.60","0.467"],["64657.60","0.608"],["64657.70","0.372"],["64659.70","0.210"],["64659.80","0.541"],["64660.00","0.100"],["64660.30","0.177"],["64660.50","0.049"],["64666.50","0.542"],["64668.70","0.005"],["64670.10","0.314"],["64671.30","0.002"],["64676.10","0.856"],["64677.80","0.091"],["64679.50","0.433"],["64694.90","0.032"],["64801.80","0.977"],["64886.00","2.171"],["65296.50","0.032"],["65326.20","0.000"],["65451.00","0.767"],["65582.40","7.903"],["65593.90","0.760"],["65942.90","0.648"]],"st":1}}
{"stream":"btcusdt@depth@100ms","data":{"e":"depthUpdate","E":1784410668102,"T":1784410668101,"s":"BTCUSDT","ps":"BTCUSDT","U":11079104943704,"u":11079104948782,"pu":11079104943559,"b":[["14149.90","1.988"],["14249.90","0.728"],["14349.90","1.330"],["14449.90","0.000"],["14549.90","0.154"],["51719.90","0.000"],["58184.90","0.002"],["61417.40","0.008"],["61417.50","0.013"],["62729.80","0.002"],["64003.40","0.000"],["64449.90","0.000"],["64581.20","0.075"],["64581.80","6.061"],["64582.20","0.074"],["64582.50","0.062"],["64615.80","0.360"],["64619.20","0.585"],["64619.30","0.196"],["64630.60","1.289"],["64631.40","1.274"],["64633.00","0.061"],["64638.30","0.626"],["64643.50","0.234"],["64643.90","0.002"],["64647.30","1.962"],["64647.50","0.000"]],"a":[["64650.90","0.000"],["64651.30","0.002"],["64653.70","0.017"],["64655.10","0.048"],["64656.20","0.590"],["64656.30","0.035"],["64656.40","0.001"],["64656.50","0.018"],["64656.60","0.154"],["64657.50","0.127"],["64657.60","0.171"],["64659.70","0.029"],["64659.80","0.722"],["64671.50","0.465"],["64672.20","0.004"],["64681.50","1.950"],["64681.60","0.004"],["64693.90","0.065"],["64694.30","0.032"],["64694.60","0.032"],["64695.30","0.032"],["65296.50","0.032"]],"st":1}}
{"stream":"btcusdt@depth@100ms","data":{"e":"depthUpdate","E":1784410668204,"T":1784410668202,"s":"BTCUSDT","ps":"BTCUSDT","U":11079104948870,"u":11079104954159,"pu":11079104948782,"b":[["1000.00","50.241"],["14149.90","2.002"],["14249.90","0.714"],["14349.90","1.218"],["14549.90","0.266"],["51720.00","0.004"],["58184.90","0.002"],["61417.40","0.008"],["62063.90","1.380"],["63699.50","2.901"],["64003.40","0.000"],["64326.70","0.944"],["64349.90","0.051"],["64449.90","0.000"],["64463.70","0.047"],["64535.90","0.000"],["64537.40","0.491"],["64538.90","0.004"],["64540.40","0.202"],["64541.90","0.000"],["64543.40","0.000"],["64544.90","0.000"],["64546.40","0.556"],["64547.90","0.000"],["64549.40","1.311"],["64613.50","2.066"],["64614.00","0.006"],["64614.10","0.018"],["64615.80","0.714"],["64616.10","0.165"],["64616.40","0.605"],["64620.80","2.017"],["64621.40","0.661"],["64627.90","0.232"],["64630.50","0.065"],["64631.40","1.194"],["64631.90","0.003"],["64633.00","0.215"],["64634.30","0.443"],["64641.50","0.001"],["64642.60","0.311"],["64643.50","0.002"],["64644.00","0.234"],["64647.00","0.311"],["64648.60","0.000"],["64649.30","0.085"],["64649.90","8.113"]],"a":[["64650.00","2.416"],["64652.40","0.003"],["64652.90","0.000"],["64653.50","0.310"],["64653.70","0.007"],["64654.60","0.003"],["64655.10","0.635"],["64656.20","0.003"],["64656.50","0.740"],["64656.80","0.000"],["64657.60","0.437"],["64658.50","0.011"],["64659.00","0.312"],["64659.60","0.050"],["64659.70","0.029"],["64659.80","0.000"],["64660.30","0.176"],["64660.50","0.050"],["64661.10","0.177"],["64661.20","0.000"],["64661.90","0.621"],["64667.60","0.001"],["64668.40","0.004"],["64668.80","0.681"],["64670.10","0.005"],["64670.20","0.003"],["64671.60","0.309"],["64672.20","0.000"],["64672.70","0.007"],["64672.90","0.003"],["64675.60","2.747"],["64676.10","0.299"],["64676.60","0.589"],["64682.90","0.392"],["64683.10","0.047"],["64684.60","0.050"],["64685.60","0.011"],["65296.50","0.033"],["65328.80","2.604"],["65550.00","5.892"]],"st":1}}
{"stream":"btcusdt@depth@100ms","data":{"e":"depthUpdate","E":1784410668306,"T":1784410668305,"s":"BTCUSDT","ps":"BTCUSDT","U":11079104954417,"u":11079104958585,"pu":11079104954159,"b":[["1000.00","50.241"],["14149.90","1.988"],["14249.90","0.728"],["14349.90","1.092"],["14549.90","0.392"],["58184.90","0.002"],["61417.40","0.008"],["62063.90","1.383"],["63945.20","6.240"],["64003.40","0.000"],["64320.00","0.613"],["64400.00","28.447"],["64480.00","4.537"],["64560.00","1.320"],["64598.70","0.002"],["64600.90","21.488"],["64615.70","0.156"],["64616.10","0.321"],["64616.50","0.307"],["64617.00","0.603"],["64631.40","1.274"],["64632.60","0.001"],["64633.60","0.121"],["64635.60","0.372"],["64635.70","0.000"],["64636.30","0.715"],["64637.20","0.083"],["64637.30","0.542"],["64640.00","0.928"],["64649.30","0.005"]],"a":[["64655.10","0.048"],["64656.20","0.698"],["64656.30","0.035"],["64656.40","0.001"],["64656.50","0.045"],["64659.80","0.000"],["64666.40","0.543"],["64666.50","0.001"],["64668.70","0.005"],["64676.60","0.032"],["64677.70","0.560"],["64707.70","4.285"],["64708.50","23.944"],["64710.60","0.692"],["64710.70","0.006"],["64720.00","0.552"],["64800.00","18.636"],["64880.00","9.708"],["64960.00","2.432"],["65040.00","0.594"],["65296.50","0.033"]],"st":1}}
{"stream":"btcusdt@depth@100ms","data":{"e":"depthUpdate","E":1784410668408,"T":1784410668405,"s":"BTCUSDT","ps":"BTCUSDT","U":11079104958685,"u":11079104962863,"pu":11079104958585,"b":[["14149.90","2.002"],["14249.90","0.714"],["14349.90","0.980"],["14549.90","0.504"],["51720.00","0.006"],["58184.90","0.002"],["62063.90","1.380"],["64003.40","0.000"],["64488.30","0.037"],["64500.00","5.501"],["64598.70","21.373"],["64600.90","0.146"],["64615.90","0.132"],["64621.40","0.352"],["64627.90","0.077"],["64633.60","0.005"],["64634.30","0.366"],["64634.90","0.271"],["64640.70","0.060"],["64649.90","8.115"]],"a":[["64650.00","2.974"],["64655.10","0.048"],["64656.10","0.003"],["64656.20","0.003"],["64656.40","0.552"],["64656.50","0.189"],["64656.60","0.154"],["64657.60","0.124"],["64657.80","0.002"],["64659.10","0.051"],["64659.60","0.003"],["64659.70","0.029"],["64659.80","0.000"],["64660.00","0.101"],["64660.50","0.049"],["64666.40","0.002"],["64668.70","0.546"],["64715.80","1.125"],["64885.30","0.336"],["65296.50","0.033"],["65548.00","2.492"]],"st":1}}
{"stream":"btcusdt@depth@100ms","data":{"e":"depthUpdate","E":1784410668510,"T":1784410668509,"s":"BTCUSDT","ps":"BTCUSDT","U":11079104962963,"u":11079104966793,"pu":11079104962863,"b":[["1000.00","50.241"],["14149.90","1.988"],["14249.90","0.728"],["14349.90","0.854"],["14549.90","0.630"],["51720.00","0.004"],["58184.90","0.002"],["64003.40","0.000"],["64320.00","0.630"],["64326.70","0.944"],["64400.00","28.464"],["64449.90","0.000"],["64480.00","4.554"],["64560.00","1.337"],["64615.10","0.690"],["64633.00","0.215"],["64634.40","0.126"],["64634.90","0.155"],["64636.40","0.736"],["64637.30","0.001"],["64640.00","0.945"]],"a":[["64655.10","0.048"],["64656.40","0.001"],["64656.50","0.740"],["64656.60","0.154"],["64657.60","0.124"],["64659.80","0.000"],["64660.00","0.100"],["64660.50","0.050"],["64666.50","0.542"],["64668.70","0.005"],["64720.00","0.569"],["64800.00","18.653"],["64880.00","9.725"],["64960.00","2.449"],["64973.20","3.150"],["65040.00","0.611"],["65296.50","0.033"]],"st":1}}
{"stream":"btcusdt@depth@100ms","data":{"e":"depthUpdate","E":1784410668612,"T":1784410668609,"s":"BTCUSDT","ps":"BTCUSDT","U":11079104966882,"u":11079104972326,"pu":11079104966793,"b":[["1000.00","50.241"],["14149.90","2.002"],["14249.90","0.714"],["14349.90","0.742"],["14549.90","0.742"],["51720.00","0.008"],["58184.90","0.002"],["61417.40","0.006"],["61417.50","0.015"],["62063.90","1.383"],["64003.40","0.000"],["64326.60","3.731"],["64449.90","0.000"],["64463.70","0.043"],["64536.80","2.321"],["64536.90","0.243"],["64537.40","0.000"],["64549.40","0.035"],["64590.80","0.025"],["64598.60","0.557"],["64620.80","0.017"],["64624.60","10.003"],["64631.40","1.272"],["64632.30","0.004"],["64633.00","0.061"],["64633.30","0.637"],["64634.40","0.010"]],"a":[["64650.00","3.589"],["64653.50","0.000"],["64656.10","0.003"],["64656.20","0.003"],["64656.30","0.035"],["64656.40","0.001"],["64656.50","0.018"],["64659.10","0.004"],["64659.80","0.722"],["64660.00","0.101"],["64660.50","0.049"],["64666.50","0.542"],["64668.70","0.005"],["64672.70","0.005"],["64673.20","0.002"],["64675.60","0.747"],["64678.70","10.001"],["64681.50","2.027"],["64707.70","0.730"],["64708.50","0.000"],["64710.70","23.940"],["64753.20","2.320"],["64753.30","0.024"],["65296.50","0.033"],["65942.90","0.648"]],"st":1}}
{"stream":"btcusdt@depth@100ms","data":{"e":"depthUpdate","E":1784410668714,"T":1784410668713,"s":"BTCUSDT","ps":"BTCUSDT","U":11079104972427,"u":11079104977920,"pu":11079104972326,"b":[["14149.90","1.876"],["14249.90","0.784"],["14349.90","0.616"],["14549.90","0.924"],["58184.90","0.000"],["61417.40","0.006"],["62063.90","1.380"],["64003.40","0.000"],["64326.60","3.730"],["64349.90","0.051"],["64449.90","0.000"],["64463.70","0.047"],["64524.80","0.016"],["64530.80","0.008"],["64618.20","2.032"],["64624.50","3.856"],["64624.60","0.005"],["64627.50","0.011"],["64646.40","0.007"],["64649.90","8.027"]],"a":[["64650.00","3.972"],["64652.00","0.005"],["64653.60","0.310"],["64655.20","1.324"],["64656.40","0.012"],["64656.60","0.154"],["64658.50","0.000"],["64659.30","0.050"],["64660.00","0.100"],["64660.30","0.177"],["64674.60","2.047"],["64678.70","0.003"],["64680.20","1.788"],["64681.50","2.027"],["64725.00","0.013"],["64973.30","1.694"],["65296.50","0.033"]],"st":1}}
{"stream":"btcusdt@depth@100ms","data":{"e":"depthUpdate","E":1784410668816,"T":1784410668813,"s":"BTCUSDT","ps":"BTCUSDT","U":11079104977941,"u":11079104981719,"pu":11079104977920,"b":[["1000.00","50.241"],["14149.90","1.638"],["14249.90","0.896"],["14349.90","0.504"],["14549.90","1.162"],["58184.90","0.000"],["61417.40","0.006"],["62063.90","1.383"],["63874.10","31.750"],["64003.40","0.000"],["64326.70","0.944"],["64631.50","1.222"],["64632.30","0.002"],["64643.40","0.007"]],"a":[["64650.00","3.973"],["64656.60","0.741"],["64681.50","1.950"],["64708.50","23.934"],["64710.70","0.006"],["64778.30","0.100"],["65296.50","0.033"],["65942.90","0.651"]],"st":1}}
{"stream":"btcusdt@depth@100ms","data":{"e":"depthUpdate","E":1784410668918,"T":1784410668916,"s":"BTCUSDT","ps":"BTCUSDT","U":11079104981804,"u":11079104985899,"pu":11079104981719,"b":[["1000.00","50.241"],["14149.90","1.400"],["14249.90","1.022"],["14349.90","0.378"],["14549.90","1.400"],["58184.90","0.002"],["61417.40","0.006"],["62063.90","1.380"],["63731.90","5.908"],["64003.40","0.000"],["64320.00","0.613"],["64400.00","28.447"],["64480.00","4.537"],["64560.00","1.320"],["64633.00","0.215"],["64636.20","0.522"],["64640.00","0.928"],["64647.00","0.380"]],"a":[["64656.60","0.741"],["64668.70","0.005"],["64720.00","0.552"],["64800.00","18.636"],["64880.00","9.708"],["64960.00","2.432"],["65040.00","0.594"],["65458.10","10.402"],["65568.00","1.348"]],"st":1}}
{"stream":"btcusdt@depth@100ms","data":{"e":"depthUpdate","E":1784410669022,"T":1784410669021,"s":"BTCUSDT","ps":"BTCUSDT","U":11079104986008,"u":11079104989928,"pu":11079104985899,"b":[["14149.90","1.148"],["14249.90","1.134"],["14349.90","0.266"],["14549.90","1.652"],["58184.90","0.002"],["61417.40","0.006"],["64003.40","0.000"],["64326.60","3.885"],["64449.90","0.000"],["64561.90","0.104"],["64569.70","0.001"],["64649.90","8.025"]],"a":[["64656.60","0.741"],["64676.20","0.573"],["64677.70","0.003"],["65389.50","0.000"],["65477.20","1.391"]],"st":1}}
{"stream":"btcusdt@depth@100ms","data":{"e":"depthUpdate","E":1784410669124,"T":1784410669122,"s":"BTCUSDT","ps":"BTCUSDT","U":11079104989972,"u":11079104994959,"pu":11079104989928,"b":[["1000.00","50.241"],["14149.90","0.924"],["14249.90","1.260"],["14349.90","0.140"],["14549.90","1.876"],["51719.90","0.000"],["58184.90","0.002"],["61417.40","0.006"],["61417.50","0.013"],["62063.90","1.383"],["64003.40","0.000"],["64320.00","0.443"],["64326.70","0.934"],["64400.00","28.277"],["64449.90","0.000"],["64478.40","0.886"],["64480.00","4.367"],["64495.60","0.868"],["64536.90","0.694"],["64560.00","1.150"],["64614.00","1.039"],["64633.00","0.061"],["64638.30","0.626"],["64640.00","0.758"],["64643.40","0.005"],["64647.20","1.465"],["64649.80","0.024"],["64649.90","8.017"]],"a":[["64650.00","3.966"],["64655.20","1.277"],["64656.60","0.741"],["64688.00","1.821"],["64709.50","0.000"],["64720.00","0.382"],["64800.00","18.466"],["64801.80","1.026"],["64818.90","0.901"],["64819.00","0.000"],["64880.00","9.538"],["64960.00","2.262"],["65040.00","0.424"],["65296.50","0.033"],["65419.30","4.583"],["65942.90","0.654"]],"st":1}}
{"stream":"btcusdt@depth@100ms","data":{"e":"depthUpdate","E":1784410669226,"T":1784410669225,"s":"BTCUSDT","ps":"BTCUSDT","U":11079104995046,"u":11079104998426,"pu":11079104994959,"b":[["1000.00","50.241"],["14149.90","0.742"],["14249.90","1.372"],["14349.90","0.028"],["14449.90","0.070"],["14549.90","1.988"],["58184.90","0.002"],["61417.40","0.006"],["62063.90","1.380"],["62726.20","0.682"],["63221.70","0.000"],["63854.20","2.946"],["64003.40","0.000"],["64320.00","0.630"],["64349.90","0.051"],["64400.00","28.464"],["64449.90","0.000"],["64480.00","4.554"],["64560.00","1.337"],["64633.00","0.215"],["64640.00","0.945"]],"a":[["64656.60","0.154"],["64720.00","0.569"],["64725.00","0.011"],["64800.00","18.653"],["64880.00","9.725"],["64960.00","2.449"],["65040.00","0.611"],["65296.50","0.032"],["65588.80","0.779"]],"st":1}}
{"stream":"btcusdt@depth@100ms","data":{"e":"depthUpdate","E":1784410669328,"T":1784410669326,"s":"BTCUSDT","ps":"BTCUSDT","U":11079104998546,"u":11079105003065,"pu":11079104998426,"b":[["14149.90","0.728"],["14249.90","1.302"],["14349.90","0.000"],["14449.90","0.182"],["14549.90","1.988"],["51720.00","0.008"],["58184.90","0.002"],["62063.90","1.383"],["63466.60","0.844"],["63788.70","0.783"],["63854.20","2.681"],["63906.40","9.379"],["64003.40","0.000"],["64326.70","0.934"],["64441.60","0.013"],["64478.40","0.000"],["64495.60","0.007"],["64621.60","0.310"],["64628.00","0.158"],["64634.50","0.432"],["64649.90","8.018"]],"a":[["64650.00","3.967"],["64654.80","0.100"],["64656.60","0.154"],["64661.30","0.156"],["64667.70","0.431"],["64801.80","0.000"],["64818.90","0.000"],["64855.80","0.000"],["65130.80","0.014"],["65296.50","0.034"],["65366.10","0.235"],["65518.80","0.766"]],"st":1}}
{"stream":"btcusdt@depth@100ms","data":{"e":"depthUpdate","E":1784410669430,"T":1784410669429,"s":"BTCUSDT","ps":"BTCUSDT","U":11079105003269,"u":11079105008863,"pu":11079105003065,"b":[["1000.00","50.241"],["14149.90","0.714"],["14249.90","1.190"],["14449.90","0.308"],["14549.90","1.988"],["51720.00","0.008"],["58184.90","0.002"],["61417.40","0.006"],["62063.90","1.380"],["63744.80","23.032"],["63954.30","2.529"],["64003.40","0.000"],["64441.60","4.580"],["64478.40","0.905"],["64495.50","0.704"],["64550.30","0.000"],["64557.60","0.001"],["64559.90","0.005"],["64624.50","3.858"],["64624.60","0.003"],["64640.00","5.586"],["64649.20","0.200"]],"a":[["64650.00","3.358"],["64651.70","0.013"],["64654.80","0.023"],["64656.50","0.740"],["64656.60","0.154"],["64657.20","0.306"],["64657.50","0.003"],["64659.30","0.003"],["64659.60","0.050"],["64659.80","0.000"],["64661.30","0.001"],["64667.70","0.122"],["64693.00","0.059"],["64701.70","0.032"],["64708.50","23.936"],["64709.40","0.001"],["64801.80","0.000"],["64818.90","0.910"],["64840.70","0.208"],["64855.80","3.486"],["64886.00","2.288"],["65296.50","0.032"]],"st":1}}
{"stream":"btcusdt@depth@100ms","data":{"e":"depthUpdate","E":1784410669532,"T":1784410669529,"s":"BTCUSDT","ps":"BTCUSDT","U":11079105008969,"u":11079105013635,"pu":11079105008863,"b":[["1000.00","50.241"],["14149.90","0.728"],["14249.90","1.064"],["14449.90","0.420"],["14549.90","1.988"],["58184.90","0.002"],["61417.40","0.006"],["63163.00","3.166"],["63868.60","0.776"],["64003.40","0.000"],["64449.90","0.000"],["64463.70","0.043"],["64495.50","1.580"],["64561.90","0.100"],["64633.00","0.061"],["64643.20","1.891"],["64649.90","8.024"]],"a":[["64650.00","3.353"],["64656.40","0.001"],["64656.50","0.018"],["64656.60","0.741"],["64658.10","0.016"],["64659.80","0.722"],["64801.80","1.041"],["64942.30","0.102"],["65107.50","0.238"],["65296.50","0.032"],["65393.10","0.000"],["65418.60","1.471"],["65492.40","0.153"],["65495.70","0.267"],["65575.90","8.933"],["65776.40","6.833"],["65942.90","0.657"]],"st":1}}
{"stream":"btcusdt@depth@100ms","data":{"e":"depthUpdate","E":1784410669634,"T":1784410669633,"s":"BTCUSDT","ps":"BTCUSDT","U":11079105013773,"u":11079105018534,"pu":11079105013635,"b":[["14149.90","0.714"],["14249.90","0.952"],["14449.90","0.546"],["14549.90","1.988"],["58184.90","0.002"],["61417.40","0.004"],["61417.50","0.015"],["62063.90","1.383"],["63645.30","1.098"],["64003.40","0.000"],["64326.70","0.944"],["64449.90","0.000"]],"a":[["64656.40","0.001"],["64656.50","0.018"],["64656.60","0.741"],["64659.80","0.722"],["65227.00","0.245"],["65296.50","0.032"],["65555.10","17.412"],["65827.90","0.758"]],"st":1}}
{"stream":"btcusdt@depth@100ms","data":{"e":"depthUpdate","E":1784410669736,"T":1784410669735,"s":"BTCUSDT","ps":"BTCUSDT","U":11079105018573,"u":11079105023768,"pu":11079105018534,"b":[["1000.00","50.241"],["14149.90","0.728"],["14249.90","0.826"],["14449.90","0.658"],["14549.90","1.988"],["58184.90","0.002"],["61417.40","0.002"],["61417.50","0.015"],["62063.90","1.380"],["63760.20","0.017"],["63860.30","1.867"],["64003.40","0.000"],["64378.40","0.000"],["64381.60","0.117"],["64449.90","0.000"],["64485.00","0.343"],["64488.30","0.193"],["64495.50","1.431"],["64500.00","5.496"],["64562.60","0.008"],["64564.50","0.002"],["64618.20","0.032"],["64621.60","0.001"],["64622.60","10.003"],["64628.00","0.003"],["64634.50","0.355"],["64647.20","1.443"],["64649.90","8.004"]],"a":[["64650.00","3.353"],["64651.70","0.015"],["64654.00","0.008"],["64654.40","0.025"],["64654.70","0.000"],["64655.00","0.051"],["64656.50","0.018"],["64656.60","0.154"],["64659.80","0.722"],["64660.30","0.003"],["64674.60","0.047"],["64678.50","10.107"],["64708.50","0.002"],["64710.60","4.257"],["64710.70","23.940"],["64722.50","0.000"],["64801.80","0.943"],["64882.70","0.174"],["64973.30","1.692"],["65271.30","0.000"],["65296.50","0.032"],["65414.20","0.763"],["65522.80","5.631"],["65548.60","7.277"],["65644.60","27.204"],["65711.70","1.530"]],"st":1}}
{"stream":"btcusdt@depth@100ms","data":{"e":"depthUpdate","E":1784410669838,"T":1784410669837,"s":"BTCUSDT","ps":"BTCUSDT","U":11079105023808,"u":11079105027490,"pu":11079105023768,"b":[["1000.00","50.241"],["14149.90","0.714"],["14249.90","0.714"],["14449.90","0.784"],["14549.90","1.988"],["58184.90","0.002"],["61417.40","0.002"],["62063.90","1.383"],["63569.30","0.549"],["63874.10","33.313"],["63874.90","0.004"],["64003.40","0.000"],["64029.70","4.914"],["64326.60","3.887"],["64553.10","0.004"],["64559.90","0.001"],["64632.60","0.117"],["64633.00","0.215"],["64633.30","0.521"]],"a":[["64666.50","0.001"],["64668.70","0.546"],["64676.20","0.016"],["64677.00","0.559"],["65296.50","0.032"],["65470.90","3.550"],["65477.20","1.133"],["65548.00","1.730"],["65619.70","0.684"],["65627.70","8.449"]],"st":1}}
{"stream":"btcusdt@depth@100ms","data":{"e":"depthUpdate","E":1784410669940,"T":1784410669937,"s":"BTCUSDT","ps":"BTCUSDT","U":11079105027576,"u":11079105032711,"pu":11079105027490,"b":[["14149.90","0.812"],["14249.90","0.588"],["14449.90","0.980"],["14549.90","1.820"],["58184.90","0.002"],["62729.80","0.011"],["63357.00","0.011"],["63647.80","10.981"],["64003.00","0.749"],["64003.40","0.000"],["64326.70","0.944"],["64478.40","0.916"],["64495.50","1.589"],["64573.40","0.075"],["64578.30","0.009"],["64580.20","0.001"],["64585.10","0.008"],["64636.20","0.522"]],"a":[["64655.00","0.004"],["64656.40","0.001"],["64656.50","0.018"],["64656.60","0.201"],["64659.80","0.722"],["64666.50","0.542"],["64668.70","0.005"],["64801.80","1.012"],["64818.90","0.888"],["65203.80","0.077"],["65296.50","0.032"]],"st":1}}
{"stream":"btcusdt@depth@100ms","data":{"e":"depthUpdate","E":1784410670042,"T":1784410670041,"s":"BTCUSDT","ps":"BTCUSDT","U":11079105032945,"u":11079105038904,"pu":11079105032711,"b":[["1000.00","50.241"],["14149.90","0.924"],["14249.90","0.476"],["14449.90","1.232"],["14549.90","1.568"],["58184.90","0.002"],["62063.90","1.380"],["63566.10","0.000"],["63835.70","2.194"],["63880.60","6.566"],["63954.30","1.748"],["64003.40","0.000"],["64029.70","4.368"],["64449.90","0.000"],["64633.00","0.215"],["64638.30","0.631"]],"a":[["64656.50","0.605"],["64681.50","2.027"],["65296.50","0.032"],["65511.20","0.761"],["65600.40","3.048"],["65639.00","0.002"],["65684.40","7.266"]],"st":1}}
{"stream":"btcusdt@depth@100ms","data":{"e":"depthUpdate","E":1784410670144,"T":1784410670141,"s":"BTCUSDT","ps":"BTCUSDT","U":11079105038978,"u":11079105045023,"pu":11079105038904,"b":[["1000.00","50.241"],["14149.90","1.050"],["14249.90","0.350"],["14449.90","1.456"],["14549.90","1.344"],["51719.90","0.000"],["58184.90","0.002"],["61417.40","0.002"],["61417.50","0.017"],["62063.90","1.383"],["63550.90","7.963"],["63635.10","0.012"],["64003.40","0.000"],["64449.90","0.000"],["64598.80","3.281"],["64623.70","2.452"],["64633.00","0.061"],["64638.30","0.626"],["64649.90","8.004"]],"a":[["64650.00","3.348"],["64656.50","0.605"],["64656.60","0.154"],["64678.40","3.685"],["64679.60","0.007"],["64709.50","0.002"],["65296.50","0.032"],["65574.20","3.464"],["65664.80","0.794"]],"st":1}}
{"stream":"btcusdt@depth@100ms","data":{"e":"depthUpdate","E":1784410670246,"T":1784410670245,"s":"BTCUSDT","ps":"BTCUSDT","U":11079105045172,"u":11079105051117,"pu":11079105045023,"b":[["14149.90","1.162"],["14249.90","0.238"],["14449.90","1.708"],["14549.90","1.092"],["58184.90","0.002"],["61417.40","0.002"],["62063.90","1.380"],["63357.00","0.008"],["63635.10","0.024"],["63886.60","5.255"],["64003.40","0.000"],["64029.70","3.822"],["64326.70","0.944"],["64449.90","0.000"],["64485.00","0.499"],["64535.90","1.276"],["64537.40","1.276"],["64538.90","1.280"],["64540.40","1.478"],["64541.90","1.276"],["64567.10","0.017"],["64569.70","0.005"],["64624.30","0.154"],["64626.70","0.000"],["64632.60","0.001"],["64633.00","0.061"],["64633.20","0.124"],["64633.80","4.516"],["64635.20","0.559"],["64635.40","0.973"],["64635.60","0.913"],["64636.10","0.155"],["64636.30","0.158"],["64636.40","0.195"],["64640.70","0.782"],["64643.30","1.378"],["64644.50","0.003"],["64645.30","0.645"],["64645.50","0.120"],["64647.30","0.119"],["64647.40","0.063"],["64647.50","0.000"],["64647.60","0.000"],["64647.70","0.001"]],"a":[["64655.10","0.635"],["64656.40","0.001"],["64656.50","0.018"],["64656.60","0.154"],["64657.60","0.281"],["64659.60","0.003"],["64659.70","0.076"],["64659.80","0.722"],["64665.70","0.597"],["64667.90","0.036"],["64668.90","0.926"],["64669.80","0.004"],["64675.40","0.004"],["64676.30","0.803"],["64677.00","0.002"],["64681.50","1.950"],["65296.50","0.032"],["65619.80","2.766"],["65664.70","0.012"],["65817.20","0.008"]],"st":1}}
{"stream":"btcusdt@depth@100ms","data":{"e":"depthUpdate","E":1784410670348,"T":1784410670345,"s":"BTCUSDT","ps":"BTCUSDT","U":11079105051245,"u":11079105056429,"pu":11079105051117,"b":[["1000.00","50.241"],["14149.90","1.288"],["14249.90","0.112"],["14449.90","1.932"],["14549.90","0.868"],["58184.90","0.002"],["61417.40","0.002"],["62063.90","1.383"],["63809.10","0.570"],["63954.30","0.967"],["64003.00","1.295"],["64003.40","0.000"],["64495.50","0.704"],["64535.90","0.000"],["64537.40","0.000"],["64538.90","0.004"],["64540.40","0.202"],["64541.90","0.000"],["64553.10","0.000"],["64559.90","0.005"],["64633.00","0.215"],["64639.80","0.840"],["64640.00","5.588"],["64640.70","0.601"],["64643.20","1.892"],["64643.30","0.064"],["64643.40","0.005"],["64643.50","0.002"],["64644.30","0.002"],["64645.10","0.219"],["64645.40","0.105"],["64646.50","0.156"],["64647.20","1.442"],["64647.30","1.614"],["64647.40","0.063"],["64649.60","0.842"]],"a":[["64650.00","3.349"],["64653.30","0.005"],["64655.10","0.048"],["64656.50","0.018"],["64656.60","0.154"],["64657.60","0.124"],["64659.80","0.722"],["64678.50","10.109"],["64678.70","0.001"],["64801.80","0.000"],["64886.00","2.171"],["64940.70","0.000"],["65296.50","0.032"]],"st":1}}
{"stream":"btcusdt@depth@100ms","data":{"e":"depthUpdate","E":1784410670450,"T":1784410670449,"s":"BTCUSDT","ps":"BTCUSDT","U":11079105056570,"u":11079105063028,"pu":11079105056429,"b":[["1000.00","50.241"],["14149.90","1.400"],["14249.90","0.000"],["14349.90","0.098"],["14449.90","1.988"],["14549.90","0.714"],["58184.90","0.002"],["61417.40","0.022"],["63642.00","6.710"],["63706.60","5.180"],["64003.00","1.841"],["64003.40","0.000"],["64029.70","3.276"],["64495.50","1.506"],["64535.90","0.000"],["64537.40","0.000"],["64538.90","0.004"],["64540.40","0.202"],["64541.90","0.000"],["64621.40","0.661"],["64622.90","0.683"],["64627.90","0.232"],["64633.00","0.061"],["64634.30","0.443"],["64640.70","0.060"],["64640.80","0.843"],["64643.30","1.378"],["64646.60","0.024"],["64647.30","0.119"],["64647.40","0.063"],["64647.50","0.000"],["64647.60","0.000"],["64647.70","0.001"]],"a":[["64650.00","3.344"],["64653.30","0.006"],["64654.60","0.080"],["64656.40","0.001"],["64656.50","0.018"],["64656.60","0.154"],["64659.70","0.029"],["64659.80","0.722"],["64661.10","0.332"],["64667.60","0.310"],["64801.80","0.978"],["65005.50","0.000"],["65070.30","0.000"],["65296.50","0.032"],["65381.90","5.118"],["65418.60","0.708"],["65789.80","0.875"]],"st":1}}
{"stream":"btcusdt@depth@100ms","data":{"e":"depthUpdate","E":1784410670552,"T":1784410670549,"s":"BTCUSDT","ps":"BTCUSDT","U":11079105063075,"u":11079105068599,"pu":11079105063028,"b":[["14149.90","1.274"],["14349.90","0.210"],["14449.90","1.988"],["14549.90","0.728"],["51720.00","0.008"],["58184.90","0.002"],["62063.90","1.380"],["63642.00","5.141"],["63835.70","1.646"],["63874.10","33.782"],["64003.40","0.000"],["64326.70","0.944"],["64449.90","0.000"],["64633.00","0.215"],["64640.80","0.689"],["64643.40","0.159"],["64644.30","0.004"],["64645.10","0.217"],["64649.60","0.606"]],"a":[["64656.40","0.588"],["64656.50","0.018"],["64656.60","0.154"],["64658.20","0.054"],["64659.80","0.722"],["65135.10","0.007"],["65296.50","0.032"],["65563.00","0.935"]],"st":1}}
{"stream":"btcusdt@depth@100ms","data":{"e":"depthUpdate","E":1784410670654,"T":1784410670652,"s":"BTCUSDT","ps":"BTCUSDT","U":11079105068734,"u":11079105074737,"pu":11079105068599,"b":[["1000.00","50.241"],["14149.90","1.162"],["14349.90","0.336"],["14449.90","1.988"],["14549.90","0.714"],["58184.90","0.002"],["62063.90","1.383"],["63512.60","4.405"],["63680.20","2.393"],["63703.70","8.704"],["64003.40","0.001"],["64029.70","2.730"],["64449.90","0.000"],["64478.40","0.000"],["64495.50","0.704"],["64553.10","0.004"],["64559.90","0.001"],["64585.30","0.132"]],"a":[["64656.40","0.588"],["64656.50","0.018"],["64656.60","0.154"],["64659.80","0.722"],["64730.40","0.002"],["64801.80","0.000"],["64818.90","0.000"],["64875.90","0.137"],["65296.50","0.032"],["65354.70","1.374"],["65563.00","0.402"],["71115.00","0.002"]],"st":1}}
{"stream":"btcusdt@depth@100ms","data":{"e":"depthUpdate","E":1784410670756,"T":1784410670755,"s":"BTCUSDT","ps":"BTCUSDT","U":11079105074804,"u":11079105081130,"pu":11079105074737,"b":[["1000.00","50.241"],["14149.90","1.036"],["14349.90","0.448"],["14449.90","1.988"],["14549.90","0.728"],["58184.90","0.002"],["61417.40","0.016"],["62063.90","1.380"],["63357.00","0.005"],["63615.50","7.530"],["63706.60","3.613"],["63835.70","1.098"],["64003.00","2.387"],["64003.40","0.000"],["64029.70","1.638"],["64378.40","0.117"],["64381.60","0.000"],["64441.60","0.013"],["64449.90","0.000"],["64564.50","0.006"],["64585.30","0.133"],["64613.50","0.003"],["64614.00","0.006"],["64633.00","0.061"],["64643.40","0.161"]],"a":[["64650.00","3.343"],["64656.40","0.001"],["64656.50","0.018"],["64656.60","0.154"],["64659.80","0.722"],["64842.70","0.241"],["64842.80","0.003"],["64855.80","0.000"],["64940.50","0.062"],["65005.10","0.042"],["65296.50","0.032"],["65841.10","6.376"],["71115.00","0.000"]],"st":1}}
{"stream":"btcusdt@depth@100ms","data":{"e":"depthUpdate","E":1784410670858,"T":1784410670857,"s":"BTCUSDT","ps":"BTCUSDT","U":11079105081230,"u":11079105086940,"pu":11079105081130,"b":[["14149.90","0.924"],["14349.90","0.574"],["14449.90","1.988"],["14549.90","0.714"],["58184.90","0.002"],["61417.40","0.002"],["62063.90","1.383"],["63615.50","9.100"],["63706.60","2.046"],["63712.50","25.855"],["63809.10","1.666"],["64003.40","0.002"],["64326.60","3.885"],["64326.70","0.944"],["64440.50","0.000"],["64441.50","4.567"],["64441.60","2.633"],["64478.40","0.820"],["64485.00","0.499"],["64495.50","0.704"],["64633.00","0.215"],["64649.50","0.138"]],"a":[["64655.10","0.048"],["64657.60","0.437"],["64801.80","0.000"],["64818.90","0.853"],["64855.70","3.537"],["64973.30","1.694"],["65069.70","0.058"],["65296.50","0.032"],["65458.10","10.660"],["65470.90","3.322"],["65647.10","5.865"]],"st":1}}
{"stream":"btcusdt@depth@100ms","data":{"e":"depthUpdate","E":1784410670960,"T":1784410670958,"s":"BTCUSDT","ps":"BTCUSDT","U":11079105086946,"u":11079105092285,"pu":11079105086940,"b":[["1000.00","50.241"],["14149.90","0.798"],["14349.90","0.686"],["14449.90","1.988"],["14549.90","0.728"],["58184.90","0.002"],["61417.40","0.002"],["62690.80","1.366"],["63486.20","3.366"],["63577.30","7.072"],["63680.20","3.961"],["63841.80","9.291"],["64003.00","3.479"],["64003.40","0.000"],["64495.50","1.582"],["64564.50","0.002"],["64636.20","0.522"],["64640.80","0.148"],["64643.40","0.702"]],"a":[["64655.10","0.048"],["64658.20","0.007"],["64659.10","0.051"],["64668.70","0.005"],["64801.80","1.026"],["65296.50","0.032"],["65413.60","1.833"],["65419.30","5.499"],["65535.70","2.663"],["65550.00","4.978"],["65561.60","4.111"],["65580.80","0.266"],["65612.70","2.281"],["65617.10","2.415"],["65813.70","2.723"],["66589.30","0.000"]],"st":1}}
{"stream":"btcusdt@depth@100ms","data":{"e":"depthUpdate","E":1784410671062,"T":1784410671061,"s":"BTCUSDT","ps":"BTCUSDT","U":11079105092425,"u":11079105097331,"pu":11079105092285,"b":[["1000.00","50.241"],["14149.90","0.686"],["14349.90","0.812"],["14449.90","1.988"],["14549.90","0.714"],["58184.90","0.002"],["62063.90","1.380"],["63512.60","2.204"],["63971.80","1.169"],["64003.00","4.025"],["64003.40","0.000"],["64449.90","0.000"],["64638.30","0.626"]],"a":[["64655.10","0.635"],["64681.50","1.950"],["64778.30","0.000"],["65296.50","0.032"],["65419.30","6.415"],["66646.70","0.000"]],"st":1}}
{"stream":"btcusdt@depth@100ms","data":{"e":"depthUpdate","E":1784410671166,"T":1784410671165,"s":"BTCUSDT","ps":"BTCUSDT","U":11079105097575,"u":11079105104450,"pu":11079105097331,"b":[["14149.90","0.560"],["14349.90","1.050"],["14449.90","1.750"],["14549.90","0.840"],["51719.90","0.000"],["58184.90","0.002"],["61417.40","0.002"],["61417.50","0.015"],["62063.90","1.383"],["63512.60","0.002"],["63550.90","8.748"],["63680.20","5.529"],["63733.90","0.097"],["63841.80","9.556"],["64003.40","0.000"],["64132.70","7.779"],["64326.70","0.944"],["64485.00","0.343"],["64610.30","0.487"],["64614.00","0.731"],["64644.00","0.002"],["64644.30","0.236"]],"a":[["64655.10","0.635"],["65296.50","0.032"],["65619.70","2.206"]],"st":1}}
{"stream":"btcusdt@depth@100ms","data":{"e":"depthUpdate","E":1784410671268,"T":1784410671267,"s":"BTCUSDT","ps":"BTCUSDT","U":11079105104521,"u":11079105111507,"pu":11079105104450,"b":[["1000.00","50.241"],["14149.90","0.448"],["14349.90","1.288"],["14449.90","1.512"],["14549.90","0.952"],["58184.90","0.002"],["61417.40","0.002"],["62063.90","1.380"],["63357.00","0.008"],["63918.00","1.565"],["63945.20","6.942"],["64003.40","0.002"],["64029.70","1.092"],["64449.90","0.000"],["64610.30","0.490"]],"a":[["64650.00","3.344"],["64653.50","0.587"],["64655.10","0.048"],["64656.60","0.467"],["64657.50","0.160"],["64707.70","4.272"],["64708.50","23.855"],["64710.60","0.692"],["64710.70","0.006"],["65296.50","0.032"],["65374.10","0.011"],["65381.90","5.882"],["65413.60","0.917"],["65490.50","2.055"]],"st":1}}
{"stream":"btcusdt@depth@100ms","data":{"e":"depthUpdate","E":1784410671370,"T":1784410671368,"s":"BTCUSDT","ps":"BTCUSDT","U":11079105111546,"u":11079105117358,"pu":11079105111507,"b":[["14149.90","0.322"],["14349.90","1.526"],["14449.90","1.274"],["14549.90","1.078"],["51720.00","0.010"],["58184.90","0.002"],["61417.40","0.002"],["63486.20","5.568"],["63708.40","0.094"],["63835.70","0.550"],["64003.40","0.000"],["64553.10","0.000"],["64554.60","14.290"],["64556.40","3.279"],["64559.40","0.370"],["64559.90","0.005"],["64561.20","0.023"],["64562.70","2.691"],["64563.20","0.265"],["64633.00","0.061"],["64643.40","0.700"]],"a":[["64650.00","3.339"],["64653.50","0.000"],["64656.40","0.001"],["64656.50","0.018"],["64656.60","0.741"],["64657.10","0.128"],["64657.20","0.182"],["64657.50","0.003"],["64657.60","0.124"],["64659.10","0.004"],["64659.50","0.231"],["64659.80","0.722"],["64707.70","0.730"],["64708.50","23.883"],["64710.70","0.006"],["65277.10","1.854"],["65296.50","0.032"],["65749.10","3.565"]],"st":1}}
{"stream":"btcusdt@depth@100ms","data":{"e":"depthUpdate","E":1784410671472,"T":1784410671471,"s":"BTCUSDT","ps":"BTCUSDT","U":11079105117508,"u":11079105122672,"pu":11079105117358,"b":[["14149.90","0.210"],["14349.90","1.764"],["14449.90","1.036"],["14549.90","1.190"],["51720.00","0.008"],["58184.90","0.002"],["61417.40","0.002"],["62063.90","1.383"],["63486.20","7.771"],["63724.10","0.786"],["63835.70","0.002"],["63841.80","9.821"],["63936.20","3.097"],["63963.00","10.958"],["64003.00","4.571"],["64003.40","0.000"],["64092.20","0.002"],["64326.70","0.944"],["64585.30","0.132"]],"a":[["64656.40","0.001"],["64656.50","0.018"],["64656.60","0.154"],["64659.80","0.722"],["64708.50","0.002"],["64710.70","23.887"],["64714.60","0.001"],["65296.50","0.032"],["65492.30","0.157"],["66637.60","0.000"]],"st":1}}
{"stream":"btcusdt@depth@100ms","data":{"e":"depthUpdate","E":1784410671574,"T":1784410671573,"s":"BTCUSDT","ps":"BTCUSDT","U":11079105122739,"u":11079105129297,"pu":11079105122672,"b":[["1000.00","50.241"],["14149.90","0.084"],["14349.90","2.002"],["14449.90","0.798"],["14549.90","1.316"],["58184.90","0.002"],["61417.40","0.002"],["62063.90","1.380"],["63809.10","2.214"],["64003.40","0.000"],["64452.70","0.156"],["64488.30","0.037"],["64495.50","1.582"],["64535.90","0.000"],["64536.90","0.243"],["64537.40","0.000"],["64537.50","0.909"],["64538.90","0.004"],["64540.40","0.202"],["64541.90","0.000"],["64543.40","1.276"],["64592.10","21.967"],["64594.70","4.141"],["64598.70","0.002"],["64598.80","0.000"],["64614.20","0.010"],["64614.30","0.400"],["64614.40","0.018"],["64614.60","0.000"],["64614.70","0.002"],["64614.80","0.006"],["64630.10","0.385"],["64630.20","0.053"],["64630.30","0.387"],["64633.00","0.215"],["64649.90","8.002"]],"a":[["64650.00","3.342"],["64651.90","0.002"],["64656.10","0.050"],["64656.60","0.741"],["64681.50","2.027"],["64801.70","1.349"],["64801.80","0.000"],["65296.50","0.032"],["65419.30","7.331"],["65458.10","10.918"]],"st":1}}
{"stream":"btcusdt@depth@100ms","data":{"e":"depthUpdate","E":1784410671676,"T":1784410671675,"s":"BTCUSDT","ps":"BTCUSDT","U":11079105129395,"u":11079105134633,"pu":11079105129297,"b":[["14149.90","0.000"],["14249.90","0.126"],["14349.90","1.988"],["14449.90","0.714"],["14549.90","1.372"],["51720.00","0.008"],["58184.90","0.002"],["62063.90","1.383"],["63465.00","0.001"],["64003.40","0.000"],["64068.00","2.415"],["64488.30","0.193"],["64537.50","0.037"],["64540.40","0.202"],["64541.90","0.000"],["64543.40","0.000"],["64564.50","0.006"],["64592.10","0.006"],["64594.70","0.818"],["64596.50","21.965"],["64644.20","0.576"],["64649.90","8.003"]],"a":[["64656.10","0.003"],["64656.30","0.082"],["64656.40","0.588"],["64656.50","0.172"],["64656.60","0.154"],["64659.80","0.568"],["65296.50","0.032"],["65458.10","11.146"],["65511.20","1.523"],["65549.30","31.712"]],"st":1}}
{"stream":"btcusdt@depth@100ms","data":{"e":"depthUpdate","E":1784410671778,"T":1784410671776,"s":"BTCUSDT","ps":"BTCUSDT","U":11079105134651,"u":11079105139608,"pu":11079105134633,"b":[["14249.90","0.238"],["14349.90","2.002"],["14449.90","0.714"],["14549.90","1.246"],["51720.00","0.008"],["58184.90","0.002"],["61417.40","0.002"],["62063.90","1.380"],["63530.10","0.788"],["63790.70","0.785"],["63809.10","2.762"],["63918.00","2.346"],["63938.80","0.702"],["64003.40","0.000"],["64326.70","0.944"]],"a":[["64656.30","0.035"],["64656.40","0.001"],["64656.50","0.723"],["64656.60","0.154"],["64659.80","0.017"],["64681.50","1.950"],["65296.50","0.032"],["65413.60","0.001"],["65420.00","22.861"],["65477.20","0.875"],["65490.50","3.123"],["65555.10","17.671"],["66610.50","2.175"]],"st":1}}
{"stream":"btcusdt@depth@100ms","data":{"e":"depthUpdate","E":1784410671880,"T":1784410671877,"s":"BTCUSDT","ps":"BTCUSDT","U":11079105139650,"u":11079105143894,"pu":11079105139608,"b":[["1000.00","50.241"],["14249.90","0.364"],["14349.90","1.988"],["14449.90","0.714"],["14549.90","1.134"],["58184.90","0.002"],["61417.40","0.002"],["61417.50","0.013"],["63639.10","9.646"],["63854.20","2.447"],["63868.30","3.362"],["64003.40","0.001"],["64485.00","0.002"],["64585.30","0.131"],["64596.50","0.004"],["64598.70","21.963"],["64633.00","0.061"]],"a":[["64650.00","3.336"],["64656.50","0.723"],["64656.60","0.154"],["64659.80","0.017"],["64973.30","1.692"],["65296.50","0.032"],["65763.50","0.533"]],"st":1}}
{"stream":"btcusdt@depth@100ms","data":{"e":"depthUpdate","E":1784410671982,"T":1784410671981,"s":"BTCUSDT","ps":"BTCUSDT","U":11079105144080,"u":11079105149107,"pu":11079105143894,"b":[["14249.90","0.476"],["14349.90","2.002"],["14449.90","0.714"],["14549.90","1.008"],["58184.90","0.002"],["61417.40","0.002"],["62063.90","1.383"],["63874.10","34.048"],["64003.40","0.001"],["64020.40","0.689"],["64297.30","0.018"],["64326.60","3.887"],["64378.40","0.000"],["64381.60","0.117"],["64421.30","0.828"],["64495.50","1.580"],["64564.50","0.002"],["64608.90","0.012"],["64615.40","0.145"],["64621.40","0.352"],["64621.90","0.000"],["64627.90","0.077"],["64634.30","0.366"],["64636.20","0.522"],["64640.80","0.121"],["64643.30","0.064"],["64643.40","0.005"],["64644.30","0.234"],["64645.10","0.219"],["64645.20","3.043"],["64645.30","1.070"],["64647.20","1.443"],["64647.30","2.155"],["64649.60","0.853"],["64649.90","7.975"]],"a":[["64650.00","3.336"],["64654.60","0.003"],["64655.40","0.000"],["64655.70","0.002"],["64655.90","0.033"],["64656.00","0.055"],["64656.50","0.018"],["64656.60","0.741"],["64657.60","0.124"],["64659.80","0.722"],["64661.10","0.177"],["64662.90","0.004"],["64663.00","0.028"],["64667.60","0.001"],["64668.70","0.005"],["64801.70","1.349"],["65296.50","0.032"],["65419.30","8.247"],["65425.80","31.099"],["65555.10","19.956"]],"st":1}}
{"stream":"btcusdt@depth@100ms","data":{"e":"depthUpdate","E":1784410672084,"T":1784410672082,"s":"BTCUSDT","ps":"BTCUSDT","U":11079105149169,"u":11079105154744,"pu":11079105149107,"b":[["14249.90","0.602"],["14349.90","1.988"],["14449.90","0.714"],["14549.90","0.896"],["58184.90","0.002"],["61417.40","0.002"],["61417.50","0.011"],["62063.90","1.380"],["63635.10","0.013"],["64003.40","0.001"],["64326.70","0.934"],["64495.50","1.582"],["64599.70","0.001"],["64608.20","0.025"],["64633.00","0.061"],["64635.20","0.002"],["64636.30","0.715"],["64638.30","0.626"]],"a":[["64656.40","0.001"],["64656.50","0.723"],["64656.60","0.154"],["64659.80","0.017"],["64662.90","0.001"],["64663.00","0.032"],["64681.50","1.950"],["64801.70","1.349"],["65296.50","0.032"],["65664.80","0.783"]],"st":1}}
{"stream":"btcusdt@depth@100ms","data":{"e":"depthUpdate","E":1784410672186,"T":1784410672185,"s":"BTCUSDT","ps":"BTCUSDT","U":11079105154922,"u":11079105160424,"pu":11079105154744,"b":[["1000.00","50.241"],["14249.90","0.714"],["14349.90","2.002"],["14449.90","0.714"],["14549.90","0.770"],["51719.90","0.000"],["58184.90","0.002"],["61417.40","0.002"],["61417.50","0.013"],["62063.90","1.383"],["63635.10","0.024"],["63647.80","12.079"],["63841.80","10.134"],["63854.20","2.057"],["63918.00","3.127"],["63954.30","0.186"],["64003.40","0.001"],["64421.30","0.833"],["64598.80","3.369"],["64609.50","0.002"],["64633.00","0.215"]],"a":[["64656.40","0.001"],["64656.50","0.018"],["64656.60","0.154"],["64659.80","0.722"],["64679.70","0.067"],["64681.50","1.950"],["65296.50","0.032"],["65381.90","6.646"],["65451.00","0.004"],["65535.70","3.195"],["65736.10","0.578"]],"st":1}}
{"stream":"btcusdt@depth@100ms","data":{"e":"depthUpdate","E":1784410672288,"T":1784410672286,"s":"BTCUSDT","ps":"BTCUSDT","U":11079105160538,"u":11079105165215,"pu":11079105160424,"b":[["14249.90","0.868"],["14349.90","1.932"],["14449.90","0.742"],["14549.90","0.658"],["58184.90","0.002"],["61417.40","0.002"],["62063.90","1.380"],["64003.40","0.001"],["64567.10","0.017"],["64633.00","0.215"]],"a":[["64650.00","3.308"],["64656.40","0.001"],["64656.50","0.018"],["64656.60","0.154"],["64659.80","0.722"],["64681.50","2.027"],["65296.50","0.032"],["65477.20","0.616"],["65664.80","0.794"]],"st":1}}
{"stream":"btcusdt@depth@100ms","data":{"e":"depthUpdate","E":1784410672390,"T":1784410672389,"s":"BTCUSDT","ps":"BTCUSDT","U":11079105165295,"u":11079105171348,"pu":11079105165215,"b":[["1000.00","50.241"],["14249.90","1.106"],["14349.90","1.694"],["14449.90","0.868"],["14549.90","0.532"],["58184.90","0.002"],["61417.40","0.002"],["63801.30","5.898"],["64003.40","0.001"],["64297.30","0.023"],["64326.70","0.944"],["64495.50","1.589"],["64567.10","0.017"],["64617.50","2.207"],["64633.20","0.008"],["64633.80","4.632"],["64634.30","0.366"],["64635.20","0.559"],["64636.30","0.158"],["64649.90","7.948"]],"a":[["64650.00","3.303"],["64655.90","0.080"],["64656.00","0.008"],["64656.40","0.001"],["64656.50","0.018"],["64656.60","0.154"],["64659.50","0.184"],["64659.80","0.722"],["64662.90","0.004"],["64663.00","0.028"],["64669.10","0.004"],["64669.20","0.050"],["64669.30","0.312"],["64682.40","0.008"],["64685.50","0.021"],["64685.60","0.013"],["64685.70","0.123"],["64686.00","0.019"],["64686.10","0.052"],["64686.20","0.116"],["64801.70","1.349"],["65041.70","0.350"],["65041.80","0.000"],["65296.50","0.032"],["65942.90","0.654"]],"st":1}}
{"stream":"btcusdt@depth@100ms","data":{"e":"depthUpdate","E":1784410672492,"T":1784410672491,"s":"BTCUSDT","ps":"BTCUSDT","U":11079105171507,"u":11079105176741,"pu":11079105171348,"b":[["1000.00","50.241"],["14249.90","1.344"],["14349.90","1.456"],["14449.90","0.980"],["14549.90","0.420"],["58184.90","0.002"],["61417.40","0.002"],["62063.90","1.383"],["63551.70","0.000"],["64003.40","0.001"],["64567.10","0.013"],["64625.80","2.239"]],"a":[["64650.00","3.331"],["64656.20","0.157"],["64656.30","0.062"],["64656.40","0.001"],["64656.50","0.018"],["64656.60","0.154"],["64659.80","0.541"],["64662.90","0.001"],["64663.00","0.032"],["64681.50","1.950"],["65296.50","0.032"],["65549.30","29.447"],["65942.90","0.654"]],"st":1}}
{"stream":"btcusdt@depth@100ms","data":{"e":"depthUpdate","E":1784410672594,"T":1784410672593,"s":"BTCUSDT","ps":"BTCUSDT","U":11079105176800,"u":11079105181847,"pu":11079105176741,"b":[["14249.90","1.582"],["14349.90","1.218"],["14449.90","1.106"],["14549.90","0.294"],["58184.90","0.002"],["61417.40","0.002"],["62063.90","1.380"],["63854.30","0.000"],["64003.40","0.001"],["64452.70","0.000"],["64485.00","0.158"],["64488.30","0.037"],["64550.70","0.001"],["64559.90","0.005"],["64633.00","0.061"],["64633.40","0.116"],["64633.80","4.516"],["64635.20","0.002"],["64635.40","0.047"],["64635.90","0.754"],["64636.20","1.448"],["64636.80","0.016"],["64637.10","0.177"],["64639.80","1.205"]],"a":[["64651.60","0.001"],["64651.80","0.001"],["64652.60","0.003"],["64652.70","0.001"],["64652.90","0.000"],["64653.10","0.001"],["64655.10","0.635"],["64656.20","0.003"],["64656.30","0.035"],["64656.40","0.001"],["64656.50","0.018"],["64656.60","0.154"],["64657.60","0.281"],["64659.70","0.046"],["64659.80","0.705"],["64666.40","0.543"],["64666.50","0.001"],["64668.70","0.005"],["64668.90","0.000"],["64669.60","0.926"],["64676.30","0.246"],["64677.00","0.559"],["65296.50","0.032"],["65458.10","11.374"],["65547.60","8.142"]],"st":1}}
{"stream":"btcusdt@depth@100ms","data":{"e":"depthUpdate","E":1784410672696,"T":1784410672695,"s":"BTCUSDT","ps":"BTCUSDT","U":11079105181925,"u":11079105188445,"pu":11079105181847,"b":[["1000.00","50.241"],["14249.90","1.820"],["14349.90","0.980"],["14449.90","1.218"],["14549.90","0.182"],["51720.00","0.008"],["58184.90","0.002"],["61417.40","0.014"],["62063.90","1.383"],["63871.60","0.940"],["64003.40","0.001"],["64326.70","0.944"],["64633.00","0.215"]],"a":[["64655.10","0.048"],["64656.50","0.723"],["64656.60","0.154"],["64659.80","0.000"],["65296.50","0.032"],["65522.80","6.546"],["65568.00","1.614"],["65575.80","1.075"],["65619.80","3.108"]],"st":1}}
{"stream":"btcusdt@depth@100ms","data":{"e":"depthUpdate","E":1784410672798,"T":1784410672797,"s":"BTCUSDT","ps":"BTCUSDT","U":11079105188494,"u":11079105193614,"pu":11079105188445,"b":[["1000.00","50.241"],["14149.90","0.028"],["14249.90","2.002"],["14349.90","0.770"],["14449.90","1.344"],["14549.90","0.056"],["58184.90","0.002"],["61417.40","0.004"],["63492.70","0.499"],["63960.50","2.638"],["64003.40","0.001"],["64488.30","0.193"],["64553.70","0.000"],["64633.00","0.061"]],"a":[["64655.10","0.048"],["64656.50","0.723"],["64656.60","0.154"],["64657.60","0.124"],["64659.80","0.000"],["64742.90","0.356"],["64745.30","0.002"],["65296.50","0.032"],["65483.30","0.770"],["65555.10","22.241"],["66609.10","2.569"]],"st":1}}
{"stream":"btcusdt@depth@100ms","data":{"e":"depthUpdate","E":1784410672900,"T":1784410672898,"s":"BTCUSDT","ps":"BTCUSDT","U":11079105193695,"u":11079105198895,"pu":11079105193614,"b":[["14149.90","0.154"],["14249.90","1.988"],["14349.90","0.714"],["14449.90","1.344"],["14549.90","0.000"],["58184.90","0.002"],["61417.50","0.011"],["62063.90","1.380"],["64003.40","0.000"],["64326.60","3.885"],["64495.50","1.589"],["64553.60","4.531"],["64585.30","0.132"],["64633.00","0.061"],["64649.90","8.007"]],"a":[["64650.00","3.165"],["64656.50","0.018"],["64656.60","0.741"],["64657.60","0.124"],["64659.80","0.705"],["64660.30","0.002"],["64660.50","0.050"],["64681.50","2.027"],["64693.00","0.044"],["64700.60","0.015"],["64742.90","0.836"],["64745.10","3.534"],["64801.70","1.268"],["65296.50","0.032"],["65419.30","7.331"]],"st":1}}
{"stream":"btcusdt@depth@100ms","data":{"e":"depthUpdate","E":1784410673002,"T":1784410673001,"s":"BTCUSDT","ps":"BTCUSDT","U":11079105199021,"u":11079105204433,"pu":11079105198895,"b":[["1000.00","50.241"],["14149.90","0.266"],["14249.90","2.002"],["14349.90","0.714"],["14449.90","1.218"],["58184.90","0.002"],["61417.40","0.006"],["62063.90","1.383"],["63782.80","0.000"],["63880.60","7.504"],["64003.40","0.002"],["64089.90","0.027"],["64326.70","0.944"],["64495.50","1.591"],["64622.80","0.310"],["64629.20","0.163"],["64635.70","0.077"],["64636.20","1.446"]],"a":[["64650.00","3.166"],["64650.80","0.000"],["64650.90","0.000"],["64651.10","0.000"],["64651.30","0.002"],["64651.40","0.000"],["64651.60","0.001"],["64651.80","0.001"],["64652.00","0.005"],["64652.20","0.002"],["64652.40","0.003"],["64652.60","0.003"],["64652.80","0.002"],["64653.00","0.000"],["64653.50","0.077"],["64656.30","0.035"],["64656.40","0.001"],["64656.50","0.018"],["64656.60","0.154"],["64659.80","0.705"],["64660.00","0.255"],["64660.30","0.003"],["64660.50","0.049"],["64666.40","0.002"],["64666.50","0.851"],["64668.70","0.003"],["64681.50","1.950"],["64778.30","0.100"],["64801.70","1.297"],["64973.30","1.694"],["65296.50","0.032"],["65588.80","0.170"],["65942.90","0.651"]],"st":1}}
{"stream":"btcusdt@depth@100ms","data":{"e":"depthUpdate","E":1784410673104,"T":1784410673101,"s":"BTCUSDT","ps":"BTCUSDT","U":11079105204477,"u":11079105210649,"pu":11079105204433,"b":[["1000.00","50.241"],["14149.90","0.392"],["14249.90","1.988"],["14349.90","0.714"],["14449.90","1.106"],["51720.00","0.004"],["58175.10","0.000"],["58184.90","0.002"],["61417.40","0.006"],["61417.50","0.009"],["62063.90","1.380"],["63383.40","0.000"],["63886.60","4.989"],["63938.80","1.170"],["64003.40","0.000"],["64636.20","1.448"],["64638.30","0.626"],["64649.90","8.080"]],"a":[["64655.90","0.033"],["64656.50","0.770"],["64656.60","0.154"],["64657.60","0.124"],["64659.80","0.000"],["64668.70","0.005"],["64681.50","1.950"],["65296.50","0.032"],["65419.30","8.247"]],"st":1}}
{"stream":"btcusdt@depth@100ms","data":{"e":"depthUpdate","E":1784410673206,"T":1784410673205,"s":"BTCUSDT","ps":"BTCUSDT","U":11079105210892,"u":11079105216932,"pu":11079105210649,"b":[["14149.90","0.504"],["14249.90","2.002"],["14349.90","0.714"],["14449.90","0.980"],["51719.90","0.000"],["58184.90","0.002"],["61417.40","0.026"],["61417.50","0.007"],["62063.90","1.383"],["63828.10","0.001"],["64003.40","0.000"],["64536.90","0.694"],["64562.70","2.387"],["64562.80","1.669"],["64633.00","0.215"],["64649.90","8.082"]],"a":[["64656.40","0.001"],["64656.50","0.770"],["64656.60","0.154"],["64659.80","0.000"],["64681.50","2.027"],["64710.60","4.249"],["65296.50","0.032"]],"st":1}}
{"stream":"btcusdt@depth@100ms","data":{"e":"depthUpdate","E":1784410673308,"T":1784410673305,"s":"BTCUSDT","ps":"BTCUSDT","U":11079105217109,"u":11079105222368,"pu":11079105216932,"b":[["1000.00","50.241"],["14149.90","0.630"],["14249.90","1.988"],["14349.90","0.714"],["14449.90","0.868"],["51720.00","0.004"],["58184.90","0.002"],["61417.40","0.006"],["63324.60","2.365"],["63357.00","0.005"],["63698.50","0.002"],["64003.40","0.001"],["64068.10","0.468"],["64326.70","0.944"],["64495.50","0.704"],["64600.00","1.038"],["64633.00","0.061"]],"a":[["64656.50","0.065"],["64656.60","0.741"],["64659.80","0.705"],["64681.50","1.950"],["64801.70","0.308"],["65296.50","0.032"],["65700.00","44.828"],["65942.90","0.651"]],"st":1}}
{"stream":"btcusdt@depth@100ms","data":{"e":"depthUpdate","E":1784410673410,"T":1784410673409,"s":"BTCUSDT","ps":"BTCUSDT","U":11079105222557,"u":11079105228380,"pu":11079105222368,"b":[["1000.00","50.241"],["14149.90","0.742"],["14249.90","2.002"],["14349.90","0.714"],["14449.90","0.742"],["34000.00","7.459"],["58184.90","0.002"],["61417.40","0.006"],["62063.90","1.380"],["63415.80","0.050"],["63440.90","2.155"],["63809.30","1.180"],["64003.40","0.001"],["64441.50","0.000"],["64478.40","0.000"],["64554.30","0.004"],["64559.90","0.001"],["64567.10","0.017"],["64581.20","0.001"],["64581.50","0.003"],["64581.80","6.000"],["64582.20","0.000"],["64582.50","0.001"],["64600.20","0.000"],["64600.50","0.002"],["64600.80","0.000"],["64601.20","0.000"],["64601.50","0.016"],["64615.70","0.000"],["64615.80","0.000"],["64615.90","0.012"],["64616.10","0.009"],["64616.40","0.311"],["64616.50","0.001"],["64617.00","0.327"],["64619.20","0.435"],["64619.30","0.016"],["64631.50","1.220"],["64632.30","0.004"],["64637.60","0.032"],["64637.70","0.007"],["64637.90","0.005"],["64638.20","0.048"],["64638.30","0.002"],["64638.50","0.212"],["64638.80","0.249"],["64638.90","0.752"],["64639.20","0.003"],["64639.50","0.121"],["64639.80","0.840"]],"a":[["64650.00","3.160"],["64655.90","0.001"],["64656.30","0.003"],["64656.40","0.001"],["64656.50","0.018"],["64656.60","0.589"],["64656.90","0.004"],["64657.20","0.002"],["64657.30","0.062"],["64657.60","0.064"],["64657.70","0.312"],["64657.90","0.181"],["64659.20","0.052"],["64659.80","0.705"],["64674.90","0.002"],["64675.30","0.001"],["64675.60","0.715"],["64675.90","0.975"],["64676.30","0.094"],["64678.40","3.625"],["64678.50","10.049"],["64679.10","0.117"],["64679.40","0.012"],["64679.50","0.373"],["64679.70","0.007"],["64679.80","0.120"],["64693.90","0.033"],["64694.30","0.000"],["64694.60","0.000"],["64694.90","0.000"],["64695.30","0.000"],["64818.90","0.000"],["64855.70","0.000"],["65034.50","0.350"],["65041.70","0.000"],["65296.50","0.032"]],"st":1}}
{"stream":"btcusdt@depth@100ms","data":{"e":"depthUpdate","E":1784410673512,"T":1784410673508,"s":"BTCUSDT","ps":"BTCUSDT","U":11079105228484,"u":11079105233481,"pu":11079105228380,"b":[["14149.90","0.924"],["14249.90","1.876"],["14349.90","0.770"],["14449.90","0.630"],["58184.90","0.002"],["61417.40","0.006"],["62063.90","1.383"],["63764.20","2.737"],["64003.40","0.001"],["64358.10","0.293"],["64378.40","0.117"],["64381.60","0.000"],["64422.90","0.289"],["64441.50","3.341"],["64441.60","1.951"],["64478.40","0.633"],["64487.70","0.291"],["64495.50","1.342"],["64537.40","0.000"],["64538.90","0.004"],["64540.40","1.478"],["64541.90","1.276"],["64543.40","1.276"],["64600.90","0.220"],["64601.50","0.077"],["64601.80","0.536"],["64602.10","0.093"],["64633.00","0.215"],["64638.20","0.204"],["64638.50","0.368"],["64638.90","1.132"],["64639.50","0.320"],["64639.80","0.914"],["64640.10","0.062"]],"a":[["64650.00","3.138"],["64656.00","0.040"],["64656.30","0.035"],["64656.60","0.681"],["64657.20","0.122"],["64657.30","0.094"],["64657.60","0.124"],["64657.90","0.241"],["64659.20","0.005"],["64659.70","0.046"],["64675.00","0.145"],["64675.30","0.033"],["64675.60","0.747"],["64676.30","0.126"],["64678.50","10.109"],["64679.10","0.237"],["64679.50","0.433"],["64679.80","0.180"],["64801.70","1.108"],["64818.80","0.693"],["64855.70","2.861"],["65040.00","0.567"],["65296.50","0.032"],["65614.70","0.916"]],"st":1}}
{"stream":"btcusdt@depth@100ms","data":{"e":"depthUpdate","E":1784410673614,"T":1784410673613,"s":"BTCUSDT","ps":"BTCUSDT","U":11079105233640,"u":11079105239894,"pu":11079105233481,"b":[["1000.00","50.241"],["14149.90","1.148"],["14249.90","1.652"],["14349.90","0.896"],["14449.90","0.504"],["58184.90","0.002"],["61417.40","0.006"],["62063.90","1.380"],["63356.90","4.491"],["63675.00","0.293"],["63824.90","2.345"],["64003.40","0.001"],["64293.30","0.294"],["64326.70","0.944"],["64423.10","0.043"],["64485.00","0.002"],["64638.40","0.519"],["64639.50","0.458"],["64644.50","0.196"]],"a":[["64656.60","0.154"],["64657.70","0.372"],["64659.10","0.004"],["64678.40","3.685"],["64679.50","0.493"],["65296.50","0.032"],["65458.10","11.632"],["65582.40","7.371"],["65942.90","0.651"]],"st":1}}
{"stream":"btcusdt@depth@100ms","data":{"e":"depthUpdate","E":1784410673716,"T":1784410673713,"s":"BTCUSDT","ps":"BTCUSDT","U":11079105240154,"u":11079105252644,"pu":11079105239894,"b":[["1000.00","50.241"],["14149.90","1.400"],["14249.90","1.400"],["14349.90","1.008"],["14449.90","0.392"],["58184.90","0.002"],["61417.40","0.006"],["63806.80","0.000"],["63841.80","10.368"],["63854.20","1.823"],["64003.40","0.001"],["64029.30","1.035"],["64293.90","0.042"],["64358.50","0.043"],["64485.00","0.158"],["64540.40","0.202"],["64541.90","0.000"],["64543.40","0.000"],["64551.80","0.000"],["64551.90","0.111"],["64564.50","0.002"],["64569.20","0.028"],["64570.90","0.182"],["64575.70","0.030"],["64580.50","2.603"],["64582.10","0.374"],["64585.40","1.345"],["64588.60","0.642"],["64595.00","1.265"],["64601.20","0.067"],["64619.10","0.001"],["64620.20","0.120"],["64622.60","0.002"],["64622.80","0.001"],["64623.70","1.039"],["64623.90","1.507"],["64624.10","0.000"],["64624.40","0.003"],["64626.60","0.053"],["64626.80","0.002"],["64627.40","0.585"],["64628.40","0.000"],["64628.90","0.005"],["64629.20","0.008"],["64629.70","0.031"],["64630.10","0.385"],["64631.40","1.272"],["64631.50","11.251"],["64632.30","0.003"],["64633.00","0.061"],["64633.40","0.000"],["64634.30","0.482"],["64634.70","0.092"],["64634.80","0.003"],["64635.70","0.000"],["64635.90","0.754"],["64637.00","0.394"],["64637.10","0.178"],["64637.50","0.048"],["64638.30","0.554"],["64638.80","0.399"],["64638.90","1.312"],["64639.20","0.070"],["64642.70","0.003"],["64644.30","0.002"],["64644.50","0.199"],["64644.60","0.000"],["64645.00","0.521"],["64647.50","0.000"],["64649.90","8.080"]],"a":[["64650.00","2.988"],["64653.50","0.000"],["64653.60","0.000"],["64656.60","0.741"],["64656.90","0.036"],["64657.30","0.214"],["64657.90","0.421"],["64659.70","0.046"],["64659.80","0.798"],["64659.90","1.276"],["64660.00","0.007"],["64660.20","0.002"],["64660.30","0.002"],["64660.50","0.050"],["64661.40","0.032"],["64661.70","0.018"],["64661.90","0.312"],["64662.00","0.189"],["64662.20","0.018"],["64662.50","0.353"],["64662.60","0.320"],["64662.70","0.182"],["64662.80","0.002"],["64663.00","0.079"],["64664.00","0.002"],["64664.60","0.017"],["64665.40","0.386"],["64665.50","0.084"],["64665.70","0.597"],["64665.80","0.047"],["64666.50","0.542"],["64667.60","0.032"],["64668.00","0.002"],["64668.70","0.005"],["64669.30","0.343"],["64669.40","0.060"],["64670.60","0.008"],["64671.60","0.000"],["64672.30","0.002"],["64672.40","0.310"],["64672.90","0.001"],["64673.60","1.246"],["64675.90","1.045"],["64676.30","0.246"],["64678.40","2.136"],["64678.50","0.109"],["64679.70","0.067"],["64679.80","0.300"],["64680.10","1.296"],["64681.50","1.950"],["64683.30","0.386"],["64683.80","0.001"],["64685.80","0.062"],["64688.60","0.000"],["64692.60","0.117"],["64708.50","23.977"],["64710.60","0.692"],["64710.70","0.006"],["64790.50","0.000"],["64795.40","0.004"],["64799.10","0.005"],["64799.20","0.006"],["64801.20","0.001"],["64804.00","0.005"],["64807.10","0.001"],["64811.30","0.004"],["64811.60","0.005"],["65262.00","0.002"],["65264.30","0.000"],["65296.50","0.032"],["65587.40","21.279"]],"st":1}}
{"stream":"btcusdt@depth@100ms","data":{"e":"depthUpdate","E":1784410673818,"T":1784410673817,"s":"BTCUSDT","ps":"BTCUSDT","U":11079105252883,"u":11079105258617,"pu":11079105252644,"b":[["14149.90","1.638"],["14249.90","1.162"],["14349.90","1.134"],["14449.90","0.266"],["51720.00","0.004"],["58184.90","0.002"],["61417.40","0.006"],["62063.90","1.383"],["62710.40","2.452"],["63803.70","1.568"],["63841.80","10.758"],["63871.60","0.002"],["64003.40","0.003"],["64229.30","0.042"],["64281.30","0.000"],["64281.60","0.538"],["64320.00","0.443"],["64377.80","0.003"],["64380.60","1.643"],["64400.00","28.277"],["64448.70","0.017"],["64451.10","1.921"],["64480.00","4.367"],["64488.30","0.193"],["64500.00","5.497"],["64560.00","1.150"],["64564.50","0.002"],["64581.90","0.536"],["64582.50","0.062"],["64582.80","0.148"],["64583.10","0.061"],["64616.70","0.156"],["64617.00","0.483"],["64628.90","10.005"],["64631.50","1.251"],["64633.80","4.632"],["64634.30","0.366"],["64638.30","0.716"],["64638.90","1.450"],["64640.00","5.401"]],"a":[["64650.00","2.994"],["64655.10","0.048"],["64656.40","0.001"],["64656.50","0.018"],["64656.60","0.154"],["64657.20","0.182"],["64657.90","0.481"],["64659.50","0.175"],["64659.70","0.029"],["64659.80","0.815"],["64679.00","0.062"],["64679.70","0.127"],["64683.90","10.001"],["64694.00","2.200"],["64694.30","0.032"],["64694.60","0.032"],["64695.30","0.032"],["64708.50","0.002"],["64710.70","0.006"],["64712.90","23.958"],["64720.00","0.382"],["64800.00","18.466"],["64840.70","0.091"],["64849.00","4.786"],["64849.60","0.001"],["64880.00","9.538"],["64886.00","2.288"],["64919.40","0.991"],["64920.90","0.010"],["64960.00","2.262"],["65018.20","0.268"],["65018.30","0.000"],["65040.00","0.380"],["65250.00","9.179"],["65296.50","0.032"],["65942.90","0.648"]],"st":1}}
{"stream":"btcusdt@depth@100ms","data":{"e":"depthUpdate","E":1784410673920,"T":1784410673918,"s":"BTCUSDT","ps":"BTCUSDT","U":11079105258634,"u":11079105262770,"pu":11079105258617,"b":[["1000.00","50.241"],["14149.90","1.876"],["14249.90","0.924"],["14349.90","1.246"],["14449.90","0.154"],["58184.90","0.002"],["61417.40","0.006"],["62063.90","1.380"],["62710.40","2.309"],["63918.00","3.908"],["64003.40","0.001"],["64250.20","4.321"],["64264.10","9.072"],["64281.40","0.096"],["64326.70","0.944"],["64442.50","0.216"],["64448.80","0.001"],["64616.40","0.467"],["64616.70","0.312"],["64617.10","0.307"],["64617.60","1.326"],["64633.00","0.215"],["64644.50","0.431"],["64645.00","0.289"]],"a":[["64655.10","0.048"],["64656.60","0.311"],["64657.60","0.437"],["64681.50","2.027"],["64710.70","23.962"],["64712.90","0.002"],["64849.50","0.004"],["64849.90","0.216"],["65296.50","0.032"],["65414.20","1.527"]],"st":1}}
{"stream":"btcusdt@depth@100ms","data":{"e":"depthUpdate","E":1784410674022,"T":1784410674021,"s":"BTCUSDT","ps":"BTCUSDT","U":11079105262835,"u":11079105266731,"pu":11079105262770,"b":[["1000.00","50.241"],["14149.90","2.002"],["14249.90","0.742"],["14349.90","1.372"],["14449.90","0.028"],["14549.90","0.056"],["51720.00","0.004"],["58184.90","0.002"],["61417.40","0.006"],["62063.90","1.383"],["63868.60","0.001"],["64003.40","0.001"],["64018.30","0.003"],["64165.80","0.000"],["64326.60","3.887"],["64536.60","2.320"],["64536.80","0.001"],["64536.90","0.243"],["64582.20","0.067"],["64616.50","0.121"],["64617.70","0.139"],["64633.00","0.061"],["64636.20","1.446"],["64646.60","0.002"],["64647.50","0.022"]],"a":[["64655.10","0.635"],["64656.40","0.001"],["64656.50","0.018"],["64656.60","0.154"],["64657.60","0.124"],["64657.80","0.002"],["64659.80","0.815"],["64666.50","0.001"],["64668.70","0.544"],["64672.50","0.088"],["64681.50","1.950"],["64694.90","0.032"],["64753.20","0.000"],["64757.30","2.321"],["64973.30","1.692"],["64995.40","0.614"],["65135.40","0.033"],["65285.20","1.058"],["65296.50","0.032"],["65458.10","11.891"],["65942.90","0.651"]],"st":1}}
{"stream":"btcusdt@depth@100ms","data":{"e":"depthUpdate","E":1784410674124,"T":1784410674123,"s":"BTCUSDT","ps":"BTCUSDT","U":11079105266781,"u":11079105274231,"pu":11079105266731,"b":[["14149.90","1.988"],["14249.90","0.714"],["14349.90","1.316"],["14449.90","0.000"],["14549.90","0.182"],["58184.90","0.002"],["61417.40","0.006"],["61417.50","0.009"],["62063.90","1.380"],["63550.90","9.297"],["63777.10","5.941"],["63826.20","0.000"],["63880.60","8.442"],["64003.40","0.001"],["64567.10","0.013"],["64616.40","0.641"],["64616.50","0.661"],["64619.80","0.150"],["64619.90","0.180"],["64633.00","0.215"],["64633.80","4.516"],["64635.00","0.398"],["64636.20","1.448"],["64638.30","0.716"]],"a":[["64655.10","0.048"],["64656.50","0.182"],["64656.60","0.154"],["64659.80","0.651"],["64668.70","0.546"],["65296.50","0.032"],["65481.00","0.000"]],"st":1}}
{"stream":"btcusdt@depth@100ms","data":{"e":"depthUpdate","E":1784410674226,"T":1784410674225,"s":"BTCUSDT","ps":"BTCUSDT","U":11079105274308,"u":11079105279952,"pu":11079105274231,"b":[["1000.00","50.241"],["14149.90","2.002"],["14249.90","0.714"],["14349.90","1.190"],["14549.90","0.294"],["51719.90","0.000"],["51720.00","0.004"],["58184.90","0.002"],["61417.40","0.016"],["63777.10","6.723"],["64003.40","0.001"],["64320.00","0.460"],["64326.70","0.944"],["64400.00","28.294"],["64480.00","4.384"],["64536.70","0.450"],["64560.00","1.167"],["64617.10","0.445"],["64622.50","0.045"],["64629.00","0.002"],["64635.50","0.859"],["64640.00","5.418"],["64649.90","8.068"]],"a":[["64650.00","2.994"],["64653.50","0.000"],["64656.40","1.290"],["64656.50","0.038"],["64656.60","0.154"],["64657.80","0.002"],["64659.70","0.029"],["64659.80","0.093"],["64660.00","0.007"],["64660.20","0.002"],["64662.20","0.574"],["64666.50","0.001"],["64669.00","0.001"],["64669.10","0.002"],["64669.20","0.048"],["64669.30","0.341"],["64675.90","1.060"],["64681.50","2.027"],["64685.50","0.019"],["64685.60","0.011"],["64685.70","0.121"],["64686.00","0.017"],["64686.10","0.050"],["64686.20","0.114"],["64710.60","4.260"],["64714.30","0.000"],["64720.00","0.399"],["64721.10","0.030"],["64755.50","0.523"],["64800.00","18.483"],["64880.00","9.555"],["64960.00","2.279"],["65040.00","0.397"],["65296.50","0.032"],["65942.90","0.654"]],"st":1}}
{"stream":"btcusdt@depth@100ms","data":{"e":"depthUpdate","E":1784410674328,"T":1784410674325,"s":"BTCUSDT","ps":"BTCUSDT","U":11079105280068,"u":11079105284795,"pu":11079105279952,"b":[["1000.00","50.241"],["14149.90","1.988"],["14249.90","0.714"],["14349.90","1.078"],["14549.90","0.420"],["58184.90","0.002"],["61417.40","0.006"],["62063.90","1.383"],["63841.80","11.023"],["63871.10","0.876"],["64003.40","0.000"],["64320.00","0.630"],["64326.70","1.061"],["64378.40","0.000"],["64400.00","28.464"],["64480.00","4.554"],["64560.00","1.337"],["64611.10","0.104"],["64640.00","5.588"]],"a":[["64653.70","0.594"],["64656.40","0.314"],["64656.50","1.053"],["64656.60","0.467"],["64657.20","0.495"],["64657.60","0.437"],["64657.80","0.002"],["64659.80","0.093"],["64660.00","0.007"],["64660.50","0.050"],["64663.00","0.079"],["64666.50","0.542"],["64668.70","0.005"],["64681.50","1.950"],["64720.00","0.569"],["64800.00","18.653"],["64880.00","9.725"],["64960.00","2.449"],["65040.00","0.567"],["65296.50","0.032"],["65381.90","5.960"],["65522.80","7.079"]],"st":1}}
{"stream":"btcusdt@depth@100ms","data":{"e":"depthUpdate","E":1784410674430,"T":1784410674429,"s":"BTCUSDT","ps":"BTCUSDT","U":11079105285006,"u":11079105289692,"pu":11079105284795,"b":[["14149.90","2.002"],["14249.90","0.714"],["14349.90","0.952"],["14549.90","0.532"],["51720.00","0.004"],["58184.90","0.002"],["61417.40","0.006"],["62063.90","1.380"],["62726.20","0.000"],["63874.10","33.267"],["64003.40","0.000"],["64326.70","1.051"],["64495.50","1.581"],["64617.60","1.316"],["64619.90","0.190"],["64633.00","0.061"],["64635.90","0.197"],["64636.50","0.558"],["64637.00","0.394"],["64642.60","0.002"],["64643.80","0.311"]],"a":[["64650.00","2.894"],["64652.20","0.589"],["64653.20","0.005"],["64653.70","0.007"],["64655.10","0.361"],["64656.40","0.001"],["64656.50","0.018"],["64656.60","0.467"],["64657.20","0.495"],["64657.60","0.437"],["64657.80","0.315"],["64659.80","0.815"],["64660.00","0.007"],["64660.50","0.050"],["64663.00","0.032"],["64665.70","0.644"],["64665.80","0.000"],["64666.50","0.001"],["64668.70","0.546"],["64681.50","2.027"],["64685.60","0.001"],["64686.60","0.143"],["64798.70","0.009"],["64801.70","1.293"],["65296.50","0.032"]],"st":1}}
{"stream":"btcusdt@depth@100ms","data":{"e":"depthUpdate","E":1784410674532,"T":1784410674531,"s":"BTCUSDT","ps":"BTCUSDT","U":11079105289705,"u":11079105294178,"pu":11079105289692,"b":[["1000.00","50.241"],["14149.90","1.988"],["14249.90","0.714"],["14349.90","0.840"],["14549.90","0.658"],["58184.90","0.002"],["61417.40","0.006"],["62063.90","1.383"],["63724.50","0.001"],["64003.40","0.000"],["64088.90","1.091"],["64326.70","1.061"],["64633.00","0.215"]],"a":[["64652.20","0.002"],["64653.20","0.014"],["64655.10","0.048"],["64656.40","0.855"],["64656.50","0.189"],["64656.60","0.278"],["64657.10","0.004"],["64657.20","0.182"],["64657.60","0.124"],["64657.80","0.002"],["64659.80","0.103"],["64659.90","1.277"],["64660.00","0.007"],["64660.50","0.049"],["64681.50","1.950"],["64798.70","0.000"],["65296.50","0.034"],["65354.70","2.061"],["65446.50","0.773"],["65491.50","0.000"],["65942.90","0.651"]],"st":1}}
{"stream":"btcusdt@depth@100ms","data":{"e":"depthUpdate","E":1784410674634,"T":1784410674633,"s":"BTCUSDT","ps":"BTCUSDT","U":11079105294200,"u":11079105299673,"pu":11079105294178,"b":[["1000.00","50.241"],["14149.90","2.002"],["14249.90","0.714"],["14349.90","0.714"],["14549.90","0.770"],["51720.00","0.004"],["58184.90","0.002"],["61417.40","0.006"],["62063.90","1.380"],["63706.00","1.181"],["64003.40","0.000"],["64517.80","3.878"],["64518.70","0.000"],["64579.10","0.046"],["64579.20","0.004"],["64635.60","0.372"],["64636.20","0.522"],["64636.50","0.001"],["64637.00","0.935"],["64637.10","0.735"],["64637.30","0.927"],["64638.10","0.002"],["64638.50","0.368"],["64638.80","0.399"],["64639.80","1.347"],["64649.90","7.916"]],"a":[["64650.00","2.876"],["64652.50","0.002"],["64653.20","0.005"],["64653.40","0.324"],["64653.70","0.007"],["64656.20","0.001"],["64656.40","0.001"],["64656.50","0.018"],["64656.60","0.278"],["64657.60","0.124"],["64658.20","0.054"],["64659.80","0.815"],["64659.90","1.276"],["64660.00","0.007"],["64660.50","0.050"],["64662.40","0.007"],["64662.60","0.320"],["64662.80","0.002"],["64662.90","0.048"],["64669.60","0.000"],["64670.90","0.926"],["64677.00","0.002"],["64677.70","0.003"],["64678.40","2.692"],["64721.40","0.046"],["64721.50","0.001"],["64773.90","3.867"],["64774.00","0.000"],["64798.70","0.009"],["65296.50","0.032"],["65942.90","0.648"]],"st":1}}
{"stream":"btcusdt@depth@100ms","data":{"e":"depthUpdate","E":1784410674736,"T":1784410674735,"s":"BTCUSDT","ps":"BTCUSDT","U":11079105299741,"u":11079105305174,"pu":11079105299673,"b":[["14149.90","1.820"],["14249.90","0.798"],["14349.90","0.602"],["14549.90","0.980"],["58184.90","0.002"],["61417.40","0.006"],["61417.50","0.007"],["63698.70","1.450"],["63874.10","34.048"],["64003.40","0.000"],["64016.50","60.168"],["64068.00","3.506"],["64164.10","49.198"],["64326.70","1.061"],["64346.70","0.706"],["64485.00","0.002"],["64518.10","1.173"],["64521.50","0.890"],["64530.90","0.077"],["64595.50","0.043"],["64595.60","0.013"],["64627.90","0.077"],["64633.00","0.061"],["64643.40","0.007"],["64649.90","7.916"]],"a":[["64653.70","0.594"],["64656.40","0.018"],["64656.50","0.485"],["64656.60","0.278"],["64657.60","0.437"],["64658.20","0.007"],["64658.30","0.004"],["64658.60","0.000"],["64658.80","0.001"],["64659.00","0.313"],["64659.10","0.003"],["64659.30","0.003"],["64659.60","0.003"],["64659.70","0.029"],["64659.80","0.644"],["64659.90","1.323"],["64660.00","0.008"],["64660.50","0.049"],["64666.10","0.001"],["64666.20","0.311"],["64666.50","0.001"],["64668.70","0.546"],["64669.20","0.974"],["64670.90","0.000"],["64681.50","1.950"],["64688.80","0.007"],["64721.10","0.030"],["64785.70","0.091"],["64785.80","0.043"],["65296.50","0.032"],["65515.70","0.762"]],"st":1}}
{"stream":"btcusdt@depth@100ms","data":{"e":"depthUpdate","E":1784410674838,"T":1784410674837,"s":"BTCUSDT","ps":"BTCUSDT","U":11079105305209,"u":11079105309230,"pu":11079105305174,"b":[["1000.00","50.241"],["14149.90","1.582"],["14249.90","0.924"],["14349.90","0.476"],["14549.90","1.218"],["51720.00","0.004"],["58184.90","0.002"],["61417.40","0.006"],["62063.90","1.383"],["63824.40","76.916"],["63874.10","34.314"],["64003.40","0.000"],["64495.50","1.589"],["64633.00","0.215"]],"a":[["64650.00","2.880"],["64653.70","0.007"],["64656.40","0.001"],["64656.50","0.018"],["64657.60","0.124"],["64659.70","0.210"],["64659.80","0.634"],["64659.90","1.276"],["64660.00","0.007"],["64660.50","0.050"],["64681.50","2.027"],["64801.70","1.345"],["65135.20","49.981"],["65285.00","62.593"],["65296.50","0.032"],["65480.80","79.571"],["65561.60","4.720"]],"st":1}}
{"stream":"btcusdt@depth@100ms","data":{"e":"depthUpdate","E":1784410674940,"T":1784410674939,"s":"BTCUSDT","ps":"BTCUSDT","U":11079105309266,"u":11079105314043,"pu":11079105309230,"b":[["1000.00","50.241"],["14149.90","1.344"],["14249.90","1.036"],["14349.90","0.364"],["14549.90","1.456"],["58184.90","0.002"],["61417.40","0.010"],["62063.90","1.380"],["63680.20","5.920"],["64003.40","0.000"],["64643.40","0.005"]],"a":[["64650.00","2.818"],["64653.40","0.014"],["64655.10","0.048"],["64656.50","0.569"],["64657.60","0.124"],["64659.70","0.200"],["64659.80","0.093"],["64660.00","0.007"],["64660.50","0.050"],["64662.90","0.001"],["65296.50","0.034"]],"st":1}}
{"stream":"btcusdt@depth@100ms","data":{"e":"depthUpdate","E":1784410675042,"T":1784410675040,"s":"BTCUSDT","ps":"BTCUSDT","U":11079105314092,"u":11079105318697,"pu":11079105314043,"b":[["14149.90","1.106"],["14249.90","1.162"],["14349.90","0.238"],["14549.90","1.694"],["58184.90","0.002"],["62063.90","1.383"],["63824.40","0.000"],["64003.40","0.000"],["64016.50","0.006"],["64164.10","0.000"],["64326.60","3.885"],["64326.70","1.061"],["64633.00","0.061"],["64638.30","0.721"]],"a":[["64655.10","0.635"],["64656.40","0.001"],["64656.50","0.018"],["64656.60","0.435"],["64657.60","0.281"],["64659.70","0.046"],["64659.80","0.798"],["64681.50","1.950"],["65135.20","0.000"],["65285.00","0.203"],["65296.50","0.032"],["65480.80","0.031"]],"st":1}}
{"stream":"btcusdt@depth@100ms","data":{"e":"depthUpdate","E":1784410675144,"T":1784410675141,"s":"BTCUSDT","ps":"BTCUSDT","U":11079105318776,"u":11079105323352,"pu":11079105318697,"b":[["1000.00","50.241"],["14149.90","0.868"],["14249.90","1.274"],["14349.90","0.126"],["14549.90","1.932"],["58184.90","0.002"],["61417.40","0.010"],["61417.50","0.003"],["63874.10","33.690"],["64003.40","0.000"],["64633.00","0.215"],["64636.20","0.522"],["64638.30","0.716"]],"a":[["64655.10","0.635"],["64656.60","0.278"],["64668.70","0.546"],["64677.10","0.596"],["64678.40","2.136"],["64973.30","1.694"],["65296.50","0.032"],["67896.00","0.330"]],"st":1}}
{"stream":"btcusdt@depth@100ms","data":{"e":"depthUpdate","E":1784410675246,"T":1784410675244,"s":"BTCUSDT","ps":"BTCUSDT","U":11079105323593,"u":11079105329228,"pu":11079105323352,"b":[["1000.00","50.241"],["14149.90","0.714"],["14249.90","1.400"],["14349.90","0.000"],["14449.90","0.084"],["14549.90","2.002"],["51719.90","0.000"],["58184.90","0.002"],["61417.40","0.010"],["62063.90","1.380"],["63803.70","0.786"],["63874.10","34.314"],["64003.40","0.000"],["64349.90","0.051"],["64441.50","0.000"],["64478.40","0.000"],["64495.50","0.704"],["64616.20","0.002"],["64622.60","0.002"],["64626.50","10.575"],["64628.90","0.005"],["64629.00","0.002"],["64630.10","0.385"],["64635.50","0.859"],["64636.50","0.558"],["64637.10","0.178"],["64644.20","0.575"],["64646.50","0.125"],["64649.90","7.887"]],"a":[["64650.00","2.818"],["64653.50","0.000"],["64653.60","0.310"],["64655.10","0.048"],["64656.40","0.706"],["64656.50","0.018"],["64657.60","0.124"],["64658.20","0.007"],["64658.50","0.047"],["64659.80","0.093"],["64660.00","0.007"],["64662.40","0.054"],["64666.50","0.001"],["64669.00","0.016"],["64675.90","1.045"],["64682.90","1.836"],["64714.20","0.016"],["64721.10","0.015"],["64801.70","0.308"],["64818.80","0.004"],["64855.70","0.000"],["65296.50","0.032"],["65711.70","0.011"]],"st":1}}
{"stream":"btcusdt@depth@100ms","data":{"e":"depthUpdate","E":1784410675348,"T":1784410675347,"s":"BTCUSDT","ps":"BTCUSDT","U":11079105329443,"u":11079105334438,"pu":11079105329228,"b":[["14149.90","0.714"],["14249.90","1.288"],["14449.90","0.210"],["14549.90","1.988"],["51720.00","0.004"],["58184.90","0.002"],["61417.40","0.010"],["62063.90","1.383"],["63788.70","1.565"],["64003.40","0.000"],["64062.40","8.302"],["64279.80","40.754"],["64281.60","6.500"],["64326.70","0.944"],["64376.30","32.573"],["64376.80","7.779"],["64378.40","0.117"],["64441.50","4.587"],["64447.20","25.382"],["64448.00","3.969"],["64478.40","0.907"],["64495.50","1.582"],["64537.40","1.276"],["64538.90","1.280"],["64540.40","1.478"],["64541.90","1.276"],["64633.00","0.061"],["64636.40","1.121"],["64637.30","0.001"],["64647.50","0.000"]],"a":[["64655.10","0.635"],["64656.40","0.001"],["64656.50","0.018"],["64656.60","0.154"],["64657.90","0.605"],["64658.50","0.000"],["64659.80","0.798"],["64666.40","0.543"],["64666.50","0.001"],["64668.70","0.005"],["64685.30","0.105"],["64692.60","0.027"],["64801.70","1.345"],["64818.80","0.889"],["64840.70","0.208"],["64849.00","7.874"],["64850.80","26.662"],["64855.70","3.487"],["64886.00","2.171"],["64922.20","32.619"],["65018.20","6.592"],["65019.60","42.844"],["65291.30","7.639"],["65296.50","0.032"],["65555.10","22.773"]],"st":1}}
{"stream":"btcusdt@depth@100ms","data":{"e":"depthUpdate","E":1784410675450,"T":1784410675449,"s":"BTCUSDT","ps":"BTCUSDT","U":11079105334491,"u":11079105339875,"pu":11079105334438,"b":[["1000.00","50.241"],["14149.90","0.714"],["14249.90","1.162"],["14449.90","0.322"],["14549.90","2.002"],["51720.00","0.004"],["58184.90","0.002"],["61417.40","0.008"],["61417.50","0.005"],["62063.90","1.380"],["63227.60","0.001"],["63809.50","3.366"],["63829.60","0.000"],["64003.40","0.001"],["64016.50","60.456"],["64485.00","0.158"],["64488.30","0.193"],["64537.40","0.000"],["64538.90","0.004"],["64540.40","0.000"],["64540.50","0.006"],["64585.30","0.131"],["64633.00","0.215"],["64647.60","0.023"]],"a":[["64655.10","0.048"],["64656.50","0.723"],["64657.60","0.124"],["64657.80","0.126"],["64657.90","0.481"],["64659.60","0.050"],["64659.80","0.093"],["64660.00","0.007"],["64660.50","0.050"],["64666.40","0.002"],["64668.60","0.544"],["64681.50","1.950"],["65286.40","66.409"],["65291.30","6.952"],["65296.50","0.032"],["65515.70","0.000"]],"st":1}}
{"stream":"btcusdt@depth@100ms","data":{"e":"depthUpdate","E":1784410675552,"T":1784410675549,"s":"BTCUSDT","ps":"BTCUSDT","U":11079105339913,"u":11079105343732,"pu":11079105339875,"b":[["1000.00","50.241"],["14149.90","0.714"],["14249.90","1.050"],["14449.90","0.448"],["14549.90","1.988"],["51720.00","0.004"],["58184.90","0.002"],["62063.90","1.383"],["63777.10","7.505"],["63841.80","11.257"],["64003.40","0.000"],["64164.10","50.054"],["64250.20","0.001"],["64264.10","12.528"],["64279.90","0.864"],["64442.50","0.000"],["64447.30","0.220"],["64495.50","0.704"],["64541.90","0.000"],["64585.30","0.132"],["64649.90","7.890"]],"a":[["64650.00","2.813"],["64656.40","0.001"],["64656.50","0.723"],["64656.60","0.154"],["64657.60","0.124"],["64659.60","0.003"],["64659.70","0.046"],["64659.80","0.093"],["64662.40","0.007"],["64662.70","0.229"],["64801.70","0.308"],["65136.60","51.002"],["65296.50","0.032"],["65587.40","20.214"],["65612.70","1.520"]],"st":1}}
{"stream":"btcusdt@depth@100ms","data":{"e":"depthUpdate","E":1784410675654,"T":1784410675653,"s":"BTCUSDT","ps":"BTCUSDT","U":11079105343869,"u":11079105347642,"pu":11079105343732,"b":[["14149.90","0.714"],["14249.90","0.924"],["14449.90","0.560"],["14549.90","2.002"],["58184.90","0.002"],["61417.40","0.008"],["63824.90","1.563"],["64003.40","0.000"],["64326.70","0.944"]],"a":[["64655.10","0.048"],["64656.40","0.001"],["64656.50","0.723"],["64656.60","0.154"],["64659.80","0.093"],["65264.20","4.509"],["65296.50","0.032"],["65942.90","0.651"]],"st":1}}
{"stream":"btcusdt@depth@100ms","data":{"e":"depthUpdate","E":1784410675756,"T":1784410675754,"s":"BTCUSDT","ps":"BTCUSDT","U":11079105347720,"u":11079105352761,"pu":11079105347642,"b":[["1000.00","50.241"],["14149.90","0.714"],["14249.90","0.812"],["14449.90","0.686"],["14549.90","1.988"],["58184.90","0.002"],["61417.40","0.008"],["62063.90","1.380"],["63809.40","1.485"],["64003.40","0.000"],["64349.90","0.051"],["64441.50","0.000"],["64478.40","0.000"],["64553.60","0.123"],["64633.00","0.061"],["64649.90","7.869"]],"a":[["64656.30","0.035"],["64656.40","0.001"],["64656.50","0.723"],["64656.60","0.154"],["64659.80","0.093"],["64742.90","0.356"],["64745.10","0.012"],["64818.80","0.004"],["64855.70","0.000"],["65264.20","5.196"],["65296.50","0.032"]],"st":1}}
{"stream":"btcusdt@depth@100ms","data":{"e":"depthUpdate","E":1784410675858,"T":1784410675857,"s":"BTCUSDT","ps":"BTCUSDT","U":11079105352972,"u":11079105357707,"pu":11079105352761,"b":[["1000.00","50.241"],["14149.90","0.714"],["14249.90","0.686"],["14449.90","0.798"],["14549.90","2.002"],["58184.90","0.002"],["61417.40","0.008"],["62063.90","1.383"],["63824.40","79.718"],["63874.10","35.096"],["64003.40","0.000"],["64441.50","2.792"],["64478.30","0.577"],["64495.50","1.268"],["64500.00","5.496"],["64513.20","0.000"],["64513.40","2.960"],["64515.10","0.345"],["64553.60","5.010"],["64633.00","0.215"],["64649.90","7.870"]],"a":[["64656.30","0.035"],["64656.40","0.001"],["64656.50","0.018"],["64656.60","0.741"],["64659.80","0.798"],["64745.00","3.939"],["64784.00","0.582"],["64785.20","0.000"],["64785.30","6.500"],["64801.70","0.956"],["64818.80","0.557"],["64855.70","2.043"],["65296.50","0.032"],["65482.30","82.668"],["65587.40","21.280"]],"st":1}}
{"stream":"btcusdt@depth@100ms","data":{"e":"depthUpdate","E":1784410675960,"T":1784410675958,"s":"BTCUSDT","ps":"BTCUSDT","U":11079105357752,"u":11079105362263,"pu":11079105357707,"b":[["14149.90","0.826"],["14249.90","0.574"],["14449.90","1.036"],["14549.90","1.764"],["58184.90","0.002"],["61417.40","0.008"],["62063.90","1.380"],["63880.60","9.380"],["64003.40","0.000"],["64326.70","0.944"],["64633.00","0.061"],["64649.90","7.752"]],"a":[["64650.00","2.817"],["64651.70","0.012"],["64656.20","0.588"],["64656.30","0.045"],["64656.40","0.001"],["64656.50","0.018"],["64656.60","0.154"],["64658.10","0.005"],["64658.30","0.004"],["64658.50","0.047"],["64659.70","0.029"],["64659.80","0.815"],["64697.60","0.033"],["64698.50","0.000"],["64705.70","0.074"],["64706.50","0.014"],["64742.90","0.898"],["65296.50","0.032"]],"st":1}}
{"stream":"btcusdt@depth@100ms","data":{"e":"depthUpdate","E":1784410676062,"T":1784410676061,"s":"BTCUSDT","ps":"BTCUSDT","U":11079105362336,"u":11079105367528,"pu":11079105362263,"b":[["1000.00","50.241"],["14149.90","0.952"],["14249.90","0.448"],["14449.90","1.274"],["14549.90","1.526"],["58184.90","0.002"],["61417.40","0.008"],["61417.50","0.007"],["62063.90","1.383"],["64003.40","0.000"],["64495.50","1.593"],["64567.10","0.017"],["64626.50","0.575"],["64638.30","0.716"],["64647.00","0.070"],["64649.90","7.107"]],"a":[["64650.00","2.817"],["64654.50","0.041"],["64655.40","0.000"],["64655.60","0.002"],["64656.20","0.001"],["64656.40","0.001"],["64656.50","0.018"],["64656.60","0.154"],["64658.50","0.000"],["64659.80","0.815"],["64679.90","2.583"],["64682.90","0.392"],["64683.90","0.001"],["64685.80","0.015"],["64698.90","0.008"],["64706.50","0.000"],["64707.70","4.332"],["64708.50","24.166"],["64710.60","0.692"],["64710.70","0.006"],["64801.70","1.267"],["65296.50","0.032"],["65942.90","0.657"]],"st":1}}
{"stream":"btcusdt@depth@100ms","data":{"e":"depthUpdate","E":1784410676164,"T":1784410676163,"s":"BTCUSDT","ps":"BTCUSDT","U":11079105367635,"u":11079105372287,"pu":11079105367528,"b":[["1000.00","50.241"],["14149.90","1.064"],["14249.90","0.336"],["14449.90","1.512"],["14549.90","1.288"],["58184.90","0.002"],["61417.40","0.008"],["61417.50","0.009"],["62690.80","2.049"],["64003.40","0.000"],["64132.70","7.779"],["64326.60","3.887"],["64458.50","0.065"],["64495.50","0.704"],["64564.50","0.006"],["64598.70","0.002"],["64598.80","0.000"],["64600.90","0.220"],["64601.30","0.464"],["64622.90","10.683"],["64633.00","0.215"],["64636.20","0.522"],["64647.00","0.380"],["64649.90","7.108"]],"a":[["64656.40","0.542"],["64656.50","0.018"],["64656.60","0.741"],["64659.80","0.274"],["64668.70","0.005"],["64681.50","2.027"],["64687.50","2.183"],["64694.00","0.035"],["64707.70","0.744"],["64708.50","0.002"],["64710.70","24.170"],["64801.70","0.308"],["64973.30","1.692"],["65296.50","0.032"]],"st":1}}
{"stream":"btcusdt@depth@100ms","data":{"e":"depthUpdate","E":1784410676266,"T":1784410676264,"s":"BTCUSDT","ps":"BTCUSDT","U":11079105372316,"u":11079105377129,"pu":11079105372287,"b":[["14149.90","1.190"],["14249.90","0.210"],["14449.90","1.750"],["14549.90","1.050"],["51719.90","0.000"],["51720.00","0.008"],["58184.90","0.002"],["62063.90","1.380"],["64003.40","0.001"],["64088.40","0.000"],["64326.70","0.944"],["64349.90","0.051"],["64455.90","0.041"],["64495.50","1.589"],["64515.10","0.704"],["64585.30","0.131"],["64598.70","22.284"],["64623.70","2.485"],["64646.60","0.033"],["64649.90","7.391"]],"a":[["64651.70","0.010"],["64653.50","0.587"],["64656.30","0.045"],["64656.40","0.001"],["64656.50","0.723"],["64656.60","0.741"],["64657.60","0.437"],["64659.70","0.029"],["64659.80","0.110"],["64660.00","0.008"],["64660.50","0.049"],["64662.70","0.182"],["64662.90","0.048"],["64681.50","1.950"],["64685.80","0.062"],["64801.70","1.267"],["65296.50","0.032"],["65495.90","0.267"]],"st":1}}
{"stream":"btcusdt@depth@100ms","data":{"e":"depthUpdate","E":1784410676368,"T":1784410676367,"s":"BTCUSDT","ps":"BTCUSDT","U":11079105377174,"u":11079105382214,"pu":11079105377129,"b":[["1000.00","50.391"],["14149.90","1.302"],["14249.90","0.098"],["14449.90","1.988"],["14549.90","0.812"],["51720.00","0.004"],["58184.90","0.002"],["62063.90","1.383"],["63733.90","0.003"],["64003.40","0.001"],["64279.80","0.000"],["64281.60","0.538"],["64326.70","1.061"],["64376.30","0.079"],["64376.80","0.022"],["64378.40","0.000"],["64447.20","0.000"],["64448.00","0.263"],["64458.50","0.061"],["64485.00","0.002"],["64564.50","0.002"],["64622.80","0.310"],["64629.20","0.163"],["64633.00","0.061"],["64635.70","0.077"],["64649.90","7.393"]],"a":[["64650.00","2.861"],["64653.20","0.014"],["64653.50","0.664"],["64656.30","0.045"],["64656.40","0.001"],["64656.50","0.175"],["64656.60","0.467"],["64657.20","0.463"],["64657.60","0.124"],["64657.80","0.002"],["64659.80","0.815"],["64660.00","0.162"],["64660.50","0.050"],["64662.00","0.189"],["64662.90","0.001"],["64666.50","0.310"],["64669.00","0.001"],["64669.10","0.004"],["64669.30","0.343"],["64675.70","0.015"],["64685.50","0.021"],["64685.60","0.003"],["64685.70","0.123"],["64686.00","0.019"],["64686.10","0.052"],["64686.20","0.116"],["64714.20","0.001"],["64721.00","0.015"],["64798.70","0.000"],["64840.70","0.091"],["64849.00","4.786"],["64850.80","0.139"],["64886.00","2.288"],["64922.20","0.010"],["65018.20","0.268"],["65019.60","0.243"],["65296.50","0.032"]],"st":1}}
{"stream":"btcusdt@depth@100ms","data":{"e":"depthUpdate","E":1784410676470,"T":1784410676468,"s":"BTCUSDT","ps":"BTCUSDT","U":11079105382264,"u":11079105387230,"pu":11079105382214,"b":[["1000.00","50.241"],["14149.90","1.372"],["14249.90","0.000"],["14349.90","0.112"],["14449.90","2.002"],["14549.90","0.714"],["58184.90","0.002"],["62063.90","1.380"],["63929.50","0.000"],["64003.40","0.001"],["64068.00","4.596"],["64250.20","4.321"],["64264.10","9.072"],["64279.90","0.000"],["64442.50","0.216"],["64447.30","0.004"],["64485.00","0.158"],["64488.30","0.037"],["64553.60","0.123"],["64622.80","0.001"],["64629.20","0.008"],["64633.00","0.215"],["64635.70","0.000"],["64649.90","7.022"]],"a":[["64650.00","2.858"],["64653.20","0.005"],["64653.50","0.000"],["64656.30","0.045"],["64656.40","0.001"],["64657.20","0.306"],["64658.80","0.001"],["64659.10","0.003"],["64659.80","0.815"],["64660.00","0.008"],["64660.50","0.049"],["64661.90","0.312"],["64662.10","0.051"],["64666.50","0.001"],["64669.20","0.976"],["64742.90","0.356"],["64745.00","0.001"],["64798.70","0.009"],["65296.50","0.032"],["65942.90","0.660"]],"st":1}}
{"stream":"btcusdt@depth@100ms","data":{"e":"depthUpdate","E":1784410676572,"T":1784410676571,"s":"BTCUSDT","ps":"BTCUSDT","U":11079105387307,"u":11079105393175,"pu":11079105387230,"b":[["14149.90","1.260"],["14349.90","0.238"],["14449.90","1.988"],["14549.90","0.714"],["58184.90","0.002"],["61417.40","0.008"],["64003.40","0.001"],["64016.50","0.006"],["64164.10","0.000"],["64326.70","1.051"],["64421.30","0.828"],["64449.90","0.000"],["64488.30","0.193"],["64553.60","5.157"],["64585.30","0.132"],["64630.50","0.034"],["64633.00","0.215"],["64649.90","7.012"]],"a":[["64650.00","3.636"],["64653.70","0.007"],["64656.50","0.018"],["64656.60","0.154"],["64657.60","0.437"],["64659.10","0.050"],["64660.00","0.007"],["64660.50","0.050"],["64662.10","0.004"],["64662.90","0.048"],["64666.50","0.542"],["64668.60","0.003"],["64676.20","0.573"],["64677.10","0.039"],["64677.70","0.003"],["64708.50","24.223"],["64710.70","0.006"],["64714.60","0.002"],["64745.00","3.923"],["65136.60","0.000"],["65286.40","0.534"],["65296.50","0.032"],["65478.80","1.002"],["65612.30","7.611"]],"st":1}}
{"stream":"btcusdt@depth@100ms","data":{"e":"depthUpdate","E":1784410676674,"T":1784410676673,"s":"BTCUSDT","ps":"BTCUSDT","U":11079105393185,"u":11079105399675,"pu":11079105393175,"b":[["1000.00","50.241"],["14149.90","1.134"],["14349.90","0.350"],["14449.90","2.002"],["14549.90","0.714"],["51720.00","0.004"],["58184.90","0.002"],["61417.40","0.008"],["62063.90","1.383"],["63708.40","0.188"],["63726.10","5.728"],["63824.40","0.000"],["63920.10","2.188"],["64003.40","0.001"],["64297.30","0.018"],["64349.90","0.054"],["64615.10","0.386"],["64633.00","0.061"]],"a":[["64650.00","2.651"],["64653.50","0.587"],["64656.30","0.603"],["64656.40","0.001"],["64656.50","0.329"],["64656.60","0.467"],["64657.50","0.003"],["64657.60","0.437"],["64659.10","0.003"],["64659.30","0.050"],["64659.80","0.103"],["64660.00","0.007"],["64660.50","0.050"],["64666.50","0.001"],["64668.70","0.546"],["64676.20","0.016"],["64677.10","0.596"],["64708.50","0.002"],["64710.70","24.227"],["65296.50","0.032"],["65482.30","0.085"]],"st":1}}
{"stream":"btcusdt@depth@100ms","data":{"e":"depthUpdate","E":1784410676776,"T":1784410676773,"s":"BTCUSDT","ps":"BTCUSDT","U":11079105399692,"u":11079105403693,"pu":11079105399675,"b":[["14149.90","1.022"],["14349.90","0.476"],["14449.90","1.988"],["14549.90","0.714"],["58184.90","0.002"],["61417.40","0.008"],["62063.90","1.380"],["63698.70","1.059"],["63828.60","0.000"],["64003.40","0.001"],["64349.90","0.051"],["64633.00","0.215"]],"a":[["64650.00","2.858"],["64653.50","0.000"],["64656.30","0.045"],["64656.40","0.001"],["64656.50","0.723"],["64656.60","0.154"],["64657.60","0.124"],["64659.30","0.003"],["64659.70","0.029"],["64659.80","0.110"],["64660.00","0.007"],["64660.50","0.050"],["65296.50","0.032"],["65548.00","0.968"],["65587.40","21.394"],["65684.40","6.202"]],"st":1}}
{"stream":"btcusdt@depth@100ms","data":{"e":"depthUpdate","E":1784410676878,"T":1784410676877,"s":"BTCUSDT","ps":"BTCUSDT","U":11079105403838,"u":11079105407984,"pu":11079105403693,"b":[["14149.90","0.896"],["14349.90","0.588"],["14449.90","2.002"],["14549.90","0.714"],["58184.90","0.002"],["61417.40","0.008"],["62063.90","1.383"],["63699.50","4.232"],["63866.00","16.602"],["64003.40","0.001"],["64326.70","1.061"],["64421.30","0.833"],["64446.30","26.492"],["64537.40","0.000"],["64538.90","0.004"],["64540.40","0.000"],["64541.90","1.276"],["64633.00","0.061"],["64644.90","0.000"]],"a":[["64653.50","0.000"],["64656.40","0.542"],["64656.50","0.182"],["64656.60","0.154"],["64656.70","1.400"],["64657.20","0.182"],["64657.60","0.124"],["64659.20","0.005"],["64659.70","0.029"],["64659.80","0.110"],["64660.00","0.007"],["64660.10","0.048"],["64660.50","0.050"],["64666.50","0.001"],["64668.70","0.546"],["64840.70","0.208"],["64850.80","26.301"],["65296.50","0.032"],["65420.00","21.348"],["65488.00","0.884"]],"st":1}}
{"stream":"btcusdt@depth@100ms","data":{"e":"depthUpdate","E":1784410676980,"T":1784410676979,"s":"BTCUSDT","ps":"BTCUSDT","U":11079105408020,"u":11079105411936,"pu":11079105407984,"b":[["1000.00","50.391"],["14149.90","0.784"],["14349.90","0.714"],["14449.90","1.988"],["14549.90","0.714"],["56740.30","0.000"],["58184.90","0.002"],["61417.40","0.008"],["62063.90","1.380"],["63893.50","2.188"],["64003.40","0.001"],["64618.60","0.339"],["64633.00","0.215"],["64647.30","2.133"]],"a":[["64655.10","0.048"],["64656.40","0.696"],["64656.50","0.018"],["64656.60","0.154"],["64657.60","0.281"],["64659.80","0.110"],["64681.50","2.027"],["65296.50","0.034"],["65425.80","32.625"],["65587.40","20.328"],["65684.40","7.266"]],"st":1}}
{"stream":"btcusdt@depth@100ms","data":{"e":"depthUpdate","E":1784410677082,"T":1784410677081,"s":"BTCUSDT","ps":"BTCUSDT","U":11079105411969,"u":11079105416019,"pu":11079105411936,"b":[["14149.90","0.658"],["14349.90","0.854"],["14449.90","1.946"],["14549.90","0.742"],["58184.90","0.002"],["61417.40","0.008"],["63680.20","6.311"],["63736.70","20.970"],["63809.30","2.275"],["64003.40","0.001"],["64068.10","0.702"],["64297.30","0.023"],["64442.50","0.000"],["64446.40","0.216"],["64449.90","0.000"],["64484.30","0.004"],["64592.10","22.288"],["64598.70","0.002"],["64638.30","0.716"]],"a":[["64656.30","0.045"],["64656.40","0.001"],["64656.50","0.723"],["64656.60","0.154"],["64657.60","0.124"],["64659.80","0.110"],["65296.50","0.032"],["65478.80","1.765"],["65555.00","10.928"],["65581.60","16.610"],["65684.40","8.786"]],"st":1}}
{"stream":"btcusdt@depth@100ms","data":{"e":"depthUpdate","E":1784410677184,"T":1784410677180,"s":"BTCUSDT","ps":"BTCUSDT","U":11079105416140,"u":11079105420481,"pu":11079105416019,"b":[["14149.90","0.546"],["14349.90","1.092"],["14449.90","1.708"],["14549.90","0.854"],["52715.30","0.000"],["58184.90","0.002"],["61417.40","0.008"],["61417.50","0.007"],["62063.90","1.383"],["63831.20","0.000"],["64003.40","0.001"],["64326.60","3.885"],["64326.70","1.051"],["64349.90","0.051"],["64458.50","0.061"],["64499.80","0.004"],["64541.90","0.000"],["64543.40","0.000"],["64544.90","0.000"],["64546.40","0.556"],["64547.90","0.000"],["64549.40","0.035"],["64550.90","0.014"],["64552.40","0.000"],["64559.30","0.026"],["64592.10","0.006"],["64594.30","22.703"],["64636.20","0.522"]],"a":[["64653.70","0.007"],["64656.30","0.045"],["64656.40","0.001"],["64656.50","0.723"],["64656.60","0.467"],["64657.60","0.437"],["64659.60","0.003"],["64659.70","0.029"],["64659.80","0.110"],["64660.00","0.008"],["64660.50","0.049"],["64666.50","0.001"],["64668.60","0.544"],["64668.70","0.005"],["64708.50","24.146"],["64710.70","0.006"],["64733.20","0.002"],["64973.30","1.693"],["65296.50","0.032"],["65587.40","20.328"]],"st":1}}
{"stream":"btcusdt@depth@100ms","data":{"e":"depthUpdate","E":1784410677286,"T":1784410677285,"s":"BTCUSDT","ps":"BTCUSDT","U":11079105420610,"u":11079105425883,"pu":11079105420481,"b":[["1000.00","50.391"],["14149.90","0.420"],["14349.90","1.330"],["14449.90","1.470"],["14549.90","0.980"],["51719.90","0.000"],["58184.90","0.002"],["62063.90","1.380"],["63357.00","0.002"],["63695.50","0.000"],["63712.50","24.758"],["63739.00","7.179"],["63744.80","25.381"],["64003.40","0.000"],["64376.80","3.327"],["64448.00","4.167"],["64449.90","0.000"],["64540.40","0.202"],["64567.10","0.013"],["64585.30","0.133"],["64594.30","0.418"],["64594.70","0.818"],["64598.70","22.287"],["64633.00","0.061"],["64649.90","7.013"]],"a":[["64650.00","2.860"],["64653.50","0.000"],["64656.30","0.632"],["64656.40","0.001"],["64656.50","0.018"],["64656.60","0.154"],["64657.60","0.124"],["64659.80","0.815"],["64660.00","0.007"],["64660.50","0.050"],["64681.50","1.950"],["64707.70","0.744"],["64708.50","24.146"],["64710.70","0.006"],["64742.90","0.895"],["64784.00","1.479"],["64849.00","7.820"],["64886.00","2.171"],["64973.30","1.694"],["65296.50","0.032"],["65575.80","1.837"],["65587.40","21.394"]],"st":1}}
{"stream":"btcusdt@depth@100ms","data":{"e":"depthUpdate","E":1784410677388,"T":1784410677385,"s":"BTCUSDT","ps":"BTCUSDT","U":11079105425940,"u":11079105430481,"pu":11079105425883,"b":[["14149.90","0.308"],["14349.90","1.568"],["14449.90","1.232"],["14549.90","1.092"],["51720.00","0.004"],["58184.90","0.002"],["61417.40","0.008"],["62063.90","1.383"],["63788.70","2.348"],["63809.50","3.679"],["63880.60","8.442"],["64003.40","0.000"],["64016.50","65.190"],["64088.90","0.000"],["64164.10","51.266"],["64250.20","0.001"],["64264.10","12.528"],["64279.80","41.075"],["64279.90","0.864"],["64281.60","6.548"],["64326.70","0.934"],["64376.30","32.798"],["64378.40","0.117"],["64567.10","0.017"],["64623.20","0.309"],["64629.70","0.186"],["64633.00","0.215"],["64636.10","0.232"]],"a":[["64650.00","2.861"],["64653.60","0.387"],["64656.30","0.045"],["64656.50","0.723"],["64656.60","0.154"],["64659.80","0.110"],["64660.00","0.162"],["64666.50","0.310"],["64922.20","32.057"],["65018.20","6.389"],["65019.50","41.241"],["65136.60","51.164"],["65286.40","63.463"],["65296.50","0.032"],["65409.60","0.018"],["65587.40","20.328"],["65652.10","8.981"],["65767.50","2.123"]],"st":1}}
{"stream":"btcusdt@depth@100ms","data":{"e":"depthUpdate","E":1784410677490,"T":1784410677488,"s":"BTCUSDT","ps":"BTCUSDT","U":11079105430591,"u":11079105434431,"pu":11079105430481,"b":[["14149.90","0.182"],["14349.90","1.806"],["14449.90","0.994"],["14549.90","1.218"],["48149.70","0.000"],["58184.90","0.002"],["61417.40","0.008"],["62063.90","1.380"],["63712.50","26.796"],["63801.30","5.163"],["64003.40","0.000"],["64320.00","0.613"],["64326.70","0.944"],["64400.00","28.447"],["64480.00","4.537"],["64485.00","0.158"],["64488.30","0.037"],["64553.60","0.123"],["64560.00","1.320"],["64633.00","0.061"],["64640.00","5.572"],["64648.20","0.022"]],"a":[["64650.00","2.856"],["64653.50","0.000"],["64656.40","0.001"],["64656.50","0.018"],["64656.60","0.741"],["64657.60","0.124"],["64659.80","0.815"],["64660.00","0.162"],["64660.10","0.001"],["64660.50","0.050"],["64681.50","1.950"],["64720.00","0.552"],["64742.90","0.356"],["64745.00","0.001"],["64800.00","18.636"],["64880.00","9.708"],["64960.00","2.432"],["65040.00","0.550"],["65296.50","0.032"],["65470.90","3.094"],["65587.40","21.394"],["65620.90","0.000"],["65942.90","0.657"]],"st":1}}
{"stream":"btcusdt@depth@100ms","data":{"e":"depthUpdate","E":1784410677592,"T":1784410677589,"s":"BTCUSDT","ps":"BTCUSDT","U":11079105434469,"u":11079105439137,"pu":11079105434431,"b":[["1000.00","50.391"],["14149.90","0.070"],["14249.90","0.028"],["14349.90","1.988"],["14449.90","0.784"],["14549.90","1.330"],["51720.00","0.006"],["58184.90","0.002"],["61417.40","0.008"],["63824.40","77.681"],["63880.60","9.380"],["64003.40","0.000"],["64184.70","0.002"],["64449.90","0.000"],["64488.30","0.193"],["64553.60","5.778"],["64633.00","0.215"]],"a":[["64655.10","0.048"],["64656.40","0.001"],["64656.50","0.018"],["64656.60","0.741"],["64659.80","0.815"],["64681.50","2.027"],["64709.50","0.000"],["64745.00","3.922"],["65296.50","0.032"],["65482.30","80.969"],["65582.40","6.611"],["65942.90","0.660"]],"st":1}}
{"stream":"btcusdt@depth@100ms","data":{"e":"depthUpdate","E":1784410677694,"T":1784410677693,"s":"BTCUSDT","ps":"BTCUSDT","U":11079105439216,"u":11079105443059,"pu":11079105439137,"b":[["14149.90","0.000"],["14249.90","0.140"],["14349.90","2.002"],["14449.90","0.714"],["14549.90","1.344"],["51720.00","0.004"],["58184.90","0.004"],["61417.40","0.008"],["62063.90","1.383"],["63444.00","0.832"],["63854.20","1.557"],["64003.40","0.002"],["64068.00","5.687"],["64320.00","0.630"],["64333.00","1.722"],["64349.90","0.051"],["64400.00","28.464"],["64478.30","0.916"],["64480.00","4.554"],["64495.50","1.589"],["64560.00","1.337"],["64633.00","0.061"],["64634.50","0.471"],["64635.00","0.282"],["64636.50","0.558"],["64637.80","0.003"],["64640.00","5.589"],["64649.20","0.023"]],"a":[["64650.00","2.800"],["64651.90","0.005"],["64653.50","0.587"],["64655.10","0.048"],["64656.30","0.035"],["64656.40","0.001"],["64656.50","0.018"],["64656.60","0.467"],["64657.60","0.437"],["64658.20","0.017"],["64659.70","0.029"],["64659.80","0.815"],["64659.90","1.276"],["64660.10","0.001"],["64666.50","0.851"],["64668.60","0.003"],["64669.20","0.050"],["64670.30","0.927"],["64677.10","0.039"],["64678.10","0.557"],["64681.50","1.950"],["64720.00","0.569"],["64800.00","18.653"],["64801.70","1.266"],["64818.80","0.822"],["64880.00","9.725"],["64960.00","2.449"],["65040.00","0.567"],["65296.50","0.032"],["65587.40","21.394"],["65652.10","8.982"],["65684.40","7.722"],["65871.50","0.758"]],"st":1}}
{"stream":"btcusdt@depth@100ms","data":{"e":"depthUpdate","E":1784410677796,"T":1784410677795,"s":"BTCUSDT","ps":"BTCUSDT","U":11079105443085,"u":11079105446537,"pu":11079105443059,"b":[["1000.00","50.391"],["14249.90","0.266"],["14349.90","1.988"],["14449.90","0.714"],["14549.90","1.232"],["58184.90","0.002"],["61417.40","0.008"],["62063.90","1.380"],["63227.60","0.000"],["63671.40","0.000"],["64003.40","0.000"],["64326.70","0.944"],["64449.90","0.000"],["64633.00","0.215"]],"a":[["64653.50","0.000"],["64656.30","0.035"],["64656.40","0.001"],["64656.50","0.018"],["64656.60","0.154"],["64657.30","0.214"],["64657.40","0.001"],["64657.60","0.124"],["64659.80","0.815"],["64660.00","0.162"],["64660.50","0.050"],["64666.50","0.310"],["64668.70","0.546"],["64681.50","2.027"],["65296.50","0.032"],["65555.10","23.534"],["65938.10","0.000"]],"st":1}}
{"stream":"btcusdt@depth@100ms","data":{"e":"depthUpdate","E":1784410677898,"T":1784410677897,"s":"BTCUSDT","ps":"BTCUSDT","U":11079105446544,"u":11079105450056,"pu":11079105446537,"b":[["1000.00","50.391"],["14249.90","0.378"],["14349.90","2.002"],["14449.90","0.714"],["14549.90","1.106"],["51720.00","0.004"],["58184.90","0.002"],["61417.40","0.008"],["62063.90","1.383"],["63744.30","0.005"],["63788.40","4.227"],["63866.00","15.052"],["64003.40","0.000"],["64623.20","0.000"],["64629.70","0.031"],["64634.50","0.355"],["64635.50","0.975"],["64636.10","0.155"],["64643.30","0.373"],["64643.80","0.002"]],"a":[["64650.00","3.457"],["64653.50","0.000"],["64655.10","0.048"],["64656.50","0.028"],["64656.60","0.467"],["64657.60","0.124"],["64657.70","0.372"],["64657.90","0.481"],["64658.10","0.005"],["64658.20","0.017"],["64658.40","0.000"],["64658.60","0.000"],["64658.80","0.001"],["64658.90","0.002"],["64659.10","0.003"],["64659.20","0.005"],["64659.40","0.000"],["64659.50","0.222"],["64659.70","0.724"],["64659.80","0.110"],["64660.00","0.163"],["64660.50","0.049"],["64666.50","0.310"],["64668.70","0.546"],["64669.10","0.002"],["64669.20","0.048"],["64669.30","0.341"],["64681.50","1.950"],["64685.50","0.019"],["64685.60","0.001"],["64685.70","0.121"],["64686.00","0.017"],["64686.10","0.050"],["64686.20","0.114"],["65296.50","0.032"],["65606.70","1.068"],["65652.10","10.047"]],"st":1}}
{"stream":"btcusdt@depth@100ms","data":{"e":"depthUpdate","E":1784410678000,"T":1784410677999,"s":"BTCUSDT","ps":"BTCUSDT","U":11079105450105,"u":11079105454918,"pu":11079105450056,"b":[["14249.90","0.504"],["14349.90","1.988"],["14449.90","0.714"],["14549.90","0.994"],["58184.90","0.002"],["61417.40","0.008"],["64003.40","0.000"],["64633.00","0.215"],["64634.90","0.271"],["64635.50","0.859"],["64635.60","1.470"],["64636.50","0.001"],["64637.00","0.394"]],"a":[["64653.70","0.007"],["64655.10","0.635"],["64656.50","0.018"],["64656.60","0.154"],["64657.50","0.160"],["64657.60","0.437"],["64659.50","0.175"],["64659.60","0.167"],["64659.70","0.570"],["64666.50","0.851"],["64668.30","0.926"],["64668.70","0.005"],["64670.30","0.001"],["64675.80","0.557"],["64678.10","0.000"],["64681.50","2.027"],["65296.50","0.032"],["65478.90","0.001"],["65484.70","9.828"],["65581.60","15.553"],["65587.40","22.460"],["65684.40","8.786"],["65763.50","0.002"],["65910.70","1.212"],["65942.90","0.663"]],"st":1}}
{"stream":"btcusdt@depth@100ms","data":{"e":"depthUpdate","E":1784410678102,"T":1784410678101,"s":"BTCUSDT","ps":"BTCUSDT","U":11079105454993,"u":11079105459978,"pu":11079105454918,"b":[["1000.00","50.391"],["14249.90","0.616"],["14349.90","2.002"],["14449.90","0.714"],["14549.90","0.868"],["58184.90","0.002"],["61417.40","0.008"],["61417.50","0.009"],["62063.90","1.380"],["63929.90","0.000"],["64003.40","0.000"],["64326.70","0.944"],["64449.90","0.000"],["64535.90","0.000"],["64537.40","0.000"],["64538.90","0.004"],["64540.40","0.202"],["64541.90","0.000"],["64564.50","0.006"],["64619.00","2.088"],["64622.90","0.683"],["64623.70","1.039"],["64633.00","0.061"],["64638.30","0.716"],["64642.80","0.309"],["64643.30","0.064"],["64644.50","0.429"],["64645.20","3.045"],["64647.20","1.443"],["64649.90","7.006"]],"a":[["64650.00","3.461"],["64651.90","0.002"],["64653.60","0.310"],["64655.10","0.048"],["64656.20","0.011"],["64656.40","0.048"],["64656.50","0.713"],["64656.60","0.154"],["64657.50","0.003"],["64657.60","0.281"],["64658.20","0.007"],["64658.60","0.010"],["64659.60","0.003"],["64659.70","0.029"],["64660.00","0.054"],["64660.50","0.050"],["64665.70","0.473"],["64666.50","0.542"],["64668.30","0.000"],["64668.80","0.478"],["64669.10","0.928"],["64674.90","10.002"],["64678.50","0.107"],["64679.90","2.585"],["64681.50","1.950"],["64685.80","0.015"],["64708.50","0.002"],["64710.70","24.150"],["64722.50","0.000"],["65296.50","0.032"],["65470.90","2.714"]],"st":1}}
{"stream":"btcusdt@depth@100ms","data":{"e":"depthUpdate","E":1784410678204,"T":1784410678203,"s":"BTCUSDT","ps":"BTCUSDT","U":11079105460026,"u":11079105464078,"pu":11079105459978,"b":[["1000.00","50.391"],["14249.90","0.742"],["14349.90","1.988"],["14449.90","0.714"],["14549.90","0.756"],["51719.90","0.002"],["58184.90","0.002"],["61417.40","0.006"],["61417.50","0.011"],["62063.90","1.383"],["63319.10","0.000"],["63874.10","36.660"],["63933.70","0.241"],["64003.40","0.000"],["64349.90","0.051"],["64449.90","0.000"],["64633.00","0.061"],["64634.30","0.482"],["64634.90","0.155"],["64636.20","0.522"],["64638.90","1.408"]],"a":[["64656.40","0.635"],["64656.50","0.018"],["64656.60","0.154"],["64657.60","0.281"],["64659.80","0.805"],["64668.70","0.005"],["64675.80","0.000"],["64676.50","0.557"],["64681.50","2.027"],["64709.50","0.002"],["64714.70","0.002"],["64943.40","0.077"],["64973.30","1.693"],["65296.50","0.032"],["65587.40","23.526"]],"st":1}}
{"stream":"btcusdt@depth@100ms","data":{"e":"depthUpdate","E":1784410678306,"T":1784410678305,"s":"BTCUSDT","ps":"BTCUSDT","U":11079105464135,"u":11079105467610,"pu":11079105464078,"b":[["14249.90","0.910"],["14349.90","1.890"],["14449.90","0.770"],["14549.90","0.630"],["51719.90","0.000"],["58184.90","0.002"],["62026.80","0.000"],["62063.90","1.380"],["62673.00","0.000"],["63671.30","0.000"],["64003.40","0.000"],["64184.80","0.003"],["64326.60","3.886"],["64376.80","7.788"],["64495.50","0.704"],["64564.50","0.002"],["64567.10","0.013"],["64601.30","3.744"],["64603.60","0.887"],["64604.40","3.512"],["64619.00","0.088"],["64623.70","10.032"],["64623.80","2.586"],["64633.40","0.116"],["64634.30","0.366"],["64646.60","0.002"],["64647.20","1.443"],["64649.90","7.005"]],"a":[["64650.00","3.045"],["64656.40","0.001"],["64656.50","0.713"],["64656.60","0.154"],["64656.80","0.000"],["64657.60","0.124"],["64659.80","0.110"],["64672.90","0.979"],["64674.40","3.653"],["64674.90","0.004"],["64678.90","10.055"],["64679.90","0.585"],["64680.50","0.002"],["64681.50","1.950"],["64710.60","4.288"],["64742.90","0.895"],["64801.70","0.308"],["64973.30","1.692"],["65296.50","0.032"],["65587.40","22.460"],["65716.70","3.192"],["65873.40","2.952"]],"st":1}}
{"stream":"btcusdt@depth@100ms","data":{"e":"depthUpdate","E":1784410678408,"T":1784410678405,"s":"BTCUSDT","ps":"BTCUSDT","U":11079105467658,"u":11079105470919,"pu":11079105467610,"b":[["1000.00","50.391"],["14249.90","1.148"],["14349.90","1.652"],["14449.90","0.882"],["14549.90","0.518"],["51720.00","0.004"],["58184.90","0.002"],["61380.70","0.007"],["61417.40","0.006"],["62063.90","1.383"],["63712.50","25.699"],["64003.40","0.000"],["64326.60","3.887"],["64326.70","0.944"],["64495.50","1.581"],["64633.00","0.215"]],"a":[["64655.10","0.635"],["64656.50","0.018"],["64656.60","0.154"],["64657.60","0.437"],["64659.80","0.805"],["64660.00","0.054"],["64660.50","0.050"],["64681.50","2.027"],["64801.70","1.266"],["65296.50","0.033"]],"st":1}}
{"stream":"btcusdt@depth@100ms","data":{"e":"depthUpdate","E":1784410678510,"T":1784410678509,"s":"BTCUSDT","ps":"BTCUSDT","U":11079105471136,"u":11079105476110,"pu":11079105470919,"b":[["1000.00","50.391"],["14249.90","1.386"],["14349.90","1.414"],["14449.90","1.008"],["14549.90","0.392"],["58184.90","0.002"],["60734.60","0.027"],["61417.40","0.006"],["64003.40","0.000"],["64320.00","0.613"],["64400.00","28.447"],["64480.00","4.537"],["64560.00","1.320"],["64622.80","0.310"],["64627.00","0.716"],["64629.30","0.255"],["64633.00","0.061"],["64633.40","0.000"],["64634.60","0.118"],["64635.70","0.077"],["64640.00","5.572"]],"a":[["64650.00","3.040"],["64653.50","0.077"],["64655.10","0.048"],["64656.50","0.713"],["64656.60","0.467"],["64659.80","0.110"],["64660.00","0.163"],["64660.50","0.049"],["64666.50","0.310"],["64669.00","0.542"],["64669.10","0.943"],["64675.70","0.000"],["64676.50","0.000"],["64677.00","0.559"],["64681.50","1.950"],["64714.40","0.016"],["64720.00","0.552"],["64721.00","0.000"],["64786.60","0.028"],["64800.00","18.636"],["64880.00","9.708"],["64960.00","2.432"],["65040.00","0.550"],["65296.50","0.033"],["65458.10","12.004"],["65485.40","3.048"],["65846.00","6.314"]],"st":1}}
{"stream":"btcusdt@depth@100ms","data":{"e":"depthUpdate","E":1784410678612,"T":1784410678609,"s":"BTCUSDT","ps":"BTCUSDT","U":11079105476255,"u":11079105479980,"pu":11079105476110,"b":[["14249.90","1.624"],["14349.90","1.176"],["14449.90","1.120"],["14549.90","0.280"],["58184.90","0.002"],["61417.40","0.008"],["62063.90","1.380"],["63824.90","0.781"],["63841.80","11.374"],["64003.40","0.000"],["64088.10","0.000"],["64449.90","0.000"],["64488.30","0.037"],["64633.00","0.215"],["64635.60","0.913"],["64636.80","0.573"]],"a":[["64653.50","0.077"],["64656.30","0.035"],["64656.40","0.001"],["64656.50","0.018"],["64656.60","0.154"],["64657.60","0.124"],["64659.80","0.805"],["64660.00","0.162"],["64660.50","0.050"],["65296.50","0.033"],["65511.20","2.285"],["65587.40","23.526"],["65716.70","4.256"]],"st":1}}
{"stream":"btcusdt@depth@100ms","data":{"e":"depthUpdate","E":1784410678714,"T":1784410678713,"s":"BTCUSDT","ps":"BTCUSDT","U":11079105480182,"u":11079105484319,"pu":11079105479980,"b":[["1000.00","50.391"],["14249.90","1.862"],["14349.90","0.938"],["14449.90","1.246"],["14549.90","0.154"],["58184.90","0.002"],["61417.40","0.008"],["62063.90","1.383"],["63712.50","26.796"],["64003.40","0.000"],["64326.70","0.944"],["64349.90","0.051"],["64449.90","0.000"],["64622.90","0.467"],["64633.00","0.215"]],"a":[["64653.50","0.077"],["64656.50","0.870"],["64656.60","0.154"],["64657.20","0.182"],["64659.80","0.110"],["64660.00","0.163"],["64660.50","0.049"],["64681.50","1.950"],["64702.20","0.567"],["65296.50","0.033"],["65490.80","0.306"]],"st":1}}
{"stream":"btcusdt@depth@100ms","data":{"e":"depthUpdate","E":1784410678816,"T":1784410678814,"s":"BTCUSDT","ps":"BTCUSDT","U":11079105484387,"u":11079105488489,"pu":11079105484319,"b":[["1000.00","50.391"],["14149.90","0.056"],["14249.90","1.988"],["14349.90","0.756"],["14449.90","1.358"],["14549.90","0.042"],["58184.90","0.002"],["62063.90","1.380"],["63615.50","8.001"],["63712.50","25.699"],["63889.60","1.564"],["64003.40","0.000"],["64067.90","3.273"],["64320.00","0.630"],["64400.00","28.464"],["64480.00","4.554"],["64560.00","1.337"],["64640.00","5.589"]],"a":[["64650.00","2.862"],["64653.50","0.077"],["64656.40","0.001"],["64656.50","0.713"],["64656.60","0.154"],["64657.20","0.495"],["64659.80","0.110"],["64660.00","0.163"],["64660.50","0.049"],["64681.50","2.027"],["64720.00","0.569"],["64800.00","18.653"],["64880.00","9.725"],["64960.00","2.449"],["65040.00","0.567"],["65296.50","0.033"]],"st":1}}
{"stream":"btcusdt@depth@100ms","data":{"e":"depthUpdate","E":1784410678918,"T":1784410678917,"s":"BTCUSDT","ps":"BTCUSDT","U":11079105488605,"u":11079105492235,"pu":11079105488489,"b":[["14149.90","0.168"],["14249.90","2.002"],["14349.90","0.714"],["14449.90","1.316"],["14549.90","0.000"],["58184.90","0.002"],["61417.40","0.008"],["62063.90","1.383"],["64003.40","0.000"],["64633.00","0.061"]],"a":[["64653.50","0.077"],["64656.20","0.001"],["64656.30","0.035"],["64656.40","0.001"],["64656.50","0.018"],["64656.60","0.467"],["64657.20","0.182"],["64657.90","0.491"],["64659.80","0.805"],["64660.00","0.163"],["64660.50","0.049"],["65296.50","0.033"]],"st":1}}
{"stream":"btcusdt@depth@100ms","data":{"e":"depthUpdate","E":1784410679020,"T":1784410679019,"s":"BTCUSDT","ps":"BTCUSDT","U":11079105492286,"u":11079105496248,"pu":11079105492235,"b":[["1000.00","50.391"],["14149.90","0.294"],["14249.90","1.988"],["14349.90","0.714"],["14449.90","1.204"],["51720.00","0.004"],["58184.90","0.002"],["61417.40","0.008"],["63583.20","4.194"],["63659.40","1.568"],["63906.40","8.441"],["64003.40","0.000"],["64315.80","0.000"],["64326.70","0.944"],["64449.90","0.000"],["64633.00","0.215"]],"a":[["64653.50","0.077"],["64656.50","0.018"],["64660.00","0.163"],["64660.50","0.049"],["64669.50","0.003"],["64681.50","1.950"],["64733.20","0.000"],["65156.60","0.000"],["65296.50","0.033"],["65420.00","19.835"],["65587.40","22.460"],["65742.60","1.292"]],"st":1}}
{"stream":"btcusdt@depth@100ms","data":{"e":"depthUpdate","E":1784410679122,"T":1784410679121,"s":"BTCUSDT","ps":"BTCUSDT","U":11079105496260,"u":11079105500952,"pu":11079105496248,"b":[["1000.00","50.391"],["14149.90","0.406"],["14249.90","2.002"],["14349.90","0.714"],["14449.90","1.078"],["58184.90","0.002"],["61417.40","0.008"],["61417.50","0.009"],["62063.90","1.380"],["63615.50","8.001"],["63635.10","0.012"],["63712.50","25.699"],["63777.10","8.240"],["64003.40","0.000"],["64087.60","1.090"],["64326.70","1.332"],["64449.90","0.000"],["64537.40","0.000"],["64538.90","1.280"],["64540.40","1.276"],["64540.50","0.589"],["64631.90","0.003"],["64635.90","0.674"],["64636.80","0.016"],["64638.30","0.716"],["64638.40","0.599"],["64647.60","0.000"],["64648.20","0.000"],["64649.90","7.005"]],"a":[["64653.50","0.077"],["64655.10","0.048"],["64660.00","0.163"],["64660.50","0.049"],["64662.90","0.001"],["64666.50","0.310"],["64669.00","0.542"],["64682.30","2.409"],["64685.80","0.062"],["65167.20","7.865"],["65296.50","0.033"],["65549.30","27.182"],["65587.40","21.394"],["65664.70","0.000"]],"st":1}}
{"stream":"btcusdt@depth@100ms","data":{"e":"depthUpdate","E":1784410679224,"T":1784410679223,"s":"BTCUSDT","ps":"BTCUSDT","U":11079105501012,"u":11079105504991,"pu":11079105500952,"b":[["14149.90","0.532"],["14249.90","1.988"],["14349.90","0.714"],["14449.90","0.966"],["51719.90","0.000"],["51720.00","0.004"],["58184.90","0.002"],["62063.90","1.383"],["63637.00","0.042"],["64320.00","0.460"],["64326.60","3.886"],["64349.90","0.051"],["64400.00","28.294"],["64449.90","0.000"],["64480.00","4.384"],["64538.90","0.004"],["64540.40","0.000"],["64540.50","0.006"],["64560.00","1.167"],["64636.20","0.522"],["64640.00","5.419"]],"a":[["64653.50","0.664"],["64656.50","0.175"],["64660.00","0.162"],["64660.50","0.050"],["64660.70","0.000"],["64660.80","0.207"],["64662.60","0.320"],["64668.70","0.005"],["64720.00","0.399"],["64800.00","18.483"],["64880.00","9.555"],["64960.00","2.279"],["64973.30","1.693"],["65040.00","0.397"],["65296.50","0.033"],["65419.30","9.163"],["65663.00","1.529"],["65834.40","0.758"],["65942.90","0.660"]],"st":1}}
{"stream":"btcusdt@depth@100ms","data":{"e":"depthUpdate","E":1784410679326,"T":1784410679325,"s":"BTCUSDT","ps":"BTCUSDT","U":11079105505040,"u":11079105508620,"pu":11079105504991,"b":[["1000.00","50.391"],["14149.90","0.644"],["14249.90","2.002"],["14349.90","0.714"],["14449.90","0.840"],["51720.00","0.004"],["58184.90","0.002"],["61417.40","0.006"],["61417.50","0.009"],["62063.90","1.380"],["63583.20","5.294"],["63670.80","0.942"],["63906.40","9.379"],["64003.40","0.000"],["64132.70","6.846"],["64192.30","0.821"],["64320.00","0.443"],["64326.60","3.885"],["64326.70","1.332"],["64400.00","28.277"],["64480.00","4.367"],["64495.40","0.879"],["64495.50","0.704"],["64560.00","1.150"],["64640.00","5.402"],["64646.50","0.156"],["64649.90","7.053"]],"a":[["64653.50","0.077"],["64653.70","0.594"],["64655.10","0.048"],["64656.50","0.175"],["64660.00","0.162"],["64660.50","0.050"],["64660.80","0.160"],["64661.00","0.002"],["64661.30","0.001"],["64661.50","0.388"],["64661.70","0.018"],["64661.90","0.312"],["64662.10","0.004"],["64662.40","0.007"],["64662.60","0.367"],["64678.40","3.096"],["64681.50","2.027"],["64720.00","0.382"],["64800.00","18.466"],["64801.60","1.040"],["64801.70","0.308"],["64880.00","9.538"],["64960.00","2.262"],["65040.00","0.380"],["65296.50","0.032"],["65458.10","12.232"],["65587.40","21.394"],["65625.10","0.271"],["65800.00","36.683"]],"st":1}}
{"stream":"btcusdt@depth@100ms","data":{"e":"depthUpdate","E":1784410679428,"T":1784410679425,"s":"BTCUSDT","ps":"BTCUSDT","U":11079105508669,"u":11079105512566,"pu":11079105508620,"b":[["1000.00","50.391"],["14149.90","0.770"],["14249.90","1.988"],["14349.90","0.714"],["14449.90","0.728"],["51720.00","0.004"],["58184.90","0.002"],["61417.40","0.006"],["63680.20","6.664"],["63712.50","26.796"],["63731.90","1.678"],["63841.80","11.640"],["64003.40","0.000"],["64068.10","0.936"],["64320.00","0.460"],["64400.00","28.294"],["64480.00","4.384"],["64495.40","0.879"],["64541.90","1.276"],["64543.40","1.276"],["64560.00","1.167"],["64567.10","0.017"],["64581.90","0.462"],["64582.20","0.000"],["64582.50","0.001"],["64582.80","0.074"],["64583.10","0.000"],["64600.90","0.146"],["64601.20","0.000"],["64601.50","0.016"],["64601.80","0.462"],["64602.10","0.032"],["64611.40","0.629"],["64616.40","0.311"],["64616.50","0.001"],["64616.70","0.000"],["64617.00","0.327"],["64617.10","0.001"],["64617.60","1.178"],["64617.70","0.001"],["64619.80","0.000"],["64619.90","0.010"],["64638.20","0.048"],["64638.30","0.002"],["64638.40","0.479"],["64638.50","0.056"],["64638.80","0.093"],["64638.90","0.710"],["64639.20","0.003"],["64639.50","0.121"],["64639.80","0.840"],["64640.00","5.419"],["64640.10","0.001"],["64647.40","0.086"]],"a":[["64650.00","2.866"],["64653.70","0.007"],["64656.00","0.008"],["64656.30","0.003"],["64656.50","0.018"],["64656.60","0.002"],["64656.90","0.004"],["64657.20","0.002"],["64657.30","0.002"],["64657.60","0.004"],["64657.70","0.312"],["64657.90","0.191"],["64675.00","0.113"],["64675.30","0.001"],["64675.60","0.715"],["64675.90","1.013"],["64676.30","0.094"],["64678.40","3.036"],["64678.50","0.047"],["64679.00","0.002"],["64679.10","0.057"],["64679.50","0.313"],["64679.70","0.007"],["64679.80","0.120"],["64694.00","0.003"],["64694.30","0.000"],["64694.60","0.000"],["64694.90","0.000"],["64695.30","0.000"],["64720.00","0.399"],["64800.00","18.483"],["64801.60","1.040"],["64880.00","9.555"],["64960.00","2.279"],["64973.30","1.694"],["65040.00","0.397"],["65296.50","0.032"],["65425.80","34.152"],["65547.60","7.610"],["65555.10","25.819"],["65587.40","23.526"],["65942.90","0.663"]],"st":1}}
{"stream":"btcusdt@depth@100ms","data":{"e":"depthUpdate","E":1784410679530,"T":1784410679529,"s":"BTCUSDT","ps":"BTCUSDT","U":11079105512660,"u":11079105515988,"pu":11079105512566,"b":[["14149.90","0.966"],["14249.90","1.834"],["14349.90","0.798"],["14449.90","0.602"],["58184.90","0.002"],["61417.40","0.006"],["62063.90","1.383"],["63615.50","9.100"],["63647.80","10.981"],["63712.50","25.699"],["63731.90","1.951"],["64003.40","0.000"],["64121.90","0.000"],["64320.00","0.630"],["64400.00","28.464"],["64449.90","0.000"],["64480.00","4.554"],["64485.00","0.158"],["64488.30","0.193"],["64537.40","0.000"],["64538.90","0.004"],["64540.40","0.000"],["64553.60","5.979"],["64560.00","1.337"],["64569.70","0.001"],["64597.40","0.025"],["64597.60","0.000"],["64601.40","0.483"],["64602.00","0.064"],["64602.40","0.090"],["64602.70","0.062"],["64608.20","0.000"],["64633.00","0.215"],["64638.80","0.249"],["64639.10","0.157"],["64639.40","0.195"],["64639.50","0.427"],["64640.00","5.788"],["64640.40","0.196"],["64640.70","0.121"]],"a":[["64650.00","2.861"],["64655.90","0.033"],["64656.20","0.033"],["64656.50","0.110"],["64656.60","0.002"],["64656.70","1.276"],["64657.10","0.124"],["64657.20","0.034"],["64657.50","0.063"],["64657.90","0.251"],["64658.60","0.134"],["64658.90","0.002"],["64674.90","0.036"],["64675.20","0.037"],["64675.50","0.733"],["64676.20","0.048"],["64678.40","3.096"],["64679.00","0.122"],["64679.40","0.072"],["64679.70","0.067"],["64681.50","1.950"],["64685.30","0.130"],["64692.60","0.002"],["64720.00","0.569"],["64742.90","0.897"],["64745.00","3.933"],["64800.00","18.653"],["64880.00","9.725"],["64960.00","2.449"],["65040.00","0.567"],["65285.90","0.000"],["65296.50","0.032"],["65652.10","8.982"]],"st":1}}
{"stream":"btcusdt@depth@100ms","data":{"e":"depthUpdate","E":1784410679632,"T":1784410679629,"s":"BTCUSDT","ps":"BTCUSDT","U":11079105516045,"u":11079105520091,"pu":11079105515988,"b":[["1000.00","50.391"],["14149.90","1.204"],["14249.90","1.596"],["14349.90","0.910"],["14449.90","0.490"],["58184.90","0.002"],["61417.40","0.006"],["62063.90","1.380"],["63764.20","3.284"],["63827.90","1.094"],["64003.40","0.000"],["64046.80","0.001"],["64132.70","7.779"],["64322.20","0.000"],["64322.30","0.144"],["64326.70","1.332"],["64449.90","0.000"],["64538.90","0.004"],["64540.40","0.000"],["64544.90","1.134"],["64561.90","0.104"],["64581.80","0.000"],["64582.30","1.140"],["64604.40","0.012"],["64604.50","0.426"],["64622.10","0.200"],["64638.90","0.830"],["64640.10","0.139"]],"a":[["64650.00","2.820"],["64651.90","0.005"],["64656.50","0.170"],["64656.60","0.002"],["64657.60","0.064"],["64678.20","0.001"],["64678.30","0.062"],["64679.50","0.373"],["64691.50","0.413"],["64694.40","0.561"],["64717.00","0.100"],["65296.50","0.032"],["65469.20","0.258"],["65483.30","0.007"],["65593.90","1.140"],["65736.10","1.109"],["65942.90","0.660"]],"st":1}}
{"stream":"btcusdt@depth@100ms","data":{"e":"depthUpdate","E":1784410679734,"T":1784410679733,"s":"BTCUSDT","ps":"BTCUSDT","U":11079105520191,"u":11079105524054,"pu":11079105520091,"b":[["1000.00","50.391"],["14149.90","1.442"],["14249.90","1.358"],["14349.90","1.036"],["14449.90","0.364"],["58184.90","0.002"],["61417.40","0.006"],["62063.90","1.383"],["63705.40","4.231"],["63771.40","1.866"],["63906.40","8.442"],["64003.40","0.000"],["64319.80","0.570"],["64349.90","0.051"],["64449.90","0.000"],["64458.50","0.065"],["64461.10","0.023"],["64478.30","0.000"],["64495.40","0.000"],["64549.50","0.000"],["64601.70","0.068"],["64633.00","0.215"],["64638.80","0.423"],["64638.90","1.370"],["64639.40","0.345"],["64639.50","0.607"],["64639.70","0.080"],["64649.90","7.105"]],"a":[["64656.60","0.002"],["64656.80","0.032"],["64657.20","0.154"],["64657.80","0.182"],["64657.90","0.311"],["64675.80","0.032"],["64676.20","0.168"],["64679.60","0.067"],["64679.70","0.247"],["64748.80","0.385"],["64749.30","0.000"],["64749.40","0.016"],["64752.00","0.010"],["64801.60","0.000"],["64818.80","0.004"],["65296.50","0.034"],["65419.30","8.247"]],"st":1}}
{"stream":"btcusdt@depth@100ms","data":{"e":"depthUpdate","E":1784410679836,"T":1784410679833,"s":"BTCUSDT","ps":"BTCUSDT","U":11079105524084,"u":11079105526877,"pu":11079105524054,"b":[["14149.90","1.680"],["14249.90","1.120"],["14349.90","1.148"],["14449.90","0.252"],["58184.90","0.002"],["61417.40","0.006"],["62063.90","1.380"],["63712.50","26.796"],["63809.40","2.580"],["63826.50","0.003"],["63906.40","6.566"],["63938.80","1.404"],["64003.40","0.000"],["64045.00","0.581"],["64132.70","8.402"],["64378.40","0.117"],["64441.50","0.000"],["64458.50","0.061"],["64461.10","0.019"],["64544.90","0.000"],["64561.90","0.100"],["64581.90","6.462"],["64582.30","1.884"],["64582.40","0.117"],["64583.00","0.074"],["64583.40","0.455"],["64583.70","0.643"],["64604.50","3.926"],["64620.70","3.221"],["64633.00","0.061"],["64639.10","0.313"],["64639.40","0.501"],["64639.50","0.745"],["64649.90","7.106"]],"a":[["64650.00","2.855"],["64656.60","0.589"],["64657.10","0.184"],["64657.20","0.214"],["64657.50","0.123"],["64657.90","0.435"],["64658.60","0.010"],["64676.40","0.772"],["64679.00","0.242"],["64679.40","0.132"],["64692.50","3.501"],["64693.90","0.065"],["64694.20","0.191"],["64694.50","0.032"],["64695.20","0.061"],["64714.00","1.756"],["64715.20","6.239"],["64840.70","0.208"],["64855.70","0.000"],["64886.00","2.288"],["65296.50","0.032"],["65458.10","12.612"],["65470.90","2.456"],["65490.40","3.100"]],"st":1}}
{"stream":"btcusdt@depth@100ms","data":{"e":"depthUpdate","E":1784410679938,"T":1784410679937,"s":"BTCUSDT","ps":"BTCUSDT","U":11079105526937,"u":11079105529828,"pu":11079105526877,"b":[["1000.00","50.391"],["14149.90","1.918"],["14249.90","0.882"],["14349.90","1.274"],["14449.90","0.126"],["58184.90","0.002"],["61417.40","0.006"],["63357.00","0.005"],["63647.80","12.079"],["63770.20","0.572"],["64003.40","0.000"],["64192.10","0.117"],["64326.70","1.332"],["64537.40","0.000"],["64541.90","0.000"],["64543.40","0.000"],["64549.60","10.000"],["64608.90","0.012"],["64615.40","0.145"],["64616.90","0.723"],["64617.30","0.158"],["64617.60","1.484"],["64618.20","0.170"],["64621.90","0.000"],["64622.80","0.001"],["64623.70","10.034"],["64624.50","3.856"],["64629.30","0.100"],["64633.00","0.061"],["64635.70","0.000"],["64649.90","7.098"]],"a":[["64650.00","2.860"],["64651.90","0.002"],["64653.50","0.000"],["64656.40","0.001"],["64656.60","0.002"],["64657.80","0.306"],["64657.90","0.311"],["64658.50","0.000"],["64658.70","1.321"],["64659.60","0.003"],["64659.70","0.029"],["64659.80","0.805"],["64660.00","0.007"],["64662.90","0.005"],["64663.00","0.028"],["64666.50","0.001"],["64674.40","3.655"],["64674.90","0.034"],["64733.50","0.041"],["64739.20","4.754"],["64747.50","10.000"],["64973.20","3.304"],["65296.50","0.032"],["65419.30","9.163"],["65627.70","7.157"],["65652.10","10.047"]],"st":1}}
{"stream":"btcusdt@depth@100ms","data":{"e":"depthUpdate","E":1784410680040,"T":1784410680038,"s":"BTCUSDT","ps":"BTCUSDT","U":11079105529882,"u":11079105535007,"pu":11079105529828,"b":[["1000.00","50.391"],["14149.90","1.988"],["14249.90","0.728"],["14349.90","1.386"],["14449.90","0.014"],["14549.90","0.084"],["58184.90","0.002"],["61417.40","0.006"],["62063.90","1.383"],["63447.90","6.610"],["63480.30","1.021"],["63495.40","0.570"],["63906.40","7.504"],["64003.40","0.000"],["64441.50","4.588"],["64449.90","0.000"],["64478.30","0.907"],["64495.40","0.879"],["64542.50","0.039"],["64542.80","0.096"],["64582.70","0.067"],["64591.30","0.008"],["64615.00","1.034"],["64617.10","0.121"],["64618.20","0.308"],["64620.40","0.150"],["64620.70","2.525"],["64624.30","0.097"],["64625.30","0.083"],["64626.00","0.760"],["64627.00","1.025"],["64633.00","0.215"],["64634.60","0.002"],["64635.00","0.398"],["64635.60","0.372"],["64635.90","0.117"],["64636.40","0.195"],["64636.90","0.564"],["64637.00","0.394"],["64637.10","1.104"],["64637.20","0.624"],["64638.30","0.007"],["64638.50","0.049"],["64638.80","0.430"],["64639.80","1.228"],["64640.00","5.263"],["64642.80","0.000"],["64643.60","0.312"],["64645.10","0.217"],["64645.20","3.047"],["64647.30","1.592"],["64647.40","0.627"]],"a":[["64658.70","1.274"],["64658.90","0.049"],["64659.70","0.570"],["64659.80","0.264"],["64661.70","0.011"],["64662.20","0.883"],["64662.60","0.058"],["64668.90","0.541"],["64669.00","0.001"],["64669.10","0.017"],["64669.50","0.003"],["64669.60","0.926"],["64671.90","0.310"],["64672.40","0.001"],["64677.80","0.148"],["64679.00","0.249"],["64679.30","0.001"],["64679.80","0.063"],["64694.80","0.087"],["64708.00","0.284"],["64715.20","6.029"],["64747.40","0.013"],["64752.00","0.002"],["64801.60","0.958"],["64818.80","0.822"],["64855.60","3.230"],["65186.40","0.305"],["65425.80","33.541"],["65576.40","0.002"],["65610.50","0.001"]],"st":1}}
{"stream":"btcusdt@depth@100ms","data":{"e":"depthUpdate","E":1784410680142,"T":1784410680141,"s":"BTCUSDT","ps":"BTCUSDT","U":11079105535146,"u":11079105542959,"pu":11079105535007,"b":[["14149.90","2.002"],["14249.90","0.714"],["14349.90","1.288"],["14449.90","0.000"],["14549.90","0.196"],["58184.90","0.002"],["61417.40","0.016"],["61417.50","0.011"],["62063.90","1.380"],["63680.20","7.017"],["63809.30","3.370"],["63906.40","9.380"],["63920.10","1.641"],["64003.40","0.000"],["64151.50","0.001"],["64283.50","0.639"],["64283.60","0.224"],["64326.70","1.332"],["64449.90","0.000"],["64617.00","0.849"],["64617.10","0.313"],["64617.60","1.622"],["64620.50","2.038"],["64636.90","1.284"],["64638.30","0.002"],["64640.00","5.723"],["64646.60","0.001"],["64649.90","7.100"]],"a":[["64650.00","2.859"],["64653.30","0.005"],["64658.90","0.002"],["64659.70","0.617"],["64662.90","0.001"],["64663.00","0.031"],["64668.90","0.000"],["64669.50","0.544"],["64694.80","0.057"],["64718.50","0.031"],["65296.50","0.036"],["65600.40","4.341"]],"st":1}}
{"stream":"btcusdt@depth@100ms","data":{"e":"depthUpdate","E":1784410680244,"T":1784410680243,"s":"BTCUSDT","ps":"BTCUSDT","U":11079105542970,"u":11079105568889,"pu":11079105542959,"b":[["1000.00","50.391"],["14149.90","1.932"],["14154.00","0.056"],["14249.90","0.658"],["14250.20","0.014"],["14254.00","0.042"],["14349.90","1.176"],["14549.90","0.266"],["14554.00","0.056"],["32267.40","0.007"],["32327.00","0.007"],["32397.90","0.042"],["32399.30","0.105"],["51719.90","0.000"],["51720.00","0.004"],["58184.90","0.051"],["58188.60","0.002"],["61417.40","0.006"],["62067.80","0.003"],["63361.00","0.003"],["63383.30","5.837"],["63421.60","2.205"],["63453.90","3.067"],["63645.10","0.012"],["63654.00","0.054"],["64003.40","0.000"],["64007.50","0.010"],["64087.60","0.000"],["64127.80","0.000"],["64136.30","0.929"],["64191.60","0.001"],["64200.90","0.001"],["64316.10","0.000"],["64326.60","3.730"],["64330.70","0.047"],["64349.90","0.051"],["64385.60","0.000"],["64394.90","0.001"],["64441.90","0.000"],["64443.00","0.000"],["64443.10","0.000"],["64444.60","0.755"],["64444.70","1.785"],["64447.10","0.348"],["64449.90","0.000"],["64452.00","0.100"],["64453.60","0.157"],["64455.40","0.047"],["64470.30","0.008"],["64477.40","0.920"],["64478.30","0.000"],["64484.30","0.104"],["64485.00","0.002"],["64486.40","3.534"],["64494.50","0.888"],["64495.40","0.000"],["64499.10","0.004"],["64499.20","0.037"],["64500.50","0.003"],["64513.60","0.003"],["64517.30","0.048"],["64525.20","0.005"],["64536.50","2.348"],["64536.60","0.000"],["64536.70","0.451"],["64542.30","0.000"],["64550.20","0.556"],["64552.30","0.000"],["64553.00","0.137"],["64553.60","5.856"],["64553.90","0.001"],["64556.50","0.032"],["64556.60","0.000"],["64557.50","0.011"],["64558.50","0.015"],["64559.40","0.029"],["64560.30","3.349"],["64561.90","0.000"],["64562.80","2.024"],["64563.00","0.123"],["64563.40","0.004"],["64564.20","0.029"],["64567.10","0.013"],["64568.70","0.000"],["64569.50","0.001"],["64570.00","0.018"],["64572.00","0.736"],["64573.20","0.000"],["64573.40","0.076"],["64573.90","0.021"],["64574.20","0.020"],["64574.60","4.048"],["64574.80","0.008"],["64576.40","0.104"],["64577.40","0.002"],["64579.60","0.313"],["64580.50","0.010"],["64580.80","0.000"],["64581.90","6.000"],["64583.40","0.458"],["64584.00","0.030"],["64584.70","0.015"],["64585.30","0.132"],["64586.30","0.001"],["64587.40","0.234"],["64588.80","0.212"],["64589.40","0.127"],["64589.70","0.012"],["64590.80","0.000"],["64591.20","0.064"],["64591.90","0.000"],["64592.10","22.622"],["64592.40","0.000"],["64592.60","0.341"],["64594.20","0.000"],["64594.30","0.418"],["64594.90","0.048"],["64596.00","0.254"],["64597.40","0.000"],["64598.20","0.682"],["64598.30","0.427"],["64598.70","0.002"],["64598.90","0.166"],["64599.00","0.417"],["64599.60","0.008"],["64599.80","0.019"],["64600.20","0.015"],["64600.30","0.000"],["64600.40","0.000"],["64600.50","0.033"],["64600.60","0.018"],["64600.70","0.000"],["64600.80","0.025"],["64601.00","0.006"],["64601.20","0.000"],["64601.30","0.466"],["64601.40","0.387"],["64601.50","0.002"],["64602.20","0.000"],["64602.30","0.642"],["64602.60","0.003"],["64602.90","0.049"],["64603.00","0.001"],["64603.30","0.022"],["64604.50","3.928"],["64604.80","0.492"],["64605.00","0.048"],["64605.30","0.000"],["64606.00","0.016"],["64606.30","0.387"],["64606.40","0.405"],["64606.90","0.258"],["64607.00","0.013"],["64607.70","0.006"],["64608.70","0.235"],["64609.40","0.014"],["64609.70","0.001"],["64610.10","0.000"],["64610.40","0.616"],["64610.50","0.328"],["64610.60","0.002"],["64610.70","0.000"],["64610.80","0.000"],["64611.00","0.024"],["64611.10","0.302"],["64611.20","0.074"],["64611.40","0.533"],["64611.60","0.049"],["64611.80","0.084"],["64612.10","0.214"],["64612.20","0.093"],["64612.80","0.449"],["64612.90","0.010"],["64613.00","1.015"],["64613.60","0.198"],["64613.80","0.051"],["64614.20","0.002"],["64614.70","0.006"],["64614.80","0.001"],["64615.00","1.032"],["64615.10","0.000"],["64615.20","0.588"],["64615.80","0.018"],["64615.90","0.003"],["64616.00","0.036"],["64616.60","0.002"],["64617.30","0.314"],["64617.40","0.002"],["64617.50","2.169"],["64617.60","1.898"],["64617.80","0.003"],["64617.90","0.054"],["64618.00","0.003"],["64618.40","0.468"],["64619.00","0.037"],["64619.10","0.001"],["64619.20","0.091"],["64619.30","0.024"],["64619.50","0.020"],["64619.70","0.000"],["64619.90","0.014"],["64620.00","0.009"],["64620.20","0.000"],["64620.50","0.181"],["64620.60","1.239"],["64620.90","0.045"],["64621.00","0.015"],["64621.10","0.571"],["64621.20","0.002"],["64621.30","0.095"],["64621.40","0.346"],["64621.50","3.144"],["64621.80","0.010"],["64622.10","0.212"],["64622.20","0.693"],["64622.30","0.395"],["64622.40","0.035"],["64622.60","0.002"],["64622.80","0.001"],["64622.90","0.516"],["64623.00","0.121"],["64623.40","0.001"],["64623.50","0.311"],["64623.60","11.121"],["64623.70","0.063"],["64623.80","0.000"],["64623.90","1.469"],["64624.00","0.681"],["64624.10","0.000"],["64624.30","0.097"],["64624.40","0.003"],["64624.50","3.858"],["64624.60","0.001"],["64624.90","0.001"],["64625.20","0.612"],["64625.30","0.006"],["64625.40","0.040"],["64625.60","0.006"],["64626.00","0.703"],["64626.30","0.395"],["64626.50","0.485"],["64626.60","0.149"],["64626.70","0.000"],["64627.00","0.773"],["64627.10","1.319"],["64627.20","0.092"],["64627.30","1.164"],["64627.40","0.562"],["64627.50","0.002"],["64627.60","0.774"],["64627.70","0.081"],["64627.80","0.185"],["64627.90","0.070"],["64628.00","0.312"],["64628.10","0.981"],["64628.30","0.017"],["64628.50","0.003"],["64628.80","0.005"],["64629.10","0.002"],["64629.20","0.013"],["64629.30","0.150"],["64629.40","0.002"],["64629.70","0.000"],["64629.80","0.006"],["64630.00","0.040"],["64630.10","0.385"],["64630.20","0.059"],["64630.30","0.387"],["64630.40","0.006"],["64630.50","0.064"],["64630.90","0.004"],["64631.00","0.171"],["64631.10","0.003"],["64631.20","0.011"],["64631.30","0.029"],["64631.40","1.281"],["64631.50","1.219"],["64631.60","0.557"],["64631.90","0.001"],["64632.00","0.720"],["64632.30","0.001"],["64632.50","0.048"],["64632.70","0.000"],["64632.80","0.001"],["64633.00","0.064"],["64633.10","0.008"],["64633.30","0.021"],["64633.60","0.005"],["64633.80","4.339"],["64634.00","0.339"],["64634.10","0.096"],["64634.20","0.047"],["64634.60","0.443"],["64634.70","0.094"],["64634.80","0.005"],["64635.00","0.282"],["64635.20","0.002"],["64635.30","0.005"],["64635.40","0.047"],["64635.50","0.684"],["64635.60","0.372"],["64635.70","0.000"],["64635.80","0.009"],["64636.20","0.003"],["64636.30","0.077"],["64636.50","0.184"],["64636.80","0.016"],["64636.90","0.724"],["64637.00","0.388"],["64637.10","0.005"],["64637.20","0.083"],["64637.30","0.000"],["64637.40","0.016"],["64637.50","0.002"],["64637.60","0.001"],["64637.90","0.000"],["64638.10","0.002"],["64638.30","0.002"],["64638.50","0.049"],["64638.60","0.621"],["64638.70","0.449"],["64638.80","0.427"],["64639.10","0.313"],["64639.20","0.003"],["64639.40","0.500"],["64639.50","0.625"],["64639.60","0.000"],["64639.70","0.091"],["64639.80","1.230"],["64639.90","0.002"],["64640.00","5.723"],["64640.10","0.139"],["64640.20","0.001"],["64640.30","0.018"],["64640.40","0.253"],["64640.50","0.121"],["64640.70","0.116"],["64640.80","0.001"],["64640.90","0.031"],["64641.10","0.003"],["64641.30","0.294"],["64641.60","0.002"],["64641.80","0.542"],["64641.90","1.253"],["64642.00","0.569"],["64642.10","0.724"],["64642.20","0.164"],["64642.40","0.001"],["64642.50","0.006"],["64642.60","0.015"],["64642.90","0.505"],["64643.00","0.005"],["64643.10","0.001"],["64643.20","1.891"],["64643.40","0.001"],["64643.50","0.017"],["64643.60","0.003"],["64643.70","0.294"],["64643.80","0.002"],["64643.90","0.002"],["64644.00","0.002"],["64644.10","0.003"],["64644.20","0.253"],["64644.30","0.003"],["64644.40","0.556"],["64644.50","0.194"],["64644.70","0.003"],["64645.10","0.078"],["64645.20","0.435"],["64645.30","0.559"],["64645.40","0.104"],["64645.50","0.120"],["64645.60","0.003"],["64645.70","0.000"],["64645.80","0.000"],["64645.90","0.189"],["64646.00","0.003"],["64646.10","0.500"],["64646.30","0.120"],["64646.40","0.008"],["64646.50","0.465"],["64646.60","0.002"],["64646.70","0.004"],["64646.80","0.225"],["64647.10","0.002"],["64647.20","1.244"],["64647.30","0.120"],["64647.40","0.001"],["64647.50","0.000"],["64647.60","0.002"],["64647.70","0.001"],["64647.80","0.405"],["64648.00","0.007"],["64648.10","0.054"],["64648.20","0.188"],["64648.40","0.000"],["64648.50","0.011"],["64648.70","0.001"],["64648.80","0.003"],["64649.00","0.001"],["64649.20","0.000"],["64649.40","0.001"],["64649.50","0.260"],["64649.60","0.008"],["64649.70","0.093"],["64649.80","0.021"],["64649.90","4.393"],["64650.00","1.244"],["64650.10","0.563"],["64650.20","0.001"],["64650.30","0.005"],["64650.40","0.015"],["64650.60","0.000"],["64650.70","0.161"],["64651.00","0.001"],["64651.10","0.267"],["64651.20","0.001"],["64651.30","0.001"],["64651.50","0.000"],["64651.60","0.000"],["64651.70","0.020"],["64651.80","0.434"],["64651.90","0.090"],["64652.00","0.000"],["64652.20","0.120"],["64652.30","0.000"],["64652.40","0.003"],["64652.50","0.001"],["64652.80","0.001"],["64653.10","0.000"],["64653.20","0.310"],["64653.30","0.000"],["64653.40","0.131"],["64653.50","0.122"],["64653.60","1.850"],["64653.70","0.124"],["64653.80","0.001"],["64653.90","0.002"],["64654.00","5.995"]],"a":[["64650.00","0.000"],["64650.10","0.000"],["64650.20","0.000"],["64650.30","0.000"],["64650.40","0.000"],["64650.50","0.000"],["64650.70","0.000"],["64651.20","0.000"],["64651.30","0.000"],["64651.60","0.000"],["64651.70","0.000"],["64651.80","0.000"],["64651.90","0.000"],["64652.00","0.000"],["64652.10","0.000"],["64652.20","0.000"],["64652.30","0.000"],["64652.40","0.000"],["64652.50","0.000"],["64652.60","0.000"],["64652.70","0.000"],["64652.80","0.000"],["64653.10","0.000"],["64653.20","0.000"],["64653.30","0.000"],["64653.40","0.000"],["64653.60","0.000"],["64653.70","0.000"],["64653.80","0.000"],["64653.90","0.000"],["64654.00","0.000"],["64654.10","7.128"],["64654.20","0.003"],["64654.30","0.002"],["64654.40","0.001"],["64654.50","0.002"],["64654.80","0.000"],["64655.10","0.001"],["64655.20","0.002"],["64655.30","0.000"],["64655.50","0.000"],["64655.90","0.001"],["64656.00","0.004"],["64656.10","0.003"],["64656.20","0.001"],["64656.50","0.002"],["64656.60","0.004"],["64656.70","0.002"],["64656.80","0.000"],["64656.90","0.003"],["64657.00","0.014"],["64657.10","0.002"],["64657.20","0.001"],["64657.30","0.002"],["64657.40","0.001"],["64657.50","0.001"],["64657.60","0.006"],["64657.70","0.012"],["64657.80","0.312"],["64657.90","0.001"],["64658.00","0.001"],["64658.10","0.001"],["64658.20","0.007"],["64658.40","0.001"],["64658.60","0.061"],["64658.70","0.000"],["64659.00","0.130"],["64659.10","0.010"],["64659.30","0.026"],["64659.40","0.541"],["64659.50","0.281"],["64659.60","0.017"],["64659.70","0.001"],["64659.80","0.000"],["64659.90","0.000"],["64660.00","0.005"],["64660.10","1.277"],["64660.20","0.049"],["64660.30","1.431"],["64660.40","4.220"],["64660.50","0.049"],["64660.60","0.015"],["64660.70","0.001"],["64660.80","0.006"],["64660.90","0.000"],["64661.10","0.002"],["64661.40","0.001"],["64661.50","0.005"],["64661.60","0.001"],["64661.70","0.001"],["64661.80","0.001"],["64661.90","0.002"],["64662.00","0.190"],["64662.10","0.004"],["64662.20","0.785"],["64662.30","24.229"],["64662.40","0.266"],["64662.50","0.353"],["64662.60","0.039"],["64662.70","0.005"],["64662.80","0.002"],["64662.90","0.001"],["64663.00","0.075"],["64663.10","0.005"],["64663.20","0.008"],["64663.30","0.000"],["64663.40","0.012"],["64663.70","0.010"],["64663.80","0.001"],["64663.90","0.000"],["64664.10","0.000"],["64664.20","0.325"],["64664.30","0.001"],["64664.40","0.120"],["64664.60","0.002"],["64664.70","0.062"],["64664.80","0.003"],["64664.90","0.000"],["64665.10","0.003"],["64665.20","0.001"],["64665.50","0.002"],["64665.70","0.428"],["64665.80","0.000"],["64665.90","0.051"],["64666.10","0.000"],["64666.20","0.312"],["64666.30","0.040"],["64666.40","0.002"],["64666.50","0.000"],["64666.60","0.312"],["64666.70","0.018"],["64667.00","0.000"],["64667.60","0.001"],["64667.70","0.002"],["64667.80","0.556"],["64667.90","0.001"],["64668.10","0.004"],["64668.20","0.093"],["64668.30","0.000"],["64668.40","0.051"],["64668.50","0.013"],["64668.60","0.003"],["64668.70","0.087"],["64668.80","0.073"],["64669.00","0.011"],["64669.10","0.002"],["64669.20","0.554"],["64669.30","0.310"],["64669.40","0.001"],["64669.50","0.100"],["64669.60","0.000"],["64669.70","0.004"],["64669.80","0.005"],["64669.90","0.389"],["64670.00","0.180"],["64670.20","0.003"],["64670.30","0.001"],["64670.40","0.558"],["64670.50","0.000"],["64670.60","0.000"],["64670.70","0.000"],["64670.80","0.001"],["64671.00","0.002"],["64671.10","0.453"],["64671.20","0.003"],["64671.30","0.002"],["64671.50","0.079"],["64671.70","0.008"],["64671.80","0.154"],["64671.90","0.542"],["64672.00","1.644"],["64672.30","1.239"],["64672.50","0.028"],["64672.60","0.484"],["64672.70","0.003"],["64672.80","0.002"],["64672.90","0.001"],["64673.00","0.003"],["64673.10","0.001"],["64673.20","0.000"],["64673.30","0.000"],["64673.50","0.743"],["64673.60","0.563"],["64673.70","0.862"],["64673.90","0.046"],["64674.00","0.003"],["64674.10","0.087"],["64674.20","0.100"],["64674.30","1.548"],["64674.40","3.219"],["64674.60","0.000"],["64674.70","0.001"],["64674.90","0.114"],["64675.00","0.113"],["64675.10","0.049"],["64675.20","0.085"],["64675.30","0.083"],["64675.40","0.020"],["64675.50","0.033"],["64675.70","0.007"],["64675.80","0.034"],["64675.90","0.965"],["64676.10","0.301"],["64676.20","1.096"],["64676.30","0.031"],["64676.40","0.082"],["64676.60","0.000"],["64676.80","0.005"],["64676.90","0.251"],["64677.00","0.002"],["64677.10","0.039"],["64677.30","0.000"],["64677.40","0.380"],["64677.60","0.003"],["64677.80","0.051"],["64677.90","0.527"],["64678.30","0.106"],["64678.40","1.432"],["64678.80","1.873"],["64678.90","0.055"],["64679.00","0.242"],["64679.10","0.010"],["64679.30","0.001"],["64679.50","0.377"],["64679.80","0.014"],["64679.90","0.027"],["64680.00","0.745"],["64680.10","0.492"],["64680.20","1.161"],["64680.30","0.001"],["64680.40","0.000"],["64680.50","0.047"],["64680.80","0.080"],["64680.90","0.160"],["64681.10","0.015"],["64681.20","0.322"],["64681.30","0.000"],["64681.50","0.001"],["64681.60","0.004"],["64681.80","10.000"],["64682.00","0.602"],["64682.10","0.000"],["64682.20","0.896"],["64682.30","2.951"],["64682.40","0.009"],["64682.80","0.003"],["64682.90","0.001"],["64683.00","0.687"],["64683.10","0.556"],["64683.20","0.101"],["64683.30","0.433"],["64683.40","0.002"],["64683.50","0.031"],["64684.00","0.001"],["64684.10","0.059"],["64684.20","0.041"],["64684.30","0.038"],["64684.50","0.001"],["64684.70","0.011"],["64684.80","0.021"],["64685.00","0.001"],["64685.30","0.015"],["64685.60","1.238"],["64685.70","0.001"],["64685.80","0.015"],["64686.00","0.122"],["64686.20","0.014"],["64686.40","0.014"],["64686.60","0.320"],["64686.70","1.264"],["64686.80","7.646"],["64687.00","0.436"],["64687.40","0.002"],["64687.70","0.002"],["64688.20","0.001"],["64688.60","0.000"],["64688.80","0.000"],["64689.00","0.017"],["64689.40","0.000"],["64689.90","0.019"],["64690.20","0.005"],["64690.30","0.341"],["64690.60","0.651"],["64690.80","0.619"],["64690.90","0.000"],["64691.00","0.000"],["64691.10","0.021"],["64691.30","0.117"],["64691.60","0.002"],["64691.80","0.000"],["64692.10","1.237"],["64692.50","3.503"],["64692.70","0.137"],["64693.10","0.032"],["64693.20","0.012"],["64693.40","0.000"],["64693.50","0.311"],["64693.70","0.000"],["64693.80","0.004"],["64694.10","0.064"],["64694.20","0.095"],["64694.40","0.005"],["64694.50","0.588"],["64695.00","0.015"],["64695.20","0.061"],["64695.40","0.452"],["64695.90","0.000"],["64696.60","0.014"],["64696.80","0.002"],["64697.10","0.014"],["64697.20","0.017"],["64697.40","0.017"],["64697.80","0.000"],["64698.40","0.000"],["64698.50","0.000"],["64698.70","0.009"],["64699.00","0.021"],["64699.30","0.029"],["64699.40","0.002"],["64699.60","0.115"],["64699.80","5.131"],["64699.90","0.002"],["64700.60","0.000"],["64701.10","0.013"],["64701.20","0.002"],["64701.40","0.000"],["64701.50","0.000"],["64701.90","0.006"],["64702.10","0.000"],["64702.20","0.071"],["64702.30","0.556"],["64702.50","1.252"],["64702.60","0.000"],["64702.70","0.001"],["64702.80","0.000"],["64703.10","0.004"],["64703.40","0.000"],["64703.50","0.003"],["64703.60","0.471"],["64703.80","0.001"],["64704.20","0.059"],["64705.00","0.061"],["64705.10","0.004"],["64705.40","0.077"],["64706.00","0.005"],["64706.10","0.377"],["64706.80","0.001"],["64707.50","0.047"],["64707.70","0.223"],["64707.80","0.000"],["64708.00","0.074"],["64708.70","0.123"],["64709.60","0.342"],["64710.10","0.399"],["64710.30","0.003"],["64710.50","1.793"],["64710.60","0.692"],["64710.70","0.031"],["64711.30","0.001"],["64711.60","0.002"],["64711.90","0.000"],["64713.90","0.556"],["64714.40","0.001"],["64714.80","0.009"],["64715.50","0.005"],["64715.80","0.107"],["64717.00","0.000"],["64717.10","0.571"],["64717.20","2.739"],["64718.00","4.038"],["64718.20","0.226"],["64718.90","0.000"],["64719.10","0.021"],["64719.40","0.000"],["64720.10","0.000"],["64721.10","0.015"],["64721.70","24.162"],["64722.10","0.410"],["64725.70","0.001"],["64726.30","0.331"],["64728.30","10.816"],["64731.00","0.100"],["64731.30","0.310"],["64732.00","0.001"],["64732.70","0.002"],["64732.90","0.002"],["64734.00","0.094"],["64736.20","0.015"],["64736.50","0.000"],["64739.50","0.028"],["64741.20","0.002"],["64744.00","0.121"],["64747.40","0.005"],["64749.90","0.046"],["64751.00","0.123"],["64752.00","0.010"],["64756.40","0.001"],["64757.30","2.321"],["64757.40","0.001"],["64758.40","0.417"],["64759.70","0.003"],["64770.00","0.035"],["64774.50","0.244"],["64775.60","1.237"],["64776.80","0.001"],["64781.30","0.002"],["64790.50","0.001"],["64798.70","0.000"],["64799.20","0.000"],["64799.60","0.009"],["64800.20","0.007"],["64801.10","0.002"],["64801.60","0.000"],["64804.00","0.001"],["64805.60","0.958"],["64807.00","0.560"],["64808.00","0.010"],["64818.80","0.004"],["64822.80","0.856"],["64826.50","0.213"],["64836.20","0.003"],["64836.30","0.212"],["64839.10","0.020"],["64846.00","0.002"],["64903.80","0.001"],["64910.60","0.028"],["64915.10","0.000"],["64968.40","0.000"],["64973.20","3.303"],["64973.30","1.693"],["64975.30","0.001"],["64976.80","0.001"],["65033.10","0.001"],["65039.90","0.003"],["65068.40","0.000"],["65097.70","0.005"],["65100.70","0.002"],["65104.60","0.001"],["65133.10","0.000"],["65162.40","0.000"],["65165.40","0.127"],["65167.20","7.560"],["65169.20","0.001"],["65197.80","0.000"],["65230.10","0.000"],["65296.50","0.032"],["65297.00","0.016"],["65298.80","0.000"],["65300.60","0.857"],["65393.70","3.632"],["65394.10","3.760"],["65398.20","7.264"],["65458.40","2.268"],["65458.80","0.000"],["65462.10","0.759"],["65462.80","5.292"],["65514.50","0.000"],["65942.90","0.654"],["66500.00","75.421"]],"st":1}}
{"stream":"btcusdt@depth@100ms","data":{"e":"depthUpdate","E":1784410680346,"T":1784410680345,"s":"BTCUSDT","ps":"BTCUSDT","U":11079105568926,"u":11079105582948,"pu":11079105568889,"b":[["1000.00","50.391"],["14149.90","1.820"],["14154.00","0.182"],["14249.90","0.532"],["14254.00","0.168"],["14349.90","1.050"],["14554.00","0.168"],["32327.00","0.021"],["58188.60","0.002"],["61417.40","0.008"],["61421.30","0.000"],["63361.00","0.009"],["63501.40","0.000"],["63647.80","10.981"],["63788.70","3.131"],["64007.50","0.010"],["64062.40","7.601"],["64326.70","1.330"],["64330.80","0.002"],["64439.40","0.000"],["64455.50","0.982"],["64488.30","0.037"],["64489.10","0.172"],["64517.30","3.915"],["64517.80","0.011"],["64542.90","0.000"],["64554.30","0.000"],["64555.20","0.618"],["64559.90","0.005"],["64563.40","0.004"],["64566.00","0.030"],["64575.10","6.317"],["64579.10","0.000"],["64579.70","0.201"],["64581.50","0.001"],["64584.70","0.000"],["64585.30","0.102"],["64587.90","0.708"],["64589.30","0.052"],["64591.20","0.039"],["64592.00","3.253"],["64592.10","0.008"],["64592.60","0.341"],["64595.10","0.004"],["64598.70","0.002"],["64600.40","0.025"],["64600.90","22.781"],["64603.30","0.002"],["64604.30","0.000"],["64604.80","0.490"],["64606.90","0.102"],["64607.00","0.015"],["64607.60","0.082"],["64607.90","0.191"],["64612.10","0.200"],["64613.30","0.576"],["64614.90","0.293"],["64615.00","1.002"],["64615.20","0.602"],["64619.00","0.067"],["64619.20","0.001"],["64619.50","0.010"],["64620.30","0.002"],["64620.50","0.197"],["64622.80","0.001"],["64623.60","1.121"],["64623.90","0.001"],["64624.00","2.149"],["64625.40","0.000"],["64626.70","0.090"],["64627.00","0.716"],["64627.30","1.191"],["64627.60","0.774"],["64627.70","2.083"],["64628.20","0.057"],["64629.60","0.048"],["64630.50","0.033"],["64630.80","0.041"],["64631.40","1.201"],["64631.90","0.008"],["64632.00","0.771"],["64634.00","0.299"],["64634.60","0.445"],["64634.70","0.094"],["64634.80","0.002"],["64635.10","0.388"],["64635.30","0.005"],["64635.40","0.047"],["64635.50","0.682"],["64635.80","0.009"],["64635.90","0.197"],["64636.30","0.077"],["64636.50","0.104"],["64638.40","0.399"],["64638.80","0.271"],["64638.90","0.753"],["64639.00","0.683"],["64639.20","0.119"],["64639.50","1.401"],["64639.60","0.557"],["64639.90","0.543"],["64640.00","5.125"],["64640.50","0.005"],["64640.90","0.011"],["64641.70","0.001"],["64641.80","1.468"],["64641.90","0.327"],["64642.00","0.543"],["64642.10","0.193"],["64642.20","0.003"],["64642.30","0.008"],["64642.40","0.156"],["64642.70","0.023"],["64643.00","0.003"],["64643.30","0.074"],["64643.50","0.017"],["64643.70","0.174"],["64643.80","0.002"],["64643.90","0.002"],["64644.50","0.274"],["64644.70","0.003"],["64644.80","0.018"],["64645.00","0.003"],["64645.30","0.715"],["64645.60","0.159"],["64645.70","0.232"],["64645.90","0.123"],["64646.00","0.309"],["64646.10","0.503"],["64646.50","0.434"],["64646.60","0.140"],["64646.90","0.078"],["64647.00","0.382"],["64647.20","1.244"],["64647.30","0.097"],["64648.60","0.023"],["64648.80","0.004"],["64648.90","0.022"],["64649.90","4.277"],["64650.00","1.245"],["64650.10","0.556"],["64650.20","1.435"],["64650.30","0.067"],["64650.70","0.041"],["64651.50","0.003"],["64652.00","0.311"],["64652.30","0.634"],["64653.20","0.310"],["64653.30","0.000"],["64653.50","0.121"],["64653.60","0.098"],["64653.70","1.712"],["64653.90","0.289"],["64654.00","5.756"]],"a":[["64654.10","5.597"],["64655.90","0.003"],["64656.20","0.000"],["64656.40","0.001"],["64656.50","0.007"],["64656.60","0.008"],["64657.00","0.002"],["64657.10","0.002"],["64657.50","0.001"],["64657.60","0.006"],["64657.70","0.002"],["64657.80","0.312"],["64659.00","0.039"],["64659.10","0.008"],["64659.20","0.005"],["64659.30","0.339"],["64659.40","0.313"],["64659.60","0.000"],["64659.70","0.048"],["64659.80","0.032"],["64659.90","0.002"],["64660.00","0.563"],["64660.10","1.337"],["64660.20","0.002"],["64660.30","1.431"],["64660.50","0.082"],["64660.70","0.121"],["64661.00","0.004"],["64661.10","0.062"],["64661.20","0.010"],["64661.50","0.065"],["64661.90","0.004"],["64662.20","0.881"],["64662.30","24.229"],["64662.40","0.265"],["64662.50","0.444"],["64663.00","0.056"],["64663.20","0.006"],["64663.40","0.002"],["64664.60","0.025"],["64664.90","0.004"],["64665.00","0.362"],["64665.70","0.272"],["64666.80","0.003"],["64667.00","0.001"],["64667.10","0.025"],["64667.40","0.020"],["64668.10","0.002"],["64669.10","0.002"],["64670.10","0.006"],["64670.20","0.004"],["64670.30","0.542"],["64671.10","0.373"],["64671.90","0.001"],["64672.00","2.570"],["64673.40","0.076"],["64674.30","0.622"],["64675.00","0.115"],["64675.10","0.049"],["64675.30","0.085"],["64675.40","0.100"],["64675.70","0.010"],["64675.80","0.032"],["64675.90","0.965"],["64676.10","0.299"],["64676.50","0.001"],["64676.60","0.000"],["64676.90","0.251"],["64678.60","0.014"],["64678.80","1.845"],["64678.90","0.030"],["64680.00","0.688"],["64680.40","0.000"],["64680.60","0.010"],["64680.80","0.040"],["64681.10","0.003"],["64681.70","0.000"],["64681.80","10.002"],["64682.30","2.935"],["64682.60","0.104"],["64682.90","0.041"],["64685.10","0.001"],["64685.50","0.003"],["64686.10","0.050"],["64686.40","0.005"],["64686.70","1.254"],["64687.40","0.030"],["64689.50","0.025"],["64689.60","0.034"],["64690.10","0.000"],["64690.60","0.666"],["64692.00","0.002"],["64692.60","0.001"],["64692.70","0.144"],["64693.90","0.058"],["64694.10","0.001"],["64695.20","0.033"],["64695.60","0.100"],["64697.10","0.062"],["64699.40","0.002"],["64700.20","0.061"],["64700.30","0.053"],["64700.80","0.145"],["64701.20","0.062"],["64701.50","0.060"],["64703.20","0.019"],["64704.30","0.026"],["64705.80","0.001"],["64708.20","0.003"],["64710.60","0.694"],["64710.70","0.029"],["64712.30","0.004"],["64713.20","0.035"],["64713.70","0.000"],["64713.80","0.034"],["64717.80","0.049"],["64718.40","0.035"],["64718.50","0.001"],["64721.40","0.000"],["64721.70","0.003"],["64722.10","0.382"],["64722.40","0.012"],["64722.70","0.030"],["64724.40","0.003"],["64728.30","10.816"],["64732.70","24.172"],["64736.40","0.000"],["64737.30","0.205"],["64737.70","0.000"],["64748.00","0.059"],["64754.10","0.595"],["64765.10","1.126"],["64767.00","4.640"],["64769.50","24.270"],["64772.20","3.867"],["64773.90","0.000"],["64778.30","0.000"],["64784.40","0.001"],["64784.50","0.480"],["64798.90","0.000"],["64802.30","0.000"],["64802.40","1.466"],["64820.20","0.002"],["64820.30","1.467"],["64822.70","0.223"],["64823.60","0.000"],["64959.30","0.001"],["64973.20","3.149"],["65300.60","0.857"],["65393.70","0.000"],["65394.10","0.096"],["65394.60","0.000"],["65398.20","14.528"],["65429.80","0.611"],["65458.40","0.000"],["65462.10","0.003"],["65462.80","8.316"]],"st":1}}
{"stream":"btcusdt@depth@100ms","data":{"e":"depthUpdate","E":1784410680448,"T":1784410680445,"s":"BTCUSDT","ps":"BTCUSDT","U":11079105583003,"u":11079105591875,"pu":11079105582948,"b":[["14149.90","1.694"],["14154.00","0.294"],["14249.90","0.420"],["14254.00","0.280"],["14349.90","0.938"],["14554.00","0.294"],["58188.60","0.002"],["61421.30","0.002"],["62067.80","0.000"],["62765.60","0.002"],["63726.10","4.474"],["63893.50","2.735"],["64007.50","0.010"],["64035.70","7.235"],["64043.00","0.629"],["64058.50","0.000"],["64326.70","0.709"],["64540.00","0.061"],["64541.50","0.000"],["64542.50","0.000"],["64542.80","0.135"],["64543.00","0.061"],["64544.50","0.007"],["64546.00","0.039"],["64547.50","4.754"],["64549.00","0.013"],["64550.50","0.000"],["64552.00","0.018"],["64553.50","1.244"],["64583.00","0.013"],["64583.40","0.384"],["64600.90","0.146"],["64603.10","22.730"],["64604.40","0.010"],["64606.40","0.501"],["64607.00","0.013"],["64607.90","0.035"],["64608.10","0.349"],["64609.60","0.026"],["64612.80","0.545"],["64617.30","0.158"],["64620.50","0.183"],["64624.80","1.870"],["64626.60","0.053"],["64626.90","1.465"],["64629.00","0.016"],["64631.00","0.039"],["64632.10","0.001"],["64634.00","0.301"],["64634.60","0.443"],["64634.80","0.156"],["64634.90","0.165"],["64636.10","0.153"],["64636.50","0.008"],["64638.90","0.633"],["64639.50","1.245"],["64640.00","5.064"],["64640.40","0.179"],["64641.10","0.004"],["64643.00","0.005"],["64644.50","0.274"],["64645.50","0.240"],["64645.70","0.000"],["64646.00","0.533"],["64646.60","0.571"],["64647.20","1.305"],["64647.30","0.284"],["64647.50","0.001"],["64648.00","0.008"],["64648.20","0.000"],["64649.80","0.020"],["64649.90","4.253"],["64651.90","0.091"],["64653.70","1.713"],["64654.00","5.809"]],"a":[["64654.10","4.751"],["64655.30","0.001"],["64657.70","0.002"],["64659.20","0.005"],["64659.30","0.026"],["64659.40","0.000"],["64659.50","0.313"],["64659.70","0.053"],["64659.90","0.002"],["64660.10","1.429"],["64660.20","0.049"],["64660.50","0.081"],["64660.80","0.098"],["64661.20","0.070"],["64662.30","24.230"],["64672.00","2.474"],["64672.60","0.388"],["64676.10","0.299"],["64681.40","0.004"],["64683.00","0.662"],["64685.60","3.238"],["64685.70","1.857"],["64689.20","0.001"],["64689.30","0.317"],["64691.70","0.034"],["64691.80","0.040"],["64692.20","0.025"],["64694.80","0.153"],["64695.20","0.093"],["64695.70","0.094"],["64695.90","0.004"],["64698.80","0.096"],["64700.20","0.121"],["64700.90","0.010"],["64701.00","0.034"],["64701.20","0.002"],["64701.30","0.062"],["64701.50","0.000"],["64702.40","0.080"],["64704.40","0.781"],["64704.60","0.032"],["64705.00","0.124"],["64712.90","24.204"],["64713.20","0.003"],["64713.50","0.000"],["64714.10","3.824"],["64714.20","0.033"],["64715.20","6.031"],["64716.10","0.024"],["64717.30","11.647"],["64721.70","0.003"],["64721.80","0.001"],["64724.40","0.002"],["64732.70","0.002"],["64734.20","0.399"],["64737.30","0.204"],["64737.90","0.034"],["64748.60","0.070"],["64783.70","0.148"],["64784.80","0.013"],["64793.90","0.471"],["64795.80","0.073"],["64973.30","1.692"],["65025.50","0.000"],["65029.70","0.009"],["65297.10","0.038"],["65300.60","0.857"],["65301.30","0.008"],["65873.40","1.968"]],"st":1}}
{"stream":"btcusdt@depth@100ms","data":{"e":"depthUpdate","E":1784410680550,"T":1784410680549,"s":"BTCUSDT","ps":"BTCUSDT","U":11079105592396,"u":11079105607620,"pu":11079105591875,"b":[["1000.00","50.391"],["14149.90","1.582"],["14154.00","0.420"],["14249.90","0.294"],["14254.00","0.406"],["14349.90","0.812"],["14554.00","0.406"],["51723.00","0.004"],["58188.60","0.002"],["61421.30","0.002"],["62067.80","0.003"],["63356.90","6.698"],["63647.80","12.079"],["63853.40","1.563"],["63866.00","14.935"],["63971.80","0.702"],["64007.50","0.010"],["64068.00","6.777"],["64326.60","3.885"],["64330.70","0.048"],["64449.90","0.000"],["64452.00","0.200"],["64452.70","0.001"],["64457.40","0.004"],["64486.10","0.003"],["64542.80","0.096"],["64543.60","0.039"],["64549.60","0.000"],["64551.90","0.108"],["64552.50","0.003"],["64553.50","0.007"],["64563.40","0.000"],["64566.00","0.026"],["64568.60","0.004"],["64581.90","0.000"],["64582.30","0.772"],["64583.70","0.582"],["64598.70","22.637"],["64600.80","0.000"],["64603.10","0.095"],["64604.50","0.428"],["64611.80","0.109"],["64615.60","0.000"],["64617.80","0.017"],["64618.20","0.170"],["64622.20","0.007"],["64627.70","0.083"],["64628.70","0.003"],["64629.00","0.002"],["64631.80","10.013"],["64633.90","0.008"],["64634.60","0.441"],["64634.80","0.002"],["64636.50","0.088"],["64638.50","0.261"],["64639.10","0.157"],["64639.40","0.426"],["64639.50","1.065"],["64641.10","0.374"],["64642.00","0.002"],["64642.10","0.183"],["64642.30","0.001"],["64642.40","0.002"],["64643.30","0.064"],["64644.50","0.194"],["64645.30","0.345"],["64645.40","0.818"],["64645.90","0.355"],["64646.00","0.851"],["64646.10","1.234"],["64646.30","0.187"],["64646.60","0.339"],["64650.30","0.727"],["64650.40","0.078"],["64653.40","0.133"],["64654.00","5.809"]],"a":[["64654.10","4.746"],["64654.50","0.000"],["64656.60","0.006"],["64657.60","0.004"],["64657.70","0.004"],["64657.80","0.002"],["64659.20","0.015"],["64659.30","0.339"],["64659.40","0.313"],["64659.70","0.006"],["64659.80","0.345"],["64659.90","0.325"],["64660.00","0.876"],["64660.20","0.049"],["64660.30","1.431"],["64660.70","0.181"],["64660.80","0.159"],["64661.40","0.181"],["64661.50","0.125"],["64662.30","24.229"],["64663.80","0.002"],["64670.30","0.001"],["64671.90","0.542"],["64672.00","1.548"],["64673.50","1.669"],["64680.10","0.493"],["64685.60","1.238"],["64692.50","0.003"],["64695.20","0.153"],["64700.20","0.001"],["64700.80","0.205"],["64701.50","0.240"],["64704.10","0.003"],["64709.60","0.328"],["64712.90","24.172"],["64714.00","0.988"],["64715.20","0.031"],["64721.40","0.000"],["64743.00","0.391"],["64747.50","0.000"],["64759.70","0.000"],["64842.80","0.000"],["64843.40","43.505"],["64977.40","0.157"],["65171.30","0.305"],["65300.60","0.857"],["65499.90","0.450"]],"st":1}}
{"stream":"btcusdt@depth@100ms","data":{"e":"depthUpdate","E":1784410680652,"T":1784410680651,"s":"BTCUSDT","ps":"BTCUSDT","U":11079105607819,"u":11079105621100,"pu":11079105607620,"b":[["1000.00","50.391"],["14149.90","1.456"],["14154.00","0.532"],["14249.90","0.182"],["14254.00","0.518"],["14349.90","0.700"],["14554.00","0.532"],["51723.00","0.000"],["58188.60","0.002"],["61421.30","0.002"],["62067.80","0.000"],["63361.00","0.012"],["63699.50","5.486"],["63726.10","3.926"],["63992.90","0.000"],["64007.50","0.010"],["64016.30","2.025"],["64293.60","0.002"],["64294.30","0.698"],["64294.40","0.298"],["64326.60","4.040"],["64454.00","0.001"],["64457.40","0.000"],["64540.00","0.061"],["64541.50","0.000"],["64543.00","0.061"],["64544.50","0.007"],["64546.00","0.039"],["64547.50","4.754"],["64549.00","0.013"],["64550.50","0.000"],["64560.80","0.004"],["64582.70","0.000"],["64583.40","0.458"],["64592.50","0.338"],["64598.70","0.002"],["64600.40","0.000"],["64600.90","22.781"],["64617.30","0.002"],["64617.60","1.604"],["64620.90","0.055"],["64621.80","0.000"],["64626.00","0.003"],["64632.00","0.071"],["64634.80","0.156"],["64635.00","0.982"],["64639.40","0.276"],["64640.10","0.001"],["64640.20","0.003"],["64640.70","0.055"],["64644.80","0.327"],["64645.70","0.156"],["64646.00","1.007"],["64646.50","0.125"],["64649.90","4.249"],["64654.00","5.814"]],"a":[["64654.10","4.735"],["64658.40","0.001"],["64659.20","0.604"],["64659.70","0.319"],["64659.80","0.032"],["64659.90","0.002"],["64660.00","0.563"],["64660.10","1.429"],["64660.20","0.049"],["64660.80","0.219"],["64661.10","0.122"],["64661.60","0.001"],["64662.20","0.871"],["64662.30","24.229"],["64663.40","0.000"],["64664.70","0.060"],["64665.70","0.275"],["64666.00","0.003"],["64671.70","0.003"],["64674.50","1.957"],["64675.00","0.113"],["64681.80","0.002"],["64682.70","0.248"],["64687.40","0.040"],["64688.20","10.001"],["64689.90","0.009"],["64700.80","0.085"],["64700.90","0.010"],["64701.20","0.002"],["64713.80","0.002"],["64723.80","0.015"],["64739.50","0.013"],["65299.80","0.002"],["65300.60","0.857"],["65942.90","0.651"]],"st":1}}
{"stream":"btcusdt@depth@100ms","data":{"e":"depthUpdate","E":1784410680754,"T":1784410680753,"s":"BTCUSDT","ps":"BTCUSDT","U":11079105621133,"u":11079105628742,"pu":11079105621100,"b":[["14149.90","1.344"],["14154.00","0.434"],["14249.90","0.168"],["14254.00","0.644"],["14349.90","0.574"],["14554.00","0.756"],["58188.60","0.002"],["62067.80","0.003"],["63945.20","7.409"],["64007.50","0.010"],["64326.60","4.661"],["64326.70","0.709"],["64454.00","0.001"],["64457.40","0.004"],["64540.00","1.338"],["64541.50","1.277"],["64543.00","1.338"],["64543.60","0.000"],["64543.70","0.039"],["64544.50","1.284"],["64546.00","1.316"],["64547.50","6.031"],["64549.00","1.290"],["64550.50","1.277"],["64552.00","1.295"],["64553.50","1.284"],["64583.00","0.074"],["64583.70","0.643"],["64600.90","0.146"],["64603.10","22.730"],["64606.90","3.602"],["64608.10","0.193"],["64608.50","0.066"],["64608.60","0.250"],["64617.00","0.513"],["64618.30","0.395"],["64618.40","0.470"],["64618.50","0.050"],["64618.70","10.057"],["64618.80","0.002"],["64618.90","0.002"],["64623.10","0.717"],["64623.80","0.156"],["64625.80","0.169"],["64634.00","0.179"],["64634.20","0.049"],["64634.30","0.368"],["64634.40","0.012"],["64634.80","0.002"],["64638.10","0.124"],["64638.80","0.097"],["64638.90","0.091"],["64639.10","0.001"],["64639.50","0.927"],["64639.70","0.024"],["64639.80","0.842"],["64640.10","0.003"],["64647.80","0.343"],["64648.50","0.000"],["64649.90","4.247"],["64651.00","0.004"],["64653.80","0.002"],["64653.90","0.290"],["64654.00","5.814"]],"a":[["64655.00","0.002"],["64655.60","0.000"],["64656.30","0.001"],["64656.90","0.001"],["64657.60","0.002"],["64658.20","0.005"],["64659.20","0.007"],["64659.30","0.026"],["64659.40","0.000"],["64659.70","0.006"],["64659.80","0.032"],["64659.90","0.059"],["64660.00","0.876"],["64660.10","1.429"],["64660.20","0.206"],["64660.80","0.218"],["64661.60","0.001"],["64662.30","24.230"],["64664.60","0.023"],["64665.90","0.049"],["64683.00","1.366"],["64695.20","0.033"],["64695.80","0.154"],["64700.80","0.025"],["64701.30","0.002"],["64701.50","0.120"],["64710.80","24.200"],["64712.90","0.002"],["64714.20","0.001"],["64847.20","0.001"],["65178.60","0.027"],["65300.60","0.859"],["65612.70","0.760"],["65850.20","0.991"]],"st":1}}
{"stream":"btcusdt@depth@100ms","data":{"e":"depthUpdate","E":1784410680856,"T":1784410680853,"s":"BTCUSDT","ps":"BTCUSDT","U":11079105628749,"u":11079105639210,"pu":11079105628742,"b":[["1000.00","50.391"],["14149.90","1.218"],["14154.00","0.322"],["14254.00","0.756"],["14349.90","0.462"],["14554.00","0.994"],["58188.60","0.002"],["61421.30","0.002"],["63562.00","0.552"],["63699.50","6.035"],["63841.80","11.757"],["64007.50","0.010"],["64540.00","0.061"],["64541.50","0.000"],["64543.00","0.061"],["64544.50","0.007"],["64546.00","0.039"],["64547.50","4.754"],["64549.00","0.013"],["64550.50","0.000"],["64552.00","0.018"],["64553.50","0.007"],["64582.70","0.067"],["64610.60","0.006"],["64624.80","2.008"],["64634.00","0.177"],["64634.70","0.096"],["64634.80","0.002"],["64639.40","0.120"],["64648.60","0.000"],["64648.90","0.000"],["64649.70","0.116"],["64649.90","4.238"],["64650.00","1.341"],["64654.00","5.821"]],"a":[["64654.10","4.736"],["64657.50","0.024"],["64659.30","0.003"],["64659.40","0.587"],["64659.90","0.325"],["64660.00","0.876"],["64660.20","0.049"],["64663.50","0.180"],["64665.10","0.176"],["64666.80","0.177"],["64668.40","0.228"],["64674.50","1.955"],["64675.40","0.102"],["64681.50","0.701"],["64687.40","0.030"],["64688.30","0.011"],["64717.30","11.649"],["64840.70","0.091"],["65267.40","0.027"],["65300.60","0.857"],["65652.10","8.982"]],"st":1}}
{"stream":"btcusdt@depth@100ms","data":{"e":"depthUpdate","E":1784410680958,"T":1784410680957,"s":"BTCUSDT","ps":"BTCUSDT","U":11079105640050,"u":11079105660513,"pu":11079105639210,"b":[["1000.00","50.391"],["14149.90","1.106"],["14154.00","0.210"],["14254.00","0.868"],["14256.40","0.014"],["14349.90","0.336"],["14554.00","1.204"],["14554.10","0.014"],["58188.60","0.002"],["62067.80","0.000"],["62603.80","0.006"],["63641.90","0.000"],["63643.10","0.004"],["63643.20","0.000"],["63645.10","0.010"],["63647.20","0.011"],["63656.40","0.013"],["63674.30","1.649"],["63726.10","2.595"],["64007.50","0.010"],["64007.60","0.000"],["64009.80","0.008"],["64029.90","0.000"],["64033.50","0.005"],["64055.20","0.000"],["64452.70","0.157"],["64453.60","0.001"],["64457.40","0.000"],["64470.30","0.004"],["64489.10","0.016"],["64494.50","0.000"],["64517.30","3.914"],["64527.20","0.000"],["64533.70","0.112"],["64551.90","10.108"],["64553.50","0.007"],["64559.50","0.007"],["64560.50","0.093"],["64560.60","0.497"],["64560.80","0.000"],["64561.50","0.757"],["64563.40","0.000"],["64566.00","0.026"],["64566.40","1.063"],["64568.60","0.000"],["64572.90","0.281"],["64574.40","0.015"],["64576.20","0.004"],["64576.40","0.100"],["64577.40","0.001"],["64583.40","0.455"],["64584.20","6.000"],["64587.40","0.024"],["64589.90","0.005"],["64592.60","0.000"],["64593.30","0.048"],["64594.30","0.433"],["64596.50","22.639"],["64596.90","0.000"],["64598.70","0.002"],["64600.20","0.000"],["64600.50","0.002"],["64601.10","0.029"],["64601.20","0.000"],["64602.30","0.642"],["64603.10","0.126"],["64603.40","0.000"],["64604.90","0.000"],["64605.10","0.221"],["64605.70","0.027"],["64606.40","0.339"],["64606.50","0.002"],["64606.90","3.604"],["64607.00","0.001"],["64608.10","0.191"],["64610.30","0.490"],["64610.40","0.556"],["64610.60","0.002"],["64610.70","0.014"],["64611.00","0.024"],["64611.10","0.102"],["64611.20","0.073"],["64611.80","0.084"],["64612.70","0.012"],["64612.80","0.449"],["64613.00","1.003"],["64613.10","0.000"],["64613.20","0.061"],["64613.30","0.576"],["64613.60","0.193"],["64614.70","0.002"],["64614.80","0.005"],["64615.50","0.212"],["64617.40","0.001"],["64617.80","0.003"],["64618.30","0.396"],["64619.30","0.016"],["64619.50","0.001"],["64619.90","0.000"],["64620.00","0.007"],["64620.30","0.007"],["64620.70","2.524"],["64620.90","0.030"],["64621.10","0.556"],["64621.80","0.009"],["64622.10","0.165"],["64622.20","0.007"],["64622.40","0.004"],["64623.10","0.717"],["64623.30","0.000"],["64623.60","1.457"],["64623.70","0.024"],["64624.00","1.715"],["64624.20","0.141"],["64624.30","0.310"],["64624.40","0.003"],["64624.50","3.873"],["64624.70","0.882"],["64625.00","0.173"],["64625.10","0.007"],["64625.30","0.037"],["64625.40","0.000"],["64625.50","0.010"],["64626.30","0.387"],["64626.50","0.495"],["64626.60","0.084"],["64626.70","0.090"],["64627.50","0.017"],["64627.60","0.774"],["64627.70","0.068"],["64627.80","0.144"],["64628.10","0.975"],["64628.30","0.002"],["64628.90","0.001"],["64629.90","0.055"],["64630.00","0.136"],["64630.20","0.047"],["64630.60","1.291"],["64630.70","0.167"],["64631.20","0.009"],["64631.30","0.006"],["64631.40","1.194"],["64631.50","1.269"],["64631.80","0.015"],["64631.90","0.074"],["64632.10","0.001"],["64632.30","0.002"],["64632.50","0.060"],["64633.00","0.060"],["64633.50","1.639"],["64633.60","0.004"],["64633.80","4.339"],["64633.90","0.006"],["64634.10","0.081"],["64634.30","0.374"],["64634.50","0.370"],["64634.60","0.450"],["64634.70","0.094"],["64634.80","0.156"],["64634.90","0.164"],["64635.10","0.392"],["64635.30","0.000"],["64635.50","0.681"],["64635.60","0.001"],["64635.80","0.009"],["64636.00","0.035"],["64636.50","0.008"],["64636.70","1.730"],["64637.00","0.436"],["64637.10","0.008"],["64637.20","0.083"],["64637.40","0.001"],["64637.80","0.003"],["64638.00","0.787"],["64638.60","0.620"],["64638.90","0.002"],["64639.20","0.003"],["64639.50","0.097"],["64639.60","0.557"],["64639.70","0.024"],["64640.00","5.061"],["64640.20","0.002"],["64640.30","0.003"],["64640.40","0.181"],["64640.70","0.050"],["64640.90","0.003"],["64641.20","0.556"],["64641.30","0.289"],["64641.50","0.006"],["64642.30","0.155"],["64642.60","0.941"],["64643.50","0.002"],["64643.90","0.118"],["64644.00","0.002"],["64644.10","0.007"],["64644.30","0.002"],["64644.40","0.556"],["64644.50","0.194"],["64644.60","2.002"],["64644.80","0.319"],["64645.10","0.081"],["64645.30","0.441"],["64645.40","1.189"],["64645.60","0.161"],["64645.70","0.159"],["64645.90","0.123"],["64646.10","1.231"],["64646.30","0.187"],["64646.40","0.040"],["64646.60","0.338"],["64646.70","0.004"],["64646.80","0.091"],["64647.10","0.009"],["64647.30","0.096"],["64647.80","0.345"],["64648.00","0.009"],["64648.80","0.005"],["64649.00","0.002"],["64649.10","0.001"],["64649.20","0.134"],["64649.50","0.196"],["64649.90","4.231"],["64650.20","0.121"],["64650.30","0.173"],["64650.40","0.392"],["64650.70","0.001"],["64651.00","0.004"],["64651.10","0.002"],["64651.20","0.346"],["64651.40","0.001"],["64651.50","0.000"],["64651.70","0.000"],["64652.10","0.001"],["64652.30","0.002"],["64652.60","0.059"],["64652.70","0.001"],["64652.80","0.002"],["64653.10","0.001"],["64653.40","0.134"],["64653.50","0.121"],["64653.70","0.125"],["64653.90","0.288"],["64654.00","1.288"],["64654.10","3.071"],["64654.20","0.002"],["64654.30","0.378"],["64654.50","2.680"],["64654.80","0.001"],["64654.90","0.364"],["64655.00","0.002"],["64655.10","0.000"],["64655.20","0.000"],["64655.60","0.000"],["64655.70","0.000"],["64655.80","0.000"],["64655.90","0.002"],["64656.00","4.125"],["64656.30","0.004"],["64656.40","15.846"]],"a":[["64654.10","0.000"],["64654.20","0.000"],["64654.30","0.000"],["64654.40","0.000"],["64654.60","0.000"],["64654.90","0.000"],["64655.00","0.000"],["64655.10","0.000"],["64655.20","0.000"],["64655.30","0.000"],["64655.70","0.000"],["64655.80","0.000"],["64655.90","0.000"],["64656.00","0.000"],["64656.10","0.000"],["64656.30","0.000"],["64656.40","0.000"],["64656.50","1.682"],["64656.60","0.006"],["64656.90","0.000"],["64657.00","0.000"],["64657.30","0.000"],["64657.40","0.000"],["64657.50","0.001"],["64657.60","0.001"],["64657.70","0.001"],["64657.90","0.000"],["64658.10","0.000"],["64658.60","0.000"],["64659.10","0.031"],["64659.20","0.002"],["64659.30","0.592"],["64659.40","0.002"],["64659.50","0.159"],["64659.70","0.012"],["64659.80","0.345"],["64659.90","0.000"],["64660.00","0.005"],["64660.10","0.153"],["64660.20","0.002"],["64660.30","0.058"],["64660.40","0.002"],["64660.50","0.034"],["64660.60","0.015"],["64661.00","0.063"],["64661.20","0.060"],["64661.50","0.122"],["64661.90","0.002"],["64662.00","0.005"],["64662.10","0.004"],["64662.20","0.000"],["64662.40","0.007"],["64662.60","0.011"],["64662.80","0.001"],["64663.00","0.006"],["64663.30","0.002"],["64663.60","0.000"],["64663.70","0.001"],["64664.00","0.003"],["64664.20","0.015"],["64664.40","0.000"],["64664.70","0.076"],["64664.90","0.004"],["64665.40","0.000"],["64665.70","0.276"],["64665.80","0.009"],["64665.90","0.002"],["64666.30","0.001"],["64666.40","0.122"],["64666.50","0.000"],["64666.60","0.003"],["64666.70","0.002"],["64666.80","0.177"],["64666.90","0.155"],["64667.10","0.001"],["64667.30","0.392"],["64667.50","0.000"],["64667.80","0.000"],["64668.20","0.093"],["64668.40","0.181"],["64668.60","0.188"],["64668.70","0.000"],["64668.80","0.112"],["64669.00","0.001"],["64669.30","0.619"],["64669.50","0.000"],["64669.90","0.392"],["64670.00","0.121"],["64670.60","0.001"],["64670.90","0.020"],["64671.50","0.001"],["64671.60","0.001"],["64671.70","0.050"],["64671.80","0.308"],["64672.00","1.887"],["64672.20","0.150"],["64672.60","0.002"],["64673.40","0.624"],["64673.50","0.588"],["64673.60","0.564"],["64673.90","0.045"],["64674.20","0.100"],["64674.30","0.357"],["64675.00","0.017"],["64675.10","0.098"],["64675.20","0.038"],["64675.30","0.083"],["64675.40","0.020"],["64675.80","0.032"],["64675.90","0.193"],["64676.00","0.097"],["64676.40","0.930"],["64676.70","0.000"],["64676.90","0.251"],["64677.10","0.040"],["64677.50","0.003"],["64677.70","0.003"],["64677.80","0.129"],["64678.30","0.401"],["64678.40","1.433"],["64678.50","0.047"],["64678.70","0.006"],["64679.30","0.000"],["64679.50","0.373"],["64679.60","0.071"],["64680.00","0.650"],["64680.10","0.493"],["64680.30","0.001"],["64680.40","0.000"],["64680.50","0.000"],["64681.80","0.000"],["64682.20","0.865"],["64682.30","2.938"],["64682.70","0.193"],["64682.80","0.018"],["64682.90","0.041"],["64683.20","0.094"],["64683.30","0.395"],["64683.50","0.000"],["64684.00","0.001"],["64684.20","0.041"],["64684.30","0.106"],["64684.60","0.000"],["64684.80","0.021"],["64685.10","0.032"],["64685.30","0.015"],["64686.00","0.122"],["64686.20","0.014"],["64686.40","0.043"],["64686.60","0.165"],["64686.80","7.643"],["64687.50","2.183"],["64687.60","0.018"],["64688.00","1.822"],["64688.10","0.045"],["64688.20","0.001"],["64688.30","0.001"],["64689.00","0.002"],["64690.00","0.031"],["64690.60","0.666"],["64690.70","10.066"],["64691.10","0.006"],["64692.40","0.015"],["64693.40","0.000"],["64694.00","0.013"],["64694.10","0.048"],["64694.80","0.057"],["64695.00","0.000"],["64695.70","0.069"],["64696.80","0.049"],["64697.10","0.050"],["64697.20","0.029"],["64697.40","0.013"],["64697.50","0.311"],["64698.70","0.009"],["64698.80","0.000"],["64699.00","0.019"],["64699.10","3.503"],["64699.60","0.162"],["64700.20","0.005"],["64700.90","0.010"],["64701.00","0.035"],["64701.10","0.016"],["64701.50","0.000"],["64702.20","0.014"],["64702.30","0.603"],["64702.40","0.080"],["64702.50","1.237"],["64702.90","0.061"],["64704.10","0.000"],["64704.70","3.265"],["64705.10","0.051"],["64705.20","0.000"],["64706.10","0.346"],["64706.20","0.003"],["64706.80","0.001"],["64707.60","0.012"],["64707.80","0.047"],["64708.00","0.120"],["64710.80","0.030"],["64712.30","0.054"],["64712.40","1.808"],["64714.00","0.974"],["64714.20","0.000"],["64714.60","0.016"],["64714.80","0.000"],["64717.20","0.009"],["64717.30","0.053"],["64719.00","10.024"],["64719.60","0.000"],["64720.80","0.002"],["64720.90","0.000"],["64721.70","24.173"],["64721.80","6.001"],["64728.20","0.133"],["64730.00","11.624"],["64730.50","0.097"],["64736.20","0.000"],["64741.80","1.240"],["64754.10","10.595"],["64758.20","0.000"],["64758.50","0.928"],["64759.40","0.001"],["64760.40","0.001"],["64762.40","0.003"],["64764.30","0.000"],["64783.50","0.020"],["64785.60","0.004"],["64792.90","0.028"],["64795.40","0.000"],["64798.20","0.006"],["64798.70","0.009"],["64799.60","0.000"],["64799.90","0.580"],["64800.20","0.001"],["64805.60","0.000"],["64811.30","0.000"],["64811.60","0.001"],["64814.40","0.008"],["64817.80","0.005"],["64841.60","0.217"],["64861.50","0.028"],["64938.90","0.023"],["64947.20","0.045"],["65003.70","0.000"],["65036.00","0.000"],["65300.60","0.857"],["65300.70","0.000"],["65303.10","0.010"],["65947.20","0.003"],["65949.60","0.013"]],"st":1}}
{"stream":"btcusdt@depth@100ms","data":{"e":"depthUpdate","E":1784410681060,"T":1784410681059,"s":"BTCUSDT","ps":"BTCUSDT","U":11079105660534,"u":11079105704909,"pu":11079105660513,"b":[["14149.90","0.980"],["14154.00","0.084"],["14256.40","0.126"],["14349.90","0.224"],["14556.40","0.238"],["14556.80","0.014"],["58188.60","0.000"],["58190.70","0.002"],["61417.40","0.006"],["61417.50","0.013"],["62070.10","0.005"],["63363.30","0.006"],["63647.20","0.003"],["63647.80","10.981"],["63649.90","0.010"],["63656.40","0.027"],["63680.20","7.370"],["64009.80","0.004"],["64010.20","0.008"],["64010.40","0.000"],["64033.50","0.001"],["64035.30","0.004"],["64071.30","0.000"],["64075.30","0.016"],["64231.40","0.298"],["64235.50","0.023"],["64262.00","0.001"],["64268.90","0.003"],["64326.70","0.698"],["64330.70","0.058"],["64333.50","0.002"],["64378.40","0.117"],["64392.00","0.000"],["64396.10","0.008"],["64453.70","0.048"],["64454.00","0.001"],["64456.00","0.006"],["64456.40","0.014"],["64462.80","0.063"],["64478.20","0.000"],["64491.60","0.082"],["64500.10","0.716"],["64508.80","0.000"],["64520.60","0.119"],["64527.50","0.001"],["64535.40","0.001"],["64540.40","0.202"],["64541.80","0.003"],["64548.20","0.001"],["64552.50","0.000"],["64552.90","0.598"],["64553.00","1.611"],["64556.50","0.024"],["64557.10","0.004"],["64559.30","0.034"],["64559.80","0.021"],["64562.30","0.002"],["64567.70","0.001"],["64569.20","0.000"],["64571.00","0.001"],["64573.00","0.106"],["64574.00","0.001"],["64574.10","0.022"],["64575.10","6.302"],["64575.70","0.000"],["64576.20","0.000"],["64576.60","0.005"],["64577.20","0.001"],["64578.90","0.003"],["64579.20","0.008"],["64582.10","0.350"],["64582.30","0.787"],["64585.50","1.651"],["64587.70","0.003"],["64588.60","0.616"],["64589.00","0.024"],["64589.70","0.001"],["64590.80","0.210"],["64591.80","0.000"],["64592.00","0.003"],["64592.10","0.006"],["64592.30","0.001"],["64592.50","0.313"],["64594.30","0.418"],["64594.60","0.026"],["64594.90","0.048"],["64595.00","1.241"],["64595.10","0.004"],["64596.10","0.219"],["64596.50","0.004"],["64596.60","0.001"],["64596.90","0.025"],["64598.20","0.452"],["64598.30","0.387"],["64598.40","0.350"],["64598.70","0.002"],["64600.00","1.036"],["64600.90","22.783"],["64601.30","3.836"],["64602.40","0.115"],["64604.40","1.908"],["64604.50","0.635"],["64604.70","0.000"],["64605.10","0.011"],["64605.30","0.011"],["64605.60","0.040"],["64605.70","0.002"],["64606.00","0.014"],["64606.50","0.004"],["64607.20","1.034"],["64607.30","0.297"],["64608.10","0.189"],["64608.60","0.094"],["64610.20","0.015"],["64610.50","0.854"],["64610.60","0.002"],["64610.90","0.001"],["64611.10","0.258"],["64611.20","0.003"],["64611.30","0.070"],["64611.80","0.005"],["64612.80","0.029"],["64613.20","0.001"],["64613.30","0.556"],["64614.80","0.001"],["64615.30","0.003"],["64617.10","0.317"],["64617.60","1.684"],["64618.80","0.002"],["64619.00","0.037"],["64619.40","0.108"],["64619.90","0.011"],["64620.70","2.524"],["64621.40","0.372"],["64622.10","0.232"],["64622.20","0.027"],["64622.30","0.389"],["64623.80","0.312"],["64624.00","1.717"],["64624.20","0.764"],["64624.30","0.001"],["64624.50","3.858"],["64624.70","0.882"],["64624.80","2.008"],["64625.20","0.214"],["64625.30","0.006"],["64625.70","0.163"],["64625.80","0.169"],["64626.10","0.167"],["64626.20","0.031"],["64626.50","0.485"],["64626.60","0.053"],["64626.70","0.092"],["64627.00","0.716"],["64627.30","1.206"],["64627.40","0.557"],["64627.50","0.048"],["64628.00","0.312"],["64628.10","0.975"],["64628.20","0.000"],["64628.60","0.006"],["64628.70","0.031"],["64629.20","0.013"],["64629.30","0.100"],["64629.40","0.000"],["64629.60","0.048"],["64629.70","0.015"],["64629.80","0.006"],["64629.90","0.017"],["64630.10","0.664"],["64630.40","0.004"],["64630.50","0.467"],["64630.70","0.005"],["64630.90","0.002"],["64631.10","0.000"],["64631.80","0.013"],["64631.90","0.074"],["64632.30","0.014"],["64632.50","0.048"],["64632.60","0.001"],["64633.30","0.037"],["64633.50","1.630"],["64633.80","4.341"],["64633.90","0.072"],["64634.10","0.078"],["64634.20","0.051"],["64634.80","0.000"],["64635.10","0.445"],["64635.20","0.372"],["64635.90","0.197"],["64636.50","0.138"],["64636.80","0.016"],["64637.00","0.439"],["64637.10","0.004"],["64637.60","0.001"],["64637.80","0.002"],["64638.00","0.788"],["64638.60","0.617"],["64639.00","0.066"],["64639.60","0.000"],["64639.70","0.012"],["64639.90","0.001"],["64640.00","5.068"],["64640.10","0.003"],["64640.40","0.002"],["64640.80","0.003"],["64640.90","0.003"],["64641.00","0.005"],["64641.30","0.289"],["64641.50","0.006"],["64641.90","0.327"],["64642.10","0.001"],["64642.20","0.000"],["64642.40","0.001"],["64642.50","0.005"],["64642.60","0.015"],["64642.70","0.003"],["64643.20","1.896"],["64643.30","0.064"],["64643.60","0.002"],["64643.70","0.000"],["64643.80","0.179"],["64644.10","0.008"],["64644.50","0.194"],["64644.80","0.319"],["64644.90","0.557"],["64645.30","0.254"],["64645.40","1.364"],["64645.60","0.159"],["64645.70","0.156"],["64645.80","0.001"],["64646.10","2.226"],["64646.20","0.542"],["64646.40","0.966"],["64646.70","0.003"],["64646.90","0.079"],["64647.00","0.555"],["64647.10","0.025"],["64647.20","1.303"],["64647.30","0.099"],["64647.70","0.000"],["64647.80","0.572"],["64648.00","0.015"],["64648.50","0.032"],["64648.60","0.180"],["64648.80","0.002"],["64649.50","0.197"],["64649.60","0.009"],["64649.70","0.093"],["64649.90","2.994"],["64650.00","1.338"],["64650.30","0.007"],["64650.40","0.079"],["64650.50","0.017"],["64650.60","0.000"],["64650.70","1.272"],["64650.80","0.010"],["64651.20","0.004"],["64651.30","0.233"],["64651.50","0.001"],["64651.80","0.437"],["64652.00","0.314"],["64652.60","0.082"],["64652.70","0.010"],["64652.80","0.005"],["64653.30","0.001"],["64653.60","0.095"],["64653.80","0.002"],["64654.00","0.889"],["64654.10","0.405"],["64654.20","0.001"],["64654.30","0.000"],["64654.40","0.001"],["64654.50","0.010"],["64654.90","0.007"],["64655.20","0.040"],["64655.30","0.002"],["64655.90","0.002"],["64656.00","0.001"],["64656.10","0.001"],["64656.20","0.000"],["64656.30","0.004"],["64656.40","1.883"],["64656.50","6.449"],["64656.60","4.680"],["64656.70","0.002"],["64656.80","10.164"]],"a":[["64656.50","0.000"],["64656.60","0.000"],["64656.70","0.000"],["64656.90","0.404"],["64657.00","0.001"],["64657.10","0.000"],["64657.20","0.000"],["64657.50","0.000"],["64658.30","0.005"],["64659.10","0.007"],["64659.30","0.005"],["64659.50","0.035"],["64659.70","0.012"],["64659.80","0.032"],["64660.00","0.003"],["64660.30","0.001"],["64660.60","0.140"],["64660.70","0.181"],["64660.90","0.000"],["64661.40","0.180"],["64661.50","0.123"],["64661.90","0.000"],["64662.00","0.004"],["64662.10","1.281"],["64662.20","0.465"],["64662.30","24.229"],["64662.40","0.006"],["64662.70","0.008"],["64663.00","0.005"],["64663.10","0.002"],["64663.20","0.007"],["64663.50","0.001"],["64663.90","0.022"],["64664.50","0.005"],["64664.80","0.004"],["64664.90","0.001"],["64665.10","0.003"],["64665.70","0.003"],["64665.80","0.000"],["64666.40","0.002"],["64666.80","0.003"],["64666.90","0.001"],["64667.30","0.005"],["64667.40","0.000"],["64667.50","0.003"],["64667.70","0.004"],["64668.10","0.005"],["64668.20","0.020"],["64668.30","0.000"],["64668.40","0.004"],["64668.50","0.002"],["64668.80","0.116"],["64668.90","0.000"],["64669.00","0.020"],["64669.20","0.635"],["64669.30","0.309"],["64669.50","0.000"],["64669.90","0.512"],["64670.00","0.121"],["64670.10","0.005"],["64670.40","0.002"],["64670.50","0.001"],["64670.60","0.001"],["64670.90","0.000"],["64671.00","0.005"],["64671.10","0.002"],["64671.20","0.003"],["64671.30","0.002"],["64671.50","0.001"],["64671.70","0.003"],["64671.80","0.309"],["64671.90","0.001"],["64672.00","1.870"],["64672.30","0.002"],["64672.50","0.013"],["64673.30","0.000"],["64673.40","0.231"],["64673.50","0.155"],["64673.60","0.560"],["64673.70","0.863"],["64673.80","0.002"],["64673.90","0.002"],["64674.00","0.005"],["64674.10","0.097"],["64674.20","0.805"],["64674.40","0.122"],["64674.70","0.010"],["64674.80","0.047"],["64674.90","0.034"],["64675.20","0.038"],["64675.40","0.000"],["64675.50","0.042"],["64675.70","0.007"],["64675.90","0.194"],["64676.10","0.543"],["64676.20","1.116"],["64676.40","0.390"],["64676.80","0.003"],["64676.90","0.201"],["64677.20","0.310"],["64677.60","0.003"],["64677.70","0.003"],["64677.80","0.140"],["64677.90","0.000"],["64678.00","0.523"],["64678.10","0.003"],["64678.30","0.369"],["64678.60","0.015"],["64678.70","0.004"],["64678.80","2.732"],["64678.90","0.014"],["64679.10","0.080"],["64679.40","0.120"],["64679.60","0.069"],["64679.70","0.242"],["64679.80","0.014"],["64680.00","0.640"],["64680.10","0.589"],["64680.70","0.000"],["64681.10","0.003"],["64681.20","0.345"],["64681.60","0.004"],["64681.80","0.004"],["64681.90","0.001"],["64682.00","0.606"],["64682.20","0.820"],["64682.30","2.382"],["64682.40","0.782"],["64682.60","0.054"],["64682.80","0.016"],["64683.40","0.015"],["64683.70","0.002"],["64683.80","0.001"],["64684.30","0.082"],["64684.40","0.777"],["64684.70","0.000"],["64685.10","0.001"],["64685.30","0.014"],["64685.50","0.559"],["64685.60","1.239"],["64685.80","0.013"],["64686.00","0.033"],["64686.40","0.005"],["64686.60","0.187"],["64686.70","1.111"],["64686.90","24.116"],["64687.20","0.023"],["64687.30","0.031"],["64687.50","0.004"],["64687.70","0.071"],["64687.80","0.012"],["64688.00","1.888"],["64688.10","0.031"],["64688.80","0.007"],["64689.10","0.010"],["64689.40","0.016"],["64689.50","0.037"],["64689.60","0.073"],["64689.90","0.014"],["64690.30","0.845"],["64690.40","0.149"],["64690.60","0.706"],["64690.70","0.004"],["64690.80","3.724"],["64691.20","0.317"],["64691.30","0.096"],["64692.30","0.002"],["64692.60","0.001"],["64692.70","0.054"],["64693.10","0.032"],["64693.50","0.861"],["64694.00","0.003"],["64694.20","0.095"],["64694.60","0.000"],["64694.70","0.010"],["64694.90","0.047"],["64695.10","0.000"],["64695.20","0.033"],["64695.70","0.004"],["64695.80","0.000"],["64696.70","0.001"],["64697.00","0.014"],["64697.20","0.015"],["64698.40","0.000"],["64698.50","0.009"],["64698.90","0.009"],["64699.00","0.002"],["64699.30","0.179"],["64699.40","0.014"],["64699.90","0.122"],["64700.30","0.053"],["64701.30","0.000"],["64701.90","0.000"],["64702.20","0.428"],["64702.90","0.001"],["64704.00","0.024"],["64704.30","0.002"],["64704.50","0.030"],["64704.60","0.032"],["64704.70","0.083"],["64704.90","0.072"],["64706.10","0.411"],["64706.40","0.003"],["64706.70","0.029"],["64707.40","0.018"],["64708.00","0.393"],["64708.20","0.009"],["64708.90","0.016"],["64710.40","0.681"],["64710.60","0.315"],["64710.70","0.004"],["64710.80","0.005"],["64711.00","0.028"],["64712.30","0.456"],["64712.50","0.001"],["64712.90","0.000"],["64713.70","0.002"],["64714.00","0.974"],["64714.10","3.826"],["64714.20","0.000"],["64715.20","0.003"],["64715.40","0.000"],["64717.30","0.025"],["64717.50","0.064"],["64717.60","0.984"],["64717.90","0.000"],["64718.20","0.016"],["64719.00","0.024"],["64719.10","0.021"],["64719.20","0.000"],["64719.30","0.019"],["64720.10","0.133"],["64720.20","0.556"],["64720.30","5.179"],["64721.20","0.000"],["64721.40","0.210"],["64721.60","0.168"],["64721.70","24.173"],["64722.70","0.000"],["64723.30","0.448"],["64723.70","1.835"],["64723.80","10.000"],["64724.50","0.100"],["64724.60","1.238"],["64725.00","0.052"],["64725.40","0.002"],["64726.30","0.331"],["64727.70","0.000"],["64729.40","0.047"],["64729.60","0.016"],["64729.90","1.930"],["64730.20","0.152"],["64730.50","0.000"],["64732.10","0.013"],["64732.60","0.582"],["64734.60","3.767"],["64734.90","0.447"],["64735.20","0.002"],["64736.00","0.035"],["64736.30","0.546"],["64737.90","0.006"],["64738.80","0.029"],["64739.40","0.026"],["64740.60","0.000"],["64741.50","0.169"],["64742.20","0.195"],["64744.50","0.033"],["64746.90","0.015"],["64750.20","0.030"],["64750.80","0.042"],["64751.00","0.125"],["64751.30","0.015"],["64752.00","0.002"],["64754.00","0.022"],["64754.10","10.007"],["64761.00","0.068"],["64761.40","0.001"],["64762.00","0.059"],["64767.80","1.047"],["64771.20","0.994"],["64773.00","0.000"],["64785.60","0.000"],["64786.80","0.956"],["64786.90","0.036"],["64798.20","0.000"],["64798.70","0.000"],["64801.70","0.000"],["64802.90","0.004"],["64806.30","0.000"],["64807.00","0.556"],["64808.00","1.081"],["64811.40","0.004"],["64813.90","0.099"],["64814.40","0.004"],["64815.30","0.321"],["64816.20","0.000"],["64817.80","0.001"],["64818.40","0.004"],["64819.50","0.002"],["64827.90","0.012"],["64843.40","43.502"],["64843.80","0.004"],["64886.00","2.288"],["64908.80","0.227"],["64912.90","0.005"],["65071.00","0.025"],["65075.20","0.013"],["65233.70","0.002"],["65237.80","0.016"],["65262.00","0.000"],["65268.00","0.976"],["65303.10","0.002"],["65303.50","0.073"],["65398.20","0.000"],["65400.50","16.056"],["65462.80","0.000"],["65465.20","9.079"],["65641.00","0.016"],["65942.90","0.648"]],"st":1}}
