{"stream":"btcusdt@depth@100ms","data":{"e":"depthUpdate","E":1784410629442,"T":1784410629441,"s":"BTCUSDT","ps":"BTCUSDT","U":11079102155344,"u":11079102164454,"pu":11079102154995,"b":[["14147.20","0.238"],["14349.90","1.218"],["14447.20","1.106"],["14449.90","0.000"],["14549.90","0.784"],["58184.90","0.002"],["61417.40","0.000"],["62063.90","0.000"],["63839.10","1.513"],["64003.40","0.000"],["64324.00","2.483"],["64326.70","0.013"],["64332.70","0.000"],["64537.40","0.000"],["64538.90","0.004"],["64540.40","0.202"],["64541.90","0.000"],["64543.40","0.000"],["64544.90","0.000"],["64546.40","0.556"],["64547.90","0.000"],["64550.80","0.003"],["64583.10","0.000"],["64596.50","0.158"],["64614.20","0.016"],["64614.30","0.558"],["64614.40","0.170"],["64614.70","0.160"],["64614.80","0.008"],["64614.90","0.040"],["64630.10","0.004"],["64630.20","0.055"],["64630.30","0.389"],["64630.80","0.178"],["64633.00","0.215"],["64635.10","0.393"],["64648.80","0.002"],["64649.90","13.871"]],"a":[["64650.00","1.662"],["64652.10","0.001"],["64652.40","0.003"],["64653.70","0.162"],["64654.80","0.070"],["64655.70","0.002"],["64656.50","0.172"],["64660.30","0.469"],["64661.20","0.047"],["64662.10","0.312"],["64662.20","0.729"],["64674.20","0.162"],["64691.40","0.156"],["64979.40","0.177"],["65174.90","0.000"],["65296.50","0.003"],["65382.10","0.764"],["65938.10","0.463"]],"st":1}}
{"stream":"btcusdt@depth@100ms","data":{"e":"depthUpdate","E":1784410629544,"T":1784410629541,"s":"BTCUSDT","ps":"BTCUSDT","U":11079102164491,"u":11079102174239,"pu":11079102164454,"b":[["1000.00","50.241"],["14147.20","0.126"],["14349.90","1.456"],["14447.20","0.868"],["14549.90","0.896"],["51719.90","0.000"],["58184.90","0.002"],["61417.40","0.000"],["62063.90","0.003"],["63450.50","0.000"],["63833.60","24.554"],["63841.80","0.266"],["64003.40","0.000"],["64451.80","0.972"],["64633.00","0.061"],["64647.00","0.002"],["64647.10","0.002"],["64647.70","0.001"],["64647.80","0.170"],["64648.50","0.023"],["64649.40","0.000"],["64649.90","13.103"]],"a":[["64650.00","2.169"],["64652.10","0.048"],["64652.70","0.001"],["64653.40","0.143"],["64653.70","0.162"],["64654.80","0.023"],["64654.90","0.050"],["64655.40","0.000"],["64656.50","0.172"],["64677.80","0.091"],["64678.10","0.607"],["64680.10","1.355"],["64681.30","0.516"],["64689.90","10.009"],["64692.30","0.380"],["64973.10","0.186"],["65167.10","0.305"],["65296.50","0.001"],["65425.70","2.055"],["65938.10","0.460"]],"st":1}}
{"stream":"btcusdt@depth@100ms","data":{"e":"depthUpdate","E":1784410629646,"T":1784410629645,"s":"BTCUSDT","ps":"BTCUSDT","U":11079102174574,"u":11079102185953,"pu":11079102174239,"b":[["14147.20","0.000"],["14249.90","0.084"],["14349.90","1.526"],["14447.20","0.714"],["14549.90","1.022"],["51720.00","0.004"],["58184.90","0.002"],["61417.40","0.000"],["62063.90","0.000"],["63357.00","0.011"],["63580.50","0.707"],["63756.00","0.001"],["64003.40","0.000"],["64207.10","0.000"],["64323.90","0.008"],["64324.00","2.638"],["64447.20","0.000"],["64517.10","0.000"],["64517.30","0.608"],["64520.90","3.867"],["64576.90","0.000"],["64580.10","0.206"],["64609.30","0.109"],["64615.70","0.000"],["64622.20","0.007"],["64633.00","0.061"],["64633.50","1.599"],["64636.20","0.522"],["64636.30","10.160"],["64638.30","0.932"],["64638.80","0.402"],["64640.00","0.726"],["64640.50","0.125"],["64640.70","0.056"],["64641.30","0.289"],["64641.60","0.387"],["64643.40","0.007"],["64645.10","0.281"],["64646.60","0.032"],["64647.80","0.168"],["64647.90","0.439"],["64649.40","0.002"],["64649.90","13.567"]],"a":[["64650.00","1.171"],["64650.10","0.000"],["64651.70","0.010"],["64652.10","0.001"],["64652.20","0.002"],["64652.90","0.000"],["64653.30","0.005"],["64654.40","0.001"],["64654.70","0.000"],["64654.90","0.003"],["64655.10","0.048"],["64656.20","0.001"],["64656.50","0.172"],["64656.60","0.617"],["64658.50","0.180"],["64658.60","0.276"],["64665.10","0.506"],["64666.00","2.005"],["64667.60","0.048"],["64668.70","0.005"],["64670.60","0.008"],["64678.10","0.050"],["64678.70","0.557"],["64679.30","0.001"],["64679.60","0.008"],["64689.90","0.011"],["64690.10","0.032"],["64692.40","10.004"],["64693.70","0.000"],["64712.90","0.002"],["64715.10","22.816"],["64719.30","0.004"],["64721.70","0.003"],["64722.40","0.059"],["64771.20","0.538"],["64774.00","0.000"],["64776.50","3.880"],["64973.30","0.002"],["65296.50","0.001"],["65393.70","13.620"]],"st":1}}
{"stream":"btcusdt@depth@100ms","data":{"e":"depthUpdate","E":1784410629748,"T":1784410629746,"s":"BTCUSDT","ps":"BTCUSDT","U":11079102186021,"u":11079102197205,"pu":11079102185953,"b":[["14249.90","0.210"],["14349.90","1.512"],["14447.20","0.602"],["14449.90","0.112"],["14549.90","0.910"],["51720.00","0.004"],["58184.90","0.002"],["61417.40","0.000"],["63729.20","0.273"],["63809.50","0.314"],["64003.40","0.000"],["64106.80","0.008"],["64326.70","0.013"],["64447.20","0.000"],["64476.60","0.200"],["64521.50","1.366"],["64591.60","0.104"],["64591.80","0.315"],["64607.60","0.082"],["64614.00","0.741"],["64632.70","10.001"],["64633.00","0.215"],["64633.50","2.879"],["64636.30","0.160"],["64636.40","1.064"],["64638.80","0.943"],["64640.00","0.185"],["64646.60","0.054"],["64647.20","2.223"],["64647.90","0.380"],["64648.20","0.000"],["64649.00","0.000"],["64649.40","0.000"],["64649.90","12.648"]],"a":[["64650.00","1.708"],["64650.10","0.002"],["64653.00","0.002"],["64653.20","0.052"],["64653.60","0.000"],["64653.80","1.275"],["64656.50","0.172"],["64679.60","1.206"],["64679.80","0.063"],["64683.70","0.002"],["64688.60","2.000"],["64692.40","0.004"],["64714.70","4.652"],["64966.40","0.228"],["65296.50","0.003"],["65482.60","0.101"],["65806.10","0.000"],["65942.90","0.636"]],"st":1}}
{"stream":"btcusdt@depth@100ms","data":{"e":"depthUpdate","E":1784410629850,"T":1784410629849,"s":"BTCUSDT","ps":"BTCUSDT","U":11079102197322,"u":11079102208156,"pu":11079102197205,"b":[["1000.00","50.241"],["14249.90","0.322"],["14349.90","1.526"],["14447.20","0.476"],["14449.90","0.238"],["14549.90","0.784"],["58184.90","0.002"],["61417.40","0.000"],["62063.90","0.003"],["63876.20","6.200"],["64003.40","0.002"],["64088.50","0.125"],["64090.60","0.008"],["64323.90","0.007"],["64327.70","0.002"],["64329.80","0.154"],["64375.10","0.117"],["64378.40","0.000"],["64449.90","0.000"],["64452.70","0.000"],["64494.50","0.000"],["64495.20","0.716"],["64501.20","0.000"],["64537.40","0.000"],["64538.90","0.004"],["64540.40","0.000"],["64540.50","0.006"],["64541.90","0.000"],["64543.40","0.000"],["64544.90","0.000"],["64546.40","0.556"],["64547.90","0.000"],["64562.60","0.349"],["64647.20","2.223"],["64648.20","0.000"],["64649.90","12.649"]],"a":[["64653.00","0.000"],["64653.20","0.005"],["64653.70","0.209"],["64656.50","0.172"],["64658.90","0.002"],["64668.60","0.018"],["64675.90","0.975"],["64683.70","0.079"],["64713.80","0.017"],["64721.10","0.000"],["64752.60","0.043"],["64753.80","0.000"],["64803.60","2.291"],["64803.70","0.000"],["64973.30","0.003"],["65296.50","0.001"]],"st":1}}
{"stream":"btcusdt@depth@100ms","data":{"e":"depthUpdate","E":1784410629952,"T":1784410629951,"s":"BTCUSDT","ps":"BTCUSDT","U":11079102208272,"u":11079102218096,"pu":11079102208156,"b":[["14249.90","0.448"],["14349.90","1.512"],["14447.20","0.364"],["14449.90","0.350"],["14549.90","0.672"],["58184.90","0.002"],["61417.40","0.000"],["62063.90","0.000"],["63357.00","0.014"],["63828.10","1.096"],["64003.40","0.000"],["64421.30","0.828"],["64518.40","0.096"],["64543.60","0.039"],["64544.50","0.007"],["64633.00","0.061"],["64643.40","0.005"],["64647.20","2.219"],["64648.20","0.000"],["64649.40","0.000"],["64649.90","12.652"]],"a":[["64653.00","0.000"],["64653.20","0.005"],["64653.60","0.000"],["64653.70","0.162"],["64656.50","0.759"],["64657.10","0.002"],["64683.70","0.002"],["65296.50","0.001"],["65482.90","6.381"],["65648.40","0.000"]],"st":1}}
{"stream":"btcusdt@depth@100ms","data":{"e":"depthUpdate","E":1784410630054,"T":1784410630053,"s":"BTCUSDT","ps":"BTCUSDT","U":11079102218239,"u":11079102228901,"pu":11079102218096,"b":[["1000.00","50.241"],["14249.90","0.560"],["14349.90","1.526"],["14447.20","0.238"],["14449.90","0.476"],["14549.90","0.546"],["58184.90","0.002"],["61417.40","0.000"],["62063.90","0.003"],["63874.10","1.577"],["64003.40","0.000"],["64297.30","0.018"],["64326.70","0.003"],["64544.90","0.000"],["64546.40","1.833"],["64547.90","1.277"],["64624.80","0.013"],["64631.30","0.007"],["64631.50","1.219"],["64633.90","0.017"],["64636.10","0.217"],["64638.30","0.937"],["64649.90","12.576"]],"a":[["64650.00","1.856"],["64652.80","0.049"],["64652.90","0.000"],["64653.00","0.000"],["64656.50","0.759"],["64665.70","0.975"],["64665.90","0.051"],["64668.70","0.546"],["64669.10","0.004"],["64669.20","0.050"],["64669.30","0.332"],["64669.70","0.560"],["64670.50","1.006"],["64671.40","0.003"],["64678.40","0.081"],["64680.10","1.298"],["64680.20","1.790"],["64681.40","0.044"],["64685.50","0.021"],["64685.60","0.003"],["64685.70","0.201"],["64686.00","0.004"],["64686.10","0.065"],["64686.20","0.116"],["65296.50","0.001"],["65427.70","13.744"],["65833.30","0.704"],["65938.10","0.457"]],"st":1}}
{"stream":"btcusdt@depth@100ms","data":{"e":"depthUpdate","E":1784410630156,"T":1784410630155,"s":"BTCUSDT","ps":"BTCUSDT","U":11079102229061,"u":11079102241655,"pu":11079102228901,"b":[["1000.00","50.241"],["14249.90","0.686"],["14349.90","1.512"],["14447.20","0.126"],["14449.90","0.588"],["14549.90","0.434"],["58184.90","0.002"],["61407.00","0.002"],["62063.90","0.000"],["64003.40","0.000"],["64633.00","0.215"],["64635.90","0.233"],["64636.90","0.007"],["64637.20","0.083"],["64638.00","0.256"],["64638.20","1.048"],["64638.30","0.932"],["64645.10","0.237"],["64645.20","0.854"],["64649.90","12.619"]],"a":[["64650.00","1.697"],["64652.80","0.002"],["64656.50","0.759"],["64656.60","0.570"],["64657.30","0.081"],["64660.70","0.000"],["64669.60","0.000"],["64670.00","0.151"],["64670.50","0.080"],["64670.60","0.934"],["64677.00","0.034"],["64678.00","0.721"],["64678.70","0.001"],["64683.70","0.002"],["65296.50","0.001"],["65587.30","0.609"]],"st":1}}
{"stream":"btcusdt@depth@100ms","data":{"e":"depthUpdate","E":1784410630258,"T":1784410630256,"s":"BTCUSDT","ps":"BTCUSDT","U":11079102241817,"u":11079102253324,"pu":11079102241655,"b":[["14249.90","0.798"],["14349.90","1.526"],["14447.20","0.000"],["14449.90","0.714"],["14549.90","0.308"],["58184.90","0.002"],["61417.40","0.000"],["64003.40","0.000"],["64421.30","0.833"],["64447.20","0.000"],["64546.40","0.556"],["64549.40","1.312"],["64622.60","0.005"],["64623.70","0.025"],["64625.50","0.059"],["64626.30","0.399"],["64627.40","0.580"],["64637.40","0.927"],["64638.20","0.122"],["64638.30","1.473"],["64638.50","0.135"],["64638.70","0.629"],["64638.80","0.402"],["64639.00","0.163"],["64640.00","0.185"],["64646.50","0.126"],["64646.60","0.032"]],"a":[["64650.00","1.845"],["64652.10","0.001"],["64652.40","0.003"],["64652.70","0.001"],["64653.00","0.000"],["64653.30","0.006"],["64653.40","0.143"],["64653.60","0.000"],["64653.70","0.749"],["64654.00","0.006"],["64654.30","0.003"],["64656.50","0.329"],["64657.10","0.029"],["64668.70","0.546"],["64669.60","0.000"],["64670.30","0.927"],["64670.60","0.008"],["64671.30","0.002"],["64677.30","0.672"],["64678.40","0.024"],["64679.20","0.000"],["65296.50","0.001"],["65579.90","1.281"]],"st":1}}
{"stream":"btcusdt@depth@100ms","data":{"e":"depthUpdate","E":1784410630360,"T":1784410630356,"s":"BTCUSDT","ps":"BTCUSDT","U":11079102253506,"u":11079102263883,"pu":11079102253324,"b":[["1000.00","50.241"],["14249.90","1.036"],["14349.90","1.288"],["14449.90","0.826"],["14549.90","0.196"],["58184.90","0.002"],["61417.40","0.000"],["62063.90","0.003"],["64003.40","0.000"],["64326.70","0.003"],["64633.00","0.215"],["64647.40","0.002"],["64649.90","12.611"]],"a":[["64652.80","0.002"],["64653.10","0.048"],["64653.70","0.162"],["64656.50","0.172"],["64659.50","0.184"],["64677.30","0.615"],["64677.80","0.148"],["64678.70","0.008"],["64679.60","1.199"],["65296.50","0.001"],["65425.80","1.527"],["65458.10","0.992"]],"st":1}}
{"stream":"btcusdt@depth@100ms","data":{"e":"depthUpdate","E":1784410630462,"T":1784410630461,"s":"BTCUSDT","ps":"BTCUSDT","U":11079102264255,"u":11079102273208,"pu":11079102263883,"b":[["1000.00","50.241"],["14249.90","1.274"],["14347.20","0.364"],["14349.90","1.162"],["14449.90","0.952"],["14549.90","0.070"],["51720.00","0.004"],["58184.90","0.002"],["61417.40","0.000"],["62063.90","0.000"],["63486.20","0.378"],["63964.40","0.151"],["64003.40","0.000"],["64104.20","0.000"],["64297.30","0.023"],["64374.20","0.000"],["64495.60","0.007"],["64546.50","0.000"],["64550.90","1.290"],["64616.30","0.000"],["64634.50","0.002"],["64637.60","0.157"],["64640.30","0.337"],["64642.00","0.019"],["64647.30","0.735"],["64649.70","0.004"]],"a":[["64653.70","0.162"],["64656.50","0.172"],["64657.80","0.002"],["65296.50","0.001"],["65361.10","1.913"]],"st":1}}
{"stream":"btcusdt@depth@100ms","data":{"e":"depthUpdate","E":1784410630564,"T":1784410630562,"s":"BTCUSDT","ps":"BTCUSDT","U":11079102273461,"u":11079102283642,"pu":11079102273208,"b":[["14249.90","1.512"],["14347.20","0.238"],["14349.90","1.050"],["14449.90","1.064"],["14547.20","0.336"],["14549.90","0.000"],["51719.90","0.000"],["58184.90","0.002"],["61417.40","0.000"],["62063.90","0.003"],["63777.10","0.626"],["64003.40","0.000"],["64106.80","0.001"],["64253.40","0.013"],["64374.70","0.005"],["64621.00","0.701"],["64628.80","0.006"],["64632.70","10.003"],["64633.00","0.061"],["64633.80","1.419"],["64635.90","0.117"],["64636.30","0.276"],["64636.80","0.006"],["64649.90","12.559"]],"a":[["64650.00","1.697"],["64653.10","0.001"],["64653.70","0.162"],["64654.40","0.001"],["64654.50","0.003"],["64656.50","0.329"],["64658.50","0.304"],["64658.60","0.152"],["64662.90","0.035"],["64684.20","10.001"],["64688.60","0.000"],["64714.80","6.000"],["64715.10","22.818"],["65296.50","0.001"]],"st":1}}
{"stream":"btcusdt@depth@100ms","data":{"e":"depthUpdate","E":1784410630666,"T":1784410630665,"s":"BTCUSDT","ps":"BTCUSDT","U":11079102283875,"u":11079102295142,"pu":11079102283642,"b":[["1000.00","50.241"],["14249.90","1.750"],["14347.20","0.126"],["14349.90","0.924"],["14449.90","1.190"],["14547.20","0.210"],["58184.90","0.002"],["61414.80","0.002"],["61414.90","0.004"],["63935.80","0.875"],["64003.40","0.000"],["64101.10","0.000"],["64326.70","0.013"],["64580.50","2.633"],["64618.40","0.528"],["64623.70","1.032"],["64628.80","0.004"],["64631.00","0.006"],["64636.20","0.522"],["64636.70","0.951"],["64640.40","0.122"],["64642.00","0.029"],["64648.00","0.004"],["64649.70","0.001"],["64649.90","12.478"]],"a":[["64653.70","0.209"],["64654.20","0.000"],["64654.30","0.003"],["64654.40","0.001"],["64656.50","0.172"],["64668.70","0.546"],["64674.20","0.166"],["64675.50","0.701"],["64677.80","0.091"],["64678.30","0.211"],["64683.70","0.079"],["64709.80","0.000"],["64714.70","0.000"],["64715.10","0.002"],["64717.30","33.917"],["64723.90","0.002"],["64973.30","0.002"],["65296.50","0.005"],["65652.10","1.528"],["65938.10","0.454"]],"st":1}}
{"stream":"btcusdt@depth@100ms","data":{"e":"depthUpdate","E":1784410630768,"T":1784410630765,"s":"BTCUSDT","ps":"BTCUSDT","U":11079102295147,"u":11079102305334,"pu":11079102295142,"b":[["1000.00","50.241"],["14249.90","1.988"],["14347.20","0.000"],["14349.90","0.812"],["14449.90","1.302"],["14547.20","0.098"],["58184.90","0.002"],["62063.90","0.000"],["64003.40","0.000"],["64547.90","0.000"],["64600.30","3.936"],["64620.40","0.309"],["64626.90","1.621"],["64633.00","0.215"],["64633.30","0.598"],["64646.90","0.026"]],"a":[["64650.00","1.847"],["64652.20","0.079"],["64653.40","0.143"],["64653.50","0.000"],["64653.60","0.000"],["64653.70","0.162"],["64654.00","0.006"],["64654.40","0.001"],["64656.50","0.759"],["64658.60","0.307"],["64665.10","0.815"],["64714.00","1.869"],["65296.50","0.001"]],"st":1}}
{"stream":"btcusdt@depth@100ms","data":{"e":"depthUpdate","E":1784410630870,"T":1784410630869,"s":"BTCUSDT","ps":"BTCUSDT","U":11079102305645,"u":11079102315113,"pu":11079102305334,"b":[["14149.90","0.112"],["14249.90","2.002"],["14349.90","0.714"],["14449.90","1.372"],["14547.20","0.000"],["58184.90","0.002"],["61417.40","0.000"],["62063.90","0.003"],["64003.40","0.000"],["64042.50","0.000"],["64102.00","0.001"],["64208.80","0.003"],["64326.60","0.007"],["64375.10","0.117"],["64439.10","0.000"],["64476.00","0.002"],["64495.20","0.000"],["64534.70","0.013"],["64544.70","0.013"],["64544.90","0.000"],["64546.40","1.832"],["64580.80","0.000"],["64586.80","0.034"],["64620.90","0.030"],["64623.40","0.027"],["64645.10","0.236"],["64649.90","12.479"]],"a":[["64650.00","1.697"],["64653.00","0.000"],["64653.10","0.001"],["64653.20","0.005"],["64653.40","0.143"],["64654.20","0.047"],["64656.50","0.759"],["64677.00","0.047"],["64679.50","0.344"],["64683.70","0.002"],["64714.30","0.013"],["64715.10","22.303"],["64717.30","11.616"],["64720.30","0.764"],["64757.20","0.013"],["64767.20","0.000"],["64803.60","1.316"],["64820.90","0.000"],["64857.70","1.540"],["64973.30","0.001"],["65296.50","0.001"],["65425.50","0.000"],["65560.50","1.116"]],"st":1}}
{"stream":"btcusdt@depth@100ms","data":{"e":"depthUpdate","E":1784410630972,"T":1784410630971,"s":"BTCUSDT","ps":"BTCUSDT","U":11079102315250,"u":11079102327400,"pu":11079102315113,"b":[["1000.00","50.241"],["14149.90","0.238"],["14249.90","1.988"],["14349.90","0.714"],["14449.90","1.260"],["51720.00","0.052"],["58184.90","0.002"],["61417.40","0.002"],["62063.90","0.000"],["64003.40","0.006"],["64326.70","0.013"],["64441.90","2.112"],["64466.20","0.004"],["64476.60","0.111"],["64478.70","0.482"],["64495.90","1.554"],["64547.90","1.178"],["64552.40","1.276"],["64562.60","0.008"],["64582.00","1.405"],["64600.30","3.938"],["64600.40","0.000"],["64612.10","0.000"],["64614.20","0.014"],["64614.30","0.556"],["64614.40","0.168"],["64614.70","0.158"],["64614.80","0.006"],["64614.90","0.038"],["64616.50","0.005"],["64618.30","0.403"],["64620.40","0.000"],["64622.70","0.095"],["64625.50","0.002"],["64626.90","1.466"],["64627.10","1.441"],["64630.10","0.002"],["64630.20","0.053"],["64630.30","0.387"],["64632.20","10.434"],["64632.70","0.003"],["64633.00","0.061"],["64633.30","0.521"],["64633.50","1.599"],["64636.00","2.159"],["64638.30","0.932"],["64639.90","0.558"],["64640.00","0.185"],["64642.00","0.570"],["64646.20","0.001"],["64647.20","2.208"],["64647.60","0.023"],["64647.80","0.170"],["64648.00","0.001"],["64648.10","0.000"],["64649.40","0.000"],["64649.70","0.004"],["64649.90","12.488"]],"a":[["64650.00","1.941"],["64650.10","0.001"],["64652.20","0.002"],["64653.70","0.131"],["64653.80","1.275"],["64654.20","0.000"],["64654.90","0.050"],["64655.10","0.635"],["64656.50","0.172"],["64657.30","0.034"],["64657.70","0.357"],["64658.30","0.194"],["64658.40","0.047"],["64658.50","0.180"],["64658.60","0.152"],["64659.50","0.212"],["64660.20","0.002"],["64660.30","0.314"],["64662.10","0.002"],["64662.20","0.574"],["64665.10","0.506"],["64668.70","0.005"],["64669.60","0.541"],["64670.30","0.001"],["64671.10","1.379"],["64674.20","0.011"],["64674.30","0.313"],["64678.30","0.154"],["64678.70","0.001"],["64678.90","0.112"],["64679.30","0.008"],["64684.20","0.001"],["64688.50","0.000"],["64691.70","2.534"],["64691.80","10.000"],["64692.00","0.028"],["64717.30","11.618"],["64718.00","4.038"],["64803.50","0.680"],["64820.60","0.578"],["64857.50","1.991"],["65296.50","0.003"],["65389.30","0.000"],["65575.90","13.924"],["65595.20","1.066"],["65942.90","0.639"]],"st":1}}
{"stream":"btcusdt@depth@100ms","data":{"e":"depthUpdate","E":1784410631074,"T":1784410631073,"s":"BTCUSDT","ps":"BTCUSDT","U":11079102327410,"u":11079102338896,"pu":11079102327400,"b":[["1000.00","50.241"],["14149.90","0.350"],["14249.90","2.002"],["14349.90","0.714"],["14449.90","1.134"],["51720.00","0.004"],["58184.90","0.002"],["61417.40","0.002"],["62063.90","0.003"],["62690.80","0.683"],["63506.80","0.054"],["64003.40","0.000"],["64132.70","0.126"],["64466.20","0.000"],["64546.40","0.556"],["64615.10","0.406"],["64622.70","0.075"],["64626.40","0.504"],["64627.10","1.384"],["64627.20","0.079"],["64629.20","0.008"],["64629.70","0.002"],["64630.40","0.007"],["64632.70","0.001"],["64633.50","1.601"],["64634.00","0.299"],["64634.50","0.355"],["64638.30","0.932"],["64638.80","0.943"],["64639.90","0.739"],["64640.00","0.031"],["64642.00","0.002"],["64642.10","0.001"],["64646.90","0.004"],["64647.20","2.210"],["64647.80","0.168"]],"a":[["64650.10","0.002"],["64652.10","0.004"],["64654.00","0.003"],["64654.70","0.000"],["64654.80","0.023"],["64654.90","0.003"],["64655.10","0.048"],["64655.50","0.007"],["64668.70","0.546"],["64669.60","0.000"],["64670.30","0.927"],["64671.10","0.453"],["64687.50","2.018"],["64691.80","10.002"],["64692.10","3.500"],["64715.10","0.002"],["64717.30","33.919"],["64723.90","0.002"],["65296.50","0.003"],["65364.10","0.857"],["65419.30","0.919"],["65432.00","9.981"],["65458.10","1.251"]],"st":1}}
{"stream":"btcusdt@depth@100ms","data":{"e":"depthUpdate","E":1784410631176,"T":1784410631173,"s":"BTCUSDT","ps":"BTCUSDT","U":11079102339091,"u":11079102349524,"pu":11079102338896,"b":[["14149.90","0.476"],["14249.90","1.988"],["14349.90","0.714"],["14449.90","1.022"],["58184.90","0.002"],["61407.00","0.000"],["61417.40","0.002"],["63354.30","0.029"],["63480.40","4.312"],["63694.10","0.003"],["64003.40","0.000"],["64326.70","0.013"],["64351.80","0.001"],["64633.00","0.215"],["64647.20","2.203"]],"a":[["64654.50","0.003"],["64654.70","0.000"],["64655.00","0.004"],["64715.10","0.002"],["64717.30","11.618"],["64723.90","21.920"],["65257.80","0.038"],["65296.50","0.001"],["65548.60","1.523"],["65940.20","0.012"]],"st":1}}
{"stream":"btcusdt@depth@100ms","data":{"e":"depthUpdate","E":1784410631278,"T":1784410631277,"s":"BTCUSDT","ps":"BTCUSDT","U":11079102349811,"u":11079102360418,"pu":11079102349524,"b":[["1000.00","50.241"],["14149.90","0.588"],["14249.90","2.002"],["14349.90","0.714"],["14449.90","0.896"],["51720.00","0.004"],["58184.90","0.002"],["61412.90","0.000"],["61417.40","0.002"],["62063.90","0.000"],["63354.30","0.023"],["63424.10","4.251"],["64003.40","0.000"],["64497.70","0.002"],["64633.00","0.061"],["64637.40","0.001"],["64637.70","1.647"],["64638.60","0.622"],["64638.80","0.402"],["64638.90","0.971"],["64639.90","0.739"]],"a":[["64653.70","0.594"],["64653.90","0.003"],["64654.20","0.000"],["64654.50","0.003"],["64654.80","0.023"],["64655.10","0.048"],["64655.50","0.054"],["64656.50","0.329"],["64656.60","0.570"],["64658.60","0.276"],["64668.70","0.546"],["64669.60","0.000"],["64670.10","0.931"],["64670.30","0.001"],["64671.00","0.002"],["64717.30","33.536"],["64723.90","0.002"],["65296.50","0.001"],["65387.80","0.015"],["65425.80","6.106"],["65627.70","10.200"]],"st":1}}
{"stream":"btcusdt@depth@100ms","data":{"e":"depthUpdate","E":1784410631380,"T":1784410631378,"s":"BTCUSDT","ps":"BTCUSDT","U":11079102360579,"u":11079102370508,"pu":11079102360418,"b":[["1000.00","50.241"],["14149.90","0.714"],["14249.90","1.988"],["14349.90","0.714"],["14449.90","0.784"],["51720.00","0.004"],["58184.90","0.002"],["61417.40","0.002"],["62063.90","0.003"],["63357.00","0.017"],["63731.90","4.504"],["64003.40","0.000"],["64134.60","0.357"],["64168.20","0.156"],["64443.00","0.256"],["64446.30","0.004"],["64458.50","0.065"],["64495.90","1.077"],["64547.90","0.000"],["64553.90","1.276"],["64577.60","0.001"],["64598.70","0.002"],["64600.20","0.000"],["64600.30","0.002"],["64600.90","21.560"],["64616.90","0.568"],["64621.00","0.015"],["64623.70","1.031"],["64632.20","0.434"],["64633.00","0.215"]],"a":[["64650.00","2.244"],["64653.70","0.594"],["64654.30","0.003"],["64654.50","0.003"],["64655.10","0.095"],["64655.50","0.007"],["64656.50","0.329"],["64679.70","0.010"],["64691.70","0.022"],["64691.80","0.002"],["64692.10","0.000"],["64712.90","21.920"],["64714.00","0.048"],["64714.80","0.000"],["64717.30","11.618"],["64803.50","0.029"],["65296.50","0.001"],["65394.10","1.012"],["65482.90","6.001"],["65940.20","0.006"]],"st":1}}
{"stream":"btcusdt@depth@100ms","data":{"e":"depthUpdate","E":1784410631482,"T":1784410631481,"s":"BTCUSDT","ps":"BTCUSDT","U":11079102370747,"u":11079102379986,"pu":11079102370508,"b":[["14149.90","0.854"],["14249.90","1.946"],["14349.90","0.742"],["14449.90","0.658"],["58184.90","0.002"],["61417.40","0.002"],["62063.90","0.000"],["63354.30","0.020"],["63899.70","0.041"],["64003.40","0.000"],["64326.70","0.013"],["64446.30","0.160"],["64453.30","0.316"],["64495.90","1.786"],["64545.30","0.000"],["64549.40","0.035"],["64550.90","0.014"],["64555.40","1.276"],["64556.90","1.281"]],"a":[["64653.70","0.007"],["64655.10","0.635"],["64655.60","0.049"],["64656.50","0.172"],["64658.50","0.304"],["64658.60","0.152"],["64660.80","0.012"],["64746.60","0.437"],["64747.10","0.000"],["64803.40","1.092"],["65296.50","0.001"],["65446.80","0.775"],["65770.10","0.758"]],"st":1}}
{"stream":"btcusdt@depth@100ms","data":{"e":"depthUpdate","E":1784410631584,"T":1784410631583,"s":"BTCUSDT","ps":"BTCUSDT","U":11079102380153,"u":11079102391252,"pu":11079102379986,"b":[["1000.00","50.241"],["14149.90","1.092"],["14249.90","1.708"],["14349.90","0.854"],["14449.90","0.546"],["51719.90","0.000"],["58184.90","0.002"],["61414.80","0.000"],["61414.90","0.006"],["61417.40","0.002"],["62063.90","0.003"],["63354.30","0.017"],["63876.20","4.650"],["63920.10","3.829"],["63957.30","1.175"],["64003.40","0.000"],["64437.00","0.008"],["64495.90","1.077"],["64496.00","0.712"],["64552.40","0.000"],["64553.90","0.000"],["64582.00","0.389"],["64582.20","6.000"],["64582.30","2.091"],["64596.50","21.572"],["64600.90","0.146"],["64604.80","6.551"],["64614.20","0.016"],["64614.30","0.558"],["64614.40","0.170"],["64614.60","0.002"],["64614.70","0.160"],["64614.80","0.008"],["64615.10","0.414"],["64621.00","0.712"],["64630.10","0.004"],["64630.20","0.055"],["64630.30","0.389"],["64633.00","0.215"],["64635.70","0.116"],["64636.30","0.160"],["64637.30","0.001"],["64637.70","0.721"],["64638.40","0.956"],["64638.80","1.328"],["64638.90","0.430"],["64640.00","0.572"],["64645.10","0.218"],["64647.60","0.000"],["64649.90","12.506"]],"a":[["64650.00","1.528"],["64650.10","0.000"],["64653.70","0.594"],["64654.00","0.003"],["64654.60","0.003"],["64654.90","0.003"],["64655.10","0.048"],["64655.40","0.000"],["64655.60","0.002"],["64655.70","0.002"],["64656.50","0.329"],["64668.70","0.005"],["64669.60","0.541"],["64670.10","0.005"],["64670.40","0.095"],["64671.20","0.929"],["64678.00","0.164"],["64678.70","0.557"],["64679.90","1.291"],["64696.10","3.501"],["64718.70","6.015"],["64747.00","0.019"],["64752.00","0.010"],["64803.40","1.092"],["65296.50","0.001"],["65458.10","1.479"],["65482.90","5.621"],["65600.40","1.297"]],"st":1}}
{"stream":"btcusdt@depth@100ms","data":{"e":"depthUpdate","E":1784410631686,"T":1784410631685,"s":"BTCUSDT","ps":"BTCUSDT","U":11079102391423,"u":11079102402357,"pu":11079102391252,"b":[["1000.00","50.241"],["14149.90","1.330"],["14249.90","1.470"],["14349.90","0.980"],["14449.90","0.420"],["58184.90","0.002"],["63690.70","0.001"],["63809.40","0.313"],["63871.10","1.814"],["64003.40","0.000"],["64132.70","0.437"],["64328.50","0.002"],["64351.80","0.001"],["64453.30","0.312"],["64549.90","10.000"],["64556.40","0.536"],["64556.90","0.005"],["64596.50","0.158"],["64598.70","21.416"],["64607.20","1.049"],["64611.10","0.504"],["64629.40","0.350"],["64633.00","0.061"],["64636.20","0.522"],["64637.70","1.278"],["64638.10","1.545"],["64638.40","0.399"],["64638.80","0.402"],["64638.90","0.971"],["64639.90","0.732"],["64640.00","0.038"],["64642.00","0.002"],["64642.10","0.001"],["64643.40","0.007"],["64649.90","12.509"]],"a":[["64653.70","0.718"],["64654.80","0.023"],["64655.20","1.277"],["64655.50","0.007"],["64655.60","0.002"],["64656.50","0.329"],["64658.50","0.180"],["64668.70","0.005"],["64669.60","0.541"],["64710.60","3.958"],["64748.80","1.755"],["64751.10","10.093"],["64979.40","0.023"],["65173.30","0.000"],["65296.50","0.001"],["65417.90","0.000"],["65579.90","1.022"],["65789.30","0.570"],["65818.50","1.214"],["72957.50","0.065"]],"st":1}}
{"stream":"btcusdt@depth@100ms","data":{"e":"depthUpdate","E":1784410631788,"T":1784410631786,"s":"BTCUSDT","ps":"BTCUSDT","U":11079102402496,"u":11079102412385,"pu":11079102402357,"b":[["14149.90","1.568"],["14249.90","1.232"],["14349.90","1.092"],["14449.90","0.308"],["58184.90","0.002"],["60089.10","0.008"],["61417.40","0.002"],["62063.90","0.000"],["63354.30","0.014"],["63649.70","2.519"],["63893.50","0.547"],["64003.40","0.000"],["64326.70","0.013"],["64555.40","0.000"],["64556.40","0.326"],["64613.30","0.576"],["64615.10","0.394"],["64621.90","0.000"],["64627.50","0.011"],["64628.30","0.002"],["64634.80","0.003"],["64643.40","0.005"]],"a":[["64650.00","1.844"],["64650.10","0.002"],["64651.90","0.055"],["64652.20","0.002"],["64653.70","0.131"],["64655.10","0.635"],["64655.20","1.324"],["64656.50","0.172"],["64658.60","0.152"],["64665.10","0.506"],["64669.10","0.002"],["64669.20","0.048"],["64669.30","0.330"],["64683.10","1.065"],["64683.70","10.002"],["64685.50","0.019"],["64685.60","0.001"],["64685.70","0.199"],["64686.00","0.002"],["64686.10","0.063"],["64686.20","0.114"],["64687.50","0.018"],["64710.60","0.692"],["64712.90","0.002"],["64715.10","21.920"],["64717.30","11.618"],["64751.00","0.008"],["64752.00","0.002"],["64765.40","0.000"],["64767.50","0.004"],["65296.50","0.001"],["65593.60","9.990"],["65658.30","1.065"],["65781.40","1.214"],["65940.20","0.003"]],"st":1}}
{"stream":"btcusdt@depth@100ms","data":{"e":"depthUpdate","E":1784410631890,"T":1784410631889,"s":"BTCUSDT","ps":"BTCUSDT","U":11079102412486,"u":11079102420945,"pu":11079102412385,"b":[["1000.00","50.241"],["14149.90","1.806"],["14249.90","0.994"],["14349.90","1.218"],["14449.90","0.182"],["58184.90","0.002"],["61417.40","0.002"],["62063.90","0.003"],["63874.10","3.141"],["64003.40","0.000"],["64326.60","0.005"],["64458.50","0.061"],["64463.70","0.043"],["64478.70","0.003"],["64478.90","0.747"],["64496.00","0.711"],["64537.40","0.000"],["64538.90","0.004"],["64540.40","0.000"],["64541.90","1.276"],["64543.40","1.276"],["64544.90","1.276"],["64546.40","1.832"],["64547.90","1.276"],["64549.40","1.311"],["64550.90","1.290"],["64594.70","0.818"],["64595.00","1.240"],["64595.30","0.000"],["64595.70","0.000"],["64596.00","0.255"],["64610.30","0.487"],["64610.40","0.556"],["64610.60","0.010"],["64610.90","0.001"],["64611.00","0.074"],["64611.50","0.251"],["64611.60","0.049"],["64614.30","0.402"],["64614.40","0.020"],["64614.50","0.005"],["64614.70","0.004"],["64617.00","0.327"],["64618.50","0.048"],["64618.80","0.065"],["64619.10","0.187"],["64619.50","0.011"],["64619.80","0.000"],["64629.40","10.350"],["64633.00","0.061"],["64635.50","0.855"],["64635.70","0.000"],["64636.00","0.159"],["64636.50","0.117"],["64636.80","0.315"],["64637.00","0.561"],["64637.30","0.927"],["64637.60","0.001"],["64637.70","0.007"],["64637.80","0.003"],["64637.90","0.005"],["64638.00","0.100"],["64638.10","0.619"],["64638.20","0.048"],["64638.30","0.002"],["64638.40","0.940"],["64638.50","0.068"],["64638.80","0.093"],["64638.90","0.093"],["64639.20","0.003"],["64639.50","0.121"],["64647.20","2.203"],["64647.80","0.215"],["64648.20","0.000"],["64648.30","0.001"],["64648.50","0.023"],["64649.10","0.000"],["64649.90","12.502"]],"a":[["64650.00","2.148"],["64651.90","0.008"],["64653.70","0.131"],["64655.00","0.004"],["64655.10","0.048"],["64656.50","0.605"],["64656.60","0.002"],["64657.00","0.005"],["64657.20","0.062"],["64657.30","0.002"],["64657.60","0.004"],["64657.80","0.002"],["64657.90","0.181"],["64658.00","0.001"],["64658.30","0.162"],["64658.50","0.000"],["64658.60","0.000"],["64659.00","0.002"],["64659.10","0.003"],["64659.20","0.391"],["64659.30","0.313"],["64659.40","0.000"],["64660.00","0.007"],["64660.20","0.724"],["64660.50","0.222"],["64669.70","0.560"],["64670.60","0.934"],["64671.20","0.003"],["64677.00","0.015"],["64677.10","0.039"],["64677.40","0.380"],["64677.70","0.003"],["64678.00","0.689"],["64678.30","0.002"],["64678.70","0.001"],["64680.50","0.060"],["64681.20","0.310"],["64681.80","0.000"],["64682.20","0.000"],["64682.30","0.031"],["64682.40","0.043"],["64682.50","0.003"],["64682.70","0.283"],["64685.70","0.121"],["64697.20","0.017"],["64697.60","0.033"],["64697.90","0.004"],["64698.20","0.000"],["64698.50","0.000"],["64702.80","0.079"],["64803.40","1.092"],["64820.50","0.889"],["64820.60","0.009"],["64847.10","0.000"],["64865.40","0.145"],["65167.20","0.363"],["65296.50","0.001"]],"st":1}}
{"stream":"btcusdt@depth@100ms","data":{"e":"depthUpdate","E":1784410631992,"T":1784410631991,"s":"BTCUSDT","ps":"BTCUSDT","U":11079102421106,"u":11079102429052,"pu":11079102420945,"b":[["1000.00","50.241"],["14149.90","1.988"],["14249.90","0.784"],["14349.90","1.330"],["14449.90","0.070"],["14549.90","0.028"],["51720.00","0.004"],["57994.10","0.007"],["58184.90","0.002"],["61417.40","0.002"],["62063.90","0.000"],["64003.40","0.000"],["64326.70","0.168"],["64368.70","0.117"],["64375.10","0.000"],["64463.70","0.047"],["64496.00","0.714"],["64520.90","3.867"],["64521.50","1.367"],["64541.90","0.000"],["64543.40","0.000"],["64544.90","0.000"],["64562.60","0.349"],["64580.00","0.151"],["64580.10","0.160"],["64582.00","0.048"],["64596.60","0.075"],["64597.20","0.062"],["64597.50","0.075"],["64597.80","0.061"],["64632.70","2.591"],["64633.00","0.215"],["64636.00","0.383"],["64636.60","0.081"],["64636.70","1.089"],["64637.00","0.635"],["64637.30","0.988"]],"a":[["64655.50","0.039"],["64655.80","0.035"],["64656.10","0.095"],["64656.30","0.003"],["64656.50","0.018"],["64656.60","0.589"],["64656.70","1.308"],["64656.80","0.062"],["64658.20","0.558"],["64658.30","0.316"],["64658.40","0.047"],["64658.50","0.007"],["64658.60","0.010"],["64659.80","0.000"],["64660.20","0.002"],["64661.90","0.315"],["64675.20","0.037"],["64675.50","0.733"],["64675.80","0.032"],["64676.40","0.114"],["64676.50","0.060"],["64679.40","0.072"],["64681.00","0.079"],["64722.30","0.050"],["64722.40","0.013"],["64776.50","0.013"],["64776.70","3.891"],["64803.40","1.092"],["64973.20","0.542"],["64973.30","0.003"],["65296.50","0.001"],["65454.00","0.000"],["65548.30","0.595"],["65555.10","0.276"]],"st":1}}
{"stream":"btcusdt@depth@100ms","data":{"e":"depthUpdate","E":1784410632094,"T":1784410632093,"s":"BTCUSDT","ps":"BTCUSDT","U":11079102429107,"u":11079102436972,"pu":11079102429052,"b":[["14149.90","2.002"],["14249.90","0.714"],["14349.90","1.344"],["14449.90","0.000"],["14549.90","0.140"],["58184.90","0.002"],["61407.00","0.002"],["61417.40","0.002"],["63624.50","0.000"],["63790.70","2.974"],["64003.40","0.000"],["64326.70","0.168"],["64458.50","0.065"],["64546.40","0.556"],["64547.90","0.000"],["64549.40","0.035"],["64550.00","18.216"],["64552.40","1.276"],["64553.90","1.276"],["64603.60","0.889"],["64604.80","3.994"],["64618.70","10.058"],["64633.00","0.061"],["64635.40","0.221"],["64635.50","1.395"],["64635.70","0.116"],["64636.10","0.535"],["64636.50","0.001"],["64637.30","0.062"],["64637.90","0.931"],["64638.30","0.002"],["64638.40","0.399"],["64638.80","0.093"],["64638.90","0.634"],["64639.90","0.712"],["64640.00","0.031"],["64642.00","0.029"],["64646.60","0.055"],["64647.30","0.782"],["64649.90","12.495"]],"a":[["64650.00","1.935"],["64651.20","0.051"],["64655.10","0.635"],["64656.40","0.001"],["64656.50","0.018"],["64656.60","0.002"],["64656.70","1.368"],["64656.80","0.122"],["64657.40","0.241"],["64658.20","0.007"],["64658.30","0.162"],["64658.50","0.000"],["64658.60","0.181"],["64660.20","0.543"],["64668.70","0.546"],["64669.60","0.000"],["64670.30","0.927"],["64670.60","0.008"],["64671.30","0.002"],["64676.50","0.120"],["64680.00","0.506"],["64680.60","0.068"],["64680.70","0.180"],["64681.00","0.002"],["65296.50","0.001"],["65653.70","3.278"],["65942.90","0.642"]],"st":1}}
{"stream":"btcusdt@depth@100ms","data":{"e":"depthUpdate","E":1784410632196,"T":1784410632195,"s":"BTCUSDT","ps":"BTCUSDT","U":11079102437043,"u":11079102443874,"pu":11079102436972,"b":[["1000.00","50.241"],["14149.90","1.988"],["14249.90","0.714"],["14349.90","1.232"],["14549.90","0.266"],["51720.00","0.006"],["58184.90","0.002"],["61417.40","0.002"],["62063.90","0.003"],["63635.10","0.012"],["64003.40","0.002"],["64351.80","0.001"],["64458.50","0.061"],["64550.00","16.940"],["64550.90","0.014"],["64552.40","0.000"],["64553.00","0.198"],["64553.90","0.000"],["64559.20","4.445"],["64590.70","0.001"],["64595.50","0.015"],["64596.90","0.067"],["64623.40","0.014"],["64627.00","0.400"],["64633.00","0.215"],["64635.70","0.272"],["64636.00","0.539"],["64636.30","0.227"],["64640.00","0.058"],["64642.00","0.002"],["64649.90","12.502"]],"a":[["64656.40","0.033"],["64656.80","0.182"],["64657.10","0.089"],["64658.60","0.171"],["64660.10","0.001"],["64671.60","0.160"],["64673.40","0.063"],["64676.20","0.034"],["64680.10","1.358"],["64680.40","0.060"],["64742.70","0.013"],["64743.50","14.289"],["65296.50","0.001"]],"st":1}}
{"stream":"btcusdt@depth@100ms","data":{"e":"depthUpdate","E":1784410632298,"T":1784410632297,"s":"BTCUSDT","ps":"BTCUSDT","U":11079102443913,"u":11079102451432,"pu":11079102443874,"b":[["1000.00","50.241"],["14149.90","2.002"],["14249.90","0.714"],["14349.90","1.106"],["14549.90","0.378"],["51720.00","0.004"],["58184.90","0.002"],["61417.40","0.002"],["62063.90","0.000"],["63354.30","0.011"],["63580.80","0.031"],["64003.40","0.000"],["64576.80","0.074"],["64577.50","0.064"],["64577.80","0.088"],["64578.10","0.061"],["64612.30","0.126"],["64635.40","0.377"],["64635.70","0.428"],["64636.10","0.841"],["64636.70","1.227"]],"a":[["64655.10","0.048"],["64656.10","0.155"],["64656.50","0.713"],["64656.60","0.029"],["64656.70","1.488"],["64657.10","0.149"],["64657.40","0.301"],["64658.60","0.000"],["64660.10","0.001"],["64660.20","0.002"],["64679.40","0.132"],["64680.00","0.626"],["64680.40","0.120"],["64680.70","0.240"],["64681.00","0.079"],["64694.90","0.467"],["64695.20","0.061"],["64695.50","0.344"],["64696.20","0.032"],["65296.50","0.001"],["65427.70","12.828"],["65428.80","0.873"],["65664.70","0.011"],["65673.60","0.003"]],"st":1}}
{"stream":"btcusdt@depth@100ms","data":{"e":"depthUpdate","E":1784410632400,"T":1784410632397,"s":"BTCUSDT","ps":"BTCUSDT","U":11079102451580,"u":11079102458643,"pu":11079102451432,"b":[["14149.90","1.988"],["14249.90","0.714"],["14349.90","0.994"],["14549.90","0.504"],["51720.00","0.006"],["58184.90","0.002"],["61417.40","0.002"],["61571.30","0.004"],["62063.90","0.003"],["63354.30","0.008"],["64003.40","0.000"],["64326.70","0.168"],["64446.30","0.004"],["64613.40","0.139"],["64616.30","0.150"],["64633.00","0.061"]],"a":[["64655.10","0.048"],["64656.30","0.013"],["64656.40","1.315"],["64656.50","0.018"],["64656.60","0.019"],["64658.60","0.000"],["64660.20","0.002"],["64681.00","0.002"],["65296.50","0.001"],["72957.50","0.000"]],"st":1}}
{"stream":"btcusdt@depth@100ms","data":{"e":"depthUpdate","E":1784410632502,"T":1784410632501,"s":"BTCUSDT","ps":"BTCUSDT","U":11079102458920,"u":11079102471607,"pu":11079102458643,"b":[["1000.00","50.241"],["14149.90","2.002"],["14249.90","0.714"],["14349.90","0.868"],["14549.90","0.616"],["51720.00","0.004"],["58184.90","0.002"],["61417.40","0.002"],["62063.90","0.000"],["63823.50","0.014"],["63882.40","10.298"],["64003.40","0.001"],["64351.00","1.105"],["64351.30","0.329"],["64441.90","0.001"],["64442.10","3.449"],["64443.00","0.100"],["64446.30","0.160"],["64478.90","0.750"],["64496.00","0.714"],["64577.10","0.068"],["64612.20","0.807"],["64612.80","0.599"],["64616.40","0.491"],["64619.00","2.137"],["64629.40","0.350"],["64634.00","2.299"],["64635.70","0.312"],["64636.80","0.431"],["64649.90","12.501"]],"a":[["64650.00","1.678"],["64651.20","0.004"],["64655.20","1.277"],["64655.60","0.002"],["64656.30","0.003"],["64656.40","0.574"],["64656.50","0.172"],["64656.60","0.029"],["64658.60","0.000"],["64660.20","0.002"],["64661.50","0.388"],["64668.70","0.005"],["64669.10","0.004"],["64669.20","0.050"],["64669.30","0.332"],["64669.60","0.541"],["64670.30","0.001"],["64670.90","0.926"],["64685.50","0.021"],["64685.60","0.003"],["64685.70","0.123"],["64686.00","0.004"],["64686.10","0.065"],["64686.20","0.116"],["64688.40","0.000"],["64695.90","0.452"],["64803.30","1.239"],["64803.40","0.093"],["64820.50","0.935"],["64854.70","1.403"],["64857.30","3.699"],["64857.50","0.000"],["65296.50","0.001"]],"st":1}}
{"stream":"btcusdt@depth@100ms","data":{"e":"depthUpdate","E":1784410632604,"T":1784410632603,"s":"BTCUSDT","ps":"BTCUSDT","U":11079102471811,"u":11079102483257,"pu":11079102471607,"b":[["1000.00","50.241"],["14149.90","1.988"],["14249.90","0.714"],["14349.90","0.756"],["14549.90","0.742"],["51719.90","0.000"],["58184.90","0.002"],["61417.40","0.004"],["64003.40","0.001"],["64042.20","0.625"],["64443.00","0.256"],["64458.50","0.065"],["64598.70","0.002"],["64600.90","21.560"],["64612.40","0.158"],["64612.70","0.216"],["64612.80","0.749"],["64633.00","0.215"],["64636.40","1.601"]],"a":[["64655.10","0.048"],["64655.60","0.049"],["64656.30","0.003"],["64656.40","0.033"],["64656.50","0.172"],["64656.60","0.570"],["64658.60","0.000"],["64660.20","0.002"],["64668.70","0.546"],["64669.60","0.000"],["64681.00","0.002"],["65296.50","0.001"],["65419.30","1.835"],["65535.70","0.533"],["65582.40","9.272"]],"st":1}}
{"stream":"btcusdt@depth@100ms","data":{"e":"depthUpdate","E":1784410632706,"T":1784410632705,"s":"BTCUSDT","ps":"BTCUSDT","U":11079102483387,"u":11079102493746,"pu":11079102483257,"b":[["14149.90","1.890"],["14249.90","0.770"],["14349.90","0.630"],["14549.90","0.910"],["58184.90","0.002"],["61417.40","0.024"],["62063.90","0.003"],["64003.40","0.001"],["64134.60","0.046"],["64169.80","0.159"],["64326.70","0.168"],["64349.90","0.051"],["64550.10","5.002"],["64596.50","21.297"],["64600.90","0.146"],["64601.00","3.512"],["64612.10","0.156"],["64612.40","0.314"],["64612.80","0.905"],["64613.40","0.277"],["64620.70","2.746"],["64633.00","0.061"],["64636.20","0.520"],["64639.70","0.013"],["64649.90","12.502"]],"a":[["64656.30","0.003"],["64656.40","0.033"],["64656.50","0.018"],["64656.60","1.311"],["64658.60","0.000"],["64660.20","0.002"],["64668.70","0.544"],["64692.50","0.427"],["64715.00","3.701"],["64765.10","0.488"],["65296.50","0.001"],["65587.40","1.066"]],"st":1}}
{"stream":"btcusdt@depth@100ms","data":{"e":"depthUpdate","E":1784410632808,"T":1784410632806,"s":"BTCUSDT","ps":"BTCUSDT","U":11079102493852,"u":11079102504661,"pu":11079102493746,"b":[["1000.00","50.241"],["14149.90","1.652"],["14249.90","0.882"],["14349.90","0.518"],["14549.90","1.148"],["58184.90","0.002"],["61412.80","0.002"],["61412.90","0.002"],["61417.40","0.004"],["62063.90","0.000"],["63354.30","0.005"],["63876.00","4.220"],["63908.30","1.229"],["64003.40","0.003"],["64458.50","0.061"],["64463.70","0.043"],["64550.10","4.994"],["64550.20","0.564"],["64596.50","0.158"],["64598.70","21.141"],["64601.00","0.006"],["64620.00","0.322"],["64626.40","0.659"],["64630.10","10.004"],["64632.90","0.000"],["64633.00","0.215"],["64634.00","0.299"],["64636.20","0.638"],["64636.80","0.872"],["64637.00","0.078"],["64637.20","1.009"],["64637.40","0.001"],["64637.90","0.005"],["64638.00","0.100"],["64638.20","0.589"],["64638.30","0.002"],["64638.80","0.093"],["64638.90","0.093"],["64639.00","0.067"],["64640.00","0.058"],["64649.90","12.582"]],"a":[["64650.00","1.725"],["64651.60","0.001"],["64651.90","0.006"],["64652.20","0.002"],["64652.50","0.000"],["64653.20","0.005"],["64655.10","0.635"],["64655.60","0.002"],["64656.40","0.574"],["64656.50","0.018"],["64656.60","0.183"],["64657.60","0.031"],["64658.60","0.000"],["64659.50","0.184"],["64659.70","0.185"],["64666.10","0.309"],["64668.60","0.559"],["64668.70","0.005"],["64669.60","0.926"],["64670.90","0.000"],["64677.00","0.572"],["64678.00","0.132"],["64678.70","0.001"],["65296.50","0.003"],["65940.20","0.000"],["65942.90","0.645"]],"st":1}}
{"stream":"btcusdt@depth@100ms","data":{"e":"depthUpdate","E":1784410632910,"T":1784410632909,"s":"BTCUSDT","ps":"BTCUSDT","U":11079102504863,"u":11079102516210,"pu":11079102504661,"b":[["1000.00","50.241"],["14149.90","1.414"],["14249.90","1.008"],["14349.90","0.392"],["14549.90","1.386"],["58184.90","0.002"],["61417.40","0.004"],["62063.90","0.003"],["63656.50","0.784"],["63769.00","6.059"],["64003.40","0.001"],["64068.60","0.000"],["64071.30","0.016"],["64228.80","0.000"],["64231.40","0.306"],["64240.00","0.521"],["64320.00","0.443"],["64368.70","0.000"],["64389.30","0.018"],["64392.00","0.004"],["64400.00","28.277"],["64480.00","4.367"],["64550.30","0.000"],["64553.00","0.200"],["64560.00","1.150"],["64625.70","1.277"],["64626.40","0.602"]],"a":[["64655.10","0.635"],["64655.60","0.049"],["64656.30","0.003"],["64656.40","0.033"],["64656.60","0.002"],["64658.60","0.010"],["64660.20","0.714"],["64669.60","0.000"],["64670.40","1.021"],["64677.00","0.015"],["64677.50","0.003"],["64677.90","1.124"],["64678.30","0.059"],["64678.90","0.055"],["64720.00","0.382"],["64744.20","0.000"],["64746.90","0.017"],["64800.00","18.466"],["64880.00","9.538"],["64906.10","0.002"],["64908.80","0.231"],["64960.00","2.259"],["65040.00","0.380"],["65068.30","0.013"],["65071.00","0.033"],["65231.00","0.000"],["65233.70","0.018"],["65257.70","0.611"],["65296.50","0.001"]],"st":1}}
{"stream":"btcusdt@depth@100ms","data":{"e":"depthUpdate","E":1784410633012,"T":1784410633011,"s":"BTCUSDT","ps":"BTCUSDT","U":11079102516452,"u":11079102526717,"pu":11079102516210,"b":[["14149.90","1.176"],["14249.90","1.120"],["14349.90","0.280"],["14549.90","1.624"],["58184.90","0.002"],["61417.40","0.006"],["62063.90","0.000"],["63874.10","3.843"],["64003.40","0.001"],["64132.70","0.748"],["64326.60","0.007"],["64326.70","0.158"],["64375.10","0.117"],["64544.70","0.000"],["64559.20","4.458"],["64586.80","0.021"],["64595.50","0.028"],["64623.40","0.001"],["64627.00","0.413"],["64633.00","0.061"],["64637.20","0.083"],["64638.00","0.100"],["64638.20","0.048"],["64638.80","1.019"],["64640.00","0.599"]],"a":[["64650.80","0.000"],["64651.10","0.047"],["64655.10","0.048"],["64658.60","0.561"],["64660.20","0.163"],["64668.60","0.018"],["64669.60","0.541"],["64670.40","0.095"],["64671.20","0.929"],["64673.40","0.076"],["64677.00","0.002"],["64677.90","0.567"],["64678.70","0.557"],["64681.00","0.002"],["64705.60","0.013"],["64714.30","0.000"],["64742.70","0.026"],["64757.20","0.000"],["64973.30","0.001"],["65296.50","0.001"],["65776.40","8.728"]],"st":1}}
{"stream":"btcusdt@depth@100ms","data":{"e":"depthUpdate","E":1784410633114,"T":1784410633113,"s":"BTCUSDT","ps":"BTCUSDT","U":11079102526800,"u":11079102538004,"pu":11079102526717,"b":[["1000.00","50.241"],["14149.90","0.938"],["14249.90","1.246"],["14349.90","0.154"],["14549.90","1.862"],["58184.90","0.002"],["61407.00","0.000"],["61417.40","0.006"],["64003.40","0.001"],["64062.40","12.707"],["64090.60","0.000"],["64093.30","0.009"],["64320.00","0.630"],["64329.80","0.146"],["64332.50","0.010"],["64349.90","0.054"],["64400.00","28.464"],["64480.00","4.554"],["64560.00","1.337"],["64625.70","1.220"],["64626.40","0.659"],["64627.20","0.079"],["64637.80","0.929"],["64638.30","0.002"],["64638.80","0.093"],["64638.90","0.634"],["64639.90","0.171"],["64640.00","0.235"],["64642.00","0.553"]],"a":[["64651.10","0.000"],["64651.50","0.000"],["64651.70","0.012"],["64651.80","0.001"],["64652.10","0.004"],["64652.50","0.000"],["64652.80","0.002"],["64653.70","0.131"],["64656.30","0.544"],["64656.40","0.033"],["64656.50","0.018"],["64656.60","0.183"],["64658.60","0.000"],["64660.20","0.002"],["64668.70","0.546"],["64669.60","0.000"],["64670.30","0.927"],["64671.20","0.003"],["64678.30","0.002"],["64679.20","0.057"],["64720.00","0.569"],["64800.00","18.653"],["64880.00","9.725"],["64960.00","2.446"],["65040.00","0.567"],["65253.10","0.012"],["65296.50","0.001"],["65365.20","0.229"],["65458.10","1.859"],["65511.80","0.000"],["65547.60","8.902"],["65703.50","0.001"]],"st":1}}
{"stream":"btcusdt@depth@100ms","data":{"e":"depthUpdate","E":1784410633216,"T":1784410633214,"s":"BTCUSDT","ps":"BTCUSDT","U":11079102538111,"u":11079102549932,"pu":11079102538004,"b":[["1000.00","50.241"],["14149.90","0.756"],["14249.90","1.358"],["14349.90","0.042"],["14449.90","0.056"],["14549.90","1.988"],["58184.90","0.002"],["61417.40","0.006"],["62063.90","0.003"],["62861.80","0.000"],["63117.40","0.010"],["63372.90","0.000"],["63628.40","0.030"],["63884.00","0.000"],["64003.40","0.001"],["64349.90","0.051"],["64614.20","0.014"],["64614.30","0.400"],["64614.40","0.018"],["64614.60","0.000"],["64614.70","0.002"],["64614.80","0.006"],["64621.80","0.000"],["64630.10","10.002"],["64630.20","0.053"],["64630.30","0.387"],["64633.00","0.061"],["64634.50","0.364"],["64637.80","0.003"],["64638.20","0.974"],["64638.90","0.093"],["64639.00","0.608"],["64639.90","0.181"],["64642.00","0.002"],["64642.10","0.542"],["64642.20","0.000"],["64647.20","2.046"],["64649.90","12.749"]],"a":[["64650.00","1.568"],["64653.70","0.131"],["64655.60","0.002"],["64656.20","0.001"],["64656.30","0.003"],["64656.60","1.037"],["64657.10","0.149"],["64657.40","0.301"],["64657.70","0.357"],["64658.00","0.001"],["64658.30","0.209"],["64658.40","0.000"],["64658.60","0.000"],["64660.20","0.002"],["64668.10","0.004"],["64668.70","0.005"],["64669.60","0.541"],["64670.30","0.001"],["64670.60","0.008"],["64671.40","0.929"],["64683.10","1.112"],["64684.80","0.021"],["65296.50","0.001"]],"st":1}}
{"stream":"btcusdt@depth@100ms","data":{"e":"depthUpdate","E":1784410633318,"T":1784410633317,"s":"BTCUSDT","ps":"BTCUSDT","U":11079102550131,"u":11079102563936,"pu":11079102549932,"b":[["14149.90","0.714"],["14249.90","1.316"],["14349.90","0.000"],["14449.90","0.168"],["14549.90","2.002"],["51720.00","0.004"],["58184.90","0.002"],["61417.40","0.006"],["62063.90","0.000"],["63354.30","0.002"],["63938.70","0.234"],["64003.40","0.001"],["64326.70","0.168"],["64537.40","0.000"],["64538.90","0.004"],["64540.40","0.000"],["64541.90","0.000"],["64543.40","0.039"],["64543.60","0.000"],["64544.90","0.000"],["64546.40","1.832"],["64607.70","0.006"],["64620.00","0.013"],["64626.30","2.399"],["64626.40","0.504"],["64632.80","0.001"],["64633.00","0.215"],["64635.50","1.519"],["64637.00","0.464"],["64640.70","0.597"],["64641.60","0.001"],["64642.10","0.001"],["64646.10","0.003"],["64646.60","0.032"],["64648.70","0.000"],["64649.90","11.971"]],"a":[["64650.00","1.720"],["64653.00","0.000"],["64653.40","0.143"],["64653.70","0.178"],["64656.30","0.157"],["64656.40","0.033"],["64656.50","0.021"],["64656.60","0.029"],["64658.10","0.005"],["64658.30","0.162"],["64660.20","0.543"],["64660.30","0.311"],["64661.90","0.312"],["64668.70","0.546"],["64669.60","0.000"],["64680.50","2.494"],["64683.10","0.047"],["64684.20","0.001"],["64975.20","0.000"],["65296.50","0.001"]],"st":1}}
{"stream":"btcusdt@depth@100ms","data":{"e":"depthUpdate","E":1784410633420,"T":1784410633419,"s":"BTCUSDT","ps":"BTCUSDT","U":11079102564092,"u":11079102575061,"pu":11079102563936,"b":[["1000.00","50.241"],["14149.90","0.714"],["14249.90","1.204"],["14449.90","0.294"],["14549.90","1.988"],["51720.00","0.004"],["58184.90","0.002"],["62063.90","0.003"],["64003.40","0.003"],["64035.70","0.702"],["64596.80","0.031"],["64599.50","0.028"],["64607.70","0.010"],["64608.10","0.191"],["64626.30","0.399"],["64627.80","0.162"],["64633.00","0.061"],["64636.60","0.061"],["64636.80","0.315"],["64638.10","1.176"],["64643.10","0.021"],["64649.90","11.973"]],"a":[["64650.00","1.570"],["64653.70","0.131"],["64654.00","0.003"],["64654.40","0.001"],["64655.20","1.277"],["64655.50","0.039"],["64655.80","0.082"],["64656.30","0.003"],["64656.40","0.574"],["64656.50","0.021"],["64656.60","0.183"],["64658.60","0.000"],["64660.20","0.002"],["64668.70","0.005"],["64669.60","0.541"],["64681.00","0.002"],["65135.80","0.007"],["65231.90","1.196"],["65296.50","0.001"],["65382.20","0.799"],["65458.10","2.239"],["65490.50","1.140"],["65522.80","0.761"],["65555.10","0.535"],["65762.00","0.538"]],"st":1}}
{"stream":"btcusdt@depth@100ms","data":{"e":"depthUpdate","E":1784410633522,"T":1784410633521,"s":"BTCUSDT","ps":"BTCUSDT","U":11079102575162,"u":11079102587190,"pu":11079102575061,"b":[["1000.00","50.241"],["14149.90","0.714"],["14249.90","1.078"],["14449.90","0.406"],["14549.90","2.002"],["58184.90","0.002"],["61412.80","0.000"],["61412.90","0.004"],["61417.40","0.006"],["63357.00","0.020"],["63617.40","0.000"],["63647.80","1.098"],["63656.50","1.568"],["63714.30","2.312"],["64003.40","0.000"],["64443.00","0.100"],["64496.00","0.005"],["64496.10","0.697"],["64546.40","0.556"],["64633.00","0.215"],["64639.90","0.722"],["64640.70","0.056"],["64642.90","0.195"],["64646.30","0.143"],["64648.00","0.003"],["64649.90","11.987"]],"a":[["64650.00","1.570"],["64656.20","0.011"],["64656.30","0.544"],["64656.40","0.033"],["64656.60","0.173"],["64657.60","0.004"],["64658.60","0.000"],["64659.30","0.331"],["64681.00","0.079"],["64803.20","1.048"],["64803.30","0.159"],["65296.50","0.001"],["65587.40","2.132"],["65690.60","3.349"]],"st":1}}
{"stream":"btcusdt@depth@100ms","data":{"e":"depthUpdate","E":1784410633624,"T":1784410633622,"s":"BTCUSDT","ps":"BTCUSDT","U":11079102587363,"u":11079102598239,"pu":11079102587190,"b":[["14149.90","0.714"],["14249.90","0.966"],["14449.90","0.532"],["14549.90","1.988"],["51719.90","0.000"],["58184.90","0.002"],["61417.40","0.008"],["62063.90","0.000"],["64003.40","0.000"],["64326.70","0.168"],["64349.90","0.051"],["64636.20","0.522"],["64637.90","0.121"],["64638.20","0.048"],["64639.00","0.067"],["64639.60","0.934"],["64640.70","0.597"],["64646.10","0.000"],["64647.80","0.218"],["64649.90","11.988"]],"a":[["64650.00","1.514"],["64650.10","0.000"],["64651.70","0.010"],["64653.70","0.718"],["64655.10","0.205"],["64655.80","0.035"],["64656.20","0.001"],["64656.30","0.003"],["64656.60","1.037"],["64657.30","0.315"],["64657.60","0.317"],["64658.60","0.000"],["64660.20","0.002"],["64662.10","0.004"],["64669.60","0.000"],["64671.30","0.002"],["64671.40","0.003"],["64671.90","0.542"],["64672.00","2.422"],["64678.70","0.001"],["64679.40","0.688"],["64681.00","0.002"],["65098.20","0.012"],["65296.50","0.001"],["65652.10","2.593"]],"st":1}}
{"stream":"btcusdt@depth@100ms","data":{"e":"depthUpdate","E":1784410633726,"T":1784410633725,"s":"BTCUSDT","ps":"BTCUSDT","U":11079102598459,"u":11079102609557,"pu":11079102598239,"b":[["1000.00","50.241"],["14149.90","0.714"],["14249.90","0.840"],["14449.90","0.644"],["14549.90","2.002"],["58184.90","0.002"],["61417.40","0.008"],["62063.90","0.003"],["63815.90","1.565"],["64003.40","0.000"],["64537.40","0.000"],["64538.90","0.004"],["64540.40","0.202"],["64541.90","0.000"],["64543.40","0.039"],["64544.90","0.000"],["64546.40","0.556"],["64603.80","0.739"],["64629.40","0.002"],["64630.20","1.904"],["64633.00","0.061"],["64640.00","0.776"],["64640.70","0.056"],["64648.50","0.082"]],"a":[["64653.70","0.131"],["64655.10","0.048"],["64656.50","0.608"],["64656.60","0.724"],["64657.30","0.002"],["64657.60","0.004"],["64658.10","0.005"],["64658.30","0.162"],["64658.40","0.047"],["64658.50","0.000"],["64669.70","1.101"],["64671.90","0.001"],["64694.90","0.883"],["65296.50","0.001"],["65612.00","4.358"]],"st":1}}
{"stream":"btcusdt@depth@100ms","data":{"e":"depthUpdate","E":1784410633828,"T":1784410633827,"s":"BTCUSDT","ps":"BTCUSDT","U":11079102609912,"u":11079102621589,"pu":11079102609557,"b":[["1000.00","50.241"],["14149.90","0.714"],["14249.90","0.728"],["14449.90","0.770"],["14549.90","1.988"],["58184.90","0.002"],["61414.90","0.004"],["61417.40","0.008"],["62063.90","0.000"],["63357.00","0.017"],["63714.30","1.215"],["63764.20","0.548"],["63845.50","1.173"],["64003.40","0.000"],["64496.10","0.000"],["64620.00","0.322"],["64626.50","0.640"],["64633.00","0.138"],["64636.20","0.522"],["64637.40","0.117"],["64637.90","0.005"],["64639.00","0.993"],["64639.60","0.008"],["64649.90","11.988"]],"a":[["64650.00","1.515"],["64653.30","0.083"],["64656.40","0.033"],["64656.50","0.562"],["64656.60","0.183"],["64658.30","0.162"],["64658.40","0.047"],["64658.60","0.000"],["64668.70","0.005"],["64803.20","0.027"],["65296.50","0.003"],["65511.50","0.764"]],"st":1}}
{"stream":"btcusdt@depth@100ms","data":{"e":"depthUpdate","E":1784410633930,"T":1784410633929,"s":"BTCUSDT","ps":"BTCUSDT","U":11079102621747,"u":11079102632235,"pu":11079102621589,"b":[["14149.90","0.798"],["14249.90","0.602"],["14449.90","0.966"],["14549.90","1.834"],["58184.90","0.002"],["61417.40","0.008"],["62063.90","0.003"],["63357.00","0.020"],["63920.50","0.001"],["64003.40","0.000"],["64326.70","0.168"],["64478.90","0.004"],["64479.00","0.741"],["64496.10","0.699"],["64614.20","0.016"],["64614.30","0.402"],["64614.40","0.020"],["64614.70","0.004"],["64614.80","0.008"],["64614.90","0.040"],["64630.10","10.004"],["64630.20","1.906"],["64630.30","0.389"],["64633.00","0.292"]],"a":[["64650.00","1.514"],["64655.10","0.635"],["64656.40","0.033"],["64663.30","0.382"],["64803.20","1.049"],["64820.30","0.854"],["64820.50","0.012"],["65296.50","0.001"]],"st":1}}
{"stream":"btcusdt@depth@100ms","data":{"e":"depthUpdate","E":1784410634032,"T":1784410634031,"s":"BTCUSDT","ps":"BTCUSDT","U":11079102632401,"u":11079102643286,"pu":11079102632235,"b":[["1000.00","50.391"],["14149.90","0.910"],["14249.90","0.490"],["14449.90","1.204"],["14549.90","1.596"],["58184.90","0.002"],["63880.60","2.501"],["64003.40","0.000"],["64326.60","0.005"],["64375.10","0.000"],["64378.40","0.117"]],"a":[["64655.10","0.635"],["64656.20","0.001"],["64656.30","0.003"],["64656.40","0.033"],["64656.50","0.021"],["64656.60","0.724"],["64658.40","0.000"],["64658.60","0.000"],["64660.20","0.002"],["64672.50","0.096"],["65296.50","0.001"]],"st":1}}
{"stream":"btcusdt@depth@100ms","data":{"e":"depthUpdate","E":1784410634134,"T":1784410634133,"s":"BTCUSDT","ps":"BTCUSDT","U":11079102643395,"u":11079102656018,"pu":11079102643286,"b":[["1000.00","50.241"],["14149.90","1.036"],["14249.90","0.364"],["14449.90","1.442"],["14549.90","1.358"],["51718.00","0.038"],["58184.90","0.002"],["61407.00","0.002"],["62063.90","0.000"],["63630.50","0.000"],["63809.50","1.253"],["63866.00","17.218"],["63971.80","7.480"],["64003.40","0.000"],["64349.90","0.051"],["64633.00","0.138"],["64638.30","0.002"]],"a":[["64650.00","1.526"],["64655.10","0.048"],["64656.30","0.590"],["64656.40","0.574"],["64656.50","0.021"],["64656.60","0.183"],["64657.60","0.004"],["64658.40","0.047"],["64660.20","0.002"],["64669.10","0.002"],["64669.20","0.048"],["64669.30","0.330"],["64685.50","0.019"],["64685.60","0.001"],["64685.70","0.121"],["64686.00","0.002"],["64686.10","0.063"],["64686.20","0.114"],["64714.00","0.974"],["64715.00","0.092"],["64715.10","0.002"],["64721.70","21.365"],["65296.50","0.001"],["65659.90","1.082"]],"st":1}}
{"stream":"btcusdt@depth@100ms","data":{"e":"depthUpdate","E":1784410634236,"T":1784410634233,"s":"BTCUSDT","ps":"BTCUSDT","U":11079102656216,"u":11079102666153,"pu":11079102656018,"b":[["14149.90","1.148"],["14249.90","0.252"],["14449.90","1.680"],["14549.90","1.120"],["58184.90","0.002"],["62063.90","0.003"],["63635.10","0.024"],["63788.40","2.425"],["64003.40","0.000"],["64326.60","0.781"],["64326.70","0.158"],["64328.60","0.249"],["64496.10","0.000"],["64606.00","0.034"],["64613.30","0.556"],["64615.10","0.414"],["64633.00","0.138"],["64649.90","11.989"]],"a":[["64650.00","1.523"],["64656.30","0.003"],["64662.70","0.182"],["64717.30","32.940"],["64721.70","0.003"],["64803.20","0.027"],["64973.30","0.003"],["65296.50","0.001"],["65664.80","0.795"],["65942.90","0.648"]],"st":1}}
{"stream":"btcusdt@depth@100ms","data":{"e":"depthUpdate","E":1784410634338,"T":1784410634337,"s":"BTCUSDT","ps":"BTCUSDT","U":11079102666453,"u":11079102675682,"pu":11079102666153,"b":[["1000.00","50.241"],["14149.90","1.274"],["14249.90","0.126"],["14449.90","1.918"],["14549.90","0.882"],["58184.90","0.002"],["62063.90","0.000"],["63360.40","0.000"],["64003.40","0.000"],["64182.00","0.088"],["64279.40","0.097"],["64479.00","0.740"],["64488.40","0.007"],["64496.10","0.698"],["64543.80","4.040"],["64564.50","0.002"],["64565.00","0.050"],["64579.90","0.000"],["64619.10","0.140"],["64622.40","2.004"],["64633.00","0.061"],["64636.70","1.343"],["64637.30","0.619"],["64637.40","0.001"],["64637.80","0.929"],["64638.10","0.619"],["64638.40","0.399"],["64638.80","0.634"],["64639.00","0.067"],["64639.10","0.001"],["64640.00","0.235"],["64646.60","0.055"],["64647.30","0.472"],["64647.80","0.171"],["64648.00","0.050"],["64648.50","0.023"],["64649.90","11.961"]],"a":[["64650.00","1.931"],["64650.10","0.002"],["64651.60","0.048"],["64655.10","0.048"],["64655.40","0.047"],["64656.30","0.003"],["64656.40","0.033"],["64656.50","0.743"],["64656.60","0.002"],["64658.60","0.000"],["64660.20","0.002"],["64668.70","0.546"],["64669.70","0.560"],["64670.00","1.077"],["64670.90","0.000"],["64672.00","1.496"],["64677.50","0.560"],["64679.40","0.132"],["64680.10","3.358"],["64683.10","0.000"],["64683.70","0.002"],["64803.20","1.051"],["64820.30","0.870"],["65296.50","0.001"],["65555.10","1.297"],["65645.50","0.000"]],"st":1}}
{"stream":"btcusdt@depth@100ms","data":{"e":"depthUpdate","E":1784410634440,"T":1784410634437,"s":"BTCUSDT","ps":"BTCUSDT","U":11079102675805,"u":11079102683057,"pu":11079102675682,"b":[["14149.90","1.386"],["14249.90","0.014"],["14349.90","0.084"],["14449.90","1.988"],["14549.90","0.728"],["58184.90","0.002"],["61417.40","0.010"],["62063.90","0.003"],["63730.10","0.000"],["63945.20","0.624"],["64003.40","0.000"],["64443.00","0.256"],["64446.30","0.004"],["64463.70","0.047"],["64564.50","0.006"],["64617.70","2.001"],["64620.00","0.013"],["64622.40","0.004"],["64625.60","0.063"],["64626.40","0.447"],["64626.50","0.485"],["64630.10","0.006"],["64630.20","0.055"],["64631.40","1.272"],["64637.30","1.545"],["64637.80","0.003"],["64638.20","0.589"],["64638.80","0.093"],["64639.40","0.241"],["64639.50","0.816"],["64639.90","0.027"],["64640.70","0.056"],["64640.80","0.121"],["64641.40","0.050"],["64642.00","0.002"],["64643.30","0.064"],["64647.90","0.380"],["64648.00","0.003"],["64648.10","0.000"]],"a":[["64650.00","2.853"],["64653.40","0.453"],["64653.70","0.007"],["64656.40","0.033"],["64656.50","0.021"],["64656.60","0.002"],["64658.20","0.131"],["64658.40","0.047"],["64658.50","0.000"],["64658.60","0.000"],["64660.20","0.724"],["64672.00","3.020"],["64674.80","10.000"],["64677.50","0.617"],["64679.20","0.000"],["64680.10","1.358"],["64680.50","2.496"],["64682.00","0.102"],["64682.40","0.005"],["64712.90","21.324"],["64715.10","0.002"],["64717.30","11.618"],["65296.50","0.001"],["65450.60","3.354"],["65589.40","1.149"],["66614.70","0.526"]],"st":1}}
{"stream":"btcusdt@depth@100ms","data":{"e":"depthUpdate","E":1784410634542,"T":1784410634541,"s":"BTCUSDT","ps":"BTCUSDT","U":11079102683258,"u":11079102689920,"pu":11079102683057,"b":[["14149.90","1.288"],["14249.90","0.000"],["14349.90","0.196"],["14449.90","2.002"],["14549.90","0.714"],["51720.00","0.004"],["58184.90","0.002"],["64003.40","0.000"],["64326.70","0.168"],["64536.10","2.320"],["64598.70","0.002"],["64600.90","21.282"],["64636.10","0.957"],["64636.50","0.558"],["64636.70","1.227"],["64636.90","0.933"],["64637.00","1.005"],["64637.30","0.062"],["64638.20","0.048"]],"a":[["64656.50","0.021"],["64656.60","0.002"],["64657.80","0.126"],["64658.20","0.007"],["64658.50","0.000"],["64658.60","0.000"],["64660.20","0.714"],["64669.40","0.098"],["64712.90","0.002"],["64721.70","21.325"],["64754.60","0.021"],["64755.50","0.548"],["64755.60","2.342"],["64755.80","0.000"],["65296.50","0.003"],["65482.90","5.241"],["66589.50","2.175"]],"st":1}}
{"stream":"btcusdt@depth@100ms","data":{"e":"depthUpdate","E":1784410634644,"T":1784410634641,"s":"BTCUSDT","ps":"BTCUSDT","U":11079102689969,"u":11079102696927,"pu":11079102689920,"b":[["1000.00","50.241"],["14149.90","1.176"],["14349.90","0.322"],["14449.90","1.988"],["14549.90","0.714"],["51719.90","0.000"],["58184.90","0.002"],["62063.90","0.000"],["63744.80","0.272"],["63906.40","0.938"],["63945.30","1.563"],["64003.40","0.000"],["64086.70","0.702"],["64349.90","0.051"],["64421.30","0.828"],["64633.00","0.215"],["64634.90","0.271"],["64635.50","1.519"],["64636.10","0.841"],["64637.00","0.464"],["64638.20","0.589"],["64648.20","0.047"]],"a":[["64650.00","1.931"],["64653.30","0.006"],["64656.50","0.716"],["64656.60","0.029"],["64658.60","0.000"],["64659.70","0.030"],["64660.20","0.002"],["64666.10","0.000"],["64715.10","21.324"],["64721.70","0.003"],["65296.50","0.001"],["65482.90","4.861"],["65587.40","3.198"],["65619.80","0.342"]],"st":1}}
{"stream":"btcusdt@depth@100ms","data":{"e":"depthUpdate","E":1784410634746,"T":1784410634745,"s":"BTCUSDT","ps":"BTCUSDT","U":11079102697189,"u":11079102704607,"pu":11079102696927,"b":[["14149.90","1.050"],["14349.90","0.434"],["14449.90","2.002"],["14549.90","0.714"],["58184.90","0.002"],["62063.90","0.003"],["63828.00","0.319"],["64003.40","0.000"],["64297.30","0.018"],["64446.30","0.160"],["64596.50","21.294"],["64598.20","3.636"],["64600.90","0.146"],["64618.40","0.526"],["64618.70","10.060"],["64629.40","0.345"],["64633.00","0.061"],["64645.40","0.106"],["64647.00","0.001"],["64647.20","1.785"]],"a":[["64651.70","0.012"],["64653.40","0.143"],["64656.50","0.175"],["64656.60","0.029"],["64657.70","0.350"],["64658.60","0.000"],["64659.80","0.000"],["64660.10","0.310"],["64660.20","0.002"],["64660.30","0.543"],["64671.10","0.453"],["64674.40","3.668"],["64674.80","10.002"],["64680.40","0.120"],["65516.10","0.008"],["65749.10","0.531"],["65942.90","0.645"]],"st":1}}
{"stream":"btcusdt@depth@100ms","data":{"e":"depthUpdate","E":1784410634848,"T":1784410634847,"s":"BTCUSDT","ps":"BTCUSDT","U":11079102704657,"u":11079102711722,"pu":11079102704607,"b":[["14149.90","0.938"],["14349.90","0.560"],["14449.90","1.988"],["14549.90","0.714"],["58184.90","0.002"],["61414.90","0.002"],["62063.90","0.000"],["63357.00","0.020"],["64003.40","0.000"],["64326.70","0.168"],["64421.30","0.833"],["64463.70","0.043"],["64596.50","0.158"],["64598.20","0.440"],["64598.70","21.138"],["64617.70","0.001"],["64619.30","0.325"],["64621.80","10.000"],["64625.80","0.324"],["64632.30","0.079"],["64633.00","0.215"],["64634.90","0.155"],["64636.20","0.522"],["64636.80","0.431"],["64649.90","12.222"]],"a":[["64650.00","2.118"],["64652.60","0.080"],["64656.20","0.001"],["64656.30","0.003"],["64656.40","0.033"],["64656.50","0.743"],["64656.60","0.002"],["64659.10","0.158"],["64660.30","0.002"],["64665.50","0.393"],["64668.70","0.546"],["64669.10","0.004"],["64669.20","0.050"],["64669.30","0.332"],["64674.50","1.958"],["64685.50","0.021"],["64685.60","0.003"],["64685.70","0.123"],["64686.00","0.004"],["64686.10","0.065"],["64686.20","0.116"],["65296.50","0.003"]],"st":1}}
{"stream":"btcusdt@depth@100ms","data":{"e":"depthUpdate","E":1784410634950,"T":1784410634949,"s":"BTCUSDT","ps":"BTCUSDT","U":11079102711758,"u":11079102718279,"pu":11079102711722,"b":[["1000.00","50.241"],["14149.90","0.812"],["14349.90","0.672"],["14449.90","2.002"],["14549.90","0.714"],["58184.90","0.002"],["63357.00","0.023"],["64003.40","0.000"],["64635.70","0.428"],["64636.80","0.315"]],"a":[["64656.20","0.001"],["64656.30","0.003"],["64656.40","0.033"],["64656.50","0.743"],["64656.60","0.002"],["64658.60","0.000"],["64660.30","0.002"],["64973.30","0.157"],["65169.10","0.000"],["65296.50","0.001"],["65490.50","1.445"],["65527.40","0.925"],["65684.40","0.426"]],"st":1}}
{"stream":"btcusdt@depth@100ms","data":{"e":"depthUpdate","E":1784410635052,"T":1784410635049,"s":"BTCUSDT","ps":"BTCUSDT","U":11079102718378,"u":11079102725873,"pu":11079102718279,"b":[["14149.90","0.700"],["14349.90","0.798"],["14449.90","1.988"],["14549.90","0.714"],["58184.90","0.002"],["61407.20","0.000"],["62063.90","0.003"],["63357.00","0.020"],["64003.40","0.000"],["64297.30","0.023"],["64324.10","0.282"],["64621.80","10.002"],["64622.60","0.003"],["64636.90","0.007"],["64637.90","0.931"],["64638.30","0.007"],["64647.20","1.701"],["64649.80","0.006"],["64649.90","12.218"]],"a":[["64650.00","1.710"],["64650.70","0.003"],["64652.60","0.003"],["64655.10","0.172"],["64656.20","0.155"],["64656.30","0.003"],["64656.40","0.033"],["64656.50","0.589"],["64656.60","0.002"],["64657.60","0.022"],["64657.80","0.002"],["64658.60","0.000"],["64659.30","0.313"],["64660.30","0.002"],["64670.00","0.151"],["64670.40","1.021"],["64679.10","0.057"],["64696.10","3.503"],["64696.40","0.498"],["65167.20","1.282"],["65296.50","0.001"]],"st":1}}
{"stream":"btcusdt@depth@100ms","data":{"e":"depthUpdate","E":1784410635154,"T":1784410635153,"s":"BTCUSDT","ps":"BTCUSDT","U":11079102726110,"u":11079102734454,"pu":11079102725873,"b":[["14149.90","0.574"],["14349.90","1.022"],["14449.90","1.778"],["14549.90","0.826"],["58184.90","0.002"],["61407.00","0.000"],["62063.90","0.000"],["64003.40","0.000"],["64141.70","0.000"],["64326.70","0.168"],["64349.90","0.051"],["64461.00","0.003"],["64496.10","0.000"],["64621.80","0.002"],["64625.80","2.324"],["64638.30","0.002"],["64647.90","0.690"],["64649.90","12.287"]],"a":[["64651.60","0.001"],["64656.30","0.544"],["64656.40","0.033"],["64656.50","0.048"],["64656.60","0.002"],["64658.60","0.000"],["64803.20","0.027"],["64973.30","0.155"],["65296.50","0.001"],["65450.60","3.095"],["65935.70","1.362"]],"st":1}}
{"stream":"btcusdt@depth@100ms","data":{"e":"depthUpdate","E":1784410635256,"T":1784410635255,"s":"BTCUSDT","ps":"BTCUSDT","U":11079102734504,"u":11079102743094,"pu":11079102734454,"b":[["1000.00","50.241"],["14149.90","0.462"],["14349.90","1.260"],["14449.90","1.540"],["14549.90","0.938"],["58184.90","0.002"],["62063.90","0.003"],["63357.00","0.017"],["63712.50","1.097"],["64003.40","0.000"],["64104.70","0.080"],["64326.60","0.783"],["64368.70","0.117"],["64378.40","0.000"],["64463.70","0.047"],["64479.00","0.621"],["64496.10","0.598"],["64620.70","2.525"],["64632.30","0.002"],["64633.00","0.215"],["64638.20","0.048"],["64638.80","0.634"],["64639.90","0.027"]],"a":[["64650.00","1.858"],["64650.10","0.002"],["64651.20","0.004"],["64653.70","0.007"],["64655.40","0.000"],["64656.20","0.001"],["64656.30","0.003"],["64656.50","0.028"],["64656.60","0.022"],["64657.60","0.004"],["64658.60","0.695"],["64659.40","0.018"],["64668.70","0.546"],["64669.60","0.000"],["64670.10","0.931"],["64670.40","0.095"],["64671.10","0.453"],["64677.50","0.003"],["64678.50","0.603"],["64679.20","0.057"],["64683.20","0.001"],["64803.10","1.033"],["64820.20","2.344"],["64820.30","0.001"],["65296.50","0.001"]],"st":1}}
{"stream":"btcusdt@depth@100ms","data":{"e":"depthUpdate","E":1784410635358,"T":1784410635356,"s":"BTCUSDT","ps":"BTCUSDT","U":11079102743168,"u":11079102749718,"pu":11079102743094,"b":[["14149.90","0.336"],["14349.90","1.498"],["14449.90","1.302"],["14549.90","1.064"],["51720.00","0.006"],["58184.90","0.002"],["62063.90","0.000"],["63615.50","1.124"],["63788.40","3.208"],["63898.30","7.274"],["64003.40","0.000"],["64484.20","0.000"],["64631.90","0.001"],["64633.00","0.061"],["64638.40","0.479"],["64638.80","0.634"],["64639.90","0.027"],["64649.90","12.284"]],"a":[["64651.70","0.010"],["64655.30","0.048"],["64656.30","0.157"],["64656.40","0.033"],["64656.50","0.021"],["64656.60","0.012"],["64658.40","0.000"],["64658.60","0.558"],["64668.70","0.546"],["64669.60","0.000"],["64670.10","0.005"],["64671.00","0.928"],["64683.10","0.047"],["65296.50","0.001"],["65684.40","1.490"],["65910.70","0.757"]],"st":1}}
{"stream":"btcusdt@depth@100ms","data":{"e":"depthUpdate","E":1784410635460,"T":1784410635457,"s":"BTCUSDT","ps":"BTCUSDT","U":11079102749845,"u":11079102756818,"pu":11079102749718,"b":[["1000.00","50.241"],["14149.90","0.224"],["14349.90","1.736"],["14449.90","1.064"],["14549.90","1.176"],["51720.00","0.004"],["58184.90","0.002"],["63746.90","8.543"],["64003.40","0.000"],["64326.70","0.168"],["64496.10","0.000"],["64633.00","0.215"],["64649.90","12.059"]],"a":[["64653.70","0.007"],["64655.00","0.128"],["64655.10","0.048"],["64656.30","0.003"],["64656.50","0.038"],["64656.60","0.166"],["64658.50","0.541"],["64658.60","0.000"],["64681.00","0.002"],["64803.10","0.000"],["65296.50","0.001"],["65576.10","0.762"]],"st":1}}
{"stream":"btcusdt@depth@100ms","data":{"e":"depthUpdate","E":1784410635562,"T":1784410635561,"s":"BTCUSDT","ps":"BTCUSDT","U":11079102757049,"u":11079102763492,"pu":11079102756818,"b":[["1000.00","50.241"],["14149.90","0.098"],["14349.90","1.974"],["14449.90","0.826"],["14549.90","1.302"],["58184.90","0.002"],["62063.90","0.003"],["63712.50","2.194"],["64003.40","0.000"],["64479.00","0.701"],["64496.10","0.668"],["64614.20","0.014"],["64614.30","0.400"],["64614.40","0.018"],["64614.70","0.002"],["64614.80","0.006"],["64614.90","0.038"],["64630.10","0.004"],["64630.20","0.053"],["64630.30","0.387"],["64633.00","0.215"],["64649.90","12.109"]],"a":[["64803.00","1.070"],["64820.20","2.377"],["65296.50","0.001"]],"st":1}}
{"stream":"btcusdt@depth@100ms","data":{"e":"depthUpdate","E":1784410635664,"T":1784410635662,"s":"BTCUSDT","ps":"BTCUSDT","U":11079102763683,"u":11079102773087,"pu":11079102763492,"b":[["14149.90","0.000"],["14249.90","0.112"],["14349.90","1.988"],["14449.90","0.714"],["14549.90","1.386"],["51719.90","0.000"],["58184.90","0.004"],["61417.40","0.010"],["62063.90","0.000"],["63885.40","1.221"],["64003.40","0.000"],["64349.90","0.051"],["64626.60","0.053"],["64633.00","0.061"],["64638.40","0.479"],["64646.60","0.032"],["64646.90","0.314"],["64647.90","0.380"],["64649.90","11.910"]],"a":[["64650.00","1.858"],["64652.10","0.004"],["64652.40","0.003"],["64656.40","0.574"],["64656.50","0.038"],["64656.60","0.166"],["64658.50","0.000"],["64658.60","0.000"],["64672.00","1.496"],["64674.80","0.002"],["64679.60","2.982"],["64680.20","11.790"],["65296.50","0.001"],["68228.80","0.000"]],"st":1}}
{"stream":"btcusdt@depth@100ms","data":{"e":"depthUpdate","E":1784410635766,"T":1784410635765,"s":"BTCUSDT","ps":"BTCUSDT","U":11079102773338,"u":11079102780389,"pu":11079102773087,"b":[["1000.00","50.241"],["14249.90","0.224"],["14349.90","2.002"],["14449.90","0.714"],["14549.90","1.260"],["58184.90","0.002"],["62063.90","0.003"],["63744.80","2.622"],["63815.90","0.783"],["63880.60","1.720"],["64003.40","0.000"],["64326.70","0.168"],["64446.30","0.004"],["64496.10","0.000"],["64542.40","0.596"],["64543.40","0.000"],["64585.30","0.109"],["64616.50","1.047"],["64633.00","0.215"]],"a":[["64650.00","1.859"],["64656.40","0.574"],["64656.50","0.038"],["64656.60","0.166"],["64658.60","0.000"],["64714.00","4.038"],["64714.60","0.002"],["64803.00","0.000"],["65296.50","0.001"]],"st":1}}
{"stream":"btcusdt@depth@100ms","data":{"e":"depthUpdate","E":1784410635868,"T":1784410635867,"s":"BTCUSDT","ps":"BTCUSDT","U":11079102780539,"u":11079102787178,"pu":11079102780389,"b":[["1000.00","50.241"],["14249.90","0.350"],["14349.90","1.988"],["14449.90","0.714"],["14549.90","1.148"],["58184.90","0.002"],["62063.90","0.000"],["63841.80","0.532"],["63876.20","3.100"],["64003.40","0.000"],["64442.10","0.142"],["64479.00","0.001"],["64542.40","0.557"],["64543.20","0.039"],["64633.00","0.061"],["64636.20","0.522"]],"a":[["64656.30","0.003"],["64656.40","0.033"],["64656.50","0.038"],["64656.60","0.707"],["64658.60","0.000"],["64668.70","0.546"],["64710.70","21.382"],["64714.00","0.974"],["64715.10","0.002"],["64820.20","1.468"],["64857.30","0.000"],["65296.50","0.001"],["68228.80","0.076"]],"st":1}}
{"stream":"btcusdt@depth@100ms","data":{"e":"depthUpdate","E":1784410635970,"T":1784410635969,"s":"BTCUSDT","ps":"BTCUSDT","U":11079102787266,"u":11079102793958,"pu":11079102787178,"b":[["14249.90","0.462"],["14349.90","2.002"],["14449.90","0.714"],["14549.90","1.022"],["58184.90","0.002"],["62727.30","0.001"],["63583.80","0.549"],["63714.50","0.001"],["63874.10","5.407"],["64003.40","0.000"],["64442.10","3.131"],["64479.00","0.703"],["64496.10","0.669"],["64595.40","0.056"],["64632.90","0.077"],["64633.00","0.215"],["64635.90","0.197"],["64638.40","0.399"],["64649.90","11.909"]],"a":[["64650.00","2.009"],["64653.20","0.082"],["64656.30","0.705"],["64656.40","0.043"],["64656.50","0.031"],["64656.60","0.002"],["64658.50","0.000"],["64658.60","0.000"],["64681.00","0.002"],["64803.00","1.058"],["64820.20","2.366"],["64854.70","1.403"],["64857.00","3.722"],["65296.50","0.001"],["65942.90","0.642"]],"st":1}}
{"stream":"btcusdt@depth@100ms","data":{"e":"depthUpdate","E":1784410636072,"T":1784410636069,"s":"BTCUSDT","ps":"BTCUSDT","U":11079102794210,"u":11079102801916,"pu":11079102793958,"b":[["1000.00","50.241"],["14249.90","0.588"],["14349.90","1.988"],["14449.90","0.714"],["14549.90","0.910"],["58184.90","0.002"],["62063.90","0.003"],["63871.50","9.194"],["64003.40","0.000"],["64132.70","0.748"],["64326.70","0.168"],["64550.10","4.998"],["64557.30","0.298"],["64638.30","0.002"],["64649.90","11.903"]],"a":[["64650.00","1.858"],["64655.30","0.001"],["64656.30","0.157"],["64656.40","0.050"],["64656.50","0.031"],["64656.60","0.002"],["64657.20","0.109"],["64658.60","0.541"],["65296.50","0.001"],["65942.90","0.645"]],"st":1}}
{"stream":"btcusdt@depth@100ms","data":{"e":"depthUpdate","E":1784410636174,"T":1784410636173,"s":"BTCUSDT","ps":"BTCUSDT","U":11079102802056,"u":11079102809244,"pu":11079102801916,"b":[["1000.00","50.241"],["14249.90","0.700"],["14349.90","2.002"],["14449.90","0.714"],["14549.90","0.784"],["58184.90","0.002"],["61407.00","0.002"],["62063.90","0.000"],["63706.00","0.399"],["63712.50","3.291"],["63871.50","4.504"],["64003.40","0.000"],["64349.90","0.051"],["64550.10","4.994"],["64633.00","0.061"],["64644.20","0.576"],["64649.90","11.826"]],"a":[["64656.20","0.001"],["64656.30","0.003"],["64656.40","0.033"],["64656.50","0.021"],["64656.60","0.707"],["64658.60","0.017"],["65296.50","0.001"],["65425.80","6.365"]],"st":1}}
{"stream":"btcusdt@depth@100ms","data":{"e":"depthUpdate","E":1784410636276,"T":1784410636274,"s":"BTCUSDT","ps":"BTCUSDT","U":11079102809352,"u":11079102816266,"pu":11079102809244,"b":[["14249.90","0.840"],["14349.90","1.960"],["14449.90","0.728"],["14549.90","0.672"],["58184.90","0.002"],["61417.40","0.008"],["61417.50","0.005"],["62063.90","0.003"],["63874.10","6.188"],["64003.40","0.000"],["64322.60","0.002"],["64326.60","0.781"],["64559.90","0.005"],["64634.50","0.355"],["64649.90","11.827"]],"a":[["64654.00","0.008"],["64656.30","0.544"],["64656.40","0.050"],["64656.50","0.021"],["64656.60","0.166"],["64657.20","0.062"],["64657.50","0.048"],["64658.60","0.000"],["64681.50","1.950"],["64968.90","0.000"],["65296.50","0.001"],["65423.20","6.116"],["65458.10","2.619"]],"st":1}}
{"stream":"btcusdt@depth@100ms","data":{"e":"depthUpdate","E":1784410636378,"T":1784410636376,"s":"BTCUSDT","ps":"BTCUSDT","U":11079102816591,"u":11079102824379,"pu":11079102816266,"b":[["1000.00","50.241"],["14249.90","1.078"],["14349.90","1.722"],["14449.90","0.854"],["14549.90","0.546"],["58184.90","0.002"],["63917.70","2.969"],["64003.40","0.000"],["64068.00","0.234"],["64326.70","0.168"],["64479.00","0.001"],["64496.10","0.000"],["64633.00","0.215"]],"a":[["64650.00","1.852"],["64656.20","0.001"],["64656.30","0.003"],["64656.40","0.033"],["64656.60","0.707"],["64657.50","0.001"],["64658.00","0.048"],["64658.60","0.017"],["64681.00","0.002"],["64738.80","0.039"],["64752.60","0.004"],["64803.00","0.000"],["64820.20","1.468"],["64973.30","0.157"],["65296.50","0.001"],["65425.80","7.127"],["65942.90","0.648"],["68695.90","0.113"],["68710.50","0.001"]],"st":1}}
{"stream":"btcusdt@depth@100ms","data":{"e":"depthUpdate","E":1784410636480,"T":1784410636479,"s":"BTCUSDT","ps":"BTCUSDT","U":11079102824521,"u":11079102835076,"pu":11079102824379,"b":[["1000.00","50.241"],["14249.90","1.316"],["14349.90","1.484"],["14449.90","0.966"],["14549.90","0.434"],["58184.90","0.002"],["62063.90","0.000"],["63357.00","0.014"],["63809.50","1.566"],["63874.10","10.878"],["64003.40","0.000"],["64368.70","0.000"],["64375.10","0.117"],["64442.10","3.393"],["64443.00","0.100"],["64446.30","0.160"],["64463.70","0.043"],["64478.90","0.741"],["64496.10","0.697"],["64619.30","0.016"],["64625.60","0.006"],["64625.80","0.169"],["64626.70","0.057"],["64628.10","0.000"],["64630.90","10.000"],["64631.40","1.192"],["64631.60","0.559"],["64632.90","0.000"],["64635.10","0.390"],["64635.70","0.312"],["64636.50","0.001"],["64637.10","0.289"],["64637.80","0.003"],["64637.90","0.005"],["64638.80","0.093"],["64638.90","1.019"],["64639.00","0.624"],["64639.90","0.568"],["64640.00","0.238"],["64646.50","0.206"],["64648.70","0.000"],["64649.70","0.001"],["64649.90","11.854"]],"a":[["64650.00","0.906"],["64650.10","0.000"],["64651.50","0.005"],["64653.20","0.005"],["64655.10","0.635"],["64656.40","0.581"],["64656.50","0.021"],["64656.60","0.166"],["64656.80","0.180"],["64658.00","0.001"],["64658.60","0.010"],["64658.70","1.276"],["64659.10","0.003"],["64659.30","0.003"],["64660.30","0.002"],["64660.80","0.006"],["64661.20","0.000"],["64664.60","0.049"],["64664.80","0.003"],["64665.50","0.084"],["64668.70","0.005"],["64669.10","0.002"],["64669.20","0.048"],["64669.30","0.330"],["64669.60","0.541"],["64674.40","3.670"],["64674.80","0.000"],["64679.60","1.199"],["64680.20","1.790"],["64685.50","0.019"],["64685.60","0.001"],["64685.70","0.121"],["64685.80","0.060"],["64686.00","0.002"],["64686.10","0.063"],["64686.20","0.114"],["64687.40","10.002"],["64688.60","0.047"],["64803.00","1.064"],["64820.10","1.034"],["64854.70","0.911"],["64857.00","3.681"],["65255.40","0.000"],["65296.50","0.001"],["65398.10","0.000"],["65458.10","2.999"],["65515.30","27.317"]],"st":1}}
{"stream":"btcusdt@depth@100ms","data":{"e":"depthUpdate","E":1784410636582,"T":1784410636580,"s":"BTCUSDT","ps":"BTCUSDT","U":11079102835195,"u":11079102845125,"pu":11079102835076,"b":[["14249.90","1.554"],["14349.90","1.246"],["14449.90","1.092"],["14549.90","0.308"],["58184.90","0.002"],["62063.90","0.003"],["63357.00","0.017"],["63871.50","4.035"],["64003.40","0.000"],["64240.00","0.504"],["64320.00","0.613"],["64326.70","0.168"],["64400.00","28.447"],["64480.00","4.537"],["64537.40","0.000"],["64538.90","0.004"],["64540.40","0.000"],["64540.50","0.006"],["64541.90","0.000"],["64543.40","0.000"],["64544.90","0.000"],["64546.40","0.556"],["64547.90","0.000"],["64554.60","0.001"],["64560.00","1.320"],["64565.30","0.044"],["64630.10","0.002"],["64630.90","10.002"],["64631.20","0.012"],["64631.40","1.272"],["64631.60","0.557"],["64633.00","0.061"],["64637.70","0.933"],["64637.80","0.560"],["64638.30","0.002"],["64638.90","0.093"],["64639.00","0.067"],["64639.10","0.542"],["64639.90","0.027"],["64646.50","0.149"],["64646.60","0.032"],["64648.20","0.106"],["64649.90","11.868"]],"a":[["64650.00","1.809"],["64650.10","0.002"],["64655.10","0.048"],["64656.40","0.033"],["64656.50","0.562"],["64656.60","0.183"],["64658.60","0.000"],["64659.20","0.701"],["64660.10","0.357"],["64660.30","0.002"],["64668.70","0.546"],["64669.60","0.000"],["64680.30","0.053"],["64714.10","3.826"],["64715.10","0.000"],["64720.00","0.552"],["64800.00","18.636"],["64880.00","9.708"],["64960.00","2.429"],["64970.60","0.000"],["65040.00","0.550"],["65296.50","0.001"],["65427.70","11.315"],["65482.90","4.633"]],"st":1}}
{"stream":"btcusdt@depth@100ms","data":{"e":"depthUpdate","E":1784410636684,"T":1784410636682,"s":"BTCUSDT","ps":"BTCUSDT","U":11079102845266,"u":11079102853476,"pu":11079102845125,"b":[["1000.00","50.241"],["14249.90","1.792"],["14349.90","1.008"],["14449.90","1.204"],["14549.90","0.196"],["51719.90","0.000"],["51720.00","0.004"],["58184.90","0.002"],["62063.90","0.000"],["64003.40","0.000"],["64320.00","0.630"],["64400.00","28.464"],["64480.00","4.554"],["64560.00","1.337"],["64615.40","0.145"],["64633.00","0.215"],["64636.50","0.117"],["64637.10","0.173"],["64640.00","0.255"]],"a":[["64656.30","0.003"],["64656.40","0.033"],["64656.50","0.021"],["64656.60","0.166"],["64658.60","0.541"],["64660.10","0.048"],["64660.20","0.019"],["64660.30","0.311"],["64720.00","0.569"],["64800.00","18.653"],["64880.00","9.725"],["64960.00","2.446"],["65040.00","0.567"],["65296.50","0.001"],["65458.40","7.560"],["65490.40","0.355"],["65612.00","3.597"]],"st":1}}
{"stream":"btcusdt@depth@100ms","data":{"e":"depthUpdate","E":1784410636786,"T":1784410636785,"s":"BTCUSDT","ps":"BTCUSDT","U":11079102853802,"u":11079102863067,"pu":11079102853476,"b":[["1000.00","50.241"],["14149.90","0.014"],["14249.90","2.002"],["14349.90","0.784"],["14449.90","1.330"],["14549.90","0.070"],["51720.00","0.006"],["58184.90","0.002"],["62063.90","0.003"],["64003.40","0.001"],["64326.60","0.936"],["64478.90","0.741"],["64496.10","0.697"],["64564.50","0.002"],["64582.60","0.001"],["64598.80","3.250"],["64633.00","0.215"],["64633.50","3.262"]],"a":[["64656.30","0.698"],["64656.40","0.033"],["64656.50","0.038"],["64656.60","0.012"],["64657.30","0.002"],["64658.60","0.000"],["64660.20","0.002"],["64662.30","24.234"],["64680.30","0.048"],["64681.00","0.079"],["64688.60","0.000"],["64710.60","3.877"],["64803.00","1.079"],["64820.10","1.061"],["64973.20","0.692"],["64973.30","0.772"],["65181.20","4.548"],["65205.30","0.000"],["65296.50","0.001"],["65425.80","8.654"],["65490.40","0.660"],["65746.40","0.760"],["66626.00","8.435"]],"st":1}}
{"stream":"btcusdt@depth@100ms","data":{"e":"depthUpdate","E":1784410636888,"T":1784410636887,"s":"BTCUSDT","ps":"BTCUSDT","U":11079102863224,"u":11079102871937,"pu":11079102863067,"b":[["14149.90","0.140"],["14249.90","1.988"],["14349.90","0.714"],["14449.90","1.358"],["14549.90","0.000"],["51720.00","0.004"],["58184.90","0.002"],["61417.40","0.010"],["64003.40","0.001"],["64326.70","0.168"],["64496.40","0.000"],["64536.10","2.320"],["64636.20","0.522"]],"a":[["64651.70","0.012"],["64656.30","0.003"],["64656.50","0.175"],["64656.60","0.029"],["64658.60","0.000"],["64660.20","0.543"],["64668.70","0.546"],["64681.00","0.002"],["64755.00","2.321"],["64755.50","0.202"],["64755.60","0.022"],["65296.50","0.001"],["65425.80","8.913"],["65458.80","0.763"]],"st":1}}
{"stream":"btcusdt@depth@100ms","data":{"e":"depthUpdate","E":1784410636990,"T":1784410636989,"s":"BTCUSDT","ps":"BTCUSDT","U":11079102872062,"u":11079102880438,"pu":11079102871937,"b":[["1000.00","50.241"],["14149.90","0.252"],["14249.90","2.002"],["14349.90","0.714"],["14449.90","1.232"],["58184.90","0.002"],["62063.90","0.000"],["64003.40","0.001"],["64443.00","0.256"],["64482.90","15.485"],["64483.00","0.121"],["64483.80","0.034"],["64484.30","0.004"],["64485.00","0.343"],["64496.50","0.000"],["64498.60","0.222"],["64562.60","0.008"],["64631.60","0.774"],["64633.00","0.061"]],"a":[["64651.50","0.000"],["64653.20","0.010"],["64656.40","0.591"],["64656.50","0.175"],["64656.60","0.012"],["64658.60","0.000"],["64660.20","0.002"],["64668.70","0.005"],["64669.60","0.541"],["65296.50","0.003"]],"st":1}}
{"stream":"btcusdt@depth@100ms","data":{"e":"depthUpdate","E":1784410637092,"T":1784410637091,"s":"BTCUSDT","ps":"BTCUSDT","U":11079102880489,"u":11079102889307,"pu":11079102880438,"b":[["1000.00","50.241"],["14149.90","0.378"],["14249.90","1.988"],["14349.90","0.714"],["14449.90","1.120"],["58184.90","0.002"],["62063.90","0.003"],["64003.40","0.000"],["64551.70","0.002"],["64551.80","0.003"],["64585.30","0.110"],["64614.20","0.016"],["64614.30","0.402"],["64614.40","0.020"],["64614.70","0.004"],["64614.80","0.008"],["64614.90","0.040"],["64619.70","0.309"],["64626.20","0.468"],["64630.10","0.004"],["64630.20","0.055"],["64630.30","0.389"],["64632.60","0.078"],["64638.30","0.002"],["64648.20","0.047"],["64648.50","0.032"],["64649.90","11.853"]],"a":[["64653.00","0.077"],["64654.40","0.001"],["64655.00","0.175"],["64656.30","0.003"],["64656.40","0.033"],["64656.50","0.021"],["64656.60","0.770"],["64658.60","0.541"],["64659.40","0.173"],["64660.20","0.002"],["64665.90","0.360"],["64842.60","0.000"],["64842.70","0.244"],["65296.50","0.001"],["65416.70","0.001"],["65427.70","9.802"],["65749.00","3.343"]],"st":1}}
{"stream":"btcusdt@depth@100ms","data":{"e":"depthUpdate","E":1784410637194,"T":1784410637192,"s":"BTCUSDT","ps":"BTCUSDT","U":11079102889382,"u":11079102898332,"pu":11079102889307,"b":[["14149.90","0.490"],["14249.90","2.002"],["14349.90","0.714"],["14449.90","0.994"],["58184.90","0.002"],["61407.00","0.000"],["62063.90","0.000"],["63874.10","11.144"],["64003.40","0.000"],["64326.70","0.168"],["64496.10","0.000"],["64498.60","0.000"],["64633.00","0.215"],["64637.70","0.007"],["64638.70","1.555"],["64639.10","0.001"],["64640.70","0.597"],["64649.90","11.929"]],"a":[["64650.00","1.811"],["64655.00","0.128"],["64655.30","0.048"],["64656.20","0.723"],["64656.30","0.003"],["64656.40","0.033"],["64656.50","0.021"],["64656.60","0.589"],["64658.60","0.000"],["64660.20","0.002"],["64669.60","0.000"],["64670.90","0.000"],["64671.00","0.002"],["64671.80","0.588"],["64671.90","0.927"],["64678.50","0.054"],["64679.30","0.001"],["64679.40","0.688"],["64803.00","0.000"],["65296.50","0.001"]],"st":1}}
{"stream":"btcusdt@depth@100ms","data":{"e":"depthUpdate","E":1784410637296,"T":1784410637295,"s":"BTCUSDT","ps":"BTCUSDT","U":11079102898520,"u":11079102907412,"pu":11079102898332,"b":[["1000.00","50.241"],["14149.90","0.616"],["14249.90","1.988"],["14349.90","0.714"],["14449.90","0.882"],["51720.00","0.004"],["58184.90","0.002"],["63357.00","0.020"],["64003.40","0.000"],["64478.90","0.745"],["64496.10","0.700"],["64551.80","0.007"],["64559.90","0.001"],["64611.10","0.584"],["64639.90","0.568"],["64640.70","0.056"],["64649.90","11.931"]],"a":[["64656.20","0.001"],["64656.40","1.161"],["64656.50","0.202"],["64656.60","0.002"],["64658.60","0.000"],["64660.20","0.002"],["64669.60","0.541"],["64671.80","0.047"],["64678.50","0.047"],["64679.00","0.009"],["64802.90","1.079"],["64820.10","1.061"],["65296.50","0.001"]],"st":1}}
{"stream":"btcusdt@depth@100ms","data":{"e":"depthUpdate","E":1784410637398,"T":1784410637397,"s":"BTCUSDT","ps":"BTCUSDT","U":11079102907633,"u":11079102915872,"pu":11079102907412,"b":[["1000.00","50.241"],["14149.90","0.728"],["14249.90","2.002"],["14349.90","0.714"],["14449.90","0.756"],["58184.90","0.002"],["62063.90","0.003"],["63554.40","0.000"],["63788.40","3.991"],["63815.90","0.000"],["63848.20","0.782"],["63971.80","6.779"],["64003.40","0.000"]],"a":[["64651.70","0.010"],["64653.00","0.079"],["64656.20","0.542"],["64656.30","0.003"],["64656.40","0.033"],["64656.50","0.031"],["64656.60","0.589"],["64658.60","0.000"],["64660.20","0.173"],["64973.30","0.770"],["65296.50","0.001"],["65425.80","10.440"]],"st":1}}
{"stream":"btcusdt@depth@100ms","data":{"e":"depthUpdate","E":1784410637500,"T":1784410637497,"s":"BTCUSDT","ps":"BTCUSDT","U":11079102916005,"u":11079102924481,"pu":11079102915872,"b":[["14149.90","0.896"],["14249.90","1.904"],["14349.90","0.756"],["14449.90","0.644"],["58184.90","0.002"],["62063.90","0.000"],["63853.10","0.781"],["64003.40","0.000"],["64326.60","0.938"],["64326.70","0.158"],["64446.30","0.004"],["64478.90","0.741"],["64496.00","0.702"],["64496.10","0.000"],["64542.80","0.135"],["64543.20","0.000"],["64633.00","0.061"],["64636.50","0.001"],["64637.20","0.199"],["64637.80","0.003"],["64638.50","0.625"],["64639.50","0.662"],["64640.70","0.210"]],"a":[["64655.30","0.001"],["64655.50","0.086"],["64655.90","0.001"],["64656.00","0.008"],["64656.20","0.001"],["64656.40","0.033"],["64656.50","0.726"],["64656.60","0.002"],["64658.50","0.017"],["64658.60","0.000"],["64660.20","0.002"],["64678.70","0.557"],["64679.00","0.002"],["64679.30","0.008"],["64679.40","0.132"],["64802.90","1.079"],["64820.10","1.059"],["65296.50","0.001"],["65560.50","0.584"],["66645.20","0.000"]],"st":1}}
{"stream":"btcusdt@depth@100ms","data":{"e":"depthUpdate","E":1784410637602,"T":1784410637601,"s":"BTCUSDT","ps":"BTCUSDT","U":11079102924792,"u":11079102934250,"pu":11079102924481,"b":[["1000.00","50.241"],["14149.90","1.134"],["14249.90","1.666"],["14349.90","0.882"],["14449.90","0.518"],["58184.90","0.002"],["61417.40","0.008"],["61417.50","0.007"],["62063.90","0.003"],["63518.50","1.260"],["63877.50","3.905"],["63945.20","1.326"],["64003.40","0.000"],["64026.90","0.618"],["64488.30","0.193"],["64633.00","0.215"],["64636.80","0.431"],["64637.20","0.083"]],"a":[["64655.50","0.039"],["64655.80","0.082"],["64656.20","0.542"],["64656.30","0.157"],["64656.40","0.033"],["64656.50","0.031"],["64658.60","0.000"],["64660.20","0.002"],["64681.00","0.079"],["64700.00","1.156"],["65296.50","0.001"]],"st":1}}
{"stream":"btcusdt@depth@100ms","data":{"e":"depthUpdate","E":1784410637704,"T":1784410637703,"s":"BTCUSDT","ps":"BTCUSDT","U":11079102934414,"u":11079102949946,"pu":11079102934250,"b":[["1000.00","50.241"],["14149.90","1.372"],["14249.90","1.428"],["14349.90","0.994"],["14449.90","0.406"],["51719.90","0.000"],["58184.90","0.002"],["62063.90","0.000"],["63557.30","0.553"],["64003.40","0.000"],["64320.00","0.613"],["64368.70","0.117"],["64375.10","0.000"],["64400.00","28.447"],["64458.50","0.065"],["64480.00","4.537"],["64520.70","3.868"],["64520.90","0.000"],["64542.80","0.096"],["64543.00","0.100"],["64551.80","0.003"],["64558.30","0.001"],["64559.90","0.005"],["64560.00","1.320"],["64564.50","0.006"],["64567.10","0.013"],["64568.00","0.017"],["64569.20","0.028"],["64571.20","0.464"],["64577.70","0.464"],["64578.90","11.626"],["64579.80","0.071"],["64580.00","0.105"],["64580.90","0.000"],["64582.20","0.000"],["64582.30","1.140"],["64584.10","0.000"],["64587.40","0.024"],["64591.50","0.016"],["64591.80","0.339"],["64592.10","0.216"],["64593.90","0.000"],["64595.00","1.264"],["64598.30","0.427"],["64598.70","21.138"],["64604.70","0.022"],["64604.80","0.494"],["64607.20","0.741"],["64616.50","1.043"],["64619.70","0.000"],["64621.00","0.015"],["64623.20","0.000"],["64626.20","0.309"],["64627.40","0.582"],["64630.80","0.001"],["64630.90","0.002"],["64632.60","0.001"],["64633.00","0.061"],["64633.10","0.058"],["64633.50","1.601"],["64635.90","2.197"],["64636.80","0.315"],["64637.10","0.177"],["64637.60","0.117"],["64638.50","0.618"],["64638.70","0.629"],["64638.80","0.093"],["64639.40","0.241"],["64639.60","0.015"],["64639.90","0.027"],["64640.00","0.238"],["64640.20","0.928"],["64641.30","0.830"],["64641.90","0.334"],["64642.40","0.310"],["64645.10","0.217"],["64647.20","1.699"],["64647.80","0.173"],["64648.40","0.059"],["64648.50","0.034"],["64649.90","13.169"]],"a":[["64650.00","1.304"],["64650.10","0.000"],["64653.00","0.002"],["64655.10","0.048"],["64655.80","0.035"],["64656.20","0.001"],["64656.30","0.003"],["64656.50","0.021"],["64656.60","0.589"],["64657.00","0.005"],["64658.20","0.007"],["64658.40","0.000"],["64658.50","0.000"],["64658.60","0.000"],["64658.90","0.049"],["64659.20","0.391"],["64659.40","0.018"],["64659.50","0.184"],["64659.70","0.030"],["64660.10","0.001"],["64660.20","0.724"],["64660.30","0.311"],["64661.70","0.065"],["64665.90","0.051"],["64669.10","0.004"],["64669.20","0.050"],["64669.30","0.332"],["64669.60","0.000"],["64671.70","0.556"],["64671.80","0.047"],["64671.90","0.001"],["64672.60","1.314"],["64675.60","0.483"],["64676.00","0.001"],["64678.70","0.001"],["64679.30","0.001"],["64679.60","1.755"],["64679.80","0.070"],["64679.90","0.583"],["64681.00","0.002"],["64685.50","0.021"],["64685.60","0.003"],["64685.70","0.123"],["64685.80","0.013"],["64686.00","0.004"],["64686.10","0.065"],["64686.20","0.116"],["64687.40","0.002"],["64689.20","10.001"],["64692.50","0.696"],["64692.90","0.001"],["64694.00","2.166"],["64694.90","0.467"],["64695.70","0.084"],["64696.10","0.003"],["64699.40","0.061"],["64718.70","0.015"],["64720.00","0.552"],["64722.10","0.146"],["64722.30","0.004"],["64771.40","0.060"],["64774.60","3.867"],["64776.70","0.024"],["64780.80","0.342"],["64790.70","0.025"],["64795.00","0.000"],["64796.00","0.000"],["64798.30","0.006"],["64800.00","18.636"],["64802.80","0.004"],["64804.50","0.000"],["64880.00","9.708"],["64960.00","2.429"],["65040.00","0.550"],["65296.50","0.002"],["65427.70","8.289"],["65942.90","0.648"]],"st":1}}
{"stream":"btcusdt@depth@100ms","data":{"e":"depthUpdate","E":1784410637806,"T":1784410637804,"s":"BTCUSDT","ps":"BTCUSDT","U":11079102950148,"u":11079102959412,"pu":11079102949946,"b":[["14149.90","1.610"],["14249.90","1.190"],["14349.90","1.120"],["14449.90","0.280"],["51720.00","0.004"],["58184.90","0.002"],["62729.80","0.011"],["63619.10","0.188"],["63874.10","12.707"],["63920.10","3.282"],["64003.40","0.000"],["64326.70","0.168"],["64443.00","0.100"],["64453.30","0.316"],["64471.40","0.000"],["64540.40","0.202"],["64542.80","0.135"],["64543.00","0.061"],["64549.90","0.000"],["64582.10","0.374"],["64588.60","0.642"],["64627.40","0.584"],["64633.00","0.061"],["64635.90","0.197"],["64638.50","1.544"],["64639.60","0.556"],["64639.70","0.013"],["64640.20","0.002"],["64640.30","0.337"],["64641.30","0.289"]],"a":[["64650.00","2.109"],["64650.10","0.002"],["64655.90","0.048"],["64656.30","0.003"],["64656.40","0.033"],["64656.50","0.021"],["64656.60","0.589"],["64660.20","0.724"],["64669.60","0.541"],["64670.90","0.926"],["64671.70","0.015"],["64672.60","0.388"],["64751.10","0.093"],["64854.70","1.396"],["65250.90","1.072"],["65296.50","0.002"],["65942.90","0.645"]],"st":1}}
{"stream":"btcusdt@depth@100ms","data":{"e":"depthUpdate","E":1784410637908,"T":1784410637905,"s":"BTCUSDT","ps":"BTCUSDT","U":11079102959541,"u":11079102965906,"pu":11079102959412,"b":[["1000.00","50.241"],["14149.90","1.848"],["14249.90","0.952"],["14349.90","1.232"],["14449.90","0.168"],["58184.90","0.002"],["61417.40","0.010"],["62063.90","0.003"],["63357.00","0.023"],["64003.40","0.000"],["64320.00","0.630"],["64400.00","28.464"],["64480.00","4.554"],["64485.00","0.499"],["64537.40","1.276"],["64538.90","1.280"],["64540.40","1.478"],["64541.90","1.276"],["64543.40","1.276"],["64544.90","1.276"],["64546.40","1.832"],["64547.90","1.276"],["64549.40","1.311"],["64560.00","1.337"],["64569.70","0.001"],["64582.20","6.000"],["64594.30","21.261"],["64598.70","0.002"],["64598.80","0.000"],["64600.90","0.146"],["64601.00","3.431"],["64604.80","3.994"],["64607.70","0.006"],["64621.00","0.734"],["64626.60","0.133"],["64631.80","10.013"],["64633.00","0.215"],["64633.50","3.299"],["64635.90","0.233"],["64636.20","0.522"],["64637.40","0.558"],["64637.60","0.001"],["64637.70","0.933"],["64638.50","0.061"],["64638.80","0.634"],["64639.60","0.015"],["64640.00","0.255"],["64646.50","0.126"],["64647.10","0.004"],["64647.80","0.171"],["64648.40","0.000"],["64649.90","12.191"]],"a":[["64650.00","2.282"],["64650.40","0.004"],["64652.00","0.008"],["64652.30","1.182"],["64652.60","0.003"],["64652.90","0.000"],["64653.10","0.001"],["64653.20","0.005"],["64656.60","0.002"],["64657.50","0.311"],["64657.70","0.366"],["64659.40","0.000"],["64668.70","0.005"],["64679.60","2.452"],["64683.10","0.000"],["64695.80","3.500"],["64718.40","6.003"],["64720.00","0.569"],["64748.80","0.385"],["64800.00","18.653"],["64880.00","9.725"],["64960.00","2.446"],["65040.00","0.567"],["65296.50","0.002"],["65450.60","2.836"]],"st":1}}
{"stream":"btcusdt@depth@100ms","data":{"e":"depthUpdate","E":1784410638010,"T":1784410638009,"s":"BTCUSDT","ps":"BTCUSDT","U":11079102966135,"u":11079102973409,"pu":11079102965906,"b":[["1000.00","50.241"],["14149.90","2.002"],["14249.90","0.756"],["14349.90","1.358"],["14449.90","0.042"],["14549.90","0.042"],["51720.00","0.004"],["58184.90","0.002"],["62063.90","0.000"],["63583.20","0.707"],["63893.50","1.094"],["64003.40","0.000"],["64453.30","0.312"],["64455.90","0.045"],["64458.50","0.065"],["64485.00","0.499"],["64537.40","0.000"],["64538.90","0.004"],["64540.40","0.202"],["64541.90","0.000"],["64543.40","0.000"],["64544.90","0.000"],["64546.40","0.556"],["64546.50","0.000"],["64547.90","0.000"],["64549.40","0.035"],["64564.50","0.006"],["64567.10","0.017"],["64576.80","0.000"],["64577.10","0.001"],["64577.50","0.003"],["64577.80","0.014"],["64578.10","0.000"],["64596.60","0.001"],["64596.90","0.000"],["64597.20","0.001"],["64597.50","0.001"],["64597.80","0.000"],["64598.90","0.240"],["64599.50","0.089"],["64599.90","0.093"],["64600.20","0.061"],["64601.00","0.006"],["64607.70","0.010"],["64612.10","0.000"],["64612.20","0.093"],["64612.30","0.006"],["64612.40","0.002"],["64612.70","0.060"],["64612.80","0.461"],["64613.40","0.001"],["64616.30","0.000"],["64616.40","0.311"],["64626.60","0.053"],["64633.00","0.061"],["64635.40","0.047"],["64635.50","0.859"],["64635.70","0.000"],["64635.90","0.313"],["64636.00","0.159"],["64636.10","0.217"],["64636.30","0.160"],["64636.40","1.064"],["64636.60","0.000"],["64636.70","0.951"],["64637.00","0.390"],["64637.30","0.001"],["64638.40","0.623"],["64638.80","0.093"],["64639.00","0.121"],["64639.30","0.075"],["64639.60","0.076"],["64639.90","0.568"],["64649.90","12.198"]],"a":[["64650.00","1.811"],["64652.00","0.013"],["64653.00","0.000"],["64655.50","0.007"],["64655.80","0.003"],["64655.90","0.001"],["64656.10","0.003"],["64656.30","0.001"],["64656.40","0.001"],["64656.50","0.021"],["64656.60","0.002"],["64656.70","1.276"],["64656.80","0.000"],["64657.10","0.029"],["64657.20","0.002"],["64657.40","0.001"],["64657.70","0.398"],["64658.10","0.037"],["64658.40","0.032"],["64659.10","0.095"],["64660.20","0.724"],["64675.20","0.005"],["64675.50","0.701"],["64675.80","0.000"],["64676.20","0.002"],["64676.40","0.082"],["64676.50","0.000"],["64677.50","0.035"],["64677.80","0.123"],["64678.10","0.082"],["64678.80","0.171"],["64679.40","0.012"],["64680.00","0.446"],["64680.10","1.298"],["64680.40","0.000"],["64680.50","2.436"],["64680.60","0.008"],["64680.70","0.000"],["64694.90","0.851"],["64695.20","0.029"],["64695.50","0.312"],["64695.90","0.420"],["64696.20","0.000"],["64751.00","0.000"],["64752.00","0.010"],["65296.50","0.002"],["65425.80","11.965"]],"st":1}}
{"stream":"btcusdt@depth@100ms","data":{"e":"depthUpdate","E":1784410638112,"T":1784410638111,"s":"BTCUSDT","ps":"BTCUSDT","U":11079102973575,"u":11079102980803,"pu":11079102973409,"b":[["14149.90","1.988"],["14249.90","0.714"],["14349.90","1.330"],["14449.90","0.000"],["14549.90","0.168"],["58184.90","0.002"],["61417.40","0.012"],["62063.90","0.003"],["64003.40","0.000"],["64326.70","0.168"],["64455.90","0.041"],["64458.50","0.061"],["64463.70","0.047"],["64549.90","10.000"],["64551.70","0.005"],["64551.80","0.000"],["64594.30","0.418"],["64598.70","20.845"],["64620.00","0.322"],["64626.50","0.640"],["64632.90","0.077"],["64637.70","0.007"],["64637.80","0.717"],["64638.30","0.009"],["64638.40","0.941"],["64638.50","0.987"],["64639.30","0.075"],["64639.60","0.069"],["64649.90","12.194"]],"a":[["64650.00","1.810"],["64653.20","0.082"],["64653.70","0.007"],["64654.50","0.003"],["64654.70","0.000"],["64654.90","0.003"],["64655.20","1.277"],["64655.50","0.007"],["64655.80","0.003"],["64656.00","0.055"],["64656.60","0.002"],["64658.60","0.541"],["64659.00","0.062"],["64659.10","0.155"],["64659.60","0.063"],["64659.70","0.365"],["64660.20","0.183"],["64666.20","0.620"],["64669.60","0.000"],["64669.70","1.101"],["64670.70","0.001"],["64670.80","0.001"],["64670.90","0.000"],["64671.70","0.015"],["64671.80","0.973"],["64678.80","0.231"],["64682.20","0.060"],["64682.90","10.173"],["64683.00","0.782"],["64749.40","10.016"],["65296.50","0.002"]],"st":1}}
{"stream":"btcusdt@depth@100ms","data":{"e":"depthUpdate","E":1784410638214,"T":1784410638213,"s":"BTCUSDT","ps":"BTCUSDT","U":11079102980964,"u":11079102988516,"pu":11079102980803,"b":[["1000.00","50.241"],["14149.90","2.002"],["14249.90","0.714"],["14349.90","1.204"],["14549.90","0.280"],["51720.00","0.004"],["58184.90","0.002"],["62063.90","0.000"],["63746.90","6.213"],["64003.40","0.000"],["64599.20","0.068"],["64633.00","0.215"],["64638.10","0.775"],["64638.40","1.097"],["64638.50","1.137"],["64638.70","0.696"],["64649.90","12.195"]],"a":[["64653.70","0.594"],["64656.00","0.008"],["64656.60","0.315"],["64657.60","0.004"],["64658.70","1.308"],["64659.00","0.122"],["64659.10","0.215"],["64659.40","0.060"],["64678.40","0.056"],["64682.30","0.151"],["64682.70","0.343"],["64749.30","0.008"],["64752.00","0.002"],["65236.00","0.234"],["65296.50","0.002"],["65361.20","3.055"]],"st":1}}
{"stream":"btcusdt@depth@100ms","data":{"e":"depthUpdate","E":1784410638316,"T":1784410638315,"s":"BTCUSDT","ps":"BTCUSDT","U":11079102988625,"u":11079102996063,"pu":11079102988516,"b":[["1000.00","50.241"],["14149.90","1.988"],["14249.90","0.714"],["14349.90","1.092"],["14549.90","0.406"],["58184.90","0.002"],["64003.40","0.000"],["64240.00","0.487"],["64320.00","0.613"],["64400.00","28.447"],["64478.90","0.726"],["64480.00","4.537"],["64496.00","0.690"],["64560.00","1.320"],["64579.20","0.078"],["64579.80","0.132"],["64580.20","0.083"],["64580.50","2.694"],["64607.70","0.006"],["64620.00","0.013"],["64626.50","0.485"],["64632.90","0.000"],["64633.00","0.061"],["64636.80","0.006"],["64637.70","0.163"],["64637.90","0.125"],["64638.10","0.931"],["64638.50","0.367"],["64638.80","0.402"],["64639.00","0.259"],["64639.50","1.588"],["64639.90","0.027"],["64640.30","0.337"],["64640.70","0.751"],["64641.30","0.289"],["64649.90","12.237"]],"a":[["64650.00","1.808"],["64653.00","0.000"],["64653.20","0.005"],["64653.30","0.006"],["64653.70","0.007"],["64654.10","0.000"],["64654.40","0.001"],["64654.60","0.003"],["64654.90","0.003"],["64655.20","1.324"],["64658.40","0.092"],["64659.00","0.182"],["64659.40","0.120"],["64659.50","0.244"],["64659.70","0.270"],["64666.20","0.311"],["64669.70","0.560"],["64671.70","0.556"],["64671.80","0.047"],["64672.80","0.926"],["64675.50","0.001"],["64679.20","0.000"],["64680.70","0.057"],["64681.70","0.084"],["64682.30","0.211"],["64682.70","0.403"],["64682.80","2.533"],["64683.00","0.842"],["64697.20","0.049"],["64697.50","0.342"],["64697.80","0.032"],["64698.50","0.032"],["64720.00","0.552"],["64800.00","18.636"],["64802.90","1.079"],["64820.00","2.169"],["64820.10","0.143"],["64880.00","9.708"],["64960.00","2.429"],["65040.00","0.550"],["65296.50","0.002"],["65458.10","3.227"]],"st":1}}
{"stream":"btcusdt@depth@100ms","data":{"e":"depthUpdate","E":1784410638418,"T":1784410638416,"s":"BTCUSDT","ps":"BTCUSDT","U":11079102996130,"u":11079103002144,"pu":11079102996063,"b":[["14149.90","2.002"],["14249.90","0.714"],["14349.90","0.966"],["14549.90","0.518"],["51720.00","0.004"],["58184.90","0.002"],["61417.40","0.010"],["61417.50","0.009"],["62063.90","0.003"],["63744.80","4.972"],["63874.10","13.176"],["64003.40","0.000"],["64326.70","0.168"],["64463.70","0.043"],["64496.00","0.703"],["64537.40","0.000"],["64538.90","0.004"],["64540.40","0.202"],["64541.90","0.000"],["64543.40","0.000"],["64544.90","0.000"],["64546.40","0.556"],["64547.90","0.000"],["64560.10","0.026"],["64570.90","0.182"],["64607.70","0.010"],["64618.70","10.210"],["64627.10","1.354"],["64636.00","0.189"],["64638.70","1.622"],["64638.80","0.402"],["64639.10","0.139"],["64639.50","0.662"],["64639.90","0.568"],["64640.70","0.210"],["64640.80","0.121"],["64646.70","0.016"],["64648.80","0.061"]],"a":[["64653.30","0.130"],["64653.70","0.007"],["64655.00","0.004"],["64655.20","1.277"],["64656.10","0.003"],["64656.50","0.021"],["64657.60","0.161"],["64658.40","0.152"],["64669.30","0.312"],["64669.60","0.541"],["64670.80","0.001"],["64671.10","1.299"],["64671.20","0.023"],["64671.70","0.015"],["64672.80","0.000"],["64680.40","0.080"],["64681.60","0.064"],["64699.50","0.042"],["64714.50","0.026"],["64802.90","1.079"],["65296.50","0.002"],["65576.10","1.524"],["65592.90","0.000"]],"st":1}}
{"stream":"btcusdt@depth@100ms","data":{"e":"depthUpdate","E":1784410638520,"T":1784410638517,"s":"BTCUSDT","ps":"BTCUSDT","U":11079103002240,"u":11079103010573,"pu":11079103002144,"b":[["1000.00","50.241"],["14149.90","1.988"],["14249.90","0.714"],["14349.90","0.854"],["14549.90","0.644"],["58184.90","0.002"],["62063.90","0.000"],["63686.50","0.783"],["63949.40","0.000"],["63957.30","0.941"],["64003.40","0.000"],["64240.00","0.317"],["64320.00","0.460"],["64326.60","0.936"],["64400.00","28.294"],["64480.00","4.384"],["64488.30","0.037"],["64542.80","0.135"],["64543.00","0.061"],["64560.00","1.167"],["64579.50","0.192"],["64614.50","0.527"],["64614.60","0.496"],["64615.20","0.722"],["64618.70","10.390"],["64633.00","0.061"],["64635.90","0.197"],["64636.80","0.122"],["64637.40","0.001"],["64638.40","1.654"],["64640.00","0.272"]],"a":[["64653.70","0.594"],["64656.50","0.031"],["64656.60","0.315"],["64657.60","0.004"],["64658.50","0.171"],["64660.20","0.002"],["64670.80","0.081"],["64678.70","0.557"],["64679.00","0.009"],["64679.60","1.896"],["64679.80","0.063"],["64680.40","0.000"],["64698.20","0.032"],["64699.40","0.062"],["64714.50","0.025"],["64720.00","0.399"],["64773.30","0.012"],["64800.00","18.483"],["64880.00","9.555"],["64960.00","2.276"],["64973.30","0.772"],["65040.00","0.397"],["65296.50","0.002"]],"st":1}}
{"stream":"btcusdt@depth@100ms","data":{"e":"depthUpdate","E":1784410638622,"T":1784410638621,"s":"BTCUSDT","ps":"BTCUSDT","U":11079103010760,"u":11079103017746,"pu":11079103010573,"b":[["1000.00","50.241"],["14149.90","2.002"],["14249.90","0.714"],["14349.90","0.728"],["14549.90","0.756"],["51720.00","0.006"],["58184.90","0.002"],["62063.90","0.003"],["63686.50","0.000"],["63863.60","0.405"],["63971.80","6.078"],["64003.40","0.000"],["64614.20","0.014"],["64614.30","0.400"],["64614.40","0.018"],["64614.70","0.002"],["64614.80","0.162"],["64614.90","0.038"],["64615.10","0.570"],["64615.20","0.872"],["64630.10","0.002"],["64630.20","0.053"],["64630.30","0.387"],["64633.00","0.215"],["64638.90","0.135"],["64646.80","0.091"],["64648.20","0.106"],["64648.80","0.002"]],"a":[["64650.00","1.810"],["64653.70","0.007"],["64655.10","0.635"],["64656.50","0.021"],["64656.60","0.002"],["64658.40","0.162"],["64675.50","0.701"],["65296.50","0.002"],["65380.20","1.165"]],"st":1}}
{"stream":"btcusdt@depth@100ms","data":{"e":"depthUpdate","E":1784410638724,"T":1784410638721,"s":"BTCUSDT","ps":"BTCUSDT","U":11079103017866,"u":11079103022799,"pu":11079103017746,"b":[["14149.90","1.848"],["14249.90","0.784"],["14349.90","0.616"],["14549.90","0.952"],["51719.90","0.000"],["51720.00","0.004"],["58184.90","0.002"],["63945.20","2.028"],["64003.40","0.000"],["64240.00","0.487"],["64320.00","0.630"],["64326.70","0.168"],["64368.70","0.000"],["64375.10","0.117"],["64400.00","28.464"],["64480.00","4.554"],["64496.00","0.005"],["64498.50","0.001"],["64542.80","0.096"],["64543.00","0.100"],["64560.00","1.337"],["64578.40","0.326"],["64614.50","0.683"],["64614.60","0.616"],["64614.80","0.318"],["64615.20","1.028"],["64615.70","0.138"],["64615.80","0.138"],["64640.00","0.426"],["64640.30","0.121"],["64640.70","0.056"]],"a":[["64650.00","1.812"],["64655.10","0.048"],["64720.00","0.569"],["64800.00","18.653"],["64802.90","0.000"],["64880.00","9.725"],["64960.00","2.446"],["65040.00","0.567"],["65296.50","0.001"]],"st":1}}
{"stream":"btcusdt@depth@100ms","data":{"e":"depthUpdate","E":1784410638826,"T":1784410638824,"s":"BTCUSDT","ps":"BTCUSDT","U":11079103023077,"u":11079103029084,"pu":11079103022799,"b":[["1000.00","50.241"],["14149.90","1.610"],["14249.90","0.910"],["14349.90","0.490"],["14549.90","1.190"],["51720.00","0.004"],["58184.90","0.002"],["62063.90","0.000"],["64003.40","0.000"],["64239.30","0.002"],["64239.40","0.116"],["64368.90","0.000"],["64496.00","0.705"],["64499.20","0.173"],["64542.80","0.135"],["64543.00","0.061"],["64582.30","1.947"],["64625.70","1.189"],["64633.00","0.061"],["64636.50","0.117"],["64636.80","0.006"]],"a":[["64650.00","1.803"],["64653.60","0.000"],["64653.70","0.007"],["64653.90","0.003"],["64654.10","0.000"],["64654.40","0.001"],["64654.60","0.003"],["64654.90","0.003"],["64655.10","0.048"],["64655.30","0.001"],["64655.60","0.002"],["64655.80","0.003"],["64656.00","0.008"],["64656.50","0.726"],["64656.60","0.315"],["64657.40","0.001"],["64657.60","0.161"],["64658.40","0.152"],["64658.50","0.017"],["64658.60","0.000"],["64658.90","0.002"],["64669.60","0.541"],["64671.00","0.002"],["64671.10","0.373"],["64671.90","0.001"],["64672.00","2.422"],["64678.70","0.001"],["64679.40","0.568"],["64683.10","0.047"],["64688.00","1.824"],["64748.80","1.755"],["64802.80","1.083"],["64842.60","0.003"],["64842.70","0.241"],["65296.50","0.001"]],"st":1}}
{"stream":"btcusdt@depth@100ms","data":{"e":"depthUpdate","E":1784410638928,"T":1784410638924,"s":"BTCUSDT","ps":"BTCUSDT","U":11079103029169,"u":11079103034144,"pu":11079103029084,"b":[["1000.00","50.241"],["14149.90","1.372"],["14249.90","1.022"],["14349.90","0.378"],["14549.90","1.428"],["58184.90","0.002"],["62063.90","0.003"],["64003.40","0.000"],["64109.70","0.000"],["64236.90","0.940"],["64366.10","0.816"],["64542.80","0.096"],["64543.00","0.100"],["64636.20","0.520"]],"a":[["64653.70","0.594"],["64656.30","0.001"],["64656.40","0.001"],["64656.50","0.334"],["64656.60","0.315"],["64657.40","0.158"],["64657.60","0.004"],["64658.60","0.705"],["64658.70","1.308"],["64659.00","0.182"],["64668.70","0.003"],["64669.60","0.541"],["64671.90","0.001"],["65296.50","0.001"],["65419.30","2.751"]],"st":1}}
{"stream":"btcusdt@depth@100ms","data":{"e":"depthUpdate","E":1784410639030,"T":1784410639029,"s":"BTCUSDT","ps":"BTCUSDT","U":11079103034344,"u":11079103040978,"pu":11079103034144,"b":[["14149.90","1.134"],["14249.90","1.148"],["14349.90","0.252"],["14549.90","1.666"],["58184.90","0.002"],["61417.40","0.010"],["62063.90","0.000"],["63978.50","0.816"],["64003.40","0.000"],["64107.70","0.818"],["64326.70","0.168"],["64485.00","0.499"],["64633.00","0.061"],["64636.20","0.522"]],"a":[["64653.70","0.007"],["64656.40","0.001"],["64656.50","0.726"],["64656.60","0.002"],["64657.40","0.001"],["64657.60","0.004"],["64658.60","0.000"],["64668.70","0.005"],["64681.00","0.079"],["64798.70","0.009"],["64799.20","0.000"],["64849.40","0.014"],["65296.50","0.001"],["65675.90","0.000"],["65818.50","0.000"]],"st":1}}
{"stream":"btcusdt@depth@100ms","data":{"e":"depthUpdate","E":1784410639132,"T":1784410639129,"s":"BTCUSDT","ps":"BTCUSDT","U":11079103041150,"u":11079103047720,"pu":11079103040978,"b":[["1000.00","50.241"],["14149.90","0.896"],["14249.90","1.260"],["14349.90","0.140"],["14549.90","1.904"],["58184.90","0.002"],["61417.40","0.008"],["62063.90","0.003"],["63357.00","0.026"],["63820.80","0.782"],["64003.40","0.000"],["64496.00","0.705"],["64499.20","0.017"],["64618.60","0.431"],["64625.10","0.162"],["64631.60","0.851"],["64633.00","0.215"],["64638.30","0.009"],["64649.90","12.237"]],"a":[["64650.00","1.953"],["64652.10","0.081"],["64653.70","0.594"],["64656.40","0.001"],["64656.50","0.021"],["64656.60","0.315"],["64657.20","0.002"],["64657.40","0.314"],["64657.60","0.161"],["64657.70","0.398"],["64657.90","0.181"],["64658.10","0.084"],["64658.60","0.860"],["64665.10","0.815"],["64669.60","0.000"],["64671.90","0.542"],["64681.00","0.002"],["64802.80","1.083"],["65250.80","2.373"],["65296.50","0.001"],["65380.20","0.936"],["65449.50","0.000"]],"st":1}}
{"stream":"btcusdt@depth@100ms","data":{"e":"depthUpdate","E":1784410639234,"T":1784410639233,"s":"BTCUSDT","ps":"BTCUSDT","U":11079103047894,"u":11079103054455,"pu":11079103047720,"b":[["1000.00","50.241"],["14149.90","0.728"],["14249.90","1.386"],["14349.90","0.014"],["14449.90","0.070"],["14549.90","2.002"],["58184.90","0.002"],["63788.40","4.774"],["64003.40","0.000"],["64035.70","1.736"],["64633.00","0.061"],["64649.90","12.245"]],"a":[["64653.70","0.007"],["64656.30","0.155"],["64656.40","0.542"],["64656.50","0.031"],["64656.60","0.315"],["64657.40","0.001"],["64657.60","0.004"],["64658.10","0.037"],["64658.40","0.152"],["64658.60","0.155"],["64658.70","1.308"],["64658.90","0.002"],["64669.60","0.541"],["64671.90","0.001"],["65296.50","0.001"],["66609.10","0.642"]],"st":1}}
{"stream":"btcusdt@depth@100ms","data":{"e":"depthUpdate","E":1784410639336,"T":1784410639332,"s":"BTCUSDT","ps":"BTCUSDT","U":11079103054575,"u":11079103060763,"pu":11079103054455,"b":[["14149.90","0.714"],["14249.90","1.302"],["14349.90","0.000"],["14449.90","0.196"],["14549.90","1.988"],["51720.00","0.004"],["58184.90","0.002"],["62063.90","0.000"],["64003.40","0.000"],["64297.30","0.018"],["64326.70","0.168"],["64421.30","0.828"],["64496.00","0.705"],["64633.00","0.215"]],"a":[["64653.70","0.007"],["64656.20","0.001"],["64656.30","0.001"],["64656.40","0.001"],["64656.50","0.021"],["64656.60","0.002"],["64657.40","0.001"],["64658.60","0.860"],["64802.80","1.054"],["65296.50","0.001"],["65535.70","1.065"],["65781.40","2.429"],["65942.90","0.642"]],"st":1}}
{"stream":"btcusdt@depth@100ms","data":{"e":"depthUpdate","E":1784410639438,"T":1784410639437,"s":"BTCUSDT","ps":"BTCUSDT","U":11079103060929,"u":11079103067424,"pu":11079103060763,"b":[["1000.00","50.241"],["14149.90","0.714"],["14249.90","1.176"],["14449.90","0.308"],["14549.90","2.002"],["51720.00","0.004"],["58184.90","0.002"],["61571.30","0.003"],["62063.90","0.003"],["63357.00","0.023"],["64003.40","0.000"],["64463.70","0.047"],["64496.00","0.713"],["64542.80","0.135"],["64543.00","0.061"],["64564.50","0.006"],["64591.20","0.039"],["64591.30","0.038"],["64612.80","0.638"],["64631.80","0.013"],["64633.50","1.601"],["64635.60","2.372"],["64649.90","12.478"]],"a":[["64650.00","1.801"],["64652.10","0.004"],["64653.70","0.007"],["64656.60","0.002"],["64657.40","0.001"],["64657.50","0.001"],["64657.60","0.317"],["64657.70","0.382"],["64659.60","0.079"],["64669.10","0.002"],["64669.20","0.048"],["64669.30","0.310"],["64681.00","0.002"],["64685.50","0.019"],["64685.60","0.001"],["64685.70","0.121"],["64686.00","0.002"],["64686.10","0.063"],["64686.20","0.114"],["64802.80","1.054"],["65296.50","0.001"],["65425.80","12.224"]],"st":1}}
{"stream":"btcusdt@depth@100ms","data":{"e":"depthUpdate","E":1784410639540,"T":1784410639537,"s":"BTCUSDT","ps":"BTCUSDT","U":11079103067538,"u":11079103074375,"pu":11079103067424,"b":[["14149.90","0.714"],["14249.90","1.064"],["14449.90","0.434"],["14549.90","1.988"],["51720.00","0.004"],["58184.90","0.002"],["62063.90","0.000"],["63564.40","0.001"],["64003.40","0.000"],["64326.60","0.938"],["64421.30","0.833"],["64458.50","0.065"],["64461.10","0.023"],["64485.00","0.499"],["64496.00","0.005"],["64633.00","0.061"],["64636.50","0.001"],["64637.10","0.293"],["64649.90","12.497"]],"a":[["64650.00","1.824"],["64653.70","0.594"],["64656.60","0.315"],["64661.70","0.018"],["64661.80","0.168"],["64678.80","0.787"],["64679.40","0.012"],["64685.80","0.060"],["64688.00","0.388"],["64689.20","0.001"],["64692.70","10.047"],["64719.00","0.024"],["64802.80","0.004"],["64973.30","0.770"],["65000.00","102.073"],["65296.50","0.001"]],"st":1}}
{"stream":"btcusdt@depth@100ms","data":{"e":"depthUpdate","E":1784410639642,"T":1784410639641,"s":"BTCUSDT","ps":"BTCUSDT","U":11079103074590,"u":11079103081166,"pu":11079103074375,"b":[["14149.90","0.714"],["14249.90","0.938"],["14449.90","0.546"],["14549.90","2.002"],["58184.90","0.002"],["62063.90","0.003"],["63557.20","0.785"],["64003.40","0.000"],["64326.70","0.168"],["64478.90","0.004"],["64593.00","0.034"]],"a":[["64650.00","1.816"],["64653.70","0.007"],["64656.60","0.002"],["64657.50","0.001"],["64657.60","0.004"],["64661.80","0.168"],["64820.00","1.254"],["65231.80","0.233"],["65296.50","0.001"],["65427.70","6.776"],["65789.30","0.039"],["65868.40","0.008"]],"st":1}}
{"stream":"btcusdt@depth@100ms","data":{"e":"depthUpdate","E":1784410639744,"T":1784410639741,"s":"BTCUSDT","ps":"BTCUSDT","U":11079103081268,"u":11079103087092,"pu":11079103081166,"b":[["1000.00","50.241"],["14149.90","0.714"],["14249.90","0.826"],["14449.90","0.672"],["14549.90","1.988"],["51719.90","0.000"],["58184.90","0.002"],["64003.40","0.000"],["64297.30","0.023"],["64368.70","0.117"],["64375.10","0.000"],["64442.10","0.142"],["64633.00","0.061"],["64636.50","0.117"],["64637.10","0.177"],["64638.40","1.654"],["64638.80","0.093"],["64639.20","0.003"],["64640.10","0.310"]],"a":[["64655.10","0.048"],["64669.60","0.000"],["64671.90","0.542"],["64678.80","0.231"],["64679.50","0.900"],["64854.70","0.911"],["64857.00","0.029"],["65296.50","0.001"],["65807.20","0.455"]],"st":1}}
{"stream":"btcusdt@depth@100ms","data":{"e":"depthUpdate","E":1784410639846,"T":1784410639845,"s":"BTCUSDT","ps":"BTCUSDT","U":11079103087247,"u":11079103093190,"pu":11079103087092,"b":[["14149.90","0.714"],["14249.90","0.700"],["14449.90","0.784"],["14549.90","2.002"],["58184.90","0.002"],["62063.90","0.000"],["63465.00","1.525"],["64003.40","0.000"],["64124.50","0.814"],["64132.70","0.780"],["64442.00","3.280"],["64458.50","0.061"],["64478.90","0.745"],["64496.00","0.713"],["64499.20","0.069"],["64607.20","1.049"],["64633.00","0.215"],["64637.30","0.558"],["64638.00","1.026"],["64638.30","0.002"],["64638.40","1.097"],["64638.70","0.696"],["64638.80","0.943"],["64639.20","0.010"],["64639.90","0.027"],["64640.10","0.001"],["64640.70","0.056"],["64649.90","12.499"]],"a":[["64650.00","1.815"],["64653.70","0.007"],["64657.60","0.004"],["64661.70","0.065"],["64661.80","0.121"],["64668.60","0.003"],["64669.60","0.541"],["64670.40","0.095"],["64671.30","0.928"],["64671.90","0.001"],["64672.00","1.496"],["64675.70","0.015"],["64677.90","1.124"],["64679.00","0.002"],["64679.40","0.019"],["64679.50","0.344"],["64681.00","0.079"],["64692.50","2.145"],["64713.80","0.002"],["64721.00","0.015"],["64802.80","1.054"],["64819.90","2.699"],["64854.70","1.400"],["64856.80","3.682"],["65167.20","1.283"],["65296.50","0.001"],["65450.60","2.577"],["65644.60","27.888"]],"st":1}}
{"stream":"btcusdt@depth@100ms","data":{"e":"depthUpdate","E":1784410639948,"T":1784410639945,"s":"BTCUSDT","ps":"BTCUSDT","U":11079103093250,"u":11079103099773,"pu":11079103093190,"b":[["14149.90","0.812"],["14249.90","0.588"],["14449.90","1.008"],["14549.90","1.792"],["58184.90","0.002"],["62063.90","0.003"],["63357.00","0.020"],["64003.40","0.000"],["64326.70","0.168"],["64578.40","0.426"],["64636.20","0.520"],["64639.60","0.066"],["64643.10","0.024"]],"a":[["64653.70","0.594"],["64657.60","0.161"],["64668.70","0.003"],["64773.30","0.112"],["65296.50","0.001"],["65425.80","13.749"],["65769.90","0.000"],["65942.90","0.645"]],"st":1}}
{"stream":"btcusdt@depth@100ms","data":{"e":"depthUpdate","E":1784410640050,"T":1784410640049,"s":"BTCUSDT","ps":"BTCUSDT","U":11079103099962,"u":11079103106858,"pu":11079103099773,"b":[["1000.00","50.241"],["14149.90","0.938"],["14249.90","0.462"],["14449.90","1.246"],["14549.90","1.554"],["58184.90","0.002"],["61417.40","0.006"],["61417.50","0.011"],["62063.90","0.000"],["63357.00","0.017"],["63843.80","0.022"],["64003.40","0.000"],["64485.00","0.158"],["64562.60","0.349"],["64633.00","0.061"],["64636.20","0.522"],["64638.30","0.007"],["64638.80","0.402"],["64639.90","0.568"]],"a":[["64653.70","0.594"],["64657.60","0.161"],["64668.70","0.005"],["64681.00","0.002"],["65296.50","0.001"]],"st":1}}
{"stream":"btcusdt@depth@100ms","data":{"e":"depthUpdate","E":1784410640152,"T":1784410640149,"s":"BTCUSDT","ps":"BTCUSDT","U":11079103106962,"u":11079103115064,"pu":11079103106858,"b":[["14149.90","1.050"],["14249.90","0.350"],["14449.90","1.484"],["14549.90","1.316"],["58184.90","0.002"],["61417.40","0.008"],["63659.10","0.785"],["64003.40","0.000"],["64633.00","0.215"],["64638.00","0.100"],["64638.30","0.002"],["64638.80","1.019"],["64639.70","0.013"],["64640.00","2.426"],["64640.10","0.310"],["64649.90","12.499"]],"a":[["64650.00","1.817"],["64653.70","0.594"],["64657.60","0.161"],["64658.80","0.001"],["64659.30","0.313"],["64669.60","0.541"],["64671.20","0.949"],["64671.30","0.002"],["64671.90","0.001"],["64672.20","0.000"],["64677.90","0.567"],["64679.50","0.900"],["65296.50","0.001"],["65619.80","0.722"],["65841.10","7.133"]],"st":1}}
{"stream":"btcusdt@depth@100ms","data":{"e":"depthUpdate","E":1784410640254,"T":1784410640253,"s":"BTCUSDT","ps":"BTCUSDT","U":11079103115328,"u":11079103123295,"pu":11079103115064,"b":[["14149.90","1.176"],["14249.90","0.224"],["14449.90","1.722"],["14549.90","1.078"],["58184.90","0.002"],["61417.40","0.006"],["61417.50","0.013"],["62063.90","0.003"],["63357.00","0.020"],["63376.60","0.077"],["63448.50","0.000"],["63520.30","0.001"],["63592.20","0.000"],["63664.00","0.000"],["63735.90","0.000"],["63807.70","0.000"],["63879.60","0.000"],["63917.70","3.750"],["63951.40","0.038"],["64003.40","0.000"],["64023.30","0.001"],["64326.70","0.168"],["64458.50","0.065"],["64461.10","0.019"],["64632.70","0.001"]],"a":[["64653.70","0.594"],["64657.60","0.161"],["64681.00","0.079"],["65296.50","0.001"],["65316.70","0.000"],["65388.60","0.003"],["65460.40","0.000"],["65532.30","0.000"],["65604.10","0.001"],["65676.00","0.007"],["65747.80","0.014"],["65819.70","0.001"],["65891.50","0.009"],["65963.40","0.001"]],"st":1}}
{"stream":"btcusdt@depth@100ms","data":{"e":"depthUpdate","E":1784410640356,"T":1784410640355,"s":"BTCUSDT","ps":"BTCUSDT","U":11079103123468,"u":11079103130720,"pu":11079103123295,"b":[["1000.00","50.241"],["14149.90","1.288"],["14249.90","0.112"],["14449.90","1.960"],["14549.90","0.840"],["51720.00","0.004"],["58184.90","0.002"],["62063.90","0.000"],["63659.10","1.568"],["63841.80","1.314"],["63938.80","0.234"],["64003.40","0.002"],["64132.70","0.779"],["64188.30","0.001"],["64197.40","0.082"],["64458.50","0.061"],["64463.70","0.043"],["64564.50","0.002"],["64631.40","1.272"],["64633.00","0.061"],["64633.50","2.924"],["64638.30","0.009"],["64639.20","0.003"],["64649.90","12.498"]],"a":[["64650.00","1.965"],["64652.20","0.079"],["64653.70","0.007"],["64655.10","0.048"],["64655.30","0.048"],["64656.40","0.001"],["64656.60","0.002"],["64657.30","0.002"],["64657.60","0.004"],["64657.80","0.002"],["64658.00","0.017"],["64658.10","0.037"],["64658.30","0.162"],["64658.50","0.064"],["64659.60","0.063"],["64669.60","0.541"],["64671.00","0.928"],["64671.10","0.373"],["64671.20","0.023"],["64671.90","0.001"],["64672.00","1.496"],["64685.80","0.013"],["64686.60","2.133"],["64692.70","0.047"],["65167.20","1.282"],["65296.50","0.005"],["65361.10","2.142"],["65813.70","0.835"]],"st":1}}
{"stream":"btcusdt@depth@100ms","data":{"e":"depthUpdate","E":1784410640458,"T":1784410640457,"s":"BTCUSDT","ps":"BTCUSDT","U":11079103130822,"u":11079103140019,"pu":11079103130720,"b":[["14149.90","1.386"],["14249.90","0.000"],["14349.90","0.098"],["14449.90","2.002"],["14549.90","0.714"],["58184.90","0.002"],["62063.90","0.003"],["63841.80","1.548"],["64003.40","0.002"],["64458.50","0.061"],["64461.10","0.023"],["64463.70","0.047"],["64564.50","0.006"],["64625.60","0.222"],["64633.00","0.215"],["64633.50","1.601"],["64649.90","12.543"]],"a":[["64650.00","1.803"],["64653.20","0.005"],["64655.10","0.048"],["64655.30","0.001"],["64655.50","0.007"],["64655.60","0.002"],["64656.60","0.002"],["64658.50","0.017"],["64659.50","0.291"],["64661.70","0.018"],["64681.00","0.079"],["64685.80","0.060"],["64692.50","0.001"],["64798.70","0.009"],["65296.50","0.003"],["65942.90","0.648"]],"st":1}}
{"stream":"btcusdt@depth@100ms","data":{"e":"depthUpdate","E":1784410640560,"T":1784410640559,"s":"BTCUSDT","ps":"BTCUSDT","U":11079103140107,"u":11079103156590,"pu":11079103140019,"b":[["1000.00","50.391"],["14149.90","1.274"],["14349.90","0.224"],["14449.90","1.988"],["14549.90","0.714"],["58184.90","0.002"],["62063.90","0.000"],["63357.00","0.017"],["63863.50","14.211"],["63880.60","0.938"],["64003.40","0.000"],["64326.60","0.936"],["64326.70","0.168"],["64368.70","0.000"],["64375.10","0.117"],["64461.10","0.019"],["64463.70","0.043"],["64485.00","0.002"],["64488.30","0.193"],["64538.90","0.004"],["64540.40","0.000"],["64540.50","0.589"],["64541.90","0.000"],["64543.40","0.000"],["64544.90","0.000"],["64546.40","1.832"],["64564.50","0.002"],["64568.60","0.001"],["64590.30","0.624"],["64592.10","0.006"],["64600.50","0.002"],["64626.70","0.000"],["64629.20","0.065"],["64631.20","0.010"],["64631.40","1.272"],["64631.60","0.853"],["64632.00","0.731"],["64633.00","0.061"],["64635.60","0.372"],["64636.40","0.193"],["64636.50","0.001"],["64636.60","10.000"],["64636.70","3.689"],["64637.30","0.001"],["64637.40","0.001"],["64638.10","0.931"],["64638.30","0.002"],["64638.80","0.093"],["64639.10","0.139"],["64639.50","0.237"],["64639.90","0.027"],["64640.00","2.272"],["64640.10","0.008"],["64640.40","0.679"],["64640.80","1.047"],["64640.90","1.007"],["64641.80","0.542"],["64643.20","1.712"],["64647.20","1.599"],["64647.30","0.094"],["64647.60","0.000"],["64647.80","0.065"],["64647.90","0.002"],["64648.50","0.140"],["64649.90","13.002"]],"a":[["64650.00","1.253"],["64650.10","0.000"],["64651.90","0.004"],["64652.20","0.002"],["64653.40","0.014"],["64653.70","0.007"],["64654.10","0.129"],["64656.30","0.542"],["64656.40","0.314"],["64656.50","0.202"],["64656.60","0.002"],["64656.80","0.002"],["64657.60","0.161"],["64658.30","0.069"],["64658.50","0.000"],["64658.60","0.000"],["64658.70","1.306"],["64658.90","0.095"],["64659.50","0.244"],["64659.90","0.000"],["64660.20","0.465"],["64660.70","0.000"],["64661.50","0.388"],["64661.60","0.001"],["64661.80","0.121"],["64662.20","0.018"],["64665.10","0.506"],["64669.60","0.000"],["64669.70","0.560"],["64670.90","0.000"],["64671.00","0.002"],["64671.60","0.701"],["64671.70","0.015"],["64672.20","0.000"],["64673.20","0.926"],["64679.40","0.012"],["64679.50","0.344"],["64680.40","0.007"],["64680.60","0.564"],["64681.00","0.002"],["64686.60","0.133"],["64694.70","10.000"],["64731.30","0.001"],["64973.30","0.772"],["65296.50","0.001"]],"st":1}}
{"stream":"btcusdt@depth@100ms","data":{"e":"depthUpdate","E":1784410640662,"T":1784410640661,"s":"BTCUSDT","ps":"BTCUSDT","U":11079103156733,"u":11079103167754,"pu":11079103156590,"b":[["1000.00","50.241"],["14149.90","1.148"],["14349.90","0.336"],["14449.90","2.002"],["14549.90","0.714"],["58184.90","0.002"],["63655.20","0.000"],["64003.40","0.000"],["64437.20","0.000"],["64474.60","0.146"],["64485.00","0.158"],["64540.50","0.006"],["64546.40","0.556"],["64564.50","0.006"],["64578.50","0.001"],["64585.30","0.133"],["64613.30","0.576"],["64615.10","0.550"],["64618.40","0.495"],["64618.70","10.385"],["64618.80","0.000"],["64627.10","1.359"],["64628.10","0.057"],["64629.20","0.008"],["64633.00","0.215"],["64638.00","0.216"],["64638.90","0.135"],["64639.40","0.798"],["64639.50","0.121"],["64639.70","0.939"],["64639.90","0.017"],["64640.40","0.122"],["64640.80","0.121"],["64640.90","0.544"],["64641.00","0.542"],["64641.80","0.001"],["64642.00","0.465"],["64642.10","0.011"],["64649.90","13.004"]],"a":[["64653.70","0.594"],["64656.30","0.001"],["64656.40","0.001"],["64656.50","0.178"],["64656.60","0.315"],["64656.80","0.000"],["64657.70","0.384"],["64658.00","0.001"],["64658.60","0.722"],["64659.70","0.286"],["64661.90","0.312"],["64662.20","0.574"],["64662.40","0.007"],["64662.70","0.182"],["64662.90","0.082"],["64664.60","0.002"],["64672.20","0.000"],["64672.80","0.926"],["64673.20","0.000"],["64688.60","0.047"],["64691.40","0.002"],["65296.50","0.001"],["104929.00","0.000"]],"st":1}}
{"stream":"btcusdt@depth@100ms","data":{"e":"depthUpdate","E":1784410640764,"T":1784410640763,"s":"BTCUSDT","ps":"BTCUSDT","U":11079103167906,"u":11079103178012,"pu":11079103167754,"b":[["14149.90","1.036"],["14349.90","0.462"],["14449.90","1.988"],["14549.90","0.714"],["51719.90","0.000"],["58184.90","0.002"],["61417.50","0.011"],["62063.90","0.003"],["64003.40","0.000"],["64239.40","0.223"],["64499.20","0.168"],["64598.80","3.206"],["64599.50","0.064"],["64608.10","0.216"],["64619.00","0.088"],["64619.10","0.050"],["64623.90","1.484"],["64626.50","0.575"],["64627.70","0.073"],["64640.10","0.549"],["64641.00","0.001"]],"a":[["64653.70","0.007"],["64656.50","0.178"],["64662.90","0.035"],["64663.20","0.315"],["64663.50","0.001"],["64663.80","0.434"],["64669.70","1.101"],["64671.60","0.160"],["64691.20","0.020"],["64691.40","0.002"],["64694.60","2.396"],["64694.90","0.002"],["64773.30","0.012"],["65296.50","0.003"],["65361.10","2.371"],["65640.80","0.760"]],"st":1}}
{"stream":"btcusdt@depth@100ms","data":{"e":"depthUpdate","E":1784410640866,"T":1784410640865,"s":"BTCUSDT","ps":"BTCUSDT","U":11079103178032,"u":11079103187052,"pu":11079103178012,"b":[["1000.00","50.241"],["14149.90","0.910"],["14349.90","0.574"],["14449.90","2.002"],["14549.90","0.714"],["58184.90","0.002"],["62063.90","0.000"],["63801.30","7.117"],["64003.40","0.000"],["64326.70","0.168"],["64537.40","0.000"],["64538.90","0.004"],["64540.40","0.000"],["64541.90","0.000"],["64543.40","0.000"],["64544.90","0.000"],["64564.50","0.002"],["64568.60","0.000"],["64585.30","0.132"],["64599.60","0.026"],["64608.10","0.191"],["64625.10","0.007"],["64626.60","0.053"],["64626.70","0.057"],["64628.10","0.000"],["64630.50","0.065"],["64631.60","0.776"],["64633.00","0.061"],["64633.80","2.139"],["64635.90","0.117"],["64637.10","0.293"],["64637.30","0.558"],["64638.00","0.100"],["64638.10","1.857"],["64638.40","1.177"],["64638.60","0.622"],["64638.80","0.634"],["64638.90","0.135"],["64639.40","0.241"],["64639.70","0.013"],["64640.10","0.008"],["64646.30","0.120"],["64647.20","1.622"],["64647.30","0.095"],["64647.40","0.001"],["64649.90","13.055"]],"a":[["64650.00","1.762"],["64650.10","0.002"],["64653.70","0.007"],["64656.50","0.021"],["64656.60","0.002"],["64657.60","0.004"],["64669.60","0.541"],["64669.70","0.560"],["64671.30","0.928"],["64671.90","0.001"],["64672.80","0.000"],["64678.00","0.689"],["64680.60","0.008"],["64714.60","0.001"],["64731.30","0.000"],["65296.50","0.001"],["65482.90","4.253"],["65645.30","0.000"],["66827.40","2.149"]],"st":1}}
{"stream":"btcusdt@depth@100ms","data":{"e":"depthUpdate","E":1784410640968,"T":1784410640965,"s":"BTCUSDT","ps":"BTCUSDT","U":11079103187241,"u":11079103194558,"pu":11079103187052,"b":[["1000.00","50.241"],["14149.90","0.798"],["14349.90","0.700"],["14449.90","1.988"],["14549.90","0.714"],["58184.90","0.002"],["61417.40","0.004"],["61417.50","0.013"],["62063.90","0.003"],["64003.40","0.000"],["64608.30","0.000"],["64633.00","0.061"],["64640.10","0.549"],["64640.70","0.529"],["64640.90","0.003"],["64642.00","0.002"],["64642.10","0.001"]],"a":[["64650.00","1.734"],["64653.70","0.007"],["64657.60","0.317"],["64669.60","0.000"],["64671.20","0.564"],["64677.60","0.050"],["64678.00","0.132"],["64679.30","0.557"],["64679.70","0.067"],["64680.70","0.000"],["64681.00","0.079"],["64686.70","0.775"],["64691.40","0.002"],["65231.80","0.463"],["65296.50","0.001"],["65414.50","1.680"],["65482.90","3.873"],["65568.00","0.286"],["104929.00","0.236"]],"st":1}}
{"stream":"btcusdt@depth@100ms","data":{"e":"depthUpdate","E":1784410641070,"T":1784410641069,"s":"BTCUSDT","ps":"BTCUSDT","U":11079103194827,"u":11079103202041,"pu":11079103194558,"b":[["14149.90","0.672"],["14349.90","0.826"],["14449.90","1.974"],["14549.90","0.728"],["58184.90","0.002"],["62063.90","0.000"],["63537.90","1.665"],["63766.50","0.266"],["64003.40","0.000"],["64132.70","0.779"],["64485.00","0.499"],["64562.60","0.008"],["64608.80","0.003"],["64633.00","0.215"],["64636.20","0.522"],["64638.10","0.931"],["64638.30","0.002"],["64638.80","0.093"],["64639.10","1.065"],["64640.20","0.543"]],"a":[["64650.00","1.736"],["64653.70","0.007"],["64660.40","4.220"],["64660.60","0.000"],["64660.80","0.006"],["64668.70","0.005"],["64669.60","0.000"],["64671.20","0.023"],["64671.30","0.002"],["64671.90","0.542"],["64672.30","0.928"],["64691.40","0.002"],["65296.50","0.001"]],"st":1}}
{"stream":"btcusdt@depth@100ms","data":{"e":"depthUpdate","E":1784410641172,"T":1784410641170,"s":"BTCUSDT","ps":"BTCUSDT","U":11079103202183,"u":11079103210647,"pu":11079103202041,"b":[["1000.00","50.241"],["14149.90","0.560"],["14349.90","1.064"],["14449.90","1.736"],["14549.90","0.840"],["58184.90","0.002"],["61412.90","0.002"],["61417.40","0.002"],["62064.00","0.005"],["63848.20","0.000"],["64003.40","0.000"],["64326.70","0.168"],["64633.00","0.215"]],"a":[["64653.20","0.005"],["64653.70","0.007"],["64656.60","0.002"],["64666.50","0.001"],["64667.70","0.122"],["64669.60","0.541"],["64671.90","0.001"],["64681.00","0.002"],["64691.40","0.002"],["64798.70","0.009"],["65042.50","0.000"],["65296.50","0.001"],["65393.70","12.712"],["65619.80","1.064"],["65942.90","0.645"]],"st":1}}
{"stream":"btcusdt@depth@100ms","data":{"e":"depthUpdate","E":1784410641274,"T":1784410641273,"s":"BTCUSDT","ps":"BTCUSDT","U":11079103210893,"u":11079103218063,"pu":11079103210647,"b":[["1000.00","50.241"],["14149.90","0.434"],["14349.90","1.302"],["14449.90","1.498"],["14549.90","0.966"],["58184.90","0.002"],["62063.90","0.003"],["64003.40","0.000"],["64649.90","12.951"]],"a":[["64650.00","1.884"],["64653.70","0.007"],["64655.10","0.635"],["64657.40","0.001"],["64657.60","0.317"],["64657.90","0.197"],["64658.10","0.037"],["64658.70","1.306"],["64658.90","0.142"],["64659.70","0.270"],["64671.20","0.949"],["64672.30","0.002"],["64842.60","0.000"],["64842.70","0.244"],["65244.60","6.951"],["65296.50","0.001"],["65762.00","1.070"],["65838.60","5.915"]],"st":1}}
{"stream":"btcusdt@depth@100ms","data":{"e":"depthUpdate","E":1784410641376,"T":1784410641375,"s":"BTCUSDT","ps":"BTCUSDT","U":11079103218175,"u":11079103224817,"pu":11079103218063,"b":[["14149.90","0.322"],["14349.90","1.540"],["14449.90","1.260"],["14549.90","1.078"],["51720.00","0.004"],["58184.90","0.002"],["61417.50","0.011"],["62063.90","0.000"],["63357.00","0.020"],["63529.80","0.786"],["64003.40","0.002"],["64496.00","0.005"],["64550.40","0.021"],["64559.90","0.001"],["64632.10","0.079"],["64638.90","0.142"],["64640.10","0.542"]],"a":[["64650.00","1.930"],["64653.70","0.594"],["64655.10","0.048"],["64656.10","0.003"],["64657.60","0.161"],["64669.60","0.541"],["64671.10","0.373"],["64671.20","0.023"],["64672.00","2.422"],["64688.60","0.000"],["64690.40","2.099"],["64691.40","0.002"],["64802.80","0.004"],["65250.80","1.301"],["65296.50","0.001"]],"st":1}}
{"stream":"btcusdt@depth@100ms","data":{"e":"depthUpdate","E":1784410641478,"T":1784410641477,"s":"BTCUSDT","ps":"BTCUSDT","U":11079103224852,"u":11079103232006,"pu":11079103224817,"b":[["1000.00","50.241"],["14149.90","0.196"],["14349.90","1.778"],["14449.90","1.022"],["14549.90","1.204"],["58184.90","0.002"],["62063.90","0.003"],["63227.60","0.001"],["63369.30","6.971"],["63441.20","2.666"],["63513.00","0.149"],["63584.90","0.147"],["63656.70","0.174"],["63728.60","0.147"],["63800.40","0.147"],["63872.30","0.147"],["63944.10","0.149"],["64003.40","0.000"],["64016.00","0.465"],["64326.70","0.168"],["64496.00","0.680"],["64625.70","1.344"],["64633.00","0.215"]],"a":[["64652.50","0.077"],["64653.70","0.007"],["64655.10","0.635"],["64657.60","0.161"],["64658.90","0.297"],["64665.40","0.697"],["64681.00","0.079"],["64802.60","1.050"],["64852.40","0.002"],["65296.50","0.001"],["65309.20","8.037"],["65381.10","0.162"],["65425.80","14.008"],["65452.90","0.152"],["65524.80","0.250"],["65596.60","0.159"],["65668.50","0.147"],["65740.30","0.147"],["65812.20","0.150"],["65884.00","0.905"],["65955.90","18.528"],["70000.00","77.378"]],"st":1}}
{"stream":"btcusdt@depth@100ms","data":{"e":"depthUpdate","E":1784410641580,"T":1784410641577,"s":"BTCUSDT","ps":"BTCUSDT","U":11079103232099,"u":11079103239540,"pu":11079103232006,"b":[["1000.00","50.241"],["14149.90","0.084"],["14249.90","0.014"],["14349.90","1.988"],["14449.90","0.798"],["14549.90","1.316"],["51720.00","0.006"],["58184.90","0.002"],["63357.00","0.023"],["63396.50","0.677"],["64003.40","0.000"],["64326.60","0.938"],["64375.10","0.000"],["64378.40","0.117"],["64488.30","0.037"],["64550.40","0.017"],["64560.10","0.030"],["64633.00","0.061"],["64637.30","0.001"],["64638.50","0.924"]],"a":[["64655.10","0.635"],["64657.60","0.004"],["64679.40","0.019"],["64680.40","0.000"],["64681.00","0.002"],["64691.40","0.156"],["64973.30","0.770"],["65231.90","2.268"],["65296.50","0.001"],["65414.30","0.000"],["65547.60","8.674"],["65742.60","0.761"]],"st":1}}
{"stream":"btcusdt@depth@100ms","data":{"e":"depthUpdate","E":1784410641682,"T":1784410641681,"s":"BTCUSDT","ps":"BTCUSDT","U":11079103239818,"u":11079103247624,"pu":11079103239540,"b":[["14149.90","0.000"],["14249.90","0.126"],["14349.90","2.002"],["14449.90","0.714"],["14549.90","1.358"],["51720.00","0.004"],["58184.90","0.002"],["62063.90","0.000"],["63440.90","0.630"],["63801.30","6.680"],["64003.40","0.000"],["64442.00","3.211"],["64468.50","0.000"],["64478.80","0.867"],["64478.90","0.004"],["64496.00","0.698"],["64499.20","0.069"],["64625.60","0.279"],["64626.70","0.000"],["64633.00","0.215"],["64635.50","0.975"],["64636.30","0.160"],["64636.70","4.246"],["64637.10","1.103"],["64637.70","0.163"],["64638.20","0.589"],["64638.50","0.374"],["64638.90","0.135"],["64639.10","0.139"],["64640.20","0.002"],["64642.90","0.002"]],"a":[["64655.10","0.048"],["64657.60","0.004"],["64658.60","0.742"],["64666.40","0.002"],["64670.20","0.929"],["64672.00","1.496"],["64677.00","0.559"],["64679.30","0.001"],["64681.00","0.079"],["64691.40","0.002"],["64802.60","1.050"],["64819.80","0.946"],["64819.90","1.784"],["64854.70","0.911"],["64856.60","3.709"],["64856.80","0.004"],["65296.50","0.001"],["65618.80","0.009"]],"st":1}}
{"stream":"btcusdt@depth@100ms","data":{"e":"depthUpdate","E":1784410641784,"T":1784410641783,"s":"BTCUSDT","ps":"BTCUSDT","U":11079103247762,"u":11079103254881,"pu":11079103247624,"b":[["1000.00","50.241"],["14249.90","0.252"],["14349.90","1.988"],["14449.90","0.714"],["14549.90","1.246"],["51719.90","0.000"],["51720.00","0.004"],["58184.90","0.002"],["62063.90","0.003"],["63769.00","5.793"],["64003.40","0.000"],["64326.70","0.168"],["64446.30","0.160"],["64485.00","0.343"],["64488.30","0.193"],["64499.20","0.166"],["64537.40","0.000"],["64538.90","0.004"],["64540.40","0.202"],["64541.90","0.000"],["64543.40","0.000"],["64544.90","0.000"],["64649.90","12.442"]],"a":[["64655.10","0.048"],["64657.60","0.004"],["64677.00","0.002"],["64677.80","0.680"],["64691.40","0.156"],["64693.30","0.694"],["64717.80","0.018"],["64854.70","1.404"],["65296.50","0.001"],["65826.50","9.386"]],"st":1}}
{"stream":"btcusdt@depth@100ms","data":{"e":"depthUpdate","E":1784410641886,"T":1784410641885,"s":"BTCUSDT","ps":"BTCUSDT","U":11079103254913,"u":11079103262142,"pu":11079103254881,"b":[["1000.00","50.241"],["14249.90","0.364"],["14349.90","2.002"],["14449.90","0.714"],["14549.90","1.120"],["58184.90","0.002"],["62063.90","0.000"],["62728.70","0.000"],["63357.00","0.020"],["63866.00","16.984"],["64003.40","0.000"],["64607.70","0.010"],["64625.70","1.189"],["64630.50","0.034"],["64632.10","0.002"],["64633.00","0.061"],["64637.10","0.177"],["64638.20","1.515"],["64643.30","0.064"]],"a":[["64654.60","0.003"],["64654.90","0.003"],["64655.10","0.048"],["64655.20","1.277"],["64655.40","0.000"],["64656.60","0.002"],["64657.60","0.004"],["64668.70","0.005"],["64669.10","0.004"],["64669.20","0.050"],["64669.30","0.312"],["64669.60","0.541"],["64670.20","0.003"],["64670.70","0.927"],["64681.00","0.079"],["64685.50","0.021"],["64685.60","0.003"],["64685.70","0.123"],["64686.00","0.004"],["64686.10","0.065"],["64686.20","0.116"],["64691.40","0.156"],["64694.60","0.000"],["64694.70","0.000"],["64842.60","0.003"],["64842.70","0.241"],["65296.50","0.001"],["65522.80","0.989"],["65593.90","0.380"]],"st":1}}
{"stream":"btcusdt@depth@100ms","data":{"e":"depthUpdate","E":1784410641988,"T":1784410641985,"s":"BTCUSDT","ps":"BTCUSDT","U":11079103262255,"u":11079103269484,"pu":11079103262142,"b":[["14249.90","0.490"],["14349.90","1.988"],["14449.90","0.714"],["14549.90","1.008"],["58184.90","0.002"],["61412.90","0.000"],["62063.90","0.003"],["63227.60","0.000"],["63833.60","24.476"],["64003.40","0.000"],["64326.70","0.158"],["64633.00","0.061"],["64635.50","0.859"],["64636.30","0.158"],["64636.60","10.002"],["64636.70","4.362"],["64638.20","0.974"],["64639.90","0.558"],["64644.60","2.603"],["64645.20","1.130"]],"a":[["64653.00","0.002"],["64656.60","0.589"],["64681.00","0.002"],["64689.90","0.009"],["64690.40","2.101"],["64691.40","0.002"],["64720.60","0.074"],["64773.30","0.112"],["65427.70","5.263"],["65579.90","0.763"],["65612.30","7.725"]],"st":1}}
{"stream":"btcusdt@depth@100ms","data":{"e":"depthUpdate","E":1784410642090,"T":1784410642089,"s":"BTCUSDT","ps":"BTCUSDT","U":11079103269756,"u":11079103276893,"pu":11079103269484,"b":[["1000.00","50.241"],["14249.90","0.602"],["14349.90","2.002"],["14449.90","0.714"],["14549.90","0.882"],["58184.90","0.002"],["61417.40","0.002"],["61417.50","0.013"],["63635.10","0.013"],["63766.50","0.000"],["63863.50","13.821"],["64003.40","0.000"],["64633.00","0.215"],["64636.20","0.522"],["64636.70","3.805"],["64638.20","0.048"],["64638.30","0.002"],["64639.20","0.560"],["64639.50","1.047"],["64641.40","0.042"],["64643.30","0.072"]],"a":[["64656.00","0.008"],["64656.60","0.589"],["64668.70","0.005"],["64669.60","0.000"],["64670.70","0.001"],["64671.10","0.373"],["64671.20","0.023"],["64671.80","0.588"],["64671.90","0.927"],["64677.80","0.123"],["64678.70","0.557"],["64681.00","0.079"],["64691.40","0.002"],["65296.50","0.001"],["65664.70","0.000"],["66291.40","5.374"]],"st":1}}
{"stream":"btcusdt@depth@100ms","data":{"e":"depthUpdate","E":1784410642192,"T":1784410642189,"s":"BTCUSDT","ps":"BTCUSDT","U":11079103276933,"u":11079103283969,"pu":11079103276893,"b":[["1000.00","50.241"],["14249.90","0.728"],["14349.90","1.988"],["14449.90","0.714"],["14549.90","0.770"],["58184.90","0.002"],["62063.90","0.000"],["62710.40","2.309"],["63635.10","0.024"],["63714.40","1.089"],["63882.40","9.360"],["64003.40","0.000"],["64349.90","0.051"],["64633.00","0.215"],["64638.60","1.548"],["64639.50","0.121"]],"a":[["64656.60","0.589"],["64669.60","0.541"],["64671.80","0.047"],["64681.00","0.079"],["64691.40","0.156"],["65296.50","0.001"]],"st":1}}
{"stream":"btcusdt@depth@100ms","data":{"e":"depthUpdate","E":1784410642294,"T":1784410642293,"s":"BTCUSDT","ps":"BTCUSDT","U":11079103284250,"u":11079103291697,"pu":11079103283969,"b":[["14249.90","0.882"],["14349.90","1.918"],["14449.90","0.756"],["14549.90","0.644"],["32324.90","0.000"],["58184.90","0.002"],["62063.90","0.003"],["63712.50","4.231"],["63841.80","1.938"],["63853.10","1.563"],["64003.40","0.000"],["64326.70","0.168"],["64456.00","0.007"]],"a":[["64656.60","0.002"],["64691.40","0.156"],["65296.50","0.001"],["65425.80","15.535"],["65575.90","13.042"],["65664.70","0.011"]],"st":1}}
{"stream":"btcusdt@depth@100ms","data":{"e":"depthUpdate","E":1784410642396,"T":1784410642393,"s":"BTCUSDT","ps":"BTCUSDT","U":11079103291858,"u":11079103298340,"pu":11079103291697,"b":[["1000.00","50.241"],["14249.90","1.120"],["14349.90","1.680"],["14449.90","0.868"],["14549.90","0.532"],["51720.00","0.006"],["58184.90","0.002"],["62063.90","0.000"],["63049.30","0.000"],["63619.10","0.000"],["63628.20","0.673"],["63880.60","1.876"],["64003.40","0.000"],["64496.00","0.698"],["64499.20","0.069"],["64536.00","2.321"],["64536.10","0.000"]],"a":[["64656.60","0.002"],["64691.40","0.002"],["64755.00","0.001"],["64755.50","0.523"],["64756.20","2.645"],["64802.60","1.079"],["65296.50","0.001"]],"st":1}}
{"stream":"btcusdt@depth@100ms","data":{"e":"depthUpdate","E":1784410642498,"T":1784410642496,"s":"BTCUSDT","ps":"BTCUSDT","U":11079103298535,"u":11079103306014,"pu":11079103298340,"b":[["1000.00","50.241"],["14249.90","1.358"],["14349.90","1.442"],["14449.90","0.994"],["14549.90","0.406"],["51720.00","0.004"],["58184.90","0.002"],["62063.90","0.003"],["63863.50","13.555"],["63876.20","1.550"],["64003.40","0.000"],["64496.00","0.005"],["64567.10","0.013"],["64569.70","0.005"],["64603.70","0.028"],["64611.00","0.024"],["64617.50","2.204"],["64626.40","2.510"],["64627.30","1.334"],["64633.00","0.061"],["64633.80","2.216"]],"a":[["64650.00","1.880"],["64656.60","0.002"],["64658.90","0.250"],["64669.10","0.019"],["64675.70","0.000"],["64681.00","0.002"],["64691.40","0.002"],["64714.30","0.015"],["64721.00","0.000"],["64802.60","0.000"],["65296.50","0.001"],["65548.60","2.406"],["65838.60","5.157"]],"st":1}}
{"stream":"btcusdt@depth@100ms","data":{"e":"depthUpdate","E":1784410642600,"T":1784410642598,"s":"BTCUSDT","ps":"BTCUSDT","U":11079103306081,"u":11079103315980,"pu":11079103306014,"b":[["14249.90","1.596"],["14349.90","1.204"],["14449.90","1.106"],["14549.90","0.294"],["58184.90","0.002"],["63031.90","2.297"],["63357.00","0.017"],["63583.20","0.896"],["63863.50","13.289"],["64003.40","0.000"],["64326.60","0.936"],["64326.70","0.168"],["64375.10","0.117"],["64378.40","0.000"],["64446.30","0.004"],["64478.80","0.867"],["64485.00","0.002"],["64496.00","0.698"],["64537.40","0.000"],["64538.90","0.004"],["64540.40","0.202"],["64541.90","0.000"],["64543.40","1.276"],["64544.90","1.276"],["64546.40","1.832"],["64562.60","0.349"],["64564.50","0.006"],["64603.80","0.000"],["64616.50","0.001"],["64617.50","3.769"],["64618.60","0.122"],["64627.30","1.179"],["64631.00","0.004"],["64632.00","0.733"],["64633.00","0.215"],["64633.80","2.139"],["64636.60","0.002"],["64636.70","1.976"],["64637.60","0.117"],["64638.50","0.374"],["64638.60","1.179"],["64638.70","1.622"],["64639.00","0.259"],["64639.20","0.003"],["64639.90","0.017"],["64640.20","0.543"],["64640.40","0.122"],["64640.50","0.125"],["64641.40","0.042"],["64641.80","0.001"],["64641.90","0.326"],["64643.30","0.064"],["64644.50","0.017"],["64647.10","0.002"],["64647.70","0.001"],["64649.40","0.002"],["64649.90","14.060"]],"a":[["64650.00","0.861"],["64650.10","0.000"],["64652.50","0.000"],["64655.10","0.635"],["64656.60","0.002"],["64657.70","0.382"],["64658.60","0.722"],["64658.70","1.308"],["64658.90","0.095"],["64659.30","0.003"],["64663.00","0.032"],["64663.80","0.387"],["64664.90","0.003"],["64665.40","0.388"],["64665.70","1.022"],["64667.60","0.001"],["64667.90","0.036"],["64668.10","0.004"],["64668.50","0.060"],["64669.60","0.541"],["64671.20","0.949"],["64671.80","0.047"],["64671.90","0.001"],["64672.90","0.001"],["64678.70","0.001"],["64678.80","0.787"],["64680.70","0.000"],["64681.00","0.079"],["64688.60","0.047"],["64691.40","0.002"],["64694.00","2.168"],["64694.90","0.000"],["64695.30","0.000"],["64738.70","0.039"],["64738.80","0.000"],["64782.40","0.077"],["64802.50","0.000"],["64802.60","1.079"],["64819.70","0.947"],["64819.80","0.026"],["64842.60","0.000"],["64842.70","0.244"],["64973.30","0.772"],["65291.30","11.381"],["65296.50","0.001"],["65458.10","3.607"],["65495.10","0.762"],["65942.90","0.642"]],"st":1}}
{"stream":"btcusdt@depth@100ms","data":{"e":"depthUpdate","E":1784410642702,"T":1784410642701,"s":"BTCUSDT","ps":"BTCUSDT","U":11079103316230,"u":11079103326702,"pu":11079103315980,"b":[["1000.00","50.241"],["14249.90","1.834"],["14349.90","0.966"],["14449.90","1.232"],["14549.90","0.168"],["58184.90","0.002"],["62063.90","0.000"],["63724.90","4.390"],["63748.20","0.000"],["63777.10","1.173"],["63874.10","14.740"],["64003.40","0.000"],["64349.90","0.051"],["64463.70","0.043"],["64485.00","0.158"],["64538.90","0.004"],["64540.40","0.202"],["64541.90","0.000"],["64543.40","0.000"],["64544.90","0.000"],["64546.40","0.556"],["64564.50","0.002"],["64567.10","0.013"],["64625.60","0.222"],["64629.60","0.107"],["64633.00","0.215"],["64636.60","0.000"],["64637.60","0.001"],["64638.00","10.102"],["64638.50","0.367"],["64638.70","0.696"],["64638.90","0.251"],["64639.80","2.489"],["64640.10","0.927"],["64640.20","0.002"],["64640.70","0.066"],["64641.30","0.830"],["64641.80","1.005"],["64647.10","0.004"],["64647.70","0.001"],["64649.40","0.000"],["64649.90","12.461"]],"a":[["64650.00","0.863"],["64655.10","0.048"],["64657.90","0.181"],["64659.70","0.286"],["64662.60","0.016"],["64662.90","0.082"],["64669.60","0.000"],["64671.10","0.373"],["64671.20","0.023"],["64671.70","0.015"],["64671.90","0.542"],["64672.50","0.096"],["64673.20","0.926"],["64678.80","0.231"],["64679.40","0.012"],["64679.70","0.010"],["64680.00","0.453"],["64680.10","1.854"],["64681.00","0.002"],["64681.40","0.101"],["64691.40","0.002"],["64695.80","3.502"],["64696.10","0.001"],["65271.30","1.015"],["65296.50","0.003"],["65418.50","0.016"],["65813.70","1.593"],["71115.00","0.002"]],"st":1}}
{"stream":"btcusdt@depth@100ms","data":{"e":"depthUpdate","E":1784410642804,"T":1784410642801,"s":"BTCUSDT","ps":"BTCUSDT","U":11079103326709,"u":11079103337747,"pu":11079103326702,"b":[["1000.00","50.241"],["14149.90","0.042"],["14249.90","1.988"],["14349.90","0.770"],["14449.90","1.344"],["14549.90","0.056"],["51719.90","0.000"],["58184.90","0.002"],["62063.90","0.003"],["63744.80","5.238"],["64003.40","0.001"],["64499.20","0.166"],["64628.40","0.057"],["64629.60","0.050"],["64631.00","0.136"],["64639.50","1.047"],["64640.10","0.001"],["64640.70","0.607"],["64640.80","0.662"],["64640.90","0.466"],["64641.30","0.289"],["64641.80","0.001"],["64642.00","0.002"],["64648.50","0.117"],["64649.20","0.023"]],"a":[["64655.10","0.048"],["64681.00","0.079"],["64691.40","0.002"],["64695.70","0.890"],["64773.30","0.012"],["65296.50","0.001"],["65458.10","3.987"],["65557.00","4.690"],["65942.90","0.645"],["71115.00","0.000"]],"st":1}}
{"stream":"btcusdt@depth@100ms","data":{"e":"depthUpdate","E":1784410642906,"T":1784410642905,"s":"BTCUSDT","ps":"BTCUSDT","U":11079103338061,"u":11079103349599,"pu":11079103337747,"b":[["14149.90","0.154"],["14249.90","2.002"],["14349.90","0.714"],["14449.90","1.330"],["14549.90","0.000"],["58184.90","0.002"],["62063.90","0.000"],["63627.90","9.046"],["63744.80","7.588"],["64003.40","0.001"],["64326.70","0.168"],["64638.20","0.164"],["64638.90","0.135"],["64640.10","0.542"],["64640.70","0.066"],["64640.90","0.312"],["64641.80","0.155"],["64649.90","12.429"]],"a":[["64655.10","0.048"],["64657.70","0.382"],["64658.20","0.054"],["64669.70","1.101"],["64671.60","1.086"],["64671.90","0.001"],["64673.20","0.000"],["64681.00","0.002"],["64684.60","0.050"],["64688.60","0.000"],["64691.40","0.156"],["65264.20","0.765"],["65296.50","0.001"],["65394.10","1.928"],["65458.10","4.750"]],"st":1}}
{"stream":"btcusdt@depth@100ms","data":{"e":"depthUpdate","E":1784410643008,"T":1784410643007,"s":"BTCUSDT","ps":"BTCUSDT","U":11079103349702,"u":11079103359554,"pu":11079103349599,"b":[["1000.00","50.241"],["14149.90","0.280"],["14249.90","1.988"],["14349.90","0.714"],["14449.90","1.218"],["34000.00","7.463"],["51720.00","0.004"],["58184.90","0.002"],["63712.50","5.328"],["63820.80","1.564"],["64003.40","0.001"],["64463.70","0.047"],["64488.30","0.037"],["64496.00","0.005"],["64499.20","0.069"],["64537.40","1.276"],["64538.90","1.280"],["64540.40","1.478"],["64541.90","1.276"],["64543.40","1.276"],["64544.90","1.276"],["64546.40","1.832"],["64547.90","1.276"],["64564.50","0.006"],["64582.20","0.000"],["64582.30","1.140"],["64604.80","0.494"],["64607.20","0.741"],["64621.00","0.015"],["64633.00","0.215"],["64639.00","1.185"],["64639.50","0.121"],["64647.80","0.062"],["64649.60","0.609"],["64649.90","12.291"]],"a":[["64650.00","0.861"],["64655.10","0.048"],["64658.20","0.007"],["64658.70","1.308"],["64658.90","0.142"],["64659.10","0.525"],["64679.60","1.199"],["64691.40","0.002"],["64695.70","0.084"],["64695.80","0.002"],["64718.40","0.003"],["64802.60","0.000"],["65049.70","0.974"],["65232.90","0.000"],["65277.10","0.840"],["65296.50","0.001"],["65555.10","3.581"],["65942.90","0.642"]],"st":1}}
{"stream":"btcusdt@depth@100ms","data":{"e":"depthUpdate","E":1784410643110,"T":1784410643109,"s":"BTCUSDT","ps":"BTCUSDT","U":11079103359700,"u":11079103368664,"pu":11079103359554,"b":[["1000.00","50.241"],["14149.90","0.392"],["14249.90","2.002"],["14349.90","0.714"],["14449.90","1.092"],["34000.00","7.459"],["58184.90","0.002"],["61417.40","0.000"],["62063.90","0.003"],["63415.80","2.175"],["63635.10","0.012"],["63724.90","3.293"],["63866.00","16.719"],["64003.40","0.001"],["64320.00","0.443"],["64400.00","28.277"],["64480.00","4.367"],["64488.30","0.193"],["64495.90","1.783"],["64537.40","0.000"],["64538.90","0.004"],["64540.40","0.202"],["64541.90","0.000"],["64543.40","0.000"],["64544.90","0.000"],["64546.40","0.556"],["64547.90","0.000"],["64549.90","0.000"],["64560.00","1.150"],["64560.10","0.026"],["64636.20","0.522"],["64638.30","0.002"],["64640.00","2.085"],["64649.90","12.249"]],"a":[["64653.00","0.000"],["64655.10","0.635"],["64658.90","0.095"],["64660.10","0.048"],["64668.70","0.005"],["64691.40","0.002"],["64720.00","0.382"],["64749.40","0.016"],["64800.00","18.466"],["64802.60","1.079"],["64880.00","9.538"],["64960.00","2.259"],["65040.00","0.380"],["65231.80","0.693"],["65296.50","0.001"],["65664.80","0.783"],["65813.70","1.601"]],"st":1}}
{"stream":"btcusdt@depth@100ms","data":{"e":"depthUpdate","E":1784410643212,"T":1784410643209,"s":"BTCUSDT","ps":"BTCUSDT","U":11079103368765,"u":11079103383213,"pu":11079103368664,"b":[["14149.90","0.518"],["14249.90","1.988"],["14349.90","0.714"],["14449.90","0.980"],["51720.00","0.004"],["58184.90","0.002"],["61417.50","0.011"],["62063.90","0.000"],["63635.10","0.024"],["63660.20","2.198"],["63712.50","6.425"],["64003.40","0.001"],["64326.70","0.158"],["64349.90","0.051"],["64455.90","0.045"],["64458.50","0.065"],["64495.90","1.784"],["64527.00","0.001"],["64553.10","0.000"],["64560.00","1.154"],["64570.80","2.593"],["64570.90","0.211"],["64582.20","6.000"],["64591.60","0.089"],["64604.80","3.994"],["64610.60","0.006"],["64617.50","3.773"],["64619.10","0.170"],["64621.00","0.710"],["64621.70","0.002"],["64622.60","0.003"],["64627.70","0.066"],["64629.00","0.017"],["64630.50","0.065"],["64631.40","1.192"],["64633.00","0.215"],["64638.50","0.355"],["64643.30","0.064"],["64647.50","0.080"],["64649.70","0.000"],["64649.90","12.249"]],"a":[["64650.00","0.864"],["64652.00","0.012"],["64655.10","0.048"],["64656.50","0.743"],["64656.60","0.002"],["64657.70","0.382"],["64658.60","0.000"],["64658.70","1.308"],["64658.80","0.001"],["64658.90","0.002"],["64659.10","0.215"],["64659.70","0.285"],["64660.10","0.001"],["64662.20","0.018"],["64662.40","0.054"],["64662.50","0.353"],["64662.60","0.016"],["64662.90","0.035"],["64665.50","0.131"],["64665.70","0.704"],["64665.80","0.000"],["64666.80","0.004"],["64672.00","1.500"],["64672.70","0.005"],["64673.10","0.000"],["64679.80","0.753"],["64681.00","0.079"],["64686.30","0.000"],["64688.60","0.047"],["64690.40","0.101"],["64691.40","0.156"],["64693.90","2.033"],["64696.00","3.503"],["64699.90","11.239"],["64705.50","0.311"],["64710.80","0.030"],["64711.40","0.000"],["64717.30","11.646"],["64717.90","0.000"],["64718.10","0.310"],["64718.60","6.000"],["64718.70","0.000"],["64723.70","0.053"],["64724.90","0.093"],["64730.20","0.179"],["64730.50","0.100"],["64730.90","0.000"],["64748.80","0.385"],["64749.30","0.000"],["64752.00","0.010"],["64780.80","0.338"],["64783.30","0.007"],["64790.50","0.004"],["64790.70","0.021"],["64793.30","0.064"],["64798.30","0.000"],["64799.10","0.009"],["64800.20","0.005"],["64801.20","0.007"],["64802.50","1.079"],["64802.60","0.000"],["64802.80","0.000"],["64807.10","0.005"],["65264.30","0.002"],["65266.40","0.002"],["65296.50","0.001"]],"st":1}}
{"stream":"btcusdt@depth@100ms","data":{"e":"depthUpdate","E":1784410643314,"T":1784410643313,"s":"BTCUSDT","ps":"BTCUSDT","U":11079103383407,"u":11079103392136,"pu":11079103383213,"b":[["1000.00","50.241"],["14149.90","0.630"],["14249.90","2.002"],["14349.90","0.714"],["14449.90","0.854"],["51720.00","0.004"],["58184.90","0.002"],["61417.40","0.002"],["62063.90","0.003"],["63356.90","2.364"],["63357.00","0.017"],["63369.60","0.676"],["63918.90","0.002"],["64003.40","0.001"],["64320.00","0.630"],["64400.00","28.464"],["64455.90","0.041"],["64458.50","0.065"],["64463.70","0.043"],["64480.00","4.554"],["64485.00","0.499"],["64488.30","0.037"],["64560.00","1.341"],["64562.60","0.008"],["64564.50","0.006"],["64567.10","0.013"],["64582.30","1.947"],["64611.10","0.504"],["64631.40","1.272"],["64633.00","0.061"],["64638.00","0.102"],["64638.30","2.002"],["64639.80","1.432"],["64640.00","2.267"],["64647.50","0.000"],["64649.70","0.001"],["64649.80","0.005"],["64649.90","12.409"]],"a":[["64650.00","0.863"],["64656.50","0.021"],["64656.60","0.589"],["64657.60","0.004"],["64658.60","0.815"],["64662.30","24.281"],["64662.40","0.007"],["64662.70","0.182"],["64672.00","1.501"],["64675.50","0.001"],["64681.00","0.002"],["64691.40","0.002"],["64699.90","1.239"],["64704.30","0.026"],["64720.00","0.569"],["64800.00","18.653"],["64840.70","0.091"],["64880.00","9.725"],["64886.00","2.288"],["64960.00","2.446"],["65040.00","0.567"],["65296.50","0.001"],["65382.20","1.563"],["65433.60","2.673"],["65664.80","0.795"],["65942.90","0.645"]],"st":1}}
{"stream":"btcusdt@depth@100ms","data":{"e":"depthUpdate","E":1784410643416,"T":1784410643413,"s":"BTCUSDT","ps":"BTCUSDT","U":11079103392250,"u":11079103400199,"pu":11079103392136,"b":[["1000.00","50.241"],["14149.90","0.756"],["14249.90","1.988"],["14349.90","0.714"],["14449.90","0.742"],["58184.90","0.002"],["62063.90","0.000"],["63189.20","0.790"],["63744.80","7.854"],["63777.10","1.610"],["64003.40","0.001"],["64458.50","0.061"],["64488.30","0.193"],["64495.90","1.784"],["64530.90","0.077"],["64549.90","10.000"],["64564.50","0.002"],["64567.10","0.013"],["64595.60","0.028"],["64624.90","0.058"],["64627.10","1.359"],["64627.90","0.077"],["64628.40","0.000"],["64634.60","10.002"],["64636.20","0.638"],["64636.60","0.926"],["64636.70","3.338"],["64636.80","0.563"],["64637.20","0.083"],["64637.90","0.666"],["64638.20","0.048"],["64638.30","0.002"],["64638.50","0.355"],["64638.60","0.622"],["64638.70","0.703"],["64639.00","0.259"],["64639.10","0.139"],["64639.80","1.425"],["64640.10","0.464"],["64640.70","0.607"],["64640.80","0.121"],["64640.90","0.003"],["64641.80","0.001"],["64642.00","0.002"],["64643.40","0.007"],["64647.40","0.024"],["64649.90","12.412"]],"a":[["64650.00","1.870"],["64650.10","0.002"],["64656.40","0.001"],["64656.50","0.021"],["64656.60","0.589"],["64658.60","0.815"],["64659.10","0.526"],["64659.30","0.003"],["64662.20","0.574"],["64666.20","0.312"],["64668.80","0.679"],["64669.10","0.017"],["64669.20","0.048"],["64669.30","0.310"],["64669.60","0.926"],["64671.60","0.160"],["64678.70","0.058"],["64681.00","0.002"],["64681.40","0.044"],["64685.50","0.019"],["64685.60","0.001"],["64685.70","0.121"],["64686.00","0.002"],["64686.10","0.063"],["64686.20","0.114"],["64688.60","0.000"],["64688.80","0.007"],["64691.40","0.002"],["64695.80","0.000"],["64696.00","3.505"],["64721.10","0.015"],["64751.00","10.000"],["64785.80","0.120"],["64802.50","1.079"],["65296.50","0.001"]],"st":1}}
{"stream":"btcusdt@depth@100ms","data":{"e":"depthUpdate","E":1784410643518,"T":1784410643516,"s":"BTCUSDT","ps":"BTCUSDT","U":11079103400457,"u":11079103407422,"pu":11079103400199,"b":[["14149.90","0.938"],["14249.90","1.862"],["14349.90","0.784"],["14449.90","0.616"],["58184.90","0.002"],["63647.80","2.197"],["63660.20","1.100"],["63724.90","2.196"],["63906.40","1.876"],["64003.40","0.001"],["64326.70","0.158"],["64567.10","0.017"],["64592.10","20.597"],["64598.70","0.002"],["64598.80","0.000"],["64599.60","0.001"],["64608.10","0.216"],["64617.10","0.195"],["64620.00","0.322"],["64626.50","0.730"],["64632.90","0.077"],["64633.00","0.215"],["64636.60","0.000"],["64636.70","3.340"],["64637.80","1.643"],["64638.00","0.100"],["64649.90","12.453"]],"a":[["64650.00","2.127"],["64653.30","0.207"],["64656.60","0.589"],["64659.30","0.050"],["64659.70","0.440"],["64666.20","0.621"],["64669.10","0.004"],["64669.20","0.050"],["64669.30","0.312"],["64669.60","0.000"],["64670.10","0.931"],["64675.90","0.990"],["64685.50","0.021"],["64685.60","0.003"],["64685.70","0.123"],["64686.00","0.004"],["64686.10","0.065"],["64686.20","0.116"],["64689.90","10.009"],["64691.40","0.002"],["64693.90","0.033"],["64708.50","0.000"],["64710.70","23.219"],["64714.30","0.000"],["64719.10","0.025"],["64721.10","0.030"],["64750.90","0.008"],["64752.00","0.002"],["64753.30","0.024"],["65296.50","0.001"],["65381.90","5.804"],["66279.20","0.751"]],"st":1}}
{"stream":"btcusdt@depth@100ms","data":{"e":"depthUpdate","E":1784410643620,"T":1784410643618,"s":"BTCUSDT","ps":"BTCUSDT","U":11079103407523,"u":11079103413191,"pu":11079103407422,"b":[["1000.00","50.241"],["14149.90","1.176"],["14249.90","1.624"],["14349.90","0.896"],["14449.90","0.504"],["58184.90","0.002"],["62063.90","0.003"],["63595.60","2.437"],["63647.80","3.295"],["63712.50","7.522"],["63841.80","2.172"],["64003.40","0.001"],["64375.10","0.000"],["64485.00","0.343"],["64535.90","0.000"],["64537.40","0.000"],["64538.90","0.004"],["64540.40","0.000"],["64540.50","0.006"],["64541.90","0.000"],["64543.40","1.276"],["64592.10","0.006"],["64596.50","20.826"],["64599.60","0.026"],["64608.10","0.191"],["64640.10","0.155"],["64640.80","0.430"],["64649.90","12.452"]],"a":[["64656.60","0.002"],["64670.10","0.005"],["64670.60","0.934"],["64677.80","0.680"],["64678.60","0.026"],["64680.00","0.446"],["64680.10","1.298"],["64681.00","0.079"],["64973.30","0.770"],["65296.50","0.001"],["65406.40","0.535"],["66266.20","0.006"]],"st":1}}
{"stream":"btcusdt@depth@100ms","data":{"e":"depthUpdate","E":1784410643722,"T":1784410643721,"s":"BTCUSDT","ps":"BTCUSDT","U":11079103413302,"u":11079103419566,"pu":11079103413191,"b":[["1000.00","50.241"],["14149.90","1.414"],["14249.90","1.386"],["14349.90","1.022"],["14449.90","0.378"],["51719.90","0.002"],["58184.90","0.002"],["62063.90","0.000"],["63744.80","8.120"],["63863.50","12.634"],["64003.40","0.001"],["64326.60","0.938"],["64349.90","0.051"],["64378.40","0.117"],["64596.50","0.158"],["64598.70","20.670"],["64637.90","0.125"],["64639.90","0.558"],["64643.40","0.005"]],"a":[["64656.60","0.002"],["64670.60","0.008"],["64671.20","0.949"],["64675.50","0.701"],["64677.80","0.123"],["64678.50","0.603"],["64681.00","0.002"],["64685.80","0.013"],["64691.40","0.002"],["65296.50","0.001"],["65555.10","3.840"],["65587.40","3.958"],["65813.70","1.965"]],"st":1}}
{"stream":"btcusdt@depth@100ms","data":{"e":"depthUpdate","E":1784410643824,"T":1784410643821,"s":"BTCUSDT","ps":"BTCUSDT","U":11079103419592,"u":11079103425415,"pu":11079103419566,"b":[["14149.90","1.652"],["14249.90","1.148"],["14349.90","1.134"],["14449.90","0.266"],["51719.90","0.000"],["58184.90","0.002"],["61417.50","0.009"],["62063.90","0.003"],["63583.20","1.995"],["63809.40","0.391"],["63841.80","2.562"],["64003.40","0.000"],["64326.70","0.168"],["64482.50","0.005"],["64483.00","4.969"],["64603.70","0.440"],["64624.90","0.001"],["64628.00","0.060"],["64633.00","0.061"],["64636.80","0.006"],["64637.80","0.717"],["64638.20","0.055"],["64638.30","0.559"],["64638.60","1.548"],["64638.70","0.696"],["64639.20","0.003"],["64639.50","0.121"]],"a":[["64650.00","2.128"],["64653.70","0.007"],["64654.70","0.000"],["64654.90","0.003"],["64655.20","1.277"],["64655.40","0.000"],["64655.70","0.002"],["64655.90","0.001"],["64656.10","0.003"],["64656.30","0.001"],["64657.60","0.317"],["64669.60","0.541"],["64669.70","0.560"],["64671.10","0.373"],["64671.20","0.023"],["64671.80","0.047"],["64671.90","0.927"],["64678.50","0.047"],["64678.70","0.001"],["64679.40","0.568"],["64679.80","0.810"],["64688.00","1.813"],["64691.40","0.002"],["64748.80","1.755"],["65296.50","0.001"],["65354.70","0.687"]],"st":1}}
{"stream":"btcusdt@depth@100ms","data":{"e":"depthUpdate","E":1784410643926,"T":1784410643925,"s":"BTCUSDT","ps":"BTCUSDT","U":11079103425585,"u":11079103431519,"pu":11079103425415,"b":[["1000.00","50.241"],["14149.90","1.890"],["14249.90","0.910"],["14349.90","1.260"],["14449.90","0.140"],["58184.90","0.002"],["64003.40","0.000"],["64421.30","0.828"],["64543.40","0.000"],["64551.70","0.002"],["64551.80","0.003"],["64633.00","0.215"]],"a":[["64650.00","2.247"],["64653.70","0.594"],["64655.10","0.048"],["64657.50","0.158"],["64659.30","0.003"],["64662.30","24.234"],["64662.50","0.400"],["64681.00","0.079"],["64691.40","0.002"],["64773.30","0.112"],["65296.50","0.001"],["65377.60","0.492"]],"st":1}}
{"stream":"btcusdt@depth@100ms","data":{"e":"depthUpdate","E":1784410644028,"T":1784410644025,"s":"BTCUSDT","ps":"BTCUSDT","U":11079103431567,"u":11079103437106,"pu":11079103431519,"b":[["1000.00","50.241"],["14149.90","1.988"],["14249.90","0.742"],["14349.90","1.372"],["14449.90","0.028"],["14549.90","0.070"],["58184.90","0.002"],["61417.40","0.004"],["62063.90","0.000"],["63864.60","0.624"],["64003.40","0.000"],["64297.30","0.018"],["64579.20","0.004"],["64579.50","0.125"],["64579.80","0.071"],["64580.20","0.009"],["64580.50","2.633"],["64598.90","0.166"],["64599.20","0.001"],["64599.50","0.003"],["64599.90","0.019"],["64600.20","0.000"],["64614.50","0.005"],["64614.60","0.304"],["64614.80","0.006"],["64615.10","0.394"],["64615.20","0.584"],["64615.70","0.000"],["64615.80","0.000"],["64618.70","10.055"],["64619.40","0.096"],["64620.80","0.017"],["64631.90","0.081"],["64637.70","0.007"],["64637.80","0.003"],["64637.90","0.005"],["64638.10","0.619"],["64638.40","0.399"],["64638.50","0.049"],["64638.70","0.629"],["64639.00","0.060"],["64639.10","0.001"],["64639.30","0.001"],["64639.60","0.005"],["64643.70","0.120"],["64645.20","1.126"],["64645.30","0.003"],["64647.40","0.001"]],"a":[["64653.70","0.594"],["64657.50","0.001"],["64657.70","0.350"],["64658.10","0.005"],["64658.40","0.000"],["64658.70","1.276"],["64659.00","0.002"],["64659.10","0.314"],["64659.40","0.000"],["64659.50","0.184"],["64659.60","0.003"],["64659.70","0.200"],["64670.00","0.201"],["64677.50","0.003"],["64677.80","0.091"],["64678.10","0.000"],["64678.40","0.024"],["64678.80","0.079"],["64681.00","0.002"],["64681.60","0.004"],["64681.70","0.024"],["64682.20","0.000"],["64682.30","0.031"],["64682.70","0.283"],["64682.80","2.473"],["64682.90","10.053"],["64683.00","0.662"],["64691.40","0.002"],["64697.20","0.017"],["64697.50","0.310"],["64697.80","0.000"],["64698.20","0.000"],["64698.50","0.000"],["65296.50","0.001"],["65879.90","0.000"]],"st":1}}
{"stream":"btcusdt@depth@100ms","data":{"e":"depthUpdate","E":1784410644130,"T":1784410644129,"s":"BTCUSDT","ps":"BTCUSDT","U":11079103437404,"u":11079103444748,"pu":11079103437106,"b":[["14149.90","2.002"],["14249.90","0.714"],["14349.90","1.302"],["14449.90","0.000"],["14549.90","0.182"],["58184.90","0.002"],["61417.40","0.006"],["62063.90","0.003"],["63874.10","15.521"],["63877.80","0.000"],["64003.40","0.000"],["64326.70","0.158"],["64349.90","0.054"],["64485.00","0.499"],["64535.90","0.000"],["64537.40","0.000"],["64538.90","0.004"],["64540.40","0.000"],["64541.90","0.000"],["64543.40","0.000"],["64544.90","0.000"],["64546.40","1.832"],["64564.50","0.006"],["64619.40","0.098"],["64621.30","0.433"],["64631.90","0.081"],["64633.00","0.061"],["64635.70","0.522"],["64635.80","0.209"],["64636.20","0.638"],["64636.40","0.511"],["64636.80","0.315"],["64638.30","0.559"],["64638.90","0.155"],["64639.80","0.842"],["64640.80","0.121"],["64642.70","0.005"],["64643.10","0.004"]],"a":[["64653.70","0.007"],["64655.10","0.048"],["64656.60","0.589"],["64656.70","1.336"],["64656.80","0.060"],["64657.40","0.241"],["64657.60","0.004"],["64658.50","0.000"],["64658.60","0.257"],["64660.00","0.024"],["64660.10","0.542"],["64668.70","0.005"],["64676.50","0.060"],["64680.00","0.506"],["64680.60","0.068"],["64680.70","0.180"],["64691.40","0.002"],["65296.50","0.001"],["65577.40","3.806"]],"st":1}}
{"stream":"btcusdt@depth@100ms","data":{"e":"depthUpdate","E":1784410644232,"T":1784410644229,"s":"BTCUSDT","ps":"BTCUSDT","U":11079103444835,"u":11079103451345,"pu":11079103444748,"b":[["1000.00","50.241"],["14149.90","1.988"],["14249.90","0.714"],["14349.90","1.190"],["14549.90","0.308"],["51720.00","0.004"],["58184.90","0.002"],["61417.50","0.007"],["62063.90","0.000"],["63465.00","0.787"],["63841.80","3.344"],["63877.50","2.355"],["63898.30","7.008"],["64003.40","0.000"],["64062.40","12.006"],["64248.00","0.077"],["64349.90","0.051"],["64421.30","0.833"],["64546.40","0.556"],["64597.20","0.068"],["64633.00","0.215"],["64636.00","0.345"],["64636.30","0.314"],["64636.40","0.661"],["64636.60","0.067"],["64639.20","0.007"],["64639.30","0.003"],["64642.70","0.003"]],"a":[["64655.10","0.048"],["64656.40","0.033"],["64656.60","0.589"],["64656.70","1.396"],["64656.80","0.120"],["64657.10","0.089"],["64658.60","0.103"],["64659.30","0.005"],["64660.00","0.178"],["64664.10","0.154"],["64665.40","0.386"],["64676.20","0.034"],["64680.00","0.566"],["64680.10","1.358"],["64680.40","0.060"],["64681.00","0.079"],["64691.40","0.002"],["64840.70","0.208"],["64886.00","2.171"],["65516.00","0.638"]],"st":1}}
{"stream":"btcusdt@depth@100ms","data":{"e":"depthUpdate","E":1784410644334,"T":1784410644333,"s":"BTCUSDT","ps":"BTCUSDT","U":11079103451632,"u":11079103458006,"pu":11079103451345,"b":[["1000.00","50.241"],["14149.90","2.002"],["14249.90","0.714"],["14349.90","1.064"],["14549.90","0.420"],["58184.90","0.002"],["62063.90","0.003"],["63841.80","3.876"],["64003.40","0.000"],["64488.30","0.037"],["64596.90","0.074"],["64597.50","0.062"],["64597.80","0.074"],["64598.10","0.061"],["64614.20","0.016"],["64614.30","0.402"],["64614.40","0.020"],["64614.60","0.306"],["64614.70","0.004"],["64614.80","0.008"],["64630.10","0.004"],["64630.20","0.055"],["64630.30","0.389"],["64635.70","0.678"],["64635.80","0.329"],["64636.00","0.501"],["64636.30","0.388"],["64636.40","0.817"],["64636.90","0.206"],["64637.00","0.528"],["64637.30","0.075"],["64637.60","0.062"]],"a":[["64650.00","2.273"],["64655.50","0.039"],["64655.80","0.035"],["64656.10","0.155"],["64656.50","0.038"],["64656.60","0.589"],["64656.70","1.456"],["64656.80","0.152"],["64657.10","0.149"],["64657.20","0.062"],["64657.40","0.301"],["64658.60","0.103"],["64660.00","0.161"],["64675.20","0.037"],["64675.50","0.733"],["64675.80","0.032"],["64676.50","0.092"],["64679.40","0.688"],["64680.00","0.626"],["64680.40","0.120"],["64680.50","2.496"],["64680.70","0.240"],["64691.40","0.002"],["65296.50","0.001"],["65382.20","2.327"],["65495.10","0.000"],["65699.50","0.032"],["65873.40","3.937"]],"st":1}}
{"stream":"btcusdt@depth@100ms","data":{"e":"depthUpdate","E":1784410644436,"T":1784410644433,"s":"BTCUSDT","ps":"BTCUSDT","U":11079103458141,"u":11079103465389,"pu":11079103458006,"b":[["14149.90","1.988"],["14249.90","0.714"],["14349.90","0.952"],["14549.90","0.546"],["58184.90","0.002"],["63864.60","0.000"],["63874.10","17.085"],["63895.80","0.004"],["64003.40","0.000"],["64297.30","0.023"],["64326.70","0.168"],["64537.40","1.276"],["64538.90","1.280"],["64540.40","1.276"],["64541.90","1.276"],["64543.40","1.276"],["64544.90","1.276"],["64620.00","0.013"],["64626.50","0.575"],["64632.90","0.000"],["64633.00","0.215"],["64636.30","0.538"],["64649.90","11.644"]],"a":[["64650.00","2.109"],["64656.50","0.743"],["64656.60","0.002"],["64656.80","0.212"],["64658.60","0.093"],["64660.00","0.007"],["64660.10","0.001"],["64676.50","0.152"],["64681.00","0.079"],["64691.40","0.002"],["65296.50","0.001"],["65490.40","0.965"]],"st":1}}
{"stream":"btcusdt@depth@100ms","data":{"e":"depthUpdate","E":1784410644538,"T":1784410644536,"s":"BTCUSDT","ps":"BTCUSDT","U":11079103465615,"u":11079103471802,"pu":11079103465389,"b":[["1000.00","50.241"],["14149.90","2.002"],["14249.90","0.714"],["14349.90","0.826"],["14549.90","0.658"],["58184.90","0.002"],["62063.90","0.000"],["63357.00","0.020"],["63615.50","1.564"],["64003.40","0.000"],["64035.70","2.437"],["64132.70","0.780"],["64485.00","0.499"],["64488.30","0.193"],["64495.90","1.783"],["64537.40","0.000"],["64538.90","0.004"],["64540.40","0.000"],["64541.90","0.000"],["64543.40","0.000"],["64544.90","0.000"],["64564.50","0.002"],["64577.40","0.068"],["64612.40","0.176"],["64612.50","0.573"],["64612.70","0.216"],["64613.10","0.188"],["64616.60","0.184"],["64617.30","0.311"],["64623.80","0.155"],["64626.90","1.523"],["64628.00","0.003"],["64630.30","0.389"],["64630.50","2.065"],["64634.20","0.048"],["64634.60","10.004"],["64636.20","0.522"],["64637.40","0.117"],["64638.80","0.634"],["64639.90","0.017"],["64642.50","0.014"],["64644.50","0.009"],["64648.20","0.047"]],"a":[["64650.00","2.863"],["64653.30","0.083"],["64656.40","0.033"],["64656.50","0.202"],["64656.60","0.002"],["64658.60","0.217"],["64660.00","0.548"],["64660.10","0.001"],["64670.70","0.927"],["64671.90","0.001"],["64686.10","2.065"],["64689.90","10.011"],["64690.40","0.099"],["64691.40","0.002"],["64695.90","0.452"],["64802.50","1.079"],["65167.20","1.283"],["65296.50","0.001"],["65846.00","5.329"],["65883.90","2.983"]],"st":1}}
{"stream":"btcusdt@depth@100ms","data":{"e":"depthUpdate","E":1784410644640,"T":1784410644639,"s":"BTCUSDT","ps":"BTCUSDT","U":11079103471918,"u":11079103477643,"pu":11079103471802,"b":[["1000.00","50.241"],["14149.90","1.988"],["14249.90","0.714"],["14349.90","0.714"],["14549.90","0.784"],["51720.00","0.004"],["58184.90","0.002"],["62063.90","0.003"],["63357.00","0.017"],["63971.80","5.455"],["64003.40","0.000"],["64349.90","0.051"],["64375.10","0.117"],["64378.40","0.000"],["64577.10","0.075"],["64577.70","0.525"],["64578.10","0.074"],["64578.40","0.487"],["64595.00","1.265"],["64613.00","1.159"],["64613.10","0.338"],["64630.50","0.065"],["64633.00","0.061"],["64636.20","0.638"],["64636.80","0.315"],["64637.40","0.001"],["64637.50","0.560"],["64637.60","0.988"],["64638.10","0.619"],["64638.30","0.002"],["64638.60","0.622"],["64642.00","0.010"],["64644.50","0.001"],["64649.90","11.645"]],"a":[["64654.50","0.041"],["64656.50","0.021"],["64656.60","0.589"],["64658.50","0.181"],["64677.30","1.172"],["64679.40","0.132"],["64681.00","0.002"],["64689.90","0.011"],["64694.90","0.032"],["64695.20","0.061"],["64695.50","0.344"],["64696.20","0.032"],["65296.50","0.001"],["65458.10","5.513"],["65942.90","0.651"]],"st":1}}
{"stream":"btcusdt@depth@100ms","data":{"e":"depthUpdate","E":1784410644742,"T":1784410644741,"s":"BTCUSDT","ps":"BTCUSDT","U":11079103477689,"u":11079103483742,"pu":11079103477643,"b":[["14149.90","1.806"],["14249.90","0.812"],["14349.90","0.588"],["14549.90","0.994"],["51719.90","0.000"],["51720.00","0.006"],["58184.90","0.002"],["62063.90","0.000"],["63803.70","3.132"],["63874.10","17.709"],["64003.40","0.000"],["64326.60","0.936"],["64326.70","0.158"],["64612.40","0.332"],["64612.50","0.693"],["64612.70","0.372"],["64613.10","0.494"],["64613.70","0.276"],["64625.80","0.226"],["64626.90","1.466"],["64633.00","0.215"],["64635.60","0.488"],["64636.20","0.522"],["64638.20","0.596"],["64638.80","0.093"]],"a":[["64656.30","0.003"],["64656.50","0.202"],["64656.60","0.002"],["64658.50","0.000"],["64688.00","0.388"],["64691.40","0.002"],["65296.50","0.001"],["65482.90","3.614"],["65866.50","0.003"]],"st":1}}
{"stream":"btcusdt@depth@100ms","data":{"e":"depthUpdate","E":1784410644844,"T":1784410644843,"s":"BTCUSDT","ps":"BTCUSDT","U":11079103483827,"u":11079103490702,"pu":11079103483742,"b":[["1000.00","50.241"],["14149.90","1.568"],["14249.90","0.924"],["14349.90","0.476"],["14549.90","1.232"],["51720.00","0.004"],["58184.90","0.002"],["62063.90","0.003"],["63841.80","4.142"],["64003.40","0.000"],["64132.70","0.779"],["64540.40","0.202"],["64607.20","1.049"],["64616.60","0.334"],["64633.00","0.061"],["64634.30","0.482"],["64635.60","0.372"],["64636.70","3.897"],["64637.10","1.103"],["64637.50","0.003"],["64637.60","0.062"],["64643.40","0.007"]],"a":[["64650.00","2.253"],["64653.30","0.006"],["64656.50","0.021"],["64656.60","0.589"],["64658.50","0.000"],["64659.70","0.045"],["64660.00","0.007"],["64660.10","0.723"],["64666.20","0.312"],["64669.50","0.006"],["64670.10","0.931"],["64670.70","0.001"],["64683.20","0.026"],["64691.40","0.156"],["64692.80","0.000"],["64695.90","1.190"],["64973.30","0.772"],["65167.20","1.282"],["65296.50","0.001"],["65450.60","2.318"],["65846.90","0.000"]],"st":1}}
{"stream":"btcusdt@depth@100ms","data":{"e":"depthUpdate","E":1784410644946,"T":1784410644945,"s":"BTCUSDT","ps":"BTCUSDT","U":11079103490764,"u":11079103496559,"pu":11079103490702,"b":[["14149.90","1.330"],["14249.90","1.050"],["14349.90","0.350"],["14549.90","1.470"],["58184.90","0.002"],["63595.60","1.338"],["63724.90","1.099"],["63945.20","2.652"],["64003.40","0.000"],["64633.00","0.215"]],"a":[["64656.30","0.003"],["64656.40","0.033"],["64656.50","0.021"],["64656.60","0.002"],["64660.10","0.723"],["64691.40","0.156"],["64738.70","0.000"],["64739.10","0.045"],["65296.50","0.001"]],"st":1}}
{"stream":"btcusdt@depth@100ms","data":{"e":"depthUpdate","E":1784410645048,"T":1784410645046,"s":"BTCUSDT","ps":"BTCUSDT","U":11079103496617,"u":11079103502546,"pu":11079103496559,"b":[["14149.90","1.092"],["14249.90","1.162"],["14349.90","0.238"],["14549.90","1.708"],["58184.90","0.002"],["62063.90","0.000"],["62090.20","0.000"],["63590.20","2.348"],["64003.40","0.000"],["64326.70","0.168"],["64637.10","0.177"],["64638.30","0.933"]],"a":[["64650.00","2.255"],["64656.50","0.021"],["64656.60","0.589"],["64660.10","0.723"],["64669.10","0.002"],["64669.20","0.048"],["64669.30","0.310"],["64670.10","0.005"],["64670.70","0.927"],["64677.30","0.615"],["64678.30","0.558"],["64681.00","0.079"],["64685.70","0.121"],["64691.40","0.156"],["64941.10","0.154"],["65121.50","0.000"],["65296.50","0.001"],["65409.40","0.000"],["65480.40","1.125"]],"st":1}}
{"stream":"btcusdt@depth@100ms","data":{"e":"depthUpdate","E":1784410645150,"T":1784410645149,"s":"BTCUSDT","ps":"BTCUSDT","U":11079103502638,"u":11079103509168,"pu":11079103502546,"b":[["1000.00","50.241"],["14149.90","0.854"],["14249.90","1.288"],["14349.90","0.112"],["14549.90","1.946"],["58184.90","0.002"],["61417.40","0.004"],["62063.90","0.003"],["63163.00","0.794"],["63583.20","3.094"],["63712.50","8.619"],["64003.40","0.000"],["64349.90","0.051"],["64537.40","1.276"],["64538.90","1.280"],["64540.40","1.478"],["64541.90","1.276"],["64543.40","1.276"],["64544.90","1.276"],["64605.30","0.000"],["64612.70","0.392"],["64613.30","0.556"],["64636.20","0.522"],["64637.70","0.933"],["64638.20","0.055"],["64638.30","0.002"],["64639.90","0.558"]],"a":[["64650.00","2.265"],["64656.30","0.003"],["64656.40","0.033"],["64656.50","0.021"],["64656.60","0.589"],["64660.10","0.723"],["64662.50","0.353"],["64668.70","0.005"],["64678.60","0.019"],["64679.40","0.139"],["64685.50","0.019"],["64685.60","0.001"],["64685.80","0.060"],["64686.00","0.002"],["64686.10","2.063"],["64686.20","0.114"],["64691.40","0.002"],["65296.50","0.001"],["65577.70","7.148"],["65819.50","4.096"],["66266.20","0.081"],["67362.20","0.015"]],"st":1}}
{"stream":"btcusdt@depth@100ms","data":{"e":"depthUpdate","E":1784410645252,"T":1784410645251,"s":"BTCUSDT","ps":"BTCUSDT","U":11079103509298,"u":11079103515132,"pu":11079103509168,"b":[["14149.90","0.714"],["14249.90","1.400"],["14349.90","0.000"],["14449.90","0.098"],["14549.90","1.988"],["58184.90","0.002"],["62063.90","0.000"],["63357.00","0.014"],["63492.50","0.001"],["63563.80","0.550"],["63790.70","2.426"],["64003.40","0.000"],["64018.10","0.145"],["64335.30","0.000"],["64485.00","0.343"],["64525.70","0.007"],["64537.40","0.000"],["64538.90","0.004"],["64540.40","0.202"],["64541.90","0.000"],["64543.40","0.000"],["64589.10","0.001"],["64614.20","0.014"],["64631.60","0.559"],["64649.90","11.643"]],"a":[["64650.00","2.266"],["64656.30","0.003"],["64656.40","0.033"],["64656.50","0.021"],["64656.60","0.589"],["64660.10","0.723"],["64662.70","0.229"],["64683.20","0.001"],["64691.40","0.002"],["64691.80","0.027"],["64708.10","0.123"],["64734.40","0.000"],["64826.50","0.002"],["64989.00","0.694"],["65261.80","0.000"],["65296.50","0.003"]],"st":1}}
{"stream":"btcusdt@depth@100ms","data":{"e":"depthUpdate","E":1784410645354,"T":1784410645353,"s":"BTCUSDT","ps":"BTCUSDT","U":11079103515160,"u":11079103520775,"pu":11079103515132,"b":[["14149.90","0.714"],["14249.90","1.274"],["14449.90","0.210"],["14549.90","2.002"],["51720.00","0.004"],["58184.90","0.002"],["63945.30","0.782"],["64003.40","0.000"],["64326.70","0.168"],["64485.00","0.499"],["64615.90","0.012"],["64625.70","0.153"],["64630.60","1.289"],["64633.00","0.215"]],"a":[["64656.30","0.003"],["64656.40","0.033"],["64656.50","0.021"],["64656.60","0.002"],["64660.10","0.723"],["64669.80","0.005"],["64691.40","0.002"],["65296.50","0.001"],["65563.00","1.999"],["65587.40","5.023"]],"st":1}}
{"stream":"btcusdt@depth@100ms","data":{"e":"depthUpdate","E":1784410645456,"T":1784410645453,"s":"BTCUSDT","ps":"BTCUSDT","U":11079103520897,"u":11079103526655,"pu":11079103520775,"b":[["1000.00","50.241"],["14149.90","0.714"],["14249.90","1.162"],["14449.90","0.336"],["14549.90","1.988"],["51720.00","0.004"],["58184.90","0.002"],["60666.00","10.678"],["61236.00","0.187"],["62063.90","0.003"],["63841.80","4.797"],["63971.80","4.676"],["64003.40","0.000"],["64488.30","0.037"],["64495.90","1.077"],["64544.90","0.000"],["64546.40","0.556"],["64564.50","0.006"],["64617.50","2.208"],["64634.30","0.366"],["64637.20","0.199"],["64638.80","0.634"],["64639.90","0.017"]],"a":[["64650.00","2.309"],["64656.50","0.743"],["64656.60","0.002"],["64660.10","0.001"],["64681.00","0.002"],["64691.40","0.002"],["64692.40","0.000"],["64694.10","0.068"],["64802.50","0.000"],["65296.50","0.001"],["65432.00","9.980"]],"st":1}}
{"stream":"btcusdt@depth@100ms","data":{"e":"depthUpdate","E":1784410645558,"T":1784410645557,"s":"BTCUSDT","ps":"BTCUSDT","U":11079103526815,"u":11079103534347,"pu":11079103526655,"b":[["14149.90","0.714"],["14249.90","1.036"],["14449.90","0.448"],["14549.90","2.002"],["58184.90","0.002"],["62063.90","0.000"],["63764.20","1.096"],["63803.70","2.429"],["63921.90","0.000"],["64003.40","0.000"],["64495.90","1.783"],["64553.10","0.000"],["64560.00","1.341"],["64633.00","0.061"],["64633.20","0.085"],["64649.90","11.661"]],"a":[["64650.00","2.311"],["64653.50","0.077"],["64656.30","0.003"],["64656.40","0.033"],["64656.50","0.021"],["64656.60","0.002"],["64659.50","0.188"],["64660.00","0.162"],["64660.10","0.723"],["64662.70","0.182"],["64666.50","0.310"],["64669.30","0.325"],["64675.90","0.975"],["64691.40","0.002"],["64802.40","1.079"],["65296.50","0.003"],["65555.20","6.042"]],"st":1}}
{"stream":"btcusdt@depth@100ms","data":{"e":"depthUpdate","E":1784410645660,"T":1784410645659,"s":"BTCUSDT","ps":"BTCUSDT","U":11079103534432,"u":11079103540533,"pu":11079103534347,"b":[["14149.90","0.714"],["14249.90","0.924"],["14449.90","0.574"],["14549.90","1.988"],["58184.90","0.000"],["61417.40","0.004"],["62063.90","0.003"],["64003.40","0.000"],["64326.70","0.158"],["64349.90","0.051"],["64633.00","0.215"],["64636.50","0.117"],["64637.20","0.083"]],"a":[["64656.40","0.620"],["64656.50","0.021"],["64656.60","0.002"],["64660.10","0.723"],["65296.50","0.001"],["65480.40","0.866"],["65575.90","11.520"],["65883.90","2.074"]],"st":1}}
{"stream":"btcusdt@depth@100ms","data":{"e":"depthUpdate","E":1784410645762,"T":1784410645761,"s":"BTCUSDT","ps":"BTCUSDT","U":11079103540542,"u":11079103545673,"pu":11079103540533,"b":[["1000.00","50.241"],["14149.90","0.714"],["14249.90","0.798"],["14449.90","0.686"],["14549.90","2.002"],["51719.90","0.000"],["58184.90","0.002"],["62063.90","0.000"],["63945.20","3.432"],["64003.40","0.001"],["64147.30","0.002"],["64585.30","0.131"]],"a":[["64656.40","0.620"],["64656.50","0.021"],["64656.60","0.002"],["64660.10","0.723"],["64681.00","0.079"],["64691.40","0.156"],["65296.50","0.001"],["65365.30","0.229"],["65555.10","6.384"],["65852.50","0.758"]],"st":1}}
{"stream":"btcusdt@depth@100ms","data":{"e":"depthUpdate","E":1784410645864,"T":1784410645863,"s":"BTCUSDT","ps":"BTCUSDT","U":11079103545763,"u":11079103551883,"pu":11079103545673,"b":[["14149.90","0.714"],["14249.90","0.686"],["14449.90","0.812"],["14549.90","1.988"],["58184.90","0.002"],["64003.40","0.000"],["64368.70","0.117"],["64375.10","0.000"],["64441.90","2.010"],["64442.00","0.001"],["64463.70","0.043"],["64478.80","0.607"],["64495.90","1.541"],["64505.10","0.000"],["64505.60","0.099"],["64513.20","2.967"],["64515.10","0.705"],["64553.00","0.007"],["64553.50","3.398"],["64553.60","0.823"],["64560.20","0.000"],["64585.30","0.132"],["64617.60","1.178"],["64633.00","0.215"],["64638.80","0.093"],["64639.90","0.558"],["64643.40","0.005"],["64647.90","0.061"],["64649.90","11.670"]],"a":[["64650.00","2.183"],["64656.40","0.620"],["64656.50","0.589"],["64656.60","0.002"],["64657.90","0.197"],["64659.70","0.029"],["64660.10","0.155"],["64660.40","4.267"],["64681.00","0.079"],["64691.40","0.156"],["64744.90","3.858"],["64752.10","3.337"],["64753.60","0.000"],["64777.60","1.000"],["64778.10","0.261"],["64785.20","3.322"],["64802.40","0.676"],["64819.50","0.582"],["64819.70","0.007"],["64840.70","0.091"],["64854.70","0.911"],["64856.40","2.158"],["64856.60","0.007"],["64886.00","2.288"],["64973.30","0.770"],["65296.50","0.001"],["65548.60","3.928"]],"st":1}}
{"stream":"btcusdt@depth@100ms","data":{"e":"depthUpdate","E":1784410645966,"T":1784410645965,"s":"BTCUSDT","ps":"BTCUSDT","U":11079103551951,"u":11079103557586,"pu":11079103551883,"b":[["1000.00","50.241"],["14149.90","0.840"],["14249.90","0.560"],["14449.90","1.050"],["14549.90","1.750"],["58184.90","0.002"],["62063.90","0.003"],["63440.90","1.369"],["63874.10","17.975"],["64003.40","0.000"],["64326.60","0.938"],["64326.70","0.158"],["64585.30","0.133"],["64633.00","0.061"]],"a":[["64650.00","2.178"],["64656.10","0.155"],["64656.20","0.001"],["64656.30","0.003"],["64656.40","0.033"],["64656.50","0.021"],["64660.10","0.723"],["64660.40","4.220"],["64691.40","0.002"],["64714.60","0.002"],["65296.50","0.001"]],"st":1}}
{"stream":"btcusdt@depth@100ms","data":{"e":"depthUpdate","E":1784410646068,"T":1784410646066,"s":"BTCUSDT","ps":"BTCUSDT","U":11079103557943,"u":11079103564847,"pu":11079103557586,"b":[["1000.00","50.241"],["14149.90","0.952"],["14249.90","0.448"],["14449.90","1.288"],["14549.90","1.512"],["58184.90","0.002"],["62063.90","0.000"],["64003.40","0.000"],["64132.70","0.783"],["64633.00","0.215"],["64638.30","0.002"]],"a":[["64656.30","0.003"],["64656.40","0.033"],["64656.50","0.021"],["64656.60","0.002"],["64660.10","0.723"],["64691.40","0.002"],["65296.50","0.001"],["65671.70","0.652"]],"st":1}}
{"stream":"btcusdt@depth@100ms","data":{"e":"depthUpdate","E":1784410646170,"T":1784410646169,"s":"BTCUSDT","ps":"BTCUSDT","U":11079103564986,"u":11079103571145,"pu":11079103564847,"b":[["14149.90","1.078"],["14249.90","0.322"],["14449.90","1.526"],["14549.90","1.274"],["58184.90","0.002"],["61417.40","0.006"],["62063.90","0.003"],["63357.00","0.017"],["63874.10","18.241"],["63971.80","3.897"],["64003.40","0.000"],["64132.70","0.779"],["64349.90","0.051"],["64495.90","1.077"],["64636.20","0.522"],["64649.90","11.671"]],"a":[["64656.40","0.204"],["64656.50","0.031"],["64656.60","0.002"],["64660.10","0.542"],["64668.70","0.005"],["64691.40","0.002"],["64802.40","0.000"],["65248.20","0.001"],["65296.50","0.001"],["65431.00","0.087"],["65476.80","0.002"],["65674.60","5.096"]],"st":1}}
{"stream":"btcusdt@depth@100ms","data":{"e":"depthUpdate","E":1784410646272,"T":1784410646271,"s":"BTCUSDT","ps":"BTCUSDT","U":11079103571245,"u":11079103577419,"pu":11079103571145,"b":[["1000.00","50.241"],["14149.90","1.190"],["14249.90","0.210"],["14449.90","1.764"],["14549.90","1.036"],["58184.90","0.002"],["62063.90","0.000"],["63971.80","3.196"],["64003.40","0.000"],["64326.70","0.168"],["64478.80","0.145"],["64633.00","0.061"],["64649.90","11.670"]],"a":[["64650.00","2.177"],["64655.10","0.048"],["64656.30","0.003"],["64656.40","0.033"],["64656.50","0.021"],["64656.60","0.002"],["64660.00","0.884"],["64660.10","0.001"],["64662.70","0.229"],["64681.00","0.079"],["64691.40","0.002"],["64819.50","0.002"],["65296.50","0.003"],["65651.80","0.000"],["68695.90","0.113"]],"st":1}}
{"stream":"btcusdt@depth@100ms","data":{"e":"depthUpdate","E":1784410646374,"T":1784410646373,"s":"BTCUSDT","ps":"BTCUSDT","U":11079103577476,"u":11079103583172,"pu":11079103577419,"b":[["1000.00","50.241"],["14149.90","1.316"],["14249.90","0.084"],["14449.90","2.002"],["14549.90","0.798"],["51720.00","0.004"],["58184.90","0.002"],["61417.40","0.008"],["63912.90","0.002"],["63945.20","4.134"],["64003.40","0.000"],["64441.90","0.001"],["64553.50","3.288"],["64553.60","0.123"],["64633.00","0.215"],["64638.80","0.093"],["64639.90","0.017"],["64640.10","0.696"],["64649.90","11.671"]],"a":[["64656.40","1.332"],["64656.50","0.031"],["64656.60","0.002"],["64660.00","0.162"],["64660.10","0.001"],["64662.50","0.400"],["64662.70","0.182"],["64691.40","0.156"],["64744.90","3.871"],["64856.40","0.002"],["65296.50","0.001"],["65577.70","6.082"],["65859.00","0.910"]],"st":1}}
{"stream":"btcusdt@depth@100ms","data":{"e":"depthUpdate","E":1784410646476,"T":1784410646474,"s":"BTCUSDT","ps":"BTCUSDT","U":11079103583314,"u":11079103591378,"pu":11079103583172,"b":[["14149.90","1.372"],["14249.90","0.000"],["14349.90","0.126"],["14449.90","1.988"],["14549.90","0.714"],["58184.90","0.002"],["62063.90","0.003"],["63777.10","2.393"],["63945.20","4.914"],["64003.40","0.000"],["64441.90","3.296"],["64478.80","0.886"],["64495.90","1.786"],["64633.00","0.061"]],"a":[["64656.40","0.745"],["64656.50","0.031"],["64656.60","0.002"],["64659.90","0.000"],["64660.00","0.162"],["64660.10","0.001"],["64662.50","0.353"],["64662.70","0.182"],["64681.00","0.002"],["64691.40","0.156"],["64802.40","1.027"],["64819.50","0.898"],["64854.70","1.368"],["64856.40","3.466"],["65296.50","0.001"],["65458.10","5.771"],["65619.80","1.094"],["65684.40","2.554"],["65834.70","0.757"]],"st":1}}
{"stream":"btcusdt@depth@100ms","data":{"e":"depthUpdate","E":1784410646578,"T":1784410646577,"s":"BTCUSDT","ps":"BTCUSDT","U":11079103591539,"u":11079103598096,"pu":11079103591378,"b":[["1000.00","50.241"],["14149.90","1.246"],["14349.90","0.238"],["14449.90","2.002"],["14549.90","0.714"],["51720.00","0.004"],["58184.90","0.002"],["62063.90","0.000"],["62711.30","0.000"],["63703.00","0.016"],["64003.40","0.000"],["64326.70","0.158"],["64631.90","0.001"],["64633.00","0.215"],["64638.40","0.479"]],"a":[["64650.00","2.175"],["64656.40","0.033"],["64656.50","0.021"],["64660.10","0.723"],["64681.00","0.002"],["64691.40","0.156"],["64714.40","0.016"],["64721.10","0.015"],["65095.10","0.000"],["65296.50","0.001"],["65425.80","15.794"],["65482.90","3.355"],["65587.40","6.089"]],"st":1}}
{"stream":"btcusdt@depth@100ms","data":{"e":"depthUpdate","E":1784410646680,"T":1784410646678,"s":"BTCUSDT","ps":"BTCUSDT","U":11079103598262,"u":11079103604998,"pu":11079103598096,"b":[["1000.00","50.241"],["14149.90","1.134"],["14349.90","0.364"],["14449.90","1.988"],["14549.90","0.714"],["58184.90","0.002"],["62063.90","0.003"],["64003.40","0.000"],["64320.00","0.613"],["64349.90","0.051"],["64400.00","28.447"],["64480.00","4.537"],["64553.50","0.007"],["64560.00","1.324"],["64614.60","0.002"],["64640.00","2.250"],["64649.90","11.669"]],"a":[["64650.00","2.323"],["64656.60","0.589"],["64660.20","0.465"],["64660.60","0.047"],["64691.40","0.002"],["64703.60","0.008"],["64716.30","0.346"],["64720.00","0.552"],["64744.90","0.472"],["64800.00","18.636"],["64880.00","9.708"],["64960.00","2.429"],["65040.00","0.550"],["65106.80","0.129"],["65296.50","0.001"],["65433.60","2.139"],["65478.40","0.000"],["65577.70","5.016"]],"st":1}}
{"stream":"btcusdt@depth@100ms","data":{"e":"depthUpdate","E":1784410646782,"T":1784410646781,"s":"BTCUSDT","ps":"BTCUSDT","U":11079103605076,"u":11079103610671,"pu":11079103604998,"b":[["14149.90","1.008"],["14349.90","0.476"],["14449.90","2.002"],["14549.90","0.714"],["51719.90","0.000"],["58184.90","0.002"],["61417.40","0.010"],["62063.90","0.693"],["63712.50","9.716"],["64003.40","0.000"],["64553.50","3.288"],["64633.00","0.215"],["64636.70","3.340"],["64638.30","0.559"],["64640.10","0.542"],["64640.80","0.275"]],"a":[["64656.30","0.003"],["64656.40","0.033"],["64656.50","0.021"],["64656.60","0.002"],["64660.00","0.471"],["64660.10","0.723"],["64660.30","0.002"],["64681.00","0.079"],["64702.70","0.026"],["64716.30","0.321"],["64744.90","3.885"],["64886.00","2.171"],["65296.50","0.001"],["65382.20","3.091"],["65406.40","1.069"]],"st":1}}
{"stream":"btcusdt@depth@100ms","data":{"e":"depthUpdate","E":1784410646884,"T":1784410646883,"s":"BTCUSDT","ps":"BTCUSDT","U":11079103610834,"u":11079103616691,"pu":11079103610671,"b":[["1000.00","50.241"],["14149.90","0.896"],["14349.90","0.602"],["14449.90","1.988"],["14549.90","0.714"],["58184.90","0.002"],["62063.90","0.690"],["62688.10","2.313"],["63357.00","0.020"],["64003.40","0.000"],["64217.30","0.003"],["64217.40","0.000"],["64320.00","0.630"],["64326.70","0.168"],["64368.70","0.000"],["64375.10","0.117"],["64400.00","28.464"],["64480.00","4.554"],["64553.50","0.007"],["64560.00","1.341"],["64564.50","0.002"],["64598.80","3.180"],["64640.00","2.267"]],"a":[["64650.00","2.168"],["64656.40","0.574"],["64656.50","0.204"],["64656.60","0.002"],["64658.70","1.274"],["64659.90","0.000"],["64660.10","0.001"],["64660.60","0.000"],["64681.00","0.002"],["64691.40","0.002"],["64720.00","0.569"],["64744.90","0.472"],["64800.00","18.653"],["64840.70","0.208"],["64880.00","9.725"],["64960.00","2.446"],["65040.00","0.567"],["65296.50","0.001"],["65458.10","6.030"]],"st":1}}
{"stream":"btcusdt@depth@100ms","data":{"e":"depthUpdate","E":1784410646986,"T":1784410646985,"s":"BTCUSDT","ps":"BTCUSDT","U":11079103616772,"u":11079103622633,"pu":11079103616691,"b":[["1000.00","50.241"],["14149.90","0.770"],["14349.90","0.714"],["14449.90","2.002"],["14549.90","0.714"],["58184.90","0.002"],["62063.90","0.693"],["63863.50","12.400"],["63870.20","0.003"],["64326.60","0.936"],["64484.30","0.004"],["64553.50","3.288"],["64617.30","0.529"],["64633.00","0.061"],["64637.70","0.007"],["64638.50","0.975"],["64638.80","0.093"],["64639.40","0.241"],["64639.50","0.121"],["64639.90","0.558"],["64640.10","0.001"]],"a":[["64656.30","0.003"],["64656.40","0.591"],["64656.50","0.187"],["64656.60","0.002"],["64658.50","0.000"],["64659.90","0.000"],["64662.20","0.574"],["64662.40","0.007"],["64662.60","0.011"],["64669.60","0.541"],["64670.60","0.008"],["64670.70","0.001"],["64671.70","0.015"],["64671.80","0.973"],["64678.30","0.002"],["64679.30","0.557"],["64681.00","0.002"],["64691.40","0.002"],["64744.90","3.885"],["65296.50","0.001"],["65433.60","1.605"],["65535.70","1.597"],["65576.80","5.463"],["65587.40","7.155"],["65641.40","1.065"]],"st":1}}
{"stream":"btcusdt@depth@100ms","data":{"e":"depthUpdate","E":1784410647088,"T":1784410647086,"s":"BTCUSDT","ps":"BTCUSDT","U":11079103622797,"u":11079103629373,"pu":11079103622633,"b":[["14149.90","0.658"],["14349.90","0.868"],["14449.90","1.932"],["14549.90","0.742"],["58184.90","0.002"],["62063.90","0.690"],["63465.20","0.787"],["63917.70","4.531"],["64003.40","0.000"],["64638.30","0.559"],["64647.40","0.023"]],"a":[["64656.30","0.157"],["64656.40","0.050"],["64656.50","0.033"],["64656.60","0.002"],["64658.50","0.000"],["64659.90","0.541"],["64691.40","0.002"],["65296.50","0.001"],["65406.40","1.603"],["65557.00","2.425"],["66204.00","0.005"]],"st":1}}
{"stream":"btcusdt@depth@100ms","data":{"e":"depthUpdate","E":1784410647190,"T":1784410647189,"s":"BTCUSDT","ps":"BTCUSDT","U":11079103629491,"u":11079103636396,"pu":11079103629373,"b":[["1000.00","50.241"],["14149.90","0.532"],["14349.90","1.106"],["14449.90","1.694"],["14549.90","0.868"],["58184.90","0.002"],["61417.40","0.006"],["61417.50","0.009"],["62063.90","0.693"],["64003.40","0.000"],["64026.90","0.673"],["64326.70","0.158"],["64333.60","0.045"],["64349.90","0.051"],["64485.00","0.343"],["64488.30","0.193"],["64495.90","1.077"],["64517.60","0.014"],["64597.30","0.007"],["64621.50","3.142"],["64622.50","0.045"],["64633.00","0.215"],["64636.20","0.522"],["64649.90","11.667"]],"a":[["64650.00","2.175"],["64656.30","0.003"],["64656.40","0.033"],["64656.50","0.564"],["64656.60","0.166"],["64658.50","0.017"],["64659.90","0.000"],["64668.70","0.005"],["64691.40","0.002"],["64719.50","0.007"],["64727.00","0.027"],["64747.60","0.005"],["64802.40","0.000"],["64820.90","0.014"],["64973.30","0.772"],["64989.80","0.033"],["65271.40","0.055"],["65296.50","0.003"],["65642.30","1.360"],["65942.90","0.648"]],"st":1}}
