{"stream":"btcusdt@depth@100ms","data":{"e":"depthUpdate","E":1784410647292,"T":1784410647291,"s":"BTCUSDT","ps":"BTCUSDT","U":11079103636494,"u":11079103643810,"pu":11079103636396,"b":[["1000.00","50.241"],["14149.90","0.420"],["14349.90","1.344"],["14449.90","1.456"],["14549.90","0.980"],["58184.90","0.002"],["63777.10","3.097"],["63880.60","2.814"],["63885.40","2.003"],["64003.40","0.002"],["64400.30","0.006"],["64412.20","22.041"],["64441.90","0.001"],["64478.80","0.145"],["64560.00","1.337"],["64633.00","0.061"],["64643.40","0.007"]],"a":[["64650.00","2.136"],["64655.10","0.635"],["64656.20","0.001"],["64656.30","0.003"],["64656.40","0.033"],["64656.50","0.023"],["64656.60","0.002"],["64658.50","0.551"],["64659.90","0.171"],["64660.10","0.001"],["64660.40","4.220"],["64660.60","0.000"],["64660.80","0.006"],["64661.00","0.002"],["64661.30","0.001"],["64662.50","0.353"],["64669.60","0.000"],["64671.70","0.556"],["64681.60","0.004"],["64691.40","0.002"],["64805.10","0.000"],["64819.50","0.002"],["64856.40","0.002"],["65296.50","0.005"],["65587.40","8.221"],["65652.10","4.722"]],"st":1}}
{"stream":"btcusdt@depth@100ms","data":{"e":"depthUpdate","E":1784410647394,"T":1784410647393,"s":"BTCUSDT","ps":"BTCUSDT","U":11079103643951,"u":11079103651295,"pu":11079103643810,"b":[["14149.90","0.294"],["14349.90","1.582"],["14449.90","1.218"],["14549.90","1.106"],["51720.00","0.004"],["58184.90","0.002"],["61417.40","0.008"],["62063.90","0.690"],["64003.40","0.000"],["64326.70","0.168"],["64402.70","4.209"],["64412.30","3.432"],["64441.90","3.269"],["64478.70","0.741"],["64495.90","1.783"],["64553.10","0.000"],["64560.00","1.341"],["64633.00","0.215"],["64638.80","0.634"],["64639.90","0.017"]],"a":[["64650.00","1.973"],["64653.70","0.007"],["64655.10","0.048"],["64656.40","0.043"],["64656.50","0.177"],["64656.60","0.002"],["64657.90","0.181"],["64658.40","0.017"],["64658.50","0.000"],["64659.60","0.018"],["64659.90","0.541"],["64662.10","0.051"],["64662.30","24.234"],["64662.50","0.353"],["64669.60","0.541"],["64671.70","0.015"],["64691.40","0.002"],["64802.30","2.464"],["64819.50","0.870"],["64854.70","0.911"],["64856.30","3.453"],["65296.50","0.001"],["65458.10","6.289"],["65555.10","8.669"],["65577.70","3.950"],["65674.60","4.032"],["65802.40","0.100"],["65859.00","1.819"]],"st":1}}
{"stream":"btcusdt@depth@100ms","data":{"e":"depthUpdate","E":1784410647496,"T":1784410647495,"s":"BTCUSDT","ps":"BTCUSDT","U":11079103651339,"u":11079103657952,"pu":11079103651295,"b":[["1000.00","50.241"],["14149.90","0.182"],["14349.90","1.820"],["14449.90","0.980"],["14549.90","1.218"],["58184.90","0.002"],["62063.90","0.693"],["63357.00","0.017"],["63415.80","0.286"],["63777.80","11.801"],["63845.50","0.235"],["64003.40","0.000"],["64128.90","4.671"],["64633.00","0.061"],["64638.80","0.093"],["64640.10","0.542"],["64649.90","11.666"]],"a":[["64650.00","1.974"],["64655.10","0.048"],["64656.40","0.033"],["64656.50","0.564"],["64656.60","0.002"],["64658.40","0.000"],["64658.50","0.000"],["64659.90","0.181"],["64681.60","0.081"],["64691.40","0.002"],["65296.50","0.001"]],"st":1}}
{"stream":"btcusdt@depth@100ms","data":{"e":"depthUpdate","E":1784410647598,"T":1784410647597,"s":"BTCUSDT","ps":"BTCUSDT","U":11079103658041,"u":11079103665210,"pu":11079103657952,"b":[["1000.00","50.241"],["14149.90","0.056"],["14249.90","0.028"],["14349.90","2.002"],["14449.90","0.770"],["14549.90","1.344"],["51720.00","0.006"],["58184.90","0.002"],["62063.90","0.690"],["64003.40","0.000"],["64303.00","0.319"],["64633.00","0.215"]],"a":[["64656.30","0.003"],["64656.40","0.033"],["64656.50","0.023"],["64656.70","2.043"],["64658.50","0.551"],["64659.90","0.171"],["64681.60","0.004"],["64691.40","0.002"],["64773.30","0.012"],["64806.00","0.000"],["65296.50","0.001"],["68888.00","32.975"]],"st":1}}
{"stream":"btcusdt@depth@100ms","data":{"e":"depthUpdate","E":1784410647700,"T":1784410647699,"s":"BTCUSDT","ps":"BTCUSDT","U":11079103665297,"u":11079103673533,"pu":11079103665210,"b":[["14149.90","0.000"],["14249.90","0.154"],["14349.90","1.988"],["14449.90","0.714"],["14549.90","1.344"],["51720.00","0.004"],["58184.90","0.002"],["62063.90","0.693"],["63356.90","4.255"],["63751.30","0.909"],["63809.50","2.505"],["64003.40","0.000"],["64326.70","0.168"],["64441.90","0.001"],["64478.70","0.003"],["64495.90","1.077"],["64537.40","1.276"],["64538.90","1.280"],["64540.40","1.478"],["64541.90","1.276"],["64543.40","1.276"],["64544.90","1.276"],["64567.10","0.017"],["64594.60","0.026"],["64595.10","0.000"],["64609.30","0.078"],["64612.80","0.461"],["64614.60","0.000"],["64614.90","0.040"],["64617.30","0.220"],["64618.40","0.464"],["64618.80","0.031"],["64619.00","0.119"],["64619.60","0.001"],["64620.10","0.031"],["64620.20","0.000"],["64621.50","3.159"],["64621.80","0.000"],["64622.20","0.038"],["64622.30","0.404"],["64623.80","0.000"],["64628.80","0.019"],["64629.00","0.002"],["64630.50","0.097"],["64631.60","0.557"],["64632.20","0.436"],["64632.70","0.001"],["64633.00","0.061"],["64633.20","0.008"],["64634.60","0.004"],["64636.50","0.001"],["64637.10","0.293"],["64638.00","0.085"],["64638.20","0.048"],["64638.40","0.479"],["64639.10","0.008"],["64640.30","0.136"],["64649.90","11.666"]],"a":[["64650.00","1.319"],["64650.10","0.000"],["64652.00","0.010"],["64653.50","0.000"],["64653.70","0.131"],["64656.20","0.003"],["64656.40","0.214"],["64656.50","0.564"],["64656.60","0.002"],["64656.70","1.456"],["64658.50","0.000"],["64658.60","0.093"],["64659.10","0.004"],["64659.20","0.005"],["64659.90","0.000"],["64660.00","0.007"],["64660.10","0.310"],["64662.10","0.004"],["64662.20","0.574"],["64665.50","0.084"],["64666.50","0.001"],["64668.50","0.013"],["64668.70","0.160"],["64669.30","0.310"],["64671.80","0.926"],["64674.20","0.009"],["64674.40","3.655"],["64674.60","0.047"],["64674.70","0.003"],["64675.10","0.311"],["64676.20","0.049"],["64676.30","0.125"],["64676.70","0.015"],["64677.40","0.427"],["64677.60","0.003"],["64678.20","0.001"],["64678.40","0.410"],["64678.60","0.050"],["64678.70","0.001"],["64678.80","0.110"],["64679.00","0.558"],["64679.30","0.001"],["64679.50","0.313"],["64679.90","0.614"],["64683.60","0.015"],["64685.30","0.015"],["64686.00","0.017"],["64686.10","0.050"],["64688.60","0.047"],["64690.60","10.002"],["64691.30","0.047"],["64691.40","0.002"],["64694.10","0.115"],["64695.40","0.111"],["64695.70","0.069"],["64696.80","0.049"],["64699.50","0.011"],["64699.60","0.069"],["64700.30","0.002"],["64707.70","0.744"],["64713.40","0.027"],["64714.40","0.001"],["64721.50","0.016"],["64798.70","0.009"],["64802.30","1.466"],["64819.50","0.002"],["64856.30","0.000"],["65296.50","0.001"],["65545.10","0.532"],["65577.70","2.884"],["65587.40","9.287"],["65684.40","3.618"],["65707.00","0.001"]],"st":1}}
{"stream":"btcusdt@depth@100ms","data":{"e":"depthUpdate","E":1784410647802,"T":1784410647801,"s":"BTCUSDT","ps":"BTCUSDT","U":11079103673583,"u":11079103680641,"pu":11079103673533,"b":[["1000.00","50.241"],["14249.90","0.266"],["14349.90","2.002"],["14449.90","0.714"],["14549.90","1.218"],["51719.90","0.000"],["58184.90","0.002"],["64003.40","0.000"],["64441.90","3.269"],["64478.70","0.741"],["64485.00","0.158"],["64495.90","1.783"],["64537.40","0.000"],["64538.90","0.004"],["64540.40","0.202"],["64541.90","0.000"],["64543.40","0.000"],["64544.90","0.000"],["64546.40","0.556"],["64547.90","0.000"],["64549.40","0.035"],["64562.60","0.349"],["64564.50","0.002"],["64632.00","10.733"],["64633.50","3.078"],["64636.50","0.117"],["64636.70","1.978"],["64637.10","0.177"],["64637.80","0.560"],["64638.20","0.974"],["64638.30","0.002"],["64638.40","0.479"],["64638.50","0.049"],["64639.10","0.008"],["64639.30","0.003"],["64639.50","0.121"],["64639.90","0.017"],["64640.10","0.001"],["64640.20","0.002"],["64640.80","0.816"],["64641.30","0.289"]],"a":[["64650.00","1.976"],["64650.10","0.002"],["64655.10","0.048"],["64656.40","0.033"],["64656.50","0.021"],["64656.60","0.589"],["64657.50","0.003"],["64659.30","0.315"],["64660.00","0.729"],["64665.00","0.002"],["64665.30","0.000"],["64665.60","0.053"],["64669.00","0.048"],["64669.60","0.000"],["64670.60","0.934"],["64671.70","0.556"],["64671.80","0.047"],["64672.60","0.388"],["64673.90","0.012"],["64674.70","0.001"],["64679.00","0.002"],["64679.40","0.132"],["64680.10","1.914"],["64680.20","1.797"],["64688.00","1.820"],["64694.10","0.068"],["64696.80","0.002"],["64699.60","0.022"],["64704.30","0.037"],["64802.30","2.464"],["64819.50","0.872"],["64856.30","3.464"],["65296.50","0.001"],["65522.80","1.217"]],"st":1}}
{"stream":"btcusdt@depth@100ms","data":{"e":"depthUpdate","E":1784410647904,"T":1784410647901,"s":"BTCUSDT","ps":"BTCUSDT","U":11079103680759,"u":11079103686789,"pu":11079103680641,"b":[["1000.00","50.241"],["14249.90","0.392"],["14349.90","1.988"],["14449.90","0.714"],["14549.90","1.106"],["58184.90","0.002"],["62063.90","0.690"],["63357.00","0.014"],["64003.40","0.000"],["64026.90","0.055"],["64035.70","3.060"],["64320.00","0.613"],["64400.00","28.447"],["64480.00","4.537"],["64553.60","0.807"],["64560.00","1.324"],["64633.00","0.215"],["64638.80","0.634"],["64640.00","2.250"],["64640.80","0.275"]],"a":[["64650.00","1.971"],["64656.60","0.589"],["64668.70","0.701"],["64671.70","0.015"],["64677.70","0.560"],["64680.10","1.358"],["64691.80","0.181"],["64720.00","0.552"],["64784.00","1.020"],["64800.00","18.636"],["64854.70","1.368"],["64880.00","9.708"],["64960.00","2.429"],["65040.00","0.550"],["65236.20","0.266"],["65296.50","0.002"],["65323.70","1.537"],["65942.90","0.645"],["66614.80","0.001"]],"st":1}}
{"stream":"btcusdt@depth@100ms","data":{"e":"depthUpdate","E":1784410648006,"T":1784410648005,"s":"BTCUSDT","ps":"BTCUSDT","U":11079103687031,"u":11079103693219,"pu":11079103686789,"b":[["14249.90","0.504"],["14349.90","2.002"],["14449.90","0.714"],["14549.90","0.980"],["58184.90","0.002"],["62063.90","0.693"],["64003.40","0.000"],["64326.70","0.168"],["64633.00","0.061"]],"a":[["64656.60","0.002"],["64668.70","0.160"],["64669.60","0.541"],["64681.60","0.081"],["64778.30","0.100"],["65296.50","0.002"],["65587.40","10.353"],["65716.70","1.064"]],"st":1}}
{"stream":"btcusdt@depth@100ms","data":{"e":"depthUpdate","E":1784410648108,"T":1784410648105,"s":"BTCUSDT","ps":"BTCUSDT","U":11079103693373,"u":11079103700246,"pu":11079103693219,"b":[["1000.00","50.241"],["14249.90","0.630"],["14349.90","1.988"],["14449.90","0.714"],["14549.90","0.868"],["58184.90","0.002"],["61417.40","0.010"],["61417.50","0.007"],["62063.90","0.690"],["63702.10","0.119"],["63885.40","2.785"],["64003.40","0.000"],["64320.00","0.630"],["64400.00","28.464"],["64480.00","4.554"],["64560.00","1.341"],["64614.60","0.002"],["64614.70","0.002"],["64633.00","0.215"],["64638.30","0.002"],["64640.00","2.267"],["64647.60","0.003"],["64649.60","0.606"],["64649.90","11.667"]],"a":[["64656.60","0.002"],["64681.60","0.081"],["64685.90","2.003"],["64720.00","0.569"],["64800.00","18.653"],["64880.00","9.725"],["64960.00","2.446"],["65040.00","0.567"],["65296.50","0.002"],["65942.90","0.648"],["66589.50","4.349"]],"st":1}}
{"stream":"btcusdt@depth@100ms","data":{"e":"depthUpdate","E":1784410648210,"T":1784410648208,"s":"BTCUSDT","ps":"BTCUSDT","U":11079103700490,"u":11079103706809,"pu":11079103700246,"b":[["1000.00","50.241"],["14249.90","0.742"],["14349.90","2.002"],["14449.90","0.714"],["14549.90","0.742"],["58184.90","0.002"],["63861.60","0.390"],["64003.40","0.000"],["64231.10","0.070"],["64326.60","0.938"],["64636.20","0.520"]],"a":[["64656.60","0.589"],["64668.70","0.158"],["64778.30","0.000"],["64973.30","0.770"],["65296.50","0.033"],["65458.10","6.517"],["65527.40","0.010"],["65692.10","0.673"]],"st":1}}
{"stream":"btcusdt@depth@100ms","data":{"e":"depthUpdate","E":1784410648312,"T":1784410648311,"s":"BTCUSDT","ps":"BTCUSDT","U":11079103706949,"u":11079103714039,"pu":11079103706809,"b":[["14249.90","0.924"],["14349.90","1.876"],["14449.90","0.770"],["14549.90","0.630"],["58184.90","0.002"],["62063.90","0.693"],["63605.30","0.001"],["63702.20","0.001"],["63712.50","10.813"],["64003.40","0.002"],["64326.70","0.168"],["64478.70","0.741"],["64495.80","1.884"],["64495.90","1.077"],["64567.10","0.013"],["64632.00","10.735"],["64633.50","3.076"],["64636.20","0.522"],["64638.80","0.634"],["64640.10","0.001"],["64649.90","12.445"]],"a":[["64650.00","2.287"],["64656.60","0.002"],["64662.50","0.353"],["64668.70","0.701"],["64669.60","0.000"],["64670.50","0.080"],["64670.60","0.008"],["64671.60","1.086"],["64677.70","0.003"],["64679.00","0.558"],["64681.60","0.004"],["64683.20","0.026"],["64688.00","0.388"],["64689.90","0.009"],["64690.60","0.004"],["64691.30","0.000"],["64691.80","0.156"],["64802.30","2.545"],["64819.40","0.944"],["64819.50","0.002"],["65296.50","0.033"],["65458.10","6.776"],["65557.00","0.160"],["66291.40","3.190"]],"st":1}}
{"stream":"btcusdt@depth@100ms","data":{"e":"depthUpdate","E":1784410648414,"T":1784410648413,"s":"BTCUSDT","ps":"BTCUSDT","U":11079103714084,"u":11079103720507,"pu":11079103714039,"b":[["1000.00","50.241"],["14249.90","1.162"],["14349.90","1.638"],["14449.90","0.896"],["14549.90","0.504"],["58184.90","0.002"],["62063.90","0.690"],["63572.80","0.010"],["63751.20","0.000"],["64003.40","0.000"],["64197.40","0.166"],["64637.00","0.532"],["64649.90","12.441"]],"a":[["64656.70","1.456"],["64681.60","0.081"],["65296.50","0.033"],["65942.90","0.642"],["66266.30","2.185"]],"st":1}}
{"stream":"btcusdt@depth@100ms","data":{"e":"depthUpdate","E":1784410648516,"T":1784410648515,"s":"BTCUSDT","ps":"BTCUSDT","U":11079103720596,"u":11079103726307,"pu":11079103720507,"b":[["1000.00","50.241"],["14249.90","1.400"],["14349.90","1.400"],["14449.90","1.008"],["14549.90","0.392"],["58184.90","0.002"],["62063.90","0.693"],["63615.50","2.663"],["63712.50","11.910"],["64003.40","0.000"],["64320.00","0.613"],["64400.00","28.447"],["64480.00","4.537"],["64560.00","1.324"],["64617.30","0.524"],["64635.30","0.119"],["64636.50","0.001"],["64640.00","2.250"],["64649.90","12.470"]],"a":[["64650.00","2.287"],["64670.30","0.927"],["64671.60","0.160"],["64681.60","0.004"],["64685.90","0.003"],["64689.50","10.000"],["64720.00","0.552"],["64800.00","18.636"],["64880.00","9.708"],["64960.00","2.429"],["65040.00","0.550"],["65296.50","0.033"],["65490.40","1.880"],["65555.10","10.954"]],"st":1}}
{"stream":"btcusdt@depth@100ms","data":{"e":"depthUpdate","E":1784410648618,"T":1784410648617,"s":"BTCUSDT","ps":"BTCUSDT","U":11079103726361,"u":11079103732888,"pu":11079103726307,"b":[["14249.90","1.638"],["14349.90","1.162"],["14449.90","1.134"],["14549.90","0.266"],["51720.00","0.008"],["58184.90","0.002"],["62063.90","0.690"],["63583.20","4.194"],["64003.40","0.000"],["64297.30","0.018"],["64326.70","0.168"],["64421.30","0.828"],["64633.00","0.061"],["64635.30","0.003"],["64635.90","0.233"],["64637.60","0.988"],["64638.20","0.048"],["64642.40","0.001"],["64643.50","0.311"]],"a":[["64650.00","2.285"],["64668.70","0.160"],["64669.60","0.541"],["64670.30","0.001"],["64671.10","1.299"],["64681.60","0.081"],["65256.60","16.406"],["65296.50","0.035"],["65576.80","4.397"],["65588.80","4.127"]],"st":1}}
{"stream":"btcusdt@depth@100ms","data":{"e":"depthUpdate","E":1784410648720,"T":1784410648717,"s":"BTCUSDT","ps":"BTCUSDT","U":11079103732950,"u":11079103740142,"pu":11079103732888,"b":[["1000.00","50.241"],["14249.90","1.876"],["14349.90","0.924"],["14449.90","1.246"],["14549.90","0.154"],["58184.90","0.002"],["63604.80","1.101"],["63701.70","5.524"],["63895.70","3.752"],["64003.40","0.000"],["64240.00","0.317"],["64240.80","0.000"],["64320.00","0.460"],["64400.00","28.294"],["64480.00","4.384"],["64485.00","0.343"],["64560.00","1.171"],["64562.60","0.008"],["64564.80","0.606"],["64621.30","0.742"],["64625.60","0.006"],["64627.80","0.317"],["64633.00","0.215"],["64634.20","0.125"],["64636.80","0.006"],["64637.10","0.486"],["64637.30","0.075"],["64637.40","0.558"],["64637.80","0.003"],["64638.10","0.002"],["64638.90","0.772"],["64640.00","2.267"],["64647.40","0.001"],["64649.90","12.470"]],"a":[["64650.00","1.819"],["64654.60","0.080"],["64656.60","0.589"],["64673.90","0.010"],["64674.40","3.657"],["64677.70","0.003"],["64678.30","0.559"],["64679.00","0.002"],["64720.00","0.399"],["64738.80","0.027"],["64798.70","0.009"],["64800.00","18.483"],["64880.00","9.555"],["64960.00","2.276"],["65040.00","0.397"],["65231.80","0.923"],["65296.50","0.033"],["65548.00","4.777"],["65576.80","2.265"],["65587.40","11.419"],["65942.90","0.645"],["66646.60","0.001"]],"st":1}}
{"stream":"btcusdt@depth@100ms","data":{"e":"depthUpdate","E":1784410648822,"T":1784410648821,"s":"BTCUSDT","ps":"BTCUSDT","U":11079103740340,"u":11079103746852,"pu":11079103740142,"b":[["1000.00","50.241"],["14149.90","0.056"],["14249.90","2.002"],["14349.90","0.742"],["14449.90","1.372"],["14549.90","0.028"],["51719.90","0.000"],["58184.90","0.002"],["62063.90","0.693"],["63615.50","3.762"],["63637.10","3.300"],["63701.70","4.427"],["63712.50","13.007"],["63764.90","1.566"],["63841.80","5.031"],["64003.40","0.000"],["64320.00","0.630"],["64400.00","28.464"],["64421.30","0.833"],["64480.00","4.554"],["64560.00","1.341"],["64585.20","0.021"],["64633.00","0.061"],["64640.00","2.437"]],"a":[["64650.00","1.804"],["64656.60","0.589"],["64665.60","0.006"],["64666.10","0.047"],["64681.60","0.004"],["64720.00","0.569"],["64798.70","0.000"],["64800.00","18.653"],["64880.00","9.725"],["64960.00","2.446"],["65040.00","0.567"],["65296.50","0.033"],["65641.40","0.000"]],"st":1}}
{"stream":"btcusdt@depth@100ms","data":{"e":"depthUpdate","E":1784410648924,"T":1784410648922,"s":"BTCUSDT","ps":"BTCUSDT","U":11079103746922,"u":11079103753215,"pu":11079103746852,"b":[["14149.90","0.182"],["14249.90","1.988"],["14349.90","0.714"],["14449.90","1.316"],["14549.90","0.000"],["58184.90","0.002"],["62063.90","0.690"],["64121.90","5.137"],["64326.70","0.168"],["64633.00","0.215"],["64635.90","0.117"],["64636.70","2.094"],["64647.50","0.023"],["64649.90","12.469"]],"a":[["64650.00","1.834"],["64656.60","0.589"],["64674.50","1.956"],["64675.60","0.715"],["64798.70","0.000"],["65296.50","0.032"],["65448.10","0.454"],["65575.90","10.607"],["65587.40","12.485"]],"st":1}}
{"stream":"btcusdt@depth@100ms","data":{"e":"depthUpdate","E":1784410649026,"T":1784410649025,"s":"BTCUSDT","ps":"BTCUSDT","U":11079103753389,"u":11079103759150,"pu":11079103753215,"b":[["1000.00","50.241"],["14149.90","0.294"],["14249.90","2.002"],["14349.90","0.714"],["14449.90","1.190"],["58184.90","0.002"],["61417.40","0.012"],["62063.90","0.693"],["63712.50","14.104"],["63906.40","2.814"],["64003.40","0.000"],["64297.30","0.023"],["64638.80","0.093"],["64640.10","0.542"]],"a":[["64653.20","0.005"],["64656.60","0.002"],["64656.70","2.043"],["64798.70","0.009"],["65296.50","0.032"],["65478.50","0.258"],["65587.40","13.551"],["65770.10","1.517"]],"st":1}}
{"stream":"btcusdt@depth@100ms","data":{"e":"depthUpdate","E":1784410649128,"T":1784410649126,"s":"BTCUSDT","ps":"BTCUSDT","U":11079103759258,"u":11079103766263,"pu":11079103759150,"b":[["1000.00","50.241"],["14149.90","0.420"],["14249.90","1.988"],["14349.90","0.714"],["14449.90","1.078"],["58184.90","0.002"],["61417.40","0.012"],["62063.90","0.690"],["63357.00","0.014"],["63647.80","4.393"],["63845.50","0.000"],["63895.70","2.814"],["64003.40","0.000"],["64132.70","1.712"],["64495.80","1.178"],["64635.80","2.329"],["64638.30","0.002"],["64649.90","12.453"]],"a":[["64650.00","1.843"],["64656.70","1.456"],["64798.70","0.009"],["64802.30","1.466"],["65296.50","0.032"],["65548.60","4.841"],["65652.10","5.787"]],"st":1}}
{"stream":"btcusdt@depth@100ms","data":{"e":"depthUpdate","E":1784410649230,"T":1784410649229,"s":"BTCUSDT","ps":"BTCUSDT","U":11079103766446,"u":11079103773207,"pu":11079103766263,"b":[["14149.90","0.532"],["14249.90","2.002"],["14349.90","0.714"],["14449.90","0.952"],["58184.90","0.002"],["63895.70","0.938"],["64003.40","0.000"],["64326.60","0.936"],["64326.70","0.158"],["64485.00","0.499"],["64488.30","0.037"],["64564.50","0.006"],["64569.70","0.001"],["64572.30","0.004"],["64596.50","0.004"],["64596.90","0.228"],["64615.10","0.386"],["64623.70","1.039"],["64632.00","0.735"],["64633.50","1.599"],["64636.70","2.627"],["64649.90","12.439"]],"a":[["64650.00","1.806"],["64656.60","0.002"],["64656.70","1.456"],["64660.20","0.465"],["64679.00","0.009"],["64680.20","1.790"],["64681.60","0.004"],["65296.50","0.032"],["65408.30","2.665"],["65942.90","0.648"]],"st":1}}
{"stream":"btcusdt@depth@100ms","data":{"e":"depthUpdate","E":1784410649332,"T":1784410649329,"s":"BTCUSDT","ps":"BTCUSDT","U":11079103773306,"u":11079103779143,"pu":11079103773207,"b":[["1000.00","50.241"],["14149.90","0.658"],["14249.90","1.988"],["14349.90","0.714"],["14449.90","0.840"],["51720.00","0.008"],["58184.90","0.002"],["62063.90","0.693"],["64003.40","0.000"],["64368.70","0.117"],["64375.10","0.000"],["64441.80","3.323"],["64441.90","0.001"],["64478.70","0.745"],["64495.80","1.887"],["64550.30","0.004"],["64560.00","1.337"],["64636.20","0.522"],["64649.90","12.442"]],"a":[["64663.30","0.429"],["64668.70","0.160"],["64802.30","2.545"],["64819.40","0.941"],["64854.70","1.401"],["64856.20","3.682"],["64856.30","0.000"],["64973.30","0.772"],["65296.50","0.032"],["65478.50","0.000"]],"st":1}}
{"stream":"btcusdt@depth@100ms","data":{"e":"depthUpdate","E":1784410649434,"T":1784410649433,"s":"BTCUSDT","ps":"BTCUSDT","U":11079103779345,"u":11079103787157,"pu":11079103779143,"b":[["1000.00","50.241"],["14149.90","0.770"],["14249.90","2.002"],["14349.90","0.714"],["14449.90","0.714"],["58184.90","0.002"],["62063.90","0.690"],["63906.40","4.689"],["64003.40","0.000"],["64495.80","1.891"],["64633.00","0.061"],["64637.60","0.062"],["64638.90","1.698"],["64644.70","0.181"]],"a":[["64656.70","1.456"],["64663.30","0.382"],["64666.10","0.000"],["64802.30","2.545"],["65296.50","0.032"],["65419.30","3.667"]],"st":1}}
{"stream":"btcusdt@depth@100ms","data":{"e":"depthUpdate","E":1784410649536,"T":1784410649535,"s":"BTCUSDT","ps":"BTCUSDT","U":11079103787340,"u":11079103794976,"pu":11079103787157,"b":[["14149.90","0.980"],["14249.90","1.820"],["14349.90","0.798"],["14449.90","0.602"],["58184.90","0.002"],["62063.90","0.693"],["63300.40","0.003"],["63906.40","5.627"],["63945.30","0.001"],["64003.40","0.000"],["64326.70","0.168"],["64488.30","0.193"],["64550.30","0.000"],["64557.60","0.005"],["64564.50","0.002"],["64569.70","0.001"],["64614.20","0.014"],["64614.30","0.402"],["64614.40","0.020"],["64614.70","0.004"],["64614.80","0.006"],["64625.80","0.169"],["64629.30","0.157"],["64630.10","0.004"],["64630.20","0.055"],["64630.30","0.389"],["64634.60","0.002"],["64635.80","2.331"],["64636.70","2.511"],["64637.10","0.177"],["64637.40","0.001"],["64638.90","0.772"],["64639.10","0.001"],["64639.30","0.119"],["64640.00","2.420"],["64640.10","0.001"],["64640.20","0.009"],["64640.40","1.048"],["64640.60","1.794"],["64640.70","0.056"],["64640.80","0.121"],["64641.00","10.001"],["64641.30","0.830"],["64641.80","0.001"],["64642.00","0.010"],["64643.20","3.269"],["64643.60","0.003"],["64645.30","1.034"]],"a":[["64650.00","1.299"],["64650.10","0.000"],["64654.60","0.003"],["64659.30","0.005"],["64665.60","0.006"],["64669.00","0.001"],["64669.60","0.000"],["64671.10","0.373"],["64671.70","0.015"],["64671.90","0.542"],["64673.40","1.002"],["64678.30","0.002"],["64679.00","0.002"],["64679.30","0.001"],["64679.80","0.753"],["64680.40","0.127"],["64680.70","0.796"],["64681.20","0.367"],["64683.20","0.001"],["64689.50","0.002"],["64690.60","0.002"],["64691.30","0.047"],["64692.70","0.072"],["64708.50","23.910"],["64710.70","0.006"],["64798.70","0.009"],["65291.30","10.694"],["65296.50","0.034"],["65414.80","4.077"]],"st":1}}
{"stream":"btcusdt@depth@100ms","data":{"e":"depthUpdate","E":1784410649638,"T":1784410649637,"s":"BTCUSDT","ps":"BTCUSDT","U":11079103795055,"u":11079103801924,"pu":11079103794976,"b":[["1000.00","50.241"],["14149.90","1.218"],["14249.90","1.582"],["14349.90","0.924"],["14449.90","0.476"],["58184.90","0.004"],["61417.40","0.010"],["61417.50","0.009"],["63637.10","2.201"],["64003.40","0.000"],["64614.60","0.000"],["64614.80","0.008"],["64621.30","0.433"],["64627.80","0.162"],["64628.10","0.057"],["64629.30","0.100"],["64634.20","0.048"],["64636.40","10.817"],["64638.00","0.201"],["64638.70","1.186"],["64639.10","0.001"],["64639.30","0.003"],["64639.50","1.047"],["64639.60","0.012"],["64640.10","0.542"],["64640.20","0.002"],["64640.40","0.122"],["64640.60","1.237"],["64640.70","0.056"],["64641.00","0.001"],["64641.30","0.289"],["64647.50","0.000"]],"a":[["64650.00","1.956"],["64650.10","0.002"],["64656.60","0.589"],["64667.70","0.169"],["64669.60","0.541"],["64671.90","0.927"],["64673.40","0.076"],["64679.00","0.558"],["64680.70","0.240"],["64692.10","10.000"],["64707.70","4.292"],["64710.60","0.692"],["64798.70","0.009"],["65296.50","0.032"],["65588.40","0.000"]],"st":1}}
{"stream":"btcusdt@depth@100ms","data":{"e":"depthUpdate","E":1784410649740,"T":1784410649737,"s":"BTCUSDT","ps":"BTCUSDT","U":11079103802140,"u":11079103808873,"pu":11079103801924,"b":[["1000.00","50.241"],["14149.90","1.456"],["14249.90","1.344"],["14349.90","1.036"],["14449.90","0.364"],["58184.90","0.002"],["62063.90","0.690"],["63501.40","1.571"],["63860.50","3.313"],["64003.40","0.000"],["64569.70","0.005"],["64633.00","0.061"],["64636.40","10.819"],["64636.70","3.922"],["64637.30","0.191"],["64638.00","0.085"],["64638.60","1.179"],["64638.70","0.629"],["64638.90","1.698"],["64639.10","0.008"],["64639.50","0.121"],["64639.60","0.005"],["64640.70","0.778"],["64640.80","0.430"],["64643.20","1.714"],["64645.30","0.003"]],"a":[["64656.60","0.589"],["64657.10","0.122"],["64660.50","0.050"],["64669.60","0.541"],["64671.80","0.047"],["64679.00","0.002"],["64679.70","0.566"],["64679.80","0.063"],["64691.80","0.154"],["64692.10","10.002"],["64707.70","0.744"],["64708.50","0.000"],["64710.70","23.899"],["64712.90","0.002"],["64962.30","0.254"],["65264.20","1.453"],["65296.50","0.032"],["65425.80","16.405"]],"st":1}}
{"stream":"btcusdt@depth@100ms","data":{"e":"depthUpdate","E":1784410649842,"T":1784410649841,"s":"BTCUSDT","ps":"BTCUSDT","U":11079103809110,"u":11079103816645,"pu":11079103808873,"b":[["14149.90","1.694"],["14249.90","1.106"],["14349.90","1.162"],["14449.90","0.238"],["51719.90","0.000"],["51720.00","0.008"],["58184.90","0.002"],["62063.90","0.693"],["63647.80","5.491"],["64003.40","0.000"],["64315.80","1.164"],["64326.70","0.168"],["64635.80","0.331"],["64637.30","0.075"],["64638.20","0.164"],["64640.70","2.778"],["64643.20","1.791"],["64647.60","0.026"]],"a":[["64650.00","1.299"],["64650.10","0.000"],["64655.60","0.085"],["64656.60","0.002"],["64659.20","0.234"],["64660.10","0.001"],["64660.30","0.311"],["64663.20","0.006"],["64663.70","0.309"],["64667.70","0.122"],["64668.30","0.047"],["64669.60","0.541"],["64671.80","0.047"],["64678.30","0.704"],["64692.10","0.002"],["64695.40","10.111"],["64798.70","0.000"],["65118.70","0.001"],["65156.20","5.853"],["65296.50","0.034"]],"st":1}}
{"stream":"btcusdt@depth@100ms","data":{"e":"depthUpdate","E":1784410649944,"T":1784410649943,"s":"BTCUSDT","ps":"BTCUSDT","U":11079103816712,"u":11079103824729,"pu":11079103816645,"b":[["1000.00","50.391"],["14149.90","1.932"],["14249.90","0.868"],["14349.90","1.274"],["14449.90","0.126"],["58184.90","0.002"],["61417.40","0.012"],["62063.90","0.690"],["63841.80","5.297"],["64003.40","0.000"],["64315.80","0.543"],["64485.00","0.158"],["64537.40","1.276"],["64538.90","1.280"],["64540.40","1.478"],["64541.90","1.276"],["64543.40","1.276"],["64544.90","1.276"],["64546.40","1.832"],["64564.50","0.006"],["64577.10","0.001"],["64577.40","0.001"],["64577.70","0.464"],["64578.10","0.000"],["64578.40","0.426"],["64590.20","0.000"],["64596.90","0.154"],["64597.20","0.001"],["64597.50","0.001"],["64597.80","0.000"],["64598.10","0.000"],["64599.60","0.034"],["64604.90","0.157"],["64612.40","0.002"],["64612.50","0.033"],["64612.70","0.080"],["64613.00","1.003"],["64613.10","0.050"],["64613.70","0.000"],["64614.10","0.018"],["64616.60","0.004"],["64618.90","0.000"],["64626.70","0.057"],["64628.10","0.000"],["64630.30","0.389"],["64633.00","0.215"],["64635.70","0.000"],["64635.80","0.019"],["64636.00","0.189"],["64636.30","0.158"],["64636.40","0.195"],["64636.60","0.000"],["64636.70","2.331"],["64636.80","0.161"],["64636.90","0.007"],["64637.00","0.394"],["64637.30","0.255"],["64637.60","0.001"],["64638.20","0.048"],["64638.30","0.928"],["64638.90","0.772"],["64639.00","0.601"],["64640.10","0.001"],["64643.20","1.714"]],"a":[["64650.00","1.293"],["64653.20","0.005"],["64655.50","0.007"],["64655.80","0.003"],["64656.10","0.003"],["64656.40","0.001"],["64656.60","0.589"],["64656.70","1.276"],["64656.80","0.000"],["64657.10","0.002"],["64657.20","0.002"],["64657.40","0.061"],["64658.10","0.004"],["64663.60","0.078"],["64673.70","0.014"],["64675.20","0.005"],["64675.50","0.701"],["64675.80","0.000"],["64676.20","0.017"],["64676.50","0.000"],["64679.40","0.012"],["64680.00","0.446"],["64680.10","1.298"],["64680.40","0.007"],["64680.50","2.436"],["64680.60","0.008"],["64680.70","0.060"],["64681.60","0.004"],["64694.90","0.000"],["64695.20","0.029"],["64695.50","0.312"],["64695.90","1.158"],["64696.20","0.000"],["64798.70","0.000"],["65200.10","0.049"],["65296.50","0.032"],["65942.90","0.645"]],"st":1}}
{"stream":"btcusdt@depth@100ms","data":{"e":"depthUpdate","E":1784410650046,"T":1784410650045,"s":"BTCUSDT","ps":"BTCUSDT","U":11079103824833,"u":11079103832469,"pu":11079103824729,"b":[["1000.00","50.241"],["14149.90","2.002"],["14249.90","0.714"],["14349.90","1.400"],["14449.90","0.000"],["14549.90","0.084"],["51720.00","0.008"],["58184.90","0.002"],["62063.90","0.693"],["63200.00","30.651"],["63357.00","0.011"],["64003.40","0.000"],["64326.60","1.091"],["64463.70","0.047"],["64537.40","0.000"],["64538.90","0.004"],["64540.40","0.000"],["64540.50","0.006"],["64541.90","0.000"],["64543.40","0.000"],["64544.90","0.000"],["64546.40","0.556"],["64547.90","0.000"],["64549.40","0.035"],["64550.90","0.014"],["64562.60","0.349"],["64597.20","0.075"],["64597.80","0.061"],["64598.10","0.074"],["64598.40","0.112"],["64607.70","0.006"],["64633.00","0.215"],["64633.80","1.419"],["64636.30","0.158"],["64636.40","0.311"],["64636.60","0.224"],["64636.70","1.976"],["64637.20","0.144"],["64637.30","0.139"],["64637.60","0.075"],["64637.90","0.066"],["64638.30","0.933"],["64640.70","2.780"],["64641.40","0.040"],["64649.90","11.842"]],"a":[["64650.00","1.800"],["64650.10","0.002"],["64656.60","0.589"],["64656.80","0.032"],["64657.10","0.034"],["64657.40","0.107"],["64658.10","0.096"],["64658.30","0.379"],["64659.00","0.002"],["64659.40","0.000"],["64659.60","0.003"],["64659.90","0.000"],["64660.10","0.001"],["64660.30","0.311"],["64660.60","0.000"],["64660.80","0.006"],["64661.10","0.177"],["64661.30","0.048"],["64662.00","0.189"],["64665.70","0.426"],["64666.00","0.005"],["64673.70","0.013"],["64676.50","0.032"],["64676.90","0.245"],["64677.20","0.373"],["64677.80","0.123"],["64677.90","0.627"],["64691.50","1.138"],["64691.60","2.002"],["64693.30","0.000"],["64695.40","0.113"],["64696.00","3.503"],["64773.30","0.112"],["64798.70","0.009"],["64973.20","0.846"],["65167.20","1.587"],["65296.50","0.032"],["65942.90","0.648"]],"st":1}}
{"stream":"btcusdt@depth@100ms","data":{"e":"depthUpdate","E":1784410650148,"T":1784410650147,"s":"BTCUSDT","ps":"BTCUSDT","U":11079103832584,"u":11079103841072,"pu":11079103832469,"b":[["14149.90","1.988"],["14249.90","0.714"],["14349.90","1.288"],["14549.90","0.210"],["58184.90","0.002"],["61417.50","0.011"],["63041.70","0.000"],["63723.80","0.790"],["63746.90","3.883"],["63861.60","0.000"],["64003.40","0.000"],["64326.70","0.789"],["64598.70","0.002"],["64598.80","0.000"],["64600.90","21.115"],["64601.00","3.460"],["64607.70","0.010"],["64614.90","0.038"],["64633.00","0.061"],["64636.00","0.711"],["64636.10","0.409"],["64636.30","0.314"],["64636.70","2.294"],["64638.30","0.928"],["64649.90","11.840"]],"a":[["64650.00","1.801"],["64656.60","0.589"],["64658.00","0.061"],["64658.10","0.156"],["64658.30","0.069"],["64658.50","0.060"],["64658.70","1.394"],["64658.80","0.121"],["64661.30","0.001"],["64661.60","0.001"],["64662.20","0.574"],["64662.40","0.007"],["64677.80","0.183"],["64681.30","0.576"],["64681.60","0.081"],["64681.70","0.084"],["64682.00","0.282"],["64682.10","0.060"],["64773.30","0.012"],["65296.50","0.032"],["65641.00","1.081"]],"st":1}}
{"stream":"btcusdt@depth@100ms","data":{"e":"depthUpdate","E":1784410650250,"T":1784410650249,"s":"BTCUSDT","ps":"BTCUSDT","U":11079103841161,"u":11079103850492,"pu":11079103841072,"b":[["1000.00","50.241"],["14149.90","2.002"],["14249.90","0.714"],["14349.90","1.162"],["14549.90","0.322"],["51720.00","0.008"],["58184.90","0.002"],["62063.90","0.690"],["63797.00","0.594"],["63889.60","5.473"],["64003.40","0.000"],["64328.60","0.376"],["64458.50","0.065"],["64463.70","0.047"],["64537.40","0.000"],["64538.90","0.004"],["64540.40","0.000"],["64541.90","0.000"],["64543.40","0.000"],["64544.90","0.000"],["64546.40","0.556"],["64546.50","0.000"],["64547.90","1.276"],["64549.40","1.311"],["64550.90","1.290"],["64552.40","1.276"],["64553.90","1.276"],["64582.20","0.000"],["64582.30","1.140"],["64597.50","0.068"],["64604.80","0.494"],["64607.20","0.741"],["64621.00","0.015"],["64633.00","0.215"],["64636.30","0.470"],["64636.60","0.380"],["64636.70","2.444"],["64636.90","0.074"],["64640.00","3.060"],["64640.70","2.626"],["64641.80","0.155"],["64644.60","0.000"],["64645.20","0.850"]],"a":[["64656.60","0.589"],["64657.80","0.034"],["64658.10","0.276"],["64658.50","0.120"],["64665.20","0.094"],["64665.40","0.386"],["64677.50","0.035"],["64678.30","0.002"],["64681.30","0.636"],["64681.40","0.104"],["64681.70","0.144"],["64695.90","0.420"],["64696.00","0.003"],["64718.60","0.000"],["65296.50","0.032"],["66016.10","0.302"]],"st":1}}
{"stream":"btcusdt@depth@100ms","data":{"e":"depthUpdate","E":1784410650352,"T":1784410650351,"s":"BTCUSDT","ps":"BTCUSDT","U":11079103850658,"u":11079103858976,"pu":11079103850492,"b":[["14149.90","1.988"],["14249.90","0.714"],["14349.90","1.050"],["14549.90","0.448"],["51720.00","0.010"],["58184.90","0.002"],["61417.50","0.007"],["62063.90","0.693"],["63357.00","0.014"],["63738.30","0.627"],["63744.80","10.470"],["64003.40","0.002"],["64326.60","1.093"],["64368.70","0.000"],["64453.30","0.316"],["64547.90","0.000"],["64549.40","0.035"],["64549.90","0.000"],["64550.90","0.014"],["64552.40","0.000"],["64553.90","0.000"],["64555.40","1.276"],["64577.40","0.075"],["64578.10","0.061"],["64578.40","0.500"],["64578.70","0.061"],["64614.00","0.879"],["64633.00","0.061"],["64636.00","0.867"],["64636.10","0.529"],["64636.20","0.522"],["64636.70","2.600"],["64636.80","0.006"],["64637.20","0.282"],["64649.90","11.828"]],"a":[["64650.00","1.952"],["64656.60","0.002"],["64657.50","0.063"],["64658.00","0.121"],["64658.50","0.180"],["64658.60","0.247"],["64658.80","0.181"],["64659.30","0.315"],["64660.00","0.575"],["64661.20","0.000"],["64661.90","0.359"],["64663.70","0.309"],["64665.20","0.141"],["64668.70","0.160"],["64680.70","0.120"],["64681.30","0.696"],["64681.60","0.004"],["64681.80","0.060"],["64682.00","0.342"],["64691.30","0.000"],["64696.20","0.032"],["64696.60","0.123"],["64696.90","0.035"],["64697.60","0.065"],["64708.50","23.840"],["64710.70","0.006"],["64748.80","0.385"],["64751.00","0.000"],["64840.70","0.091"],["64973.30","0.770"],["65296.50","0.032"],["65883.90","1.317"]],"st":1}}
{"stream":"btcusdt@depth@100ms","data":{"e":"depthUpdate","E":1784410650454,"T":1784410650453,"s":"BTCUSDT","ps":"BTCUSDT","U":11079103859024,"u":11079103865959,"pu":11079103858976,"b":[["14149.90","2.002"],["14249.90","0.714"],["14349.90","0.924"],["14549.90","0.560"],["51720.00","0.008"],["58184.90","0.002"],["62063.90","0.690"],["63375.00","0.128"],["63701.70","3.329"],["63895.70","0.000"],["64003.40","0.000"],["64326.70","0.906"],["64495.80","1.872"],["64583.10","6.000"],["64605.70","3.502"],["64616.90","0.718"],["64621.90","0.720"],["64633.00","0.215"],["64643.40","0.005"],["64649.90","11.829"]],"a":[["64650.00","1.802"],["64656.60","0.589"],["64658.40","0.010"],["64660.00","0.565"],["64678.20","0.717"],["64694.40","4.061"],["64717.10","6.015"],["64750.90","0.000"],["64752.00","0.010"],["64798.70","0.126"],["64802.20","1.126"],["64802.30","1.466"],["64841.20","0.107"],["65296.50","0.032"],["65511.50","1.526"],["65561.60","0.763"],["65652.10","6.852"],["65705.60","0.001"],["65870.50","0.000"],["66609.10","1.284"]],"st":1}}
{"stream":"btcusdt@depth@100ms","data":{"e":"depthUpdate","E":1784410650556,"T":1784410650553,"s":"BTCUSDT","ps":"BTCUSDT","U":11079103866009,"u":11079103873829,"pu":11079103865959,"b":[["1000.00","50.241"],["14149.90","1.988"],["14249.90","0.714"],["14349.90","0.812"],["14549.90","0.686"],["58184.90","0.002"],["63714.40","0.001"],["63751.80","0.000"],["64003.40","0.000"],["64453.30","0.312"],["64455.90","0.045"],["64488.30","0.037"],["64495.80","1.178"],["64545.90","0.009"],["64555.40","0.000"],["64577.80","0.081"],["64612.70","0.254"],["64612.80","1.001"],["64613.00","1.159"],["64613.30","0.712"],["64613.40","0.139"],["64617.00","0.507"],["64633.00","0.215"],["64639.00","0.607"],["64649.90","11.831"]],"a":[["64650.00","1.702"],["64656.60","0.589"],["64661.90","0.312"],["64665.20","0.094"],["64668.30","0.000"],["64668.50","0.060"],["64669.10","0.004"],["64669.20","0.050"],["64669.30","0.312"],["64685.50","0.021"],["64685.60","0.003"],["64685.70","0.123"],["64686.00","0.019"],["64686.10","0.052"],["64686.20","0.116"],["64697.20","0.049"],["64708.50","0.000"],["64710.70","23.846"],["64802.20","0.047"],["64840.70","0.208"],["65296.50","0.032"],["65480.40","0.608"],["65942.90","0.645"]],"st":1}}
{"stream":"btcusdt@depth@100ms","data":{"e":"depthUpdate","E":1784410650658,"T":1784410650657,"s":"BTCUSDT","ps":"BTCUSDT","U":11079103874086,"u":11079103880958,"pu":11079103873829,"b":[["14149.90","2.002"],["14249.90","0.714"],["14349.90","0.686"],["14549.90","0.798"],["58184.90","0.002"],["61417.40","0.010"],["61417.50","0.009"],["62063.90","0.693"],["63572.60","0.061"],["63701.80","1.629"],["63712.50","15.201"],["63751.70","0.000"],["63906.40","6.565"],["64003.40","0.000"],["64455.90","0.041"],["64458.50","0.061"],["64495.80","1.884"],["64550.20","0.556"],["64550.80","10.003"],["64550.90","0.022"],["64613.00","1.315"],["64613.40","0.289"],["64635.10","0.606"]],"a":[["64656.60","0.589"],["64678.70","0.557"],["64679.30","0.008"],["64679.70","0.010"],["64680.40","0.000"],["64681.60","0.004"],["64748.80","1.755"],["64749.30","0.008"],["64749.40","10.016"],["64752.00","0.002"],["64802.20","1.126"],["65296.50","0.032"],["65425.80","16.664"],["65458.10","7.156"],["65624.50","0.822"],["65716.70","2.128"]],"st":1}}
{"stream":"btcusdt@depth@100ms","data":{"e":"depthUpdate","E":1784410650760,"T":1784410650757,"s":"BTCUSDT","ps":"BTCUSDT","U":11079103881068,"u":11079103889608,"pu":11079103880958,"b":[["14149.90","1.764"],["14249.90","0.826"],["14349.90","0.574"],["14549.90","1.036"],["58184.90","0.002"],["62063.90","0.690"],["63637.10","1.103"],["64003.40","0.000"],["64062.40","11.337"],["64326.70","0.906"],["64612.70","0.410"],["64612.90","0.130"],["64613.40","0.445"],["64614.00","1.017"],["64626.40","0.447"]],"a":[["64656.60","0.002"],["65296.50","0.032"],["65427.70","3.750"],["65587.40","14.464"],["65673.30","0.000"],["67882.50","0.002"]],"st":1}}
{"stream":"btcusdt@depth@100ms","data":{"e":"depthUpdate","E":1784410650862,"T":1784410650861,"s":"BTCUSDT","ps":"BTCUSDT","U":11079103889850,"u":11079103898234,"pu":11079103889608,"b":[["1000.00","50.241"],["14149.90","1.526"],["14249.90","0.952"],["14349.90","0.448"],["14549.90","1.274"],["51719.90","0.000"],["58184.90","0.002"],["62063.90","0.693"],["63637.10","0.005"],["63647.80","6.589"],["63701.70","2.232"],["63764.90","0.939"],["63809.50","2.740"],["64003.40","0.000"],["64121.90","4.827"],["64594.90","0.077"],["64607.50","0.012"],["64616.00","0.005"],["64633.00","0.061"]],"a":[["64656.60","0.002"],["64664.40","0.000"],["64664.50","0.048"],["64668.00","0.016"],["64677.10","0.039"],["64686.70","0.761"],["65296.50","0.032"],["65684.40","4.682"],["65776.40","8.198"],["67882.50","0.002"]],"st":1}}
{"stream":"btcusdt@depth@100ms","data":{"e":"depthUpdate","E":1784410650964,"T":1784410650963,"s":"BTCUSDT","ps":"BTCUSDT","U":11079103898399,"u":11079103905086,"pu":11079103898234,"b":[["14149.90","1.288"],["14249.90","1.064"],["14349.90","0.336"],["14549.90","1.512"],["58184.90","0.002"],["62063.90","0.690"],["63583.20","5.294"],["63712.50","16.298"],["63746.90","1.553"],["64003.40","0.000"],["64495.80","1.178"],["64594.90","0.063"],["64604.10","0.014"],["64621.50","3.468"],["64627.90","0.232"],["64632.40","10.004"],["64633.00","0.215"],["64634.40","0.087"]],"a":[["64650.00","1.997"],["64661.70","0.065"],["64683.20","0.026"],["64687.60","10.018"],["64692.70","0.047"],["64695.40","0.467"],["64802.20","0.047"],["65296.50","0.032"],["65425.80","18.191"],["65942.90","0.648"],["67882.50","0.000"]],"st":1}}
{"stream":"btcusdt@depth@100ms","data":{"e":"depthUpdate","E":1784410651066,"T":1784410651065,"s":"BTCUSDT","ps":"BTCUSDT","U":11079103905247,"u":11079103912907,"pu":11079103905086,"b":[["14149.90","1.050"],["14249.90","1.190"],["14349.90","0.210"],["14549.90","1.750"],["58184.90","0.002"],["63550.00","3.915"],["63604.80","0.002"],["63701.70","1.135"],["64003.40","0.000"],["64035.70","3.730"],["64132.70","2.026"],["64326.70","0.896"],["64463.70","0.047"],["64485.00","0.499"],["64495.80","1.884"],["64562.60","0.008"],["64585.30","0.132"],["64596.50","0.004"],["64598.70","21.141"],["64600.90","0.146"],["64601.00","0.006"],["64632.40","0.004"],["64633.00","0.215"],["64633.50","1.599"],["64633.90","0.006"],["64636.80","0.015"],["64637.40","0.558"],["64638.30","0.928"],["64638.60","0.622"],["64649.90","11.730"]],"a":[["64656.60","0.002"],["64661.70","0.018"],["64664.50","0.001"],["64664.80","0.050"],["64668.00","0.002"],["64670.40","1.021"],["64671.90","0.001"],["64676.20","0.031"],["64681.60","0.004"],["64691.60","0.002"],["64714.60","0.001"],["64802.20","1.126"],["65296.50","0.032"],["65644.60","27.546"]],"st":1}}
{"stream":"btcusdt@depth@100ms","data":{"e":"depthUpdate","E":1784410651168,"T":1784410651164,"s":"BTCUSDT","ps":"BTCUSDT","U":11079103912920,"u":11079103920905,"pu":11079103912907,"b":[["1000.00","50.241"],["14149.90","0.812"],["14249.90","1.302"],["14349.90","0.098"],["14549.90","1.988"],["58184.90","0.002"],["61417.40","0.008"],["61417.50","0.009"],["62063.90","0.693"],["63480.30","3.063"],["63647.80","7.686"],["63712.50","17.394"],["63744.80","12.819"],["63860.60","0.624"],["63892.90","1.047"],["63928.00","0.013"],["64003.40","0.000"],["64068.80","0.000"],["64132.70","2.022"],["64458.50","0.065"],["64598.70","0.002"],["64600.90","21.285"],["64637.40","0.001"],["64638.50","0.606"]],"a":[["64656.60","0.002"],["64660.80","0.160"],["64662.00","0.236"],["64670.40","0.095"],["64671.30","0.928"],["64681.60","0.081"],["65296.50","0.032"],["65445.00","2.613"],["65458.10","7.414"]],"st":1}}
{"stream":"btcusdt@depth@100ms","data":{"e":"depthUpdate","E":1784410651270,"T":1784410651269,"s":"BTCUSDT","ps":"BTCUSDT","U":11079103921233,"u":11079103928848,"pu":11079103920905,"b":[["14149.90","0.714"],["14249.90","1.372"],["14349.90","0.000"],["14449.90","0.112"],["14549.90","2.002"],["58184.90","0.002"],["62063.90","0.690"],["63917.80","0.781"],["64003.40","0.000"],["64614.20","0.012"],["64614.30","0.400"],["64614.40","0.018"],["64614.70","0.002"],["64614.80","0.006"],["64630.10","0.002"],["64630.20","0.053"],["64630.30","0.387"],["64633.00","0.061"],["64649.90","11.815"]],"a":[["64656.60","0.002"],["64657.40","0.093"],["64657.80","0.034"],["64658.00","0.168"],["64659.10","0.018"],["64681.60","0.004"],["64687.60","0.018"],["64688.60","0.000"],["64690.60","10.002"],["65296.50","0.032"],["65418.60","2.234"],["65568.00","0.551"]],"st":1}}
{"stream":"btcusdt@depth@100ms","data":{"e":"depthUpdate","E":1784410651372,"T":1784410651370,"s":"BTCUSDT","ps":"BTCUSDT","U":11079103928980,"u":11079103937020,"pu":11079103928848,"b":[["1000.00","50.241"],["14149.90","0.714"],["14249.90","1.260"],["14449.90","0.238"],["14549.90","1.988"],["51720.00","0.008"],["58184.90","0.002"],["62063.90","0.693"],["63453.90","1.023"],["63615.50","4.861"],["63712.50","18.491"],["63816.00","0.105"],["63860.60","0.234"],["63902.00","0.086"],["64003.40","0.000"],["64326.60","1.091"],["64326.70","0.789"],["64368.70","0.117"],["64478.70","0.003"],["64495.80","1.178"],["64633.00","0.215"],["64636.20","0.522"],["64649.90","11.773"]],"a":[["64656.60","0.002"],["64658.00","0.121"],["64658.20","0.007"],["64658.80","0.228"],["64668.70","0.160"],["64798.70","0.009"],["64802.20","0.047"],["64819.40","0.000"],["65296.50","0.032"],["65590.30","0.000"],["65619.70","0.342"],["67882.50","0.002"]],"st":1}}
{"stream":"btcusdt@depth@100ms","data":{"e":"depthUpdate","E":1784410651474,"T":1784410651473,"s":"BTCUSDT","ps":"BTCUSDT","U":11079103937166,"u":11079103943750,"pu":11079103937020,"b":[["1000.00","50.241"],["14149.90","0.714"],["14249.90","1.134"],["14449.90","0.350"],["14549.90","2.002"],["51720.00","0.008"],["58184.90","0.002"],["62063.90","0.690"],["63292.30","0.327"],["63465.30","0.786"],["63733.70","0.273"],["64003.40","0.000"],["64441.80","3.296"],["64478.70","0.741"],["64495.80","1.884"],["64518.80","3.884"],["64520.70","0.001"],["64521.50","1.367"],["64579.40","0.046"],["64579.80","0.025"],["64649.90","11.131"]],"a":[["64650.00","2.163"],["64656.60","0.589"],["64658.40","0.551"],["64659.90","0.309"],["64660.00","0.024"],["64660.30","0.002"],["64681.60","0.081"],["64721.70","0.049"],["64722.10","0.100"],["64774.60","0.000"],["64774.80","3.868"],["64802.20","1.126"],["64819.30","2.099"],["64854.70","1.403"],["64856.20","3.699"],["64973.30","0.772"],["65296.50","0.032"],["67882.50","0.002"]],"st":1}}
{"stream":"btcusdt@depth@100ms","data":{"e":"depthUpdate","E":1784410651576,"T":1784410651573,"s":"BTCUSDT","ps":"BTCUSDT","U":11079103943912,"u":11079103951452,"pu":11079103943750,"b":[["14149.90","0.714"],["14249.90","1.022"],["14449.90","0.476"],["14549.90","1.988"],["58184.90","0.002"],["63357.00","0.017"],["63841.80","5.562"],["64003.40","0.000"],["64458.50","0.061"],["64463.70","0.043"],["64535.90","0.000"],["64537.40","0.000"],["64538.90","0.004"],["64540.40","0.000"],["64541.90","0.000"],["64543.40","0.000"],["64544.90","0.000"],["64546.40","0.556"],["64547.90","0.000"],["64549.40","0.035"],["64550.90","0.022"],["64552.40","1.164"],["64604.10","0.000"],["64607.70","0.010"],["64621.50","3.159"],["64624.70","0.896"],["64627.10","1.319"],["64627.90","0.077"],["64628.50","0.003"],["64630.50","0.065"],["64633.00","0.061"],["64634.40","0.010"],["64636.10","0.569"],["64637.70","0.564"],["64638.50","0.056"],["64639.10","0.001"],["64640.00","1.060"],["64646.20","0.003"],["64646.70","0.016"],["64646.90","0.004"],["64647.10","0.002"],["64649.90","11.162"]],"a":[["64650.00","2.769"],["64650.10","0.006"],["64653.50","0.000"],["64653.60","0.000"],["64654.00","0.008"],["64654.20","0.000"],["64654.40","0.001"],["64654.60","0.003"],["64655.30","0.001"],["64655.60","0.085"],["64655.80","0.003"],["64656.00","0.008"],["64656.50","0.021"],["64656.60","0.002"],["64657.20","0.016"],["64658.40","0.010"],["64658.60","0.247"],["64659.10","0.004"],["64659.90","0.000"],["64660.00","0.565"],["64660.10","0.310"],["64678.20","0.774"],["64681.20","0.310"],["64681.60","0.004"],["64685.80","0.013"],["64686.10","2.052"],["64690.60","0.002"],["65107.00","0.524"],["65296.50","0.032"],["67882.50","0.000"]],"st":1}}
{"stream":"btcusdt@depth@100ms","data":{"e":"depthUpdate","E":1784410651678,"T":1784410651677,"s":"BTCUSDT","ps":"BTCUSDT","U":11079103951692,"u":11079103958850,"pu":11079103951452,"b":[["1000.00","50.241"],["14149.90","0.714"],["14249.90","0.896"],["14449.90","0.588"],["14549.90","2.002"],["58184.90","0.002"],["62063.90","0.693"],["63725.00","0.046"],["64003.40","0.000"],["64326.70","0.789"],["64458.50","0.061"],["64463.70","0.047"],["64495.80","1.178"],["64552.40","0.000"],["64617.10","0.001"],["64632.30","10.002"],["64633.00","0.215"],["64635.60","0.488"],["64636.40","0.195"],["64647.50","0.310"]],"a":[["64650.00","2.013"],["64658.40","0.551"],["64658.80","0.181"],["64659.20","0.234"],["64660.00","0.024"],["64802.20","0.047"],["65156.20","5.546"],["65170.00","5.128"],["65296.50","0.032"]],"st":1}}
{"stream":"btcusdt@depth@100ms","data":{"e":"depthUpdate","E":1784410651780,"T":1784410651776,"s":"BTCUSDT","ps":"BTCUSDT","U":11079103958961,"u":11079103965456,"pu":11079103958850,"b":[["1000.00","50.241"],["14149.90","0.714"],["14249.90","0.784"],["14449.90","0.714"],["14549.90","1.988"],["58184.90","0.002"],["62063.90","0.690"],["63357.00","0.020"],["63512.60","6.607"],["64003.40","0.000"],["64458.50","0.065"],["64495.80","1.872"],["64596.50","0.004"],["64598.70","0.002"],["64600.90","21.166"],["64632.30","0.002"],["64635.60","0.372"],["64636.50","0.117"],["64649.90","11.162"]],"a":[["64650.00","1.697"],["64659.20","0.234"],["64681.60","0.004"],["64686.10","0.052"],["64690.00","10.031"],["64802.20","1.126"],["65167.20","1.894"],["65260.30","0.230"],["65296.50","0.032"],["67882.50","0.002"]],"st":1}}
{"stream":"btcusdt@depth@100ms","data":{"e":"depthUpdate","E":1784410651882,"T":1784410651881,"s":"BTCUSDT","ps":"BTCUSDT","U":11079103965698,"u":11079103973163,"pu":11079103965456,"b":[["14149.90","0.742"],["14249.90","0.658"],["14449.90","0.854"],["14549.90","1.946"],["51719.90","0.000"],["58184.90","0.002"],["62063.90","0.693"],["63577.30","10.636"],["63841.80","5.952"],["63954.30","5.653"],["64003.40","0.000"],["64568.60","0.001"]],"a":[["64650.00","1.665"],["64650.10","0.016"],["64656.60","0.002"],["64658.30","0.610"],["64658.40","0.010"],["64660.00","0.024"],["64662.00","0.189"],["64664.80","0.003"],["64731.30","0.001"],["65296.50","0.032"],["65515.30","27.012"],["67882.50","0.000"]],"st":1}}
{"stream":"btcusdt@depth@100ms","data":{"e":"depthUpdate","E":1784410651984,"T":1784410651983,"s":"BTCUSDT","ps":"BTCUSDT","U":11079103973330,"u":11079103980119,"pu":11079103973163,"b":[["1000.00","50.241"],["14149.90","0.854"],["14249.90","0.546"],["14449.90","1.092"],["14549.90","1.708"],["58184.90","0.002"],["63033.70","0.079"],["63486.20","1.163"],["63706.90","1.215"],["63777.10","3.284"],["63798.90","0.009"],["63802.20","0.000"],["63853.20","0.782"],["64003.40","0.000"],["64039.20","0.000"],["64277.10","0.000"],["64326.70","0.789"],["64458.50","0.061"],["64515.90","0.354"],["64553.60","2.213"],["64568.60","0.000"],["64585.50","1.600"],["64607.20","1.047"],["64638.00","2.689"],["64639.80","1.254"],["64646.60","0.001"]],"a":[["64650.00","1.660"],["64650.10","0.020"],["64653.70","0.131"],["64657.30","0.697"],["64657.40","0.103"],["64657.50","0.063"],["64657.60","0.021"],["64658.30","0.069"],["64658.40","0.000"],["64658.60","0.093"],["64660.00","0.007"],["64665.70","0.473"],["64685.80","0.060"],["64688.00","1.813"],["64710.60","4.243"],["64731.30","0.000"],["64819.30","2.098"],["65059.20","0.888"],["65236.40","0.233"],["65296.50","0.032"],["65300.00","30.643"],["65414.80","2.245"],["65541.70","0.175"],["66007.60","0.312"]],"st":1}}
{"stream":"btcusdt@depth@100ms","data":{"e":"depthUpdate","E":1784410652086,"T":1784410652084,"s":"BTCUSDT","ps":"BTCUSDT","U":11079103980187,"u":11079103986992,"pu":11079103980119,"b":[["1000.00","50.241"],["14149.90","0.980"],["14249.90","0.420"],["14449.90","1.330"],["14549.90","1.470"],["58184.90","0.002"],["61417.40","0.028"],["62063.90","0.690"],["63557.20","0.000"],["63635.10","0.001"],["63731.90","4.777"],["63863.30","3.740"],["64003.40","0.000"],["64031.10","0.003"],["64268.90","0.002"],["64485.00","0.158"],["64507.60","0.002"],["64562.60","0.349"],["64633.00","0.215"],["64638.30","0.928"]],"a":[["64657.30","0.002"],["64657.40","0.093"],["64657.60","0.004"],["64658.60","0.798"],["64660.00","0.024"],["64681.60","0.081"],["64773.30","0.112"],["64811.00","0.001"],["65050.90","0.003"],["65291.60","0.003"],["65296.50","0.032"],["65490.50","1.750"],["65533.20","0.005"],["65664.70","0.000"],["65664.80","0.783"],["65859.00","2.576"],["67882.50","0.002"]],"st":1}}
{"stream":"btcusdt@depth@100ms","data":{"e":"depthUpdate","E":1784410652188,"T":1784410652187,"s":"BTCUSDT","ps":"BTCUSDT","U":11079103987071,"u":11079103993496,"pu":11079103986992,"b":[["14149.90","1.092"],["14249.90","0.308"],["14449.90","1.568"],["14549.90","1.232"],["58184.90","0.002"],["61417.40","0.026"],["61417.50","0.013"],["62063.90","0.693"],["63437.30","0.000"],["63635.10","0.024"],["63777.10","3.675"],["63794.10","3.120"],["64003.40","0.000"]],"a":[["64656.60","0.589"],["64742.90","0.831"],["64743.50","0.000"],["64755.10","14.293"],["65291.30","10.083"],["65296.50","0.034"],["65833.30","1.354"],["67882.50","0.002"]],"st":1}}
{"stream":"btcusdt@depth@100ms","data":{"e":"depthUpdate","E":1784410652290,"T":1784410652289,"s":"BTCUSDT","ps":"BTCUSDT","U":11079103993510,"u":11079104000657,"pu":11079103993496,"b":[["1000.00","50.241"],["14149.90","1.218"],["14249.90","0.182"],["14449.90","1.806"],["14549.90","0.994"],["51720.00","0.008"],["58184.90","0.002"],["62063.90","0.690"],["63712.50","19.588"],["64003.40","0.000"],["64121.90","0.623"],["64315.80","0.388"],["64326.70","0.789"],["64453.30","0.312"],["64495.80","1.894"],["64594.30","21.438"],["64600.90","0.146"],["64621.30","0.433"],["64627.80","0.162"],["64628.50","0.003"],["64630.50","0.034"],["64631.70","0.167"],["64631.90","0.081"],["64632.20","0.434"],["64634.20","0.048"],["64636.20","0.542"],["64637.70","0.007"],["64637.80","0.560"],["64638.40","0.399"],["64638.90","0.752"],["64639.10","0.001"],["64642.80","0.309"],["64643.30","0.377"],["64643.50","0.002"],["64645.70","0.003"],["64647.40","0.024"],["64647.60","0.000"],["64647.80","0.109"],["64647.90","0.061"],["64648.20","0.000"],["64648.30","0.001"]],"a":[["64650.00","2.736"],["64652.10","0.001"],["64652.20","0.002"],["64652.40","0.003"],["64652.50","0.000"],["64652.80","0.002"],["64653.00","0.000"],["64653.20","0.005"],["64653.40","0.324"],["64653.50","0.000"],["64655.10","0.635"],["64656.30","0.050"],["64656.50","0.021"],["64656.60","0.315"],["64657.60","0.317"],["64658.30","0.610"],["64658.40","0.000"],["64658.60","0.257"],["64660.00","0.024"],["64662.50","0.662"],["64663.70","0.000"],["64669.10","0.002"],["64669.20","0.048"],["64669.30","0.310"],["64670.50","1.006"],["64671.30","0.002"],["64671.90","0.001"],["64673.50","0.899"],["64674.40","3.655"],["64678.70","0.001"],["64679.30","0.564"],["64681.60","0.004"],["64685.50","2.019"],["64685.60","0.001"],["64685.70","0.121"],["64686.00","0.017"],["64686.10","0.050"],["64686.20","0.114"],["64688.00","0.388"],["64690.00","0.031"],["64802.10","1.079"],["64802.20","0.047"],["64962.30","0.100"],["65156.20","1.716"],["65296.50","0.032"],["65425.80","20.022"],["65458.10","7.672"],["65664.70","0.023"],["67882.50","0.000"]],"st":1}}
{"stream":"btcusdt@depth@100ms","data":{"e":"depthUpdate","E":1784410652392,"T":1784410652390,"s":"BTCUSDT","ps":"BTCUSDT","U":11079104000709,"u":11079104007425,"pu":11079104000657,"b":[["1000.00","50.241"],["14149.90","1.330"],["14249.90","0.070"],["14349.90","0.028"],["14449.90","1.988"],["14549.90","0.784"],["58184.90","0.002"],["61417.40","0.016"],["62063.90","0.693"],["63059.90","0.656"],["63583.80","0.000"],["63712.50","20.685"],["63874.10","19.491"],["64003.40","0.000"],["64594.30","0.418"],["64598.70","20.847"],["64633.00","0.061"],["64635.70","0.116"],["64636.20","0.542"],["64636.50","0.001"],["64637.60","1.001"],["64638.30","0.002"],["64643.30","0.064"],["64645.70","0.000"],["64647.40","0.027"]],"a":[["64652.20","0.589"],["64653.70","0.164"],["64655.10","0.361"],["64656.30","0.003"],["64656.40","0.855"],["64656.50","0.359"],["64656.80","0.032"],["64657.50","0.376"],["64657.80","0.081"],["64657.90","0.305"],["64658.30","0.069"],["64658.60","0.093"],["64659.90","0.000"],["64660.00","0.007"],["64668.70","0.160"],["64681.60","0.081"],["64973.30","0.770"],["65296.50","0.032"],["65408.30","1.749"],["65448.10","0.195"]],"st":1}}
{"stream":"btcusdt@depth@100ms","data":{"e":"depthUpdate","E":1784410652494,"T":1784410652493,"s":"BTCUSDT","ps":"BTCUSDT","U":11079104007493,"u":11079104015140,"pu":11079104007425,"b":[["14149.90","1.344"],["14249.90","0.000"],["14349.90","0.140"],["14449.90","2.002"],["14549.90","0.714"],["58184.90","0.002"],["61417.40","0.016"],["63742.20","10.407"],["63860.50","3.079"],["64003.40","0.000"],["64132.70","5.914"],["64326.60","1.093"],["64598.70","0.002"],["64600.90","20.991"],["64633.00","0.061"],["64639.80","3.314"],["64643.30","0.221"]],"a":[["64650.00","2.667"],["64652.20","0.002"],["64653.70","0.007"],["64655.10","0.048"],["64656.30","0.003"],["64656.40","0.001"],["64656.50","0.021"],["64656.60","0.589"],["64657.20","0.002"],["64657.50","0.063"],["64657.60","0.004"],["64657.80","0.034"],["64657.90","0.181"],["64658.40","0.705"],["64658.60","0.217"],["64658.70","1.441"],["64658.90","0.016"],["64659.40","0.000"],["64660.00","0.024"],["64660.50","0.050"],["64681.60","0.004"],["64973.30","0.924"],["65167.20","5.724"],["65264.20","2.064"],["65296.50","0.032"],["65480.40","0.380"]],"st":1}}
{"stream":"btcusdt@depth@100ms","data":{"e":"depthUpdate","E":1784410652596,"T":1784410652595,"s":"BTCUSDT","ps":"BTCUSDT","U":11079104015249,"u":11079104022290,"pu":11079104015140,"b":[["1000.00","50.241"],["14149.90","1.232"],["14349.90","0.266"],["14449.90","1.988"],["14549.90","0.714"],["58184.90","0.002"],["62063.90","0.690"],["63357.00","0.023"],["63738.30","1.254"],["64003.40","0.000"],["64132.70","6.225"],["64326.70","0.944"],["64633.00","0.215"],["64643.30","0.064"]],"a":[["64656.40","0.542"],["64656.50","0.192"],["64656.60","0.002"],["64658.20","0.131"],["64658.40","0.000"],["64658.60","0.093"],["64660.00","0.017"],["64681.60","0.081"],["65296.50","0.034"],["65419.30","4.583"]],"st":1}}
{"stream":"btcusdt@depth@100ms","data":{"e":"depthUpdate","E":1784410652698,"T":1784410652697,"s":"BTCUSDT","ps":"BTCUSDT","U":11079104022297,"u":11079104029174,"pu":11079104022290,"b":[["1000.00","50.241"],["14149.90","1.106"],["14349.90","0.378"],["14449.90","2.002"],["14549.90","0.714"],["58184.90","0.002"],["62063.90","0.693"],["63649.10","4.235"],["63675.60","0.000"],["63744.80","15.169"],["63970.60","0.003"],["63971.80","2.573"],["64003.40","0.000"],["64495.80","1.178"],["64643.30","0.064"],["64649.90","11.162"]],"a":[["64650.00","2.664"],["64651.90","0.007"],["64656.30","0.003"],["64656.40","0.001"],["64656.50","0.743"],["64656.60","0.002"],["64658.60","0.093"],["64660.00","0.007"],["64677.70","0.560"],["64679.30","0.008"],["64681.60","0.004"],["64802.10","0.000"],["65296.50","0.032"],["65414.80","1.787"],["65427.70","2.237"],["65749.10","1.062"]],"st":1}}
{"stream":"btcusdt@depth@100ms","data":{"e":"depthUpdate","E":1784410652800,"T":1784410652799,"s":"BTCUSDT","ps":"BTCUSDT","U":11079104029296,"u":11079104035729,"pu":11079104029174,"b":[["14149.90","0.994"],["14349.90","0.504"],["14449.90","1.988"],["14549.90","0.714"],["58184.90","0.002"],["61417.50","0.011"],["62063.90","0.690"],["62962.80","0.000"],["63357.00","0.026"],["63824.90","5.472"],["63841.80","6.217"],["63863.30","3.114"],["63945.20","5.538"],["64003.40","0.000"],["64042.20","1.313"],["64326.70","0.944"],["64643.30","0.064"],["64649.90","11.160"]],"a":[["64653.90","0.050"],["64656.50","0.021"],["64656.60","0.002"],["64658.60","0.788"],["64660.00","0.034"],["65296.50","0.032"],["65543.10","0.841"]],"st":1}}
{"stream":"btcusdt@depth@100ms","data":{"e":"depthUpdate","E":1784410652902,"T":1784410652901,"s":"BTCUSDT","ps":"BTCUSDT","U":11079104035831,"u":11079104042357,"pu":11079104035729,"b":[["1000.00","50.241"],["14149.90","0.868"],["14349.90","0.616"],["14449.90","2.002"],["14549.90","0.714"],["51719.90","0.000"],["58184.90","0.002"],["62063.90","0.693"],["63590.20","1.799"],["63764.90","0.000"],["63874.10","19.757"],["63938.20","0.390"],["64003.40","0.001"],["64441.80","0.027"],["64478.70","0.003"],["64553.50","0.007"],["64553.80","5.856"],["64556.40","1.213"],["64601.00","3.441"],["64633.00","0.061"]],"a":[["64650.00","1.908"],["64653.90","0.003"],["64655.30","0.001"],["64656.30","0.013"],["64656.40","0.713"],["64656.50","0.021"],["64656.60","0.002"],["64657.60","0.004"],["64658.10","0.400"],["64658.20","0.007"],["64658.40","0.000"],["64658.60","0.093"],["64660.00","0.007"],["64662.50","0.353"],["64662.90","0.344"],["64742.90","0.000"],["64744.90","0.472"],["64746.20","3.504"],["64819.30","1.154"],["64840.70","0.091"],["64854.70","0.911"],["64856.20","0.000"],["64886.00","2.288"],["65296.50","0.032"],["65382.10","1.528"],["65425.80","21.549"]],"st":1}}
{"stream":"btcusdt@depth@100ms","data":{"e":"depthUpdate","E":1784410653004,"T":1784410653003,"s":"BTCUSDT","ps":"BTCUSDT","U":11079104042442,"u":11079104049631,"pu":11079104042357,"b":[["1000.00","50.241"],["14149.90","0.756"],["14349.90","0.742"],["14449.90","1.988"],["14549.90","0.714"],["58184.90","0.002"],["62904.40","0.953"],["63227.60","0.001"],["63726.10","9.409"],["63788.50","0.783"],["64003.40","0.003"],["64368.70","0.000"],["64371.90","0.117"],["64441.80","3.392"],["64463.70","0.043"],["64478.60","0.753"],["64495.80","1.895"],["64630.50","0.065"],["64631.70","0.165"],["64631.90","0.001"],["64632.40","0.006"],["64633.00","0.215"],["64633.60","0.005"],["64636.90","0.631"],["64637.80","0.003"],["64638.10","0.543"],["64638.40","0.479"],["64639.00","0.066"],["64646.50","0.157"]],"a":[["64650.00","1.737"],["64653.40","0.014"],["64653.70","0.131"],["64656.30","0.003"],["64656.40","0.001"],["64656.50","0.031"],["64656.60","0.002"],["64658.10","0.276"],["64658.40","0.558"],["64658.60","0.247"],["64658.70","1.394"],["64659.00","0.002"],["64659.40","0.000"],["64660.00","0.007"],["64661.60","0.001"],["64665.30","0.000"],["64665.50","0.084"],["64665.60","0.053"],["64665.70","0.426"],["64673.50","0.897"],["64674.00","0.004"],["64677.70","0.003"],["64678.30","0.558"],["64681.60","0.081"],["64683.20","0.001"],["64685.50","0.019"],["64688.60","0.047"],["64691.50","2.709"],["64691.80","10.154"],["64691.90","0.083"],["64802.10","1.012"],["64819.30","2.023"],["64840.70","0.208"],["64854.70","1.358"],["64856.10","3.397"],["65296.50","0.032"],["65425.80","21.808"],["65477.40","0.517"],["65771.40","0.759"]],"st":1}}
{"stream":"btcusdt@depth@100ms","data":{"e":"depthUpdate","E":1784410653106,"T":1784410653105,"s":"BTCUSDT","ps":"BTCUSDT","U":11079104049672,"u":11079104057208,"pu":11079104049631,"b":[["14149.90","0.630"],["14349.90","0.910"],["14449.90","1.890"],["14549.90","0.770"],["58184.90","0.002"],["61417.50","0.009"],["62063.90","0.690"],["63227.60","0.000"],["63777.80","10.236"],["63874.10","20.382"],["64003.40","0.001"],["64326.70","0.944"],["64633.00","0.061"],["64636.90","0.074"],["64638.10","0.002"],["64638.20","0.605"],["64638.30","0.002"],["64639.90","0.558"],["64646.20","0.001"],["64647.10","0.004"],["64649.90","11.193"]],"a":[["64650.00","1.587"],["64656.40","0.001"],["64656.50","0.021"],["64656.60","0.002"],["64658.40","0.000"],["64658.60","0.093"],["64660.00","0.729"],["64681.60","0.004"],["65296.50","0.032"],["65568.00","0.817"],["65942.90","0.645"]],"st":1}}
{"stream":"btcusdt@depth@100ms","data":{"e":"depthUpdate","E":1784410653208,"T":1784410653207,"s":"BTCUSDT","ps":"BTCUSDT","U":11079104057294,"u":11079104064086,"pu":11079104057208,"b":[["1000.00","50.241"],["14149.90","0.518"],["14349.90","1.148"],["14449.90","1.652"],["14549.90","0.882"],["58184.90","0.002"],["62063.90","0.693"],["63708.20","0.094"],["63841.80","6.607"],["64003.40","0.001"],["64349.90","0.051"],["64627.10","1.359"],["64633.00","0.215"],["64636.10","0.529"],["64637.60","0.075"],["64639.40","1.167"],["64649.90","12.372"]],"a":[["64656.40","0.542"],["64656.50","0.021"],["64656.60","0.183"],["64658.40","0.000"],["64658.60","0.093"],["64660.00","0.007"],["64661.30","0.001"],["64661.50","0.388"],["64661.70","0.018"],["64661.90","0.359"],["64663.60","0.001"],["64668.70","0.005"],["64669.60","0.000"],["64670.50","0.080"],["64671.00","0.543"],["64671.10","0.373"],["64671.90","0.927"],["64675.10","0.002"],["64678.20","0.717"],["64678.30","0.002"],["64679.30","0.564"],["64679.80","0.120"],["65296.50","0.032"]],"st":1}}
{"stream":"btcusdt@depth@100ms","data":{"e":"depthUpdate","E":1784410653310,"T":1784410653309,"s":"BTCUSDT","ps":"BTCUSDT","U":11079104064176,"u":11079104070346,"pu":11079104064086,"b":[["1000.00","50.241"],["14149.90","0.392"],["14349.90","1.386"],["14449.90","1.414"],["14549.90","1.008"],["51720.00","0.008"],["58184.90","0.002"],["62063.90","0.690"],["63699.50","0.549"],["63908.50","0.000"],["64003.40","0.001"],["64062.40","10.715"],["64320.00","0.443"],["64400.00","28.277"],["64421.30","0.828"],["64480.00","4.367"],["64560.00","1.150"],["64621.50","3.468"],["64627.90","0.232"],["64633.00","0.215"],["64634.40","0.087"],["64638.50","0.982"],["64639.00","0.607"],["64639.40","0.241"],["64639.90","0.017"],["64640.00","0.873"],["64649.90","12.373"]],"a":[["64650.00","1.902"],["64654.70","0.077"],["64656.40","0.155"],["64656.50","0.048"],["64656.60","0.002"],["64658.60","0.093"],["64660.00","0.548"],["64661.20","0.155"],["64661.90","0.312"],["64662.10","0.004"],["64662.30","24.234"],["64662.50","0.353"],["64662.80","0.002"],["64667.70","0.431"],["64669.60","0.541"],["64671.00","0.002"],["64671.80","0.047"],["64720.00","0.382"],["64800.00","18.466"],["64880.00","9.538"],["64960.00","2.259"],["65040.00","0.380"],["65296.50","0.032"],["65749.10","1.441"]],"st":1}}
{"stream":"btcusdt@depth@100ms","data":{"e":"depthUpdate","E":1784410653412,"T":1784410653411,"s":"BTCUSDT","ps":"BTCUSDT","U":11079104070443,"u":11079104076857,"pu":11079104070346,"b":[["14149.90","0.280"],["14349.90","1.624"],["14449.90","1.176"],["14549.90","1.120"],["51720.00","0.010"],["58184.90","0.002"],["61417.40","0.018"],["63751.30","2.474"],["63817.60","1.212"],["64003.40","0.003"],["64297.30","0.018"],["64326.60","1.091"],["64326.70","0.944"],["64485.00","0.002"],["64488.30","0.193"],["64495.80","1.889"],["64535.90","0.000"],["64537.00","0.000"],["64537.40","0.000"],["64537.50","0.909"],["64538.90","0.004"],["64540.40","0.000"],["64541.90","0.000"],["64543.40","0.000"],["64544.90","0.000"],["64546.40","0.556"],["64547.90","1.276"],["64607.70","0.010"],["64627.90","0.077"],["64631.80","0.015"],["64632.40","0.004"],["64633.00","0.061"],["64634.40","0.010"],["64635.70","0.000"],["64636.20","0.542"],["64637.10","0.293"],["64640.70","0.626"],["64649.90","11.905"]],"a":[["64650.00","2.048"],["64653.40","0.324"],["64656.40","0.001"],["64656.50","0.021"],["64656.60","0.002"],["64656.70","1.276"],["64657.10","0.081"],["64658.40","0.000"],["64658.60","0.093"],["64660.00","0.729"],["64668.70","0.005"],["64687.60","2.018"],["64691.50","1.138"],["64691.80","0.154"],["64802.10","1.012"],["65296.50","0.032"]],"st":1}}
{"stream":"btcusdt@depth@100ms","data":{"e":"depthUpdate","E":1784410653514,"T":1784410653513,"s":"BTCUSDT","ps":"BTCUSDT","U":11079104076939,"u":11079104084289,"pu":11079104076857,"b":[["1000.00","50.241"],["14149.90","0.154"],["14349.90","1.862"],["14449.90","0.938"],["14549.90","1.246"],["51720.00","0.008"],["58184.90","0.002"],["62063.90","0.693"],["64003.40","0.001"],["64320.00","0.630"],["64400.00","28.464"],["64480.00","4.554"],["64485.00","0.158"],["64537.50","0.037"],["64547.90","0.000"],["64560.00","1.337"],["64562.60","0.008"],["64564.50","0.006"],["64596.50","0.004"],["64598.70","20.688"],["64600.90","0.146"],["64601.00","0.006"],["64629.40","0.002"],["64630.00","10.040"],["64630.10","1.855"],["64630.80","0.194"],["64633.00","0.061"],["64636.50","0.117"],["64637.10","0.734"],["64637.40","0.927"],["64638.20","0.048"],["64638.50","0.056"],["64640.00","1.060"],["64649.90","11.904"]],"a":[["64653.40","0.014"],["64656.50","0.021"],["64656.60","0.002"],["64657.10","0.034"],["64658.40","0.000"],["64658.60","0.093"],["64660.00","0.729"],["64662.80","0.049"],["64669.80","0.931"],["64671.90","0.001"],["64720.00","0.569"],["64800.00","18.653"],["64880.00","9.725"],["64960.00","2.446"],["64973.30","0.926"],["65040.00","0.567"],["65296.50","0.032"],["65480.40","0.000"]],"st":1}}
{"stream":"btcusdt@depth@100ms","data":{"e":"depthUpdate","E":1784410653616,"T":1784410653613,"s":"BTCUSDT","ps":"BTCUSDT","U":11079104084402,"u":11079104091506,"pu":11079104084289,"b":[["1000.00","50.241"],["14149.90","0.042"],["14249.90","0.056"],["14349.90","1.988"],["14449.90","0.756"],["14549.90","1.358"],["58184.90","0.002"],["62063.90","0.690"],["64003.40","0.001"],["64035.70","4.353"],["64421.30","0.833"],["64562.60","0.349"],["64633.00","0.215"],["64635.90","0.233"],["64636.50","0.001"]],"a":[["64650.00","1.584"],["64656.50","0.743"],["64656.60","0.002"],["64658.60","0.093"],["64660.00","0.007"],["64662.80","0.049"],["64669.80","0.005"],["64670.90","0.926"],["64681.60","0.081"],["65296.50","0.032"],["65771.40","0.380"]],"st":1}}
{"stream":"btcusdt@depth@100ms","data":{"e":"depthUpdate","E":1784410653718,"T":1784410653717,"s":"BTCUSDT","ps":"BTCUSDT","U":11079104091695,"u":11079104098358,"pu":11079104091506,"b":[["14149.90","0.000"],["14249.90","0.168"],["14349.90","2.002"],["14449.90","0.714"],["14549.90","1.316"],["58184.90","0.002"],["62063.90","0.693"],["63550.90","1.334"],["63917.80","1.562"],["64003.40","0.001"],["64297.30","0.023"],["64326.70","0.934"],["64349.90","0.051"],["64564.50","0.002"],["64567.10","0.017"],["64640.80","0.275"],["64641.80","0.001"],["64643.40","1.319"],["64645.20","0.435"],["64645.30","0.645"]],"a":[["64656.40","0.001"],["64656.50","0.021"],["64656.60","0.002"],["64658.60","0.093"],["64660.00","0.007"],["64660.10","0.723"],["64672.50","0.405"],["65296.50","0.032"],["65500.00","98.324"],["65942.90","0.642"]],"st":1}}
{"stream":"btcusdt@depth@100ms","data":{"e":"depthUpdate","E":1784410653820,"T":1784410653819,"s":"BTCUSDT","ps":"BTCUSDT","U":11079104098561,"u":11079104104444,"pu":11079104098358,"b":[["1000.00","50.241"],["14249.90","0.294"],["14349.90","1.988"],["14449.90","0.714"],["14549.90","1.204"],["51720.00","0.008"],["58184.90","0.002"],["61417.50","0.007"],["62063.90","0.690"],["63529.90","0.785"],["64003.40","0.001"],["64495.80","1.178"],["64553.80","0.000"],["64556.40","0.326"],["64633.00","0.061"]],"a":[["64650.00","1.585"],["64656.40","0.001"],["64656.50","0.021"],["64656.60","0.002"],["64660.10","0.723"],["64669.10","0.004"],["64669.20","0.050"],["64669.30","0.312"],["64681.60","0.004"],["64685.50","0.021"],["64685.60","0.003"],["64685.70","0.123"],["64686.00","0.019"],["64686.10","0.052"],["64686.20","0.116"],["64746.20","0.000"],["64802.10","1.072"],["65296.50","0.032"],["65589.40","0.092"],["65749.10","1.820"],["65771.40","0.001"],["65942.90","0.645"],["67882.50","0.002"]],"st":1}}
{"stream":"btcusdt@depth@100ms","data":{"e":"depthUpdate","E":1784410653922,"T":1784410653921,"s":"BTCUSDT","ps":"BTCUSDT","U":11079104104446,"u":11079104110724,"pu":11079104104444,"b":[["1000.00","50.241"],["14249.90","0.406"],["14349.90","2.002"],["14449.90","0.714"],["14549.90","1.078"],["51719.90","0.000"],["58184.90","0.002"],["63357.00","0.020"],["63408.10","0.156"],["63860.60","0.000"],["63869.80","0.001"],["64003.40","0.000"],["64371.90","0.000"],["64375.10","0.117"],["64495.80","1.895"],["64553.80","6.024"],["64556.40","1.238"],["64598.80","3.192"],["64633.00","0.215"]],"a":[["64656.40","0.696"],["64656.50","0.048"],["64656.60","0.002"],["64657.60","0.004"],["64658.50","0.227"],["64658.60","0.093"],["64660.10","0.001"],["64688.60","0.000"],["64746.00","0.972"],["64746.10","3.489"],["64746.60","0.003"],["64886.00","2.171"],["65296.50","0.034"],["65425.80","22.067"],["65587.40","15.530"],["67882.50","0.002"]],"st":1}}
{"stream":"btcusdt@depth@100ms","data":{"e":"depthUpdate","E":1784410654024,"T":1784410654021,"s":"BTCUSDT","ps":"BTCUSDT","U":11079104110780,"u":11079104117351,"pu":11079104110724,"b":[["14249.90","0.532"],["14349.90","1.988"],["14449.90","0.714"],["14549.90","0.966"],["58184.90","0.002"],["62063.90","0.693"],["64003.40","0.000"],["64326.70","0.944"],["64635.90","0.117"],["64637.20","0.398"]],"a":[["64650.00","1.580"],["64656.40","0.696"],["64656.50","0.048"],["64656.60","0.589"],["64658.50","0.180"],["64660.10","0.001"],["64662.80","0.002"],["64681.60","0.081"],["65085.40","0.009"],["65296.50","0.032"],["65548.00","4.015"],["65749.10","2.199"],["67882.50","0.000"]],"st":1}}
{"stream":"btcusdt@depth@100ms","data":{"e":"depthUpdate","E":1784410654126,"T":1784410654125,"s":"BTCUSDT","ps":"BTCUSDT","U":11079104117567,"u":11079104124010,"pu":11079104117351,"b":[["1000.00","50.241"],["14249.90","0.644"],["14349.90","2.002"],["14449.90","0.714"],["14549.90","0.840"],["58184.90","0.002"],["61417.40","0.016"],["61417.50","0.011"],["62063.90","0.690"],["63557.30","1.102"],["64003.40","0.000"],["64633.00","0.061"],["64636.30","0.586"],["64637.10","0.177"],["64637.20","0.282"],["64637.40","0.001"],["64638.30","0.559"],["64638.70","1.555"],["64639.00","0.066"],["64639.10","0.001"],["64639.60","0.005"],["64639.90","0.558"],["64640.80","0.275"],["64649.90","11.909"]],"a":[["64656.30","0.590"],["64656.40","0.001"],["64656.50","0.021"],["64656.60","0.002"],["64659.60","0.003"],["64659.80","0.000"],["64660.00","0.007"],["64660.10","0.723"],["64662.80","0.049"],["64669.60","0.541"],["64670.80","0.081"],["64670.90","0.000"],["64671.90","0.001"],["64672.00","2.427"],["64681.60","0.004"],["65162.30","0.005"],["65296.50","0.032"]],"st":1}}
{"stream":"btcusdt@depth@100ms","data":{"e":"depthUpdate","E":1784410654228,"T":1784410654226,"s":"BTCUSDT","ps":"BTCUSDT","U":11079104124113,"u":11079104130268,"pu":11079104124010,"b":[["1000.00","50.241"],["14249.90","0.770"],["14349.90","1.988"],["14449.90","0.714"],["14549.90","0.728"],["58184.90","0.002"],["62063.90","0.693"],["63033.60","0.634"],["63841.80","6.842"],["63880.60","3.752"],["63942.90","0.000"],["64003.40","0.000"],["64349.90","0.051"],["64633.00","0.215"]],"a":[["64656.30","0.003"],["64656.40","0.742"],["64656.50","0.038"],["64656.60","0.002"],["64660.10","0.552"],["65296.50","0.032"],["65458.10","7.900"]],"st":1}}
{"stream":"btcusdt@depth@100ms","data":{"e":"depthUpdate","E":1784410654330,"T":1784410654329,"s":"BTCUSDT","ps":"BTCUSDT","U":11079104130431,"u":11079104137044,"pu":11079104130268,"b":[["14249.90","0.966"],["14349.90","1.834"],["14449.90","0.798"],["14549.90","0.602"],["58184.90","0.002"],["62063.90","0.690"],["63706.10","0.000"],["63943.60","0.002"],["64003.40","0.000"],["64326.70","0.944"],["64495.80","1.178"],["64567.10","0.013"],["64627.90","0.232"],["64634.40","0.087"]],"a":[["64650.00","1.582"],["64656.40","0.001"],["64656.50","0.038"],["64656.60","0.589"],["64660.00","0.161"],["64660.10","0.552"],["64802.10","0.000"],["65296.50","0.032"],["65550.00","8.481"]],"st":1}}
{"stream":"btcusdt@depth@100ms","data":{"e":"depthUpdate","E":1784410654432,"T":1784410654431,"s":"BTCUSDT","ps":"BTCUSDT","U":11079104137151,"u":11079104142940,"pu":11079104137044,"b":[["1000.00","50.241"],["14249.90","1.204"],["14349.90","1.596"],["14449.90","0.910"],["14549.90","0.490"],["51720.00","0.008"],["58184.90","0.002"],["63788.50","1.566"],["63920.10","2.735"],["64003.40","0.000"],["64270.20","0.000"],["64270.30","1.503"],["64366.70","0.024"],["64366.80","0.148"],["64437.60","0.002"],["64438.40","0.232"],["64478.60","0.002"],["64536.00","0.001"],["64537.30","2.347"],["64636.20","0.542"]],"a":[["64650.00","1.583"],["64656.40","0.001"],["64656.50","0.021"],["64656.60","0.002"],["64660.00","0.007"],["64660.10","0.723"],["64662.30","24.281"],["64662.80","0.002"],["64668.70","0.005"],["64754.30","2.333"],["64755.50","0.202"],["64756.20","0.325"],["64819.30","1.154"],["64840.70","0.091"],["64841.90","6.816"],["64843.00","0.017"],["64886.00","2.288"],["64913.90","0.075"],["64914.30","0.003"],["65011.40","0.639"],["65011.70","0.000"],["65167.20","6.643"],["65296.50","0.032"],["65806.80","2.179"]],"st":1}}
{"stream":"btcusdt@depth@100ms","data":{"e":"depthUpdate","E":1784410654534,"T":1784410654533,"s":"BTCUSDT","ps":"BTCUSDT","U":11079104143015,"u":11079104149762,"pu":11079104142940,"b":[["1000.00","50.241"],["14249.90","1.442"],["14349.90","1.358"],["14449.90","1.036"],["14549.90","0.364"],["58184.90","0.002"],["62063.90","0.693"],["63480.30","2.042"],["63678.20","1.364"],["64003.40","0.000"],["64441.80","0.027"],["64449.90","0.000"],["64485.00","0.158"],["64488.30","0.037"],["64562.60","0.008"],["64634.30","2.366"],["64649.90","11.940"]],"a":[["64656.40","0.001"],["64656.50","0.743"],["64656.60","0.589"],["64660.10","0.001"],["64726.30","0.331"],["64854.70","0.911"],["64856.10","0.000"],["64973.30","0.924"],["65296.50","0.032"],["65425.80","22.525"],["65522.80","2.587"]],"st":1}}
{"stream":"btcusdt@depth@100ms","data":{"e":"depthUpdate","E":1784410654636,"T":1784410654633,"s":"BTCUSDT","ps":"BTCUSDT","U":11079104149840,"u":11079104155112,"pu":11079104149762,"b":[["14249.90","1.680"],["14349.90","1.120"],["14449.90","1.148"],["14549.90","0.252"],["58184.90","0.002"],["62063.90","0.690"],["63563.80","1.099"],["63869.40","1.203"],["63893.50","1.641"],["64003.40","0.000"],["64007.00","1.248"],["64127.90","0.311"],["64154.50","0.003"],["64250.20","4.321"],["64264.10","9.072"],["64270.30","0.639"],["64326.60","1.093"],["64326.70","0.944"],["64446.30","0.160"],["64485.00","0.499"]],"a":[["64656.40","0.001"],["64656.50","0.021"],["64656.60","0.002"],["64660.10","0.723"],["65128.70","0.000"],["65278.50","0.000"],["65296.50","0.032"],["65458.10","8.129"],["65806.80","1.421"]],"st":1}}
{"stream":"btcusdt@depth@100ms","data":{"e":"depthUpdate","E":1784410654738,"T":1784410654737,"s":"BTCUSDT","ps":"BTCUSDT","U":11079104155281,"u":11079104160843,"pu":11079104155112,"b":[["1000.00","50.241"],["14249.90","1.918"],["14349.90","0.882"],["14449.90","1.274"],["14549.90","0.126"],["58184.90","0.002"],["62063.90","0.693"],["63453.90","2.045"],["63641.40","0.000"],["63738.30","2.193"],["63814.80","0.001"],["63874.10","22.258"],["64003.40","0.000"],["64132.70","7.159"],["64349.90","0.051"],["64375.10","0.000"],["64557.60","0.001"],["64560.00","1.341"],["64633.00","0.061"],["64647.40","0.004"]],"a":[["64656.50","0.736"],["64656.60","0.002"],["64660.10","0.008"],["64669.60","0.541"],["64671.90","0.001"],["64681.60","0.081"],["65296.50","0.032"],["65414.50","0.764"],["65474.40","0.578"],["65647.60","0.000"],["65967.50","0.653"]],"st":1}}
{"stream":"btcusdt@depth@100ms","data":{"e":"depthUpdate","E":1784410654840,"T":1784410654837,"s":"BTCUSDT","ps":"BTCUSDT","U":11079104160891,"u":11079104167271,"pu":11079104160843,"b":[["1000.00","50.241"],["14149.90","0.084"],["14249.90","1.988"],["14349.90","0.728"],["14449.90","1.386"],["14549.90","0.014"],["58184.90","0.002"],["63357.00","0.017"],["63860.50","2.845"],["64003.40","0.000"],["64067.90","1.091"],["64091.50","0.000"],["64326.70","1.061"],["64441.80","3.364"],["64478.60","0.719"],["64495.70","0.712"],["64633.00","0.215"]],"a":[["64656.40","0.001"],["64656.50","0.021"],["64660.10","0.723"],["64681.60","0.004"],["64802.10","1.043"],["64819.20","0.936"],["64856.10","3.710"],["65296.50","0.032"],["65550.00","7.720"],["65574.40","0.762"]],"st":1}}
{"stream":"btcusdt@depth@100ms","data":{"e":"depthUpdate","E":1784410654942,"T":1784410654941,"s":"BTCUSDT","ps":"BTCUSDT","U":11079104167501,"u":11079104173268,"pu":11079104167271,"b":[["14149.90","0.196"],["14249.90","2.002"],["14349.90","0.714"],["14449.90","1.288"],["14549.90","0.000"],["51719.90","0.000"],["58184.90","0.002"],["62063.90","0.690"],["63613.60","1.417"],["63736.60","6.937"],["63875.80","0.000"],["64003.40","0.000"],["64326.70","1.061"],["64540.40","0.202"],["64564.50","0.006"],["64630.00","0.040"],["64630.10","0.385"],["64633.00","0.061"]],"a":[["64650.00","1.578"],["64656.60","0.589"],["64742.90","0.356"],["64854.70","1.405"],["65296.50","0.032"],["65419.30","5.499"],["65548.00","3.253"],["65621.70","1.324"]],"st":1}}
{"stream":"btcusdt@depth@100ms","data":{"e":"depthUpdate","E":1784410655044,"T":1784410655042,"s":"BTCUSDT","ps":"BTCUSDT","U":11079104173368,"u":11079104179582,"pu":11079104173268,"b":[["1000.00","50.241"],["14149.90","0.322"],["14249.90","1.988"],["14349.90","0.714"],["14449.90","1.176"],["51720.00","0.008"],["58184.90","0.002"],["62063.90","0.693"],["63606.10","0.002"],["63615.50","5.960"],["63809.50","3.053"],["63906.40","7.503"],["64003.40","0.000"],["64449.90","0.000"],["64598.70","0.002"],["64598.80","0.000"],["64600.90","20.820"],["64601.00","3.416"],["64633.00","0.215"],["64638.30","0.564"]],"a":[["64656.40","0.001"],["64656.50","0.021"],["64656.60","0.589"],["64658.70","1.394"],["64658.90","0.016"],["64659.10","0.051"],["64660.00","0.017"],["64660.10","0.713"],["64669.60","0.000"],["64671.90","0.542"],["64681.30","1.159"],["64681.60","0.004"],["65296.50","0.032"],["65420.90","3.358"],["65577.70","1.818"],["65587.40","16.596"],["65674.60","2.967"]],"st":1}}
{"stream":"btcusdt@depth@100ms","data":{"e":"depthUpdate","E":1784410655146,"T":1784410655145,"s":"BTCUSDT","ps":"BTCUSDT","U":11079104179717,"u":11079104185943,"pu":11079104179582,"b":[["1000.00","50.241"],["14149.90","0.434"],["14249.90","2.002"],["14349.90","0.714"],["14449.90","1.050"],["51720.00","0.004"],["58184.90","0.000"],["61417.50","0.009"],["62063.90","0.690"],["63876.10","0.000"],["64003.40","0.000"],["64028.40","0.000"],["64517.30","0.049"],["64518.00","3.867"],["64518.10","1.117"],["64518.80","0.017"],["64521.50","0.890"],["64579.30","0.046"],["64579.40","0.000"],["64633.00","0.061"],["64636.30","0.470"],["64637.40","0.558"],["64637.90","1.108"],["64638.30","0.002"],["64638.70","0.629"],["64639.00","0.607"],["64639.90","0.017"],["64649.90","12.330"]],"a":[["64650.00","1.676"],["64654.70","0.000"],["64656.40","0.742"],["64656.50","0.048"],["64656.60","0.002"],["64658.30","0.056"],["64659.10","0.004"],["64659.40","0.000"],["64660.00","0.007"],["64660.10","0.542"],["64661.20","0.000"],["64662.30","24.234"],["64665.60","0.006"],["64665.70","0.473"],["64669.60","0.541"],["64670.30","0.927"],["64671.90","0.001"],["64672.00","1.501"],["64688.60","0.047"],["64721.70","0.049"],["64773.40","0.000"],["64774.80","0.001"],["64775.30","3.867"],["64778.10","0.036"],["65296.50","0.032"],["65325.30","0.000"],["65522.80","3.348"],["65588.80","3.367"],["65684.40","5.746"],["65942.90","0.648"]],"st":1}}
{"stream":"btcusdt@depth@100ms","data":{"e":"depthUpdate","E":1784410655248,"T":1784410655246,"s":"BTCUSDT","ps":"BTCUSDT","U":11079104185951,"u":11079104195669,"pu":11079104185943,"b":[["14149.90","0.560"],["14249.90","1.988"],["14349.90","0.714"],["14449.90","0.938"],["51720.00","0.004"],["58184.90","0.002"],["62063.90","0.693"],["63880.60","4.690"],["64003.40","0.000"],["64326.70","1.061"],["64349.90","0.051"],["64449.90","0.000"],["64599.70","0.001"],["64606.30","0.401"],["64609.20","0.019"],["64612.90","0.130"],["64616.80","0.003"],["64617.30","0.306"],["64619.40","0.098"],["64630.40","0.007"],["64633.00","0.215"],["64636.20","0.522"],["64637.30","0.255"],["64637.90","0.992"],["64643.60","0.023"],["64647.50","0.333"]],"a":[["64656.40","0.001"],["64656.50","0.743"],["64656.60","0.589"],["64658.60","0.093"],["64660.00","0.007"],["64660.10","0.001"],["64662.90","0.344"],["64670.30","0.001"],["64671.20","0.949"],["64681.60","0.004"],["64707.70","0.730"],["64709.70","0.000"],["64719.20","0.000"],["64719.30","0.018"],["65296.50","0.032"],["65425.80","23.287"],["65458.10","8.509"]],"st":1}}
{"stream":"btcusdt@depth@100ms","data":{"e":"depthUpdate","E":1784410655350,"T":1784410655349,"s":"BTCUSDT","ps":"BTCUSDT","U":11079104195804,"u":11079104202873,"pu":11079104195669,"b":[["1000.00","50.391"],["14149.90","0.672"],["14249.90","2.002"],["14349.90","0.714"],["14449.90","0.812"],["51720.00","0.004"],["58184.90","0.002"],["63276.00","0.000"],["63357.00","0.014"],["64003.40","0.000"],["64633.00","0.215"]],"a":[["64650.00","1.777"],["64653.50","0.077"],["64656.40","0.001"],["64656.50","0.021"],["64656.60","0.002"],["64658.60","0.805"],["64660.00","0.162"],["64660.10","0.011"],["64662.70","0.229"],["64681.60","0.081"],["64706.10","0.360"],["64719.30","0.004"],["64754.10","5.235"],["64759.90","0.272"],["65296.50","0.032"],["65561.60","1.523"]],"st":1}}
{"stream":"btcusdt@depth@100ms","data":{"e":"depthUpdate","E":1784410655452,"T":1784410655449,"s":"BTCUSDT","ps":"BTCUSDT","U":11079104202980,"u":11079104209389,"pu":11079104202873,"b":[["1000.00","50.241"],["14149.90","0.798"],["14249.90","1.988"],["14349.90","0.714"],["14449.90","0.700"],["58184.90","0.002"],["61417.40","0.006"],["62063.90","0.690"],["63059.90","0.023"],["63874.10","23.822"],["63999.30","0.974"],["64003.40","0.000"],["64621.90","0.000"],["64636.20","0.520"],["64636.70","1.960"],["64640.00","0.420"],["64643.20","1.338"]],"a":[["64656.40","0.001"],["64656.50","0.021"],["64656.60","0.002"],["64658.60","0.093"],["64659.70","0.029"],["64660.10","0.723"],["64668.70","0.003"],["64670.80","0.001"],["64680.40","0.080"],["64681.60","0.081"],["64688.60","0.000"],["65296.50","0.032"],["65300.60","0.857"],["65483.30","1.533"]],"st":1}}
{"stream":"btcusdt@depth@100ms","data":{"e":"depthUpdate","E":1784410655554,"T":1784410655553,"s":"BTCUSDT","ps":"BTCUSDT","U":11079104209567,"u":11079104216553,"pu":11079104209389,"b":[["14149.90","1.022"],["14249.90","1.778"],["14349.90","0.826"],["14449.90","0.574"],["58184.90","0.002"],["61417.40","0.006"],["62063.90","0.693"],["63357.00","0.017"],["63964.80","0.000"],["64003.40","0.000"],["64326.70","1.061"],["64441.80","0.027"],["64446.30","0.004"],["64449.90","0.000"],["64478.60","0.002"],["64485.00","0.158"],["64488.30","0.193"],["64495.70","0.000"],["64537.40","0.000"],["64538.90","0.004"],["64540.40","0.202"],["64541.90","0.000"],["64543.40","0.000"],["64544.90","0.000"],["64546.40","0.556"],["64547.90","1.276"],["64562.60","0.349"],["64606.30","0.387"],["64613.80","0.065"],["64615.50","0.212"],["64617.30","0.306"],["64625.60","0.006"],["64633.00","0.061"],["64636.20","0.522"],["64649.90","12.332"]],"a":[["64656.40","0.542"],["64656.50","0.048"],["64656.60","0.002"],["64658.60","0.093"],["64660.10","0.155"],["64668.70","0.005"],["64669.10","0.002"],["64669.20","0.048"],["64669.30","0.310"],["64671.10","0.453"],["64680.40","0.000"],["64681.60","0.004"],["64685.50","0.019"],["64685.60","0.001"],["64685.70","0.121"],["64686.00","0.017"],["64686.10","0.050"],["64686.20","0.114"],["64802.10","0.000"],["64819.20","0.018"],["64856.10","0.000"],["65296.50","0.032"]],"st":1}}
{"stream":"btcusdt@depth@100ms","data":{"e":"depthUpdate","E":1784410655656,"T":1784410655653,"s":"BTCUSDT","ps":"BTCUSDT","U":11079104216646,"u":11079104223324,"pu":11079104216553,"b":[["1000.00","50.241"],["14149.90","1.260"],["14249.90","1.540"],["14349.90","0.938"],["14449.90","0.462"],["58184.90","0.002"],["61417.40","0.008"],["62063.90","0.690"],["63841.80","7.076"],["64003.40","0.000"],["64281.30","41.249"],["64326.60","1.091"],["64349.90","0.051"],["64377.80","33.758"],["64441.70","3.424"],["64448.70","26.285"],["64478.60","0.730"],["64495.70","0.720"],["64547.90","0.000"],["64622.00","0.762"],["64633.00","0.215"],["64634.30","0.366"],["64636.90","0.794"],["64640.00","1.060"],["64649.90","12.330"]],"a":[["64656.40","0.155"],["64656.50","0.031"],["64656.60","0.012"],["64657.60","0.004"],["64658.60","0.100"],["64660.10","0.542"],["64698.50","0.014"],["64706.10","0.346"],["64802.00","1.072"],["64819.20","0.962"],["64849.60","26.140"],["64854.70","0.911"],["64856.00","3.771"],["64920.90","33.498"],["64973.30","0.926"],["65018.30","41.061"],["65296.50","0.032"],["65806.80","0.662"]],"st":1}}
{"stream":"btcusdt@depth@100ms","data":{"e":"depthUpdate","E":1784410655758,"T":1784410655757,"s":"BTCUSDT","ps":"BTCUSDT","U":11079104223551,"u":11079104229611,"pu":11079104223324,"b":[["14149.90","1.498"],["14249.90","1.302"],["14349.90","1.064"],["14449.90","0.336"],["58184.90","0.002"],["62063.90","0.693"],["63936.80","0.875"],["64003.40","0.002"],["64326.70","0.944"],["64378.40","0.117"],["64449.90","0.000"],["64451.10","5.566"]],"a":[["64656.40","0.001"],["64656.50","0.021"],["64656.60","0.002"],["64658.60","0.815"],["64660.10","0.001"],["64681.60","0.081"],["64919.40","5.899"],["65018.20","6.357"],["65018.30","40.800"],["65296.50","0.032"],["65511.40","0.762"],["65712.30","0.000"],["65942.90","0.645"]],"st":1}}
{"stream":"btcusdt@depth@100ms","data":{"e":"depthUpdate","E":1784410655860,"T":1784410655857,"s":"BTCUSDT","ps":"BTCUSDT","U":11079104229686,"u":11079104235632,"pu":11079104229611,"b":[["14149.90","1.736"],["14249.90","1.064"],["14349.90","1.176"],["14449.90","0.224"],["58184.90","0.002"],["64003.40","0.000"],["64250.20","0.001"],["64264.10","12.528"],["64281.40","0.960"],["64326.70","0.944"],["64441.70","0.000"],["64442.50","0.000"],["64448.80","0.217"],["64478.60","0.002"],["64495.70","0.000"],["64564.50","0.002"],["64631.60","10.557"]],"a":[["64650.00","1.772"],["64656.60","0.707"],["64657.60","0.004"],["64658.60","0.110"],["64681.60","0.004"],["64802.00","0.000"],["64819.20","0.018"],["64849.50","0.220"],["64849.90","0.000"],["64856.00","0.061"],["65296.50","0.032"],["66646.70","0.642"]],"st":1}}
{"stream":"btcusdt@depth@100ms","data":{"e":"depthUpdate","E":1784410655962,"T":1784410655961,"s":"BTCUSDT","ps":"BTCUSDT","U":11079104235937,"u":11079104241559,"pu":11079104235632,"b":[["1000.00","50.241"],["14149.90","1.974"],["14249.90","0.826"],["14349.90","1.302"],["14449.90","0.098"],["51719.90","0.000"],["51720.00","0.004"],["58184.90","0.002"],["62063.90","0.690"],["63685.00","0.014"],["63731.90","5.089"],["63796.00","0.001"],["63826.20","80.362"],["64003.40","0.000"],["64018.30","60.676"],["64023.10","0.935"],["64165.80","49.884"],["64281.60","6.702"],["64380.60","6.512"],["64537.40","0.491"],["64567.10","0.017"],["64633.50","3.123"]],"a":[["64656.40","0.001"],["64656.50","0.021"],["64656.60","0.002"],["64658.60","0.093"],["64660.10","0.723"],["64752.10","5.602"],["64849.00","7.817"],["65135.40","53.702"],["65285.20","66.015"],["65296.50","0.032"],["65445.00","2.354"],["65481.00","79.377"]],"st":1}}
{"stream":"btcusdt@depth@100ms","data":{"e":"depthUpdate","E":1784410656064,"T":1784410656061,"s":"BTCUSDT","ps":"BTCUSDT","U":11079104241658,"u":11079104247835,"pu":11079104241559,"b":[["14149.90","1.988"],["14249.90","0.714"],["14349.90","1.386"],["14449.90","0.000"],["14549.90","0.112"],["51720.00","0.004"],["58184.90","0.002"],["61417.40","0.010"],["62063.90","0.693"],["63777.10","3.909"],["63900.10","0.000"],["64003.40","0.000"],["64441.70","3.424"],["64449.90","0.000"],["64478.60","0.730"],["64495.70","0.720"],["64537.40","0.491"],["64538.90","0.004"],["64540.40","1.478"],["64541.90","1.276"],["64543.40","1.276"],["64544.90","1.276"],["64546.40","1.832"],["64564.50","0.006"],["64567.10","0.013"],["64577.40","0.001"],["64577.80","0.014"],["64578.10","0.000"],["64578.40","0.426"],["64578.70","0.000"],["64594.30","0.418"],["64597.20","0.001"],["64597.50","0.001"],["64597.80","0.000"],["64598.10","0.000"],["64598.30","0.501"],["64598.40","0.051"],["64598.70","20.732"],["64598.90","0.227"],["64599.60","0.095"],["64600.90","0.146"],["64601.00","0.006"],["64608.80","0.000"],["64612.70","0.080"],["64612.80","0.461"],["64612.90","0.010"],["64613.00","1.003"],["64613.30","0.556"],["64613.40","0.001"],["64614.00","0.741"],["64616.90","0.568"],["64617.00","0.327"],["64633.00","0.061"],["64636.00","0.189"],["64636.10","0.217"],["64636.30","0.158"],["64636.60","0.000"],["64636.70","1.336"],["64636.90","0.727"],["64637.20","0.157"],["64637.30","0.117"],["64637.60","0.001"],["64637.80","0.064"],["64637.90","0.931"],["64638.30","0.002"],["64638.40","0.540"]],"a":[["64656.50","0.053"],["64656.60","0.002"],["64656.80","0.000"],["64657.10","0.034"],["64657.40","0.001"],["64657.50","0.003"],["64657.80","0.034"],["64658.00","0.001"],["64658.10","0.004"],["64658.50","0.000"],["64658.60","0.093"],["64658.70","1.274"],["64658.80","0.001"],["64660.10","0.723"],["64675.90","1.007"],["64676.50","0.000"],["64676.60","0.064"],["64676.90","0.213"],["64677.20","0.373"],["64677.50","0.003"],["64677.80","0.091"],["64677.90","0.567"],["64680.70","0.000"],["64681.30","0.979"],["64681.40","0.044"],["64681.70","0.024"],["64681.80","0.000"],["64682.00","0.102"],["64682.10","0.000"],["64696.20","0.000"],["64696.60","0.091"],["64696.90","0.003"],["64697.20","0.017"],["64697.60","0.033"],["64802.00","1.072"],["64819.20","0.958"],["64840.70","0.208"],["64856.00","3.753"],["64886.00","2.171"],["65296.50","0.032"],["65388.90","0.019"],["65453.60","0.001"],["65686.30","1.336"]],"st":1}}
{"stream":"btcusdt@depth@100ms","data":{"e":"depthUpdate","E":1784410656166,"T":1784410656165,"s":"BTCUSDT","ps":"BTCUSDT","U":11079104248065,"u":11079104255163,"pu":11079104247835,"b":[["14149.90","2.002"],["14249.90","0.714"],["14349.90","1.260"],["14549.90","0.224"],["58184.90","0.002"],["61417.50","0.011"],["62063.90","0.690"],["63357.00","0.020"],["64000.00","30.233"],["64003.40","0.000"],["64132.70","7.159"],["64326.70","0.934"],["64349.90","0.051"],["64540.40","0.202"],["64585.30","0.133"],["64610.30","0.490"],["64636.60","0.714"],["64636.90","0.883"],["64637.20","0.631"]],"a":[["64656.60","0.002"],["64657.70","0.410"],["64657.80","0.154"],["64658.20","0.067"],["64658.40","0.120"],["64658.50","0.120"],["64677.20","0.433"],["64680.40","0.060"],["64680.50","2.496"],["64680.80","0.100"],["64681.10","0.255"],["64714.60","0.002"],["65296.50","0.032"],["65769.90","0.759"]],"st":1}}
{"stream":"btcusdt@depth@100ms","data":{"e":"depthUpdate","E":1784410656268,"T":1784410656267,"s":"BTCUSDT","ps":"BTCUSDT","U":11079104255296,"u":11079104261742,"pu":11079104255163,"b":[["1000.00","50.241"],["14149.90","1.988"],["14249.90","0.714"],["14349.90","1.148"],["14549.90","0.350"],["51720.00","0.004"],["58184.90","0.002"],["63903.90","0.930"],["64003.40","0.000"],["64449.90","0.000"],["64541.90","0.000"],["64598.60","0.649"],["64633.00","0.215"],["64636.90","1.039"],["64637.20","0.781"],["64637.50","0.070"],["64637.90","0.005"],["64639.00","0.066"],["64639.40","1.167"],["64640.10","0.542"],["64640.70","0.626"],["64644.90","0.031"]],"a":[["64653.70","0.718"],["64656.60","0.159"],["64657.20","0.062"],["64657.50","0.035"],["64657.60","0.161"],["64657.70","0.470"],["64658.10","0.064"],["64658.60","0.000"],["64659.20","0.234"],["64659.40","0.000"],["64659.60","0.003"],["64659.80","0.000"],["64660.00","0.255"],["64662.20","0.574"],["64669.60","0.000"],["64671.10","0.994"],["64676.90","0.245"],["64680.40","0.120"],["64680.80","0.160"],["65162.40","0.001"],["65296.50","0.032"],["65770.00","1.112"]],"st":1}}
{"stream":"btcusdt@depth@100ms","data":{"e":"depthUpdate","E":1784410656370,"T":1784410656369,"s":"BTCUSDT","ps":"BTCUSDT","U":11079104261745,"u":11079104267369,"pu":11079104261742,"b":[["14149.90","2.002"],["14249.90","0.714"],["14349.90","1.022"],["14549.90","0.462"],["51720.00","0.004"],["58184.90","0.002"],["62063.90","0.693"],["64003.40","0.000"],["64543.40","0.000"],["64578.90","11.700"],["64579.50","0.186"],["64580.20","0.070"],["64599.30","0.074"],["64633.00","0.061"],["64636.50","0.157"],["64636.70","1.456"],["64637.20","0.937"],["64637.80","0.202"],["64637.90","0.143"],["64638.10","0.076"],["64638.50","0.982"],["64639.40","0.241"],["64639.50","0.662"],["64640.10","0.001"],["64649.90","12.329"]],"a":[["64650.00","1.771"],["64653.70","0.718"],["64656.60","0.002"],["64656.80","0.032"],["64657.10","0.094"],["64657.60","0.161"],["64657.70","0.530"],["64658.20","0.127"],["64658.50","0.180"],["64662.90","0.310"],["64669.60","0.541"],["64671.10","0.453"],["64676.20","0.048"],["64679.80","0.240"],["64680.40","0.180"],["64680.90","0.060"],["64681.10","0.315"],["64681.60","0.081"],["64683.10","0.062"],["64695.30","0.032"],["64696.00","0.035"],["64696.60","0.123"],["65131.00","0.015"],["65296.50","0.032"],["65363.10","3.745"],["65769.90","1.517"],["65906.30","0.000"]],"st":1}}
{"stream":"btcusdt@depth@100ms","data":{"e":"depthUpdate","E":1784410656472,"T":1784410656471,"s":"BTCUSDT","ps":"BTCUSDT","U":11079104267473,"u":11079104273161,"pu":11079104267369,"b":[["14149.90","1.988"],["14249.90","0.714"],["14349.90","0.910"],["14549.90","0.588"],["58184.90","0.002"],["62063.90","0.690"],["63872.20","0.876"],["63889.60","4.691"],["63944.70","0.004"],["64003.40","0.000"],["64326.70","0.944"],["64617.80","0.207"],["64633.00","0.215"],["64636.20","0.520"],["64637.20","1.087"]],"a":[["64653.70","0.718"],["64657.60","0.004"],["64657.80","0.214"],["64668.70","0.003"],["64677.20","0.493"],["64773.30","0.012"],["65296.50","0.032"],["65427.70","3.092"],["65930.30","2.556"]],"st":1}}
{"stream":"btcusdt@depth@100ms","data":{"e":"depthUpdate","E":1784410656574,"T":1784410656573,"s":"BTCUSDT","ps":"BTCUSDT","U":11079104273388,"u":11079104281853,"pu":11079104273161,"b":[["1000.00","50.241"],["14149.90","2.002"],["14249.90","0.714"],["14349.90","0.784"],["14549.90","0.700"],["51720.00","0.006"],["58184.90","0.002"],["62063.90","0.693"],["63700.70","0.000"],["63841.80","7.310"],["63906.40","8.441"],["64003.40","0.000"],["64449.90","0.000"],["64485.00","0.002"],["64579.20","0.071"],["64583.10","0.000"],["64605.70","0.002"],["64613.90","1.760"],["64614.00","0.933"],["64614.20","0.168"],["64614.50","0.299"],["64622.00","0.050"],["64633.00","0.061"],["64636.20","0.522"]],"a":[["64653.70","0.718"],["64657.60","0.161"],["64659.00","0.002"],["64659.20","0.234"],["64659.40","0.000"],["64659.60","0.003"],["64659.80","0.000"],["64668.70","0.005"],["64669.60","0.541"],["64671.10","0.453"],["64671.20","0.023"],["64671.90","0.927"],["64678.20","0.001"],["64681.60","0.004"],["64694.40","0.561"],["64696.30","0.032"],["64717.10","0.015"],["65296.50","0.032"],["65386.00","0.760"],["65555.10","11.213"],["65677.40","0.760"]],"st":1}}
{"stream":"btcusdt@depth@100ms","data":{"e":"depthUpdate","E":1784410656676,"T":1784410656675,"s":"BTCUSDT","ps":"BTCUSDT","U":11079104281957,"u":11079104287357,"pu":11079104281853,"b":[["14149.90","1.960"],["14249.90","0.728"],["14349.90","0.672"],["14549.90","0.840"],["51720.00","0.004"],["58184.90","0.002"],["61417.40","0.008"],["61417.50","0.013"],["62063.90","0.690"],["63712.50","21.468"],["64003.40","0.002"],["64349.90","0.051"],["64485.00","0.158"],["64488.30","0.037"],["64537.40","0.491"],["64538.90","0.004"],["64540.40","0.202"],["64541.90","0.000"],["64543.40","0.000"],["64544.90","0.000"],["64546.40","0.556"],["64547.90","0.000"],["64549.40","1.311"],["64560.00","1.337"],["64579.90","0.074"],["64585.50","0.752"],["64607.20","0.741"],["64613.90","1.916"],["64614.20","0.324"],["64614.60","0.150"],["64615.10","0.524"],["64617.30","0.002"]],"a":[["64653.70","0.131"],["64657.60","0.004"],["64681.60","0.081"],["64691.50","0.839"],["64695.70","0.101"],["64860.00","1.779"],["64973.30","0.924"],["65107.10","0.127"],["65164.50","0.767"],["65296.50","0.032"],["65386.00","0.531"],["65511.40","1.524"],["65880.30","0.303"],["71115.00","0.002"]],"st":1}}
{"stream":"btcusdt@depth@100ms","data":{"e":"depthUpdate","E":1784410656778,"T":1784410656777,"s":"BTCUSDT","ps":"BTCUSDT","U":11079104287383,"u":11079104293002,"pu":11079104287357,"b":[["1000.00","50.241"],["14149.90","1.722"],["14249.90","0.854"],["14349.90","0.546"],["14549.90","1.078"],["51720.00","0.004"],["58184.90","0.002"],["63357.00","0.017"],["64003.40","0.000"],["64127.90","0.000"],["64326.60","1.093"],["64326.70","0.944"],["64378.40","0.000"],["64449.90","0.000"],["64458.50","0.065"],["64478.60","0.002"],["64484.30","0.000"],["64485.00","0.499"],["64495.70","0.000"],["64549.40","0.035"],["64550.20","0.564"],["64550.80","0.003"],["64550.90","0.014"],["64553.10","0.004"],["64553.60","0.123"],["64562.60","0.008"],["64583.20","6.000"],["64605.90","3.600"],["64614.00","1.053"],["64614.60","0.306"],["64615.20","0.722"],["64622.00","0.729"],["64631.80","0.013"],["64632.50","0.050"],["64633.00","0.215"],["64649.90","12.328"]],"a":[["64653.70","0.131"],["64657.60","0.004"],["64748.80","0.385"],["64749.30","0.000"],["64749.40","0.016"],["64752.00","0.010"],["64802.00","0.000"],["64819.20","0.018"],["65167.20","6.949"],["65296.50","0.032"],["71115.00","0.000"]],"st":1}}
{"stream":"btcusdt@depth@100ms","data":{"e":"depthUpdate","E":1784410656880,"T":1784410656877,"s":"BTCUSDT","ps":"BTCUSDT","U":11079104293047,"u":11079104298439,"pu":11079104293002,"b":[["1000.00","50.241"],["14149.90","1.484"],["14249.90","0.966"],["14349.90","0.434"],["14549.90","1.316"],["51720.00","0.004"],["58184.90","0.002"],["61417.40","0.010"],["62063.90","0.693"],["63675.50","0.274"],["63876.20","0.000"],["64003.40","0.000"],["64378.40","0.117"],["64458.50","0.061"],["64463.70","0.047"],["64617.80","0.357"],["64633.00","0.061"],["64647.30","0.097"]],"a":[["64653.70","0.131"],["64678.20","0.702"],["64681.60","0.081"],["64694.40","4.061"],["64717.00","6.100"],["65296.50","0.032"],["65361.20","3.284"],["65477.40","0.258"],["65575.90","9.085"],["65971.00","0.000"]],"st":1}}
{"stream":"btcusdt@depth@100ms","data":{"e":"depthUpdate","E":1784410656982,"T":1784410656981,"s":"BTCUSDT","ps":"BTCUSDT","U":11079104298557,"u":11079104303716,"pu":11079104298439,"b":[["14149.90","1.246"],["14249.90","1.092"],["14349.90","0.308"],["14549.90","1.554"],["51719.90","0.000"],["58184.90","0.002"],["62063.90","0.690"],["64003.40","0.000"],["64320.00","0.613"],["64400.00","28.447"],["64441.70","2.139"],["64463.70","0.043"],["64478.60","0.480"],["64480.00","4.537"],["64484.30","0.004"],["64488.30","0.193"],["64495.70","0.478"],["64551.00","10.000"],["64551.10","1.541"],["64553.10","0.000"],["64560.00","1.324"],["64564.50","0.002"],["64567.10","0.017"],["64585.50","1.600"],["64607.20","1.047"],["64623.10","0.219"],["64623.60","0.120"],["64633.00","0.215"],["64633.80","4.512"],["64636.70","1.851"],["64637.40","0.001"],["64638.30","0.559"],["64640.00","1.043"]],"a":[["64650.00","1.766"],["64653.70","0.131"],["64656.60","0.002"],["64657.60","0.161"],["64671.80","0.356"],["64672.50","0.096"],["64678.50","0.603"],["64679.30","0.008"],["64681.60","0.004"],["64720.00","0.552"],["64748.80","1.755"],["64749.40","10.016"],["64800.00","18.636"],["64802.00","0.801"],["64819.20","0.721"],["64854.70","1.264"],["64856.00","2.823"],["64880.00","9.708"],["64960.00","2.429"],["65040.00","0.550"],["65296.50","0.032"],["65361.20","3.513"]],"st":1}}
{"stream":"btcusdt@depth@100ms","data":{"e":"depthUpdate","E":1784410657084,"T":1784410657081,"s":"BTCUSDT","ps":"BTCUSDT","U":11079104303784,"u":11079104309123,"pu":11079104303716,"b":[["1000.00","50.241"],["14149.90","1.008"],["14249.90","1.204"],["14349.90","0.196"],["14549.90","1.792"],["58184.90","0.002"],["62063.90","0.693"],["63033.70","0.713"],["63874.10","25.386"],["64003.40","0.000"],["64320.00","0.630"],["64326.70","0.944"],["64400.00","28.464"],["64449.90","0.000"],["64480.00","4.554"],["64550.20","0.556"],["64551.10","1.549"],["64560.00","1.341"],["64633.00","0.061"],["64637.00","0.510"],["64637.30","0.001"],["64638.30","0.559"],["64640.00","1.060"],["64642.30","0.001"],["64645.00","0.292"],["64647.40","0.001"],["64649.50","1.304"]],"a":[["64650.00","1.792"],["64653.70","0.718"],["64671.80","0.047"],["64672.50","0.405"],["64681.60","0.004"],["64720.00","0.569"],["64749.30","0.008"],["64752.00","0.002"],["64800.00","18.653"],["64880.00","9.725"],["64960.00","2.446"],["65040.00","0.567"],["65296.50","0.032"],["65548.60","6.364"],["65587.10","0.001"]],"st":1}}
{"stream":"btcusdt@depth@100ms","data":{"e":"depthUpdate","E":1784410657186,"T":1784410657185,"s":"BTCUSDT","ps":"BTCUSDT","U":11079104309251,"u":11079104316100,"pu":11079104309123,"b":[["1000.00","50.241"],["14149.90","0.784"],["14249.90","1.330"],["14349.90","0.070"],["14449.90","0.014"],["14549.90","2.002"],["58184.90","0.002"],["61417.50","0.009"],["63240.30","0.677"],["63501.40","0.785"],["64003.40","0.000"],["64349.90","0.051"],["64449.90","0.000"],["64633.00","0.215"]],"a":[["64650.00","1.793"],["64653.70","0.718"],["64681.60","0.004"],["65296.50","0.032"],["65390.00","0.806"],["65446.70","0.763"],["65944.90","2.544"]],"st":1}}
{"stream":"btcusdt@depth@100ms","data":{"e":"depthUpdate","E":1784410657288,"T":1784410657286,"s":"BTCUSDT","ps":"BTCUSDT","U":11079104316209,"u":11079104322121,"pu":11079104316100,"b":[["14149.90","0.714"],["14249.90","1.358"],["14349.90","0.000"],["14449.90","0.140"],["14549.90","1.988"],["58184.90","0.002"],["61417.40","0.008"],["61417.50","0.011"],["62063.90","0.690"],["63357.00","0.020"],["63824.90","4.690"],["64003.40","0.000"],["64568.60","0.001"],["64633.00","0.061"],["64649.90","12.281"]],"a":[["64650.00","1.945"],["64653.40","0.601"],["64653.50","0.201"],["64653.70","0.007"],["64657.30","0.002"],["64657.50","0.035"],["64657.90","0.181"],["64658.10","0.064"],["64658.20","0.174"],["64731.30","0.001"],["65296.50","0.032"]],"st":1}}
{"stream":"btcusdt@depth@100ms","data":{"e":"depthUpdate","E":1784410657390,"T":1784410657389,"s":"BTCUSDT","ps":"BTCUSDT","U":11079104322269,"u":11079104327858,"pu":11079104322121,"b":[["1000.00","50.241"],["14149.90","0.714"],["14249.90","1.232"],["14449.90","0.252"],["14549.90","2.002"],["51720.00","0.004"],["58184.90","0.002"],["62063.90","0.693"],["63727.70","0.000"],["63954.30","4.872"],["64003.40","0.000"],["64326.70","0.944"],["64361.50","0.005"],["64426.30","0.022"],["64489.10","0.016"],["64491.10","0.001"],["64495.70","0.000"],["64555.90","0.000"],["64636.30","0.274"],["64637.00","0.394"],["64637.30","0.558"],["64637.70","0.007"],["64638.30","0.002"],["64638.50","0.056"],["64639.30","0.929"]],"a":[["64653.40","0.014"],["64653.50","0.077"],["64653.70","0.007"],["64655.10","0.635"],["64656.40","0.552"],["64656.50","0.053"],["64656.60","0.002"],["64657.30","0.002"],["64657.60","0.161"],["64657.80","0.214"],["64657.90","0.181"],["64658.10","0.111"],["64658.20","0.127"],["64658.30","0.043"],["64658.50","0.304"],["64659.30","0.315"],["64660.10","0.172"],["64670.10","0.005"],["64671.00","0.002"],["64671.80","0.973"],["64671.90","0.001"],["64802.00","0.000"],["65296.50","0.032"]],"st":1}}
{"stream":"btcusdt@depth@100ms","data":{"e":"depthUpdate","E":1784410657492,"T":1784410657489,"s":"BTCUSDT","ps":"BTCUSDT","U":11079104327859,"u":11079104332873,"pu":11079104327858,"b":[["1000.00","50.241"],["14149.90","0.714"],["14249.90","1.120"],["14449.90","0.378"],["14549.90","1.988"],["51720.00","0.004"],["58184.90","0.002"],["62063.90","0.690"],["64003.40","0.000"],["64295.30","0.018"],["64359.90","1.131"],["64424.50","0.793"],["64495.70","0.720"],["64633.00","0.215"],["64638.40","1.466"],["64639.30","0.003"]],"a":[["64655.10","0.048"],["64656.40","0.001"],["64656.50","0.594"],["64656.60","0.183"],["64658.10","0.064"],["64658.30","0.043"],["64658.50","0.304"],["64658.70","1.274"],["64659.10","0.004"],["64659.30","0.362"],["64659.90","0.000"],["64660.10","0.001"],["64669.60","0.541"],["64671.70","0.015"],["64802.00","0.991"],["65296.50","0.032"],["65365.20","1.085"],["65769.90","2.276"]],"st":1}}
{"stream":"btcusdt@depth@100ms","data":{"e":"depthUpdate","E":1784410657594,"T":1784410657593,"s":"BTCUSDT","ps":"BTCUSDT","U":11079104333061,"u":11079104339354,"pu":11079104332873,"b":[["14149.90","0.714"],["14249.90","0.994"],["14449.90","0.490"],["14549.90","2.002"],["58184.90","0.002"],["62063.90","0.693"],["63750.40","0.273"],["64003.40","0.000"],["64022.80","0.935"],["64449.90","0.000"],["64485.00","0.343"],["64495.70","0.000"],["64568.60","0.000"],["64636.20","0.522"],["64649.90","12.307"]],"a":[["64655.10","0.048"],["64656.40","0.001"],["64656.50","0.775"],["64656.60","0.002"],["64657.60","0.161"],["64658.30","0.004"],["64659.30","0.315"],["64659.60","0.050"],["64660.10","0.001"],["64668.70","0.005"],["64676.00","0.016"],["64681.60","0.081"],["64683.10","0.047"],["64731.30","0.000"],["64802.00","0.000"],["65260.30","0.000"],["65296.50","0.032"],["66609.10","1.927"]],"st":1}}
{"stream":"btcusdt@depth@100ms","data":{"e":"depthUpdate","E":1784410657696,"T":1784410657694,"s":"BTCUSDT","ps":"BTCUSDT","U":11079104339460,"u":11079104345335,"pu":11079104339354,"b":[["1000.00","50.241"],["14149.90","0.714"],["14249.90","0.882"],["14449.90","0.616"],["14549.90","1.988"],["58184.90","0.002"],["63357.00","0.014"],["63546.10","0.000"],["63706.00","0.790"],["64003.40","0.000"],["64326.70","0.944"],["64349.90","0.051"],["64449.90","0.000"],["64478.60","0.002"],["64631.60","0.557"],["64633.00","0.061"],["64644.70","0.004"]],"a":[["64650.00","2.043"],["64656.40","0.001"],["64656.50","0.234"],["64656.60","0.002"],["64657.60","0.004"],["64659.90","0.000"],["64660.10","0.542"],["64681.60","0.004"],["64819.20","0.018"],["65296.50","0.032"],["65425.80","23.546"]],"st":1}}
{"stream":"btcusdt@depth@100ms","data":{"e":"depthUpdate","E":1784410657798,"T":1784410657796,"s":"BTCUSDT","ps":"BTCUSDT","U":11079104345441,"u":11079104350650,"pu":11079104345335,"b":[["1000.00","50.241"],["14149.90","0.714"],["14249.90","0.756"],["14449.90","0.728"],["14549.90","2.002"],["58184.90","0.002"],["62063.90","0.690"],["63675.40","0.274"],["63762.50","3.288"],["64003.40","0.000"],["64326.60","1.091"],["64441.70","3.395"],["64463.70","0.043"],["64478.60","0.727"],["64485.00","0.158"],["64495.70","0.717"],["64562.60","0.349"],["64572.30","0.000"],["64585.30","0.133"],["64596.50","20.704"],["64598.70","0.002"],["64600.90","0.146"],["64628.20","10.000"],["64630.10","1.829"],["64633.00","0.215"],["64633.50","1.599"],["64636.30","0.158"],["64636.80","0.131"],["64637.30","0.001"],["64638.30","0.559"],["64649.90","12.309"]],"a":[["64650.40","0.006"],["64656.40","1.129"],["64656.50","0.207"],["64656.60","0.029"],["64659.60","0.003"],["64659.90","0.047"],["64660.10","0.001"],["64670.20","0.003"],["64671.10","1.379"],["64671.80","0.047"],["64802.00","0.991"],["64819.10","0.870"],["64840.70","0.091"],["64856.00","3.533"],["64886.00","2.288"],["65296.50","0.032"],["65588.80","2.606"]],"st":1}}
{"stream":"btcusdt@depth@100ms","data":{"e":"depthUpdate","E":1784410657900,"T":1784410657897,"s":"BTCUSDT","ps":"BTCUSDT","U":11079104350735,"u":11079104355231,"pu":11079104350650,"b":[["14149.90","0.756"],["14249.90","0.644"],["14449.90","0.896"],["14549.90","1.904"],["58184.90","0.002"],["62063.90","0.693"],["63550.90","4.791"],["64003.40","0.000"],["64378.40","0.000"],["64381.60","0.117"],["64549.40","0.035"],["64557.00","0.001"],["64557.60","0.005"],["64560.00","1.337"],["64596.50","0.004"],["64598.70","20.730"]],"a":[["64650.00","2.038"],["64656.40","0.696"],["64656.50","0.080"],["64656.60","0.589"],["64659.90","0.000"],["64660.10","0.001"],["64669.10","0.004"],["64669.20","0.050"],["64669.30","0.312"],["64681.60","0.081"],["64683.60","10.015"],["64685.50","0.021"],["64685.60","0.003"],["64685.70","0.123"],["64686.00","0.019"],["64686.10","0.052"],["64686.20","0.116"],["64742.90","0.357"],["64840.70","0.208"],["64973.30","0.926"],["65236.40","0.463"],["65296.50","0.032"]],"st":1}}
{"stream":"btcusdt@depth@100ms","data":{"e":"depthUpdate","E":1784410658002,"T":1784410658001,"s":"BTCUSDT","ps":"BTCUSDT","U":11079104355398,"u":11079104359722,"pu":11079104355231,"b":[["1000.00","50.241"],["14149.90","0.882"],["14249.90","0.518"],["14449.90","1.134"],["14549.90","1.666"],["51719.90","0.000"],["58184.90","0.002"],["62063.90","0.690"],["63726.10","8.861"],["63970.90","0.004"],["64003.40","0.000"],["64326.70","0.944"],["64421.30","0.828"],["64449.90","0.000"],["64598.80","3.199"],["64633.00","0.061"],["64649.90","12.308"]],"a":[["64650.00","2.041"],["64656.40","1.283"],["64656.50","0.080"],["64656.60","0.002"],["64659.90","0.000"],["64660.10","0.001"],["64681.60","0.004"],["64687.60","0.018"],["64691.50","1.254"],["65167.20","7.255"],["65296.50","0.032"]],"st":1}}
{"stream":"btcusdt@depth@100ms","data":{"e":"depthUpdate","E":1784410658104,"T":1784410658102,"s":"BTCUSDT","ps":"BTCUSDT","U":11079104359898,"u":11079104364830,"pu":11079104359722,"b":[["1000.00","50.241"],["14149.90","0.994"],["14249.90","0.406"],["14449.90","1.372"],["14549.90","1.428"],["58184.90","0.002"],["61417.50","0.013"],["62063.90","0.693"],["64003.40","0.000"],["64297.30","0.018"],["64449.90","0.000"],["64488.30","0.037"],["64557.00","0.000"],["64567.10","0.013"],["64633.00","0.215"],["64638.30","0.559"],["64649.90","12.303"]],"a":[["64650.00","2.040"],["64656.40","0.155"],["64656.50","0.080"],["64656.60","0.002"],["64658.50","0.351"],["64659.90","0.541"],["64660.10","0.001"],["64662.70","0.182"],["64662.90","0.357"],["64681.60","0.081"],["64742.90","0.356"],["65296.50","0.035"]],"st":1}}
{"stream":"btcusdt@depth@100ms","data":{"e":"depthUpdate","E":1784410658206,"T":1784410658205,"s":"BTCUSDT","ps":"BTCUSDT","U":11079104364946,"u":11079104370150,"pu":11079104364830,"b":[["14149.90","1.120"],["14249.90","0.280"],["14449.90","1.610"],["14549.90","1.190"],["34000.00","7.459"],["58184.90","0.002"],["63699.50","1.098"],["63853.20","1.564"],["63860.50","2.579"],["63889.60","3.909"],["63892.90","0.781"],["64003.40","0.000"],["64320.00","0.613"],["64349.90","0.051"],["64400.00","28.447"],["64449.90","0.000"],["64480.00","4.537"],["64495.70","0.477"],["64560.00","1.320"],["64633.00","0.061"],["64640.00","1.043"]],"a":[["64656.50","0.053"],["64656.60","0.002"],["64658.50","0.304"],["64658.80","0.048"],["64659.80","0.000"],["64659.90","0.000"],["64660.10","0.569"],["64681.60","0.004"],["64720.00","0.552"],["64800.00","18.636"],["64802.00","0.721"],["64880.00","9.708"],["64960.00","2.429"],["65040.00","0.550"],["65296.50","0.033"],["65595.20","0.000"]],"st":1}}
{"stream":"btcusdt@depth@100ms","data":{"e":"depthUpdate","E":1784410658308,"T":1784410658307,"s":"BTCUSDT","ps":"BTCUSDT","U":11079104370184,"u":11079104375292,"pu":11079104370150,"b":[["1000.00","50.241"],["14149.90","1.232"],["14249.90","0.168"],["14449.90","1.848"],["14549.90","0.952"],["58184.90","0.002"],["62063.90","0.690"],["63357.00","0.011"],["63777.80","8.671"],["63925.80","0.008"],["64003.40","0.000"],["64326.70","0.934"],["64421.30","0.833"],["64488.30","0.193"],["64567.10","0.017"],["64606.10","0.309"],["64607.70","0.006"],["64612.50","0.188"],["64619.00","0.196"],["64621.50","3.159"],["64624.60","10.003"],["64627.90","0.077"],["64628.20","0.000"],["64630.10","0.385"],["64631.90","0.003"],["64632.50","0.048"],["64633.00","0.215"],["64634.40","0.010"],["64635.60","0.488"],["64636.30","0.158"],["64636.80","0.015"],["64637.60","0.558"],["64638.30","0.002"],["64642.70","0.006"],["64645.00","0.289"],["64646.70","0.018"],["64647.10","0.002"],["64647.20","1.625"],["64647.50","0.023"],["64649.50","1.301"],["64649.90","11.435"]],"a":[["64650.00","2.208"],["64653.30","0.316"],["64653.80","1.275"],["64654.00","0.008"],["64654.10","0.129"],["64654.30","0.003"],["64654.60","0.003"],["64654.70","0.047"],["64654.90","0.003"],["64655.10","0.048"],["64655.30","0.001"],["64655.50","0.007"],["64655.60","0.085"],["64655.80","0.003"],["64656.10","0.003"],["64656.30","0.003"],["64656.40","0.001"],["64656.50","0.053"],["64656.60","0.589"],["64657.10","0.107"],["64658.80","0.001"],["64658.90","0.002"],["64659.30","0.362"],["64659.90","0.181"],["64660.10","0.542"],["64668.70","0.546"],["64669.60","0.000"],["64671.00","0.002"],["64671.60","0.000"],["64673.00","0.163"],["64673.30","0.034"],["64674.00","0.002"],["64677.90","1.124"],["64678.50","0.047"],["64679.20","0.000"],["64685.80","0.013"],["65149.10","0.000"],["65296.50","0.033"],["65640.60","0.760"],["65942.90","0.642"],["66327.90","0.000"]],"st":1}}
{"stream":"btcusdt@depth@100ms","data":{"e":"depthUpdate","E":1784410658410,"T":1784410658409,"s":"BTCUSDT","ps":"BTCUSDT","U":11079104375401,"u":11079104380324,"pu":11079104375292,"b":[["1000.00","50.241"],["14149.90","1.358"],["14249.90","0.042"],["14349.90","0.042"],["14449.90","2.002"],["14549.90","0.756"],["51720.00","0.004"],["58184.90","0.002"],["61417.40","0.006"],["61417.50","0.015"],["62063.90","0.693"],["63742.20","8.077"],["63954.30","4.091"],["64003.40","0.000"],["64320.00","0.630"],["64400.00","28.464"],["64480.00","4.554"],["64560.00","1.337"],["64607.70","0.010"],["64633.00","0.061"],["64640.00","1.060"],["64649.90","11.437"]],"a":[["64650.00","2.210"],["64654.70","0.000"],["64655.20","1.277"],["64655.80","0.003"],["64656.10","0.050"],["64656.50","0.053"],["64656.60","0.002"],["64659.90","0.000"],["64660.10","0.723"],["64720.00","0.569"],["64778.30","0.100"],["64800.00","18.653"],["64880.00","9.725"],["64960.00","2.446"],["65011.10","1.223"],["65040.00","0.567"],["65140.30","1.520"],["65269.50","1.329"],["65278.70","0.000"],["65296.50","0.033"],["65398.70","1.212"],["65408.30","0.539"],["65537.90","4.569"]],"st":1}}
{"stream":"btcusdt@depth@100ms","data":{"e":"depthUpdate","E":1784410658512,"T":1784410658510,"s":"BTCUSDT","ps":"BTCUSDT","U":11079104380479,"u":11079104386203,"pu":11079104380324,"b":[["14149.90","1.330"],["14249.90","0.000"],["14349.90","0.168"],["14449.90","1.988"],["14549.90","0.714"],["51720.00","0.020"],["58184.90","0.002"],["62063.90","0.690"],["64003.40","0.000"],["64297.30","0.023"],["64326.70","0.944"],["64449.90","0.000"],["64567.10","0.013"],["64628.70","2.000"],["64633.00","0.215"],["64638.10","0.379"],["64647.20","1.935"]],"a":[["64650.00","1.774"],["64653.30","0.006"],["64656.10","0.003"],["64656.50","0.775"],["64656.60","0.002"],["64659.30","0.315"],["64659.70","0.029"],["64660.10","0.001"],["64662.80","0.049"],["64662.90","0.310"],["64668.70","0.005"],["64669.60","0.541"],["64673.30","0.032"],["64673.90","0.012"],["64681.60","0.081"],["65296.50","0.033"],["65458.10","8.768"],["65587.40","17.662"],["66170.20","0.000"]],"st":1}}
{"stream":"btcusdt@depth@100ms","data":{"e":"depthUpdate","E":1784410658614,"T":1784410658613,"s":"BTCUSDT","ps":"BTCUSDT","U":11079104386289,"u":11079104391508,"pu":11079104386203,"b":[["1000.00","50.241"],["14149.90","1.204"],["14349.90","0.280"],["14449.90","2.002"],["14549.90","0.714"],["51720.00","0.004"],["58184.90","0.002"],["63744.80","17.519"],["63751.30","4.040"],["63954.30","3.310"],["64132.70","7.470"],["64449.90","0.000"],["64636.20","0.522"]],"a":[["64656.30","0.003"],["64656.40","0.001"],["64656.50","0.775"],["64656.60","0.002"],["64660.10","0.001"],["64668.70","0.005"],["64746.00","0.960"],["65296.50","0.033"],["66100.00","14.838"],["66266.30","2.411"]],"st":1}}
{"stream":"btcusdt@depth@100ms","data":{"e":"depthUpdate","E":1784410658718,"T":1784410658717,"s":"BTCUSDT","ps":"BTCUSDT","U":11079104391714,"u":11079104396648,"pu":11079104391508,"b":[["1000.00","50.241"],["14149.90","1.078"],["14349.90","0.406"],["14449.90","1.988"],["14549.90","0.728"],["58184.90","0.002"],["62063.90","0.693"],["63357.00","0.014"],["63900.00","19.341"],["63963.70","0.000"],["64003.40","0.000"],["64130.00","0.003"],["64324.00","0.310"],["64449.90","0.000"],["64564.50","0.006"],["64569.70","0.001"],["64598.70","0.002"],["64600.90","20.874"],["64624.60","0.003"],["64635.10","0.390"]],"a":[["64650.00","1.787"],["64656.30","0.003"],["64656.40","0.001"],["64656.50","0.053"],["64656.60","0.589"],["64659.90","0.010"],["64660.10","0.713"],["64681.60","0.004"],["64969.60","0.218"],["64970.50","0.004"],["65296.50","0.033"]],"st":1}}
{"stream":"btcusdt@depth@100ms","data":{"e":"depthUpdate","E":1784410658820,"T":1784410658818,"s":"BTCUSDT","ps":"BTCUSDT","U":11079104396727,"u":11079104401340,"pu":11079104396648,"b":[["14149.90","0.966"],["14349.90","0.518"],["14449.90","2.002"],["14549.90","0.714"],["58184.90","0.002"],["61417.40","0.008"],["62063.90","0.690"],["63590.20","1.329"],["63898.30","5.134"],["64003.40","0.000"],["64320.00","0.613"],["64324.00","0.155"],["64326.30","0.490"],["64326.60","3.420"],["64326.70","0.944"],["64381.60","0.000"],["64400.00","28.447"],["64463.70","0.043"],["64480.00","4.537"],["64495.70","0.718"],["64553.80","5.933"],["64556.40","1.222"],["64560.00","1.320"],["64562.60","0.349"],["64591.70","0.026"],["64591.80","0.024"],["64592.70","0.550"],["64598.20","0.240"],["64598.80","0.000"],["64599.20","0.201"],["64611.10","0.104"],["64612.10","0.200"],["64619.00","0.119"],["64633.00","0.215"],["64635.60","0.372"],["64636.90","1.155"],["64640.00","1.043"],["64649.90","11.435"]],"a":[["64650.00","1.782"],["64656.40","0.001"],["64656.50","0.053"],["64656.60","0.002"],["64659.90","0.000"],["64660.10","0.723"],["64677.90","0.567"],["64678.40","0.966"],["64681.60","0.081"],["64720.00","0.552"],["64737.30","0.204"],["64738.30","0.000"],["64743.80","0.201"],["64744.80","0.144"],["64745.70","3.480"],["64746.00","0.440"],["64746.10","0.000"],["64800.00","18.636"],["64802.00","0.991"],["64880.00","9.708"],["64886.00","2.171"],["64960.00","2.429"],["64973.10","1.114"],["64973.20","2.688"],["64973.30","0.924"],["65021.80","0.217"],["65022.80","0.009"],["65040.00","0.594"],["65042.30","0.350"],["65043.30","0.093"],["65296.50","0.033"]],"st":1}}
{"stream":"btcusdt@depth@100ms","data":{"e":"depthUpdate","E":1784410658922,"T":1784410658921,"s":"BTCUSDT","ps":"BTCUSDT","U":11079104401426,"u":11079104406533,"pu":11079104401340,"b":[["1000.00","50.241"],["14149.90","0.840"],["14349.90","0.644"],["14449.90","1.988"],["14549.90","0.728"],["58184.90","0.002"],["62063.90","0.693"],["63465.30","1.573"],["63934.80","0.960"],["64003.40","0.000"],["64132.70","7.781"],["64320.00","0.460"],["64326.60","3.422"],["64326.70","1.099"],["64328.60","0.731"],["64378.40","0.117"],["64400.00","28.294"],["64480.00","4.384"],["64560.00","1.167"],["64640.00","0.890"]],"a":[["64720.00","0.399"],["64800.00","18.483"],["64880.00","9.555"],["64960.00","2.276"],["64973.20","2.842"],["65040.00","0.441"],["65296.50","0.033"],["65393.70","10.896"],["65423.10","2.976"]],"st":1}}
{"stream":"btcusdt@depth@100ms","data":{"e":"depthUpdate","E":1784410659024,"T":1784410659023,"s":"BTCUSDT","ps":"BTCUSDT","U":11079104406633,"u":11079104411954,"pu":11079104406533,"b":[["1000.00","50.241"],["14149.90","0.728"],["14349.90","0.756"],["14449.90","2.002"],["14549.90","0.714"],["51719.90","0.000"],["58184.90","0.002"],["62063.90","0.690"],["63371.60","0.000"],["63788.60","0.784"],["63860.30","2.927"],["64003.40","0.000"],["64320.00","0.630"],["64400.00","28.464"],["64449.90","0.000"],["64480.00","4.554"],["64495.70","0.000"],["64560.00","1.337"],["64601.00","3.482"],["64604.90","0.001"],["64605.00","0.204"],["64605.30","0.014"],["64606.50","0.068"],["64616.00","0.005"],["64616.80","0.003"],["64624.70","0.882"],["64630.10","0.612"],["64640.00","1.060"],["64647.50","0.000"],["64649.90","11.428"]],"a":[["64650.00","1.788"],["64653.20","0.315"],["64656.80","0.079"],["64681.60","0.004"],["64720.00","0.569"],["64800.00","18.653"],["64802.00","0.000"],["64880.00","9.725"],["64960.00","2.446"],["65040.00","0.611"],["65296.50","0.033"],["65393.70","9.988"],["65425.80","24.766"],["65568.00","1.082"]],"st":1}}
{"stream":"btcusdt@depth@100ms","data":{"e":"depthUpdate","E":1784410659126,"T":1784410659125,"s":"BTCUSDT","ps":"BTCUSDT","U":11079104411996,"u":11079104417754,"pu":11079104411954,"b":[["14149.90","0.602"],["14349.90","0.952"],["14449.90","1.848"],["14549.90","0.798"],["58184.90","0.002"],["61417.50","0.013"],["63577.30","9.693"],["63688.30","0.466"],["63917.90","0.781"],["64003.40","0.002"],["64326.70","1.099"],["64449.90","0.000"],["64495.70","0.720"],["64638.30","0.002"],["64649.90","11.428"]],"a":[["64802.00","0.991"],["65296.50","0.032"],["65393.70","8.172"],["65394.10","2.844"]],"st":1}}
{"stream":"btcusdt@depth@100ms","data":{"e":"depthUpdate","E":1784410659228,"T":1784410659227,"s":"BTCUSDT","ps":"BTCUSDT","U":11079104417799,"u":11079104423178,"pu":11079104417754,"b":[["1000.00","50.241"],["14149.90","0.490"],["14349.90","1.190"],["14449.90","1.610"],["14549.90","0.910"],["58184.90","0.002"],["61417.40","0.006"],["61417.50","0.013"],["62063.90","0.693"],["64003.40","0.000"],["64449.90","0.000"],["64478.60","0.002"],["64495.70","0.000"]],"a":[["64655.10","0.048"],["64656.40","0.001"],["64656.50","0.053"],["64656.60","0.002"],["64656.80","0.032"],["64657.10","0.154"],["64660.10","0.723"],["64802.00","0.000"],["64819.10","0.001"],["65296.50","0.032"],["65394.10","3.759"],["65776.40","7.288"]],"st":1}}
{"stream":"btcusdt@depth@100ms","data":{"e":"depthUpdate","E":1784410659330,"T":1784410659329,"s":"BTCUSDT","ps":"BTCUSDT","U":11079104423223,"u":11079104428835,"pu":11079104423178,"b":[["1000.00","50.241"],["14149.90","0.364"],["14349.90","1.428"],["14449.90","1.372"],["14549.90","1.036"],["51720.00","0.004"],["58184.90","0.002"],["62063.90","0.690"],["63790.70","1.879"],["64003.40","0.000"],["64478.50","0.725"],["64488.30","0.037"],["64495.70","0.000"],["64649.90","11.407"]],"a":[["64656.30","0.544"],["64656.40","0.155"],["64656.50","0.080"],["64656.60","0.002"],["64660.10","0.001"],["64802.00","0.000"],["64819.10","0.870"],["65296.50","0.032"],["65393.70","6.356"],["65394.10","4.675"],["65425.70","1.369"]],"st":1}}
{"stream":"btcusdt@depth@100ms","data":{"e":"depthUpdate","E":1784410659432,"T":1784410659428,"s":"BTCUSDT","ps":"BTCUSDT","U":11079104428927,"u":11079104433416,"pu":11079104428835,"b":[["14149.90","0.252"],["14349.90","1.666"],["14449.90","1.134"],["14549.90","1.148"],["58184.90","0.002"],["61417.50","0.011"],["62063.90","0.693"],["63357.00","0.017"],["63576.70","0.002"],["63731.90","5.362"],["63738.30","3.133"],["63877.90","0.000"],["64003.40","0.000"],["64326.70","1.089"],["64495.70","0.718"],["64613.10","0.227"],["64634.00","0.376"],["64636.30","0.274"],["64636.90","1.039"],["64637.60","0.001"],["64637.90","0.700"],["64638.80","0.093"],["64649.90","11.348"]],"a":[["64653.80","1.275"],["64654.00","0.008"],["64654.20","0.000"],["64654.40","0.001"],["64656.30","0.003"],["64656.40","0.001"],["64656.50","0.053"],["64660.10","0.723"],["64678.40","0.410"],["64679.00","0.558"],["64802.00","0.991"],["65296.50","0.032"],["65296.60","0.002"],["65394.10","5.591"]],"st":1}}
{"stream":"btcusdt@depth@100ms","data":{"e":"depthUpdate","E":1784410659534,"T":1784410659533,"s":"BTCUSDT","ps":"BTCUSDT","U":11079104433722,"u":11079104438017,"pu":11079104433416,"b":[["1000.00","50.241"],["14149.90","0.126"],["14349.90","1.904"],["14449.90","0.896"],["14549.90","1.274"],["58184.90","0.002"],["62063.90","0.690"],["64003.40","0.000"],["64449.90","0.000"],["64603.00","0.001"],["64622.90","0.467"],["64649.90","11.306"]],"a":[["64681.60","0.004"],["65296.50","0.032"],["65394.10","7.423"],["65425.70","0.760"],["65561.60","2.284"]],"st":1}}
{"stream":"btcusdt@depth@100ms","data":{"e":"depthUpdate","E":1784410659636,"T":1784410659634,"s":"BTCUSDT","ps":"BTCUSDT","U":11079104438092,"u":11079104442941,"pu":11079104438017,"b":[["1000.00","50.241"],["14149.90","0.014"],["14249.90","0.070"],["14349.90","2.002"],["14449.90","0.728"],["14549.90","1.386"],["51720.00","0.004"],["58184.90","0.002"],["63549.10","1.367"],["63798.80","2.582"],["64003.40","0.000"],["64449.90","0.000"],["64495.70","0.713"],["64633.00","0.215"],["64636.20","0.522"],["64649.90","11.268"]],"a":[["64657.10","0.107"],["64657.60","0.051"],["64668.70","0.005"],["64802.00","1.072"],["65260.00","0.045"],["65296.50","0.032"],["65425.80","25.452"],["65942.90","0.642"]],"st":1}}
{"stream":"btcusdt@depth@100ms","data":{"e":"depthUpdate","E":1784410659738,"T":1784410659737,"s":"BTCUSDT","ps":"BTCUSDT","U":11079104443425,"u":11079104450585,"pu":11079104442941,"b":[["14149.90","0.000"],["14249.90","0.196"],["14349.90","1.988"],["14449.90","0.728"],["14549.90","1.288"],["51720.00","0.004"],["58184.90","0.002"],["62063.90","0.693"],["63880.60","5.628"],["63938.70","3.357"],["64003.40","0.000"],["64326.70","1.099"],["64449.90","0.000"],["64495.70","0.713"],["64518.00","0.000"],["64518.10","0.540"],["64518.60","3.875"],["64579.30","0.046"]],"a":[["64650.00","1.783"],["64657.60","0.004"],["64658.10","0.064"],["64681.60","0.081"],["64708.00","0.074"],["64721.60","0.048"],["64721.70","0.003"],["64775.30","0.000"],["64775.50","3.947"],["64802.00","1.072"],["64850.00","25.940"],["65296.50","0.032"],["65425.80","26.061"],["65652.10","7.917"],["65659.90","0.017"],["65967.50","0.004"]],"st":1}}
{"stream":"btcusdt@depth@100ms","data":{"e":"depthUpdate","E":1784410659840,"T":1784410659839,"s":"BTCUSDT","ps":"BTCUSDT","U":11079104450784,"u":11079104454944,"pu":11079104450585,"b":[["1000.00","50.241"],["14249.90","0.308"],["14349.90","2.002"],["14449.90","0.714"],["14549.90","1.176"],["51720.00","0.004"],["58184.90","0.002"],["62063.90","0.690"],["63777.10","4.299"],["63874.10","25.652"],["64003.40","0.000"],["64622.00","0.050"],["64624.70","10.882"],["64628.70","0.000"],["64633.00","0.061"],["64636.30","0.158"],["64636.90","0.319"],["64637.10","0.293"],["64640.00","0.420"],["64649.90","11.428"]],"a":[["64650.00","2.097"],["64657.10","0.094"],["64658.80","0.013"],["64681.60","0.004"],["65296.50","0.036"]],"st":1}}
{"stream":"btcusdt@depth@100ms","data":{"e":"depthUpdate","E":1784410659942,"T":1784410659941,"s":"BTCUSDT","ps":"BTCUSDT","U":11079104454952,"u":11079104458886,"pu":11079104454944,"b":[["1000.00","50.241"],["14249.90","0.434"],["14349.90","1.988"],["14449.90","0.728"],["14549.90","1.050"],["58184.90","0.002"],["61417.50","0.009"],["62063.90","0.693"],["63790.70","1.332"],["63841.80","7.576"],["63853.20","2.346"],["63860.50","2.314"],["64003.40","0.000"],["64043.00","1.641"],["64076.30","0.000"],["64326.60","3.420"],["64378.40","0.000"],["64381.60","0.117"],["64485.00","0.158"],["64488.30","0.193"],["64535.90","0.000"],["64537.40","0.491"],["64538.90","0.004"],["64540.40","0.202"],["64541.90","0.000"],["64543.40","0.000"],["64544.90","0.000"],["64546.40","1.832"],["64596.50","0.004"],["64598.70","20.571"],["64600.90","0.146"],["64601.00","0.006"],["64630.10","0.385"],["64633.00","0.215"],["64649.90","11.427"]],"a":[["64650.00","2.099"],["64669.10","0.002"],["64669.20","0.048"],["64669.30","0.310"],["64685.50","0.019"],["64685.60","0.001"],["64685.70","0.121"],["64686.00","0.017"],["64686.10","0.050"],["64686.20","0.114"],["65296.50","0.032"],["65724.60","0.000"],["65942.90","0.639"]],"st":1}}
{"stream":"btcusdt@depth@100ms","data":{"e":"depthUpdate","E":1784410660044,"T":1784410660043,"s":"BTCUSDT","ps":"BTCUSDT","U":11079104458928,"u":11079104464450,"pu":11079104458886,"b":[["14249.90","0.546"],["14349.90","2.002"],["14449.90","0.714"],["14549.90","0.938"],["51719.90","0.000"],["58184.90","0.002"],["63563.10","5.186"],["63751.30","5.605"],["63777.80","7.106"],["63917.90","1.562"],["64003.40","0.000"],["64326.70","1.099"],["64449.90","0.000"],["64495.70","0.718"],["64557.00","0.001"],["64562.60","0.349"],["64598.80","3.175"],["64622.00","0.744"],["64626.90","2.753"],["64636.70","1.967"],["64636.90","1.039"],["64637.10","0.177"],["64638.20","0.053"],["64640.00","1.060"],["64649.90","11.344"]],"a":[["64650.00","2.247"],["64656.00","0.008"],["64656.30","0.003"],["64656.50","0.053"],["64656.80","0.079"],["64657.10","0.106"],["64658.80","0.001"],["64742.90","0.357"],["64745.60","1.053"],["64746.00","0.002"],["64801.90","1.099"],["64802.00","0.000"],["64973.30","0.926"],["65296.50","0.032"],["65716.70","3.192"],["66294.20","0.000"]],"st":1}}
{"stream":"btcusdt@depth@100ms","data":{"e":"depthUpdate","E":1784410660146,"T":1784410660145,"s":"BTCUSDT","ps":"BTCUSDT","U":11079104464494,"u":11079104477817,"pu":11079104464450,"b":[["1000.00","50.241"],["14249.90","0.672"],["14349.90","1.988"],["14449.90","0.728"],["14549.90","0.812"],["58184.90","0.002"],["61417.40","0.004"],["61417.50","0.013"],["62063.90","0.690"],["64003.40","0.000"],["64016.30","1.012"],["64068.00","1.325"],["64317.70","0.007"],["64324.00","0.000"],["64546.40","0.556"],["64564.50","0.002"],["64567.10","0.013"],["64569.70","0.005"],["64590.30","0.414"],["64592.40","0.210"],["64599.70","0.001"],["64617.50","2.204"],["64619.10","0.121"],["64624.40","0.007"],["64626.30","0.448"],["64633.20","2.008"],["64638.20","0.048"],["64649.90","11.345"]],"a":[["64650.00","1.683"],["64653.20","0.005"],["64653.70","0.131"],["64655.10","0.635"],["64656.60","0.002"],["64656.80","0.032"],["64658.00","0.001"],["64658.20","0.127"],["64658.50","0.180"],["64659.30","0.005"],["64662.20","0.018"],["64662.80","0.002"],["64664.10","0.154"],["64665.70","0.473"],["64670.00","0.151"],["64676.80","0.065"],["64683.60","0.015"],["64685.80","0.060"],["64688.60","0.047"],["64800.20","0.001"],["64807.10","0.009"],["64973.10","0.960"],["65167.10","0.000"],["65296.50","0.032"],["65942.90","0.636"],["66268.40","2.185"]],"st":1}}
{"stream":"btcusdt@depth@100ms","data":{"e":"depthUpdate","E":1784410660248,"T":1784410660245,"s":"BTCUSDT","ps":"BTCUSDT","U":11079104478071,"u":11079104486736,"pu":11079104477817,"b":[["1000.00","50.241"],["14249.90","0.784"],["14349.90","2.002"],["14449.90","0.714"],["14549.90","0.700"],["58184.90","0.002"],["62063.90","0.693"],["63536.60","4.244"],["64003.40","0.000"],["64449.90","0.000"],["64564.50","0.006"],["64567.10","0.017"],["64624.70","0.882"],["64626.90","1.466"],["64632.00","0.733"],["64633.00","0.061"],["64633.80","4.514"],["64637.80","0.759"],["64637.90","0.143"],["64638.00","0.085"],["64638.50","0.056"],["64638.90","0.752"]],"a":[["64650.00","1.684"],["64653.70","0.131"],["64655.10","0.048"],["64656.60","0.315"],["64657.10","0.094"],["64657.60","0.004"],["64657.70","0.519"],["64658.80","0.013"],["64662.30","24.281"],["64669.60","0.541"],["64671.00","0.002"],["64678.10","0.557"],["64679.00","0.002"],["64688.00","1.820"],["64688.50","10.000"],["65296.50","0.032"],["65593.60","8.924"],["65942.90","0.639"]],"st":1}}
{"stream":"btcusdt@depth@100ms","data":{"e":"depthUpdate","E":1784410660350,"T":1784410660349,"s":"BTCUSDT","ps":"BTCUSDT","U":11079104486918,"u":11079104493200,"pu":11079104486736,"b":[["14249.90","1.008"],["14349.90","1.792"],["14449.90","0.826"],["14549.90","0.574"],["58184.90","0.002"],["62063.90","0.690"],["64003.40","0.000"],["64326.60","3.575"],["64326.70","1.099"],["64463.70","0.043"],["64537.40","0.491"],["64538.90","0.004"],["64540.40","0.000"],["64540.50","0.589"],["64541.90","0.000"],["64543.40","0.000"],["64544.90","0.000"],["64546.40","0.556"],["64547.90","0.000"],["64549.40","1.311"],["64598.70","0.002"],["64598.80","0.000"],["64600.90","20.715"],["64633.00","0.215"],["64639.40","0.121"]],"a":[["64653.70","0.131"],["64657.60","0.004"],["64662.30","24.234"],["64662.60","0.058"],["64843.80","0.001"],["64973.20","2.996"],["65167.20","7.560"],["65296.50","0.032"],["65496.60","3.023"],["65955.10","0.000"],["66137.00","0.878"]],"st":1}}
{"stream":"btcusdt@depth@100ms","data":{"e":"depthUpdate","E":1784410660452,"T":1784410660449,"s":"BTCUSDT","ps":"BTCUSDT","U":11079104493380,"u":11079104499844,"pu":11079104493200,"b":[["1000.00","50.241"],["14249.90","1.246"],["14349.90","1.554"],["14449.90","0.938"],["14549.90","0.462"],["58184.90","0.002"],["62063.90","0.693"],["63917.90","2.343"],["64003.40","0.000"],["64035.70","5.132"],["64062.40","9.937"],["64463.70","0.047"],["64478.50","0.728"],["64495.70","0.720"],["64540.50","0.006"],["64549.40","0.035"],["64629.40","0.002"],["64631.50","1.220"]],"a":[["64650.00","2.151"],["64653.70","0.718"],["64657.60","0.161"],["64659.00","0.312"],["64674.50","1.955"],["64801.90","1.099"],["64819.10","0.939"],["65120.00","1.228"],["65296.50","0.032"],["65515.30","26.707"]],"st":1}}
{"stream":"btcusdt@depth@100ms","data":{"e":"depthUpdate","E":1784410660554,"T":1784410660553,"s":"BTCUSDT","ps":"BTCUSDT","U":11079104500070,"u":11079104506863,"pu":11079104499844,"b":[["1000.00","50.241"],["14249.90","1.484"],["14349.90","1.316"],["14449.90","1.064"],["14549.90","0.336"],["58184.90","0.002"],["63376.30","0.005"],["63874.10","27.527"],["64003.40","0.000"],["64361.00","0.403"],["64633.00","0.215"],["64644.20","0.808"],["64649.90","11.372"]],"a":[["64650.00","1.685"],["64653.40","0.601"],["64653.50","0.201"],["64653.70","0.007"],["64657.60","0.004"],["64662.60","0.011"],["65291.30","9.090"],["65296.50","0.032"],["65552.50","3.279"],["65587.40","18.728"],["65629.90","0.231"]],"st":1}}
{"stream":"btcusdt@depth@100ms","data":{"e":"depthUpdate","E":1784410660656,"T":1784410660653,"s":"BTCUSDT","ps":"BTCUSDT","U":11079104506966,"u":11079104513473,"pu":11079104506863,"b":[["14249.90","1.722"],["14349.90","1.078"],["14449.90","1.176"],["14549.90","0.224"],["51720.00","0.004"],["58184.90","0.002"],["62063.90","0.690"],["63563.80","1.569"],["63777.80","6.199"],["64003.40","0.000"],["64326.70","1.099"],["64557.00","0.000"],["64636.20","0.522"],["64649.90","11.370"]],"a":[["64650.00","1.680"],["64653.40","0.601"],["64653.70","0.007"],["64656.60","0.315"],["64657.60","0.161"],["64662.20","0.574"],["64668.70","0.005"],["64669.10","0.004"],["64669.20","0.050"],["64669.30","0.312"],["64685.50","0.021"],["64685.60","0.003"],["64685.70","0.123"],["64686.00","0.019"],["64686.10","0.052"],["64686.20","0.116"],["64742.90","0.356"],["65296.50","0.032"]],"st":1}}
{"stream":"btcusdt@depth@100ms","data":{"e":"depthUpdate","E":1784410660758,"T":1784410660757,"s":"BTCUSDT","ps":"BTCUSDT","U":11079104513729,"u":11079104520463,"pu":11079104513473,"b":[["1000.00","50.241"],["14249.90","1.960"],["14349.90","0.840"],["14449.90","1.302"],["14549.90","0.098"],["58184.90","0.002"],["62063.90","0.693"],["63841.80","7.966"],["64003.40","0.000"],["64633.00","0.061"],["64639.80","1.254"]],"a":[["64650.00","1.693"],["64653.40","0.014"],["64656.40","0.723"],["64656.50","0.053"],["64656.60","0.002"],["64657.60","0.161"],["64660.10","0.001"],["64665.70","0.426"],["64665.80","0.047"],["65296.50","0.034"],["65490.40","2.185"],["65658.30","0.000"]],"st":1}}
{"stream":"btcusdt@depth@100ms","data":{"e":"depthUpdate","E":1784410660860,"T":1784410660859,"s":"BTCUSDT","ps":"BTCUSDT","U":11079104520536,"u":11079104527272,"pu":11079104520463,"b":[["14149.90","0.098"],["14249.90","2.002"],["14349.90","0.714"],["14449.90","1.386"],["14549.90","0.000"],["58184.90","0.002"],["62063.90","0.690"],["63550.90","5.734"],["64003.40","0.000"],["64378.40","0.117"],["64381.60","0.000"],["64488.30","0.037"],["64633.00","0.215"],["64649.90","11.371"]],"a":[["64650.00","1.729"],["64653.40","0.601"],["64656.30","0.003"],["64656.40","0.001"],["64656.50","1.088"],["64656.60","0.315"],["64660.10","0.001"],["65264.20","3.057"],["65296.50","0.034"],["65389.60","0.229"],["65515.30","26.402"],["65555.10","13.498"]],"st":1}}
{"stream":"btcusdt@depth@100ms","data":{"e":"depthUpdate","E":1784410660962,"T":1784410660961,"s":"BTCUSDT","ps":"BTCUSDT","U":11079104527440,"u":11079104533581,"pu":11079104527272,"b":[["14149.90","0.224"],["14249.90","1.988"],["14349.90","0.728"],["14449.90","1.260"],["51719.90","0.002"],["58184.90","0.002"],["61417.40","0.024"],["62063.90","0.693"],["63369.30","6.824"],["63441.20","2.519"],["63513.00","0.002"],["63584.90","0.000"],["63656.70","0.027"],["63680.20","0.472"],["63726.10","7.607"],["63728.60","0.000"],["63751.30","6.512"],["63800.40","0.000"],["63872.30","0.000"],["63944.10","0.002"],["64003.40","0.000"],["64016.00","0.318"],["64132.70","7.782"],["64326.70","1.099"],["64459.80","0.000"],["64495.60","0.725"],["64495.70","0.000"],["64627.50","0.227"],["64649.90","11.308"]],"a":[["64650.00","1.881"],["64653.40","0.014"],["64656.30","0.003"],["64656.40","0.001"],["64656.50","0.053"],["64656.60","0.315"],["64657.60","0.317"],["64658.20","0.127"],["64658.40","0.120"],["64658.70","1.274"],["64658.90","0.002"],["64659.20","0.281"],["64660.10","0.723"],["64678.10","0.000"],["64678.70","0.557"],["64801.90","1.099"],["65296.50","0.032"],["65309.20","7.890"],["65381.10","0.015"],["65394.10","8.339"],["65452.90","0.005"],["65477.20","2.394"],["65524.80","0.103"],["65596.60","0.012"],["65668.50","0.000"],["65740.30","0.000"],["65749.10","3.109"],["65812.20","0.003"],["65884.00","0.758"],["65955.90","18.381"]],"st":1}}
{"stream":"btcusdt@depth@100ms","data":{"e":"depthUpdate","E":1784410661064,"T":1784410661061,"s":"BTCUSDT","ps":"BTCUSDT","U":11079104533627,"u":11079104539646,"pu":11079104533581,"b":[["1000.00","50.241"],["14149.90","0.336"],["14249.90","2.002"],["14349.90","0.714"],["14449.90","1.148"],["51719.90","0.000"],["58184.90","0.002"],["61417.40","0.004"],["63357.00","0.014"],["64003.40","0.000"],["64463.70","0.043"],["64499.80","0.059"],["64521.50","1.367"],["64601.00","3.458"],["64638.30","0.002"]],"a":[["64653.40","0.601"],["64656.20","0.316"],["64656.30","0.857"],["64656.40","0.314"],["64656.50","0.053"],["64656.60","0.159"],["64657.70","0.504"],["64659.20","0.234"],["64659.50","0.235"],["64660.10","0.182"],["64973.30","0.924"],["65296.50","0.032"],["65593.60","7.858"],["65652.10","8.982"]],"st":1}}
{"stream":"btcusdt@depth@100ms","data":{"e":"depthUpdate","E":1784410661166,"T":1784410661165,"s":"BTCUSDT","ps":"BTCUSDT","U":11079104539863,"u":11079104547330,"pu":11079104539646,"b":[["14149.90","0.462"],["14249.90","1.988"],["14349.90","0.728"],["14449.90","1.022"],["58184.90","0.002"],["61417.40","0.004"],["61417.50","0.011"],["62063.90","0.690"],["63635.10","0.024"],["63764.20","1.643"],["64003.40","0.000"],["64132.70","7.782"],["64326.60","3.577"],["64463.70","0.047"],["64495.60","0.007"],["64633.00","0.061"],["64649.90","11.309"]],"a":[["64653.40","0.601"],["64656.20","0.003"],["64656.30","0.003"],["64656.40","0.001"],["64656.50","0.080"],["64657.60","0.317"],["64658.60","0.154"],["64659.50","0.188"],["64659.70","0.076"],["64659.90","0.541"],["64660.10","0.001"],["64670.80","0.081"],["64671.10","1.299"],["64680.40","0.180"],["64801.90","0.027"],["65296.50","0.032"],["65366.40","0.245"],["65490.40","2.490"],["65664.70","0.011"]],"st":1}}
{"stream":"btcusdt@depth@100ms","data":{"e":"depthUpdate","E":1784410661268,"T":1784410661266,"s":"BTCUSDT","ps":"BTCUSDT","U":11079104547481,"u":11079104553973,"pu":11079104547330,"b":[["14149.90","0.574"],["14249.90","2.002"],["14349.90","0.714"],["14449.90","0.910"],["58184.90","0.002"],["62063.90","0.693"],["63357.00","0.017"],["63699.50","2.352"],["64003.40","0.000"],["64326.70","1.099"],["64478.50","0.000"],["64550.30","0.004"],["64557.60","0.001"],["64585.30","0.132"],["64633.00","0.061"]],"a":[["64653.40","0.014"],["64656.50","0.053"],["64656.60","0.166"],["64657.60","0.317"],["64658.60","0.017"],["64659.80","0.000"],["64681.60","0.004"],["64714.60","0.001"],["64819.10","0.001"],["65256.60","16.176"],["65296.50","0.032"],["65419.30","4.583"],["65587.40","19.794"],["65639.00","0.381"],["65664.80","0.795"]],"st":1}}
{"stream":"btcusdt@depth@100ms","data":{"e":"depthUpdate","E":1784410661370,"T":1784410661369,"s":"BTCUSDT","ps":"BTCUSDT","U":11079104554147,"u":11079104560861,"pu":11079104553973,"b":[["1000.00","50.241"],["14149.90","0.700"],["14249.90","1.988"],["14349.90","0.728"],["14449.90","0.784"],["51720.00","0.004"],["58184.90","0.002"],["62063.90","0.690"],["63750.60","0.000"],["64003.40","0.000"],["64132.70","7.781"],["64441.70","0.000"],["64633.00","0.215"],["64643.70","0.352"],["64644.20","0.576"],["64649.90","11.294"]],"a":[["64650.00","1.896"],["64653.40","0.014"],["64655.10","0.048"],["64656.40","0.696"],["64656.50","0.053"],["64656.60","0.012"],["64657.20","0.074"],["64657.50","0.035"],["64657.60","0.004"],["64658.80","0.001"],["64659.90","0.000"],["64660.10","0.001"],["64683.30","0.411"],["64691.90","0.058"],["64856.00","0.061"],["65296.50","0.032"],["65930.30","3.205"]],"st":1}}
{"stream":"btcusdt@depth@100ms","data":{"e":"depthUpdate","E":1784410661472,"T":1784410661471,"s":"BTCUSDT","ps":"BTCUSDT","U":11079104560977,"u":11079104567754,"pu":11079104560861,"b":[["14149.90","0.826"],["14249.90","1.974"],["14349.90","0.728"],["14449.90","0.672"],["58184.90","0.002"],["61417.40","0.004"],["63500.00","46.181"],["63860.30","2.662"],["64003.40","0.002"],["64553.80","0.000"],["64556.40","0.326"],["64562.60","0.008"],["64633.00","0.061"]],"a":[["64650.00","2.210"],["64656.30","0.050"],["64656.40","0.001"],["64656.60","0.002"],["64658.60","0.000"],["64660.10","0.723"],["64669.60","0.000"],["64671.00","0.543"],["64671.10","0.373"],["64671.80","0.973"],["64684.00","2.557"],["64688.60","0.000"],["64745.70","0.000"],["65232.30","0.230"],["65260.20","0.230"],["65296.50","0.034"],["65419.30","5.499"],["65777.00","1.253"]],"st":1}}
{"stream":"btcusdt@depth@100ms","data":{"e":"depthUpdate","E":1784410661574,"T":1784410661573,"s":"BTCUSDT","ps":"BTCUSDT","U":11079104567765,"u":11079104574276,"pu":11079104567754,"b":[["14149.90","1.064"],["14249.90","1.736"],["14349.90","0.854"],["14449.90","0.546"],["58184.90","0.002"],["62063.90","0.693"],["63357.00","0.020"],["64003.40","0.000"],["64326.70","1.099"],["64441.70","2.130"],["64458.50","0.061"],["64478.50","0.477"],["64485.00","0.499"],["64495.60","0.484"],["64550.30","0.000"],["64553.70","5.933"],["64560.00","1.341"],["64589.30","0.022"],["64633.00","0.215"],["64637.80","0.202"],["64638.00","0.642"],["64639.00","0.066"]],"a":[["64650.00","2.211"],["64650.10","0.016"],["64653.30","0.130"],["64653.40","0.014"],["64653.50","0.077"],["64653.70","0.594"],["64656.30","0.003"],["64656.50","1.088"],["64656.60","0.315"],["64656.90","0.003"],["64657.60","0.317"],["64659.70","0.029"],["64660.10","0.001"],["64662.30","24.281"],["64669.60","0.541"],["64671.00","0.002"],["64671.70","0.324"],["64672.50","0.096"],["64678.70","0.001"],["64679.20","0.556"],["64688.00","0.388"],["64688.50","0.000"],["64709.50","0.002"],["64745.60","4.041"],["64801.90","0.697"],["64819.00","0.582"],["64824.70","0.036"],["64840.70","0.208"],["64855.90","2.329"],["64886.00","2.288"],["65296.50","0.032"],["65385.90","13.726"],["65427.70","2.634"],["65619.80","1.473"]],"st":1}}
{"stream":"btcusdt@depth@100ms","data":{"e":"depthUpdate","E":1784410661676,"T":1784410661674,"s":"BTCUSDT","ps":"BTCUSDT","U":11079104574335,"u":11079104580842,"pu":11079104574276,"b":[["1000.00","50.241"],["14149.90","1.302"],["14249.90","1.498"],["14349.90","0.966"],["14449.90","0.434"],["58184.90","0.002"],["62063.90","0.690"],["63764.20","2.190"],["63841.80","8.231"],["64003.40","0.000"],["64132.70","7.470"],["64630.80","0.001"],["64636.20","0.522"],["64649.90","11.231"]],"a":[["64650.00","2.059"],["64653.70","0.007"],["64656.40","0.314"],["64656.50","0.775"],["64656.60","0.002"],["64658.70","1.274"],["64659.00","0.312"],["64659.20","0.234"],["64659.40","0.000"],["64659.70","0.076"],["64662.30","24.234"],["64663.00","0.032"],["64668.70","0.005"],["64671.70","0.015"],["64672.40","0.310"],["64674.50","1.956"],["64681.60","0.081"],["65236.40","0.693"],["65296.50","0.032"],["65425.80","21.482"]],"st":1}}
{"stream":"btcusdt@depth@100ms","data":{"e":"depthUpdate","E":1784410661778,"T":1784410661777,"s":"BTCUSDT","ps":"BTCUSDT","U":11079104580993,"u":11079104587266,"pu":11079104580842,"b":[["14149.90","1.540"],["14249.90","1.260"],["14349.90","1.092"],["14449.90","0.308"],["51720.00","0.004"],["58184.90","0.002"],["61417.40","0.004"],["62063.90","0.693"],["64003.40","0.000"],["64458.50","0.061"],["64463.70","0.047"],["64535.90","0.000"],["64537.40","0.491"],["64538.90","0.004"],["64540.40","0.000"],["64541.90","0.000"],["64543.40","0.000"],["64544.90","0.000"],["64546.40","0.556"],["64547.90","0.000"],["64549.40","1.311"],["64550.90","1.290"],["64578.90","0.031"],["64579.00","0.371"],["64579.20","0.004"],["64579.50","0.125"],["64579.90","0.000"],["64580.20","0.009"],["64587.00","11.598"],["64598.30","0.427"],["64598.60","0.582"],["64598.80","0.074"],["64598.90","0.166"],["64599.30","0.000"],["64599.40","0.074"],["64599.60","0.034"],["64599.70","0.075"],["64600.00","1.087"],["64613.90","1.238"],["64614.00","0.741"],["64614.20","0.012"],["64614.50","0.005"],["64614.60","0.000"],["64615.10","0.386"],["64615.20","0.584"],["64617.80","0.027"],["64633.00","0.061"],["64636.50","0.001"],["64636.60","0.000"],["64636.70","1.847"],["64636.90","0.727"],["64637.00","0.916"],["64637.10","0.369"],["64637.20","0.083"],["64637.30","0.157"],["64637.50","0.003"],["64637.60","0.369"],["64637.80","0.003"],["64637.90","0.005"],["64638.10","0.305"],["64638.20","0.109"],["64638.40","1.405"],["64638.60","0.696"],["64638.90","0.813"],["64649.90","11.230"]],"a":[["64650.00","2.211"],["64653.70","0.594"],["64656.30","0.035"],["64656.40","0.001"],["64656.50","0.178"],["64656.60","0.315"],["64656.70","1.308"],["64656.80","0.000"],["64657.00","0.037"],["64657.10","0.002"],["64657.20","0.014"],["64657.50","0.003"],["64657.60","0.409"],["64657.70","0.384"],["64657.80","0.004"],["64658.00","0.061"],["64658.10","0.004"],["64658.20","0.067"],["64658.30","0.184"],["64658.40","0.000"],["64658.50","0.000"],["64660.10","0.723"],["64669.00","0.016"],["64675.70","0.032"],["64675.90","0.975"],["64676.00","0.001"],["64676.10","0.331"],["64676.20","0.016"],["64676.40","0.114"],["64676.60","0.032"],["64676.90","0.213"],["64677.10","0.071"],["64677.20","0.341"],["64679.80","0.120"],["64680.20","1.850"],["64680.30","0.108"],["64680.40","0.000"],["64680.50","2.436"],["64680.70","0.060"],["64680.80","0.040"],["64680.90","0.120"],["64681.00","0.122"],["64681.10","0.015"],["64681.60","0.004"],["64695.30","0.000"],["64695.70","0.069"],["64696.00","0.003"],["64696.30","0.000"],["64696.60","0.091"],["64714.30","0.015"],["64721.50","0.001"],["64725.00","0.011"],["65296.50","0.032"],["65425.80","21.940"],["65550.00","7.415"],["65555.20","3.777"],["65593.60","6.792"],["65722.90","0.000"],["65750.40","1.323"]],"st":1}}
{"stream":"btcusdt@depth@100ms","data":{"e":"depthUpdate","E":1784410661880,"T":1784410661879,"s":"BTCUSDT","ps":"BTCUSDT","U":11079104587330,"u":11079104594070,"pu":11079104587266,"b":[["1000.00","50.241"],["14149.90","1.778"],["14249.90","1.022"],["14349.90","1.204"],["14449.90","0.196"],["58184.90","0.002"],["61417.40","0.006"],["62063.90","0.690"],["64003.40","0.000"],["64132.70","7.780"],["64326.70","1.099"],["64478.50","0.000"],["64495.60","0.007"],["64637.30","0.313"],["64637.70","0.157"],["64638.20","0.247"]],"a":[["64650.00","2.220"],["64650.10","0.006"],["64653.70","0.594"],["64657.00","0.097"],["64657.60","0.469"],["64658.00","0.121"],["64659.70","0.029"],["64662.10","0.051"],["64678.30","0.558"],["64679.20","0.000"],["64679.70","0.070"],["64680.30","0.168"],["64680.70","0.120"],["64801.90","0.027"],["64819.00","0.000"],["65296.50","0.032"],["65361.10","2.600"],["65555.10","15.783"],["65930.10","0.710"]],"st":1}}
{"stream":"btcusdt@depth@100ms","data":{"e":"depthUpdate","E":1784410661982,"T":1784410661981,"s":"BTCUSDT","ps":"BTCUSDT","U":11079104594075,"u":11079104601924,"pu":11079104594070,"b":[["1000.00","50.241"],["14149.90","1.988"],["14249.90","0.798"],["14349.90","1.330"],["14449.90","0.070"],["14549.90","0.014"],["51719.90","0.000"],["58184.90","0.002"],["61417.40","0.004"],["63512.00","0.000"],["63645.30","3.286"],["64003.40","0.002"],["64441.70","0.000"],["64549.40","0.035"],["64550.90","0.014"],["64553.10","0.000"],["64560.00","1.341"],["64599.10","0.067"],["64604.40","0.070"],["64612.70","0.020"],["64633.00","0.215"],["64637.00","1.072"],["64637.10","0.489"],["64637.70","0.313"],["64637.90","0.072"],["64638.30","0.140"],["64640.70","0.058"],["64640.80","0.121"],["64642.50","0.006"],["64643.40","0.005"],["64643.80","0.010"],["64644.50","2.603"],["64644.60","0.551"],["64645.30","0.967"],["64645.40","1.591"],["64649.90","11.231"]],"a":[["64650.00","2.058"],["64650.10","0.002"],["64653.70","0.007"],["64656.50","0.021"],["64656.60","0.002"],["64657.00","0.157"],["64657.30","0.034"],["64657.60","0.529"],["64657.80","0.002"],["64658.10","0.064"],["64658.30","0.244"],["64662.10","0.004"],["64662.60","0.011"],["64662.90","0.357"],["64676.70","0.047"],["64679.60","1.259"],["64680.30","0.228"],["64680.70","0.180"],["64681.00","0.182"],["64855.90","0.152"],["65296.50","0.032"],["65425.80","26.519"],["65612.70","3.042"],["65627.70","8.982"]],"st":1}}
{"stream":"btcusdt@depth@100ms","data":{"e":"depthUpdate","E":1784410662084,"T":1784410662081,"s":"BTCUSDT","ps":"BTCUSDT","U":11079104601965,"u":11079104608212,"pu":11079104601924,"b":[["14149.90","2.002"],["14249.90","0.714"],["14349.90","1.358"],["14449.90","0.000"],["14549.90","0.126"],["58184.90","0.002"],["62063.90","0.693"],["63635.10","0.013"],["64003.40","0.000"],["64441.70","3.353"],["64478.50","0.720"],["64495.60","0.720"],["64556.40","1.222"],["64579.30","0.120"],["64580.00","0.166"],["64580.30","0.077"],["64580.60","2.147"],["64587.80","2.996"],["64633.00","0.061"],["64633.20","0.008"],["64637.60","0.519"],["64637.70","0.493"],["64638.30","0.140"],["64649.90","11.229"]],"a":[["64651.90","0.005"],["64653.70","0.007"],["64656.60","0.589"],["64657.60","0.336"],["64658.80","0.048"],["64677.10","0.191"],["64695.20","0.061"],["64695.50","0.344"],["64695.80","0.032"],["64696.50","0.357"],["64801.90","1.047"],["64819.00","0.882"],["64855.90","3.558"],["65296.50","0.032"],["65490.40","2.795"],["65587.40","20.860"],["65600.40","2.515"],["65620.20","0.342"],["65664.70","0.000"],["65716.70","4.256"]],"st":1}}
{"stream":"btcusdt@depth@100ms","data":{"e":"depthUpdate","E":1784410662186,"T":1784410662184,"s":"BTCUSDT","ps":"BTCUSDT","U":11079104608546,"u":11079104615793,"pu":11079104608212,"b":[["1000.00","50.241"],["14149.90","1.988"],["14249.90","0.728"],["14349.90","1.232"],["14549.90","0.252"],["51720.00","0.004"],["58184.90","0.002"],["61417.50","0.013"],["62063.90","0.690"],["63365.10","0.147"],["63437.00","0.477"],["63484.90","1.369"],["63508.80","0.650"],["63580.70","0.147"],["63635.10","0.024"],["63652.50","0.148"],["63724.30","0.149"],["63796.20","0.147"],["63868.00","0.147"],["63939.90","0.538"],["64003.40","0.000"],["64011.70","6.335"],["64326.60","3.575"],["64326.70","1.089"],["64378.40","0.000"],["64463.70","0.043"],["64485.00","0.343"],["64488.30","0.193"],["64596.50","20.390"],["64600.90","0.146"],["64604.40","0.010"],["64612.70","0.080"],["64614.30","0.922"],["64614.40","0.210"],["64614.60","0.156"],["64614.90","0.194"],["64615.00","1.142"],["64625.80","10.169"],["64626.90","2.761"],["64638.00","0.085"],["64638.10","0.862"],["64639.00","0.066"]],"a":[["64650.00","2.222"],["64653.60","0.310"],["64655.70","0.049"],["64655.80","0.003"],["64656.00","0.008"],["64656.30","0.035"],["64656.40","0.001"],["64656.50","0.021"],["64656.60","0.002"],["64657.70","0.372"],["64660.10","0.723"],["64669.60","0.541"],["64671.70","0.015"],["64678.30","0.002"],["64679.20","0.556"],["64685.80","0.013"],["65296.50","0.032"],["65304.90","0.147"],["65376.70","0.147"],["65448.60","0.147"],["65520.40","0.147"],["65592.30","0.147"],["65631.70","0.002"],["65664.10","0.147"],["65735.90","0.151"],["65807.80","0.151"],["65879.60","0.147"],["65951.50","1.501"]],"st":1}}
{"stream":"btcusdt@depth@100ms","data":{"e":"depthUpdate","E":1784410662288,"T":1784410662287,"s":"BTCUSDT","ps":"BTCUSDT","U":11079104615944,"u":11079104621713,"pu":11079104615793,"b":[["1000.00","50.241"],["14149.90","2.002"],["14249.90","0.714"],["14349.90","1.120"],["14549.90","0.364"],["51720.00","0.004"],["58184.90","0.002"],["61417.40","0.004"],["62063.90","0.693"],["63647.80","8.784"],["64003.40","0.000"],["64381.60","0.117"],["64485.00","0.499"],["64579.70","0.222"],["64596.50","0.004"],["64598.70","20.528"],["64601.00","0.006"],["64614.30","1.078"],["64614.60","0.312"],["64615.00","1.448"],["64615.60","0.141"],["64633.00","0.215"]],"a":[["64653.50","0.077"],["64656.50","0.021"],["64656.60","0.002"],["64657.60","0.493"],["64696.10","0.033"],["64973.30","0.926"],["65256.60","15.946"],["65296.50","0.032"],["65664.80","0.806"]],"st":1}}
{"stream":"btcusdt@depth@100ms","data":{"e":"depthUpdate","E":1784410662390,"T":1784410662389,"s":"BTCUSDT","ps":"BTCUSDT","U":11079104621817,"u":11079104628229,"pu":11079104621713,"b":[["14149.90","1.988"],["14249.90","0.728"],["14349.90","0.994"],["14549.90","0.490"],["58184.90","0.002"],["61417.40","0.006"],["61417.50","0.011"],["64003.40","0.000"],["64326.70","0.934"],["64614.40","0.330"],["64615.60","0.279"]],"a":[["64653.50","0.664"],["64656.50","0.178"],["64656.60","0.315"],["64670.20","0.929"],["64671.80","0.047"],["64681.70","0.101"],["64973.20","2.842"],["65167.20","7.254"],["65296.50","0.032"]],"st":1}}
{"stream":"btcusdt@depth@100ms","data":{"e":"depthUpdate","E":1784410662492,"T":1784410662491,"s":"BTCUSDT","ps":"BTCUSDT","U":11079104628274,"u":11079104634178,"pu":11079104628229,"b":[["1000.00","50.241"],["14149.90","2.002"],["14249.90","0.714"],["14349.90","0.882"],["14549.90","0.602"],["58184.90","0.002"],["61417.40","0.006"],["62063.90","0.690"],["63709.90","3.299"],["63824.90","3.908"],["64003.40","0.000"],["64326.70","0.944"],["64485.00","0.158"],["64562.60","0.349"],["64613.50","2.066"],["64618.20","0.182"],["64618.30","0.583"],["64621.40","0.348"],["64636.20","0.638"],["64636.70","1.731"],["64637.70","1.419"],["64638.40","0.479"],["64639.20","0.005"]],"a":[["64650.00","2.277"],["64653.50","0.664"],["64656.50","0.178"],["64659.50","0.186"],["64679.60","1.261"],["64681.60","0.081"],["64681.70","0.024"],["64886.00","2.171"],["64973.20","2.996"],["65167.20","7.559"],["65296.50","0.032"],["65942.90","0.642"]],"st":1}}
{"stream":"btcusdt@depth@100ms","data":{"e":"depthUpdate","E":1784410662594,"T":1784410662593,"s":"BTCUSDT","ps":"BTCUSDT","U":11079104634261,"u":11079104640810,"pu":11079104634178,"b":[["1000.00","50.241"],["14149.90","1.988"],["14249.90","0.728"],["14349.90","0.756"],["14549.90","0.728"],["51720.00","0.006"],["58184.90","0.002"],["61417.40","0.006"],["62063.90","0.693"],["63889.60","3.127"],["64003.40","0.000"],["64062.40","9.237"],["64326.60","3.730"],["64495.60","0.007"],["64621.40","0.352"],["64637.30","0.870"],["64638.10","0.305"],["64639.20","0.003"],["64639.30","0.001"],["64643.00","0.006"],["64643.10","0.005"]],"a":[["64650.00","2.272"],["64653.50","0.077"],["64655.10","0.048"],["64655.70","0.002"],["64656.50","0.021"],["64656.60","0.002"],["64656.90","0.004"],["64657.00","0.158"],["64657.60","0.336"],["64659.30","0.003"],["64659.50","0.184"],["64679.60","3.032"],["64679.80","10.120"],["64681.60","0.004"],["64801.90","0.027"],["65231.80","1.153"],["65296.50","0.032"],["65942.90","0.645"]],"st":1}}
{"stream":"btcusdt@depth@100ms","data":{"e":"depthUpdate","E":1784410662696,"T":1784410662693,"s":"BTCUSDT","ps":"BTCUSDT","U":11079104640915,"u":11079104646800,"pu":11079104640810,"b":[["14149.90","1.918"],["14249.90","0.756"],["14349.90","0.644"],["14549.90","0.882"],["51720.00","0.004"],["58184.90","0.002"],["61417.40","0.006"],["62063.90","0.690"],["63357.00","0.017"],["63704.30","26.391"],["64003.40","0.000"],["64297.30","0.018"],["64421.30","0.828"],["64478.50","0.000"],["64636.20","0.638"],["64649.90","11.238"]],"a":[["64656.60","0.589"],["64668.70","0.005"],["64669.10","0.002"],["64669.20","0.048"],["64669.30","0.310"],["64681.60","0.081"],["64684.00","0.557"],["64685.50","0.019"],["64685.60","0.001"],["64685.70","0.121"],["64686.00","0.017"],["64686.10","0.050"],["64686.20","0.114"],["64819.00","0.000"],["64948.20","0.000"],["65260.20","0.000"],["65296.50","0.032"],["65389.60","0.000"],["65458.10","9.026"]],"st":1}}
{"stream":"btcusdt@depth@100ms","data":{"e":"depthUpdate","E":1784410662798,"T":1784410662797,"s":"BTCUSDT","ps":"BTCUSDT","U":11079104647098,"u":11079104652938,"pu":11079104646800,"b":[["1000.00","50.241"],["14149.90","1.680"],["14249.90","0.882"],["14349.90","0.518"],["14549.90","1.120"],["58184.90","0.002"],["61417.40","0.006"],["62063.90","0.693"],["63680.20","0.825"],["63712.50","22.564"],["63795.90","0.782"],["64003.40","0.000"],["64326.70","0.944"],["64633.00","0.061"]],"a":[["64656.60","0.589"],["64681.60","0.004"],["65296.50","0.032"],["65458.10","9.284"],["65485.40","3.162"],["65587.40","19.794"]],"st":1}}
{"stream":"btcusdt@depth@100ms","data":{"e":"depthUpdate","E":1784410662900,"T":1784410662897,"s":"BTCUSDT","ps":"BTCUSDT","U":11079104653043,"u":11079104659254,"pu":11079104652938,"b":[["1000.00","50.241"],["14149.90","1.442"],["14249.90","0.994"],["14349.90","0.406"],["14549.90","1.358"],["58184.90","0.002"],["61417.40","0.006"],["64003.40","0.000"],["64035.70","5.833"],["64421.30","0.833"],["64441.60","3.438"],["64441.70","0.000"],["64478.50","0.728"],["64495.60","0.728"]],"a":[["64656.60","0.589"],["64658.80","0.001"],["64677.70","0.560"],["64679.20","0.000"],["64681.60","0.004"],["64801.90","1.047"],["64819.00","0.881"],["64855.90","3.557"],["65237.10","0.230"],["65296.50","0.032"],["65477.20","2.166"],["65582.40","8.663"],["65841.50","0.000"]],"st":1}}
{"stream":"btcusdt@depth@100ms","data":{"e":"depthUpdate","E":1784410663002,"T":1784410663001,"s":"BTCUSDT","ps":"BTCUSDT","U":11079104659487,"u":11079104665194,"pu":11079104659254,"b":[["14149.90","1.204"],["14249.90","1.120"],["14349.90","0.280"],["14549.90","1.596"],["51719.90","0.000"],["58184.90","0.002"],["62063.90","0.690"],["63874.10","26.825"],["64003.40","0.000"],["64550.60","0.000"],["64560.00","1.341"],["64633.00","0.215"]],"a":[["64656.60","0.589"],["64681.60","0.081"],["65296.50","0.032"],["65366.30","0.521"]],"st":1}}
{"stream":"btcusdt@depth@100ms","data":{"e":"depthUpdate","E":1784410663104,"T":1784410663103,"s":"BTCUSDT","ps":"BTCUSDT","U":11079104665316,"u":11079104671933,"pu":11079104665194,"b":[["1000.00","50.241"],["14149.90","0.966"],["14249.90","1.232"],["14349.90","0.168"],["14549.90","1.834"],["58184.90","0.002"],["61417.40","0.008"],["61417.50","0.009"],["62063.90","0.693"],["64003.40","0.000"],["64297.30","0.023"],["64326.70","0.944"],["64540.40","0.202"],["64564.50","0.002"],["64598.80","3.233"],["64638.30","0.140"]],"a":[["64656.60","0.002"],["64660.00","0.302"],["64742.90","0.833"],["65296.50","0.032"],["65458.10","9.398"],["65543.10","0.461"],["65815.00","1.372"]],"st":1}}
{"stream":"btcusdt@depth@100ms","data":{"e":"depthUpdate","E":1784410663206,"T":1784410663205,"s":"BTCUSDT","ps":"BTCUSDT","U":11079104672046,"u":11079104678192,"pu":11079104671933,"b":[["1000.00","50.241"],["14149.90","0.770"],["14249.90","1.358"],["14349.90","0.042"],["14449.90","0.042"],["14549.90","1.988"],["58184.90","0.002"],["61417.40","0.008"],["62063.90","0.690"],["63731.90","5.635"],["63841.80","8.496"],["63874.10","27.527"],["64003.40","0.001"],["64381.60","0.000"],["64441.60","2.837"],["64478.50","0.580"],["64495.60","0.574"],["64635.70","0.116"],["64636.20","0.522"],["64649.90","11.237"]],"a":[["64650.00","2.106"],["64653.50","0.077"],["64656.60","0.002"],["64660.00","0.255"],["64681.60","0.004"],["64801.90","1.002"],["64819.00","0.842"],["64855.90","3.585"],["65296.50","0.032"],["65649.40","1.217"]],"st":1}}
{"stream":"btcusdt@depth@100ms","data":{"e":"depthUpdate","E":1784410663308,"T":1784410663307,"s":"BTCUSDT","ps":"BTCUSDT","U":11079104678274,"u":11079104685621,"pu":11079104678192,"b":[["14149.90","0.714"],["14249.90","1.330"],["14349.90","0.000"],["14449.90","0.154"],["14549.90","2.002"],["51720.00","0.004"],["58184.90","0.002"],["62063.90","0.693"],["64003.40","0.001"],["64326.60","3.732"],["64381.60","0.117"],["64485.00","0.002"],["64564.80","0.464"],["64637.30","0.313"],["64637.80","0.560"],["64638.60","0.696"],["64649.90","11.235"]],"a":[["64650.00","1.806"],["64653.70","0.007"],["64656.60","0.002"],["64657.60","0.336"],["64659.60","0.003"],["64659.80","0.000"],["64659.90","0.000"],["64660.20","0.465"],["64660.40","4.220"],["64660.60","0.000"],["64660.80","0.160"],["64661.00","0.002"],["64661.20","0.000"],["64661.40","0.001"],["64661.70","0.018"],["64661.90","0.359"],["64662.90","0.310"],["64670.20","0.003"],["64671.40","0.929"],["64677.70","0.003"],["64678.80","0.666"],["64679.60","1.265"],["64679.80","0.120"],["64684.00","2.557"],["64685.80","0.060"],["64973.30","0.924"],["65296.50","0.032"],["65786.90","0.771"]],"st":1}}
{"stream":"btcusdt@depth@100ms","data":{"e":"depthUpdate","E":1784410663410,"T":1784410663409,"s":"BTCUSDT","ps":"BTCUSDT","U":11079104685763,"u":11079104692756,"pu":11079104685621,"b":[["1000.00","50.241"],["14149.90","0.728"],["14249.90","1.204"],["14449.90","0.280"],["14549.90","1.988"],["51720.00","0.004"],["58184.90","0.002"],["61417.40","0.028"],["61417.50","0.007"],["64003.40","0.001"],["64326.70","0.944"],["64635.70","0.000"],["64636.80","0.131"],["64643.70","0.120"],["64644.10","0.305"]],"a":[["64653.50","0.077"],["64656.50","0.743"],["64656.60","0.315"],["64657.20","0.002"],["64657.50","0.003"],["64657.60","0.336"],["64658.90","0.014"],["64660.10","0.001"],["64661.90","0.312"],["64662.10","0.004"],["64662.50","0.353"],["64662.60","0.011"],["64663.00","0.079"],["64681.60","0.081"],["64995.40","0.768"],["64997.90","0.454"],["65296.50","0.032"],["65522.80","3.728"],["65574.20","3.723"],["65648.10","0.000"],["65652.10","10.046"]],"st":1}}
{"stream":"btcusdt@depth@100ms","data":{"e":"depthUpdate","E":1784410663512,"T":1784410663511,"s":"BTCUSDT","ps":"BTCUSDT","U":11079104692851,"u":11079104699527,"pu":11079104692756,"b":[["1000.00","50.241"],["14149.90","0.714"],["14249.90","1.092"],["14449.90","0.392"],["14549.90","2.002"],["51720.00","0.004"],["58184.90","0.002"],["62063.90","0.690"],["63562.00","1.101"],["63813.00","0.000"],["63963.00","11.192"],["64003.40","0.001"],["64132.70","7.469"],["64642.00","0.002"],["64643.10","0.009"],["64644.20","0.769"],["64649.90","11.260"]],"a":[["64653.50","0.664"],["64656.30","0.035"],["64656.40","0.001"],["64656.50","0.178"],["64657.00","0.160"],["64657.10","0.004"],["64657.60","0.493"],["64660.10","0.723"],["65296.50","0.032"]],"st":1}}
{"stream":"btcusdt@depth@100ms","data":{"e":"depthUpdate","E":1784410663614,"T":1784410663613,"s":"BTCUSDT","ps":"BTCUSDT","U":11079104699617,"u":11079104704967,"pu":11079104699527,"b":[["14149.90","0.728"],["14249.90","0.966"],["14449.90","0.518"],["14549.90","1.988"],["58184.90","0.002"],["62063.90","0.693"],["64003.40","0.001"],["64320.00","0.443"],["64400.00","28.277"],["64480.00","4.367"],["64560.00","1.154"],["64640.00","0.873"]],"a":[["64653.50","0.664"],["64656.50","0.021"],["64657.60","0.336"],["64681.60","0.004"],["64720.00","0.382"],["64800.00","18.466"],["64880.00","9.538"],["64960.00","2.259"],["65040.00","0.424"],["65296.50","0.032"],["65624.90","0.271"],["65942.90","0.648"]],"st":1}}
{"stream":"btcusdt@depth@100ms","data":{"e":"depthUpdate","E":1784410663716,"T":1784410663715,"s":"BTCUSDT","ps":"BTCUSDT","U":11079104705043,"u":11079104711331,"pu":11079104704967,"b":[["1000.00","50.241"],["14149.90","0.714"],["14249.90","0.854"],["14449.90","0.630"],["14549.90","2.002"],["58184.90","0.004"],["61417.40","0.008"],["62063.90","0.690"],["63357.00","0.017"],["63590.20","0.780"],["64003.40","0.001"],["64132.70","7.779"],["64326.70","0.944"],["64441.60","2.678"],["64478.50","0.561"],["64485.00","0.343"],["64495.60","0.559"],["64562.60","0.008"],["64604.30","0.256"],["64612.70","0.020"],["64612.90","0.070"],["64636.20","0.522"],["64644.20","0.777"]],"a":[["64650.00","2.484"],["64653.50","0.077"],["64653.70","0.594"],["64660.00","0.302"],["64668.70","0.005"],["64801.90","1.002"],["64819.00","0.850"],["64855.90","3.624"],["65041.80","0.350"],["65042.30","0.000"],["65296.50","0.032"],["65550.00","6.654"],["65575.90","9.846"]],"st":1}}
{"stream":"btcusdt@depth@100ms","data":{"e":"depthUpdate","E":1784410663818,"T":1784410663817,"s":"BTCUSDT","ps":"BTCUSDT","U":11079104711407,"u":11079104719157,"pu":11079104711331,"b":[["1000.00","50.241"],["14149.90","0.728"],["14249.90","0.728"],["14449.90","0.756"],["14549.90","1.988"],["58184.90","0.002"],["61417.40","0.008"],["63357.00","0.014"],["63938.80","0.468"],["64003.40","0.001"],["64320.00","0.630"],["64400.00","28.464"],["64480.00","4.554"],["64560.00","1.341"],["64640.00","1.060"]],"a":[["64650.00","2.167"],["64653.70","0.007"],["64656.60","0.002"],["64720.00","0.569"],["64800.00","18.653"],["64880.00","9.725"],["64960.00","2.446"],["65040.00","0.611"],["65296.50","0.032"]],"st":1}}
{"stream":"btcusdt@depth@100ms","data":{"e":"depthUpdate","E":1784410663920,"T":1784410663917,"s":"BTCUSDT","ps":"BTCUSDT","U":11079104719302,"u":11079104725631,"pu":11079104719157,"b":[["14149.90","0.784"],["14249.90","0.616"],["14449.90","0.938"],["14549.90","1.862"],["58184.90","0.002"],["61417.40","0.006"],["61417.50","0.009"],["62063.90","0.693"],["63647.80","7.686"],["64003.40","0.001"],["64062.40","8.536"],["64326.70","0.934"]],"a":[["64656.60","0.002"],["65296.50","0.032"],["65522.80","4.489"],["65587.40","18.728"],["65652.10","8.981"]],"st":1}}
{"stream":"btcusdt@depth@100ms","data":{"e":"depthUpdate","E":1784410664022,"T":1784410664021,"s":"BTCUSDT","ps":"BTCUSDT","U":11079104725782,"u":11079104731390,"pu":11079104725631,"b":[["1000.00","50.241"],["14149.90","0.910"],["14249.90","0.490"],["14449.90","1.176"],["14549.90","1.624"],["51719.90","0.000"],["58184.90","0.002"],["61417.40","0.006"],["62063.90","0.690"],["63788.60","1.567"],["64003.40","0.001"],["64647.50","0.023"]],"a":[["64656.50","0.021"],["64656.60","0.002"],["64657.60","0.336"],["64660.10","0.723"],["65256.60","15.716"],["65296.50","0.032"],["65563.00","1.467"],["65624.60","0.267"]],"st":1}}
{"stream":"btcusdt@depth@100ms","data":{"e":"depthUpdate","E":1784410664124,"T":1784410664122,"s":"BTCUSDT","ps":"BTCUSDT","U":11079104731462,"u":11079104737202,"pu":11079104731390,"b":[["1000.00","50.241"],["14149.90","1.022"],["14249.90","0.378"],["14449.90","1.414"],["14549.90","1.386"],["58184.90","0.002"],["61417.50","0.011"],["62063.90","0.693"],["64003.40","0.001"],["64581.10","0.001"],["64591.50","0.195"],["64591.70","0.029"],["64633.00","0.061"],["64636.30","0.274"],["64636.80","0.015"],["64638.30","0.140"],["64649.90","11.261"]],"a":[["64656.50","0.021"],["64656.60","0.002"],["64656.70","1.308"],["64656.80","0.000"],["64657.10","0.004"],["64657.60","0.336"],["64660.10","0.723"],["64669.60","0.541"],["64671.30","0.002"],["64685.80","0.013"],["64697.70","0.000"],["65296.50","0.032"],["65425.90","1.513"]],"st":1}}
{"stream":"btcusdt@depth@100ms","data":{"e":"depthUpdate","E":1784410664226,"T":1784410664225,"s":"BTCUSDT","ps":"BTCUSDT","U":11079104737320,"u":11079104742003,"pu":11079104737202,"b":[["14149.90","1.148"],["14249.90","0.252"],["14449.90","1.652"],["14549.90","1.148"],["58184.90","0.002"],["61417.40","0.026"],["62063.90","0.690"],["62064.00","0.006"],["63868.60","2.326"],["64003.40","0.000"],["64035.70","6.534"],["64326.70","0.944"],["64349.90","0.051"],["64568.60","0.001"],["64636.30","0.158"],["64637.40","0.117"],["64649.90","11.403"]],"a":[["64650.00","2.132"],["64656.60","0.589"],["64660.00","0.255"],["64669.00","0.001"],["64675.80","0.015"],["64681.60","0.081"],["64708.20","0.007"],["64714.30","0.000"],["64721.00","0.015"],["64731.30","0.001"],["65296.50","0.032"],["65477.40","0.000"]],"st":1}}
{"stream":"btcusdt@depth@100ms","data":{"e":"depthUpdate","E":1784410664328,"T":1784410664325,"s":"BTCUSDT","ps":"BTCUSDT","U":11079104742118,"u":11079104747064,"pu":11079104742003,"b":[["1000.00","50.241"],["14149.90","1.260"],["14249.90","0.140"],["14449.90","1.890"],["14549.90","0.910"],["58184.90","0.002"],["64003.40","0.000"],["64326.60","3.730"],["64633.00","0.215"],["64636.90","0.843"],["64637.40","0.001"]],"a":[["64656.60","0.589"],["64660.20","0.465"],["64739.10","0.006"],["64739.20","4.793"],["65231.80","1.383"],["65296.50","0.032"],["65425.80","28.046"]],"st":1}}
{"stream":"btcusdt@depth@100ms","data":{"e":"depthUpdate","E":1784410664430,"T":1784410664429,"s":"BTCUSDT","ps":"BTCUSDT","U":11079104747223,"u":11079104752322,"pu":11079104747064,"b":[["1000.00","50.241"],["14149.90","1.386"],["14249.90","0.014"],["14349.90","0.070"],["14449.90","1.988"],["14549.90","0.742"],["58184.90","0.002"],["59887.00","0.010"],["62063.90","0.693"],["63853.30","0.789"],["63874.10","29.091"],["63880.60","4.690"],["64003.40","0.000"],["64495.60","0.007"],["64633.00","0.215"],["64649.90","11.404"]],"a":[["64650.00","2.169"],["64656.60","0.589"],["64681.60","0.081"],["64801.90","0.027"],["64973.30","0.926"],["65296.50","0.032"],["65458.10","9.626"],["66270.80","0.000"]],"st":1}}
{"stream":"btcusdt@depth@100ms","data":{"e":"depthUpdate","E":1784410664532,"T":1784410664531,"s":"BTCUSDT","ps":"BTCUSDT","U":11079104752383,"u":11079104757637,"pu":11079104752322,"b":[["14149.90","1.302"],["14249.90","0.000"],["14349.90","0.182"],["14449.90","2.002"],["14549.90","0.714"],["58184.90","0.002"],["61417.40","0.008"],["62063.90","0.690"],["63777.10","4.689"],["64003.40","0.000"],["64326.70","0.944"],["64495.60","0.721"]],"a":[["64656.60","0.589"],["64801.90","1.070"],["65296.50","0.032"]],"st":1}}
{"stream":"btcusdt@depth@100ms","data":{"e":"depthUpdate","E":1784410664634,"T":1784410664633,"s":"BTCUSDT","ps":"BTCUSDT","U":11079104757677,"u":11079104761687,"pu":11079104757637,"b":[["1000.00","50.241"],["14149.90","1.176"],["14349.90","0.308"],["14449.90","1.988"],["14549.90","0.728"],["58184.90","0.002"],["62063.90","0.693"],["64003.40","0.002"],["64568.60","0.000"],["64633.00","0.061"],["64649.90","11.412"]],"a":[["64650.00","1.979"],["64656.50","0.031"],["64656.60","0.714"],["64657.60","0.336"],["64660.10","0.001"],["64681.60","0.004"],["64731.30","0.000"],["65296.50","0.032"],["65555.10","16.392"],["65587.40","19.794"]],"st":1}}
{"stream":"btcusdt@depth@100ms","data":{"e":"depthUpdate","E":1784410664736,"T":1784410664733,"s":"BTCUSDT","ps":"BTCUSDT","U":11079104761716,"u":11079104766444,"pu":11079104761687,"b":[["1000.00","50.241"],["14149.90","1.064"],["14349.90","0.420"],["14449.90","2.002"],["14549.90","0.714"],["58184.90","0.002"],["61417.40","0.008"],["64003.40","0.000"],["64349.90","0.051"],["64485.00","0.002"],["64495.60","0.007"],["64562.60","0.349"],["64614.20","0.014"],["64614.30","1.080"],["64614.40","0.332"],["64614.60","0.314"],["64614.70","0.004"],["64614.80","0.008"],["64633.00","0.215"],["64636.20","0.520"]],"a":[["64650.00","2.139"],["64656.50","0.021"],["64656.60","0.589"],["64660.10","0.723"],["64668.70","0.003"],["64801.90","0.027"],["65130.70","0.115"],["65296.50","0.032"],["65385.90","13.497"],["65942.90","0.645"]],"st":1}}
{"stream":"btcusdt@depth@100ms","data":{"e":"depthUpdate","E":1784410664838,"T":1784410664837,"s":"BTCUSDT","ps":"BTCUSDT","U":11079104766684,"u":11079104771927,"pu":11079104766444,"b":[["14149.90","0.938"],["14349.90","0.546"],["14449.90","1.988"],["14549.90","0.728"],["58184.90","0.002"],["61417.40","0.008"],["62063.90","0.690"],["63577.30","8.640"],["63709.90","2.211"],["64003.40","0.000"],["64326.70","0.944"],["64381.60","0.000"],["64485.00","0.158"],["64488.30","0.037"],["64564.50","0.006"],["64583.20","0.000"],["64585.50","0.752"],["64599.60","0.009"],["64599.70","0.100"],["64605.90","0.100"],["64607.20","0.741"],["64608.20","0.000"],["64622.00","0.050"],["64636.20","0.522"]],"a":[["64656.60","0.589"],["64668.70","0.005"],["64678.20","0.001"],["64691.50","0.839"],["64694.40","0.561"],["64717.00","0.100"],["65296.50","0.032"]],"st":1}}
{"stream":"btcusdt@depth@100ms","data":{"e":"depthUpdate","E":1784410664940,"T":1784410664936,"s":"BTCUSDT","ps":"BTCUSDT","U":11079104772000,"u":11079104776074,"pu":11079104771927,"b":[["1000.00","50.241"],["14149.90","0.826"],["14349.90","0.658"],["14449.90","2.002"],["14549.90","0.714"],["58184.90","0.002"],["62063.90","0.693"],["62098.90","0.000"],["63357.00","0.017"],["63695.50","0.784"],["63712.50","23.661"],["64003.40","0.000"],["64378.40","0.117"],["64441.60","0.013"],["64458.50","0.065"],["64478.50","0.000"],["64551.00","0.000"],["64551.10","0.051"],["64553.00","0.200"],["64630.10","0.387"],["64630.20","0.055"],["64630.30","0.389"]],"a":[["64650.00","2.289"],["64656.60","0.002"],["64657.60","0.923"],["64748.80","0.385"],["64749.40","0.016"],["64819.00","0.000"],["64855.90","0.152"],["65296.50","0.032"],["65542.00","0.571"]],"st":1}}
{"stream":"btcusdt@depth@100ms","data":{"e":"depthUpdate","E":1784410665042,"T":1784410665041,"s":"BTCUSDT","ps":"BTCUSDT","U":11079104776198,"u":11079104783854,"pu":11079104776074,"b":[["1000.00","50.241"],["14149.90","0.700"],["14349.90","0.784"],["14449.90","1.988"],["14549.90","0.728"],["51719.90","0.000"],["58184.90","0.002"],["61417.40","0.008"],["61417.50","0.009"],["62063.90","0.690"],["63550.90","6.237"],["63760.20","0.799"],["63906.40","7.503"],["64003.40","0.000"],["64074.10","0.000"],["64441.60","3.367"],["64478.50","0.720"],["64495.60","0.721"],["64550.20","0.564"],["64551.10","0.043"],["64581.80","6.000"],["64604.40","3.510"],["64620.60","1.934"],["64638.30","0.145"]],"a":[["64656.50","0.021"],["64656.60","0.002"],["64657.60","0.336"],["64660.10","0.723"],["64678.20","0.697"],["64694.40","4.061"],["64717.00","6.100"],["64749.30","0.000"],["64752.00","0.010"],["64801.80","1.043"],["64819.00","0.909"],["64855.80","3.662"],["65107.50","0.123"],["65189.60","0.056"],["65296.50","0.032"],["65361.10","2.829"],["65762.00","1.601"]],"st":1}}
{"stream":"btcusdt@depth@100ms","data":{"e":"depthUpdate","E":1784410665144,"T":1784410665141,"s":"BTCUSDT","ps":"BTCUSDT","U":11079104784040,"u":11079104790522,"pu":11079104783854,"b":[["14149.90","0.588"],["14349.90","0.994"],["14449.90","1.806"],["14549.90","0.812"],["58184.90","0.002"],["61417.50","0.007"],["62063.90","0.693"],["63860.30","2.397"],["64003.40","0.000"],["64326.70","0.944"],["64458.50","0.061"],["64549.50","10.000"],["64564.50","0.002"],["64582.30","1.947"],["64603.70","0.028"],["64604.50","0.916"],["64638.30","0.140"]],"a":[["64656.60","0.724"],["64657.60","0.336"],["64660.10","0.001"],["64681.60","0.081"],["64691.50","1.251"],["64973.30","1.540"],["65296.50","0.032"],["65515.30","26.097"],["65555.10","16.651"],["65933.10","0.000"]],"st":1}}
{"stream":"btcusdt@depth@100ms","data":{"e":"depthUpdate","E":1784410665246,"T":1784410665245,"s":"BTCUSDT","ps":"BTCUSDT","U":11079104790742,"u":11079104798196,"pu":11079104790522,"b":[["1000.00","50.241"],["14149.90","0.462"],["14349.90","1.232"],["14449.90","1.568"],["14549.90","0.938"],["58184.90","0.002"],["61417.40","0.008"],["63577.30","7.856"],["63763.30","3.289"],["63804.60","0.274"],["64003.40","0.000"],["64349.90","0.051"],["64488.30","0.193"],["64495.60","0.484"],["64553.70","6.043"],["64603.30","0.022"],["64612.70","0.000"],["64623.10","0.001"],["64633.00","0.215"],["64649.90","11.325"]],"a":[["64650.00","2.288"],["64653.50","0.664"],["64653.80","1.275"],["64654.00","0.008"],["64654.90","0.003"],["64655.00","0.051"],["64656.60","0.002"],["64657.10","0.016"],["64657.60","0.493"],["64658.80","0.048"],["64658.90","0.002"],["64660.10","0.723"],["64669.00","0.016"],["64675.80","0.000"],["64681.60","0.004"],["64714.30","0.015"],["64721.00","0.000"],["64745.40","3.507"],["64745.60","0.534"],["64748.80","1.755"],["64749.30","0.008"],["64749.40","10.016"],["64752.00","0.002"],["64801.80","0.670"],["65167.20","6.640"],["65296.50","0.032"],["65588.80","1.692"]],"st":1}}
{"stream":"btcusdt@depth@100ms","data":{"e":"depthUpdate","E":1784410665348,"T":1784410665347,"s":"BTCUSDT","ps":"BTCUSDT","U":11079104798334,"u":11079104803539,"pu":11079104798196,"b":[["1000.00","50.241"],["14149.90","0.350"],["14349.90","1.470"],["14449.90","1.330"],["14549.90","1.050"],["51720.00","0.004"],["58184.90","0.002"],["61417.40","0.008"],["62063.90","0.690"],["62064.00","0.005"],["63537.90","2.215"],["63645.30","2.187"],["63709.90","1.114"],["63860.30","2.132"],["64003.40","0.000"],["64495.60","0.721"],["64603.30","0.002"],["64613.30","0.576"],["64643.60","0.255"],["64644.10","0.073"]],"a":[["64653.50","0.664"],["64655.00","0.004"],["64655.30","0.001"],["64801.80","0.991"],["65167.20","7.559"],["65291.30","8.403"],["65296.50","0.034"],["65385.90","13.268"]],"st":1}}
{"stream":"btcusdt@depth@100ms","data":{"e":"depthUpdate","E":1784410665450,"T":1784410665449,"s":"BTCUSDT","ps":"BTCUSDT","U":11079104803557,"u":11079104808567,"pu":11079104803539,"b":[["14149.90","0.224"],["14349.90","1.708"],["14449.90","1.092"],["14549.90","1.176"],["58184.90","0.002"],["61417.40","0.010"],["62063.90","0.693"],["63615.50","4.861"],["63712.50","22.564"],["63742.20","3.417"],["63795.70","2.075"],["64003.40","0.000"],["64326.60","3.732"],["64326.70","0.934"],["64495.60","0.007"],["64633.00","0.061"],["64647.50","0.000"],["64649.90","11.326"]],"a":[["64650.00","1.987"],["64653.50","0.000"],["64657.60","0.336"],["64658.30","0.321"],["64801.80","0.000"],["64973.30","1.538"],["65130.70","0.000"],["65296.50","0.032"],["65490.70","0.544"],["65680.80","0.611"],["65684.40","4.682"]],"st":1}}
{"stream":"btcusdt@depth@100ms","data":{"e":"depthUpdate","E":1784410665552,"T":1784410665551,"s":"BTCUSDT","ps":"BTCUSDT","U":11079104808653,"u":11079104813401,"pu":11079104808567,"b":[["1000.00","50.241"],["14149.90","0.112"],["14349.90","1.946"],["14449.90","0.854"],["14549.90","1.288"],["51720.00","0.006"],["58184.90","0.000"],["62063.90","0.690"],["63550.90","7.022"],["63563.80","2.119"],["64003.40","0.000"],["64219.20","0.003"],["64244.10","0.000"],["64325.90","0.004"],["64350.80","0.000"],["64432.50","0.003"],["64449.90","0.000"],["64457.40","0.000"],["64495.60","0.007"],["64504.40","0.000"],["64518.10","0.663"],["64536.90","2.563"],["64537.30","0.027"],["64537.40","0.491"],["64538.90","0.004"],["64540.40","1.478"],["64647.40","0.001"]],"a":[["64650.00","2.139"],["64753.30","2.344"],["64754.30","0.013"],["64801.80","0.000"],["64865.70","0.005"],["64892.50","0.000"],["64972.40","0.006"],["64999.20","0.003"],["65079.00","0.019"],["65105.90","0.000"],["65264.20","3.745"],["65296.50","0.032"],["65361.10","3.058"],["65587.40","20.860"],["65871.90","0.455"]],"st":1}}
{"stream":"btcusdt@depth@100ms","data":{"e":"depthUpdate","E":1784410665654,"T":1784410665653,"s":"BTCUSDT","ps":"BTCUSDT","U":11079104813415,"u":11079104818832,"pu":11079104813401,"b":[["1000.00","50.241"],["14149.90","0.000"],["14249.90","0.098"],["14349.90","1.988"],["14449.90","0.728"],["14549.90","1.386"],["51720.00","0.004"],["58184.90","0.002"],["63357.00","0.020"],["63647.80","8.784"],["63744.80","22.219"],["63857.20","0.000"],["64003.40","0.000"],["64132.70","7.780"],["64495.60","0.721"],["64540.40","0.202"],["64633.00","0.215"]],"a":[["64650.00","2.146"],["64658.80","0.001"],["64681.60","0.004"],["64801.80","0.991"],["65296.50","0.032"],["65619.80","2.386"],["65652.10","10.046"]],"st":1}}
{"stream":"btcusdt@depth@100ms","data":{"e":"depthUpdate","E":1784410665756,"T":1784410665755,"s":"BTCUSDT","ps":"BTCUSDT","U":11079104818902,"u":11079104823034,"pu":11079104818832,"b":[["14249.90","0.210"],["14349.90","2.002"],["14449.90","0.714"],["14549.90","1.274"],["58184.90","0.002"],["62063.90","0.693"],["63777.10","5.080"],["64003.40","0.000"],["64326.70","0.934"],["64349.90","0.051"],["64562.60","0.008"],["64636.20","0.520"]],"a":[["64668.70","0.003"],["64678.20","0.001"],["65108.00","0.158"],["65477.20","1.907"],["65535.70","2.130"]],"st":1}}
{"stream":"btcusdt@depth@100ms","data":{"e":"depthUpdate","E":1784410665858,"T":1784410665857,"s":"BTCUSDT","ps":"BTCUSDT","U":11079104823058,"u":11079104827495,"pu":11079104823034,"b":[["1000.00","50.241"],["14249.90","0.336"],["14349.90","1.988"],["14449.90","0.728"],["14549.90","1.148"],["58184.90","0.002"],["61417.40","0.010"],["62063.90","0.690"],["64003.40","0.003"],["64132.70","7.779"],["64485.00","0.499"],["64495.60","0.728"],["64535.90","0.000"],["64537.40","0.491"],["64538.90","0.004"],["64540.40","0.202"],["64541.90","0.000"],["64543.40","0.000"],["64544.90","0.000"],["64564.50","0.006"],["64581.80","0.000"],["64582.30","1.140"],["64585.30","0.131"],["64604.40","0.010"],["64604.50","0.001"],["64620.60","1.239"],["64636.20","0.522"]],"a":[["64650.00","1.899"],["64653.60","0.000"],["64663.00","0.032"],["64668.70","0.005"],["64679.80","0.120"],["64684.00","0.557"],["64685.80","0.060"],["64691.50","0.839"],["64694.40","0.561"],["64717.00","0.100"],["64801.80","0.991"],["65296.50","0.032"]],"st":1}}
{"stream":"btcusdt@depth@100ms","data":{"e":"depthUpdate","E":1784410665960,"T":1784410665958,"s":"BTCUSDT","ps":"BTCUSDT","U":11079104827513,"u":11079104832669,"pu":11079104827495,"b":[["1000.00","50.241"],["14249.90","0.448"],["14349.90","2.002"],["14449.90","0.714"],["14549.90","1.036"],["58184.90","0.002"],["61417.40","0.010"],["62063.90","0.693"],["63889.60","2.345"],["64003.40","0.001"],["64351.00","0.950"],["64458.50","0.065"],["64549.50","0.000"],["64553.10","0.004"],["64560.00","1.337"],["64622.10","0.884"],["64633.00","0.215"],["64649.90","11.333"]],"a":[["64650.00","2.198"],["64657.10","0.004"],["64659.00","0.324"],["64662.50","0.400"],["64678.20","0.720"],["64681.60","0.004"],["64682.50","10.003"],["64748.80","0.385"],["64749.30","0.000"],["64749.40","0.016"],["64752.00","0.010"],["65296.50","0.034"],["65458.10","9.885"]],"st":1}}
{"stream":"btcusdt@depth@100ms","data":{"e":"depthUpdate","E":1784410666062,"T":1784410666061,"s":"BTCUSDT","ps":"BTCUSDT","U":11079104832728,"u":11079104837182,"pu":11079104832669,"b":[["14249.90","0.574"],["14349.90","1.988"],["14449.90","0.728"],["14549.90","0.910"],["51719.90","0.000"],["58184.90","0.002"],["61417.40","0.010"],["62063.90","0.690"],["63357.00","0.023"],["63712.50","21.467"],["63871.50","0.935"],["64003.40","0.001"],["64326.70","0.944"],["64449.90","0.000"],["64633.00","0.061"],["64638.30","0.140"],["64649.90","11.334"]],"a":[["64681.60","0.004"],["65296.50","0.032"]],"st":1}}
{"stream":"btcusdt@depth@100ms","data":{"e":"depthUpdate","E":1784410666164,"T":1784410666162,"s":"BTCUSDT","ps":"BTCUSDT","U":11079104837247,"u":11079104841685,"pu":11079104837182,"b":[["1000.00","50.241"],["14249.90","0.686"],["14349.90","2.002"],["14449.90","0.714"],["14549.90","0.798"],["58184.90","0.002"],["61417.50","0.009"],["63880.60","5.628"],["64003.40","0.001"],["64132.70","7.779"],["64349.90","0.051"],["64378.40","0.000"],["64458.50","0.061"],["64488.30","0.193"],["64518.60","0.008"],["64520.00","4.089"],["64549.50","10.000"],["64553.10","0.000"],["64559.90","0.005"],["64564.50","0.002"],["64579.20","0.050"],["64579.30","0.074"],["64581.80","6.000"],["64582.30","1.947"],["64603.70","0.371"],["64604.40","3.510"],["64633.00","0.215"],["64649.90","11.327"]],"a":[["64650.00","2.224"],["64691.50","1.251"],["64694.40","4.061"],["64717.00","6.100"],["64721.50","0.047"],["64721.60","0.002"],["64749.40","10.016"],["64774.80","3.868"],["64775.50","0.080"],["65296.50","0.032"]],"st":1}}
{"stream":"btcusdt@depth@100ms","data":{"e":"depthUpdate","E":1784410666266,"T":1784410666264,"s":"BTCUSDT","ps":"BTCUSDT","U":11079104842024,"u":11079104846749,"pu":11079104841685,"b":[["14249.90","0.812"],["14349.90","1.988"],["14449.90","0.728"],["14549.90","0.672"],["58184.90","0.002"],["61417.40","0.010"],["62063.90","0.693"],["63357.00","0.020"],["63874.10","30.655"],["64003.40","0.001"],["64381.60","0.117"],["64449.90","0.000"]],"a":[["64656.50","0.733"],["64656.60","0.002"],["64660.10","0.011"],["64749.30","0.008"],["64752.00","0.002"],["65296.50","0.032"]],"st":1}}
{"stream":"btcusdt@depth@100ms","data":{"e":"depthUpdate","E":1784410666368,"T":1784410666367,"s":"BTCUSDT","ps":"BTCUSDT","U":11079104846781,"u":11079104853704,"pu":11079104846749,"b":[["14249.90","1.050"],["14349.90","1.750"],["14449.90","0.840"],["14549.90","0.560"],["58184.90","0.002"],["61417.40","0.008"],["61417.50","0.011"],["62063.90","0.690"],["63874.10","31.438"],["64003.40","0.000"],["64326.70","0.944"],["64441.60","0.013"],["64478.50","0.000"],["64495.60","0.007"],["64535.90","1.221"],["64537.40","1.767"],["64538.90","1.280"],["64540.40","1.478"],["64541.90","1.276"],["64543.40","1.276"],["64544.90","1.276"],["64550.30","0.004"],["64559.90","0.001"],["64564.50","0.006"],["64585.30","0.133"],["64593.00","0.016"],["64616.90","0.567"],["64633.00","0.061"],["64636.90","0.727"],["64637.50","0.002"],["64637.70","0.493"],["64637.80","0.003"],["64639.50","0.121"],["64642.80","0.000"],["64644.60","0.541"],["64645.40","0.122"],["64649.80","0.004"]],"a":[["64650.00","2.206"],["64656.30","0.045"],["64656.40","0.001"],["64656.50","0.021"],["64656.60","0.721"],["64660.10","0.713"],["64714.60","0.002"],["64801.80","0.000"],["64819.00","0.000"],["64855.80","0.000"],["65296.50","0.034"],["65386.00","0.302"]],"st":1}}
{"stream":"btcusdt@depth@100ms","data":{"e":"depthUpdate","E":1784410666470,"T":1784410666469,"s":"BTCUSDT","ps":"BTCUSDT","U":11079104853726,"u":11079104858962,"pu":11079104853704,"b":[["1000.00","50.241"],["14249.90","1.288"],["14349.90","1.512"],["14449.90","0.966"],["14549.90","0.434"],["51720.00","0.004"],["58184.90","0.002"],["61417.40","0.010"],["62063.90","0.693"],["64003.40","0.000"],["64326.60","3.730"],["64441.60","3.367"],["64478.40","0.720"],["64495.60","0.721"],["64535.90","0.000"],["64537.40","0.491"],["64538.90","0.004"],["64540.40","0.202"],["64541.90","0.000"],["64543.40","0.000"],["64544.90","0.000"],["64550.30","0.000"],["64557.60","0.005"],["64564.50","0.002"],["64618.80","0.000"],["64619.00","0.088"],["64620.10","0.000"],["64622.20","0.007"],["64622.30","0.389"],["64622.80","0.001"],["64626.60","0.084"],["64628.40","0.031"],["64633.00","0.215"],["64634.70","0.123"],["64634.80","0.018"],["64635.70","0.116"],["64636.80","0.016"],["64637.40","0.558"],["64637.60","0.550"],["64637.70","1.960"],["64640.10","0.001"],["64640.70","0.058"],["64640.90","0.023"],["64643.50","0.311"],["64643.60","0.235"],["64644.60","0.000"],["64645.10","0.218"],["64645.40","1.419"],["64645.50","0.835"],["64645.60","0.008"],["64649.80","0.005"]],"a":[["64650.00","2.207"],["64653.70","0.007"],["64655.10","0.635"],["64656.30","0.035"],["64656.50","0.021"],["64656.60","0.002"],["64657.60","0.336"],["64660.10","0.723"],["64660.40","4.251"],["64664.00","0.033"],["64668.00","0.017"],["64670.60","0.039"],["64672.30","0.033"],["64674.50","1.955"],["64676.30","0.094"],["64678.60","0.019"],["64678.80","0.635"],["64679.90","0.583"],["64683.60","0.000"],["64801.80","1.020"],["64819.00","0.896"],["64855.80","3.480"],["65296.50","0.032"],["65361.20","3.742"]],"st":1}}
{"stream":"btcusdt@depth@100ms","data":{"e":"depthUpdate","E":1784410666572,"T":1784410666569,"s":"BTCUSDT","ps":"BTCUSDT","U":11079104859027,"u":11079104864293,"pu":11079104858962,"b":[["14249.90","1.526"],["14349.90","1.274"],["14449.90","1.078"],["14549.90","0.322"],["58184.90","0.002"],["61417.40","0.010"],["61417.50","0.009"],["62063.90","1.380"],["64003.40","0.000"],["64449.90","0.000"],["64596.80","0.185"],["64596.90","0.000"],["64633.00","0.061"],["64649.90","11.344"]],"a":[["64650.00","2.209"],["64655.10","0.635"],["64681.60","0.004"],["64682.80","0.003"],["64682.90","0.003"],["64690.70","10.052"],["64973.30","1.540"],["65296.50","0.032"]],"st":1}}
{"stream":"btcusdt@depth@100ms","data":{"e":"depthUpdate","E":1784410666674,"T":1784410666673,"s":"BTCUSDT","ps":"BTCUSDT","U":11079104864408,"u":11079104869313,"pu":11079104864293,"b":[["14249.90","1.764"],["14349.90","1.036"],["14449.90","1.204"],["14549.90","0.196"],["58184.90","0.002"],["61417.40","0.020"],["63550.90","7.571"],["63724.00","0.784"],["63874.10","32.219"],["64003.40","0.000"],["64326.70","0.944"],["64349.90","0.051"],["64495.60","0.007"],["64633.00","0.215"],["64638.10","0.002"]],"a":[["64650.00","2.214"],["64655.10","0.635"],["64681.60","0.081"],["64801.80","0.000"],["64997.90","0.300"],["65296.50","0.032"],["65425.80","27.284"],["65522.80","4.869"]],"st":1}}
{"stream":"btcusdt@depth@100ms","data":{"e":"depthUpdate","E":1784410666776,"T":1784410666773,"s":"BTCUSDT","ps":"BTCUSDT","U":11079104869338,"u":11079104873470,"pu":11079104869313,"b":[["1000.00","50.241"],["14249.90","2.002"],["14349.90","0.798"],["14449.90","1.316"],["14549.90","0.084"],["58184.90","0.002"],["61417.40","0.010"],["62063.90","1.383"],["63357.00","0.017"],["63659.40","0.784"],["63906.40","8.441"],["64003.40","0.000"],["64068.10","0.234"],["64449.90","0.000"],["64478.40","0.000"],["64643.40","0.007"],["64643.60","0.003"],["64644.00","0.234"],["64649.90","11.342"]],"a":[["64650.00","2.219"],["64655.10","0.048"],["64681.60","0.004"],["64819.00","0.000"],["64973.30","0.925"],["65296.50","0.032"],["65942.90","0.648"]],"st":1}}
{"stream":"btcusdt@depth@100ms","data":{"e":"depthUpdate","E":1784410666878,"T":1784410666877,"s":"BTCUSDT","ps":"BTCUSDT","U":11079104873603,"u":11079104877319,"pu":11079104873470,"b":[["14149.90","0.126"],["14249.90","1.988"],["14349.90","0.728"],["14449.90","1.358"],["14549.90","0.000"],["58184.90","0.002"],["61417.40","0.010"],["62063.90","1.380"],["63841.80","8.761"],["63874.10","27.529"],["64003.40","0.000"],["64485.00","0.343"],["64633.00","0.061"],["64636.20","0.522"]],"a":[["64655.10","0.048"],["64668.70","0.005"],["64681.60","0.081"],["64973.30","1.079"],["65296.50","0.032"],["65425.80","28.046"]],"st":1}}
{"stream":"btcusdt@depth@100ms","data":{"e":"depthUpdate","E":1784410666980,"T":1784410666978,"s":"BTCUSDT","ps":"BTCUSDT","U":11079104877384,"u":11079104881791,"pu":11079104877319,"b":[["14149.90","0.238"],["14249.90","2.002"],["14349.90","0.714"],["14449.90","1.246"],["51720.00","0.004"],["58184.90","0.002"],["61417.40","0.010"],["62063.90","1.383"],["63744.80","22.485"],["64003.40","0.000"],["64326.70","0.944"],["64441.60","0.013"],["64484.30","0.000"],["64616.20","0.220"],["64633.00","0.215"]],"a":[["64655.10","0.048"],["64855.80","0.000"],["64860.00","1.776"],["64960.00","2.449"],["65500.00","98.322"]],"st":1}}
{"stream":"btcusdt@depth@100ms","data":{"e":"depthUpdate","E":1784410667082,"T":1784410667081,"s":"BTCUSDT","ps":"BTCUSDT","U":11079104881911,"u":11079104886676,"pu":11079104881791,"b":[["1000.00","50.241"],["14149.90","0.364"],["14249.90","1.988"],["14349.90","0.728"],["14449.90","1.120"],["51719.90","0.000"],["58184.90","0.002"],["61417.40","0.008"],["61417.50","0.011"],["63712.50","22.564"],["63874.10","32.219"],["64003.40","0.000"],["64441.60","3.410"],["64449.90","0.000"],["64478.40","0.725"],["64484.30","0.004"],["64485.00","0.158"],["64495.60","0.725"],["64562.60","0.349"],["64564.50","0.006"],["64598.70","0.002"],["64600.90","21.329"],["64606.00","0.189"],["64606.10","0.000"],["64612.50","0.110"],["64618.30","2.583"],["64625.80","0.169"],["64626.90","1.466"],["64631.20","0.014"],["64631.40","1.272"],["64631.90","0.001"],["64632.00","0.731"],["64634.00","0.299"],["64635.90","0.197"],["64638.30","0.140"],["64638.40","0.399"],["64639.00","0.788"],["64642.20","0.309"],["64643.20","1.570"],["64643.50","0.002"],["64644.00","0.002"],["64644.50","2.605"],["64645.20","0.433"],["64645.40","1.421"],["64645.50","0.120"],["64645.60","0.001"],["64645.70","0.000"],["64646.40","0.030"],["64646.70","0.016"],["64647.00","0.311"],["64647.20","1.602"],["64647.50","0.000"],["64649.90","10.312"]],"a":[["64650.00","2.383"],["64651.30","0.002"],["64652.20","0.002"],["64652.40","0.313"],["64653.30","0.006"],["64654.50","0.041"],["64655.10","0.048"],["64656.60","0.724"],["64657.10","0.051"],["64657.60","0.336"],["64658.30","0.368"],["64659.90","1.276"],["64660.00","0.100"],["64660.10","0.001"],["64660.30","0.176"],["64661.20","0.309"],["64662.90","0.001"],["64667.70","0.122"],["64671.30","0.311"],["64672.20","0.000"],["64672.30","0.035"],["64672.40","0.001"],["64672.90","0.003"],["64673.90","0.010"],["64674.20","0.007"],["64675.00","2.113"],["64677.80","0.648"],["64678.80","0.079"],["64682.50","0.005"],["64682.90","0.001"],["64798.70","0.009"],["64801.80","1.020"],["64819.00","0.903"],["64840.70","0.208"],["64855.80","3.513"],["64871.70","0.054"],["64872.50","0.000"],["64886.00","2.288"],["64973.30","1.694"],["65296.50","0.032"],["65561.60","3.198"],["65942.90","0.651"]],"st":1}}
{"stream":"btcusdt@depth@100ms","data":{"e":"depthUpdate","E":1784410667184,"T":1784410667182,"s":"BTCUSDT","ps":"BTCUSDT","U":11079104886858,"u":11079104891400,"pu":11079104886676,"b":[["14149.90","0.476"],["14249.90","2.002"],["14349.90","0.714"],["14449.90","1.008"],["58184.90","0.002"],["61417.40","0.008"],["61417.50","0.009"],["62063.90","1.380"],["63615.50","5.960"],["63647.80","9.883"],["63712.50","23.661"],["63750.40","0.000"],["63841.80","9.026"],["64003.40","0.000"],["64320.00","0.613"],["64349.90","0.051"],["64378.40","0.117"],["64381.60","0.000"],["64400.00","28.447"],["64463.70","0.047"],["64480.00","4.537"],["64488.30","0.037"],["64535.90","0.000"],["64537.40","0.491"],["64538.90","0.004"],["64540.40","0.000"],["64540.50","0.006"],["64541.90","0.000"],["64543.40","0.000"],["64544.90","0.000"],["64546.40","1.832"],["64547.90","1.222"],["64560.00","1.320"],["64598.80","0.074"],["64603.70","0.028"],["64604.50","0.916"],["64635.30","0.119"],["64635.70","0.000"],["64639.00","0.607"],["64640.00","1.043"],["64645.50","0.301"],["64645.60","0.001"],["64645.70","0.000"],["64649.90","10.236"]],"a":[["64650.00","2.378"],["64655.10","0.635"],["64656.40","0.001"],["64656.50","0.021"],["64656.60","0.012"],["64657.80","0.176"],["64658.20","0.191"],["64658.30","0.244"],["64658.60","0.154"],["64659.80","0.558"],["64681.60","0.004"],["64682.70","0.243"],["64686.70","0.801"],["64708.50","23.944"],["64710.70","0.006"],["64720.00","0.552"],["64748.80","1.755"],["64800.00","18.636"],["64880.00","9.708"],["64960.00","2.432"],["65040.00","0.594"],["65296.50","0.034"],["65477.20","1.649"],["65684.40","5.746"]],"st":1}}
{"stream":"btcusdt@depth@100ms","data":{"e":"depthUpdate","E":1784410667286,"T":1784410667285,"s":"BTCUSDT","ps":"BTCUSDT","U":11079104891441,"u":11079104896752,"pu":11079104891400,"b":[["1000.00","50.241"],["14149.90","0.602"],["14249.90","1.988"],["14349.90","0.728"],["14449.90","0.882"],["51720.00","0.004"],["58184.90","0.002"],["61417.40","0.008"],["62063.90","1.383"],["64003.40","0.000"],["64326.60","3.575"],["64326.70","0.944"],["64421.30","0.828"],["64449.90","0.000"],["64463.70","0.043"],["64546.40","0.556"],["64546.50","0.000"],["64633.00","0.061"],["64639.00","0.066"],["64645.50","0.301"],["64645.60","0.542"],["64645.70","0.000"]],"a":[["64650.00","2.382"],["64655.10","0.048"],["64656.40","0.542"],["64656.50","0.038"],["64656.60","0.166"],["64658.60","0.000"],["64659.80","0.000"],["64710.60","0.692"],["65200.00","54.516"],["65296.50","0.032"],["65420.00","24.374"],["65614.70","1.220"],["65700.00","44.823"]],"st":1}}
{"stream":"btcusdt@depth@100ms","data":{"e":"depthUpdate","E":1784410667388,"T":1784410667387,"s":"BTCUSDT","ps":"BTCUSDT","U":11079104896822,"u":11079104901850,"pu":11079104896752,"b":[["1000.00","50.241"],["14149.90","0.714"],["14249.90","2.002"],["14349.90","0.714"],["14449.90","0.770"],["51720.00","0.004"],["58184.90","0.002"],["61417.40","0.008"],["62063.90","1.380"],["63821.00","0.787"],["64003.40","0.002"],["64297.30","0.018"],["64320.00","0.630"],["64340.50","0.000"],["64400.00","28.464"],["64480.00","4.554"],["64488.30","0.193"],["64495.60","0.894"],["64518.70","3.867"],["64520.00","0.222"],["64535.90","0.000"],["64537.40","0.491"],["64538.90","0.004"],["64540.40","0.000"],["64541.90","0.000"],["64543.40","0.000"],["64544.90","0.000"],["64546.40","0.556"],["64546.50","0.000"],["64553.70","6.192"],["64560.00","1.337"],["64579.20","0.050"],["64611.10","0.184"],["64633.00","0.215"],["64634.90","0.271"],["64635.30","0.003"],["64639.00","0.607"],["64640.00","1.060"],["64643.20","1.338"],["64643.90","0.234"],["64645.50","0.301"],["64645.60","0.001"],["64645.70","0.000"],["64648.60","0.634"],["64649.90","9.602"]],"a":[["64650.00","2.989"],["64654.40","0.048"],["64656.20","0.003"],["64656.30","0.035"],["64656.40","0.001"],["64656.50","0.021"],["64656.60","0.166"],["64657.10","0.004"],["64657.60","0.383"],["64659.80","0.558"],["64685.80","0.013"],["64708.50","0.000"],["64710.70","23.950"],["64720.00","0.569"],["64721.50","0.047"],["64745.30","3.512"],["64745.40","0.000"],["64771.20","0.992"],["64774.00","3.867"],["64774.80","0.001"],["64800.00","18.653"],["64801.80","1.025"],["64880.00","9.725"],["64960.00","2.449"],["65040.00","0.611"],["65296.50","0.032"],["65749.00","0.002"]],"st":1}}
