{"stream":"btcusdt@depth@100ms","data":{"e":"depthUpdate","E":1784410681162,"T":1784410681161,"s":"BTCUSDT","ps":"BTCUSDT","U":11079105704946,"u":11079105732622,"pu":11079105704909,"b":[["1000.00","50.391"],["14149.90","0.826"],["14154.00","0.000"],["14256.80","0.014"],["14258.80","0.112"],["14349.90","0.098"],["14556.80","0.042"],["14558.80","0.210"],["58190.70","0.000"],["58191.10","0.000"],["58192.90","0.002"],["61417.50","0.011"],["62070.10","0.002"],["63319.10","0.300"],["63365.70","0.006"],["63647.80","12.079"],["63649.90","0.002"],["63654.00","0.050"],["63658.80","0.042"],["63712.50","25.699"],["63800.00","26.869"],["63906.40","8.442"],["64010.20","0.000"],["64010.30","0.003"],["64012.20","0.186"],["64141.50","0.002"],["64330.80","0.000"],["64444.70","0.920"],["64452.00","0.100"],["64454.00","0.001"],["64480.00","1.306"],["64480.40","0.025"],["64483.00","4.897"],["64483.80","0.106"],["64484.20","0.100"],["64484.30","0.004"],["64492.50","0.000"],["64492.60","0.250"],["64493.30","0.072"],["64497.20","3.248"],["64499.20","0.520"],["64505.60","0.402"],["64511.60","0.001"],["64519.60","0.000"],["64525.20","0.002"],["64525.70","0.044"],["64549.70","0.000"],["64559.10","0.001"],["64559.20","3.056"],["64559.30","0.026"],["64560.20","0.865"],["64560.40","0.008"],["64560.70","0.043"],["64560.90","0.001"],["64562.50","0.021"],["64563.50","0.000"],["64565.70","0.000"],["64570.30","4.640"],["64570.80","2.597"],["64572.00","1.325"],["64573.60","0.015"],["64575.60","0.033"],["64576.00","0.020"],["64576.60","0.001"],["64577.80","0.077"],["64579.20","0.004"],["64579.70","0.155"],["64581.20","0.005"],["64581.40","0.021"],["64582.30","0.772"],["64583.40","0.217"],["64585.70","0.000"],["64586.50","0.047"],["64587.80","3.024"],["64588.80","0.047"],["64588.90","0.004"],["64589.30","0.022"],["64590.30","0.027"],["64590.80","0.000"],["64591.50","0.125"],["64593.90","0.025"],["64594.30","0.391"],["64594.60","0.264"],["64594.70","0.040"],["64595.10","0.559"],["64596.60","0.000"],["64596.90","0.000"],["64597.70","0.000"],["64598.00","0.003"],["64598.10","0.000"],["64598.20","0.662"],["64598.60","0.556"],["64598.80","0.025"],["64599.90","0.187"],["64600.10","0.008"],["64600.70","0.024"],["64600.90","0.148"],["64601.30","0.464"],["64601.50","0.026"],["64602.40","0.090"],["64603.10","0.126"],["64604.40","1.893"],["64604.50","0.686"],["64605.10","0.011"],["64605.30","22.381"],["64606.00","0.014"],["64606.80","0.087"],["64607.20","4.362"],["64607.40","0.019"],["64607.80","0.008"],["64607.90","0.020"],["64608.50","0.067"],["64610.20","0.013"],["64610.70","0.000"],["64611.10","0.102"],["64611.20","0.025"],["64611.30","0.000"],["64611.40","0.535"],["64611.80","0.001"],["64612.10","0.200"],["64612.70","0.000"],["64613.20","0.001"],["64613.60","0.222"],["64613.80","0.004"],["64614.90","0.305"],["64616.00","0.005"],["64616.60","0.006"],["64616.80","0.030"],["64617.10","0.313"],["64617.20","0.060"],["64617.80","0.000"],["64618.00","0.002"],["64618.40","0.466"],["64619.30","0.020"],["64619.50","0.071"],["64619.70","0.031"],["64621.30","0.094"],["64621.40","0.370"],["64621.80","0.000"],["64622.10","0.232"],["64622.90","0.476"],["64623.40","0.000"],["64623.50","0.311"],["64623.70","0.028"],["64624.00","0.013"],["64624.10","1.468"],["64624.20","0.704"],["64624.50","3.472"],["64624.80","0.296"],["64626.10","0.047"],["64626.20","0.000"],["64626.40","0.375"],["64626.50","0.481"],["64626.70","0.002"],["64626.80","0.002"],["64627.10","1.314"],["64627.20","0.092"],["64627.30","1.312"],["64627.40","0.558"],["64627.50","0.002"],["64627.60","0.784"],["64627.80","0.147"],["64628.00","0.003"],["64628.10","0.965"],["64628.20","0.001"],["64628.30","0.001"],["64628.50","0.034"],["64628.60","0.006"],["64628.70","0.007"],["64629.10","0.017"],["64629.70","0.015"],["64630.00","0.040"],["64630.10","0.690"],["64630.50","0.435"],["64630.70","0.027"],["64630.80","0.013"],["64630.90","0.014"],["64631.00","0.004"],["64631.10","0.023"],["64631.20","0.024"],["64631.90","0.067"],["64632.30","0.002"],["64633.30","0.148"],["64633.40","0.096"],["64633.50","1.607"],["64633.60","0.018"],["64633.80","4.398"],["64633.90","0.073"],["64634.00","0.177"],["64634.50","0.367"],["64634.60","0.388"],["64634.70","0.126"],["64635.00","1.291"],["64635.10","0.388"],["64635.20","0.376"],["64635.90","0.217"],["64636.00","0.005"],["64636.50","0.058"],["64637.00","0.388"],["64637.40","0.001"],["64637.50","0.002"],["64637.60","0.000"],["64637.80","0.001"],["64638.30","0.037"],["64638.80","0.137"],["64638.90","0.035"],["64639.00","0.097"],["64639.20","0.000"],["64639.40","0.373"],["64639.50","0.001"],["64639.90","0.001"],["64640.00","5.068"],["64640.40","0.002"],["64640.50","0.008"],["64640.60","1.237"],["64640.80","0.006"],["64640.90","0.000"],["64641.00","0.001"],["64641.20","0.636"],["64641.50","0.006"],["64641.80","0.097"],["64641.90","1.794"],["64642.00","0.002"],["64642.20","0.002"],["64643.30","0.059"],["64643.60","0.003"],["64643.80","0.178"],["64644.10","0.003"],["64644.50","0.224"],["64644.80","0.010"],["64644.90","1.483"],["64645.10","0.078"],["64645.40","1.367"],["64645.50","0.120"],["64645.60","0.545"],["64645.70","0.156"],["64645.90","0.010"],["64646.00","1.010"],["64646.20","0.001"],["64646.30","0.067"],["64646.40","0.024"],["64646.50","0.005"],["64646.80","0.094"],["64646.90","0.079"],["64647.00","0.553"],["64647.10","0.565"],["64647.20","1.303"],["64647.30","0.099"],["64647.60","0.001"],["64647.80","0.345"],["64647.90","0.061"],["64648.00","0.015"],["64648.10","0.048"],["64648.20","0.000"],["64648.30","0.017"],["64648.40","0.695"],["64648.50","0.032"],["64648.60","0.180"],["64649.00","0.001"],["64649.10","0.002"],["64649.20","0.003"],["64649.60","0.008"],["64649.90","2.843"],["64650.00","1.341"],["64650.10","0.565"],["64650.20","0.148"],["64650.30","0.006"],["64650.40","0.064"],["64650.50","0.134"],["64650.70","0.777"],["64650.80","0.000"],["64650.90","1.316"],["64651.00","0.006"],["64651.20","0.235"],["64651.30","0.001"],["64651.50","0.310"],["64651.60","0.001"],["64651.80","0.436"],["64651.90","0.090"],["64652.00","0.314"],["64652.10","0.189"],["64652.40","0.009"],["64652.60","0.059"],["64652.70","0.001"],["64652.90","0.001"],["64653.00","0.000"],["64653.50","0.120"],["64653.60","0.099"],["64653.70","0.123"],["64653.90","0.289"],["64654.00","0.628"],["64654.10","0.403"],["64654.20","0.049"],["64654.40","0.176"],["64654.60","0.024"],["64654.80","0.001"],["64655.10","0.001"],["64655.20","0.000"],["64655.40","0.002"],["64655.50","0.001"],["64655.60","0.015"],["64655.80","0.001"],["64656.30","0.003"],["64656.40","1.579"],["64656.50","0.002"],["64656.60","0.556"],["64656.70","0.000"],["64656.80","0.208"],["64656.90","0.126"],["64657.00","0.379"],["64657.10","0.000"],["64657.20","0.003"],["64657.30","0.000"],["64657.40","0.000"],["64657.50","0.378"],["64657.60","0.000"],["64657.70","0.000"],["64657.80","0.047"],["64657.90","0.000"],["64658.00","0.001"],["64658.10","0.000"],["64658.20","0.016"],["64658.30","0.201"],["64658.40","0.157"],["64658.50","0.001"],["64658.60","0.000"],["64658.70","0.124"],["64658.80","12.384"]],"a":[["64656.90","0.000"],["64657.00","0.000"],["64657.50","0.000"],["64657.60","0.000"],["64657.70","0.000"],["64657.80","0.000"],["64658.00","0.000"],["64658.20","0.000"],["64658.30","0.000"],["64658.40","0.000"],["64658.80","0.000"],["64658.90","1.561"],["64659.00","0.040"],["64659.10","0.001"],["64659.30","0.004"],["64659.50","0.034"],["64660.00","0.002"],["64660.10","0.153"],["64660.20","0.002"],["64660.30","0.000"],["64660.40","0.000"],["64660.50","0.033"],["64660.60","0.000"],["64660.70","0.181"],["64661.00","0.002"],["64661.30","0.005"],["64661.40","0.181"],["64662.00","0.127"],["64662.10","1.281"],["64662.40","0.005"],["64662.50","0.446"],["64662.60","0.011"],["64662.70","0.008"],["64663.30","0.061"],["64663.40","0.006"],["64663.50","0.001"],["64663.90","0.000"],["64664.50","0.001"],["64664.60","0.001"],["64664.70","0.048"],["64665.10","0.025"],["64665.40","0.015"],["64665.50","0.003"],["64666.00","0.005"],["64666.20","0.002"],["64666.40","0.003"],["64666.50","0.338"],["64667.30","0.002"],["64667.50","0.000"],["64667.60","0.002"],["64667.70","0.002"],["64667.90","0.001"],["64668.10","0.005"],["64668.20","0.000"],["64668.30","0.001"],["64668.50","0.002"],["64668.60","0.235"],["64668.80","0.073"],["64668.90","0.003"],["64669.00","0.004"],["64669.10","0.002"],["64669.20","0.635"],["64669.30","0.001"],["64669.40","0.000"],["64669.60","0.000"],["64669.70","0.007"],["64669.90","0.516"],["64670.10","0.005"],["64670.20","0.020"],["64670.30","0.310"],["64670.60","0.048"],["64671.10","0.022"],["64671.70","0.158"],["64671.80","0.309"],["64671.90","0.001"],["64672.00","1.492"],["64672.10","0.002"],["64672.20","0.077"],["64672.30","0.002"],["64672.70","0.003"],["64673.00","0.158"],["64673.10","0.507"],["64673.50","0.165"],["64673.70","0.851"],["64674.10","0.087"],["64674.20","0.805"],["64674.40","0.122"],["64674.60","0.005"],["64674.80","0.000"],["64674.90","0.034"],["64675.10","0.049"],["64675.20","0.038"],["64675.50","0.033"],["64675.60","0.713"],["64675.70","0.000"],["64676.00","0.001"],["64676.10","0.003"],["64676.20","0.730"],["64676.30","0.001"],["64676.90","0.297"],["64677.10","0.039"],["64677.90","0.001"],["64678.10","0.541"],["64678.20","0.001"],["64678.30","0.986"],["64678.40","1.431"],["64678.60","0.004"],["64678.80","1.796"],["64679.00","0.338"],["64679.30","0.000"],["64679.60","0.064"],["64679.80","0.007"],["64679.90","0.336"],["64680.30","0.002"],["64680.50","0.003"],["64680.70","0.000"],["64680.80","0.040"],["64681.10","0.389"],["64681.20","0.347"],["64681.40","0.006"],["64681.50","0.031"],["64681.60","0.006"],["64681.70","0.000"],["64681.80","0.000"],["64682.00","0.602"],["64682.10","0.012"],["64682.30","2.382"],["64682.70","0.115"],["64682.80","0.016"],["64683.00","1.366"],["64683.40","0.000"],["64684.10","0.063"],["64684.90","0.312"],["64685.50","0.003"],["64685.60","1.238"],["64685.70","0.001"],["64686.00","0.002"],["64686.20","0.000"],["64686.60","0.497"],["64686.70","1.096"],["64686.90","24.123"],["64687.00","0.469"],["64687.30","0.000"],["64687.40","0.002"],["64687.70","0.059"],["64687.80","0.000"],["64687.90","0.568"],["64688.00","0.997"],["64688.30","0.002"],["64688.40","0.031"],["64688.80","0.009"],["64688.90","0.367"],["64689.00","0.028"],["64689.90","0.038"],["64690.00","0.032"],["64690.30","0.814"],["64690.40","0.051"],["64690.60","0.651"],["64690.70","0.042"],["64690.80","3.726"],["64690.90","0.002"],["64691.20","0.318"],["64691.30","0.096"],["64692.20","0.039"],["64692.40","0.000"],["64692.70","0.048"],["64693.90","0.033"],["64694.00","0.034"],["64694.50","0.603"],["64694.70","0.000"],["64694.80","0.067"],["64695.40","0.359"],["64697.00","0.000"],["64697.10","0.003"],["64697.30","0.002"],["64697.60","0.015"],["64697.70","0.070"],["64698.60","0.002"],["64698.70","0.033"],["64699.00","0.003"],["64699.40","0.002"],["64700.30","0.002"],["64701.00","0.133"],["64701.10","0.001"],["64701.60","0.084"],["64701.70","0.000"],["64701.90","0.026"],["64702.20","0.425"],["64702.60","0.015"],["64704.40","0.000"],["64704.50","0.015"],["64704.90","0.495"],["64706.00","0.020"],["64706.60","2.166"],["64707.40","0.036"],["64707.60","0.000"],["64708.00","1.966"],["64708.20","0.027"],["64708.40","0.032"],["64708.70","0.201"],["64709.10","0.002"],["64709.70","10.064"],["64710.10","0.399"],["64712.30","0.456"],["64714.60","0.002"],["64714.80","2.000"],["64715.30","0.000"],["64715.50","0.001"],["64715.70","0.026"],["64716.30","0.321"],["64717.10","0.580"],["64717.20","0.000"],["64717.30","0.022"],["64717.60","0.984"],["64717.80","0.018"],["64718.00","4.020"],["64718.30","0.035"],["64718.60","0.000"],["64719.30","0.004"],["64719.40","0.001"],["64720.70","0.026"],["64721.00","0.004"],["64721.40","0.000"],["64721.60","0.159"],["64722.10","0.336"],["64723.70","0.340"],["64723.80","0.000"],["64726.50","3.443"],["64726.80","0.000"],["64727.00","0.041"],["64727.90","0.210"],["64728.90","0.046"],["64732.30","0.001"],["64732.60","0.557"],["64733.00","1.688"],["64736.70","0.859"],["64737.10","0.000"],["64739.20","4.994"],["64739.40","0.053"],["64740.00","0.269"],["64742.20","0.186"],["64742.60","0.030"],["64749.10","0.026"],["64752.90","0.001"],["64753.60","0.009"],["64754.00","0.014"],["64754.10","10.000"],["64755.50","1.319"],["64757.00","0.015"],["64757.30","7.921"],["64759.90","0.047"],["64761.70","0.013"],["64762.40","0.004"],["64766.00","0.226"],["64766.90","0.008"],["64774.50","0.001"],["64781.30","0.001"],["64784.50","0.000"],["64784.60","0.480"],["64787.00","0.000"],["64788.20","0.001"],["64788.40","0.276"],["64794.70","0.556"],["64795.30","0.001"],["64797.90","0.009"],["64801.60","1.595"],["64802.40","0.000"],["64802.50","1.466"],["64814.10","0.000"],["64814.70","0.000"],["64818.40","0.000"],["64820.30","0.001"],["64820.40","1.490"],["64823.00","0.004"],["64827.10","0.071"],["64827.80","0.070"],["64842.10","0.002"],["64846.00","0.001"],["64849.90","0.000"],["64852.90","0.222"],["64875.10","0.000"],["64891.30","0.004"],["64910.60","0.027"],["64917.50","0.001"],["64971.30","0.002"],["64975.30","0.000"],["64976.80","0.000"],["64980.10","0.113"],["64982.20","0.001"],["65039.90","0.002"],["65046.90","0.001"],["65104.60","0.000"],["65111.50","0.003"],["65169.20","0.000"],["65176.20","0.002"],["65303.50","0.063"],["65303.60","0.000"],["65305.00","14.047"],["65305.50","0.000"],["65400.50","1.528"],["65403.00","14.528"],["65465.20","0.763"],["65467.70","8.316"],["65531.70","0.536"],["65658.80","1.066"],["65716.70","3.192"],["65942.90","0.645"],["65952.00","0.009"]],"st":1}}
{"stream":"btcusdt@depth@100ms","data":{"e":"depthUpdate","E":1784410681264,"T":1784410681263,"s":"BTCUSDT","ps":"BTCUSDT","U":11079105732653,"u":11079105745504,"pu":11079105732622,"b":[["1000.00","50.391"],["14149.90","0.700"],["14158.80","0.014"],["14258.80","0.196"],["14349.90","0.000"],["14458.80","0.112"],["14558.80","0.224"],["51725.10","0.002"],["58192.90","0.002"],["61421.30","0.002"],["62026.80","2.000"],["62072.40","0.003"],["62673.00","1.000"],["63699.50","7.366"],["64012.20","0.186"],["64062.40","6.900"],["64297.30","0.018"],["64330.70","0.057"],["64335.60","0.003"],["64421.30","0.828"],["64451.00","8.334"],["64454.00","0.001"],["64472.10","0.146"],["64483.80","0.082"],["64527.70","2.054"],["64543.70","0.000"],["64544.50","0.046"],["64544.80","0.000"],["64546.30","4.313"],["64546.80","0.000"],["64547.80","1.454"],["64549.30","0.001"],["64550.20","0.559"],["64550.80","0.003"],["64550.90","0.000"],["64552.30","0.000"],["64553.80","0.000"],["64555.30","0.803"],["64556.80","0.015"],["64558.30","0.001"],["64559.80","0.021"],["64559.90","0.001"],["64560.30","3.008"],["64561.30","0.002"],["64562.10","0.766"],["64562.80","2.024"],["64564.30","2.594"],["64565.00","0.391"],["64565.80","0.000"],["64566.40","1.129"],["64566.50","5.911"],["64567.10","0.017"],["64567.30","0.000"],["64568.80","1.289"],["64578.10","0.028"],["64578.40","0.326"],["64587.80","2.875"],["64591.00","0.024"],["64597.50","0.026"],["64598.80","0.173"],["64599.60","0.000"],["64603.10","0.095"],["64604.50","0.684"],["64605.30","22.383"],["64605.60","0.071"],["64608.70","0.243"],["64610.20","0.109"],["64611.40","0.533"],["64613.40","0.003"],["64618.40","0.562"],["64619.30","0.016"],["64619.50","0.075"],["64621.40","0.340"],["64623.80","0.342"],["64627.00","0.726"],["64627.30","1.281"],["64627.60","0.774"],["64627.70","0.099"],["64627.80","0.150"],["64628.50","0.003"],["64628.90","0.032"],["64631.10","0.000"],["64631.90","0.090"],["64632.90","0.010"],["64633.40","0.000"],["64634.50","0.355"],["64634.60","0.400"],["64634.70","0.117"],["64635.60","0.010"],["64636.30","0.080"],["64638.90","0.073"],["64640.00","5.070"],["64640.10","0.005"],["64640.30","0.001"],["64640.50","0.004"],["64641.80","0.001"],["64643.90","0.002"],["64644.10","0.001"],["64644.60","0.002"],["64644.70","0.001"],["64644.90","0.926"],["64645.10","0.196"],["64645.30","0.256"],["64645.40","1.369"],["64645.50","0.677"],["64645.60","0.545"],["64646.00","1.010"],["64646.20","0.542"],["64646.40","0.024"],["64647.10","0.024"],["64647.60","0.001"],["64647.70","0.000"],["64647.80","0.002"],["64647.90","0.061"],["64648.00","0.004"],["64648.20","0.007"],["64648.40","0.000"],["64648.50","0.430"],["64648.70","0.001"],["64650.00","1.341"],["64650.10","0.790"],["64650.20","0.121"],["64650.50","0.134"],["64650.90","0.002"],["64651.00","0.006"],["64651.10","0.002"],["64651.20","0.003"],["64652.10","0.189"],["64652.30","0.007"],["64652.70","0.002"],["64653.20","0.314"],["64653.40","0.005"],["64653.90","0.289"],["64654.00","0.477"],["64654.10","10.403"],["64654.20","2.075"],["64654.40","1.594"],["64654.50","0.020"],["64655.30","0.033"],["64656.00","0.005"],["64656.30","0.003"],["64656.40","1.577"],["64657.60","0.634"],["64658.30","0.332"],["64658.50","0.001"],["64658.60","0.000"],["64658.70","0.124"],["64658.80","11.123"]],"a":[["64658.90","2.343"],["64659.00","0.003"],["64659.30","0.002"],["64659.40","0.000"],["64661.40","0.183"],["64661.50","0.124"],["64662.00","0.139"],["64662.10","1.283"],["64662.50","0.355"],["64663.90","0.129"],["64666.40","0.103"],["64667.20","0.002"],["64667.30","0.000"],["64668.40","0.002"],["64668.60","0.233"],["64669.70","0.005"],["64669.90","0.434"],["64670.70","0.080"],["64671.00","0.003"],["64671.20","0.001"],["64671.90","0.005"],["64672.80","0.000"],["64673.40","0.228"],["64674.60","0.006"],["64676.10","0.544"],["64676.90","0.201"],["64677.60","0.005"],["64678.10","0.000"],["64679.00","0.242"],["64681.00","0.004"],["64681.20","0.346"],["64681.60","0.004"],["64682.10","0.015"],["64682.30","2.384"],["64683.40","0.001"],["64684.10","0.059"],["64684.40","0.781"],["64684.80","0.069"],["64686.40","0.561"],["64687.00","0.438"],["64687.40","0.033"],["64687.90","0.012"],["64688.40","0.000"],["64688.80","0.040"],["64692.00","0.004"],["64692.50","0.123"],["64692.90","0.014"],["64693.60","0.010"],["64694.80","0.057"],["64695.50","0.324"],["64695.80","0.014"],["64698.70","0.069"],["64699.70","1.197"],["64699.90","0.002"],["64700.20","0.001"],["64700.50","0.507"],["64700.60","0.001"],["64701.60","0.072"],["64701.70","0.012"],["64702.60","0.115"],["64704.90","0.481"],["64706.20","0.001"],["64706.60","2.168"],["64707.80","0.000"],["64707.90","0.078"],["64708.00","3.259"],["64708.40","0.032"],["64708.50","10.000"],["64708.70","0.123"],["64709.70","10.066"],["64710.60","0.346"],["64714.80","0.000"],["64717.50","0.067"],["64719.20","0.014"],["64719.60","0.210"],["64721.10","0.039"],["64722.60","0.001"],["64725.00","0.022"],["64725.80","0.006"],["64726.50","3.419"],["64727.00","0.027"],["64727.40","0.031"],["64727.60","0.353"],["64727.90","0.000"],["64730.80","0.025"],["64737.30","0.228"],["64737.50","0.244"],["64743.40","0.006"],["64746.30","0.002"],["64752.30","0.027"],["64757.20","0.008"],["64760.30","0.007"],["64766.90","0.000"],["64767.20","0.064"],["64767.80","1.079"],["64772.20","0.000"],["64863.50","0.147"],["65029.70","0.001"],["65034.50","0.358"],["65301.30","0.000"],["65305.50","0.153"],["65306.00","0.084"],["65684.40","7.722"]],"st":1}}
{"stream":"btcusdt@depth@100ms","data":{"e":"depthUpdate","E":1784410681366,"T":1784410681365,"s":"BTCUSDT","ps":"BTCUSDT","U":11079105745669,"u":11079105756855,"pu":11079105745504,"b":[["14149.90","0.574"],["14158.80","0.140"],["14258.80","0.070"],["14458.80","0.224"],["14556.40","0.154"],["14556.80","0.014"],["14558.80","0.350"],["51720.00","0.004"],["51725.10","0.000"],["58192.90","0.002"],["60734.60","4.027"],["61380.70","3.007"],["61425.80","0.001"],["63365.70","0.009"],["63712.50","26.796"],["63889.60","0.783"],["63906.40","9.380"],["64012.20","0.186"],["64023.10","0.007"],["64039.80","2.129"],["64132.70","8.092"],["64330.70","0.047"],["64333.10","0.000"],["64349.50","0.000"],["64371.50","0.004"],["64544.50","0.007"],["64544.70","0.039"],["64557.90","0.008"],["64560.40","0.000"],["64570.80","2.593"],["64576.00","0.024"],["64582.40","0.117"],["64583.40","0.317"],["64590.80","0.210"],["64591.40","0.311"],["64594.10","0.030"],["64598.20","0.452"],["64603.70","3.279"],["64604.50","1.077"],["64605.80","0.368"],["64612.70","0.000"],["64614.40","0.017"],["64615.10","0.120"],["64616.30","0.049"],["64618.80","0.016"],["64619.50","0.005"],["64623.10","0.717"],["64624.10","0.000"],["64624.20","2.172"],["64625.80","0.179"],["64626.30","0.387"],["64626.50","0.531"],["64627.00","0.716"],["64629.60","1.905"],["64630.10","0.641"],["64630.70","0.013"],["64633.10","0.317"],["64633.30","0.028"],["64635.00","0.982"],["64635.60","0.165"],["64636.50","0.008"],["64636.90","0.004"],["64637.30","10.000"],["64637.90","0.020"],["64638.60","0.619"],["64638.80","0.139"],["64639.20","0.000"],["64639.40","0.355"],["64639.70","0.012"],["64639.80","2.006"],["64640.00","5.068"],["64640.10","0.003"],["64640.40","0.156"],["64640.70","0.205"],["64640.80","0.002"],["64641.20","0.636"],["64641.90","0.327"],["64642.00","1.469"],["64642.70","0.119"],["64643.00","0.562"],["64643.30","0.059"],["64643.70","0.000"],["64644.00","0.928"],["64644.50","0.765"],["64644.60","0.002"],["64644.90","0.000"],["64645.10","0.080"],["64645.50","0.120"],["64645.70","0.156"],["64646.20","0.001"],["64646.30","0.944"],["64647.00","0.560"],["64647.30","0.254"],["64648.20","0.000"],["64648.50","0.410"],["64649.30","0.005"],["64649.80","0.329"],["64649.90","2.842"],["64650.00","1.275"],["64650.10","0.566"],["64650.20","1.435"],["64650.80","0.188"],["64651.10","0.002"],["64651.20","0.004"],["64651.50","0.001"],["64652.10","0.001"],["64652.60","0.000"],["64653.60","0.117"],["64654.00","0.465"],["64654.10","0.403"],["64654.20","0.049"],["64654.30","0.002"],["64654.40","0.285"],["64654.50","0.320"],["64654.60","0.000"],["64656.30","0.001"],["64656.40","0.340"],["64656.50","0.001"],["64656.80","0.128"],["64657.10","0.634"],["64657.30","0.310"],["64657.60","0.000"],["64657.70","0.452"],["64657.80","0.000"],["64658.10","0.000"],["64658.30","0.332"],["64658.80","10.516"]],"a":[["64658.90","3.357"],["64659.90","0.047"],["64661.70","0.311"],["64662.00","0.129"],["64662.20","1.187"],["64662.70","0.055"],["64665.00","0.002"],["64665.60","0.053"],["64667.50","0.001"],["64669.20","0.901"],["64669.90","0.430"],["64670.60","0.047"],["64670.80","0.060"],["64671.80","1.546"],["64671.90","0.005"],["64672.50","0.013"],["64673.50","0.155"],["64674.20","0.093"],["64675.50","0.574"],["64676.10","0.003"],["64676.30","0.001"],["64678.10","0.926"],["64678.30","0.060"],["64679.60","0.069"],["64679.70","0.246"],["64680.10","0.589"],["64680.60","0.010"],["64681.00","0.002"],["64681.40","0.004"],["64683.00","1.416"],["64684.00","0.001"],["64685.50","0.559"],["64686.40","0.005"],["64690.40","0.001"],["64690.50","1.855"],["64691.50","1.856"],["64692.40","0.010"],["64692.90","10.014"],["64693.60","0.000"],["64697.70","0.070"],["64699.70","1.197"],["64702.30","0.556"],["64702.50","1.262"],["64705.10","0.004"],["64707.70","0.301"],["64707.90","0.000"],["64708.00","1.979"],["64708.50","0.000"],["64712.40","1.783"],["64716.40","3.302"],["64717.60","4.465"],["64719.50","24.208"],["64720.30","1.641"],["64721.70","0.003"],["64722.60","0.032"],["64729.00","0.112"],["64737.30","0.224"],["64744.50","0.018"],["64759.50","0.004"],["64771.20","0.540"],["64780.80","0.915"],["64782.00","3.883"],["64783.30","0.107"],["64784.60","0.000"],["64784.70","0.479"],["64802.50","0.000"],["64802.60","1.466"],["64820.40","0.024"],["64820.50","1.478"],["64982.20","0.002"],["65305.50","0.153"],["65467.10","0.228"]],"st":1}}
{"stream":"btcusdt@depth@100ms","data":{"e":"depthUpdate","E":1784410681468,"T":1784410681467,"s":"BTCUSDT","ps":"BTCUSDT","U":11079105756966,"u":11079105765851,"pu":11079105756855,"b":[["1000.00","50.391"],["14149.90","0.462"],["14158.80","0.252"],["14256.40","0.098"],["14256.80","0.000"],["14258.80","0.000"],["14458.80","0.350"],["14554.00","1.120"],["14554.10","0.000"],["14556.40","0.126"],["14558.80","0.462"],["51720.00","0.004"],["58192.90","0.002"],["61417.50","0.009"],["61425.80","0.001"],["62072.40","0.000"],["63736.70","18.640"],["64007.60","0.001"],["64012.20","0.188"],["64326.80","1.085"],["64421.30","0.833"],["64544.80","1.278"],["64546.30","5.591"],["64547.80","2.732"],["64549.30","1.279"],["64550.80","1.281"],["64552.30","1.278"],["64553.80","1.278"],["64555.30","2.081"],["64556.80","1.293"],["64558.30","1.279"],["64559.80","1.299"],["64561.30","1.280"],["64562.80","3.302"],["64564.30","3.872"],["64565.80","1.278"],["64567.30","1.278"],["64588.80","0.046"],["64594.60","0.266"],["64605.30","0.028"],["64605.80","0.298"],["64607.20","0.026"],["64607.40","22.374"],["64607.50","4.501"],["64613.00","1.073"],["64615.10","0.000"],["64616.30","0.000"],["64622.60","0.122"],["64623.70","0.077"],["64626.50","0.481"],["64633.50","0.907"],["64633.70","0.055"],["64635.60","0.010"],["64637.30","0.000"],["64639.80","0.589"],["64640.40","0.002"],["64640.70","0.050"],["64640.80","0.003"],["64641.10","2.374"],["64644.00","1.628"],["64645.90","0.014"],["64646.30","0.067"],["64647.30","0.099"],["64649.10","0.234"],["64650.30","0.714"],["64650.80","0.198"],["64652.00","0.316"],["64652.30","0.009"],["64654.00","0.457"],["64654.50","0.010"],["64658.80","10.526"]],"a":[["64658.90","2.344"],["64659.90","0.000"],["64661.70","0.001"],["64662.20","0.465"],["64662.50","0.665"],["64662.70","0.008"],["64666.80","0.004"],["64669.30","0.000"],["64671.70","0.880"],["64679.70","0.242"],["64680.20","1.165"],["64691.50","0.413"],["64692.40","0.000"],["64692.90","0.024"],["64695.40","0.617"],["64697.50","2.311"],["64709.40","0.000"],["64717.30","4.622"],["64717.40","24.203"],["64717.60","0.001"],["64719.50","0.007"],["64786.90","0.063"],["64867.20","0.001"],["64889.90","0.004"],["64919.10","0.018"],["65305.50","0.153"],["65455.50","2.683"],["65725.80","1.064"]],"st":1}}
{"stream":"btcusdt@depth@100ms","data":{"e":"depthUpdate","E":1784410681570,"T":1784410681569,"s":"BTCUSDT","ps":"BTCUSDT","U":11079105765931,"u":11079105775675,"pu":11079105765851,"b":[["1000.00","50.391"],["14149.90","0.336"],["14158.80","0.378"],["14254.00","0.840"],["14256.40","0.000"],["14458.80","0.462"],["14554.00","1.008"],["14558.80","0.588"],["58192.90","0.002"],["61425.80","0.001"],["62072.40","0.003"],["62442.10","0.082"],["63692.00","0.002"],["63992.60","0.001"],["64012.20","0.186"],["64136.80","0.310"],["64330.70","0.046"],["64454.00","0.001"],["64456.40","0.014"],["64458.80","0.000"],["64544.70","0.000"],["64544.80","0.000"],["64544.90","0.039"],["64546.30","4.313"],["64547.80","1.454"],["64549.30","0.001"],["64550.80","0.003"],["64552.30","0.000"],["64552.90","0.595"],["64553.20","0.004"],["64553.80","0.000"],["64555.30","0.803"],["64556.80","0.015"],["64558.30","0.001"],["64559.80","0.021"],["64561.30","0.002"],["64562.80","2.024"],["64564.30","2.594"],["64565.80","0.000"],["64567.30","0.000"],["64624.10","0.004"],["64628.70","0.003"],["64635.00","0.282"],["64638.80","0.137"],["64639.00","0.069"],["64639.40","0.357"],["64640.40","0.156"],["64640.80","0.007"],["64642.70","0.003"],["64644.00","0.702"],["64645.60","0.661"],["64646.30","0.203"],["64646.40","0.950"],["64651.70","0.002"],["64652.10","0.003"],["64654.00","0.456"],["64654.90","0.094"],["64656.40","0.338"],["64657.10","0.000"],["64657.70","0.499"],["64657.80","0.634"],["64658.80","10.527"]],"a":[["64658.90","3.077"],["64662.00","0.284"],["64662.20","0.620"],["64662.30","24.276"],["64662.50","0.355"],["64666.40","0.105"],["64666.80","0.006"],["64670.30","0.407"],["64670.70","0.260"],["64671.70","0.726"],["64672.90","0.155"],["64674.60","0.010"],["64690.70","0.002"],["64692.00","0.044"],["64699.00","0.002"],["64699.70","1.197"],["64717.20","0.004"],["64717.50","0.063"],["64806.80","3.838"],["64811.40","0.000"],["64843.80","0.001"],["64844.20","0.003"],["65305.50","0.153"],["65467.10","0.486"],["65470.90","2.198"],["65693.40","1.064"]],"st":1}}
{"stream":"btcusdt@depth@100ms","data":{"e":"depthUpdate","E":1784410681672,"T":1784410681669,"s":"BTCUSDT","ps":"BTCUSDT","U":11079105775896,"u":11079105786338,"pu":11079105775675,"b":[["14149.90","0.224"],["14158.80","0.490"],["14254.00","0.728"],["14458.80","0.588"],["14554.00","0.882"],["14558.80","0.700"],["58192.90","0.002"],["61425.80","0.001"],["62072.40","0.000"],["63365.10","0.000"],["63437.00","0.330"],["63508.80","0.503"],["63580.70","0.000"],["63652.50","0.001"],["63666.50","0.783"],["63692.60","3.334"],["63724.30","0.002"],["63753.00","2.366"],["63795.70","1.801"],["63796.20","0.000"],["63868.00","0.000"],["63939.90","0.391"],["64011.70","6.188"],["64012.20","0.186"],["64297.30","0.023"],["64335.50","0.012"],["64421.30","0.835"],["64585.30","0.101"],["64613.00","1.003"],["64620.20","0.070"],["64623.10","0.001"],["64640.40","0.002"],["64641.10","2.004"],["64643.00","0.560"],["64643.40","0.117"],["64643.60","0.001"],["64644.30","0.000"],["64644.50","0.572"],["64644.70","0.927"],["64645.60","0.545"],["64646.30","0.067"],["64646.40","0.024"],["64647.30","0.099"],["64649.10","0.002"],["64649.70","0.325"],["64650.30","0.173"],["64650.80","0.198"],["64650.90","0.543"],["64655.40","0.000"],["64657.40","0.007"],["64657.70","0.379"],["64657.90","0.002"],["64658.80","11.307"]],"a":[["64658.90","3.079"],["64662.00","0.129"],["64662.20","0.465"],["64662.30","24.229"],["64662.70","0.008"],["64671.70","0.716"],["64672.80","0.010"],["64677.10","0.048"],["64689.00","0.728"],["64699.70","1.197"],["64714.60","0.001"],["64721.90","0.027"],["64810.00","0.498"],["64923.50","0.021"],["64982.20","0.003"],["65304.90","0.000"],["65305.50","0.153"],["65376.70","0.000"],["65448.60","0.000"],["65466.50","2.276"],["65520.40","0.000"],["65592.30","0.000"],["65664.10","0.000"],["65735.90","0.004"],["65774.00","9.501"],["65807.80","0.004"],["65879.60","0.000"],["65951.50","1.354"]],"st":1}}
{"stream":"btcusdt@depth@100ms","data":{"e":"depthUpdate","E":1784410681774,"T":1784410681773,"s":"BTCUSDT","ps":"BTCUSDT","U":11079105786542,"u":11079105795453,"pu":11079105786338,"b":[["1000.00","50.541"],["14149.90","0.098"],["14158.80","0.616"],["14254.00","0.602"],["14458.80","0.700"],["14554.00","0.770"],["14558.80","0.826"],["58192.90","0.002"],["63615.50","8.001"],["63684.20","0.394"],["63712.50","25.699"],["63744.80","27.731"],["64012.20","0.186"],["64458.80","0.000"],["64585.30","0.100"],["64594.10","0.031"],["64603.10","0.095"],["64604.50","4.363"],["64605.30","22.383"],["64607.00","1.100"],["64607.40","0.019"],["64607.50","0.012"],["64640.40","0.002"],["64641.10","0.004"],["64641.40","0.040"],["64643.30","0.779"],["64644.00","0.704"],["64644.10","0.003"],["64645.00","10.003"],["64646.10","3.743"],["64646.30","0.199"],["64647.30","0.821"],["64649.70","0.093"],["64649.90","2.842"],["64650.20","1.667"],["64650.30","0.002"],["64650.80","0.188"],["64650.90","0.002"],["64651.00","0.006"],["64654.30","0.000"],["64656.50","0.003"],["64657.30","0.620"],["64658.80","12.096"]],"a":[["64658.90","2.505"],["64659.00","0.004"],["64665.40","0.015"],["64665.60","0.006"],["64665.70","0.050"],["64666.00","0.023"],["64668.90","0.000"],["64677.80","0.187"],["64695.40","0.359"],["64697.50","0.311"],["64699.70","1.197"],["64702.10","1.923"],["64702.20","10.011"],["64714.60","0.000"],["64717.40","0.002"],["64719.50","24.208"],["64723.60","0.002"],["64788.30","0.000"],["65305.50","0.153"],["65470.90","1.970"],["65596.50","1.072"],["65628.80","0.343"],["65767.50","1.592"]],"st":1}}
{"stream":"btcusdt@depth@100ms","data":{"e":"depthUpdate","E":1784410681876,"T":1784410681875,"s":"BTCUSDT","ps":"BTCUSDT","U":11079105795582,"u":11079105802590,"pu":11079105795453,"b":[["1000.00","50.391"],["14149.90","0.000"],["14158.80","0.728"],["14254.00","0.490"],["14458.80","0.840"],["14554.00","0.644"],["14558.80","0.910"],["58192.90","0.002"],["61425.80","0.001"],["62072.40","0.003"],["63624.30","1.099"],["63712.50","24.603"],["63721.20","1.099"],["64012.20","0.186"],["64136.80","1.556"],["64400.00","28.460"],["64451.90","0.176"],["64544.80","0.000"],["64546.30","4.313"],["64547.80","1.454"],["64549.30","0.001"],["64550.80","0.003"],["64552.30","0.000"],["64553.80","0.000"],["64555.30","0.803"],["64556.80","0.015"],["64558.30","0.001"],["64559.80","0.021"],["64560.60","0.341"],["64561.30","0.002"],["64562.80","3.302"],["64602.30","0.636"],["64604.50","1.163"],["64607.00","4.296"],["64607.10","0.016"],["64615.20","0.600"],["64620.00","0.009"],["64623.70","0.028"],["64628.30","0.716"],["64630.10","0.947"],["64630.90","0.063"],["64637.90","0.000"],["64640.40","0.156"],["64641.10","0.002"],["64645.90","0.016"],["64647.30","0.099"],["64648.50","0.430"],["64649.70","0.325"],["64650.00","1.303"],["64650.20","1.435"],["64650.30","0.560"],["64650.80","0.352"],["64654.80","0.067"],["64657.70","0.381"],["64658.80","11.313"]],"a":[["64658.90","2.506"],["64662.00","0.284"],["64662.20","0.620"],["64665.10","0.026"],["64665.70","0.003"],["64667.50","0.000"],["64699.70","1.197"],["65176.20","1.228"],["65305.50","0.153"]],"st":1}}
{"stream":"btcusdt@depth@100ms","data":{"e":"depthUpdate","E":1784410681978,"T":1784410681977,"s":"BTCUSDT","ps":"BTCUSDT","U":11079105802647,"u":11079105809493,"pu":11079105802590,"b":[["14158.80","0.854"],["14254.00","0.364"],["14458.80","1.078"],["14554.00","0.532"],["14558.80","0.784"],["58192.90","0.002"],["61425.80","0.001"],["62072.40","0.000"],["63583.20","4.194"],["63647.80","10.982"],["63712.50","23.506"],["64012.20","0.188"],["64335.50","0.012"],["64634.00","0.002"],["64640.40","0.002"],["64642.90","0.711"],["64645.00","0.003"],["64645.40","1.265"],["64646.40","0.101"],["64647.30","0.099"],["64649.90","2.845"],["64650.00","1.306"],["64650.10","3.150"],["64650.20","1.443"],["64650.30","0.019"],["64650.70","1.336"],["64650.80","0.198"],["64650.90","0.002"],["64651.00","0.701"],["64652.30","0.004"],["64653.90","0.003"],["64654.00","0.461"],["64656.40","0.329"],["64658.80","11.320"]],"a":[["64658.90","3.114"],["64664.10","0.000"],["64664.50","0.048"],["64670.30","0.310"],["64670.70","0.080"],["64697.90","2.004"],["64699.70","1.197"],["64782.20","0.128"],["65305.50","0.153"]],"st":1}}
{"stream":"btcusdt@depth@100ms","data":{"e":"depthUpdate","E":1784410682080,"T":1784410682079,"s":"BTCUSDT","ps":"BTCUSDT","U":11079105809561,"u":11079105817678,"pu":11079105809493,"b":[["1000.00","50.391"],["14158.80","0.966"],["14254.00","0.252"],["14458.80","1.316"],["14554.00","0.406"],["14558.80","0.672"],["58192.90","0.002"],["61425.80","0.001"],["62072.40","0.003"],["62280.30","0.004"],["63465.50","0.803"],["63635.10","0.001"],["63777.80","5.260"],["64012.20","0.186"],["64068.00","7.868"],["64088.00","0.175"],["64452.70","0.001"],["64458.80","0.000"],["64484.20","0.256"],["64560.60","0.000"],["64562.80","2.024"],["64564.30","2.594"],["64565.80","0.000"],["64566.40","1.457"],["64587.70","0.344"],["64603.80","0.015"],["64605.30","0.028"],["64607.00","0.001"],["64607.40","22.374"],["64607.50","4.501"],["64616.80","0.045"],["64629.70","0.030"],["64632.40","0.042"],["64633.50","0.907"],["64638.90","0.035"],["64640.00","5.068"],["64640.40","0.156"],["64643.80","10.178"],["64644.50","0.031"],["64645.50","0.661"],["64646.10","2.377"],["64646.40","0.024"],["64647.20","1.303"],["64649.70","0.093"],["64650.20","1.675"],["64652.30","0.002"],["64656.40","0.252"],["64656.80","0.123"],["64657.40","0.641"],["64657.80","0.000"],["64658.30","0.394"],["64658.80","12.107"]],"a":[["64658.90","2.508"],["64661.40","0.183"],["64662.00","0.129"],["64662.20","0.465"],["64664.50","0.001"],["64664.80","0.049"],["64667.90","0.001"],["64672.90","0.154"],["64674.40","0.122"],["64676.40","0.392"],["64676.50","0.016"],["64685.90","0.060"],["64687.70","0.002"],["64689.40","0.031"],["64689.70","0.001"],["64699.00","0.558"],["64699.70","1.197"],["64702.20","0.011"],["64702.40","0.095"],["64717.10","0.571"],["64721.80","6.016"],["64728.20","0.148"],["64801.50","4.642"],["64839.90","1.060"],["64886.00","2.171"],["65167.20","7.253"],["65305.50","0.153"],["65470.90","1.590"],["65547.60","7.077"],["65664.80","0.783"]],"st":1}}
{"stream":"btcusdt@depth@100ms","data":{"e":"depthUpdate","E":1784410682182,"T":1784410682181,"s":"BTCUSDT","ps":"BTCUSDT","U":11079105817834,"u":11079105826758,"pu":11079105817678,"b":[["14158.80","1.092"],["14254.00","0.126"],["14458.80","1.554"],["14549.90","0.224"],["14554.00","0.336"],["14558.80","0.546"],["58192.90","0.002"],["61417.50","0.011"],["62072.40","0.000"],["63365.70","0.012"],["63645.80","0.011"],["63651.90","1.098"],["63716.50","1.097"],["64012.20","0.186"],["64062.40","6.433"],["64068.10","1.170"],["64559.20","3.043"],["64568.60","0.013"],["64595.50","0.030"],["64603.00","0.001"],["64604.50","4.354"],["64604.70","0.013"],["64605.20","22.234"],["64607.00","1.100"],["64607.40","0.019"],["64607.50","0.012"],["64627.00","0.703"],["64636.10","0.166"],["64636.80","0.015"],["64643.00","0.003"],["64643.80","0.178"],["64644.90","0.557"],["64646.00","1.011"],["64646.10","2.377"],["64647.70","2.000"],["64648.50","0.677"],["64650.20","0.361"],["64651.10","1.316"],["64656.40","0.178"],["64657.20","0.005"],["64657.40","0.643"],["64658.80","12.175"]],"a":[["64658.90","2.342"],["64664.40","0.047"],["64664.80","0.002"],["64665.50","0.050"],["64668.00","0.181"],["64671.60","0.001"],["64671.70","0.158"],["64672.80","0.010"],["64672.90","0.712"],["64673.40","0.215"],["64682.10","0.028"],["64697.90","0.004"],["64699.70","1.351"],["64702.10","1.870"],["64703.10","10.004"],["64705.00","0.111"],["64714.20","0.013"],["64717.20","4.607"],["64717.30","24.223"],["64719.50","0.007"],["64742.70","0.013"],["64751.10","0.106"],["65305.50","0.153"],["67210.00","0.121"]],"st":1}}
{"stream":"btcusdt@depth@100ms","data":{"e":"depthUpdate","E":1784410682284,"T":1784410682282,"s":"BTCUSDT","ps":"BTCUSDT","U":11079105826778,"u":11079105833461,"pu":11079105826758,"b":[["14158.80","1.204"],["14254.00","0.014"],["14458.80","1.792"],["14549.90","0.098"],["14558.80","0.434"],["58192.90","0.002"],["61425.80","0.001"],["63755.30","0.939"],["63865.50","19.251"],["64012.20","0.186"],["64335.50","0.002"],["64389.00","0.091"],["64458.80","0.000"],["64510.00","0.341"],["64517.30","0.047"],["64518.10","0.663"],["64527.00","3.867"],["64565.00","0.050"],["64566.40","1.129"],["64604.50","1.163"],["64607.00","4.275"],["64610.00","0.333"],["64618.30","0.394"],["64618.40","0.560"],["64618.50","0.048"],["64618.70","10.055"],["64618.80","0.014"],["64618.90","0.000"],["64629.20","0.008"],["64634.20","0.054"],["64634.30","0.372"],["64634.40","0.010"],["64640.40","0.156"],["64642.80","0.002"],["64645.10","0.080"],["64646.70","0.000"],["64649.90","2.838"],["64650.40","0.067"],["64654.90","0.007"],["64655.20","0.090"],["64655.30","0.002"],["64658.80","12.182"]],"a":[["64677.60","0.005"],["64699.70","1.197"],["64717.10","0.575"],["64717.20","4.603"],["64733.30","2.319"],["64982.20","0.002"],["65305.50","0.153"],["65672.00","0.012"],["65677.50","0.114"]],"st":1}}
{"stream":"btcusdt@depth@100ms","data":{"e":"depthUpdate","E":1784410682386,"T":1784410682385,"s":"BTCUSDT","ps":"BTCUSDT","U":11079105833563,"u":11079105840745,"pu":11079105833461,"b":[["1000.00","50.391"],["14158.80","1.330"],["14249.90","0.070"],["14250.20","0.000"],["14254.00","0.000"],["14358.80","0.014"],["14458.80","2.002"],["14549.90","0.000"],["14558.80","0.308"],["45255.00","0.004"],["51727.00","0.000"],["58192.90","0.002"],["61425.80","0.001"],["61425.90","0.003"],["62072.40","0.003"],["63546.70","0.549"],["63581.40","1.334"],["63591.90","1.108"],["63721.20","2.196"],["64012.20","0.186"],["64335.50","0.003"],["64422.90","0.000"],["64487.70","0.002"],["64537.50","0.035"],["64553.20","0.001"],["64553.30","0.004"],["64565.00","0.391"],["64636.00","0.012"],["64640.40","0.002"],["64641.00","10.001"],["64642.70","0.005"],["64643.50","0.002"],["64645.00","0.544"],["64645.50","0.120"],["64647.70","0.000"],["64649.00","0.611"],["64650.70","1.338"],["64654.00","0.462"],["64656.40","0.169"],["64656.50","0.002"],["64656.70","0.001"],["64657.00","0.380"],["64658.70","0.125"],["64658.80","12.181"]],"a":[["64658.90","2.445"],["64662.00","0.284"],["64662.20","0.620"],["64665.50","0.003"],["64667.20","0.003"],["64674.30","0.358"],["64677.40","1.306"],["64678.10","0.000"],["64687.50","0.704"],["64689.00","0.028"],["64696.90","0.010"],["64698.40","2.000"],["64699.70","1.351"],["64702.10","0.433"],["64703.10","0.004"],["64765.60","0.006"],["64841.60","0.100"],["65176.10","0.314"],["65305.50","0.153"],["65425.80","31.710"],["65470.40","0.000"],["65500.00","99.322"],["65581.60","14.496"]],"st":1}}
{"stream":"btcusdt@depth@100ms","data":{"e":"depthUpdate","E":1784410682488,"T":1784410682486,"s":"BTCUSDT","ps":"BTCUSDT","U":11079105840817,"u":11079105848298,"pu":11079105840745,"b":[["14158.80","1.358"],["14249.90","0.000"],["14358.80","0.140"],["14458.80","1.988"],["14558.80","0.238"],["58192.90","0.002"],["61425.80","0.001"],["62072.40","0.000"],["63874.10","35.410"],["63882.90","1.564"],["64012.20","0.186"],["64035.70","7.702"],["64132.70","4.200"],["64228.10","0.289"],["64292.80","0.291"],["64293.30","0.005"],["64357.50","0.303"],["64358.10","0.004"],["64422.20","0.289"],["64489.40","0.059"],["64627.10","3.359"],["64639.40","0.375"],["64640.40","0.156"],["64643.20","3.256"],["64644.70","0.001"],["64644.90","1.483"],["64645.00","0.003"],["64645.70","0.697"],["64645.90","0.016"],["64648.50","0.430"],["64649.90","2.788"],["64654.00","0.461"],["64655.20","0.001"],["64658.80","12.233"]],"a":[["64658.90","2.279"],["64663.60","0.000"],["64663.90","0.129"],["64664.30","0.001"],["64664.60","0.001"],["64664.90","0.001"],["64665.20","0.001"],["64665.50","0.003"],["64665.80","0.047"],["64675.50","0.033"],["64676.10","0.544"],["64677.40","1.306"],["64678.30","0.060"],["64678.40","1.431"],["64679.30","0.309"],["64679.90","0.027"],["64699.70","1.197"],["64722.40","0.001"],["64885.20","0.124"],["65167.20","3.423"],["65305.50","0.153"]],"st":1}}
{"stream":"btcusdt@depth@100ms","data":{"e":"depthUpdate","E":1784410682590,"T":1784410682589,"s":"BTCUSDT","ps":"BTCUSDT","U":11079105848486,"u":11079105855852,"pu":11079105848298,"b":[["14158.80","1.232"],["14358.80","0.252"],["14458.80","2.002"],["14558.80","0.238"],["51727.00","0.000"],["58192.90","0.002"],["61417.50","0.009"],["61425.80","0.001"],["62072.40","0.003"],["63880.60","8.442"],["64012.20","0.186"],["64335.50","0.013"],["64658.80","12.232"]],"a":[["64658.90","2.274"],["64665.80","0.000"],["64699.70","1.197"],["64707.50","0.125"],["64707.70","0.223"],["64778.00","0.299"],["64790.80","0.246"],["65305.50","0.153"],["65584.90","0.761"],["65596.50","2.138"]],"st":1}}
{"stream":"btcusdt@depth@100ms","data":{"e":"depthUpdate","E":1784410682692,"T":1784410682690,"s":"BTCUSDT","ps":"BTCUSDT","U":11079105855970,"u":11079105864062,"pu":11079105855852,"b":[["1000.00","50.391"],["14158.80","1.120"],["14358.80","0.378"],["14458.80","1.988"],["14556.40","0.098"],["14556.80","0.000"],["14558.80","0.280"],["58192.90","0.002"],["61425.80","0.001"],["62072.40","0.000"],["62118.50","0.002"],["63866.00","13.385"],["64012.20","0.186"],["64132.70","7.781"],["64326.70","0.543"],["64335.50","0.014"],["64500.10","0.002"],["64565.90","0.001"],["64640.40","0.002"],["64648.50","0.433"],["64649.90","2.787"],["64657.40","0.645"],["64658.70","0.201"],["64658.80","11.449"]],"a":[["64658.90","2.255"],["64699.70","1.197"],["64707.80","0.003"],["64720.30","1.217"],["64723.20","0.017"],["64740.30","0.856"],["64741.90","3.620"],["64762.40","0.001"],["64808.00","0.010"],["64942.30","0.129"],["64973.30","1.538"],["64982.20","0.001"],["65176.20","5.057"],["65305.50","0.153"],["65434.80","1.831"]],"st":1}}
{"stream":"btcusdt@depth@100ms","data":{"e":"depthUpdate","E":1784410682794,"T":1784410682793,"s":"BTCUSDT","ps":"BTCUSDT","U":11079105864253,"u":11079105871422,"pu":11079105864062,"b":[["14158.80","0.994"],["14358.80","0.490"],["14458.80","2.002"],["14554.00","0.308"],["14556.40","0.000"],["14558.80","0.406"],["58192.90","0.002"],["63785.30","0.783"],["63878.20","3.594"],["63889.40","0.938"],["64012.20","0.186"],["64066.80","0.234"],["64141.50","0.313"],["64326.30","0.391"],["64335.50","0.169"],["64340.10","0.099"],["64356.60","0.003"],["64504.30","0.742"],["64505.60","0.504"],["64543.30","1.278"],["64544.80","1.278"],["64546.30","5.591"],["64547.80","2.732"],["64549.30","1.279"],["64550.80","1.281"],["64552.30","1.278"],["64553.80","1.278"],["64555.30","2.081"],["64556.80","1.293"],["64558.30","1.279"],["64559.80","1.165"],["64640.40","0.002"],["64641.50","0.008"],["64644.10","0.560"],["64644.30","0.926"],["64644.50","0.031"],["64644.90","0.000"],["64645.70","0.697"],["64647.00","0.553"],["64647.40","0.008"],["64648.20","0.000"],["64656.60","0.558"],["64658.80","11.450"]],"a":[["64661.90","0.000"],["64662.00","0.129"],["64662.20","0.465"],["64674.40","0.122"],["64675.50","0.574"],["64676.10","0.003"],["64699.80","5.285"],["64811.10","1.092"],["64850.00","25.931"],["64982.20","0.155"],["65305.50","0.153"],["65581.60","13.439"],["65661.10","1.065"]],"st":1}}
{"stream":"btcusdt@depth@100ms","data":{"e":"depthUpdate","E":1784410682896,"T":1784410682894,"s":"BTCUSDT","ps":"BTCUSDT","U":11079105871553,"u":11079105877135,"pu":11079105871422,"b":[["14158.80","0.882"],["14358.80","0.616"],["14458.80","1.988"],["14554.00","0.196"],["14558.80","0.518"],["58192.90","0.002"],["61425.90","0.005"],["62072.40","0.003"],["63348.10","0.237"],["63419.90","0.147"],["63491.70","0.147"],["63563.60","0.150"],["63635.40","0.164"],["63707.20","0.149"],["63779.00","2.494"],["63818.20","0.587"],["63825.60","0.000"],["63850.80","0.149"],["63922.70","0.147"],["63994.50","0.147"],["64012.20","0.186"],["64335.50","0.159"],["64543.30","0.000"],["64544.80","0.000"],["64546.30","4.313"],["64547.80","1.454"],["64549.30","0.001"],["64550.80","0.003"],["64552.30","0.000"],["64553.80","0.000"],["64555.30","0.803"],["64556.80","0.015"],["64558.30","0.001"],["64559.80","0.021"],["64623.10","0.003"],["64623.20","0.002"],["64623.30","0.002"],["64623.50","0.313"],["64623.60","1.459"],["64623.70","0.030"],["64639.00","0.071"],["64639.10","0.003"],["64639.20","0.002"],["64649.90","2.736"],["64654.00","0.456"],["64654.90","0.093"],["64655.80","0.006"],["64658.80","11.501"]],"a":[["64671.70","0.003"],["64673.00","0.003"],["64682.70","0.117"],["64686.60","0.187"],["65287.30","0.150"],["65305.50","0.153"],["65359.10","0.148"],["65431.00","0.234"],["65502.80","0.147"],["65574.60","0.148"],["65646.40","0.147"]],"st":1}}
{"stream":"btcusdt@depth@100ms","data":{"e":"depthUpdate","E":1784410682998,"T":1784410682997,"s":"BTCUSDT","ps":"BTCUSDT","U":11079105877324,"u":11079105883636,"pu":11079105877135,"b":[["1000.00","50.391"],["14158.80","0.756"],["14358.80","0.728"],["14458.80","2.002"],["14554.00","0.070"],["14558.80","0.644"],["58192.90","0.002"],["61425.80","0.001"],["62072.40","0.000"],["63882.90","3.126"],["64012.20","0.186"],["64031.60","0.936"],["64477.40","0.000"],["64484.20","0.100"],["64504.30","0.001"],["64505.60","0.402"],["64559.20","3.030"],["64565.90","0.000"],["64568.60","0.026"],["64595.50","0.017"],["64604.70","0.026"],["64627.00","0.690"],["64636.10","0.179"],["64640.40","0.156"],["64658.80","11.511"]],"a":[["64658.90","2.251"],["64663.40","0.008"],["64673.40","0.202"],["64682.30","2.397"],["64705.60","0.000"],["64714.50","0.038"],["64742.70","0.000"],["64751.60","0.015"],["64811.10","0.000"],["64822.70","0.096"],["64822.80","0.001"],["64839.90","0.943"],["65305.50","0.153"],["65419.30","8.247"],["65596.50","3.204"],["65718.20","0.147"],["65790.10","0.147"],["65861.90","0.147"],["65933.70","0.147"],["65952.00","0.012"]],"st":1}}
{"stream":"btcusdt@depth@100ms","data":{"e":"depthUpdate","E":1784410683100,"T":1784410683099,"s":"BTCUSDT","ps":"BTCUSDT","U":11079105883741,"u":11079105891808,"pu":11079105883636,"b":[["14158.80","0.644"],["14358.80","0.896"],["14458.80","1.904"],["14554.00","0.000"],["14558.80","0.756"],["58192.90","0.002"],["61417.50","0.007"],["61425.80","0.001"],["62072.40","0.003"],["63798.50","1.095"],["63853.40","2.344"],["64012.20","0.186"],["64451.90","0.176"],["64487.10","0.737"],["64489.40","0.161"],["64504.30","0.742"],["64505.60","0.504"],["64543.30","0.000"],["64544.80","0.000"],["64546.30","4.313"],["64547.80","1.454"],["64549.30","0.001"],["64550.80","0.003"],["64552.30","0.000"],["64553.80","0.000"],["64555.30","0.803"],["64556.80","0.015"],["64558.30","0.001"],["64558.60","0.497"],["64559.80","0.021"],["64561.30","0.002"],["64587.70","0.003"],["64633.60","0.327"],["64640.00","5.223"],["64640.40","0.156"],["64641.00","0.001"],["64643.20","1.995"],["64644.30","0.000"],["64645.10","3.006"],["64646.50","0.082"],["64647.20","1.303"],["64649.90","2.684"],["64658.80","11.641"]],"a":[["64661.50","0.201"],["64667.90","0.156"],["64674.40","0.431"],["64811.10","1.092"],["64828.30","1.381"],["65305.50","0.155"],["65469.20","0.000"],["65500.00","99.337"]],"st":1}}
{"stream":"btcusdt@depth@100ms","data":{"e":"depthUpdate","E":1784410683202,"T":1784410683201,"s":"BTCUSDT","ps":"BTCUSDT","U":11079105891926,"u":11079105898802,"pu":11079105891808,"b":[["1000.00","50.391"],["14158.80","0.518"],["14358.80","1.134"],["14458.80","1.666"],["14558.80","0.882"],["58192.90","0.002"],["63799.10","0.000"],["63874.10","34.785"],["64007.60","0.000"],["64012.20","0.186"],["64335.50","0.159"],["64504.30","0.001"],["64505.60","0.402"],["64594.10","0.032"],["64640.40","0.002"],["64652.30","0.004"],["64654.30","0.023"],["64658.80","12.417"]],"a":[["64661.50","0.124"],["64667.90","0.001"],["64670.80","0.063"],["64674.40","0.122"],["64702.10","1.870"],["64702.30","10.556"],["64785.60","0.015"],["64811.10","0.000"],["64858.90","0.027"],["64882.00","0.125"],["65305.50","0.153"],["65428.30","0.920"],["65942.90","0.642"]],"st":1}}
{"stream":"btcusdt@depth@100ms","data":{"e":"depthUpdate","E":1784410683304,"T":1784410683302,"s":"BTCUSDT","ps":"BTCUSDT","U":11079105898884,"u":11079105905311,"pu":11079105898802,"b":[["1000.00","50.391"],["14158.80","0.406"],["14358.80","1.372"],["14458.80","1.428"],["14558.80","0.994"],["51727.00","0.002"],["58192.90","0.002"],["61425.80","0.001"],["62072.40","0.000"],["63813.00","0.274"],["63925.10","0.017"],["64012.20","0.186"],["64324.30","0.049"],["64504.30","0.744"],["64505.60","0.504"],["64640.40","0.156"],["64645.10","3.004"]],"a":[["64677.60","0.003"],["64690.20","0.082"],["64730.80","0.026"],["64734.10","0.002"],["64811.10","1.092"],["65305.50","0.153"],["65467.10","0.744"]],"st":1}}
{"stream":"btcusdt@depth@100ms","data":{"e":"depthUpdate","E":1784410683406,"T":1784410683405,"s":"BTCUSDT","ps":"BTCUSDT","U":11079105905475,"u":11079105912308,"pu":11079105905311,"b":[["14158.80","0.280"],["14358.80","1.610"],["14458.80","1.190"],["14558.80","1.120"],["51727.00","0.000"],["58192.90","0.002"],["61417.40","0.004"],["61417.50","0.009"],["61425.80","0.001"],["62072.40","0.003"],["63659.40","2.351"],["63809.40","3.676"],["63882.90","3.751"],["64012.20","0.343"],["64335.50","0.158"],["64504.30","0.001"],["64505.60","0.402"],["64565.00","0.050"],["64587.70","0.344"],["64596.80","0.031"],["64604.90","0.154"],["64633.60","0.018"],["64638.90","0.037"],["64640.00","5.068"],["64645.10","3.006"],["64646.50","0.005"],["64655.80","0.037"],["64655.90","0.004"],["64658.80","11.642"]],"a":[["64677.60","0.005"],["64684.00","0.003"],["64690.20","0.005"],["64702.10","0.433"],["64702.30","0.556"],["64811.10","0.000"],["64982.20","0.156"],["65305.50","0.153"],["65467.10","1.230"],["65758.10","0.911"],["65952.00","0.015"]],"st":1}}
{"stream":"btcusdt@depth@100ms","data":{"e":"depthUpdate","E":1784410683508,"T":1784410683505,"s":"BTCUSDT","ps":"BTCUSDT","U":11079105912420,"u":11079105919439,"pu":11079105912308,"b":[["1000.00","50.391"],["14158.80","0.168"],["14358.80","1.848"],["14458.80","0.952"],["14558.80","1.232"],["58192.90","0.002"],["61425.80","0.001"],["62072.40","0.000"],["63683.70","0.274"],["63753.60","0.266"],["64335.50","0.158"],["64441.50","0.000"],["64487.10","0.003"],["64632.40","0.227"],["64635.90","0.137"],["64643.80","0.258"],["64649.90","2.677"],["64658.80","11.649"]],"a":[["64664.00","0.005"],["64665.50","0.050"],["64828.30","0.558"],["64855.60","0.007"],["65305.50","0.153"],["65751.60","0.531"]],"st":1}}
{"stream":"btcusdt@depth@100ms","data":{"e":"depthUpdate","E":1784410683610,"T":1784410683609,"s":"BTCUSDT","ps":"BTCUSDT","U":11079105919683,"u":11079105926857,"pu":11079105919439,"b":[["1000.00","50.391"],["14158.80","0.042"],["14258.80","0.042"],["14358.80","2.002"],["14458.80","0.756"],["14558.80","1.358"],["45255.00","0.002"],["51727.00","0.002"],["58192.90","0.002"],["61425.80","0.001"],["62072.40","0.003"],["63817.60","1.095"],["64012.20","0.343"],["64450.30","3.269"],["64487.10","0.739"],["64489.40","0.162"],["64504.30","0.744"],["64505.60","0.504"],["64527.00","0.001"],["64527.40","4.023"],["64536.50","0.028"],["64536.70","0.105"],["64541.80","2.323"],["64577.30","0.000"],["64586.50","0.001"],["64586.60","0.046"],["64589.50","0.002"],["64595.40","0.027"],["64597.30","0.009"],["64603.90","0.029"],["64620.30","0.002"],["64622.60","0.127"],["64627.70","0.098"],["64631.20","0.009"],["64632.00","0.086"],["64633.50","0.899"],["64633.90","0.068"],["64635.30","0.008"],["64635.90","0.020"],["64636.20","0.004"],["64640.40","0.002"],["64641.30","0.309"],["64643.40","0.001"],["64644.00","0.820"],["64644.10","0.003"],["64644.60","0.559"],["64644.70","0.001"],["64644.90","0.926"],["64645.10","2.082"],["64645.20","0.974"],["64645.30","0.256"],["64645.50","0.120"],["64645.70","0.156"],["64645.90","0.133"],["64646.20","0.001"],["64647.50","0.006"],["64648.50","0.413"],["64649.50","0.077"],["64650.80","0.010"],["64652.30","0.192"],["64653.30","0.001"],["64653.60","0.095"],["64654.30","0.082"],["64655.80","0.044"],["64656.20","0.120"],["64656.70","1.238"],["64657.40","0.011"],["64657.70","0.641"],["64657.80","0.000"],["64657.90","0.636"],["64658.40","0.117"],["64658.50","0.001"],["64658.80","11.729"]],"a":[["64658.90","2.249"],["64659.50","0.002"],["64659.80","0.000"],["64660.10","0.001"],["64660.50","0.001"],["64660.70","0.001"],["64660.80","0.006"],["64661.10","0.002"],["64661.20","0.000"],["64661.40","0.003"],["64661.50","0.004"],["64662.00","0.716"],["64662.10","1.281"],["64662.20","0.000"],["64664.50","0.061"],["64664.90","0.033"],["64665.20","0.048"],["64665.50","0.003"],["64665.60","0.066"],["64665.80","0.000"],["64669.20","0.635"],["64671.40","0.000"],["64671.80","0.154"],["64672.90","0.171"],["64673.40","0.588"],["64675.50","0.033"],["64676.10","0.544"],["64677.10","0.039"],["64677.40","0.380"],["64677.70","0.929"],["64678.60","0.004"],["64678.80","1.797"],["64679.50","0.313"],["64680.20","1.161"],["64680.90","0.162"],["64681.20","0.348"],["64682.70","0.112"],["64686.60","0.032"],["64690.80","3.727"],["64692.20","2.414"],["64693.80","0.009"],["64699.80","5.131"],["64699.90","0.156"],["64700.20","0.061"],["64700.50","0.453"],["64701.30","0.060"],["64706.00","0.005"],["64706.90","0.034"],["64713.80","0.034"],["64714.30","0.033"],["64717.30","24.225"],["64718.00","4.018"],["64719.90","0.032"],["64728.90","0.000"],["64729.00","0.158"],["64757.30","5.601"],["64768.60","2.322"],["64782.00","0.017"],["64784.30","3.866"],["64812.90","1.100"],["64830.00","1.677"],["64866.90","3.126"],["65305.50","0.153"],["65381.90","5.274"]],"st":1}}
{"stream":"btcusdt@depth@100ms","data":{"e":"depthUpdate","E":1784410683712,"T":1784410683709,"s":"BTCUSDT","ps":"BTCUSDT","U":11079105926891,"u":11079105933587,"pu":11079105926857,"b":[["14158.80","0.000"],["14258.80","0.168"],["14358.80","1.988"],["14458.80","0.714"],["14558.80","1.330"],["51727.00","0.000"],["58192.90","0.002"],["61417.40","0.002"],["61417.50","0.011"],["61425.80","0.001"],["64012.20","0.343"],["64057.20","0.000"],["64335.50","0.157"],["64613.40","0.001"],["64614.20","0.004"],["64640.40","0.156"],["64643.40","0.117"],["64644.00","0.704"],["64644.50","0.957"],["64644.70","0.542"],["64644.90","0.000"],["64645.20","0.433"]],"a":[["64658.90","2.244"],["64661.90","0.002"],["64662.00","0.716"],["64663.90","0.161"],["64664.20","0.047"],["64664.50","0.093"],["64665.20","0.093"],["64674.40","0.663"],["64675.80","0.000"],["64676.10","0.003"],["64690.80","3.728"],["64691.50","0.724"],["64695.20","0.093"],["64699.90","0.002"],["64700.00","1.310"],["64712.90","0.032"],["64713.20","0.035"],["64713.50","0.032"],["64713.80","0.002"],["64714.20","0.045"],["64719.90","0.060"],["64780.80","0.338"],["64844.20","0.000"],["64844.30","0.007"],["64982.20","0.157"],["65305.50","0.153"],["65467.10","1.610"],["65560.50","0.051"],["66974.30","0.000"],["66976.90","0.001"]],"st":1}}
{"stream":"btcusdt@depth@100ms","data":{"e":"depthUpdate","E":1784410683814,"T":1784410683813,"s":"BTCUSDT","ps":"BTCUSDT","U":11079105933765,"u":11079105940231,"pu":11079105933587,"b":[["1000.00","50.391"],["14258.80","0.280"],["14358.80","2.002"],["14458.80","0.714"],["14558.80","1.204"],["58192.90","0.002"],["61417.50","0.009"],["61425.80","0.001"],["62072.40","0.000"],["63827.00","0.001"],["64012.20","0.343"],["64335.50","0.157"],["64340.10","0.000"],["64340.40","0.101"],["64504.30","0.748"],["64505.60","0.402"],["64640.40","0.002"],["64643.90","0.559"],["64644.60","0.002"],["64658.80","11.729"]],"a":[["64662.00","0.129"],["64665.10","0.086"],["64665.20","0.213"],["64665.50","0.063"],["64665.80","0.120"],["64665.90","0.122"],["64668.60","0.186"],["64669.40","0.047"],["64674.40","0.663"],["64674.90","0.002"],["64675.50","0.033"],["64676.20","0.610"],["64676.70","0.000"],["64677.40","1.306"],["64677.70","0.003"],["64678.30","0.000"],["64679.60","0.009"],["64695.20","0.033"],["64700.80","0.085"],["64700.90","0.070"],["64701.20","0.062"],["64701.50","0.240"],["64714.20","0.013"],["64783.30","0.007"],["64811.10","1.106"],["64812.90","0.000"],["65305.50","0.153"],["65363.70","0.689"],["65531.80","0.533"]],"st":1}}
{"stream":"btcusdt@depth@100ms","data":{"e":"depthUpdate","E":1784410683916,"T":1784410683915,"s":"BTCUSDT","ps":"BTCUSDT","U":11079105940390,"u":11079105945887,"pu":11079105940231,"b":[["1000.00","50.391"],["14258.80","0.406"],["14358.80","1.988"],["14458.80","0.714"],["14558.80","1.092"],["58192.90","0.002"],["61425.80","0.001"],["62072.40","0.003"],["63480.30","0.000"],["63818.20","0.704"],["64012.20","0.343"],["64505.60","0.505"],["64640.40","0.156"],["64644.70","0.001"],["64645.50","0.661"]],"a":[["64664.50","0.153"],["64665.10","0.206"],["64665.50","0.123"],["64665.90","0.182"],["64674.40","0.122"],["64675.20","0.006"],["64675.50","0.542"],["64676.20","0.578"],["64679.00","0.182"],["64679.70","0.062"],["64681.50","0.033"],["64685.30","0.016"],["64700.20","0.121"],["64700.80","0.205"],["64701.20","0.062"],["64701.50","0.300"],["64713.80","0.034"],["65305.50","0.153"],["65467.10","1.868"],["65627.70","5.939"]],"st":1}}
{"stream":"btcusdt@depth@100ms","data":{"e":"depthUpdate","E":1784410684018,"T":1784410684017,"s":"BTCUSDT","ps":"BTCUSDT","U":11079105945973,"u":11079105952919,"pu":11079105945887,"b":[["14258.80","0.518"],["14358.80","2.002"],["14458.80","0.714"],["14558.80","0.966"],["58192.90","0.002"],["61425.80","0.001"],["62072.40","0.000"],["63957.50","0.001"],["64012.20","0.343"],["64072.20","1.096"],["64487.10","0.003"],["64504.30","0.001"],["64505.60","0.402"],["64558.60","0.341"],["64654.10","0.260"],["64658.80","11.729"]],"a":[["64659.70","0.014"],["64678.40","1.371"],["64679.00","0.002"],["64679.40","0.060"],["64679.70","0.002"],["64688.60","0.005"],["64693.80","0.004"],["64701.50","0.240"],["64714.20","0.045"],["64811.10","0.000"],["64830.00","0.839"],["65305.50","0.157"],["65616.00","0.076"]],"st":1}}
{"stream":"btcusdt@depth@100ms","data":{"e":"depthUpdate","E":1784410684120,"T":1784410684117,"s":"BTCUSDT","ps":"BTCUSDT","U":11079105952927,"u":11079105959588,"pu":11079105952919,"b":[["1000.00","50.391"],["14258.80","0.644"],["14358.80","1.988"],["14458.80","0.714"],["14558.80","0.854"],["58192.90","0.002"],["61417.50","0.011"],["61425.80","0.001"],["63462.60","1.022"],["63566.10","0.549"],["63806.00","1.370"],["64012.20","0.343"],["64093.30","0.001"],["64097.40","0.008"],["64332.50","0.002"],["64335.50","0.157"],["64336.60","0.008"],["64484.20","0.256"],["64487.10","0.765"],["64489.40","0.059"],["64504.30","0.765"],["64558.60","0.000"],["64640.40","0.002"],["64644.50","0.031"],["64644.90","0.926"],["64645.90","0.133"],["64647.20","1.303"],["64647.90","0.370"],["64649.90","2.541"],["64654.30","0.082"],["64658.80","11.791"]],"a":[["64658.90","2.246"],["64660.20","0.000"],["64660.80","0.004"],["64661.50","0.002"],["64661.90","0.000"],["64664.70","0.050"],["64665.80","0.120"],["64666.10","0.000"],["64666.50","0.338"],["64671.00","0.080"],["64677.40","0.380"],["64677.50","0.158"],["64677.90","0.010"],["64678.30","0.926"],["64679.40","0.000"],["64683.90","0.310"],["64684.20","0.161"],["64687.30","0.007"],["64688.80","0.033"],["64811.10","1.092"],["64828.20","0.814"],["65186.40","0.000"],["65305.50","0.153"],["65499.50","3.056"],["65549.30","24.917"],["65580.80","0.000"],["65609.40","1.218"]],"st":1}}
{"stream":"btcusdt@depth@100ms","data":{"e":"depthUpdate","E":1784410684222,"T":1784410684221,"s":"BTCUSDT","ps":"BTCUSDT","U":11079105959851,"u":11079105966360,"pu":11079105959588,"b":[["1000.00","50.391"],["14258.80","0.756"],["14358.80","2.002"],["14458.80","0.714"],["14558.80","0.728"],["58192.90","0.002"],["62072.40","0.003"],["63813.60","3.465"],["63850.00","7.238"],["64012.20","0.343"],["64084.40","0.004"],["64492.20","0.018"],["64497.40","0.000"],["64649.90","2.540"],["64654.00","0.443"],["64658.80","11.804"]],"a":[["64665.40","0.015"],["64665.80","0.120"],["64666.10","0.000"],["64666.50","0.338"],["64666.60","0.003"],["64677.30","0.926"],["64678.30","0.000"],["64691.40","0.000"],["64882.00","0.008"],["65240.80","0.920"],["65305.50","0.153"],["65761.00","3.163"]],"st":1}}
{"stream":"btcusdt@depth@100ms","data":{"e":"depthUpdate","E":1784410684324,"T":1784410684323,"s":"BTCUSDT","ps":"BTCUSDT","U":11079105966464,"u":11079105972745,"pu":11079105966360,"b":[["14258.80","0.952"],["14358.80","1.848"],["14458.80","0.784"],["14558.80","0.616"],["58192.90","0.004"],["61425.80","0.001"],["62072.40","0.000"],["63882.30","2.267"],["63947.60","0.234"],["64012.20","0.343"],["64072.20","2.031"],["64320.00","0.443"],["64400.00","28.273"],["64480.00","1.119"],["64505.60","0.507"],["64560.00","1.150"],["64640.00","4.881"],["64640.40","0.156"],["64645.10","2.080"],["64649.90","2.256"],["64658.80","11.884"]],"a":[["64666.40","0.105"],["64677.60","0.003"],["64687.40","0.093"],["64687.70","0.062"],["64720.00","0.382"],["64800.00","18.466"],["64880.00","9.538"],["64960.00","2.262"],["65040.00","0.380"],["65305.50","0.153"],["65564.10","0.914"],["65942.90","0.639"]],"st":1}}
{"stream":"btcusdt@depth@100ms","data":{"e":"depthUpdate","E":1784410684426,"T":1784410684425,"s":"BTCUSDT","ps":"BTCUSDT","U":11079105972783,"u":11079105978269,"pu":11079105972745,"b":[["1000.00","50.391"],["14258.80","1.190"],["14358.80","1.610"],["14458.80","0.910"],["14558.80","0.490"],["51727.00","0.000"],["58192.90","0.002"],["61425.80","0.001"],["62072.40","0.003"],["63880.60","7.504"],["63889.60","0.001"],["64012.20","0.342"],["64065.20","1.091"],["64335.50","0.168"],["64451.90","0.020"],["64598.80","0.148"],["64608.50","0.092"],["64640.40","0.002"],["64645.10","2.082"]],"a":[["64677.60","0.005"],["64686.60","0.034"],["64687.30","0.000"],["64687.90","0.019"],["64695.90","0.000"],["64704.70","0.087"],["64982.20","0.156"],["65305.50","0.153"],["65564.10","3.199"]],"st":1}}
{"stream":"btcusdt@depth@100ms","data":{"e":"depthUpdate","E":1784410684528,"T":1784410684527,"s":"BTCUSDT","ps":"BTCUSDT","U":11079105978293,"u":11079105984489,"pu":11079105978269,"b":[["1000.00","50.391"],["14258.80","1.428"],["14358.80","1.372"],["14458.80","1.022"],["14558.80","0.378"],["58192.90","0.002"],["61425.90","0.007"],["62072.40","0.000"],["63785.90","0.625"],["63850.00","6.848"],["64012.20","0.342"],["64320.00","0.613"],["64400.00","28.443"],["64451.90","0.176"],["64480.00","1.289"],["64560.00","1.320"],["64636.10","0.026"],["64640.00","5.051"],["64645.00","0.146"],["64650.20","0.129"],["64650.70","1.570"],["64655.80","0.013"],["64658.80","11.896"]],"a":[["64660.40","0.002"],["64663.00","0.000"],["64665.30","0.002"],["64669.40","0.000"],["64680.60","0.057"],["64682.80","0.018"],["64720.00","0.552"],["64800.00","18.636"],["64880.00","9.708"],["64960.00","2.432"],["65040.00","0.550"],["65305.50","0.153"],["65425.80","31.252"],["65517.70","6.555"]],"st":1}}
{"stream":"btcusdt@depth@100ms","data":{"e":"depthUpdate","E":1784410684630,"T":1784410684629,"s":"BTCUSDT","ps":"BTCUSDT","U":11079105984557,"u":11079105991810,"pu":11079105984489,"b":[["1000.00","50.591"],["14258.80","1.666"],["14358.80","1.134"],["14458.80","1.148"],["14558.80","0.252"],["51727.00","0.000"],["58192.90","0.002"],["63889.40","1.876"],["64012.20","0.342"],["64320.00","0.630"],["64400.00","28.460"],["64480.00","1.306"],["64558.60","0.341"],["64560.00","1.337"],["64587.70","0.003"],["64624.10","0.000"],["64630.40","0.008"],["64640.00","5.068"],["64643.40","0.001"],["64643.90","0.002"],["64644.20","0.369"],["64644.90","0.557"],["64645.10","1.008"],["64645.50","0.661"],["64645.70","0.156"],["64645.80","0.001"],["64645.90","0.133"],["64646.00","1.011"],["64647.10","0.024"],["64647.90","0.061"],["64648.50","0.015"],["64649.20","10.005"],["64649.30","2.017"],["64649.90","2.203"],["64652.00","0.313"],["64655.10","0.004"],["64658.80","12.153"]],"a":[["64658.90","2.354"],["64659.00","0.004"],["64662.10","1.281"],["64662.20","0.002"],["64666.50","0.028"],["64667.30","0.310"],["64669.20","0.325"],["64671.50","0.048"],["64672.20","0.030"],["64675.50","0.542"],["64676.10","0.003"],["64677.30","0.000"],["64677.80","0.187"],["64678.10","0.926"],["64678.20","0.001"],["64678.30","0.000"],["64679.50","0.313"],["64683.40","0.048"],["64685.50","0.003"],["64685.70","0.557"],["64685.90","0.003"],["64687.00","0.495"],["64687.60","0.018"],["64687.90","0.012"],["64688.70","0.009"],["64692.20","2.416"],["64692.50","0.121"],["64698.20","0.004"],["64698.40","0.000"],["64702.90","10.001"],["64704.70","0.083"],["64706.30","0.000"],["64717.20","0.000"],["64717.30","0.024"],["64720.00","0.569"],["64720.30","4.675"],["64721.70","24.210"],["64797.90","0.009"],["64800.00","18.653"],["64806.80","3.834"],["64813.10","0.776"],["64880.00","9.725"],["64885.20","0.124"],["64960.00","2.449"],["65040.00","0.567"],["65102.60","0.072"],["65111.50","0.080"],["65305.50","0.155"],["65547.60","6.545"],["65942.90","0.636"],["65952.00","0.018"],["71124.80","0.002"]],"st":1}}
{"stream":"btcusdt@depth@100ms","data":{"e":"depthUpdate","E":1784410684732,"T":1784410684729,"s":"BTCUSDT","ps":"BTCUSDT","U":11079105991894,"u":11079105997624,"pu":11079105991810,"b":[["1000.00","50.591"],["14258.80","1.904"],["14358.80","0.896"],["14458.80","1.260"],["14558.80","0.140"],["58192.90","0.002"],["61425.80","0.001"],["62072.40","0.003"],["64012.20","0.342"],["64335.50","0.169"],["64561.30","0.002"],["64639.00","0.045"],["64640.40","0.156"],["64649.30","2.019"],["64655.80","0.008"],["64658.50","0.005"],["64658.60","0.001"],["64658.80","12.160"]],"a":[["64658.90","2.187"],["64669.70","0.002"],["64717.10","0.571"],["64717.60","0.005"],["64719.50","24.171"],["64720.30","1.217"],["64721.70","0.003"],["64982.20","0.155"],["65167.20","3.392"],["65176.20","5.088"],["65305.50","0.153"],["65499.50","3.971"],["71124.80","0.000"]],"st":1}}
{"stream":"btcusdt@depth@100ms","data":{"e":"depthUpdate","E":1784410684834,"T":1784410684833,"s":"BTCUSDT","ps":"BTCUSDT","U":11079105997780,"u":11079106002730,"pu":11079105997624,"b":[["1000.00","50.591"],["14158.80","0.070"],["14258.80","2.002"],["14358.80","0.728"],["14458.80","1.386"],["14558.80","0.014"],["58192.90","0.002"],["61425.80","0.001"],["62072.40","0.000"],["63365.70","0.015"],["63804.10","0.000"],["64012.20","0.342"],["64340.40","0.002"],["64340.50","0.099"],["64658.80","12.153"]],"a":[["64691.30","0.099"],["64717.30","0.028"],["64717.40","24.166"],["64717.60","0.001"],["64719.50","0.007"],["64919.30","0.035"],["65305.50","0.153"],["65942.90","0.633"]],"st":1}}
{"stream":"btcusdt@depth@100ms","data":{"e":"depthUpdate","E":1784410684936,"T":1784410684934,"s":"BTCUSDT","ps":"BTCUSDT","U":11079106002781,"u":11079106008169,"pu":11079106002730,"b":[["14158.80","0.196"],["14258.80","1.988"],["14358.80","0.714"],["14458.80","1.302"],["14558.80","0.000"],["58192.90","0.002"],["61425.80","0.001"],["62072.40","0.003"],["64012.20","0.342"],["64504.30","0.744"],["64647.00","0.484"],["64650.70","1.338"],["64651.10","1.548"],["64656.50","0.071"],["64658.80","12.944"]],"a":[["64658.90","2.185"],["64687.90","0.014"],["64690.20","0.082"],["64811.00","1.113"],["64811.10","0.000"],["64941.10","0.014"],["65305.50","0.153"],["65467.10","2.126"]],"st":1}}
{"stream":"btcusdt@depth@100ms","data":{"e":"depthUpdate","E":1784410685038,"T":1784410685037,"s":"BTCUSDT","ps":"BTCUSDT","U":11079106008280,"u":11079106014506,"pu":11079106008169,"b":[["1000.00","50.591"],["14158.80","0.308"],["14258.80","2.002"],["14358.80","0.714"],["14458.80","1.176"],["58192.90","0.002"],["62072.40","0.000"],["63753.60","1.206"],["63874.10","32.909"],["63942.50","0.258"],["64012.20","0.342"],["64086.90","3.091"],["64335.50","0.159"],["64484.20","0.100"],["64504.30","0.744"],["64505.60","0.402"],["64647.20","1.308"],["64649.90","2.201"],["64654.00","0.182"],["64654.40","0.188"],["64658.80","12.946"]],"a":[["64661.00","0.004"],["64666.00","0.005"],["64667.70","0.009"],["64669.70","0.005"],["64684.10","0.061"],["64690.20","0.005"],["64691.30","0.096"],["64811.00","1.113"],["65167.20","2.473"],["65305.50","0.153"],["65549.30","22.652"],["65761.00","2.632"]],"st":1}}
{"stream":"btcusdt@depth@100ms","data":{"e":"depthUpdate","E":1784410685140,"T":1784410685139,"s":"BTCUSDT","ps":"BTCUSDT","U":11079106014639,"u":11079106020019,"pu":11079106014506,"b":[["1000.00","50.591"],["14158.80","0.434"],["14258.80","1.988"],["14358.80","0.714"],["14458.80","1.064"],["58192.90","0.002"],["61417.50","0.009"],["63826.40","0.000"],["64012.20","0.344"],["64132.70","6.847"],["64527.40","0.157"],["64527.50","3.867"],["64586.60","0.046"],["64635.30","0.317"],["64641.70","0.156"],["64647.20","1.303"],["64648.20","0.077"],["64649.90","2.157"],["64656.50","0.069"],["64657.40","0.013"],["64658.80","13.278"]],"a":[["64658.90","2.187"],["64666.00","0.007"],["64700.00","1.310"],["64729.00","0.158"],["64784.30","0.000"],["64784.70","4.345"],["65305.50","0.153"]],"st":1}}
{"stream":"btcusdt@depth@100ms","data":{"e":"depthUpdate","E":1784410685242,"T":1784410685241,"s":"BTCUSDT","ps":"BTCUSDT","U":11079106020124,"u":11079106025069,"pu":11079106020019,"b":[["1000.00","50.791"],["14158.80","0.546"],["14258.80","2.002"],["14358.80","0.714"],["14458.80","0.938"],["58192.90","0.002"],["62072.40","0.003"],["63357.00","0.002"],["64012.20","0.342"],["64076.90","0.237"],["64618.60","0.122"]],"a":[["64674.50","1.954"],["64700.00","1.310"],["65305.50","0.153"],["65564.10","5.484"],["65576.50","0.265"],["65577.10","0.270"]],"st":1}}
{"stream":"btcusdt@depth@100ms","data":{"e":"depthUpdate","E":1784410685344,"T":1784410685342,"s":"BTCUSDT","ps":"BTCUSDT","U":11079106025176,"u":11079106030855,"pu":11079106025069,"b":[["1000.00","50.791"],["14158.80","0.672"],["14258.80","1.988"],["14358.80","0.714"],["14458.80","0.826"],["51727.00","0.002"],["58192.90","0.002"],["61425.80","0.001"],["62072.40","0.000"],["63361.00","0.009"],["63365.70","0.018"],["63882.90","5.627"],["64012.20","0.342"],["64141.50","1.247"],["64335.50","0.169"],["64450.30","0.000"],["64487.10","0.003"],["64489.40","0.059"],["64504.30","0.001"],["64542.80","0.135"],["64544.90","0.000"],["64638.40","0.419"],["64641.30","0.129"],["64647.00","0.485"],["64650.20","0.289"],["64655.10","0.027"],["64658.30","0.332"]],"a":[["64658.90","2.189"],["64674.40","0.002"],["64676.90","0.321"],["64700.00","1.310"],["64702.10","1.870"],["64811.00","0.001"],["64828.20","0.000"],["64866.90","0.000"],["65176.20","6.007"],["65305.50","0.153"]],"st":1}}
{"stream":"btcusdt@depth@100ms","data":{"e":"depthUpdate","E":1784410685446,"T":1784410685445,"s":"BTCUSDT","ps":"BTCUSDT","U":11079106030911,"u":11079106036276,"pu":11079106030855,"b":[["1000.00","50.791"],["14158.80","0.784"],["14258.80","2.002"],["14358.80","0.714"],["14458.80","0.700"],["51727.00","0.000"],["58192.90","0.002"],["61417.40","0.000"],["61417.50","0.011"],["61425.80","0.001"],["61425.90","0.005"],["61426.00","0.006"],["62072.40","0.003"],["63812.90","1.096"],["64012.20","0.342"],["64335.50","0.168"],["64450.30","3.314"],["64487.10","0.744"],["64504.20","0.761"],["64542.80","0.096"],["64544.50","0.046"],["64553.30","0.001"],["64553.40","0.003"],["64645.10","1.008"],["64654.30","0.059"],["64655.40","0.022"],["64658.80","13.278"]],"a":[["64658.90","2.183"],["64677.60","0.005"],["64700.00","1.310"],["64811.00","1.113"],["64828.20","0.823"],["64865.00","3.628"],["64982.20","0.156"],["65305.50","0.153"],["65544.70","0.543"]],"st":1}}
{"stream":"btcusdt@depth@100ms","data":{"e":"depthUpdate","E":1784410685548,"T":1784410685547,"s":"BTCUSDT","ps":"BTCUSDT","U":11079106036377,"u":11079106042047,"pu":11079106036276,"b":[["14158.80","1.008"],["14258.80","1.792"],["14358.80","0.812"],["14458.80","0.588"],["58192.90","0.002"],["61425.80","0.001"],["63880.60","6.566"],["64012.20","0.342"],["64335.50","0.168"],["64544.50","0.007"],["64544.70","0.039"],["64582.40","0.043"],["64582.70","0.000"],["64583.00","0.013"],["64583.40","0.243"],["64583.70","0.582"],["64601.40","0.313"],["64601.70","0.001"],["64602.00","0.003"],["64602.40","0.016"],["64602.70","0.001"],["64608.60","0.168"],["64609.20","0.080"],["64609.50","0.076"],["64609.80","0.313"],["64616.90","0.567"],["64617.00","0.327"],["64617.10","0.001"],["64617.60","1.080"],["64618.20","0.032"],["64620.40","0.000"],["64620.50","0.003"],["64623.60","1.123"],["64623.80","0.030"],["64624.20","1.878"],["64624.80","0.158"],["64634.50","0.002"],["64640.40","0.002"],["64643.40","0.327"],["64645.30","0.100"],["64645.40","0.551"],["64645.50","0.541"],["64645.60","0.389"],["64645.70","0.000"],["64645.90","0.289"],["64646.00","0.007"],["64646.20","0.157"],["64646.30","0.132"],["64646.60","0.381"],["64646.90","0.005"],["64647.20","1.441"],["64647.50","0.080"],["64647.80","0.063"]],"a":[["64661.70","0.003"],["64663.80","0.034"],["64663.90","0.129"],["64664.20","0.047"],["64664.50","0.093"],["64664.90","0.001"],["64665.10","0.178"],["64665.20","0.001"],["64665.50","0.063"],["64665.60","0.006"],["64665.80","0.060"],["64665.90","0.002"],["64682.80","0.050"],["64683.20","0.126"],["64683.50","0.032"],["64684.10","0.093"],["64684.20","0.041"],["64685.40","0.004"],["64686.30","0.060"],["64686.90","24.243"],["64687.30","0.060"],["64687.40","0.033"],["64687.60","0.078"],["64687.70","0.002"],["64689.20","0.003"],["64693.90","0.001"],["64694.20","0.063"],["64694.50","0.571"],["64694.80","0.025"],["64695.20","0.001"],["64700.00","1.310"],["64700.20","0.001"],["64700.80","0.025"],["64700.90","0.010"],["64701.20","0.002"],["64701.30","0.000"],["64701.50","0.000"],["64712.90","0.000"],["64713.20","0.003"],["64713.50","0.000"],["64713.80","0.002"],["64714.20","0.013"],["64783.30","0.107"],["65305.50","0.153"],["65425.80","30.490"]],"st":1}}
{"stream":"btcusdt@depth@100ms","data":{"e":"depthUpdate","E":1784410685650,"T":1784410685649,"s":"BTCUSDT","ps":"BTCUSDT","U":11079106042091,"u":11079106048071,"pu":11079106042047,"b":[["1000.00","50.791"],["14158.80","1.246"],["14258.80","1.554"],["14358.80","0.938"],["14458.80","0.462"],["58192.90","0.002"],["61425.80","0.001"],["62072.40","0.000"],["63361.00","0.006"],["64012.20","0.342"],["64487.10","0.003"],["64504.20","0.014"],["64544.50","0.046"],["64544.70","0.000"],["64640.40","0.156"],["64646.10","2.497"],["64646.50","0.155"],["64647.20","1.579"],["64656.00","0.036"]],"a":[["64658.90","2.170"],["64664.50","0.153"],["64665.10","0.238"],["64665.60","0.066"],["64668.30","0.048"],["64684.10","0.153"],["64686.30","0.120"],["64687.40","0.093"],["64700.00","1.310"],["64811.00","0.001"],["64828.20","0.000"],["65305.50","0.153"],["65336.00","0.919"],["65420.00","18.322"],["65470.90","1.210"],["65854.00","0.001"]],"st":1}}
{"stream":"btcusdt@depth@100ms","data":{"e":"depthUpdate","E":1784410685752,"T":1784410685750,"s":"BTCUSDT","ps":"BTCUSDT","U":11079106048166,"u":11079106053751,"pu":11079106048071,"b":[["1000.00","50.791"],["14158.80","1.484"],["14258.80","1.316"],["14358.80","1.050"],["14458.80","0.350"],["58192.90","0.002"],["62072.40","0.003"],["63753.00","2.358"],["63828.20","1.095"],["64012.20","0.342"],["64335.50","0.167"],["64450.30","3.407"],["64487.10","0.755"],["64504.20","0.770"],["64608.90","0.079"],["64643.30","0.895"],["64644.20","0.253"],["64645.10","1.006"],["64646.00","0.721"],["64646.60","0.699"],["64646.90","0.072"],["64650.60","0.232"],["64651.10","1.316"]],"a":[["64658.90","2.163"],["64664.80","0.034"],["64665.10","0.358"],["64665.70","0.063"],["64665.80","0.240"],["64666.60","0.005"],["64683.80","0.033"],["64684.10","0.213"],["64686.90","24.303"],["64687.60","0.318"],["64700.00","1.156"],["64811.00","1.113"],["64828.20","0.823"],["64865.00","3.628"],["65305.50","0.153"],["65434.80","2.593"]],"st":1}}
{"stream":"btcusdt@depth@100ms","data":{"e":"depthUpdate","E":1784410685854,"T":1784410685853,"s":"BTCUSDT","ps":"BTCUSDT","U":11079106053820,"u":11079106059647,"pu":11079106053751,"b":[["14158.80","1.722"],["14258.80","1.078"],["14358.80","1.176"],["14458.80","0.224"],["51727.00","0.000"],["58192.90","0.002"],["61425.80","0.001"],["61425.90","0.007"],["62072.40","0.000"],["63889.40","2.814"],["64012.20","0.342"],["64335.50","0.167"],["64544.50","0.007"],["64544.70","0.039"],["64589.60","0.074"],["64590.20","0.061"],["64590.50","0.075"],["64590.80","0.271"],["64591.50","0.186"],["64644.70","0.001"],["64646.30","0.288"],["64646.60","0.855"],["64658.80","13.293"]],"a":[["64658.90","2.163"],["64665.10","0.418"],["64665.50","0.123"],["64668.30","0.001"],["64668.50","0.312"],["64668.70","0.047"],["64687.00","0.555"],["64687.30","0.120"],["64691.60","0.000"],["64700.00","1.310"],["64701.80","0.032"],["64702.20","0.043"],["64702.50","1.294"],["64703.10","0.036"],["64982.20","0.157"],["65176.20","6.313"],["65305.50","0.153"],["65434.80","4.118"]],"st":1}}
{"stream":"btcusdt@depth@100ms","data":{"e":"depthUpdate","E":1784410685956,"T":1784410685953,"s":"BTCUSDT","ps":"BTCUSDT","U":11079106059743,"u":11079106064403,"pu":11079106059647,"b":[["1000.00","50.791"],["14158.80","1.960"],["14258.80","0.840"],["14358.80","1.288"],["14458.80","0.112"],["58192.90","0.002"],["61425.80","0.001"],["62072.40","0.003"],["63726.10","1.264"],["63850.60","0.270"],["64012.20","0.342"],["64094.40","0.156"],["64624.10","0.156"],["64624.40","0.159"],["64624.80","0.464"],["64625.30","0.144"],["64640.40","0.156"],["64654.00","0.173"],["64658.80","13.302"]],"a":[["64700.00","1.156"],["65305.50","0.153"],["65419.30","7.331"],["65433.60","1.071"],["65745.20","0.531"],["65952.00","0.021"]],"st":1}}
{"stream":"btcusdt@depth@100ms","data":{"e":"depthUpdate","E":1784410686058,"T":1784410686057,"s":"BTCUSDT","ps":"BTCUSDT","U":11079106064558,"u":11079106070203,"pu":11079106064403,"b":[["1000.00","50.791"],["14158.80","2.002"],["14258.80","0.714"],["14358.80","1.386"],["14458.80","0.000"],["14558.80","0.098"],["51727.00","0.000"],["58192.90","0.002"],["61425.80","0.021"],["63361.00","0.000"],["63363.30","0.003"],["63365.70","0.021"],["63818.20","1.799"],["63882.90","5.893"],["64012.20","0.342"],["64421.30","0.830"],["64541.80","0.003"],["64543.30","0.000"],["64544.80","2.320"],["64544.90","1.278"],["64546.30","5.591"],["64547.80","2.732"],["64549.30","1.279"],["64550.80","1.281"],["64552.30","1.278"],["64553.40","0.000"],["64553.50","0.010"],["64553.80","1.278"],["64555.30","2.081"],["64556.80","1.293"],["64558.30","1.279"],["64558.60","0.341"],["64559.80","1.299"],["64561.30","0.002"],["64561.80","0.568"],["64565.90","0.001"],["64589.90","0.072"],["64623.10","0.001"],["64623.20","0.000"],["64623.30","0.000"],["64623.50","0.311"],["64623.60","1.121"],["64623.70","0.028"],["64624.20","1.998"],["64625.40","0.138"],["64627.50","0.152"],["64638.40","0.399"],["64639.00","0.043"],["64639.10","0.001"],["64639.20","0.000"],["64640.40","0.002"],["64647.20","1.579"],["64648.50","0.035"],["64656.80","0.128"],["64658.50","0.001"],["64658.60","0.000"],["64658.70","0.201"],["64658.80","13.202"]],"a":[["64658.90","2.310"],["64662.30","24.231"],["64663.80","0.034"],["64664.50","0.153"],["64664.90","0.001"],["64665.40","0.062"],["64665.80","0.247"],["64667.70","0.002"],["64684.10","0.262"],["64686.70","1.098"],["64690.40","0.003"],["64691.30","0.047"],["64698.60","2.002"],["64699.60","0.115"],["64702.10","0.433"],["64702.80","0.032"],["64702.90","0.001"],["64737.20","0.200"],["64737.30","0.024"],["64743.70","0.757"],["64743.80","0.001"],["64765.70","2.322"],["64768.60","0.002"],["64844.30","0.004"],["64844.40","0.073"],["64971.30","0.004"],["65021.70","0.200"],["65021.80","0.017"],["65305.50","0.153"],["65548.00","0.206"]],"st":1}}
{"stream":"btcusdt@depth@100ms","data":{"e":"depthUpdate","E":1784410686160,"T":1784410686159,"s":"BTCUSDT","ps":"BTCUSDT","U":11079106070265,"u":11079106076489,"pu":11079106070203,"b":[["14158.80","1.988"],["14258.80","0.714"],["14358.80","1.274"],["14558.80","0.224"],["51727.00","0.002"],["58192.90","0.002"],["61425.90","0.009"],["62072.40","0.000"],["63365.70","0.018"],["63740.00","0.480"],["63824.90","0.000"],["63862.20","0.782"],["64012.20","0.342"],["64067.70","0.157"],["64141.50","1.247"],["64297.30","0.018"],["64335.50","0.167"],["64504.20","0.761"],["64543.30","0.000"],["64544.80","2.320"],["64544.90","0.000"],["64546.30","4.313"],["64547.80","1.454"],["64549.30","0.001"],["64550.80","0.003"],["64552.30","0.000"],["64553.80","0.000"],["64555.30","0.803"],["64556.80","0.015"],["64558.30","0.001"],["64559.80","1.299"],["64565.90","0.000"],["64624.10","0.330"],["64624.20","2.538"],["64624.80","0.602"],["64627.60","0.954"],["64640.40","0.156"],["64652.30","0.190"],["64658.80","13.193"]],"a":[["64658.90","2.281"],["64665.40","0.015"],["64700.00","1.310"],["64811.00","0.001"],["65000.00","102.075"],["65305.50","0.153"],["65415.40","0.534"],["65428.30","1.836"],["65581.60","12.684"]],"st":1}}
{"stream":"btcusdt@depth@100ms","data":{"e":"depthUpdate","E":1784410686262,"T":1784410686261,"s":"BTCUSDT","ps":"BTCUSDT","U":11079106076503,"u":11079106081068,"pu":11079106076489,"b":[["1000.00","50.791"],["14158.80","2.002"],["14258.80","0.714"],["14358.80","1.148"],["14558.80","0.336"],["51727.00","0.000"],["58192.90","0.002"],["62072.40","0.003"],["63363.30","0.000"],["63708.30","1.331"],["63850.60","0.660"],["64012.20","0.344"],["64349.90","0.051"],["64504.20","0.014"],["64610.30","0.487"],["64624.40","0.315"],["64624.70","1.038"],["64649.90","2.109"],["64658.80","13.241"]],"a":[["64658.90","2.130"],["64667.30","0.312"],["64676.50","0.001"],["64683.30","0.410"],["64700.00","1.156"],["64702.40","0.080"],["64709.10","0.017"],["64811.00","0.001"],["65305.50","0.153"],["65434.80","4.576"],["65952.00","0.018"]],"st":1}}
{"stream":"btcusdt@depth@100ms","data":{"e":"depthUpdate","E":1784410686364,"T":1784410686362,"s":"BTCUSDT","ps":"BTCUSDT","U":11079106081115,"u":11079106085826,"pu":11079106081068,"b":[["1000.00","50.791"],["14158.80","1.988"],["14258.80","0.714"],["14358.80","1.036"],["14558.80","0.462"],["51727.00","0.002"],["58192.90","0.002"],["61425.80","0.001"],["62072.40","0.000"],["63798.70","0.000"],["64012.20","0.342"],["64421.30","0.835"],["64504.20","0.761"],["64505.60","0.505"],["64618.30","0.397"],["64640.40","0.002"],["64643.30","0.175"],["64646.30","0.156"],["64658.30","0.394"]],"a":[["64658.90","2.132"],["64664.40","0.000"],["64668.00","0.002"],["64700.00","1.310"],["64717.20","0.004"],["64717.30","4.626"],["64811.00","1.115"],["65305.50","0.153"],["65531.80","1.065"]],"st":1}}
{"stream":"btcusdt@depth@100ms","data":{"e":"depthUpdate","E":1784410686466,"T":1784410686465,"s":"BTCUSDT","ps":"BTCUSDT","U":11079106085912,"u":11079106092225,"pu":11079106085826,"b":[["14158.80","2.002"],["14258.80","0.714"],["14358.80","0.910"],["14558.80","0.574"],["51727.00","0.000"],["58192.90","0.002"],["63869.40","0.266"],["64012.20","0.342"],["64075.30","0.000"],["64080.10","0.016"],["64235.50","0.015"],["64240.30","0.022"],["64335.50","0.167"],["64396.10","0.004"],["64400.90","0.025"],["64504.20","0.761"],["64505.60","0.402"],["64553.60","0.000"],["64557.10","0.002"],["64559.80","0.021"],["64561.90","0.002"],["64562.50","3.513"],["64562.80","2.637"],["64645.10","1.006"],["64658.80","13.239"]],"a":[["64658.90","2.133"],["64677.60","0.005"],["64700.00","1.310"],["64742.90","0.356"],["64745.00","0.001"],["64751.00","0.123"],["64753.80","3.434"],["64755.80","0.002"],["64811.00","1.115"],["64858.70","0.367"],["64912.90","0.001"],["64917.70","1.342"],["64982.20","0.156"],["65075.20","0.005"],["65080.00","1.486"],["65237.80","0.000"],["65242.70","0.020"],["65305.50","0.153"],["65596.50","3.965"]],"st":1}}
{"stream":"btcusdt@depth@100ms","data":{"e":"depthUpdate","E":1784410686568,"T":1784410686567,"s":"BTCUSDT","ps":"BTCUSDT","U":11079106092379,"u":11079106097703,"pu":11079106092225,"b":[["1000.00","50.791"],["14158.80","1.988"],["14258.80","0.714"],["14358.80","0.798"],["14558.80","0.700"],["58192.90","0.002"],["61425.80","0.001"],["62072.40","0.003"],["63827.80","0.020"],["63950.30","0.782"],["64012.20","0.342"],["64297.30","0.023"],["64335.50","0.168"],["64543.30","0.000"],["64544.80","2.320"],["64546.30","4.313"],["64547.80","1.454"],["64549.30","0.001"],["64550.80","0.003"],["64552.30","0.000"],["64553.80","0.000"],["64555.30","0.803"],["64556.80","0.015"],["64640.40","0.156"],["64643.30","0.808"],["64644.10","0.560"],["64644.30","0.926"],["64644.50","0.031"],["64644.90","0.000"],["64645.10","0.080"],["64645.50","0.541"],["64646.40","0.348"]],"a":[["64664.50","0.303"],["64668.10","0.282"],["64668.70","0.047"],["64674.40","0.002"],["64675.50","0.542"],["64676.80","0.003"],["64677.70","0.929"],["64678.10","0.000"],["64700.00","1.156"],["65305.50","0.153"]],"st":1}}
{"stream":"btcusdt@depth@100ms","data":{"e":"depthUpdate","E":1784410686670,"T":1784410686669,"s":"BTCUSDT","ps":"BTCUSDT","U":11079106097789,"u":11079106103523,"pu":11079106097703,"b":[["1000.00","50.791"],["14158.80","1.974"],["14258.80","0.728"],["14358.80","0.672"],["14558.80","0.826"],["58192.90","0.002"],["61425.80","0.001"],["62072.40","0.000"],["63818.20","2.895"],["63882.90","6.830"],["64012.20","0.343"],["64522.00","3.892"],["64594.10","0.031"],["64623.10","0.003"],["64623.20","0.002"],["64623.30","0.002"],["64623.50","0.313"],["64623.60","1.123"],["64623.70","0.030"],["64627.00","0.387"],["64639.00","0.045"],["64639.10","0.003"],["64639.20","0.002"],["64640.40","0.002"],["64650.60","0.000"],["64651.00","0.933"],["64655.10","0.004"],["64658.80","13.239"]],"a":[["64658.90","2.128"],["64670.60","0.048"],["64698.20","0.000"],["64700.00","1.156"],["64704.70","0.087"],["64736.90","0.200"],["64737.20","0.000"],["64743.40","0.206"],["64743.70","0.557"],["65021.40","0.203"],["65021.70","0.000"],["65305.50","0.153"],["65466.50","2.017"]],"st":1}}
{"stream":"btcusdt@depth@100ms","data":{"e":"depthUpdate","E":1784410686772,"T":1784410686769,"s":"BTCUSDT","ps":"BTCUSDT","U":11079106103618,"u":11079106109056,"pu":11079106103523,"b":[["14158.80","1.736"],["14258.80","0.840"],["14358.80","0.560"],["14558.80","1.064"],["58192.90","0.002"],["61425.80","0.001"],["62072.40","0.003"],["64012.20","0.343"],["64151.30","0.001"],["64335.50","0.158"],["64349.90","0.051"],["64504.20","0.014"],["64594.10","0.032"],["64640.40","0.156"],["64649.90","2.056"],["64655.90","0.027"],["64658.80","13.290"]],"a":[["64658.90","2.125"],["64668.60","0.188"],["64668.70","0.000"],["64698.20","0.004"],["64700.00","1.156"],["64704.70","0.083"],["64709.50","0.000"],["64723.60","0.003"],["64811.00","0.001"],["65305.50","0.153"],["65466.50","1.758"],["65745.20","1.062"]],"st":1}}
{"stream":"btcusdt@depth@100ms","data":{"e":"depthUpdate","E":1784410686874,"T":1784410686873,"s":"BTCUSDT","ps":"BTCUSDT","U":11079106109225,"u":11079106114714,"pu":11079106109056,"b":[["1000.00","50.791"],["14158.80","1.498"],["14258.80","0.966"],["14358.80","0.434"],["14558.80","1.302"],["58192.90","0.002"],["61425.80","0.001"],["62072.40","0.000"],["63816.90","1.105"],["64012.20","0.343"],["64304.00","4.010"],["64306.70","0.661"],["64335.50","0.159"],["64504.20","0.757"],["64543.30","0.000"],["64544.80","2.320"],["64546.30","4.313"],["64547.80","1.454"],["64549.30","0.001"],["64550.80","0.003"],["64552.30","0.000"],["64553.80","0.000"],["64555.30","0.803"],["64556.80","0.015"],["64558.30","0.001"],["64644.30","0.000"],["64645.50","1.467"],["64656.80","0.123"],["64658.50","0.005"],["64658.60","0.001"],["64658.80","13.287"]],"a":[["64658.90","2.126"],["64665.10","0.418"],["64667.20","0.003"],["64667.90","0.048"],["64675.50","0.001"],["64676.10","0.544"],["64677.70","0.003"],["64678.60","0.930"],["64700.00","1.156"],["64811.00","1.086"],["64982.20","0.155"],["65305.50","0.153"]],"st":1}}
{"stream":"btcusdt@depth@100ms","data":{"e":"depthUpdate","E":1784410686976,"T":1784410686973,"s":"BTCUSDT","ps":"BTCUSDT","U":11079106114782,"u":11079106120536,"pu":11079106114714,"b":[["1000.00","50.791"],["14158.80","1.260"],["14258.80","1.078"],["14358.80","0.322"],["14558.80","1.540"],["58192.90","0.002"],["61425.80","0.001"],["63365.70","0.021"],["63850.00","6.458"],["64012.20","0.342"],["64594.10","0.033"],["64640.40","0.002"],["64649.90","2.048"],["64656.00","0.245"],["64658.80","13.295"]],"a":[["64675.40","0.080"],["64684.30","0.002"],["64700.00","1.156"],["65305.50","0.153"],["65482.90","3.088"]],"st":1}}
{"stream":"btcusdt@depth@100ms","data":{"e":"depthUpdate","E":1784410687078,"T":1784410687077,"s":"BTCUSDT","ps":"BTCUSDT","U":11079106120741,"u":11079106126504,"pu":11079106120536,"b":[["14158.80","1.022"],["14258.80","1.204"],["14358.80","0.196"],["14558.80","1.778"],["58192.90","0.002"],["61425.80","0.001"],["62072.40","0.003"],["63788.40","3.680"],["64012.20","0.342"],["64335.50","0.169"],["64336.60","0.000"],["64341.30","0.008"],["64558.60","0.000"],["64561.80","0.227"],["64571.50","0.342"],["64640.40","0.156"],["64647.20","1.579"],["64649.50","0.001"],["64658.40","0.193"],["64658.80","13.287"]],"a":[["64658.90","2.039"],["64667.90","0.001"],["64700.00","1.156"],["64844.40","0.070"],["64844.50","0.005"],["65305.50","0.153"],["65577.10","0.535"]],"st":1}}
{"stream":"btcusdt@depth@100ms","data":{"e":"depthUpdate","E":1784410687180,"T":1784410687178,"s":"BTCUSDT","ps":"BTCUSDT","U":11079106126642,"u":11079106133021,"pu":11079106126504,"b":[["1000.00","50.791"],["14158.80","0.798"],["14258.80","1.316"],["14358.80","0.084"],["14458.80","0.014"],["14558.80","1.988"],["58192.90","0.002"],["61425.80","0.001"],["61425.90","0.007"],["62072.40","0.000"],["64012.20","0.342"],["64097.40","0.000"],["64102.10","0.022"],["64218.90","0.000"],["64504.20","0.757"],["64640.40","0.002"],["64644.90","0.926"],["64645.50","0.541"],["64658.80","13.289"]],"a":[["64664.50","0.303"],["64664.80","0.034"],["64665.10","0.418"],["64665.50","0.123"],["64665.70","0.063"],["64665.80","0.240"],["64666.10","0.000"],["64666.50","0.028"],["64666.90","0.048"],["64667.60","0.009"],["64690.20","0.005"],["64700.00","1.156"],["64811.00","1.077"],["65305.50","0.153"]],"st":1}}
{"stream":"btcusdt@depth@100ms","data":{"e":"depthUpdate","E":1784410687282,"T":1784410687281,"s":"BTCUSDT","ps":"BTCUSDT","U":11079106133181,"u":11079106138247,"pu":11079106133021,"b":[["14158.80","0.714"],["14258.80","1.358"],["14358.80","0.000"],["14458.80","0.126"],["14558.80","2.002"],["58192.90","0.002"],["61425.80","0.001"],["62072.40","0.003"],["64012.20","0.342"],["64094.40","0.000"],["64349.90","0.051"],["64484.30","0.000"],["64485.50","0.021"],["64640.40","0.156"],["64652.30","0.192"]],"a":[["64658.90","2.040"],["64666.90","0.001"],["64667.50","0.047"],["64700.00","1.310"],["65167.20","2.167"],["65305.50","0.153"]],"st":1}}
{"stream":"btcusdt@depth@100ms","data":{"e":"depthUpdate","E":1784410687384,"T":1784410687381,"s":"BTCUSDT","ps":"BTCUSDT","U":11079106138320,"u":11079106142990,"pu":11079106138247,"b":[["14158.80","0.714"],["14258.80","1.246"],["14458.80","0.252"],["14558.80","1.988"],["51727.00","0.002"],["58192.90","0.002"],["61425.80","0.001"],["62072.40","0.000"],["64012.20","0.342"],["64086.10","0.000"],["64335.50","0.169"],["64504.20","0.014"],["64505.60","0.402"],["64565.00","0.391"],["64643.30","0.059"],["64644.00","0.820"],["64644.10","0.003"],["64644.90","1.483"],["64646.40","0.024"],["64649.80","0.020"],["64650.90","0.311"],["64651.00","0.779"],["64651.20","0.158"],["64653.90","0.002"],["64654.00","0.125"],["64656.60","0.559"],["64658.30","0.332"],["64658.80","13.336"]],"a":[["64664.50","0.153"],["64667.90","0.003"],["64668.10","0.005"],["64672.90","0.017"],["64673.30","0.154"],["64679.30","0.000"],["64679.80","0.316"],["64685.10","0.557"],["64685.70","0.001"],["64688.00","1.004"],["64688.70","0.002"],["64700.00","1.310"],["64811.00","0.001"],["65305.50","0.153"],["65350.80","1.192"],["65467.10","2.506"],["65490.00","0.898"],["65835.70","0.758"],["652000.00","0.003"]],"st":1}}
{"stream":"btcusdt@depth@100ms","data":{"e":"depthUpdate","E":1784410687486,"T":1784410687485,"s":"BTCUSDT","ps":"BTCUSDT","U":11079106143175,"u":11079106147640,"pu":11079106142990,"b":[["1000.00","50.791"],["14158.80","0.714"],["14258.80","1.120"],["14458.80","0.364"],["14558.80","2.002"],["51727.00","0.000"],["58192.90","0.002"],["63365.70","0.018"],["63753.60","1.214"],["64012.20","0.342"],["64487.10","0.706"],["64504.20","0.761"],["64640.40","0.002"],["64640.90","2.000"],["64642.80","0.118"],["64643.30","0.059"],["64644.00","0.704"],["64644.30","1.483"],["64644.50","0.572"],["64644.90","0.000"],["64645.10","0.080"],["64645.50","0.000"],["64658.80","13.342"]],"a":[["64658.90","2.188"],["64659.00","0.009"],["64674.40","0.543"],["64676.10","0.003"],["64676.70","0.926"],["64677.60","0.005"],["64678.60","0.004"],["64700.00","1.310"],["64811.00","1.078"],["64828.10","0.884"],["64828.20","0.000"],["65305.50","0.153"],["65350.80","0.963"]],"st":1}}
{"stream":"btcusdt@depth@100ms","data":{"e":"depthUpdate","E":1784410687588,"T":1784410687587,"s":"BTCUSDT","ps":"BTCUSDT","U":11079106147656,"u":11079106152781,"pu":11079106147640,"b":[["14158.80","0.714"],["14258.80","1.008"],["14458.80","0.490"],["14558.80","1.988"],["58192.90","0.002"],["61425.80","0.001"],["62072.40","0.003"],["63365.70","0.021"],["64012.20","0.342"],["64074.20","1.091"],["64335.50","0.168"],["64458.80","0.000"],["64544.50","0.046"],["64544.70","0.000"],["64553.50","0.007"],["64553.60","0.003"],["64553.80","0.000"],["64555.30","0.803"],["64556.80","0.015"],["64558.30","0.001"],["64559.80","0.021"],["64640.40","0.156"],["64640.90","0.000"],["64642.80","0.838"],["64645.80","0.323"],["64658.80","13.359"]],"a":[["64658.90","2.089"],["64662.00","0.129"],["64664.50","0.303"],["64667.50","0.000"],["64668.10","0.241"],["64668.70","0.047"],["64674.40","0.002"],["64675.50","0.542"],["64676.70","0.000"],["64677.30","0.926"],["64680.00","3.732"],["64689.80","0.070"],["64690.80","0.635"],["64697.70","0.000"],["64700.00","1.156"],["65176.20","6.619"],["65305.50","0.153"]],"st":1}}
{"stream":"btcusdt@depth@100ms","data":{"e":"depthUpdate","E":1784410687690,"T":1784410687689,"s":"BTCUSDT","ps":"BTCUSDT","U":11079106152836,"u":11079106159126,"pu":11079106152781,"b":[["14158.80","0.714"],["14258.80","0.882"],["14458.80","0.602"],["14558.80","2.002"],["58192.90","0.002"],["61425.80","0.001"],["62072.40","0.000"],["64012.20","0.342"],["64320.00","0.613"],["64335.50","0.168"],["64349.90","0.051"],["64400.00","28.443"],["64480.00","1.289"],["64543.30","0.000"],["64544.80","2.320"],["64546.30","4.313"],["64547.80","1.454"],["64549.30","0.001"],["64550.80","0.003"],["64552.30","0.000"],["64553.80","0.000"],["64555.30","0.803"],["64556.80","0.015"],["64558.30","0.001"],["64559.80","0.021"],["64560.00","1.320"],["64611.40","0.356"],["64640.00","5.051"],["64644.50","0.031"],["64645.10","0.056"],["64645.50","0.541"],["64658.80","13.361"]],"a":[["64658.90","1.938"],["64700.00","1.310"],["64720.00","0.552"],["64800.00","18.636"],["64880.00","9.708"],["64960.00","2.432"],["64982.20","0.156"],["65040.00","0.550"],["65291.30","6.265"],["65305.50","0.153"],["65479.30","0.763"]],"st":1}}
{"stream":"btcusdt@depth@100ms","data":{"e":"depthUpdate","E":1784410687792,"T":1784410687789,"s":"BTCUSDT","ps":"BTCUSDT","U":11079106159267,"u":11079106165358,"pu":11079106159126,"b":[["1000.00","50.791"],["14158.80","0.714"],["14258.80","0.770"],["14458.80","0.728"],["14558.80","1.988"],["58192.90","0.002"],["61425.80","0.001"],["61425.90","0.005"],["61426.00","0.008"],["62072.40","0.003"],["63797.50","0.783"],["64012.20","0.342"],["64335.50","0.167"],["64360.90","0.001"],["64425.70","0.000"],["64490.50","0.000"],["64504.20","0.014"],["64584.20","0.000"],["64606.90","0.104"],["64628.30","0.001"],["64640.40","0.002"],["64644.30","11.483"],["64646.10","3.716"],["64649.20","0.005"],["64649.30","0.691"],["64651.00","0.547"],["64651.40","0.233"],["64658.80","13.362"]],"a":[["64658.90","1.933"],["64668.70","0.047"],["64698.60","0.002"],["64700.00","1.310"],["64811.00","0.001"],["65273.20","0.687"],["65305.50","0.153"],["65520.20","0.763"],["65549.30","20.387"],["65564.10","7.769"]],"st":1}}
{"stream":"btcusdt@depth@100ms","data":{"e":"depthUpdate","E":1784410687894,"T":1784410687893,"s":"BTCUSDT","ps":"BTCUSDT","U":11079106165508,"u":11079106169841,"pu":11079106165358,"b":[["14158.80","0.756"],["14258.80","0.644"],["14458.80","0.882"],["14558.80","1.918"],["58192.90","0.002"],["61425.80","0.001"],["63740.60","0.273"],["64012.20","0.342"],["64296.10","1.225"],["64320.00","0.630"],["64357.20","0.064"],["64400.00","28.460"],["64421.90","0.064"],["64451.90","0.020"],["64480.00","1.306"],["64484.20","0.256"],["64560.00","1.337"],["64585.50","0.752"],["64640.00","5.068"],["64647.20","1.577"]],"a":[["64683.00","0.712"],["64699.10","0.003"],["64700.00","1.310"],["64714.70","0.000"],["64720.00","0.569"],["64720.30","0.322"],["64721.80","0.016"],["64800.00","18.653"],["64880.00","9.725"],["64960.00","2.449"],["64982.20","0.157"],["65040.00","0.567"],["65305.50","0.153"],["65547.60","5.784"],["65949.60","0.010"],["65952.00","0.015"]],"st":1}}
{"stream":"btcusdt@depth@100ms","data":{"e":"depthUpdate","E":1784410687996,"T":1784410687993,"s":"BTCUSDT","ps":"BTCUSDT","U":11079106169884,"u":11079106174721,"pu":11079106169841,"b":[["14158.80","0.868"],["14258.80","0.532"],["14458.80","1.120"],["14558.80","1.680"],["58192.90","0.002"],["61425.80","0.001"],["62072.40","0.000"],["63849.40","0.001"],["64012.20","0.342"],["64227.80","0.197"],["64292.50","0.065"],["64335.50","0.157"],["64377.50","0.145"],["64378.40","0.000"],["64450.30","0.000"],["64487.10","0.003"],["64487.50","0.156"],["64551.90","0.108"],["64553.00","0.135"],["64571.50","0.001"],["64606.00","0.022"],["64640.40","0.156"],["64658.80","13.372"]],"a":[["64667.90","0.001"],["64668.70","0.000"],["64669.20","0.327"],["64690.20","0.082"],["64700.00","1.310"],["64700.90","2.040"],["64701.00","10.133"],["64702.10","0.000"],["64715.20","0.003"],["64717.20","0.000"],["64717.30","0.024"],["64717.40","0.002"],["64717.60","0.005"],["64719.50","24.113"],["64754.10","0.000"],["64828.10","0.003"],["64839.90","1.060"],["64843.20","0.117"],["64865.00","0.542"],["64885.20","0.007"],["65305.50","0.153"],["65952.00","0.012"],["66302.70","0.000"]],"st":1}}
{"stream":"btcusdt@depth@100ms","data":{"e":"depthUpdate","E":1784410688098,"T":1784410688097,"s":"BTCUSDT","ps":"BTCUSDT","U":11079106174929,"u":11079106180172,"pu":11079106174721,"b":[["1000.00","50.791"],["14158.80","0.994"],["14258.80","0.406"],["14458.80","1.358"],["14558.80","1.442"],["58192.90","0.002"],["61425.80","0.001"],["61425.90","0.007"],["62072.40","0.003"],["63637.00","0.030"],["64012.20","0.342"],["64450.20","3.283"],["64458.80","0.000"],["64484.20","0.597"],["64487.10","0.699"],["64504.20","0.755"],["64589.90","6.072"],["64591.50","1.084"],["64612.50","3.533"],["64614.00","1.052"],["64628.70","0.701"],["64635.50","0.557"],["64640.40","0.002"],["64644.30","10.557"],["64644.50","0.185"],["64645.70","0.926"],["64647.20","1.577"],["64650.80","0.010"],["64651.20","0.390"],["64651.40","0.001"]],"a":[["64658.90","1.932"],["64677.30","0.000"],["64677.90","0.936"],["64684.50","0.708"],["64688.00","0.997"],["64688.70","0.009"],["64690.20","0.005"],["64700.00","1.156"],["64700.60","3.501"],["64717.20","0.004"],["64717.30","24.130"],["64717.60","0.001"],["64719.50","0.007"],["64723.30","6.448"],["64810.90","1.094"],["64828.10","0.890"],["64864.90","3.119"],["65305.50","0.153"],["65531.80","1.826"],["65663.00","1.517"]],"st":1}}
{"stream":"btcusdt@depth@100ms","data":{"e":"depthUpdate","E":1784410688200,"T":1784410688197,"s":"BTCUSDT","ps":"BTCUSDT","U":11079106180229,"u":11079106185309,"pu":11079106180172,"b":[["14158.80","1.106"],["14258.80","0.294"],["14458.80","1.596"],["14558.80","1.204"],["55344.50","0.005"],["58192.90","0.002"],["61425.80","0.001"],["62072.40","0.000"],["63550.90","5.840"],["63645.60","0.012"],["64012.20","0.342"],["64349.90","0.051"],["64557.60","10.001"],["64638.90","0.034"],["64640.40","0.156"],["64658.80","13.315"]],"a":[["64666.60","0.005"],["64667.30","0.312"],["64667.70","0.049"],["64690.20","0.082"],["64700.00","1.310"],["64755.50","2.365"],["64755.60","10.022"],["65167.20","1.861"],["65305.50","0.153"],["65761.00","2.100"]],"st":1}}
{"stream":"btcusdt@depth@100ms","data":{"e":"depthUpdate","E":1784410688302,"T":1784410688301,"s":"BTCUSDT","ps":"BTCUSDT","U":11079106185457,"u":11079106192290,"pu":11079106185309,"b":[["14158.80","1.232"],["14258.80","0.168"],["14458.80","1.834"],["14558.80","0.966"],["58192.90","0.002"],["62072.40","0.003"],["64012.20","0.342"],["64062.40","5.733"],["64141.50","1.557"],["64229.60","0.045"],["64335.50","0.167"],["64458.80","0.000"],["64543.30","0.000"],["64544.80","2.320"],["64546.30","4.313"],["64547.80","1.454"],["64549.30","0.001"],["64550.80","0.003"],["64552.30","0.000"],["64553.80","1.278"],["64555.30","2.081"],["64556.80","1.293"],["64623.10","0.001"],["64623.20","0.000"],["64623.30","0.000"],["64623.50","0.311"],["64623.60","1.121"],["64623.70","0.028"],["64633.10","0.008"],["64634.40","0.319"],["64639.00","0.043"],["64639.10","0.001"],["64639.20","0.000"],["64639.40","0.378"],["64642.80","0.722"],["64644.00","0.820"],["64644.30","10.000"],["64645.10","0.613"],["64647.40","0.001"],["64647.90","0.068"],["64649.90","2.047"],["64651.00","0.547"],["64651.20","0.158"],["64651.50","0.001"],["64651.60","0.233"],["64658.80","13.315"]],"a":[["64667.70","0.002"],["64668.40","0.002"],["64679.80","0.007"],["64679.90","0.336"],["64685.10","0.001"],["64685.50","0.559"],["64700.00","1.156"],["65250.50","0.000"],["65305.50","0.153"],["65466.50","1.530"],["65547.60","5.023"],["65672.10","0.012"]],"st":1}}
{"stream":"btcusdt@depth@100ms","data":{"e":"depthUpdate","E":1784410688404,"T":1784410688402,"s":"BTCUSDT","ps":"BTCUSDT","U":11079106192347,"u":11079106197896,"pu":11079106192290,"b":[["1000.00","50.791"],["14158.80","1.344"],["14258.80","0.056"],["14358.80","0.042"],["14458.80","1.988"],["14558.80","0.770"],["51727.00","0.000"],["58192.90","0.002"],["61421.30","0.000"],["61421.40","0.002"],["63236.30","0.003"],["63365.70","0.018"],["63559.60","3.457"],["63850.00","6.224"],["63926.80","0.781"],["64012.20","0.342"],["64504.20","0.757"],["64505.60","0.504"],["64553.80","0.000"],["64555.30","0.803"],["64565.00","0.050"],["64571.50","0.342"],["64640.40","0.002"],["64642.80","0.002"],["64645.80","0.001"],["64658.40","0.255"]],"a":[["64658.90","1.930"],["64664.50","0.153"],["64667.90","0.001"],["64668.10","0.005"],["64673.00","0.157"],["64673.30","0.000"],["64690.20","0.005"],["64700.00","1.156"],["64810.90","1.076"],["65305.50","0.153"],["65952.00","0.015"]],"st":1}}
{"stream":"btcusdt@depth@100ms","data":{"e":"depthUpdate","E":1784410688506,"T":1784410688505,"s":"BTCUSDT","ps":"BTCUSDT","U":11079106197984,"u":11079106202630,"pu":11079106197896,"b":[["14158.80","1.330"],["14258.80","0.000"],["14358.80","0.154"],["14458.80","2.002"],["14558.80","0.714"],["58192.90","0.002"],["62072.40","0.000"],["64012.20","0.342"],["64044.50","0.702"],["64556.80","0.015"],["64640.40","0.156"],["64645.10","0.613"],["64653.40","0.300"]],"a":[["64668.20","0.000"],["64668.60","0.235"],["64669.90","0.432"],["64673.00","0.003"],["64673.30","0.154"],["64677.60","0.005"],["64690.20","0.005"],["64700.00","1.310"],["65305.50","0.154"],["65467.10","2.764"]],"st":1}}
{"stream":"btcusdt@depth@100ms","data":{"e":"depthUpdate","E":1784410688608,"T":1784410688607,"s":"BTCUSDT","ps":"BTCUSDT","U":11079106202674,"u":11079106207720,"pu":11079106202630,"b":[["1000.00","50.791"],["14158.80","1.218"],["14358.80","0.280"],["14458.80","1.988"],["14558.80","0.714"],["51727.00","0.004"],["58192.90","0.002"],["61425.80","0.001"],["61426.00","0.006"],["62072.40","0.003"],["63850.60","1.050"],["64012.20","0.342"],["64335.50","0.167"],["64450.20","0.028"],["64458.80","0.000"],["64487.10","0.003"],["64504.20","0.014"],["64505.60","0.402"],["64643.30","0.652"],["64646.40","0.288"]],"a":[["64664.50","0.303"],["64668.10","0.251"],["64699.30","0.119"],["64700.00","1.310"],["64707.20","0.062"],["64810.90","0.001"],["64828.10","0.003"],["64864.90","0.001"],["65305.50","0.154"],["65467.10","3.023"],["65531.80","2.587"]],"st":1}}
{"stream":"btcusdt@depth@100ms","data":{"e":"depthUpdate","E":1784410688710,"T":1784410688709,"s":"BTCUSDT","ps":"BTCUSDT","U":11079106207783,"u":11079106214614,"pu":11079106207720,"b":[["1000.00","50.791"],["14158.80","1.092"],["14358.80","0.392"],["14458.80","2.002"],["14558.80","0.714"],["34000.00","7.459"],["58192.90","0.002"],["61425.80","0.001"],["62072.40","0.000"],["64012.20","0.342"],["64335.50","0.168"],["64349.90","0.051"],["64450.20","3.298"],["64487.10","0.701"],["64504.20","0.757"],["64590.80","0.061"],["64599.60","0.210"],["64603.10","21.604"],["64605.20","0.023"],["64622.60","0.007"],["64629.80","0.126"],["64638.50","0.049"],["64640.40","0.002"],["64648.30","2.017"]],"a":[["64658.90","1.568"],["64668.50","0.002"],["64668.60","0.188"],["64671.50","0.001"],["64672.00","1.492"],["64686.10","0.097"],["64689.80","0.000"],["64696.40","0.568"],["64702.50","1.269"],["64711.70","0.280"],["64810.90","1.076"],["64828.10","0.884"],["64864.90","3.092"],["64982.20","0.156"],["65305.50","0.154"],["65504.60","0.267"]],"st":1}}
{"stream":"btcusdt@depth@100ms","data":{"e":"depthUpdate","E":1784410688812,"T":1784410688811,"s":"BTCUSDT","ps":"BTCUSDT","U":11079106214661,"u":11079106221580,"pu":11079106214614,"b":[["14158.80","0.980"],["14358.80","0.518"],["14458.80","1.988"],["14558.80","0.714"],["58192.90","0.002"],["61417.50","0.009"],["61425.80","0.001"],["62072.40","0.003"],["63773.00","3.989"],["64012.20","0.344"],["64132.70","6.536"],["64458.80","0.000"],["64553.60","0.000"],["64553.70","0.003"],["64553.80","0.000"],["64555.30","0.803"],["64556.80","0.015"],["64558.30","0.001"],["64559.20","4.200"],["64559.80","0.021"],["64561.30","1.280"],["64562.80","3.915"],["64603.10","0.095"],["64605.30","21.395"],["64607.00","0.001"],["64644.00","0.704"],["64644.30","0.116"],["64644.50","0.742"],["64644.60","0.928"],["64644.70","0.001"],["64645.10","0.056"],["64645.50","0.000"],["64645.70","0.000"],["64646.10","3.038"],["64651.60","0.001"],["64652.00","0.545"],["64652.30","0.190"],["64655.90","0.004"],["64658.80","13.200"]],"a":[["64665.80","0.246"],["64667.60","0.002"],["64669.10","0.002"],["64669.40","0.000"],["64669.70","0.005"],["64671.80","0.201"],["64674.40","0.002"],["64675.40","0.621"],["64675.50","0.001"],["64705.40","0.077"],["64844.50","0.002"],["64844.60","0.003"],["65305.50","0.154"]],"st":1}}
{"stream":"btcusdt@depth@100ms","data":{"e":"depthUpdate","E":1784410688914,"T":1784410688913,"s":"BTCUSDT","ps":"BTCUSDT","U":11079106221644,"u":11079106229928,"pu":11079106221580,"b":[["1000.00","50.791"],["14158.80","0.854"],["14358.80","0.630"],["14458.80","2.002"],["14558.80","0.714"],["58192.90","0.002"],["61417.50","0.007"],["61425.80","0.001"],["63365.70","0.021"],["64012.20","0.342"],["64067.70","0.313"],["64086.60","0.000"],["64141.50","1.558"],["64320.00","0.613"],["64326.60","2.332"],["64335.50","0.168"],["64400.00","28.443"],["64480.00","1.289"],["64484.20","0.441"],["64527.50","0.001"],["64527.60","15.775"],["64557.90","0.000"],["64559.30","0.034"],["64560.00","1.320"],["64561.30","0.002"],["64586.60","0.000"],["64586.80","0.067"],["64640.00","5.051"],["64640.40","0.156"],["64644.60","0.002"],["64646.00","1.647"],["64648.30","0.017"],["64649.80","10.020"],["64649.90","1.892"],["64650.70","2.366"],["64654.50","0.010"],["64658.80","13.354"]],"a":[["64658.90","1.083"],["64659.00","0.007"],["64662.10","1.290"],["64665.80","0.240"],["64667.50","0.006"],["64671.80","0.154"],["64674.90","0.049"],["64675.10","0.002"],["64675.40","0.080"],["64676.10","0.544"],["64677.90","0.010"],["64678.40","1.791"],["64678.50","0.973"],["64685.50","0.003"],["64686.20","0.556"],["64699.60","0.162"],["64700.90","0.010"],["64701.00","0.133"],["64706.50","10.000"],["64720.00","0.552"],["64729.00","0.112"],["64729.10","0.059"],["64784.70","0.479"],["64784.90","3.874"],["64797.90","0.000"],["64800.00","18.636"],["64880.00","9.708"],["64960.00","2.432"],["64973.20","0.843"],["64982.20","0.155"],["65040.00","0.550"],["65305.50","0.154"],["65871.50","0.000"]],"st":1}}
{"stream":"btcusdt@depth@100ms","data":{"e":"depthUpdate","E":1784410689016,"T":1784410689013,"s":"BTCUSDT","ps":"BTCUSDT","U":11079106230045,"u":11079106236673,"pu":11079106229928,"b":[["1000.00","50.791"],["14158.80","0.742"],["14358.80","0.756"],["14458.80","1.988"],["14558.80","0.714"],["58192.90","0.002"],["61425.80","0.001"],["62072.40","0.000"],["63494.30","0.000"],["63828.20","0.000"],["64012.20","0.342"],["64320.00","0.630"],["64400.00","28.460"],["64451.90","0.176"],["64480.00","1.306"],["64484.20","0.100"],["64487.50","0.000"],["64560.00","1.337"],["64640.00","5.068"],["64640.40","0.002"],["64644.50","0.185"],["64646.40","0.845"]],"a":[["64662.10","1.281"],["64676.10","0.003"],["64678.30","0.541"],["64678.50","0.047"],["64679.40","0.925"],["64706.40","0.559"],["64720.00","0.569"],["64797.90","0.009"],["64800.00","18.653"],["64839.90","0.943"],["64843.20","0.000"],["64880.00","9.725"],["64885.20","0.124"],["64960.00","2.449"],["65040.00","0.567"],["65305.50","0.154"]],"st":1}}
{"stream":"btcusdt@depth@100ms","data":{"e":"depthUpdate","E":1784410689118,"T":1784410689117,"s":"BTCUSDT","ps":"BTCUSDT","U":11079106236923,"u":11079106246450,"pu":11079106236673,"b":[["14158.80","0.616"],["14358.80","0.938"],["14458.80","1.862"],["14558.80","0.784"],["58192.90","0.002"],["61425.80","0.001"],["61425.90","0.003"],["61426.00","0.008"],["62072.40","0.003"],["63818.20","3.990"],["64012.20","0.342"],["64076.40","4.336"],["64141.50","1.557"],["64335.50","2.498"],["64458.80","0.000"],["64562.80","2.637"],["64568.30","0.358"],["64638.10","0.002"],["64640.40","0.156"],["64642.90","0.812"],["64646.10","2.497"],["64647.20","1.577"],["64647.30","0.640"],["64658.80","13.280"]],"a":[["64669.40","0.000"],["64669.70","0.005"],["64670.10","0.005"],["64670.40","0.049"],["64670.50","0.003"],["64690.20","0.082"],["64982.20","2.461"],["65291.30","5.501"],["65305.50","0.154"],["65420.00","16.809"],["65935.70","0.606"]],"st":1}}
{"stream":"btcusdt@depth@100ms","data":{"e":"depthUpdate","E":1784410689220,"T":1784410689219,"s":"BTCUSDT","ps":"BTCUSDT","U":11079106246580,"u":11079106254542,"pu":11079106246450,"b":[["1000.00","50.791"],["14158.80","0.504"],["14358.80","1.176"],["14458.80","1.624"],["14558.80","0.896"],["58192.90","0.002"],["61425.80","0.001"],["62072.40","0.000"],["63498.50","3.119"],["63736.70","16.310"],["64012.20","0.342"],["64335.50","2.498"],["64335.70","0.987"],["64349.90","0.051"],["64458.80","0.000"],["64487.10","0.003"],["64504.20","0.014"],["64544.80","3.598"],["64546.30","5.591"],["64547.80","2.732"],["64549.30","1.279"],["64550.80","1.281"],["64552.30","1.278"],["64553.80","1.278"],["64555.30","2.081"],["64556.80","1.293"],["64558.30","1.279"],["64559.80","1.299"],["64620.90","0.339"],["64627.40","0.713"],["64633.80","4.398"],["64635.30","0.008"],["64641.70","0.001"],["64648.20","0.000"],["64651.40","0.233"],["64652.00","0.313"],["64656.10","0.023"],["64658.80","12.488"]],"a":[["64658.90","1.080"],["64660.70","0.004"],["64670.40","0.002"],["64670.80","0.110"],["64690.20","0.005"],["64810.90","0.001"],["64828.10","0.003"],["65305.50","0.154"],["65370.20","0.229"],["65425.80","29.270"],["65434.80","6.101"]],"st":1}}
{"stream":"btcusdt@depth@100ms","data":{"e":"depthUpdate","E":1784410689322,"T":1784410689321,"s":"BTCUSDT","ps":"BTCUSDT","U":11079106254616,"u":11079106261418,"pu":11079106254542,"b":[["1000.00","50.791"],["14158.80","0.378"],["14358.80","1.414"],["14458.80","1.386"],["14558.80","1.022"],["51727.00","0.004"],["58192.90","0.002"],["63753.60","3.564"],["64012.20","0.342"],["64132.70","6.225"],["64326.70","0.388"],["64377.50","0.145"],["64487.10","0.701"],["64504.20","0.757"],["64544.80","2.320"],["64546.30","4.313"],["64547.80","1.454"],["64549.30","0.001"],["64550.80","0.003"],["64552.30","0.000"],["64553.80","0.000"],["64555.30","0.803"],["64556.80","0.015"],["64558.30","0.001"],["64588.90","0.000"],["64640.40","0.002"],["64643.30","0.059"],["64644.30","0.000"],["64645.70","0.116"],["64658.80","12.486"]],"a":[["64670.80","0.051"],["64686.20","0.000"],["64686.90","24.859"],["64810.90","1.076"],["64828.00","2.038"],["64973.20","0.689"],["65273.20","1.451"],["65305.50","0.154"]],"st":1}}
