{"stream":"btcusdt@depth@100ms","data":{"e":"depthUpdate","E":1784410680314,"s":"BTCUSDT","U":97585371653,"u":97585372034,"b":[["64689.75000000","1.53981000"],["64689.10000000","0.00018000"],["64689.09000000","0.06918000"],["64689.08000000","0.18931000"],["64689.03000000","0.06574000"],["64688.50000000","0.00000000"],["64688.49000000","0.00018000"],["64688.26000000","0.00000000"],["64688.25000000","0.00018000"],["64688.01000000","0.00018000"],["64687.73000000","0.00018000"],["64687.17000000","0.00000000"],["64687.12000000","0.00000000"],["64686.60000000","0.00400000"],["64686.44000000","0.08218000"],["64686.39000000","0.00009000"],["64686.38000000","0.04125000"],["64685.59000000","0.00009000"],["64685.58000000","0.04026000"],["64685.52000000","0.87089000"],["64685.51000000","0.00000000"],["64685.50000000","0.00018000"],["64685.49000000","0.19679000"],["64684.63000000","0.01243000"],["64684.47000000","0.00000000"],["64684.17000000","0.00029000"],["64684.01000000","0.00773000"],["64684.00000000","0.02477000"],["64683.99000000","2.65782000"],["64683.98000000","0.00908000"],["64683.85000000","0.08227000"],["64683.84000000","0.00008000"],["64681.90000000","0.06250000"],["64681.50000000","0.00048000"],["64681.39000000","0.01007000"],["64681.26000000","0.09863000"],["64681.11000000","0.06724000"],["64680.69000000","0.21414000"],["64680.61000000","0.00048000"],["64680.38000000","0.00000000"],["64680.19000000","0.00191000"],["64680.12000000","0.10710000"],["64680.01000000","0.00000000"],["64679.56000000","0.00212000"],["64679.55000000","0.00920000"],["64679.47000000","0.00000000"],["64679.32000000","0.87933000"],["64678.84000000","0.00000000"],["64678.73000000","0.45350000"],["64678.51000000","0.11340000"],["64676.02000000","0.87398000"],["64676.01000000","0.38655000"],["64675.42000000","0.00000000"],["64672.83000000","0.00059000"],["64672.67000000","0.00000000"],["64671.83000000","0.00012000"],["64671.37000000","0.00000000"],["64671.06000000","0.00000000"],["64668.87000000","0.02000000"],["64668.61000000","0.00200000"],["64664.79000000","0.20626000"],["64660.93000000","0.00000000"],["64660.68000000","0.00000000"],["64660.61000000","0.00000000"],["64660.17000000","0.00000000"],["64659.88000000","0.00000000"],["64657.86000000","0.03022000"],["64657.35000000","0.00000000"],["64657.00000000","0.01000000"],["64653.79000000","0.22691000"],["64653.00000000","0.00000000"],["64652.60000000","0.00009000"],["64652.06000000","0.00000000"],["64651.00000000","0.00000000"],["64644.00000000","0.13083000"],["64643.87000000","0.00000000"],["64642.44000000","0.00615000"],["64632.26000000","0.00000000"],["64629.08000000","0.92822000"],["64628.56000000","0.00000000"],["64620.11000000","0.00000000"],["64618.27000000","0.02003000"],["64618.17000000","4.64603000"],["64570.86000000","0.92821000"],["64566.16000000","0.00154000"],["64560.09000000","0.00000000"],["64556.31000000","0.00000000"],["63719.40000000","0.00030000"],["58220.78000000","0.00038000"],["51747.00000000","0.00000000"]],"a":[["64689.76000000","0.95697000"],["64689.77000000","0.00066000"],["64689.84000000","0.00000000"],["64690.00000000","0.03718000"],["64690.08000000","0.00000000"],["64690.09000000","0.00000000"],["64690.10000000","0.00008000"],["64690.25000000","0.00018000"],["64690.26000000","2.12849000"],["64690.27000000","0.00000000"],["64690.45000000","0.00018000"],["64690.46000000","0.10050000"],["64691.25000000","0.00000000"],["64691.26000000","0.02018000"],["64691.27000000","0.02018000"],["64691.29000000","0.00000000"],["64691.30000000","0.00248000"],["64691.55000000","0.00000000"],["64691.56000000","0.00000000"],["64691.59000000","0.00000000"],["64691.60000000","0.02018000"],["64691.90000000","0.04018000"],["64691.92000000","0.02018000"],["64691.95000000","0.03018000"],["64692.32000000","0.00000000"],["64692.45000000","0.00000000"],["64692.46000000","0.00000000"],["64692.59000000","0.00000000"],["64692.69000000","0.00018000"],["64692.93000000","0.05800000"],["64692.94000000","2.58199000"],["64693.15000000","0.18216000"],["64693.76000000","0.00000000"],["64695.37000000","0.00000000"],["64695.52000000","0.07239000"],["64696.50000000","1.29695000"],["64696.95000000","0.00000000"],["64697.20000000","0.00000000"],["64697.64000000","0.00000000"],["64697.69000000","0.00000000"],["64697.87000000","0.00000000"],["64697.93000000","0.00000000"],["64698.11000000","0.07239000"],["64698.33000000","0.00800000"],["64699.71000000","0.03895000"],["64700.70000000","0.08687000"],["64702.31000000","0.00419000"],["64703.37000000","1.61058000"],["64704.30000000","0.00000000"],["64706.40000000","0.00000000"],["64707.69000000","0.02000000"],["64709.79000000","0.95770000"],["64710.13000000","0.00400000"],["64710.58000000","0.00000000"],["64710.63000000","0.00000000"],["64710.80000000","0.00000000"],["64713.93000000","0.00000000"],["64713.94000000","0.31640000"],["64714.14000000","0.00400000"],["64715.75000000","0.00000000"],["64715.88000000","0.00000000"],["64716.30000000","0.00000000"],["64716.79000000","0.53056000"],["64718.90000000","0.00806000"],["64719.00000000","0.00400000"],["64719.46000000","0.83508000"],["64721.09000000","0.00428000"],["64722.09000000","0.03035000"],["64722.45000000","0.00000000"],["64723.53000000","0.00433000"],["64724.09000000","0.00000000"],["64724.35000000","0.00423000"],["64726.61000000","0.00000000"],["64729.02000000","1.13768000"],["64731.42000000","0.00032000"],["64734.09000000","0.00000000"],["64735.21000000","0.00000000"],["64736.81000000","0.07890000"],["64747.05000000","0.00000000"],["64747.70000000","0.00000000"],["64753.36000000","1.25440000"],["64754.25000000","0.00000000"],["64755.38000000","0.00000000"],["64777.38000000","0.86831000"],["64779.84000000","0.00000000"],["64799.45000000","0.00000000"],["64801.84000000","1.41647000"],["64828.80000000","1.08655000"],["64837.43000000","0.00000000"],["64845.63000000","0.02422000"],["65660.11000000","0.00030000"]]}}
{"stream":"btcusdt@depth@100ms","data":{"e":"depthUpdate","E":1784410680414,"s":"BTCUSDT","U":97585372035,"u":97585372130,"b":[["64689.75000000","1.54046000"],["64689.09000000","0.06936000"],["64689.08000000","0.18931000"],["64689.04000000","0.00018000"],["64689.03000000","0.06600000"],["64688.49000000","0.00000000"],["64688.25000000","0.00000000"],["64687.72000000","0.04026000"],["64686.44000000","0.08236000"],["64686.39000000","0.00000000"],["64686.38000000","0.04143000"],["64685.59000000","0.00000000"],["64685.58000000","0.04008000"],["64685.50000000","0.00000000"],["64685.49000000","0.19669000"],["64681.90000000","0.06242000"],["64681.50000000","0.00000000"],["64680.81000000","0.00000000"],["64668.80000000","0.34090000"],["64638.35000000","0.00424000"],["64599.35000000","0.00000000"],["64580.50000000","0.00000000"],["64472.06000000","0.00000000"],["64360.57000000","0.00009000"],["64341.26000000","0.00000000"],["64321.95000000","0.00000000"],["64101.83000000","0.00012000"],["58220.78000000","0.00076000"]],"a":[["64689.76000000","1.25695000"],["64690.00000000","0.03718000"],["64690.26000000","2.12867000"],["64690.45000000","0.00000000"],["64690.46000000","0.00050000"],["64691.27000000","0.02036000"],["64691.28000000","0.18379000"],["64691.95000000","0.03000000"],["64692.69000000","0.00000000"],["64692.70000000","0.12008000"],["64692.93000000","0.05809000"],["64696.75000000","0.00176000"],["64700.28000000","0.00000000"],["64707.34000000","0.12995000"],["64709.37000000","0.33482000"],["64709.86000000","0.00000000"],["64714.50000000","0.00000000"],["64722.32000000","0.00629000"],["64728.78000000","0.66588000"],["64729.27000000","0.00000000"],["64736.81000000","0.07847000"],["64748.67000000","0.15137000"],["64748.68000000","0.45359000"],["64793.56000000","0.00000000"],["64845.63000000","0.00000000"],["64861.01000000","0.02422000"]]}}
{"stream":"btcusdt@depth@100ms","data":{"e":"depthUpdate","E":1784410680514,"s":"BTCUSDT","U":97585372131,"u":97585372173,"b":[["64689.75000000","1.50046000"],["64689.08000000","0.14931000"],["64688.01000000","0.00000000"],["64688.00000000","0.00018000"],["64687.73000000","0.00000000"],["64687.72000000","0.00026000"],["64686.45000000","0.00018000"],["64686.39000000","0.00009000"],["64685.49000000","0.15669000"],["64683.99000000","0.34317000"],["64603.60000000","0.04796000"],["64548.20000000","0.00000000"],["64508.57000000","0.00975000"],["64501.33000000","0.00000000"],["58220.78000000","0.00114000"],["51751.80000000","0.00038000"]],"a":[["64689.76000000","1.25695000"],["64689.77000000","0.00066000"],["64690.26000000","2.12867000"],["64690.46000000","0.00032000"],["64691.27000000","0.02036000"],["64691.28000000","0.18397000"],["64753.29000000","0.92822000"],["64797.71000000","0.04979000"],["64811.52000000","0.92821000"]]}}
{"stream":"btcusdt@depth@100ms","data":{"e":"depthUpdate","E":1784410680614,"s":"BTCUSDT","U":97585372174,"u":97585372211,"b":[["64689.75000000","1.49139000"],["64689.08000000","0.14923000"],["64689.03000000","0.06600000"],["64688.19000000","0.00008000"],["64688.00000000","0.00000000"],["64687.72000000","0.00008000"],["64686.19000000","0.00000000"],["64685.59000000","0.50426000"],["64685.58000000","0.04026000"],["64685.52000000","0.19266000"],["64683.01000000","0.00000000"],["64682.65000000","0.25973000"],["64680.86000000","0.00009000"],["64680.75000000","0.17470000"],["64679.85000000","0.17470000"],["64679.33000000","0.17470000"],["64588.17000000","0.00015000"],["64582.66000000","0.00023000"],["64579.83000000","0.00000000"],["64574.32000000","0.00000000"],["64557.35000000","0.00000000"],["58220.78000000","0.00152000"],["58220.00000000","0.18544000"],["58215.59000000","0.00000000"],["51751.80000000","0.00000000"]],"a":[["64778.04000000","0.00000000"],["64780.31000000","0.00000000"],["64787.74000000","0.00000000"]]}}
{"stream":"btcusdt@depth@100ms","data":{"e":"depthUpdate","E":1784410680714,"s":"BTCUSDT","U":97585372212,"u":97585372227,"b":[["64686.44000000","0.08252000"],["64686.38000000","0.04143000"],["64685.60000000","0.35502000"],["64685.52000000","0.00018000"],["64672.70000000","0.00008000"],["64666.94000000","0.00000000"],["64665.16000000","0.00009000"],["58220.78000000","0.00171000"],["58220.00000000","0.18524000"]],"a":[["64692.07000000","0.00008000"],["64703.99000000","0.00008000"],["64705.76000000","0.00000000"],["64711.52000000","0.00008000"]]}}
{"stream":"btcusdt@depth@100ms","data":{"e":"depthUpdate","E":1784410680814,"s":"BTCUSDT","U":97585372228,"u":97585372265,"b":[["64689.75000000","1.49123000"],["64689.08000000","0.14915000"],["64686.38000000","0.04143000"],["64685.60000000","0.20468000"],["64685.59000000","0.00018000"],["64685.58000000","0.04008000"],["64685.52000000","0.00000000"],["64668.80000000","0.00000000"],["64647.40000000","0.00000000"],["64565.70000000","0.00038000"],["64447.13000000","0.02422000"],["58220.78000000","0.00209000"]],"a":[["64689.76000000","0.95714000"],["64691.62000000","0.00418000"],["64701.01000000","0.10307000"],["64702.62000000","0.11336000"],["64707.34000000","0.00000000"],["64709.37000000","0.00000000"],["64717.38000000","0.00400000"],["64719.00000000","0.00000000"],["64728.78000000","0.00000000"],["64786.41000000","0.00015000"]]}}
{"stream":"btcusdt@depth@100ms","data":{"e":"depthUpdate","E":1784410680914,"s":"BTCUSDT","U":97585372266,"u":97585372326,"b":[["64686.44000000","0.08244000"],["64685.60000000","0.20468000"],["64685.59000000","0.00000000"],["64685.58000000","0.04026000"],["64683.13000000","0.15466000"],["64682.66000000","0.17470000"],["64682.65000000","0.40954000"],["64681.65000000","0.17470000"],["64680.95000000","0.06200000"],["64680.90000000","0.05800000"],["64680.30000000","0.12400000"],["64680.29000000","0.06800000"],["64680.25000000","0.05600000"],["64678.30000000","0.04400000"],["64677.67000000","0.10008000"],["64677.32000000","0.04800000"],["64677.02000000","0.04600000"],["64677.01000000","0.04600000"],["64676.97000000","0.08400000"],["64673.92000000","0.00000000"],["64673.87000000","0.00000000"],["64673.27000000","0.06200000"],["64670.65000000","0.05000000"],["64670.29000000","0.00000000"],["64669.94000000","0.00000000"],["64630.94000000","0.00000000"],["64630.58000000","0.00000000"],["64630.25000000","0.00000000"],["64574.93000000","0.00000000"],["64558.88000000","0.01872000"],["58220.78000000","0.00247000"],["40000.00000000","261.36615000"]],"a":[["64689.76000000","0.95730000"],["64689.92000000","0.00124000"],["64689.98000000","0.00124000"],["64690.46000000","0.00024000"],["64691.27000000","0.02018000"],["64691.28000000","0.00018000"],["64691.30000000","0.00000000"],["64691.77000000","0.01663000"],["64692.69000000","0.00018000"],["64693.19000000","0.01228000"],["64707.71000000","0.13193000"],["64788.68000000","0.00023000"],["64796.11000000","0.00038000"],["64861.01000000","0.00000000"]]}}
{"stream":"btcusdt@depth@100ms","data":{"e":"depthUpdate","E":1784410681014,"s":"BTCUSDT","U":97585372327,"u":97585373129,"b":[["64691.89000000","2.70522000"],["64691.88000000","0.00034000"],["64691.87000000","0.00016000"],["64691.77000000","0.00018000"],["64691.76000000","0.02063000"],["64691.62000000","0.00773000"],["64691.61000000","0.00000000"],["64691.59000000","0.00000000"],["64691.45000000","0.00000000"],["64691.29000000","0.00000000"],["64691.28000000","0.00008000"],["64691.27000000","0.00000000"],["64691.26000000","0.00000000"],["64691.25000000","0.00000000"],["64690.88000000","0.00000000"],["64690.45000000","0.00000000"],["64690.27000000","0.00008000"],["64690.26000000","0.00018000"],["64690.25000000","0.06825000"],["64690.24000000","0.00000000"],["64690.23000000","0.00000000"],["64690.19000000","0.00008000"],["64690.10000000","0.00000000"],["64690.09000000","0.00000000"],["64690.00000000","0.00000000"],["64689.99000000","0.00000000"],["64689.98000000","0.00000000"],["64689.97000000","0.00000000"],["64689.91000000","0.00000000"],["64689.84000000","0.00400000"],["64689.77000000","0.00018000"],["64689.76000000","0.10076000"],["64689.75000000","0.11431000"],["64689.74000000","0.00000000"],["64689.73000000","0.00000000"],["64689.10000000","0.00000000"],["64689.09000000","0.00027000"],["64689.04000000","0.00000000"],["64689.03000000","0.00026000"],["64688.82000000","0.00000000"],["64688.80000000","0.00000000"],["64688.22000000","0.00400000"],["64688.20000000","0.00000000"],["64688.03000000","0.01648000"],["64687.39000000","0.15748000"],["64686.96000000","0.01210000"],["64686.49000000","0.17469000"],["64686.45000000","0.21412000"],["64686.44000000","0.00034000"],["64686.39000000","0.00000000"],["64685.97000000","0.00010000"],["64685.84000000","0.00153000"],["64685.69000000","0.17469000"],["64685.68000000","0.15457000"],["64685.58000000","0.04008000"],["64685.49000000","0.15669000"],["64685.42000000","0.00009000"],["64685.00000000","0.17469000"],["64684.99000000","0.00000000"],["64684.53000000","0.00110000"],["64684.45000000","0.03895000"],["64684.15000000","0.00000000"],["64684.01000000","0.32926000"],["64684.00000000","0.02486000"],["64683.99000000","0.24899000"],["64683.85000000","0.00008000"],["64683.84000000","0.00000000"],["64683.28000000","0.00400000"],["64683.27000000","0.00000000"],["64683.13000000","0.00000000"],["64682.89000000","0.17469000"],["64682.79000000","0.00000000"],["64682.68000000","0.00000000"],["64682.66000000","0.17469000"],["64682.65000000","0.62537000"],["64682.62000000","0.14011000"],["64681.98000000","0.77357000"],["64681.65000000","0.00000000"],["64681.42000000","0.00000000"],["64681.39000000","0.00113000"],["64681.27000000","0.77341000"],["64681.26000000","0.00000000"],["64681.05000000","0.03000000"],["64680.75000000","0.00000000"],["64680.69000000","0.53052000"],["64680.61000000","0.00000000"],["64680.45000000","0.55698000"],["64680.27000000","0.01714000"],["64679.85000000","0.00000000"],["64679.55000000","0.00000000"],["64679.33000000","0.00000000"],["64678.88000000","0.00009000"],["64678.40000000","0.00200000"],["64678.11000000","0.00000000"],["64677.53000000","0.00000000"],["64676.01000000","0.00000000"],["64675.92000000","0.00200000"],["64675.28000000","0.00400000"],["64674.55000000","0.12000000"],["64673.28000000","0.00000000"],["64673.27000000","0.00000000"],["64673.22000000","0.55704000"],["64673.17000000","0.00000000"],["64672.46000000","0.00000000"],["64671.28000000","0.00000000"],["64669.99000000","0.00000000"],["64669.95000000","0.00000000"],["64669.46000000","0.00000000"],["64668.79000000","0.00000000"],["64667.47000000","0.00000000"],["64665.43000000","0.00000000"],["64665.26000000","0.00000000"],["64663.92000000","0.00000000"],["64663.56000000","0.01887000"],["64663.55000000","0.00000000"],["64662.30000000","0.00000000"],["64660.26000000","0.00000000"],["64658.49000000","0.00000000"],["64651.40000000","0.52195000"],["64647.78000000","0.00000000"],["64636.43000000","0.00000000"],["64628.39000000","0.00000000"],["64627.20000000","0.00009000"],["64627.18000000","0.04200000"],["64627.16000000","0.00000000"],["64619.31000000","0.00000000"],["64618.17000000","0.00000000"],["64615.41000000","2.17558000"],["64589.62000000","0.00000000"],["64562.51000000","0.00009000"],["64554.62000000","0.00000000"],["64547.94000000","1.20000000"],["64537.31000000","0.19057000"],["64533.72000000","0.00000000"],["64520.68000000","0.00000000"],["64497.81000000","0.00009000"],["64489.94000000","0.00000000"],["64447.13000000","0.00000000"],["64433.12000000","0.00009000"],["64425.25000000","0.00000000"],["64423.28000000","0.02422000"],["64413.11000000","0.00000000"],["64368.43000000","0.00009000"],["64360.57000000","0.00000000"],["64303.74000000","0.00009000"],["64295.89000000","0.00000000"],["64239.05000000","0.00009000"],["64231.20000000","0.00000000"],["64174.35000000","0.00009000"],["64166.52000000","0.00000000"],["63867.70000000","0.00000000"],["63730.50000000","1.77270000"],["58222.71000000","0.00019000"],["58221.23000000","0.00000000"],["58220.78000000","0.00010000"],["51753.52000000","0.00038000"]],"a":[["64689.76000000","0.00000000"],["64689.77000000","0.00000000"],["64689.92000000","0.00000000"],["64689.98000000","0.00000000"],["64689.99000000","0.00000000"],["64690.00000000","0.00000000"],["64690.10000000","0.00000000"],["64690.19000000","0.00000000"],["64690.25000000","0.00000000"],["64690.26000000","0.00000000"],["64690.27000000","0.00000000"],["64690.28000000","0.00000000"],["64690.46000000","0.00000000"],["64690.89000000","0.00000000"],["64691.25000000","0.00000000"],["64691.26000000","0.00000000"],["64691.27000000","0.00000000"],["64691.28000000","0.00000000"],["64691.46000000","0.00000000"],["64691.52000000","0.00000000"],["64691.59000000","0.00000000"],["64691.60000000","0.00000000"],["64691.62000000","0.00000000"],["64691.76000000","0.00000000"],["64691.77000000","0.00000000"],["64691.89000000","0.00000000"],["64691.90000000","0.13031000"],["64691.91000000","0.00076000"],["64691.92000000","0.02018000"],["64691.94000000","0.00018000"],["64691.95000000","0.02018000"],["64691.99000000","0.00018000"],["64692.00000000","0.02718000"],["64692.69000000","0.00000000"],["64692.70000000","0.00026000"],["64692.71000000","0.00018000"],["64692.90000000","0.00000000"],["64692.91000000","0.00018000"],["64692.92000000","0.00000000"],["64692.93000000","0.00026000"],["64692.94000000","0.00018000"],["64693.00000000","0.00000000"],["64693.08000000","0.00000000"],["64693.15000000","0.00026000"],["64693.19000000","0.00000000"],["64693.86000000","0.18379000"],["64694.06000000","0.00000000"],["64694.68000000","0.00248000"],["64694.71000000","0.00000000"],["64695.00000000","0.08008000"],["64695.05000000","0.00000000"],["64695.14000000","0.00000000"],["64695.29000000","0.00000000"],["64695.36000000","0.00000000"],["64695.52000000","0.00008000"],["64695.60000000","0.00000000"],["64696.23000000","0.00000000"],["64696.50000000","0.00009000"],["64696.51000000","2.12849000"],["64696.75000000","0.00000000"],["64696.81000000","0.00000000"],["64696.90000000","0.07000000"],["64697.33000000","0.00029000"],["64697.87000000","0.00000000"],["64698.02000000","0.15457000"],["64698.11000000","0.00000000"],["64698.21000000","0.02000000"],["64698.25000000","0.00078000"],["64698.33000000","0.00000000"],["64698.37000000","0.00009000"],["64699.13000000","0.00000000"],["64699.45000000","0.58001000"],["64699.46000000","0.45350000"],["64699.60000000","0.08000000"],["64699.69000000","0.00000000"],["64699.71000000","0.00000000"],["64699.99000000","0.99848000"],["64700.00000000","0.80900000"],["64700.70000000","0.00000000"],["64701.52000000","0.00000000"],["64701.64000000","0.00150000"],["64702.13000000","0.00000000"],["64702.14000000","0.00000000"],["64702.23000000","0.00000000"],["64702.51000000","0.00000000"],["64703.06000000","0.00008000"],["64703.20000000","0.00171000"],["64703.36000000","0.00000000"],["64703.37000000","1.61858000"],["64704.11000000","0.00000000"],["64705.31000000","0.00000000"],["64705.92000000","0.00773000"],["64706.06000000","0.00000000"],["64706.12000000","0.80519000"],["64706.82000000","0.45350000"],["64707.46000000","0.00000000"],["64707.48000000","0.00000000"],["64707.65000000","0.00000000"],["64707.68000000","0.00000000"],["64707.71000000","0.00000000"],["64707.87000000","0.00000000"],["64707.88000000","0.00000000"],["64708.15000000","0.00000000"],["64708.46000000","0.00000000"],["64708.77000000","0.00000000"],["64708.89000000","0.00000000"],["64709.63000000","0.20914000"],["64709.64000000","0.13339000"],["64710.13000000","0.00000000"],["64710.26000000","0.00000000"],["64710.78000000","0.00000000"],["64711.11000000","0.00000000"],["64711.31000000","0.00154000"],["64712.55000000","0.00200000"],["64712.70000000","0.00000000"],["64712.72000000","0.77341000"],["64713.94000000","0.00000000"],["64714.67000000","0.00000000"],["64715.22000000","0.00000000"],["64715.48000000","0.00400000"],["64716.35000000","0.00000000"],["64716.46000000","0.00000000"],["64716.79000000","0.00000000"],["64717.66000000","0.55666000"],["64718.17000000","0.00200000"],["64719.05000000","0.00200000"],["64719.13000000","0.00000000"],["64719.41000000","0.56065000"],["64720.62000000","0.00400000"],["64721.66000000","0.53052000"],["64722.24000000","0.00400000"],["64723.00000000","0.00000000"],["64725.00000000","0.09000000"],["64725.71000000","0.77305000"],["64726.36000000","0.55659000"],["64732.17000000","0.00000000"],["64732.44000000","0.00023000"],["64737.32000000","0.31640000"],["64748.68000000","0.45350000"],["64753.29000000","0.00000000"],["64756.59000000","0.00017000"],["64761.78000000","0.00000000"],["64780.29000000","0.04620000"],["64813.19000000","0.00792000"],["64813.37000000","0.00000000"],["64821.28000000","0.00009000"],["64878.05000000","0.00000000"],["64885.98000000","0.00009000"],["64942.74000000","0.00000000"],["64950.67000000","0.00009000"],["65007.42000000","0.00000000"],["65015.36000000","0.00009000"],["65072.10000000","0.00000000"],["65080.05000000","0.00009000"],["65136.79000000","0.00000000"],["65144.74000000","0.00009000"],["65201.47000000","0.00000000"],["65209.44000000","0.00009000"],["65660.11000000","0.00000000"]]}}
{"stream":"btcusdt@depth@100ms","data":{"e":"depthUpdate","E":1784410681114,"s":"BTCUSDT","U":97585373130,"u":97585373571,"b":[["64691.91000000","3.60851000"],["64691.90000000","0.31021000"],["64691.89000000","0.35421000"],["64691.88000000","0.00000000"],["64691.87000000","0.00000000"],["64691.77000000","0.00000000"],["64691.76000000","0.00018000"],["64691.62000000","0.00018000"],["64691.42000000","0.01715000"],["64691.28000000","0.00000000"],["64691.20000000","0.00018000"],["64691.19000000","0.06574000"],["64690.28000000","0.00773000"],["64690.26000000","0.00009000"],["64690.25000000","0.06843000"],["64690.20000000","0.00000000"],["64689.76000000","0.10076000"],["64689.75000000","0.10228000"],["64689.16000000","0.00000000"],["64689.09000000","0.00000000"],["64689.08000000","0.14931000"],["64689.03000000","0.00008000"],["64688.95000000","0.01239000"],["64688.60000000","0.08218000"],["64688.26000000","0.00000000"],["64688.25000000","0.00000000"],["64688.03000000","0.01666000"],["64687.77000000","0.00078000"],["64687.76000000","0.00000000"],["64687.39000000","0.00008000"],["64686.49000000","0.00016000"],["64686.46000000","0.99244000"],["64686.45000000","0.00000000"],["64686.44000000","0.00000000"],["64686.38000000","0.04125000"],["64686.01000000","0.08218000"],["64685.81000000","0.15457000"],["64685.70000000","2.58199000"],["64685.69000000","0.00000000"],["64685.68000000","0.00000000"],["64685.61000000","0.00000000"],["64685.60000000","0.00000000"],["64685.49000000","0.15645000"],["64685.44000000","0.00008000"],["64685.00000000","0.00000000"],["64684.53000000","0.00032000"],["64684.17000000","0.00000000"],["64684.02000000","0.21413000"],["64684.01000000","0.00000000"],["64683.99000000","0.24883000"],["64683.42000000","0.09862000"],["64682.91000000","1.92030000"],["64682.90000000","2.12849000"],["64682.89000000","0.00000000"],["64682.66000000","0.00000000"],["64682.65000000","0.00000000"],["64682.63000000","0.09140000"],["64681.27000000","0.00000000"],["64680.19000000","0.00000000"],["64680.00000000","0.01008000"],["64679.56000000","0.00000000"],["64679.33000000","0.77340000"],["64677.67000000","0.10000000"],["64676.51000000","0.00000000"],["64675.92000000","0.00000000"],["64674.49000000","0.00000000"],["64673.41000000","0.00200000"],["64670.65000000","0.00000000"],["64669.77000000","0.33805000"],["64668.95000000","0.00000000"],["64667.36000000","0.00000000"],["64666.68000000","0.00000000"],["64662.28000000","0.02977000"],["64659.00000000","0.02056000"],["64657.86000000","0.00000000"],["64657.14000000","0.12836000"],["64657.00000000","0.00000000"],["64654.76000000","0.00419000"],["64650.37000000","0.65824000"],["64649.74000000","0.00000000"],["64648.96000000","0.32617000"],["64637.20000000","0.00000000"],["64634.74000000","0.00000000"],["64634.00000000","0.02700000"],["64629.08000000","0.00000000"],["64601.81000000","0.00000000"],["64598.12000000","0.00000000"],["64598.11000000","0.00000000"],["64589.75000000","0.00000000"],["64419.59000000","0.00040000"],["58222.72000000","0.00019000"],["58222.71000000","0.00000000"]],"a":[["64691.90000000","0.00000000"],["64691.91000000","0.00000000"],["64691.92000000","0.34837000"],["64691.93000000","0.00058000"],["64691.94000000","0.00000000"],["64691.95000000","0.00018000"],["64692.00000000","0.02718000"],["64692.36000000","0.00000000"],["64692.70000000","0.00008000"],["64692.71000000","0.00000000"],["64692.91000000","0.00000000"],["64692.93000000","0.00008000"],["64692.94000000","0.00000000"],["64693.15000000","0.00008000"],["64693.77000000","0.00000000"],["64693.78000000","0.00018000"],["64693.85000000","0.00000000"],["64693.86000000","0.00018000"],["64693.99000000","0.00018000"],["64694.00000000","0.02718000"],["64694.44000000","0.00000000"],["64694.45000000","0.00018000"],["64694.68000000","0.00000000"],["64694.70000000","0.00000000"],["64694.80000000","0.00018000"],["64694.99000000","0.00018000"],["64695.00000000","0.08034000"],["64695.08000000","0.00000000"],["64695.09000000","0.05791000"],["64695.10000000","0.00000000"],["64695.52000000","0.00000000"],["64695.99000000","0.00018000"],["64696.04000000","0.00000000"],["64696.44000000","0.00009000"],["64696.45000000","0.16598000"],["64696.50000000","0.17045000"],["64696.90000000","0.00000000"],["64697.10000000","0.00000000"],["64697.60000000","0.07008000"],["64697.68000000","0.07239000"],["64697.83000000","0.00000000"],["64697.86000000","0.00000000"],["64697.97000000","0.00000000"],["64698.02000000","0.00000000"],["64698.03000000","0.13793000"],["64698.18000000","0.00032000"],["64698.25000000","0.00000000"],["64698.29000000","0.00000000"],["64698.60000000","0.00000000"],["64699.19000000","0.00000000"],["64699.35000000","0.01713000"],["64699.44000000","1.03352000"],["64699.45000000","0.00000000"],["64699.46000000","0.00000000"],["64699.97000000","0.18379000"],["64700.27000000","0.07239000"],["64701.48000000","0.00078000"],["64701.99000000","0.00773000"],["64702.31000000","0.00000000"],["64702.86000000","0.08687000"],["64703.37000000","1.61058000"],["64704.57000000","0.00800000"],["64704.75000000","0.00773000"],["64704.76000000","0.00000000"],["64705.82000000","0.01674000"],["64705.92000000","0.00000000"],["64708.73000000","0.00000000"],["64709.27000000","0.00000000"],["64709.64000000","0.00000000"],["64709.79000000","0.00000000"],["64710.32000000","0.00000000"],["64710.40000000","0.03895000"],["64710.54000000","0.35200000"],["64712.27000000","0.13335000"],["64712.29000000","0.01684000"],["64718.76000000","0.01690000"],["64719.44000000","0.00192000"],["64719.90000000","0.00012000"],["64722.09000000","0.00000000"],["64723.86000000","0.00400000"],["64724.52000000","0.06724000"],["64725.23000000","0.01710000"],["64729.82000000","0.55656000"],["64729.95000000","0.71427000"],["64731.89000000","0.00807000"],["64737.98000000","0.00000000"],["64742.36000000","0.00000000"],["64749.84000000","0.01741000"],["64754.09000000","0.00000000"],["64755.02000000","0.00000000"],["64755.84000000","0.00000000"],["64757.84000000","0.00000000"],["64765.07000000","0.93056000"],["64811.52000000","0.00000000"],["64811.70000000","0.92806000"]]}}
{"stream":"btcusdt@depth@100ms","data":{"e":"depthUpdate","E":1784410681214,"s":"BTCUSDT","U":97585373572,"u":97585373697,"b":[["64691.91000000","3.62711000"],["64691.90000000","0.31039000"],["64691.89000000","0.34210000"],["64691.76000000","0.00000000"],["64691.62000000","0.00000000"],["64691.46000000","0.00400000"],["64691.42000000","0.01733000"],["64691.19000000","0.06592000"],["64690.78000000","0.00008000"],["64689.08000000","0.14905000"],["64689.03000000","0.00000000"],["64688.19000000","0.00000000"],["64688.03000000","0.01648000"],["64687.77000000","0.00000000"],["64687.76000000","0.00078000"],["64686.49000000","0.00008000"],["64686.46000000","0.99252000"],["64685.93000000","0.00008000"],["64683.41000000","0.00008000"],["64678.79000000","0.00192000"],["64674.87000000","0.00008000"],["64665.54000000","0.00000000"],["64663.04000000","0.01155000"],["64656.82000000","1.16926000"],["64647.94000000","0.00434000"],["64647.23000000","0.07000000"],["64646.03000000","0.00000000"],["64645.24000000","0.00434000"],["64635.03000000","0.00000000"],["64634.54000000","0.01722000"],["64620.93000000","0.00000000"],["64619.96000000","0.04544000"],["64606.44000000","0.04796000"],["64603.60000000","0.00000000"],["64592.95000000","0.00111000"],["58222.72000000","0.00038000"],["51753.52000000","0.00000000"]],"a":[["64691.92000000","0.34813000"],["64691.93000000","0.00066000"],["64691.95000000","0.00000000"],["64692.00000000","0.02718000"],["64692.07000000","0.00000000"],["64693.78000000","0.00000000"],["64693.86000000","0.00000000"],["64694.00000000","0.02718000"],["64694.45000000","0.00000000"],["64694.66000000","0.00008000"],["64694.80000000","0.00000000"],["64695.00000000","0.08034000"],["64695.08000000","0.00009000"],["64695.09000000","0.05809000"],["64696.00000000","0.02718000"],["64696.44000000","0.00000000"],["64696.45000000","0.16616000"],["64696.50000000","0.17063000"],["64696.51000000","2.12867000"],["64697.60000000","0.07016000"],["64699.14000000","0.00000000"],["64699.18000000","0.00248000"],["64699.97000000","0.00000000"],["64712.27000000","0.00000000"],["64726.71000000","1.16799000"],["64761.81000000","0.00111000"],["64797.71000000","0.00000000"],["64800.56000000","0.04979000"]]}}
{"stream":"btcusdt@depth@100ms","data":{"e":"depthUpdate","E":1784410681314,"s":"BTCUSDT","U":97585373698,"u":97585373728,"b":[["64691.91000000","3.58463000"],["64691.90000000","0.20916000"],["64691.89000000","0.15831000"],["64640.73000000","0.92808000"],["64632.41000000","0.00384000"],["64630.59000000","0.00000000"],["64595.43000000","0.00565000"],["64567.45000000","0.00154000"],["64566.16000000","0.00000000"],["64368.45000000","0.10000000"],["64349.13000000","0.30000000"],["64329.82000000","0.03051000"],["63721.53000000","0.00030000"],["63719.40000000","0.00000000"],["63278.61000000","0.00000000"],["58222.72000000","0.00076000"]],"a":[["64691.92000000","0.78729000"],["64697.92000000","0.00248000"],["64698.38000000","0.10000000"],["64699.18000000","0.00000000"],["64699.72000000","0.00163000"],["64703.20000000","0.00000000"],["64712.52000000","0.13395000"],["64717.78000000","0.30000000"],["65662.30000000","0.00030000"]]}}
{"stream":"btcusdt@depth@100ms","data":{"e":"depthUpdate","E":1784410681414,"s":"BTCUSDT","U":97585373729,"u":97585373769,"b":[["64691.91000000","3.77090000"],["64691.90000000","0.24489000"],["64691.42000000","0.00018000"],["64686.46000000","0.32642000"],["64685.81000000","0.15465000"],["64685.71000000","0.45350000"],["64685.70000000","0.00000000"],["64684.45000000","0.00000000"],["64682.91000000","1.31024000"],["64680.69000000","0.00000000"],["64677.03000000","0.53055000"],["64640.73000000","0.00000000"],["64639.71000000","0.00000000"],["64638.59000000","0.92808000"],["64109.68000000","0.00010000"],["58222.72000000","0.00114000"]],"a":[["64691.92000000","0.93589000"],["64696.14000000","0.00248000"],["64696.50000000","0.17071000"],["64696.88000000","0.00000000"],["64697.92000000","0.00000000"],["64698.03000000","0.13801000"],["64707.13000000","0.00419000"],["64737.19000000","0.50000000"],["64756.60000000","0.70000000"]]}}
{"stream":"btcusdt@depth@100ms","data":{"e":"depthUpdate","E":1784410681514,"s":"BTCUSDT","U":97585373770,"u":97585373814,"b":[["64691.91000000","4.23464000"],["64691.89000000","0.15831000"],["64691.42000000","0.00000000"],["64690.28000000","0.00791000"],["64684.31000000","0.03895000"],["64678.72000000","0.00000000"],["64672.50000000","0.00015000"],["64664.58000000","0.00000000"],["64662.12000000","1.53214000"],["64653.09000000","0.00015000"],["64645.18000000","0.00000000"],["64638.59000000","0.00000000"],["64638.58000000","0.92808000"],["64633.69000000","0.00015000"],["64625.77000000","0.00000000"],["64614.28000000","0.00015000"],["64606.37000000","0.00000000"],["64594.87000000","0.00015000"],["64586.96000000","0.00000000"],["58222.72000000","0.00152000"],["51753.53000000","0.00038000"]],"a":[["64691.92000000","0.50495000"],["64691.93000000","0.00074000"],["64696.50000000","0.17063000"],["64703.41000000","0.00000000"],["64711.33000000","0.00015000"],["64722.81000000","0.00000000"],["64730.74000000","0.00015000"],["64742.22000000","0.00000000"],["64750.14000000","0.00015000"],["64761.62000000","0.00000000"],["64769.55000000","0.00015000"],["64781.03000000","0.00000000"],["64788.96000000","0.00015000"]]}}
{"stream":"btcusdt@depth@100ms","data":{"e":"depthUpdate","E":1784410681615,"s":"BTCUSDT","U":97585373815,"u":97585373828,"b":[["64669.77000000","0.00000000"],["64644.74000000","0.00386000"],["64642.03000000","0.00000000"],["64640.15000000","0.00383000"],["64638.58000000","0.00000000"],["64637.97000000","0.92808000"],["64634.47000000","0.00000000"],["64580.10000000","0.00154000"],["64577.12000000","0.00000000"],["64575.54000000","0.00154000"],["64569.74000000","0.00000000"],["58222.72000000","0.00190000"],["51753.53000000","0.00000000"]],"a":[["64743.48000000","0.00010000"],["64749.83000000","0.00386000"],["64754.99000000","0.00000000"],["64756.59000000","0.00402000"],["64808.42000000","0.00000000"],["64814.99000000","0.00154000"],["64819.15000000","0.00000000"],["64821.39000000","0.00154000"]]}}
{"stream":"btcusdt@depth@100ms","data":{"e":"depthUpdate","E":1784410681714,"s":"BTCUSDT","U":97585373829,"u":97585373843,"b":[["64674.86000000","0.00008000"],["64672.70000000","0.00000000"],["64634.42000000","0.11608000"],["64586.25000000","0.00130000"],["63780.70000000","0.00039000"],["58222.72000000","0.00209000"],["33000.00000000","32.31996000"]],"a":[["64711.52000000","0.00000000"],["64713.68000000","2.12857000"],["64716.33000000","1.56051000"],["64746.34000000","1.10611000"],["64769.61000000","2.03002000"],["64769.63000000","0.00000000"],["64803.85000000","0.17821000"],["64832.96000000","0.76436000"]]}}
{"stream":"btcusdt@depth@100ms","data":{"e":"depthUpdate","E":1784410681814,"s":"BTCUSDT","U":97585373844,"u":97585373854,"b":[["64687.73000000","0.12800000"],["64674.84000000","0.34372000"],["64553.95000000","0.00130000"],["58222.72000000","0.00247000"],["58222.00000000","0.71721000"],["58220.78000000","0.00000000"],["58220.77000000","0.00010000"]],"a":[["64691.92000000","0.50485000"],["64708.85000000","0.00008000"],["71161.11000000","0.00032000"]]}}
{"stream":"btcusdt@depth@100ms","data":{"e":"depthUpdate","E":1784410681914,"s":"BTCUSDT","U":97585373855,"u":97585373911,"b":[["64689.76000000","0.14000000"],["64688.60000000","0.08226000"],["64630.93000000","0.06000000"],["64630.58000000","0.05600000"],["64630.25000000","0.06800000"],["64628.38000000","0.04400000"],["64627.18000000","0.08400000"],["64627.16000000","0.04600000"],["58222.72000000","0.00285000"],["40000.00000000","261.36615000"]],"a":[["64691.92000000","0.50477000"],["64691.93000000","0.00066000"],["64694.38000000","0.00248000"],["64696.14000000","0.00000000"],["64699.42000000","0.02000000"],["64699.43000000","0.02000000"],["64700.06000000","0.04000000"],["64700.07000000","0.02000000"],["64700.11000000","0.02000000"],["64701.94000000","0.02000000"],["64702.61000000","0.04000000"],["64702.96000000","0.02000000"],["64703.24000000","0.04000000"],["64703.26000000","0.04000000"],["64707.99000000","0.00000000"],["64709.69000000","0.00000000"],["64710.33000000","0.02000000"],["64712.89000000","0.00000000"],["64713.24000000","0.00000000"],["64713.54000000","0.00082000"],["64713.71000000","0.00061000"],["64741.27000000","0.02000000"],["64741.91000000","0.00000000"],["64741.94000000","0.00000000"],["64743.79000000","0.02000000"],["64745.09000000","0.02000000"],["64745.10000000","0.02000000"],["64748.57000000","0.02000000"],["64749.17000000","0.02000000"],["64749.26000000","0.02000000"],["64751.72000000","0.02000000"],["64752.36000000","0.02012000"],["64752.39000000","0.02000000"],["64752.69000000","0.02000000"],["64753.94000000","0.02000000"],["71161.11000000","0.00024000"],["77816.97000000","0.00019000"]]}}
{"stream":"btcusdt@depth@100ms","data":{"e":"depthUpdate","E":1784410682014,"s":"BTCUSDT","U":97585373912,"u":97585373940,"b":[["64691.91000000","4.69074000"],["64691.21000000","0.00773000"],["64690.28000000","0.00018000"],["64689.09000000","0.00773000"],["64686.38000000","0.00000000"],["64680.31000000","0.77341000"],["64679.33000000","0.00000000"],["58222.72000000","0.00323000"],["51753.53000000","0.00038000"]],"a":[["64691.92000000","0.50502000"],["64691.93000000","0.00074000"],["64701.07000000","0.00773000"],["64701.99000000","0.00000000"],["64703.23000000","0.00773000"],["64704.75000000","0.00000000"],["64707.68000000","0.12143000"],["64708.63000000","0.00008000"],["64709.63000000","0.00000000"],["64710.33000000","0.00000000"],["64710.49000000","0.00000000"],["64710.53000000","0.77341000"],["64711.80000000","0.00000000"],["64711.81000000","0.00000000"],["64712.69000000","0.06724000"],["64712.72000000","0.00000000"],["64713.52000000","0.00000000"],["64724.52000000","0.00000000"],["64743.79000000","0.00000000"],["64745.09000000","0.00000000"],["64745.10000000","0.00000000"],["64793.25000000","0.00029000"],["64794.74000000","0.00000000"]]}}
{"stream":"btcusdt@depth@100ms","data":{"e":"depthUpdate","E":1784410682114,"s":"BTCUSDT","U":97585373941,"u":97585373967,"b":[["64691.89000000","0.15831000"],["64691.21000000","0.00791000"],["64691.19000000","0.06592000"],["64690.28000000","0.00000000"],["64689.75000000","0.10228000"],["64686.46000000","1.05475000"],["64685.50000000","2.12849000"],["64602.67000000","0.00000000"],["58222.72000000","0.00361000"]],"a":[["64708.66000000","0.00000000"],["64761.75000000","2.36285000"],["64825.64000000","0.00029000"],["64830.51000000","0.00000000"],["64865.53000000","0.02421000"]]}}
{"stream":"btcusdt@depth@100ms","data":{"e":"depthUpdate","E":1784410682214,"s":"BTCUSDT","U":97585373968,"u":97585373997,"b":[["64691.91000000","4.69847000"],["64691.21000000","0.00018000"],["64686.47000000","0.21412000"],["64684.02000000","0.00000000"],["64663.59000000","0.77000000"],["64614.05000000","0.00008000"],["64610.58000000","0.00030000"],["58222.72000000","0.00399000"],["51753.53000000","0.00000000"]],"a":[["64691.92000000","0.40247000"],["64691.93000000","0.00090000"],["64694.38000000","0.00000000"],["64695.08000000","0.00018000"],["64695.09000000","0.05817000"],["64695.25000000","0.18379000"],["64695.60000000","0.00248000"],["64695.99000000","0.00009000"],["64703.23000000","0.00000000"],["64703.98000000","0.00773000"],["64727.63000000","0.00000000"],["64764.17000000","0.00008000"],["64764.38000000","0.00000000"],["64772.31000000","0.00030000"]]}}
{"stream":"btcusdt@depth@100ms","data":{"e":"depthUpdate","E":1784410682314,"s":"BTCUSDT","U":97585373998,"u":97585374031,"b":[["64691.89000000","0.15831000"],["64691.21000000","0.00000000"],["64689.09000000","0.00791000"],["64687.73000000","0.12808000"],["63721.53000000","0.00030000"],["59509.28000000","0.00017000"],["58222.72000000","0.00418000"],["51754.00000000","0.00000000"]],"a":[["64691.92000000","0.40272000"],["64691.93000000","0.00098000"],["64691.94000000","0.00016000"],["64695.09000000","0.05817000"],["64695.25000000","0.18397000"],["64696.51000000","2.12849000"],["64704.17000000","0.04726000"],["64753.94000000","0.00000000"],["64865.53000000","0.00000000"],["65662.30000000","0.00030000"]]}}
{"stream":"btcusdt@depth@100ms","data":{"e":"depthUpdate","E":1784410682414,"s":"BTCUSDT","U":97585374032,"u":97585374035,"b":[["58222.72000000","0.00418000"]],"a":[]}}
{"stream":"btcusdt@depth@100ms","data":{"e":"depthUpdate","E":1784410682514,"s":"BTCUSDT","U":97585374036,"u":97585374044,"b":[["64691.91000000","5.13119000"],["58222.72000000","0.00418000"],["58220.77000000","0.00000000"],["51753.53000000","0.00038000"]],"a":[]}}
{"stream":"btcusdt@depth@100ms","data":{"e":"depthUpdate","E":1784410682614,"s":"BTCUSDT","U":97585374045,"u":97585374050,"b":[["58222.72000000","0.00418000"],["51753.53000000","0.00000000"]],"a":[["64883.56000000","0.09247000"]]}}
{"stream":"btcusdt@depth@100ms","data":{"e":"depthUpdate","E":1784410682714,"s":"BTCUSDT","U":97585374051,"u":97585374069,"b":[["64674.86000000","0.00000000"],["64663.56000000","0.48613000"],["64618.27000000","0.66694000"],["64371.27000000","0.00000000"],["64364.95000000","0.00250000"],["58222.72000000","0.00428000"]],"a":[["64691.92000000","0.40072000"],["64713.68000000","2.12849000"],["64723.66000000","1.24043000"],["64741.89000000","1.45758000"],["64761.74000000","1.36081000"],["64761.77000000","0.00000000"],["64783.99000000","0.04025000"],["64828.80000000","0.00000000"],["64832.96000000","0.00000000"],["64974.54000000","0.00000000"],["64980.93000000","0.00250000"]]}}
{"stream":"btcusdt@depth@100ms","data":{"e":"depthUpdate","E":1784410682814,"s":"BTCUSDT","U":97585374070,"u":97585374077,"b":[["64674.86000000","0.00008000"],["64556.68000000","0.09294000"],["59509.28000000","0.00000000"],["58222.72000000","0.00428000"],["58222.00000000","0.71721000"]],"a":[["64713.68000000","2.12857000"]]}}
{"stream":"btcusdt@depth@100ms","data":{"e":"depthUpdate","E":1784410682914,"s":"BTCUSDT","U":97585374078,"u":97585374089,"b":[["64663.80000000","0.02577000"],["58222.72000000","0.00428000"],["40000.00000000","261.36615000"]],"a":[["64741.91000000","0.02000000"],["64741.94000000","0.02000000"],["64743.79000000","0.02000000"],["64745.09000000","0.02000000"],["64745.10000000","0.02000000"]]}}
{"stream":"btcusdt@depth@100ms","data":{"e":"depthUpdate","E":1784410683014,"s":"BTCUSDT","U":97585374090,"u":97585374100,"b":[["64691.91000000","5.59502000"],["64682.92000000","0.17681000"],["64682.63000000","0.00000000"],["64663.80000000","0.00000000"],["58222.72000000","0.00428000"],["51753.53000000","0.00038000"]],"a":[["64701.07000000","0.00000000"],["64701.47000000","0.00773000"],["64707.68000000","0.00000000"],["64707.99000000","0.10850000"]]}}
{"stream":"btcusdt@depth@100ms","data":{"e":"depthUpdate","E":1784410683114,"s":"BTCUSDT","U":97585374101,"u":97585374105,"b":[["64663.80000000","0.02577000"],["58222.72000000","0.00428000"]],"a":[]}}
{"stream":"btcusdt@depth@100ms","data":{"e":"depthUpdate","E":1784410683214,"s":"BTCUSDT","U":97585374106,"u":97585374118,"b":[["64682.00000000","0.00800000"],["64680.00000000","0.01808000"],["64678.00000000","0.00800000"],["64663.80000000","0.00000000"],["58222.72000000","0.00428000"],["51753.53000000","0.00000000"]],"a":[["64719.45000000","0.00000000"],["64731.10000000","0.77009000"],["64743.43000000","0.38614000"]]}}
{"stream":"btcusdt@depth@100ms","data":{"e":"depthUpdate","E":1784410683317,"s":"BTCUSDT","U":97585374119,"u":97585374129,"b":[["64687.73000000","0.12816000"],["64686.48000000","0.38648000"],["63721.53000000","0.00030000"],["58222.72000000","0.00409000"]],"a":[["64761.64000000","0.00008000"],["64770.91000000","0.00008000"],["65662.30000000","0.00030000"]]}}
{"stream":"btcusdt@depth@100ms","data":{"e":"depthUpdate","E":1784410683414,"s":"BTCUSDT","U":97585374130,"u":97585374138,"b":[["64682.00000000","0.01600000"],["64680.00000000","0.02608000"],["64678.00000000","0.01600000"],["64665.64000000","0.00015000"],["58222.72000000","0.00428000"],["51754.00000000","0.00000000"]],"a":[]}}
{"stream":"btcusdt@depth@100ms","data":{"e":"depthUpdate","E":1784410683514,"s":"BTCUSDT","U":97585374139,"u":97585374154,"b":[["64691.91000000","6.05461000"],["64690.77000000","0.01228000"],["64665.64000000","0.00000000"],["64556.68000000","0.00000000"],["58222.72000000","0.00428000"],["51754.00000000","0.00000000"],["51753.53000000","0.00038000"]],"a":[["64704.86000000","0.00306000"],["64728.21000000","0.00000000"],["64883.56000000","0.00000000"]]}}
{"stream":"btcusdt@depth@100ms","data":{"e":"depthUpdate","E":1784410683614,"s":"BTCUSDT","U":97585374155,"u":97585374190,"b":[["64691.91000000","6.05470000"],["64691.33000000","0.00000000"],["64691.19000000","0.06592000"],["64690.77000000","0.00000000"],["64690.09000000","0.02000000"],["64688.76000000","0.00000000"],["64688.75000000","0.00078000"],["64687.77000000","0.00000000"],["64687.76000000","0.00000000"],["64685.81000000","0.00008000"],["64685.49000000","0.31102000"],["64682.62000000","0.10011000"],["58222.72000000","0.00428000"],["51754.00000000","0.00000000"],["51753.53000000","0.00000000"]],"a":[["64691.92000000","0.40055000"],["64697.68000000","0.07247000"],["64698.03000000","0.00008000"],["64698.06000000","0.09246000"],["64701.48000000","0.00000000"],["64702.47000000","0.00078000"],["64704.86000000","0.00000000"],["64710.53000000","0.00000000"],["64712.51000000","0.77341000"],["64712.52000000","0.00400000"]]}}
{"stream":"btcusdt@depth@100ms","data":{"e":"depthUpdate","E":1784410683714,"s":"BTCUSDT","U":97585374191,"u":97585374203,"b":[["64691.19000000","0.06592000"],["64690.25000000","0.06843000"],["64682.00000000","0.02200000"],["58222.72000000","0.00428000"]],"a":[]}}
{"stream":"btcusdt@depth@100ms","data":{"e":"depthUpdate","E":1784410683814,"s":"BTCUSDT","U":97585374204,"u":97585374218,"b":[["64680.00000000","0.03208000"],["64678.00000000","0.02200000"],["64674.86000000","0.00008000"],["58222.72000000","0.00399000"],["58222.71000000","0.00010000"]],"a":[["64691.92000000","0.40034000"],["64704.86000000","0.00306000"],["64710.78000000","0.88249000"],["64713.68000000","2.12857000"],["64756.59000000","0.21307000"],["64774.99000000","0.04948000"],["64801.84000000","0.00000000"]]}}
{"stream":"btcusdt@depth@100ms","data":{"e":"depthUpdate","E":1784410683915,"s":"BTCUSDT","U":97585374219,"u":97585374234,"b":[["58222.72000000","0.00418000"],["58222.00000000","0.71721000"],["40000.00000000","261.36615000"]],"a":[["64713.82000000","0.13294000"],["64715.98000000","0.02000000"],["64716.62000000","0.04000000"],["64719.17000000","0.02000000"],["64719.52000000","0.02000000"],["64719.80000000","0.02000000"],["64719.82000000","0.02000000"],["64849.40000000","0.02421000"]]}}
{"stream":"btcusdt@depth@100ms","data":{"e":"depthUpdate","E":1784410684016,"s":"BTCUSDT","U":97585374235,"u":97585374258,"b":[["64690.10000000","0.00773000"],["64689.09000000","0.00018000"],["64683.43000000","0.13740000"],["64682.92000000","0.00000000"],["64682.00000000","0.02700000"],["64680.00000000","0.03708000"],["64678.00000000","0.02700000"],["64625.01000000","0.97263000"],["64623.97000000","1.18453000"],["64611.26000000","0.18644000"],["64611.25000000","0.00036000"],["64512.62000000","0.05799000"],["64501.32000000","0.00000000"],["58222.72000000","0.00418000"],["51753.53000000","0.00038000"]],"a":[["64701.47000000","0.00000000"],["64701.93000000","0.00773000"],["64704.86000000","0.00000000"],["64707.99000000","0.00000000"],["64708.89000000","0.25277000"],["64752.39000000","0.00000000"],["64761.74000000","0.00000000"],["64761.75000000","0.00000000"]]}}
{"stream":"btcusdt@depth@100ms","data":{"e":"depthUpdate","E":1784410684115,"s":"BTCUSDT","U":97585374259,"u":97585374279,"b":[["64691.91000000","6.05451000"],["64690.25000000","0.06843000"],["64690.10000000","0.00791000"],["64690.09000000","0.02018000"],["64689.75000000","0.10210000"],["64689.09000000","0.00000000"],["58222.72000000","0.00418000"],["58222.71000000","0.00000000"]],"a":[["64704.86000000","0.00306000"],["64748.57000000","0.00000000"],["64752.69000000","0.00000000"]]}}
{"stream":"btcusdt@depth@100ms","data":{"e":"depthUpdate","E":1784410684214,"s":"BTCUSDT","U":97585374280,"u":97585374286,"b":[["64691.91000000","6.05394000"],["58222.72000000","0.00418000"],["51753.53000000","0.00000000"]],"a":[["64751.72000000","0.00000000"]]}}
{"stream":"btcusdt@depth@100ms","data":{"e":"depthUpdate","E":1784410684314,"s":"BTCUSDT","U":97585374287,"u":97585374299,"b":[["64512.63000000","0.00975000"],["64508.57000000","0.00000000"],["63721.53000000","0.00030000"],["58222.72000000","0.00399000"],["51754.00000000","0.00000000"]],"a":[["64704.86000000","0.00000000"],["64749.17000000","0.00000000"],["64752.36000000","0.00012000"],["65662.30000000","0.00030000"]]}}
{"stream":"btcusdt@depth@100ms","data":{"e":"depthUpdate","E":1784410684414,"s":"BTCUSDT","U":97585374300,"u":97585374303,"b":[["58222.72000000","0.00418000"]],"a":[["64749.26000000","0.00000000"]]}}
{"stream":"btcusdt@depth@100ms","data":{"e":"depthUpdate","E":1784410684514,"s":"BTCUSDT","U":97585374304,"u":97585374308,"b":[["58222.72000000","0.00418000"],["51753.53000000","0.00038000"]],"a":[]}}
{"stream":"btcusdt@depth@100ms","data":{"e":"depthUpdate","E":1784410684614,"s":"BTCUSDT","U":97585374309,"u":97585374326,"b":[["64688.76000000","0.00078000"],["64688.75000000","0.00000000"],["64678.04000000","0.00000000"],["64625.01000000","0.00000000"],["64623.97000000","0.00000000"],["64538.44000000","0.00000000"],["58222.72000000","0.00418000"],["51753.53000000","0.00000000"]],"a":[["64691.92000000","0.40034000"],["64703.98000000","0.00000000"],["64704.56000000","0.00773000"],["64704.86000000","0.00306000"],["64832.97000000","0.00000000"]]}}
{"stream":"btcusdt@depth@100ms","data":{"e":"depthUpdate","E":1784410684714,"s":"BTCUSDT","U":97585374327,"u":97585374334,"b":[["64685.96000000","0.00222000"],["58222.72000000","0.00418000"]],"a":[["64699.35000000","0.00000000"],["64704.86000000","0.00000000"],["64801.84000000","0.55813000"]]}}
{"stream":"btcusdt@depth@100ms","data":{"e":"depthUpdate","E":1784410684814,"s":"BTCUSDT","U":97585374335,"u":97585374351,"b":[["64674.86000000","0.00008000"],["58222.72000000","0.00418000"]],"a":[["64704.86000000","0.00000000"],["64713.68000000","2.12857000"],["64725.66000000","2.02275000"],["64761.88000000","0.65517000"],["64780.94000000","0.00000000"],["64789.90000000","0.00000000"],["64801.84000000","0.00000000"],["64803.85000000","0.00012000"],["64810.36000000","0.00000000"],["64816.96000000","0.00000000"]]}}
{"stream":"btcusdt@depth@100ms","data":{"e":"depthUpdate","E":1784410684914,"s":"BTCUSDT","U":97585374352,"u":97585374360,"b":[["64546.92000000","5.88866000"],["58222.72000000","0.00418000"],["58222.00000000","0.71741000"],["40000.00000000","261.36615000"]],"a":[["64713.82000000","0.00000000"],["64714.63000000","0.13238000"],["64841.84000000","6.14161000"]]}}
{"stream":"btcusdt@depth@100ms","data":{"e":"depthUpdate","E":1784410685014,"s":"BTCUSDT","U":97585374361,"u":97585374371,"b":[["64690.74000000","0.01248000"],["64621.85000000","1.18453000"],["58222.72000000","0.00418000"],["58222.00000000","0.71721000"],["51753.53000000","0.00038000"]],"a":[["64704.86000000","0.00306000"]]}}
{"stream":"btcusdt@depth@100ms","data":{"e":"depthUpdate","E":1784410685114,"s":"BTCUSDT","U":97585374372,"u":97585374384,"b":[["64691.19000000","0.06592000"],["64688.76000000","0.00000000"],["64688.75000000","0.00078000"],["64512.63000000","0.00000000"],["64508.57000000","0.00975000"],["58222.72000000","0.00418000"]],"a":[["64733.69000000","0.46343000"],["82071.40000000","0.00000000"]]}}
{"stream":"btcusdt@depth@100ms","data":{"e":"depthUpdate","E":1784410685214,"s":"BTCUSDT","U":97585374385,"u":97585374391,"b":[["58222.72000000","0.00418000"],["51753.53000000","0.00000000"]],"a":[["64695.25000000","0.00018000"],["64699.39000000","0.01659000"]]}}
{"stream":"btcusdt@depth@100ms","data":{"e":"depthUpdate","E":1784410685315,"s":"BTCUSDT","U":97585374392,"u":97585374414,"b":[["64685.61000000","0.00311000"],["64672.62000000","0.01712000"],["63721.53000000","0.00030000"],["58222.72000000","0.00418000"]],"a":[["64691.92000000","0.40201000"],["64695.09000000","0.05809000"],["64695.25000000","0.00000000"],["64696.51000000","2.12867000"],["64704.86000000","0.00306000"],["64865.53000000","0.02421000"],["65662.30000000","0.00030000"]]}}
{"stream":"btcusdt@depth@100ms","data":{"e":"depthUpdate","E":1784410685415,"s":"BTCUSDT","U":97585374415,"u":97585374421,"b":[["64512.63000000","0.00975000"],["64508.57000000","0.00000000"],["58222.72000000","0.00399000"]],"a":[["64691.92000000","0.40051000"],["64704.86000000","0.00000000"],["65000.00000000","57.07144000"]]}}
{"stream":"btcusdt@depth@100ms","data":{"e":"depthUpdate","E":1784410685515,"s":"BTCUSDT","U":97585374422,"u":97585374428,"b":[["58222.72000000","0.00418000"],["51753.53000000","0.00038000"]],"a":[["64691.92000000","0.40043000"],["64691.93000000","0.00090000"],["64704.86000000","0.00306000"]]}}
{"stream":"btcusdt@depth@100ms","data":{"e":"depthUpdate","E":1784410685614,"s":"BTCUSDT","U":97585374429,"u":97585374437,"b":[["64587.34000000","0.00030000"],["64586.74000000","0.00000000"],["58222.72000000","0.00418000"],["51753.53000000","0.00000000"]],"a":[["64704.86000000","0.00000000"],["82071.40000000","0.00010000"]]}}
{"stream":"btcusdt@depth@100ms","data":{"e":"depthUpdate","E":1784410685715,"s":"BTCUSDT","U":97585374438,"u":97585374443,"b":[["58222.72000000","0.00418000"]],"a":[["64704.86000000","0.00000000"]]}}
{"stream":"btcusdt@depth@100ms","data":{"e":"depthUpdate","E":1784410685814,"s":"BTCUSDT","U":97585374444,"u":97585374463,"b":[["64691.91000000","6.05364000"],["64674.86000000","0.00000000"],["64623.92000000","0.83220000"],["58222.72000000","0.00418000"],["58222.71000000","0.00010000"],["51754.00000000","0.00000000"]],"a":[["64713.68000000","2.12849000"],["64717.98000000","0.00000000"],["64724.99000000","0.00336000"],["64764.99000000","0.43523000"],["64777.38000000","0.00000000"]]}}
{"stream":"btcusdt@depth@100ms","data":{"e":"depthUpdate","E":1784410685914,"s":"BTCUSDT","U":97585374464,"u":97585374473,"b":[["64674.86000000","0.00008000"],["64636.01000000","0.00773000"],["64629.02000000","0.00000000"],["58222.72000000","0.00399000"],["40000.00000000","261.36615000"]],"a":[["64704.86000000","0.00306000"],["64713.68000000","2.12857000"]]}}
{"stream":"btcusdt@depth@100ms","data":{"e":"depthUpdate","E":1784410686014,"s":"BTCUSDT","U":97585374474,"u":97585374486,"b":[["58222.72000000","0.00418000"],["58222.00000000","0.71721000"],["51753.53000000","0.00038000"]],"a":[["64691.92000000","0.40043000"],["64696.17000000","0.00168000"],["64699.72000000","0.00000000"],["64704.86000000","0.00306000"],["64763.87000000","2.36285000"]]}}
{"stream":"btcusdt@depth@100ms","data":{"e":"depthUpdate","E":1784410686114,"s":"BTCUSDT","U":97585374487,"u":97585374496,"b":[["58222.72000000","0.00418000"],["51753.53000000","0.00038000"],["33000.00000000","32.31996000"]],"a":[["64691.92000000","0.40193000"],["64704.86000000","0.00000000"]]}}
{"stream":"btcusdt@depth@100ms","data":{"e":"depthUpdate","E":1784410686214,"s":"BTCUSDT","U":97585374497,"u":97585374507,"b":[["64689.77000000","0.26829000"],["64689.76000000","0.38664000"],["64687.73000000","0.12808000"],["64686.48000000","0.00000000"],["58222.72000000","0.00418000"],["51753.53000000","0.00000000"]],"a":[]}}
{"stream":"btcusdt@depth@100ms","data":{"e":"depthUpdate","E":1784410686314,"s":"BTCUSDT","U":97585374508,"u":97585374528,"b":[["64690.74000000","0.01266000"],["64690.26000000","0.00018000"],["64690.25000000","0.06851000"],["64690.09000000","0.02018000"],["64689.77000000","0.26820000"],["64689.76000000","0.38646000"],["63721.53000000","0.00030000"],["58222.72000000","0.00418000"],["51754.00000000","0.00000000"]],"a":[["65662.30000000","0.00030000"]]}}
{"stream":"btcusdt@depth@100ms","data":{"e":"depthUpdate","E":1784410686414,"s":"BTCUSDT","U":97585374529,"u":97585374531,"b":[["58222.72000000","0.00399000"]],"a":[]}}
{"stream":"btcusdt@depth@100ms","data":{"e":"depthUpdate","E":1784410686515,"s":"BTCUSDT","U":97585374532,"u":97585374540,"b":[["64685.82000000","0.00308000"],["64685.61000000","0.00000000"],["58222.72000000","0.00418000"],["58222.71000000","0.00000000"],["58222.70000000","0.00010000"],["51753.53000000","0.00038000"]],"a":[["64691.92000000","0.40186000"],["64704.86000000","0.00000000"]]}}
{"stream":"btcusdt@depth@100ms","data":{"e":"depthUpdate","E":1784410686614,"s":"BTCUSDT","U":97585374541,"u":97585374547,"b":[["64667.80000000","0.00015000"],["58222.72000000","0.00418000"],["51753.53000000","0.00000000"]],"a":[["64730.38000000","0.00015000"]]}}
{"stream":"btcusdt@depth@100ms","data":{"e":"depthUpdate","E":1784410686715,"s":"BTCUSDT","U":97585374548,"u":97585374552,"b":[["58222.72000000","0.00418000"]],"a":[["64704.86000000","0.00306000"]]}}
{"stream":"btcusdt@depth@100ms","data":{"e":"depthUpdate","E":1784410686814,"s":"BTCUSDT","U":97585374553,"u":97585374560,"b":[["58222.72000000","0.00428000"]],"a":[["64691.92000000","0.40036000"],["64704.86000000","0.00000000"],["64761.88000000","1.27671000"]]}}
{"stream":"btcusdt@depth@100ms","data":{"e":"depthUpdate","E":1784410686914,"s":"BTCUSDT","U":97585374561,"u":97585374573,"b":[["64691.91000000","6.05156000"],["64674.86000000","0.00008000"],["58222.72000000","0.00418000"],["58222.70000000","0.00000000"],["40000.00000000","261.36615000"]],"a":[["64704.86000000","0.00306000"],["64713.68000000","2.12857000"]]}}
{"stream":"btcusdt@depth@100ms","data":{"e":"depthUpdate","E":1784410687014,"s":"BTCUSDT","U":97585374574,"u":97585374584,"b":[["64686.47000000","0.00000000"],["64685.72000000","0.21412000"],["64681.39000000","0.00105000"],["64676.38000000","0.00000000"],["58222.72000000","0.00418000"],["58222.00000000","0.71721000"],["51753.53000000","0.00038000"]],"a":[["64704.86000000","0.00306000"],["65200.62000000","0.00097000"]]}}
{"stream":"btcusdt@depth@100ms","data":{"e":"depthUpdate","E":1784410687114,"s":"BTCUSDT","U":97585374585,"u":97585374598,"b":[["64691.91000000","6.02071000"],["64691.19000000","0.06600000"],["64690.30000000","0.00009000"],["64690.29000000","0.06724000"],["64689.77000000","0.26811000"],["64687.73000000","0.12800000"],["64681.11000000","0.00000000"],["58222.72000000","0.00418000"],["58222.71000000","0.00010000"]],"a":[["64704.86000000","0.00000000"]]}}
{"stream":"btcusdt@depth@100ms","data":{"e":"depthUpdate","E":1784410687214,"s":"BTCUSDT","U":97585374599,"u":97585374609,"b":[["64690.74000000","0.01266000"],["64686.02000000","0.00310000"],["64685.82000000","0.00000000"],["58222.72000000","0.00418000"],["51753.53000000","0.00000000"]],"a":[["64704.86000000","0.00306000"]]}}
{"stream":"btcusdt@depth@100ms","data":{"e":"depthUpdate","E":1784410687314,"s":"BTCUSDT","U":97585374610,"u":97585374617,"b":[["63721.53000000","0.00030000"],["58222.72000000","0.00418000"]],"a":[["65662.30000000","0.00030000"]]}}
{"stream":"btcusdt@depth@100ms","data":{"e":"depthUpdate","E":1784410687414,"s":"BTCUSDT","U":97585374618,"u":97585374623,"b":[["58222.72000000","0.00418000"]],"a":[["64691.92000000","0.40186000"],["64704.86000000","0.00000000"]]}}
{"stream":"btcusdt@depth@100ms","data":{"e":"depthUpdate","E":1784410687514,"s":"BTCUSDT","U":97585374624,"u":97585374629,"b":[["58222.72000000","0.00399000"],["51753.53000000","0.00038000"]],"a":[["64704.86000000","0.00000000"]]}}
{"stream":"btcusdt@depth@100ms","data":{"e":"depthUpdate","E":1784410687616,"s":"BTCUSDT","U":97585374630,"u":97585374636,"b":[["58222.72000000","0.00418000"],["51753.53000000","0.00000000"]],"a":[["64704.86000000","0.00306000"],["64736.26000000","0.02372000"],["64797.45000000","0.00000000"]]}}
{"stream":"btcusdt@depth@100ms","data":{"e":"depthUpdate","E":1784410687714,"s":"BTCUSDT","U":97585374637,"u":97585374643,"b":[["64691.91000000","6.03796000"],["58222.72000000","0.00418000"]],"a":[["64691.92000000","0.40036000"],["64704.86000000","0.00000000"]]}}
{"stream":"btcusdt@depth@100ms","data":{"e":"depthUpdate","E":1784410687815,"s":"BTCUSDT","U":97585374644,"u":97585374648,"b":[["58222.72000000","0.00418000"]],"a":[["64704.86000000","0.00306000"]]}}
{"stream":"btcusdt@depth@100ms","data":{"e":"depthUpdate","E":1784410687915,"s":"BTCUSDT","U":97585374649,"u":97585374658,"b":[["64674.86000000","0.00008000"],["59509.28000000","0.00017000"],["58222.72000000","0.00418000"],["40000.00000000","261.36615000"]],"a":[["64713.68000000","2.12857000"]]}}
{"stream":"btcusdt@depth@100ms","data":{"e":"depthUpdate","E":1784410688014,"s":"BTCUSDT","U":97585374659,"u":97585374663,"b":[["64663.80000000","0.02577000"],["58222.72000000","0.00399000"],["51753.53000000","0.00038000"]],"a":[]}}
{"stream":"btcusdt@depth@100ms","data":{"e":"depthUpdate","E":1784410688114,"s":"BTCUSDT","U":97585374664,"u":97585374673,"b":[["64663.80000000","0.00000000"],["64558.92000000","0.09293000"],["58222.72000000","0.00418000"],["58222.00000000","0.71721000"]],"a":[["64704.86000000","0.00306000"],["64883.76000000","0.09247000"]]}}
{"stream":"btcusdt@depth@100ms","data":{"e":"depthUpdate","E":1784410688215,"s":"BTCUSDT","U":97585374674,"u":97585374679,"b":[["58222.72000000","0.00418000"],["51753.53000000","0.00000000"]],"a":[["64803.84000000","0.04023000"]]}}
{"stream":"btcusdt@depth@100ms","data":{"e":"depthUpdate","E":1784410688314,"s":"BTCUSDT","U":97585374680,"u":97585374698,"b":[["64686.21000000","0.00307000"],["64686.02000000","0.00000000"],["64684.49000000","0.00065000"],["63721.53000000","0.00030000"],["58222.72000000","0.00418000"],["51754.00000000","0.00000000"]],"a":[["64691.92000000","0.40044000"],["64691.93000000","0.00098000"],["64695.09000000","0.05817000"],["64695.80000000","0.18379000"],["64704.86000000","0.00000000"],["65662.30000000","0.00030000"]]}}
{"stream":"btcusdt@depth@100ms","data":{"e":"depthUpdate","E":1784410688414,"s":"BTCUSDT","U":97585374699,"u":97585374713,"b":[["59509.28000000","0.00000000"],["58222.72000000","0.00418000"]],"a":[["64695.09000000","0.05817000"],["64695.80000000","0.18397000"],["64696.51000000","2.12849000"],["64704.86000000","0.00000000"]]}}
{"stream":"btcusdt@depth@100ms","data":{"e":"depthUpdate","E":1784410688514,"s":"BTCUSDT","U":97585374714,"u":97585374718,"b":[["58222.72000000","0.00399000"],["51753.53000000","0.00038000"]],"a":[["64704.86000000","0.00306000"]]}}
{"stream":"btcusdt@depth@100ms","data":{"e":"depthUpdate","E":1784410688614,"s":"BTCUSDT","U":97585374719,"u":97585374723,"b":[["58222.72000000","0.00418000"],["51753.53000000","0.00000000"]],"a":[["64704.86000000","0.00000000"]]}}
{"stream":"btcusdt@depth@100ms","data":{"e":"depthUpdate","E":1784410688715,"s":"BTCUSDT","U":97585374724,"u":97585374731,"b":[["64686.21000000","0.00000000"],["64678.98000000","0.00309000"],["64558.92000000","0.00000000"],["58222.72000000","0.00418000"]],"a":[["64692.16000000","0.00306000"],["64883.76000000","0.00000000"]]}}
{"stream":"btcusdt@depth@100ms","data":{"e":"depthUpdate","E":1784410688815,"s":"BTCUSDT","U":97585374732,"u":97585374742,"b":[["58222.72000000","0.00418000"],["58222.71000000","0.00000000"],["58222.70000000","0.00010000"]],"a":[["64691.92000000","0.40026000"],["64692.16000000","0.00000000"],["64759.60000000","0.14650000"],["64759.61000000","0.00000000"],["64774.90000000","0.57992000"]]}}
{"stream":"btcusdt@depth@100ms","data":{"e":"depthUpdate","E":1784410688914,"s":"BTCUSDT","U":97585374743,"u":97585374755,"b":[["64674.86000000","0.00008000"],["64581.07000000","0.02421000"],["64573.87000000","0.00000000"],["58222.72000000","0.00418000"],["40000.00000000","261.36615000"]],"a":[["64692.16000000","0.00306000"],["64713.68000000","2.12857000"],["66000.00000000","62.52955000"]]}}
{"stream":"btcusdt@depth@100ms","data":{"e":"depthUpdate","E":1784410689014,"s":"BTCUSDT","U":97585374756,"u":97585374763,"b":[["64689.48000000","0.03895000"],["58222.72000000","0.00418000"],["51753.53000000","0.00038000"]],"a":[["64691.92000000","0.40034000"],["64691.93000000","0.00106000"]]}}
{"stream":"btcusdt@depth@100ms","data":{"e":"depthUpdate","E":1784410689114,"s":"BTCUSDT","U":97585374764,"u":97585374767,"b":[["64581.07000000","0.00000000"],["58222.72000000","0.00418000"]],"a":[["64692.16000000","0.00000000"]]}}
{"stream":"btcusdt@depth@100ms","data":{"e":"depthUpdate","E":1784410689214,"s":"BTCUSDT","U":97585374768,"u":97585374775,"b":[["58222.72000000","0.00418000"],["58222.00000000","0.71721000"],["51753.53000000","0.00000000"]],"a":[["77816.97000000","0.00000000"]]}}
{"stream":"btcusdt@depth@100ms","data":{"e":"depthUpdate","E":1784410689315,"s":"BTCUSDT","U":97585374776,"u":97585374787,"b":[["63721.53000000","0.00030000"],["58222.72000000","0.00418000"]],"a":[["64691.92000000","0.40026000"],["64691.93000000","0.00098000"],["64704.86000000","0.00000000"],["65662.30000000","0.00030000"]]}}
