{"stream":"btcusdt@depth@100ms","data":{"e":"depthUpdate","E":1784410629415,"s":"BTCUSDT","U":97585364523,"u":97585364530,"b":[["64557.74000000","0.00000000"],["58214.36000000","0.00418000"],["51746.00000000","0.00000000"]],"a":[["64872.90000000","0.00000000"],["64978.88000000","0.00011000"]]}}
{"stream":"btcusdt@depth@100ms","data":{"e":"depthUpdate","E":1784410629514,"s":"BTCUSDT","U":97585364531,"u":97585364535,"b":[["58214.36000000","0.00418000"],["51746.10000000","0.00038000"]],"a":[]}}
{"stream":"btcusdt@depth@100ms","data":{"e":"depthUpdate","E":1784410629614,"s":"BTCUSDT","U":97585364536,"u":97585364545,"b":[["58214.36000000","0.00418000"],["51746.10000000","0.00000000"],["51746.00000000","0.00000000"]],"a":[["64682.63000000","0.17425000"],["64693.35000000","0.00000000"],["64693.75000000","0.00773000"]]}}
{"stream":"btcusdt@depth@100ms","data":{"e":"depthUpdate","E":1784410629714,"s":"BTCUSDT","U":97585364546,"u":97585364550,"b":[["64675.00000000","0.00000000"],["64674.56000000","0.19307000"],["58214.36000000","0.00418000"]],"a":[]}}
{"stream":"btcusdt@depth@100ms","data":{"e":"depthUpdate","E":1784410629814,"s":"BTCUSDT","U":97585364551,"u":97585364563,"b":[["64675.00000000","0.08257000"],["64674.56000000","0.00000000"],["58214.36000000","0.00418000"],["58214.00000000","0.00000000"],["40000.00000000","261.36615000"]],"a":[["64748.67000000","0.00000000"],["64748.94000000","0.00000000"],["64759.61000000","0.57994000"]]}}
{"stream":"btcusdt@depth@100ms","data":{"e":"depthUpdate","E":1784410629915,"s":"BTCUSDT","U":97585364564,"u":97585364565,"b":[["58214.36000000","0.00418000"]],"a":[]}}
{"stream":"btcusdt@depth@100ms","data":{"e":"depthUpdate","E":1784410630014,"s":"BTCUSDT","U":97585364566,"u":97585364574,"b":[["63712.38000000","0.00030000"],["58214.36000000","0.00418000"],["51746.10000000","0.00038000"]],"a":[["65652.87000000","0.00030000"]]}}
{"stream":"btcusdt@depth@100ms","data":{"e":"depthUpdate","E":1784410630114,"s":"BTCUSDT","U":97585364575,"u":97585364585,"b":[["64681.42000000","0.00791000"],["64680.83000000","0.00773000"],["64665.57000000","0.00008000"],["58214.36000000","0.00418000"]],"a":[["64693.14000000","0.00773000"],["64693.75000000","0.00000000"],["64704.39000000","0.00008000"],["64720.11000000","0.70000000"],["64752.11000000","0.00822000"]]}}
{"stream":"btcusdt@depth@100ms","data":{"e":"depthUpdate","E":1784410630214,"s":"BTCUSDT","U":97585364586,"u":97585364600,"b":[["64682.62000000","4.09013000"],["64681.39000000","0.05049000"],["64675.00000000","0.07935000"],["64674.56000000","0.00000000"],["59509.29000000","0.00017000"],["58214.36000000","0.00418000"],["58214.35000000","0.00265000"],["51746.10000000","0.00000000"]],"a":[["64710.09000000","0.00000000"]]}}
{"stream":"btcusdt@depth@100ms","data":{"e":"depthUpdate","E":1784410630314,"s":"BTCUSDT","U":97585364601,"u":97585364613,"b":[["64675.00000000","0.07748000"],["64674.56000000","0.00000000"],["64670.95000000","0.00000000"],["64669.46000000","0.53061000"],["58214.36000000","0.00418000"],["51746.00000000","0.00000000"]],"a":[["64682.63000000","0.17433000"],["64685.56000000","0.00009000"],["64685.57000000","0.18381000"],["64686.19000000","0.00000000"]]}}
{"stream":"btcusdt@depth@100ms","data":{"e":"depthUpdate","E":1784410630415,"s":"BTCUSDT","U":97585364614,"u":97585364625,"b":[["64665.75000000","0.00008000"],["58214.36000000","0.00399000"]],"a":[["64684.00000000","0.02931000"],["64685.57000000","0.18399000"],["64687.73000000","0.12390000"]]}}
{"stream":"btcusdt@depth@100ms","data":{"e":"depthUpdate","E":1784410630514,"s":"BTCUSDT","U":97585364626,"u":97585364629,"b":[["58214.36000000","0.00418000"],["51746.10000000","0.00038000"]],"a":[]}}
{"stream":"btcusdt@depth@100ms","data":{"e":"depthUpdate","E":1784410630614,"s":"BTCUSDT","U":97585364630,"u":97585364636,"b":[["58214.36000000","0.00418000"],["51746.10000000","0.00000000"]],"a":[["64682.63000000","0.17441000"],["64682.64000000","0.00098000"]]}}
{"stream":"btcusdt@depth@100ms","data":{"e":"depthUpdate","E":1784410630714,"s":"BTCUSDT","U":97585364637,"u":97585364640,"b":[["58214.36000000","0.00418000"]],"a":[]}}
{"stream":"btcusdt@depth@100ms","data":{"e":"depthUpdate","E":1784410630814,"s":"BTCUSDT","U":97585364641,"u":97585364649,"b":[["64666.20000000","0.34689000"],["59509.29000000","0.00000000"],["58214.36000000","0.00418000"],["51746.10000000","0.00000000"]],"a":[["64748.67000000","0.15137000"]]}}
{"stream":"btcusdt@depth@100ms","data":{"e":"depthUpdate","E":1784410630914,"s":"BTCUSDT","U":97585364650,"u":97585364657,"b":[["58214.36000000","0.00399000"],["58214.00000000","0.00000000"],["40000.00000000","261.36615000"]],"a":[["64690.54000000","0.01253000"]]}}
{"stream":"btcusdt@depth@100ms","data":{"e":"depthUpdate","E":1784410631014,"s":"BTCUSDT","U":97585364658,"u":97585364674,"b":[["64675.00000000","0.00000000"],["64674.56000000","0.19019000"],["63712.38000000","0.00030000"],["58214.36000000","0.00418000"],["51746.10000000","0.00038000"],["51746.00000000","0.00000000"]],"a":[["65652.87000000","0.00030000"]]}}
{"stream":"btcusdt@depth@100ms","data":{"e":"depthUpdate","E":1784410631114,"s":"BTCUSDT","U":97585364675,"u":97585364682,"b":[["64675.00000000","0.07764000"],["64674.56000000","0.00000000"],["64665.57000000","0.00000000"],["58214.36000000","0.00418000"],["33000.00000000","32.31996000"]],"a":[["64704.39000000","0.00000000"]]}}
{"stream":"btcusdt@depth@100ms","data":{"e":"depthUpdate","E":1784410631215,"s":"BTCUSDT","U":97585364683,"u":97585364692,"b":[["64682.62000000","4.08454000"],["64665.57000000","0.00008000"],["58214.36000000","0.00418000"],["58214.35000000","0.00255000"],["58214.34000000","0.00010000"],["51746.10000000","0.00000000"]],"a":[["64704.39000000","0.00008000"]]}}
{"stream":"btcusdt@depth@100ms","data":{"e":"depthUpdate","E":1784410631314,"s":"BTCUSDT","U":97585364693,"u":97585364696,"b":[["58214.36000000","0.00418000"]],"a":[]}}
{"stream":"btcusdt@depth@100ms","data":{"e":"depthUpdate","E":1784410631415,"s":"BTCUSDT","U":97585364697,"u":97585364699,"b":[["58214.36000000","0.00399000"]],"a":[]}}
{"stream":"btcusdt@depth@100ms","data":{"e":"depthUpdate","E":1784410631515,"s":"BTCUSDT","U":97585364700,"u":97585364704,"b":[["63000.00000000","22.91990000"],["58214.36000000","0.00418000"],["51746.10000000","0.00038000"]],"a":[]}}
{"stream":"btcusdt@depth@100ms","data":{"e":"depthUpdate","E":1784410631614,"s":"BTCUSDT","U":97585364705,"u":97585364714,"b":[["64682.62000000","4.08439000"],["64613.37000000","0.00000000"],["58214.36000000","0.00418000"],["58214.34000000","0.00000000"],["51746.10000000","0.00000000"]],"a":[["64755.39000000","2.36285000"],["64763.87000000","0.00000000"]]}}
{"stream":"btcusdt@depth@100ms","data":{"e":"depthUpdate","E":1784410631714,"s":"BTCUSDT","U":97585364715,"u":97585364720,"b":[["64681.42000000","0.00018000"],["64680.84000000","0.00773000"],["58214.36000000","0.00418000"]],"a":[["77816.97000000","0.00000000"]]}}
{"stream":"btcusdt@depth@100ms","data":{"e":"depthUpdate","E":1784410631814,"s":"BTCUSDT","U":97585364721,"u":97585364740,"b":[["64681.85000000","0.01248000"],["64681.42000000","0.00000000"],["64681.39000000","0.05049000"],["64680.84000000","0.00791000"],["64680.82000000","0.00000000"],["58214.36000000","0.00418000"]],"a":[["64682.63000000","0.17408000"],["64685.56000000","0.00018000"],["71150.89000000","0.00008000"]]}}
{"stream":"btcusdt@depth@100ms","data":{"e":"depthUpdate","E":1784410631915,"s":"BTCUSDT","U":97585364741,"u":97585364751,"b":[["58214.36000000","0.00418000"],["58214.00000000","0.00000000"],["51746.10000000","0.00000000"],["40000.00000000","261.36615000"]],"a":[["71150.89000000","0.00000000"]]}}
{"stream":"btcusdt@depth@100ms","data":{"e":"depthUpdate","E":1784410632014,"s":"BTCUSDT","U":97585364752,"u":97585364759,"b":[["64681.41000000","0.00773000"],["64680.84000000","0.00018000"],["63712.38000000","0.00030000"],["58214.36000000","0.00418000"],["51746.10000000","0.00038000"]],"a":[["65652.87000000","0.00030000"]]}}
{"stream":"btcusdt@depth@100ms","data":{"e":"depthUpdate","E":1784410632114,"s":"BTCUSDT","U":97585364760,"u":97585364779,"b":[["64682.62000000","4.08312000"],["64681.85000000","0.01248000"],["64681.41000000","0.00791000"],["64681.39000000","0.05049000"],["64680.84000000","0.00000000"],["58214.36000000","0.00418000"],["58214.35000000","0.00265000"]],"a":[["64699.70000000","0.07768000"],["64699.99000000","0.00000000"]]}}
{"stream":"btcusdt@depth@100ms","data":{"e":"depthUpdate","E":1784410632216,"s":"BTCUSDT","U":97585364780,"u":97585364787,"b":[["64665.57000000","0.00008000"],["58214.36000000","0.00418000"],["51746.10000000","0.00000000"]],"a":[["64704.39000000","0.00008000"]]}}
{"stream":"btcusdt@depth@100ms","data":{"e":"depthUpdate","E":1784410632314,"s":"BTCUSDT","U":97585364788,"u":97585364793,"b":[["58214.36000000","0.00418000"],["51746.00000000","0.00000000"]],"a":[]}}
{"stream":"btcusdt@depth@100ms","data":{"e":"depthUpdate","E":1784410632414,"s":"BTCUSDT","U":97585364794,"u":97585364797,"b":[["58214.36000000","0.00418000"]],"a":[]}}
{"stream":"btcusdt@depth@100ms","data":{"e":"depthUpdate","E":1784410632514,"s":"BTCUSDT","U":97585364798,"u":97585364806,"b":[["64681.42000000","0.00773000"],["64680.83000000","0.00000000"],["64641.01000000","0.00000000"],["64629.02000000","0.00773000"],["64613.37000000","1.18470000"],["64564.29000000","0.00000000"],["64540.24000000","0.01872000"],["58214.36000000","0.00418000"],["51746.10000000","0.00038000"]],"a":[["64729.99000000","0.00000000"]]}}
{"stream":"btcusdt@depth@100ms","data":{"e":"depthUpdate","E":1784410632614,"s":"BTCUSDT","U":97585364807,"u":97585364821,"b":[["64681.85000000","0.01248000"],["64681.42000000","0.00791000"],["64681.39000000","0.05031000"],["58214.36000000","0.00418000"],["51746.10000000","0.00000000"]],"a":[["64691.51000000","0.00047000"],["64692.32000000","0.00048000"]]}}
{"stream":"btcusdt@depth@100ms","data":{"e":"depthUpdate","E":1784410632714,"s":"BTCUSDT","U":97585364822,"u":97585364827,"b":[["64662.79000000","0.00560000"],["64648.12000000","0.02477000"],["64633.45000000","0.00000000"],["64618.78000000","0.00561000"],["64604.11000000","0.00000000"],["64589.44000000","0.00000000"],["64574.77000000","0.00000000"],["64560.10000000","0.00000000"],["58214.36000000","0.00418000"]],"a":[["64692.12000000","0.00000000"],["64706.80000000","0.00482000"],["64717.98000000","0.00772000"],["64721.47000000","0.00000000"],["64736.14000000","0.00000000"],["64750.81000000","0.00559000"],["64765.48000000","0.00000000"],["64780.15000000","0.00000000"],["64794.82000000","0.00559000"],["64809.49000000","0.00000000"],["64824.16000000","0.00000000"]]}}
{"stream":"btcusdt@depth@100ms","data":{"e":"depthUpdate","E":1784410632814,"s":"BTCUSDT","U":97585364828,"u":97585364837,"b":[["64682.62000000","4.06903000"],["64660.48000000","0.00000000"],["64659.09000000","0.10000000"],["58214.36000000","0.00418000"],["58214.35000000","0.00255000"],["58214.34000000","0.00010000"]],"a":[["64682.63000000","0.17147000"]]}}
{"stream":"btcusdt@depth@100ms","data":{"e":"depthUpdate","E":1784410632914,"s":"BTCUSDT","U":97585364838,"u":97585364856,"b":[["58214.36000000","0.00418000"],["40000.00000000","261.36615000"]],"a":[["64707.99000000","0.02000000"],["64708.63000000","0.02008000"],["64708.66000000","0.02000000"],["64710.49000000","0.02000000"],["64711.80000000","0.02000000"],["64711.81000000","0.02000000"],["64741.26000000","0.00000000"],["64741.27000000","0.00000000"],["64741.61000000","0.00382000"],["64741.91000000","0.00000000"],["64741.94000000","0.00000000"],["64743.78000000","0.00000000"],["64745.09000000","0.00000000"]]}}
{"stream":"btcusdt@depth@100ms","data":{"e":"depthUpdate","E":1784410633015,"s":"BTCUSDT","U":97585364857,"u":97585364869,"b":[["64682.62000000","4.03809000"],["64681.42000000","0.00018000"],["64680.82000000","0.00773000"],["63712.38000000","0.00030000"],["58214.36000000","0.00399000"],["58214.00000000","0.00000000"],["51746.10000000","0.00038000"]],"a":[["64691.32000000","0.00191000"],["65652.87000000","0.00030000"]]}}
{"stream":"btcusdt@depth@100ms","data":{"e":"depthUpdate","E":1784410633114,"s":"BTCUSDT","U":97585364870,"u":97585364880,"b":[["64681.85000000","0.01248000"],["64681.42000000","0.00000000"],["64681.39000000","0.05049000"],["58214.36000000","0.00418000"]],"a":[]}}
{"stream":"btcusdt@depth@100ms","data":{"e":"depthUpdate","E":1784410633214,"s":"BTCUSDT","U":97585364881,"u":97585364893,"b":[["64682.62000000","4.03801000"],["64665.57000000","0.00008000"],["64662.96000000","0.00938000"],["64650.31000000","0.00000000"],["58214.36000000","0.00418000"],["58214.34000000","0.00000000"],["51746.10000000","0.00000000"]],"a":[["64682.63000000","0.17216000"],["64704.39000000","0.00008000"]]}}
{"stream":"btcusdt@depth@100ms","data":{"e":"depthUpdate","E":1784410633315,"s":"BTCUSDT","U":97585364894,"u":97585364906,"b":[["64681.41000000","0.00018000"],["64680.83000000","0.00773000"],["64675.00000000","0.00000000"],["64674.56000000","0.16208000"],["64622.65000000","0.00000000"],["64613.37000000","0.00000000"],["64611.26000000","0.53840000"],["64611.25000000","1.18506000"],["64610.91000000","0.00000000"],["64559.09000000","0.00000000"],["58214.36000000","0.00418000"]],"a":[["64692.96000000","0.00773000"],["64693.41000000","0.00000000"]]}}
{"stream":"btcusdt@depth@100ms","data":{"e":"depthUpdate","E":1784410633414,"s":"BTCUSDT","U":97585364907,"u":97585364924,"b":[["64681.85000000","0.01248000"],["64681.41000000","0.00000000"],["64681.39000000","0.05049000"],["64680.83000000","0.00791000"],["64622.65000000","0.00382000"],["64559.09000000","0.00154000"],["58214.36000000","0.00418000"]],"a":[]}}
{"stream":"btcusdt@depth@100ms","data":{"e":"depthUpdate","E":1784410633514,"s":"BTCUSDT","U":97585364925,"u":97585364931,"b":[["64673.79000000","0.00000000"],["64662.79000000","0.00000000"],["64651.79000000","0.00000000"],["64640.78000000","0.00000000"],["64629.78000000","0.00000000"],["64618.78000000","0.00000000"],["64607.78000000","0.00000000"],["64596.77000000","0.00000000"],["58214.36000000","0.00399000"],["51746.10000000","0.00038000"]],"a":[["64684.53000000","0.00248000"],["64695.79000000","0.00000000"],["64706.80000000","0.00000000"],["64717.80000000","0.00000000"],["64728.81000000","0.00000000"],["64739.81000000","0.00000000"],["64750.81000000","0.00000000"],["64761.81000000","0.00000000"],["64772.82000000","0.00000000"],["64783.82000000","0.00000000"],["64794.82000000","0.00000000"],["64805.82000000","0.00000000"]]}}
{"stream":"btcusdt@depth@100ms","data":{"e":"depthUpdate","E":1784410633615,"s":"BTCUSDT","U":97585364932,"u":97585364935,"b":[["58214.36000000","0.00418000"],["51746.10000000","0.00000000"]],"a":[]}}
{"stream":"btcusdt@depth@100ms","data":{"e":"depthUpdate","E":1784410633714,"s":"BTCUSDT","U":97585364936,"u":97585364940,"b":[["64540.24000000","0.02746000"],["58214.36000000","0.00418000"]],"a":[]}}
{"stream":"btcusdt@depth@100ms","data":{"e":"depthUpdate","E":1784410633815,"s":"BTCUSDT","U":97585364941,"u":97585364945,"b":[["64554.99000000","0.00874000"],["58214.36000000","0.00418000"]],"a":[]}}
{"stream":"btcusdt@depth@100ms","data":{"e":"depthUpdate","E":1784410633914,"s":"BTCUSDT","U":97585364946,"u":97585364952,"b":[["64569.73000000","0.00874000"],["58214.36000000","0.00418000"],["40000.00000000","261.36615000"]],"a":[]}}
{"stream":"btcusdt@depth@100ms","data":{"e":"depthUpdate","E":1784410634014,"s":"BTCUSDT","U":97585364953,"u":97585364965,"b":[["64681.41000000","0.00773000"],["64680.83000000","0.00018000"],["64675.00000000","0.08524000"],["64674.56000000","0.00000000"],["64584.48000000","0.00873000"],["64557.67000000","0.09294000"],["63712.38000000","0.00030000"],["58214.36000000","0.00418000"],["51746.10000000","0.00038000"]],"a":[["65652.87000000","0.00030000"]]}}
{"stream":"btcusdt@depth@100ms","data":{"e":"depthUpdate","E":1784410634114,"s":"BTCUSDT","U":97585364966,"u":97585364982,"b":[["64681.85000000","0.01248000"],["64681.41000000","0.00791000"],["64681.39000000","0.05049000"],["64680.83000000","0.00000000"],["64599.22000000","0.00882000"],["58214.36000000","0.00418000"],["58214.00000000","0.00000000"]],"a":[]}}
{"stream":"btcusdt@depth@100ms","data":{"e":"depthUpdate","E":1784410634214,"s":"BTCUSDT","U":97585364983,"u":97585365012,"b":[["64682.62000000","4.03401000"],["64674.12000000","0.00400000"],["64667.65000000","0.00400000"],["64665.57000000","0.00000000"],["64661.18000000","0.00400000"],["64654.71000000","0.01549000"],["64613.97000000","0.00873000"],["64613.37000000","1.18470000"],["64611.26000000","0.00000000"],["64611.25000000","0.00036000"],["58214.36000000","0.00418000"],["51746.10000000","0.00000000"]],"a":[["64682.63000000","0.17224000"],["64682.64000000","0.00106000"],["64693.53000000","0.00000000"],["64700.00000000","0.81300000"],["64704.39000000","0.00000000"],["64706.47000000","0.00400000"],["64712.94000000","0.00800000"],["64876.64000000","0.09248000"]]}}
{"stream":"btcusdt@depth@100ms","data":{"e":"depthUpdate","E":1784410634317,"s":"BTCUSDT","U":97585365013,"u":97585365024,"b":[["64665.57000000","0.00008000"],["64628.72000000","0.00873000"],["64577.90000000","0.00000000"],["58214.36000000","0.00418000"],["51746.00000000","0.00000000"]],"a":[["64704.39000000","0.00008000"]]}}
{"stream":"btcusdt@depth@100ms","data":{"e":"depthUpdate","E":1784410634414,"s":"BTCUSDT","U":97585365025,"u":97585365031,"b":[["64643.46000000","0.00873000"],["64545.61000000","0.00000000"],["58214.36000000","0.00418000"]],"a":[["64692.45000000","0.00773000"],["64693.14000000","0.00000000"]]}}
{"stream":"btcusdt@depth@100ms","data":{"e":"depthUpdate","E":1784410634514,"s":"BTCUSDT","U":97585365032,"u":97585365038,"b":[["64658.21000000","0.00872000"],["64577.11000000","0.00560000"],["58214.36000000","0.00418000"],["51746.10000000","0.00038000"]],"a":[]}}
{"stream":"btcusdt@depth@100ms","data":{"e":"depthUpdate","E":1784410634614,"s":"BTCUSDT","U":97585365039,"u":97585365044,"b":[["64672.95000000","0.00872000"],["64588.16000000","0.00560000"],["58214.36000000","0.00418000"],["51746.10000000","0.00000000"]],"a":[["64682.63000000","0.17235000"]]}}
{"stream":"btcusdt@depth@100ms","data":{"e":"depthUpdate","E":1784410634714,"s":"BTCUSDT","U":97585365045,"u":97585365050,"b":[["64599.22000000","0.01442000"],["58214.36000000","0.00418000"]],"a":[["64702.45000000","0.00872000"]]}}
{"stream":"btcusdt@depth@100ms","data":{"e":"depthUpdate","E":1784410634814,"s":"BTCUSDT","U":97585365051,"u":97585365058,"b":[["64610.28000000","0.00560000"],["64557.67000000","0.00000000"],["58214.36000000","0.00418000"]],"a":[["64717.19000000","0.00872000"],["64876.64000000","0.00000000"]]}}
{"stream":"btcusdt@depth@100ms","data":{"e":"depthUpdate","E":1784410634914,"s":"BTCUSDT","U":97585365059,"u":97585365066,"b":[["64621.34000000","0.00560000"],["58214.36000000","0.00418000"],["40000.00000000","261.36615000"]],"a":[["64731.94000000","0.00871000"]]}}
{"stream":"btcusdt@depth@100ms","data":{"e":"depthUpdate","E":1784410635014,"s":"BTCUSDT","U":97585365067,"u":97585365082,"b":[["64632.40000000","0.00560000"],["64613.37000000","0.00000000"],["64611.25000000","1.18506000"],["64232.63000000","0.00011000"],["63712.38000000","0.00030000"],["58214.36000000","0.00418000"],["51746.10000000","0.00038000"]],"a":[["64692.45000000","0.00000000"],["64692.96000000","0.00000000"],["64693.14000000","0.00773000"],["64693.35000000","0.00773000"],["64746.68000000","0.00871000"],["65652.87000000","0.00030000"]]}}
{"stream":"btcusdt@depth@100ms","data":{"e":"depthUpdate","E":1784410635114,"s":"BTCUSDT","U":97585365083,"u":97585365091,"b":[["64674.88000000","0.00000000"],["64643.46000000","0.01432000"],["64611.26000000","0.54007000"],["58214.36000000","0.00399000"],["58214.00000000","0.00000000"]],"a":[["64761.43000000","0.00871000"]]}}
{"stream":"btcusdt@depth@100ms","data":{"e":"depthUpdate","E":1784410635214,"s":"BTCUSDT","U":97585365092,"u":97585365101,"b":[["64682.62000000","4.03092000"],["64654.52000000","0.00559000"],["58214.36000000","0.00418000"],["58214.35000000","0.00265000"],["51746.10000000","0.00000000"]],"a":[["64686.58000000","0.00175000"],["64689.89000000","0.00000000"],["64776.18000000","0.00871000"]]}}
{"stream":"btcusdt@depth@100ms","data":{"e":"depthUpdate","E":1784410635315,"s":"BTCUSDT","U":97585365102,"u":97585365114,"b":[["64682.62000000","4.03036000"],["64665.58000000","0.00559000"],["64665.57000000","0.00008000"],["64613.03000000","0.00436000"],["64600.19000000","0.00000000"],["64579.13000000","0.00160000"],["58214.36000000","0.00418000"]],"a":[["64704.39000000","0.00008000"],["64790.92000000","0.00871000"]]}}
{"stream":"btcusdt@depth@100ms","data":{"e":"depthUpdate","E":1784410635414,"s":"BTCUSDT","U":97585365115,"u":97585365125,"b":[["64676.64000000","0.00559000"],["64546.84000000","0.00160000"],["58214.36000000","0.00418000"],["51746.00000000","0.00000000"]],"a":[["64805.67000000","0.00870000"]]}}
{"stream":"btcusdt@depth@100ms","data":{"e":"depthUpdate","E":1784410635514,"s":"BTCUSDT","U":97585365126,"u":97585365132,"b":[["58214.36000000","0.00418000"],["51746.10000000","0.00038000"]],"a":[["64698.76000000","0.00559000"],["64820.41000000","0.00870000"]]}}
{"stream":"btcusdt@depth@100ms","data":{"e":"depthUpdate","E":1784410635616,"s":"BTCUSDT","U":97585365133,"u":97585365141,"b":[["64549.16000000","0.00000000"],["58214.36000000","0.00399000"],["51746.10000000","0.00000000"],["51746.00000000","0.00000000"]],"a":[["64709.82000000","0.00559000"],["64835.16000000","0.00870000"]]}}
{"stream":"btcusdt@depth@100ms","data":{"e":"depthUpdate","E":1784410635714,"s":"BTCUSDT","U":97585365142,"u":97585365146,"b":[["64559.01000000","0.02422000"],["58214.36000000","0.00418000"]],"a":[["64720.88000000","0.00559000"]]}}
{"stream":"btcusdt@depth@100ms","data":{"e":"depthUpdate","E":1784410635814,"s":"BTCUSDT","U":97585365147,"u":97585365152,"b":[["59509.29000000","0.00017000"],["58214.36000000","0.00418000"]],"a":[["64731.94000000","0.01430000"]]}}
{"stream":"btcusdt@depth@100ms","data":{"e":"depthUpdate","E":1784410635914,"s":"BTCUSDT","U":97585365153,"u":97585365166,"b":[["64613.37000000","1.18470000"],["64611.26000000","0.00000000"],["64611.25000000","0.00036000"],["64559.01000000","0.00000000"],["64550.24000000","0.02422000"],["58214.36000000","0.00418000"],["51746.00000000","0.00000000"],["40000.00000000","261.36615000"]],"a":[["64743.00000000","0.00559000"]]}}
{"stream":"btcusdt@depth@100ms","data":{"e":"depthUpdate","E":1784410636014,"s":"BTCUSDT","U":97585365167,"u":97585365177,"b":[["64550.24000000","0.00000000"],["63712.38000000","0.00030000"],["58214.36000000","0.00418000"],["51746.10000000","0.00038000"]],"a":[["64754.06000000","0.00558000"],["65652.87000000","0.00030000"]]}}
{"stream":"btcusdt@depth@100ms","data":{"e":"depthUpdate","E":1784410636114,"s":"BTCUSDT","U":97585365178,"u":97585365185,"b":[["64675.00000000","0.08416000"],["64674.56000000","0.00000000"],["64610.91000000","0.18466000"],["58214.36000000","0.00399000"],["33000.00000000","32.32056000"]],"a":[["64765.12000000","0.00558000"]]}}
{"stream":"btcusdt@depth@100ms","data":{"e":"depthUpdate","E":1784410636214,"s":"BTCUSDT","U":97585365186,"u":97585365196,"b":[["64682.62000000","4.02728000"],["64669.69000000","0.00311000"],["58214.36000000","0.00418000"],["58214.00000000","0.00000000"],["51746.10000000","0.00000000"],["33000.00000000","32.31996000"]],"a":[["64776.18000000","0.01429000"],["64794.12000000","0.02422000"],["64852.20000000","0.00000000"]]}}
{"stream":"btcusdt@depth@100ms","data":{"e":"depthUpdate","E":1784410636314,"s":"BTCUSDT","U":97585365197,"u":97585365208,"b":[["64665.57000000","0.00008000"],["58214.36000000","0.00418000"],["51746.00000000","0.00000000"]],"a":[["64684.53000000","0.00000000"],["64704.39000000","0.00008000"],["64787.24000000","0.00558000"]]}}
{"stream":"btcusdt@depth@100ms","data":{"e":"depthUpdate","E":1784410636414,"s":"BTCUSDT","U":97585365209,"u":97585365218,"b":[["64468.08000000","0.02422000"],["64415.31000000","0.00000000"],["59509.29000000","0.00000000"],["58214.36000000","0.00418000"]],"a":[["64794.12000000","0.00000000"],["64798.29000000","0.00558000"],["64855.31000000","0.02422000"]]}}
{"stream":"btcusdt@depth@100ms","data":{"e":"depthUpdate","E":1784410636514,"s":"BTCUSDT","U":97585365219,"u":97585365238,"b":[["64681.93000000","0.00791000"],["64680.82000000","0.00009000"],["58214.36000000","0.00418000"],["51746.10000000","0.00038000"]],"a":[["64682.63000000","0.17219000"],["64682.64000000","0.00090000"],["64685.89000000","0.00000000"],["64685.90000000","0.00034000"],["64686.19000000","0.00009000"],["64686.20000000","0.11026000"],["64688.50000000","0.04000000"],["64693.14000000","0.00000000"],["64693.35000000","0.00000000"],["64693.75000000","0.01546000"]]}}
{"stream":"btcusdt@depth@100ms","data":{"e":"depthUpdate","E":1784410636614,"s":"BTCUSDT","U":97585365239,"u":97585365259,"b":[["64682.61000000","0.16176000"],["64681.93000000","0.00809000"],["64681.39000000","0.05031000"],["58214.36000000","0.00418000"],["51746.10000000","0.00000000"]],"a":[["64685.80000000","0.05810000"],["64685.90000000","0.00016000"],["64687.73000000","0.12408000"]]}}
{"stream":"btcusdt@depth@100ms","data":{"e":"depthUpdate","E":1784410636714,"s":"BTCUSDT","U":97585365260,"u":97585365265,"b":[["64613.37000000","0.00000000"],["64611.25000000","1.18506000"],["58214.36000000","0.00418000"]],"a":[["64710.65000000","0.00070000"],["64855.31000000","0.00000000"]]}}
{"stream":"btcusdt@depth@100ms","data":{"e":"depthUpdate","E":1784410636814,"s":"BTCUSDT","U":97585365266,"u":97585365277,"b":[["64666.20000000","0.00000000"],["64654.90000000","0.02577000"],["64646.35000000","0.00000000"],["58214.36000000","0.00428000"],["51746.10000000","0.00000000"]],"a":[["64702.40000000","0.00200000"],["64719.77000000","0.00000000"]]}}
{"stream":"btcusdt@depth@100ms","data":{"e":"depthUpdate","E":1784410636915,"s":"BTCUSDT","U":97585365278,"u":97585365285,"b":[["64654.90000000","0.00000000"],["58214.36000000","0.00418000"],["40000.00000000","261.36615000"]],"a":[]}}
{"stream":"btcusdt@depth@100ms","data":{"e":"depthUpdate","E":1784410637014,"s":"BTCUSDT","U":97585365286,"u":97585365297,"b":[["64681.93000000","0.00036000"],["64681.42000000","0.00773000"],["63712.38000000","0.00030000"],["58214.36000000","0.00418000"],["51746.10000000","0.00038000"]],"a":[["64690.10000000","0.00250000"],["64705.05000000","0.00250000"],["65652.87000000","0.00030000"]]}}
{"stream":"btcusdt@depth@100ms","data":{"e":"depthUpdate","E":1784410637116,"s":"BTCUSDT","U":97585365298,"u":97585365321,"b":[["64682.61000000","0.16176000"],["64681.93000000","0.00018000"],["64681.85000000","0.01248000"],["64681.42000000","0.00791000"],["64666.23000000","0.34592000"],["64646.83000000","0.67295000"],["64611.26000000","0.54007000"],["64610.91000000","0.00000000"],["64599.81000000","0.00250000"],["64584.76000000","0.00250000"],["58214.36000000","0.00418000"]],"a":[["64702.70000000","0.33528000"],["64722.11000000","0.66916000"]]}}
{"stream":"btcusdt@depth@100ms","data":{"e":"depthUpdate","E":1784410637215,"s":"BTCUSDT","U":97585365322,"u":97585365330,"b":[["64682.62000000","4.02713000"],["58214.36000000","0.00399000"],["58214.35000000","0.00255000"],["58214.34000000","0.00010000"],["58214.00000000","0.00020000"],["51746.10000000","0.00000000"]],"a":[["64727.63000000","0.02519000"],["64734.32000000","0.00000000"]]}}
{"stream":"btcusdt@depth@100ms","data":{"e":"depthUpdate","E":1784410637314,"s":"BTCUSDT","U":97585365331,"u":97585365335,"b":[["64665.57000000","0.00000000"],["58214.36000000","0.00418000"],["58214.00000000","0.00000000"]],"a":[["64704.39000000","0.00000000"]]}}
{"stream":"btcusdt@depth@100ms","data":{"e":"depthUpdate","E":1784410637415,"s":"BTCUSDT","U":97585365336,"u":97585365343,"b":[["64665.57000000","0.00008000"],["58214.36000000","0.00418000"],["51746.00000000","0.00000000"]],"a":[["64704.39000000","0.00008000"]]}}
{"stream":"btcusdt@depth@100ms","data":{"e":"depthUpdate","E":1784410637515,"s":"BTCUSDT","U":97585365344,"u":97585365354,"b":[["64682.62000000","4.95461000"],["64468.08000000","0.00000000"],["64415.31000000","0.02422000"],["58214.36000000","0.00418000"],["51746.10000000","0.00038000"]],"a":[]}}
{"stream":"btcusdt@depth@100ms","data":{"e":"depthUpdate","E":1784410637614,"s":"BTCUSDT","U":97585365355,"u":97585365362,"b":[["64613.37000000","1.18470000"],["64611.25000000","0.00036000"],["64589.35000000","0.00000000"],["58214.36000000","0.00418000"],["51746.10000000","0.00000000"]],"a":[["64763.33000000","0.00000000"]]}}
{"stream":"btcusdt@depth@100ms","data":{"e":"depthUpdate","E":1784410637714,"s":"BTCUSDT","U":97585365363,"u":97585365375,"b":[["64611.26000000","0.00000000"],["64588.25000000","0.00111000"],["58214.36000000","0.00399000"]],"a":[["64682.63000000","0.17219000"],["64690.26000000","0.00000000"],["64690.28000000","0.00009000"],["64695.03000000","0.00000000"],["64698.59000000","0.58009000"],["64708.73000000","0.06724000"],["64742.36000000","0.00111000"]]}}
{"stream":"btcusdt@depth@100ms","data":{"e":"depthUpdate","E":1784410637814,"s":"BTCUSDT","U":97585365376,"u":97585365387,"b":[["58214.36000000","0.00418000"],["51746.00000000","0.00000000"]],"a":[["64693.14000000","0.00773000"],["64693.75000000","0.00773000"]]}}
{"stream":"btcusdt@depth@100ms","data":{"e":"depthUpdate","E":1784410637914,"s":"BTCUSDT","U":97585365388,"u":97585365401,"b":[["64622.65000000","0.00000000"],["64559.09000000","0.00000000"],["58214.36000000","0.00418000"],["58214.34000000","0.00000000"],["51746.10000000","0.00000000"],["40000.00000000","261.36615000"]],"a":[["64682.63000000","0.16910000"],["64692.94000000","0.00000000"],["64698.58000000","0.58010000"],["64698.59000000","0.00000000"]]}}
{"stream":"btcusdt@depth@100ms","data":{"e":"depthUpdate","E":1784410638014,"s":"BTCUSDT","U":97585365402,"u":97585365418,"b":[["64682.62000000","5.41826000"],["64676.29000000","0.00000000"],["64676.23000000","0.15460000"],["64622.65000000","0.00382000"],["64559.09000000","0.00154000"],["63712.38000000","0.00030000"],["58214.36000000","0.00418000"],["51746.10000000","0.00038000"]],"a":[["64688.75000000","0.00000000"],["64688.78000000","0.08122000"],["65652.87000000","0.00030000"]]}}
{"stream":"btcusdt@depth@100ms","data":{"e":"depthUpdate","E":1784410638115,"s":"BTCUSDT","U":97585365419,"u":97585365431,"b":[["64682.62000000","5.41722000"],["64677.41000000","0.09958000"],["64610.91000000","0.18466000"],["58214.36000000","0.00418000"]],"a":[["64682.63000000","0.16902000"],["64688.01000000","0.13336000"],["64755.38000000","0.71355000"],["64779.84000000","0.20608000"],["64799.45000000","0.30713000"]]}}
{"stream":"btcusdt@depth@100ms","data":{"e":"depthUpdate","E":1784410638214,"s":"BTCUSDT","U":97585365432,"u":97585365435,"b":[["58214.36000000","0.00399000"],["51746.10000000","0.00000000"]],"a":[]}}
{"stream":"btcusdt@depth@100ms","data":{"e":"depthUpdate","E":1784410638314,"s":"BTCUSDT","U":97585365436,"u":97585365456,"b":[["64682.62000000","5.41607000"],["64622.65000000","0.00000000"],["64559.09000000","0.00000000"],["58214.36000000","0.00418000"],["58214.00000000","0.00000000"],["51746.00000000","0.00000000"]],"a":[["64685.56000000","0.00000000"],["64685.57000000","0.00018000"],["64685.67000000","0.00000000"],["64686.19000000","0.00018000"],["64687.10000000","0.00009000"],["64693.14000000","0.00000000"],["64693.48000000","0.00773000"],["64718.54000000","0.00009000"],["64720.11000000","0.00000000"]]}}
{"stream":"btcusdt@depth@100ms","data":{"e":"depthUpdate","E":1784410638414,"s":"BTCUSDT","U":97585365457,"u":97585365481,"b":[["64682.62000000","5.41731000"],["64665.57000000","0.00008000"],["64664.21000000","0.89695000"],["64657.32000000","0.89925000"],["64656.92000000","0.00000000"],["64622.65000000","0.00382000"],["64559.09000000","0.00154000"],["58214.36000000","0.00418000"]],"a":[["64682.63000000","0.16894000"],["64684.00000000","0.02931000"],["64684.63000000","0.00248000"],["64685.57000000","0.00000000"],["64688.00000000","0.02718000"],["64704.39000000","0.00008000"]]}}
{"stream":"btcusdt@depth@100ms","data":{"e":"depthUpdate","E":1784410638514,"s":"BTCUSDT","U":97585365482,"u":97585365488,"b":[["64682.62000000","5.88096000"],["58214.36000000","0.00418000"],["51746.10000000","0.00038000"]],"a":[]}}
{"stream":"btcusdt@depth@100ms","data":{"e":"depthUpdate","E":1784410638615,"s":"BTCUSDT","U":97585365489,"u":97585365494,"b":[["64654.90000000","0.02577000"],["58214.36000000","0.00418000"],["51746.10000000","0.00000000"]],"a":[]}}
{"stream":"btcusdt@depth@100ms","data":{"e":"depthUpdate","E":1784410638714,"s":"BTCUSDT","U":97585365495,"u":97585365508,"b":[["64682.62000000","5.88105000"],["64654.90000000","0.00000000"],["58214.36000000","0.00418000"]],"a":[["64682.63000000","0.16894000"],["64682.64000000","0.00082000"],["77816.97000000","0.00019000"]]}}
{"stream":"btcusdt@depth@100ms","data":{"e":"depthUpdate","E":1784410638815,"s":"BTCUSDT","U":97585365509,"u":97585365512,"b":[["64682.62000000","5.85012000"],["58214.36000000","0.00418000"],["58214.35000000","0.00265000"]],"a":[]}}
{"stream":"btcusdt@depth@100ms","data":{"e":"depthUpdate","E":1784410638914,"s":"BTCUSDT","U":97585365513,"u":97585365521,"b":[["64682.62000000","5.84935000"],["64613.37000000","0.00000000"],["64611.25000000","1.18506000"],["58214.36000000","0.00418000"],["40000.00000000","261.36615000"]],"a":[]}}
{"stream":"btcusdt@depth@100ms","data":{"e":"depthUpdate","E":1784410639014,"s":"BTCUSDT","U":97585365522,"u":97585365533,"b":[["64682.62000000","6.25190000"],["64553.30000000","0.02422000"],["63712.38000000","0.00030000"],["58214.36000000","0.00418000"],["51746.10000000","0.00038000"]],"a":[["65652.87000000","0.00030000"]]}}
{"stream":"btcusdt@depth@100ms","data":{"e":"depthUpdate","E":1784410639114,"s":"BTCUSDT","U":97585365534,"u":97585365538,"b":[["64682.62000000","6.24506000"],["58214.36000000","0.00418000"]],"a":[]}}
{"stream":"btcusdt@depth@100ms","data":{"e":"depthUpdate","E":1784410639214,"s":"BTCUSDT","U":97585365539,"u":97585365551,"b":[["64611.26000000","0.54007000"],["64610.91000000","0.00000000"],["58214.36000000","0.00418000"],["58214.35000000","0.00255000"],["58214.34000000","0.00010000"],["51746.10000000","0.00000000"]],"a":[["64705.33000000","0.00944000"],["64710.32000000","0.00000000"],["64759.60000000","0.31961000"],["64780.94000000","0.13404000"],["64801.91000000","0.00000000"]]}}
{"stream":"btcusdt@depth@100ms","data":{"e":"depthUpdate","E":1784410639314,"s":"BTCUSDT","U":97585365552,"u":97585365558,"b":[["58214.36000000","0.00399000"]],"a":[["64710.90000000","0.00400000"],["64717.38000000","0.00000000"],["64794.74000000","0.02422000"],["64862.93000000","0.01865000"],["64912.14000000","0.00000000"]]}}
{"stream":"btcusdt@depth@100ms","data":{"e":"depthUpdate","E":1784410639414,"s":"BTCUSDT","U":97585365559,"u":97585365573,"b":[["64665.57000000","0.00008000"],["58214.36000000","0.00418000"],["58214.00000000","0.00000000"]],"a":[["64682.63000000","0.16902000"],["64684.76000000","0.00009000"],["64684.77000000","0.18381000"],["64687.10000000","0.00000000"],["64704.39000000","0.00008000"],["64718.54000000","0.07009000"],["64720.11000000","0.70000000"],["64876.64000000","0.09248000"]]}}
{"stream":"btcusdt@depth@100ms","data":{"e":"depthUpdate","E":1784410639514,"s":"BTCUSDT","U":97585365574,"u":97585365588,"b":[["58214.36000000","0.00418000"],["51746.10000000","0.00038000"]],"a":[["64682.63000000","0.16910000"],["64682.64000000","0.00090000"],["64684.00000000","0.02931000"],["64684.77000000","0.18399000"],["64688.00000000","0.02700000"]]}}
{"stream":"btcusdt@depth@100ms","data":{"e":"depthUpdate","E":1784410639614,"s":"BTCUSDT","U":97585365589,"u":97585365594,"b":[["64557.76000000","0.09294000"],["58214.36000000","0.00418000"],["51746.10000000","0.00000000"]],"a":[]}}
{"stream":"btcusdt@depth@100ms","data":{"e":"depthUpdate","E":1784410639714,"s":"BTCUSDT","U":97585365595,"u":97585365600,"b":[["64682.62000000","6.24487000"],["58214.36000000","0.00418000"],["58214.34000000","0.00000000"]],"a":[]}}
{"stream":"btcusdt@depth@100ms","data":{"e":"depthUpdate","E":1784410639814,"s":"BTCUSDT","U":97585365601,"u":97585365604,"b":[["58214.36000000","0.00399000"]],"a":[["64682.63000000","0.16866000"]]}}
{"stream":"btcusdt@depth@100ms","data":{"e":"depthUpdate","E":1784410639915,"s":"BTCUSDT","U":97585365605,"u":97585365609,"b":[["58214.36000000","0.00418000"],["40000.00000000","261.36615000"]],"a":[]}}
{"stream":"btcusdt@depth@100ms","data":{"e":"depthUpdate","E":1784410640015,"s":"BTCUSDT","U":97585365610,"u":97585365618,"b":[["63712.38000000","0.00030000"],["58214.36000000","0.00418000"],["51746.10000000","0.00038000"]],"a":[["65652.87000000","0.00030000"]]}}
{"stream":"btcusdt@depth@100ms","data":{"e":"depthUpdate","E":1784410640114,"s":"BTCUSDT","U":97585365619,"u":97585365624,"b":[["64682.62000000","6.24409000"],["58214.36000000","0.00418000"],["58214.35000000","0.00265000"]],"a":[]}}
{"stream":"btcusdt@depth@100ms","data":{"e":"depthUpdate","E":1784410640214,"s":"BTCUSDT","U":97585365625,"u":97585365633,"b":[["64557.76000000","0.00000000"],["58214.36000000","0.00418000"],["51746.10000000","0.00000000"]],"a":[["64761.77000000","0.03373000"],["64761.99000000","0.00000000"],["64876.64000000","0.00000000"]]}}
{"stream":"btcusdt@depth@100ms","data":{"e":"depthUpdate","E":1784410640315,"s":"BTCUSDT","U":97585365634,"u":97585365639,"b":[["58214.36000000","0.00399000"],["51746.00000000","0.00000000"]],"a":[["64892.57000000","0.01864000"],["64950.03000000","0.00000000"]]}}
{"stream":"btcusdt@depth@100ms","data":{"e":"depthUpdate","E":1784410640415,"s":"BTCUSDT","U":97585365640,"u":97585365645,"b":[["64682.62000000","6.24100000"],["64665.57000000","0.00000000"],["58214.36000000","0.00418000"],["58214.35000000","0.00255000"],["58214.34000000","0.00010000"]],"a":[["64704.39000000","0.00000000"]]}}
{"stream":"btcusdt@depth@100ms","data":{"e":"depthUpdate","E":1784410640514,"s":"BTCUSDT","U":97585365646,"u":97585365659,"b":[["64673.22000000","0.61304000"],["64665.57000000","0.00008000"],["64657.19000000","0.00000000"],["64654.90000000","0.00000000"],["58214.36000000","0.00418000"],["58214.00000000","0.00000000"],["51746.10000000","0.00038000"]],"a":[["64699.70000000","0.00017000"],["64700.13000000","0.08950000"],["64704.39000000","0.00008000"]]}}
{"stream":"btcusdt@depth@100ms","data":{"e":"depthUpdate","E":1784410640614,"s":"BTCUSDT","U":97585365660,"u":97585365676,"b":[["64680.10000000","0.00078000"],["64678.75000000","0.00000000"],["64673.65000000","0.53058000"],["64669.46000000","0.00000000"],["58214.36000000","0.00418000"],["58214.34000000","0.00000000"],["51746.10000000","0.00000000"]],"a":[["64682.63000000","0.16572000"],["64692.46000000","0.00000000"],["64693.48000000","0.00000000"],["64693.75000000","0.00000000"],["64693.81000000","0.00078000"],["64693.99000000","0.00773000"],["64694.21000000","0.00773000"],["64702.39000000","0.00000000"],["64703.38000000","0.77348000"],["64712.37000000","0.00000000"],["64714.49000000","0.53058000"]]}}
{"stream":"btcusdt@depth@100ms","data":{"e":"depthUpdate","E":1784410640714,"s":"BTCUSDT","U":97585365677,"u":97585365682,"b":[["64682.62000000","6.24061000"],["64673.65000000","0.00000000"],["64672.03000000","0.53059000"],["58214.36000000","0.00418000"]],"a":[]}}
{"stream":"btcusdt@depth@100ms","data":{"e":"depthUpdate","E":1784410640816,"s":"BTCUSDT","U":97585365683,"u":97585365686,"b":[["58214.36000000","0.00418000"]],"a":[]}}
{"stream":"btcusdt@depth@100ms","data":{"e":"depthUpdate","E":1784410640914,"s":"BTCUSDT","U":97585365687,"u":97585365690,"b":[["58214.36000000","0.00418000"],["40000.00000000","261.36615000"]],"a":[]}}
{"stream":"btcusdt@depth@100ms","data":{"e":"depthUpdate","E":1784410641014,"s":"BTCUSDT","U":97585365691,"u":97585365699,"b":[["63712.38000000","0.00030000"],["58214.36000000","0.00418000"],["51746.10000000","0.00038000"]],"a":[["65652.87000000","0.00030000"]]}}
{"stream":"btcusdt@depth@100ms","data":{"e":"depthUpdate","E":1784410641114,"s":"BTCUSDT","U":97585365700,"u":97585365707,"b":[["64682.62000000","6.24035000"],["58214.36000000","0.00418000"],["58214.35000000","0.00265000"],["33000.00000000","32.31996000"]],"a":[]}}
{"stream":"btcusdt@depth@100ms","data":{"e":"depthUpdate","E":1784410641215,"s":"BTCUSDT","U":97585365708,"u":97585365721,"b":[["64681.92000000","0.23798000"],["64681.90000000","0.24851000"],["64681.40000000","0.41187000"],["64680.82000000","0.00000000"],["64675.42000000","1.02203000"],["63337.72000000","0.00000000"],["58214.36000000","0.00418000"],["51746.10000000","0.00000000"]],"a":[["64769.63000000","0.32856000"]]}}
{"stream":"btcusdt@depth@100ms","data":{"e":"depthUpdate","E":1784410641314,"s":"BTCUSDT","U":97585365722,"u":97585365730,"b":[["64682.62000000","6.24044000"],["64676.30000000","0.21424000"],["58214.36000000","0.00418000"]],"a":[["64682.63000000","0.16572000"],["64684.76000000","0.00018000"]]}}
{"stream":"btcusdt@depth@100ms","data":{"e":"depthUpdate","E":1784410641414,"s":"BTCUSDT","U":97585365731,"u":97585365737,"b":[["64682.62000000","6.23859000"],["59508.01000000","0.00017000"],["58214.36000000","0.00399000"],["58214.35000000","0.00255000"],["58214.34000000","0.00010000"]],"a":[["64682.63000000","0.16722000"]]}}
{"stream":"btcusdt@depth@100ms","data":{"e":"depthUpdate","E":1784410641514,"s":"BTCUSDT","U":97585365738,"u":97585365747,"b":[["64665.57000000","0.00008000"],["64613.37000000","1.18470000"],["64611.25000000","0.00036000"],["58214.36000000","0.00418000"],["51746.10000000","0.00038000"]],"a":[["64684.91000000","0.00000000"],["64704.39000000","0.00008000"]]}}
{"stream":"btcusdt@depth@100ms","data":{"e":"depthUpdate","E":1784410641614,"s":"BTCUSDT","U":97585365748,"u":97585365763,"b":[["64654.90000000","0.00000000"],["64611.26000000","0.18644000"],["63894.98000000","0.00039000"],["58214.36000000","0.00418000"],["58214.00000000","0.00000000"],["51746.10000000","0.00000000"],["51746.00000000","0.00000000"]],"a":[]}}
{"stream":"btcusdt@depth@100ms","data":{"e":"depthUpdate","E":1784410641715,"s":"BTCUSDT","U":97585365764,"u":97585365768,"b":[["64672.03000000","0.00000000"],["64669.96000000","0.53061000"],["58214.36000000","0.00418000"]],"a":[]}}
{"stream":"btcusdt@depth@100ms","data":{"e":"depthUpdate","E":1784410641814,"s":"BTCUSDT","U":97585365769,"u":97585365782,"b":[["64682.62000000","6.29564000"],["64622.65000000","0.00000000"],["64559.09000000","0.00000000"],["58214.36000000","0.00418000"]],"a":[["64703.37000000","0.97962000"],["64703.39000000","0.00000000"],["64704.66000000","0.55677000"],["64716.74000000","0.00000000"],["71150.89000000","0.00008000"]]}}
{"stream":"btcusdt@depth@100ms","data":{"e":"depthUpdate","E":1784410641915,"s":"BTCUSDT","U":97585365783,"u":97585365791,"b":[["64654.90000000","0.02577000"],["64622.65000000","0.00382000"],["64559.09000000","0.00154000"],["58214.36000000","0.00399000"],["40000.00000000","261.36615000"]],"a":[["71150.89000000","0.00000000"]]}}
{"stream":"btcusdt@depth@100ms","data":{"e":"depthUpdate","E":1784410642014,"s":"BTCUSDT","U":97585365792,"u":97585365803,"b":[["64654.90000000","0.00000000"],["64613.37000000","0.00000000"],["64611.25000000","1.18506000"],["63712.38000000","0.00030000"],["59508.01000000","0.00000000"],["58214.36000000","0.00418000"],["51746.10000000","0.00038000"]],"a":[["65652.87000000","0.00030000"]]}}
{"stream":"btcusdt@depth@100ms","data":{"e":"depthUpdate","E":1784410642114,"s":"BTCUSDT","U":97585365804,"u":97585365811,"b":[["64682.62000000","6.29520000"],["64654.90000000","0.00000000"],["58214.36000000","0.00418000"],["58214.34000000","0.00000000"]],"a":[]}}
{"stream":"btcusdt@depth@100ms","data":{"e":"depthUpdate","E":1784410642214,"s":"BTCUSDT","U":97585365812,"u":97585365816,"b":[["58214.36000000","0.00418000"],["51746.10000000","0.00000000"]],"a":[]}}
{"stream":"btcusdt@depth@100ms","data":{"e":"depthUpdate","E":1784410642314,"s":"BTCUSDT","U":97585365817,"u":97585365822,"b":[["58214.36000000","0.00418000"],["51746.00000000","0.00000000"]],"a":[]}}
{"stream":"btcusdt@depth@100ms","data":{"e":"depthUpdate","E":1784410642414,"s":"BTCUSDT","U":97585365823,"u":97585365827,"b":[["64613.37000000","1.18470000"],["64611.25000000","0.00036000"],["58214.36000000","0.00399000"]],"a":[]}}
{"stream":"btcusdt@depth@100ms","data":{"e":"depthUpdate","E":1784410642514,"s":"BTCUSDT","U":97585365828,"u":97585365834,"b":[["64665.57000000","0.00008000"],["58214.36000000","0.00418000"],["51746.10000000","0.00038000"]],"a":[["64704.39000000","0.00008000"]]}}
{"stream":"btcusdt@depth@100ms","data":{"e":"depthUpdate","E":1784410642614,"s":"BTCUSDT","U":97585365835,"u":97585365846,"b":[["64659.84000000","0.00000000"],["58214.36000000","0.00418000"],["51746.10000000","0.00000000"]],"a":[["64682.63000000","0.16572000"],["64686.20000000","0.11026000"],["64698.58000000","0.00000000"],["64699.13000000","0.58009000"],["64724.55000000","0.00000000"],["64797.45000000","0.03834000"]]}}
{"stream":"btcusdt@depth@100ms","data":{"e":"depthUpdate","E":1784410642714,"s":"BTCUSDT","U":97585365847,"u":97585365855,"b":[["64682.62000000","6.30284000"],["64681.42000000","0.00018000"],["58214.36000000","0.00418000"],["58214.00000000","0.00000000"]],"a":[["64694.21000000","0.00000000"],["64694.66000000","0.00773000"]]}}
{"stream":"btcusdt@depth@100ms","data":{"e":"depthUpdate","E":1784410642814,"s":"BTCUSDT","U":97585365856,"u":97585365868,"b":[["64681.85000000","0.01248000"],["64681.42000000","0.00000000"],["64681.39000000","0.05049000"],["64517.76000000","0.00020000"],["58214.36000000","0.00418000"]],"a":[]}}
{"stream":"btcusdt@depth@100ms","data":{"e":"depthUpdate","E":1784410642914,"s":"BTCUSDT","U":97585365869,"u":97585365877,"b":[["58214.36000000","0.00418000"],["51746.10000000","0.00000000"],["40000.00000000","261.36615000"]],"a":[["64824.91000000","0.00020000"]]}}
{"stream":"btcusdt@depth@100ms","data":{"e":"depthUpdate","E":1784410643014,"s":"BTCUSDT","U":97585365878,"u":97585365893,"b":[["64682.62000000","6.29511000"],["64681.94000000","0.00773000"],["63712.38000000","0.00030000"],["58214.36000000","0.00418000"],["51746.10000000","0.00038000"],["51746.00000000","0.00000000"]],"a":[["65652.87000000","0.00030000"]]}}
{"stream":"btcusdt@depth@100ms","data":{"e":"depthUpdate","E":1784410643114,"s":"BTCUSDT","U":97585365894,"u":97585365901,"b":[["64682.61000000","0.16176000"],["58214.36000000","0.00418000"]],"a":[]}}
{"stream":"btcusdt@depth@100ms","data":{"e":"depthUpdate","E":1784410643214,"s":"BTCUSDT","U":97585365902,"u":97585365909,"b":[["64682.62000000","6.29520000"],["64681.95000000","0.00773000"],["64681.94000000","0.00000000"],["58214.36000000","0.00418000"],["51746.10000000","0.00000000"]],"a":[]}}
{"stream":"btcusdt@depth@100ms","data":{"e":"depthUpdate","E":1784410643314,"s":"BTCUSDT","U":97585365910,"u":97585365918,"b":[["64682.61000000","0.16176000"],["58214.36000000","0.00418000"]],"a":[["64720.11000000","0.00000000"]]}}
{"stream":"btcusdt@depth@100ms","data":{"e":"depthUpdate","E":1784410643414,"s":"BTCUSDT","U":97585365919,"u":97585365926,"b":[["58214.36000000","0.00418000"]],"a":[["64682.63000000","0.18482000"]]}}
{"stream":"btcusdt@depth@100ms","data":{"e":"depthUpdate","E":1784410643516,"s":"BTCUSDT","U":97585365927,"u":97585365933,"b":[["64665.57000000","0.00000000"],["64613.37000000","0.00000000"],["58214.36000000","0.00399000"],["51746.10000000","0.00038000"]],"a":[["64695.46000000","0.08479000"],["64704.39000000","0.00000000"]]}}
{"stream":"btcusdt@depth@100ms","data":{"e":"depthUpdate","E":1784410643617,"s":"BTCUSDT","U":97585365934,"u":97585365939,"b":[["64665.57000000","0.00008000"],["58214.36000000","0.00418000"],["51746.10000000","0.00000000"]],"a":[["64704.39000000","0.00008000"]]}}
{"stream":"btcusdt@depth@100ms","data":{"e":"depthUpdate","E":1784410643714,"s":"BTCUSDT","U":97585365940,"u":97585365944,"b":[["58214.36000000","0.00418000"],["58214.00000000","0.00020000"]],"a":[]}}
{"stream":"btcusdt@depth@100ms","data":{"e":"depthUpdate","E":1784410643814,"s":"BTCUSDT","U":97585365945,"u":97585365951,"b":[["64682.62000000","6.26427000"],["58214.36000000","0.00418000"],["58214.35000000","0.00265000"],["58214.00000000","0.00000000"]],"a":[]}}
{"stream":"btcusdt@depth@100ms","data":{"e":"depthUpdate","E":1784410643915,"s":"BTCUSDT","U":97585365952,"u":97585365962,"b":[["64654.90000000","0.02577000"],["64611.26000000","0.51623000"],["64611.25000000","1.18506000"],["58214.36000000","0.00418000"],["51746.10000000","0.00000000"],["40000.00000000","261.36615000"]],"a":[]}}
{"stream":"btcusdt@depth@100ms","data":{"e":"depthUpdate","E":1784410644014,"s":"BTCUSDT","U":97585365963,"u":97585365977,"b":[["64682.62000000","6.07798000"],["64654.90000000","0.00000000"],["63712.38000000","0.00030000"],["58214.36000000","0.00399000"],["51746.10000000","0.00038000"]],"a":[["64682.63000000","0.18490000"],["64682.64000000","0.00098000"],["64684.63000000","0.00000000"],["64684.90000000","0.00248000"],["64693.56000000","0.00773000"],["64694.66000000","0.00000000"],["65652.87000000","0.00000000"]]}}
{"stream":"btcusdt@depth@100ms","data":{"e":"depthUpdate","E":1784410644114,"s":"BTCUSDT","U":97585365978,"u":97585365987,"b":[["64682.62000000","6.08046000"],["64650.27000000","0.00010000"],["58214.36000000","0.00418000"]],"a":[["64682.63000000","0.18482000"],["64682.64000000","0.00090000"],["64714.98000000","0.00010000"],["65652.87000000","0.00030000"]]}}
{"stream":"btcusdt@depth@100ms","data":{"e":"depthUpdate","E":1784410644215,"s":"BTCUSDT","U":97585365988,"u":97585365994,"b":[["64662.96000000","0.00000000"],["64662.39000000","0.00954000"],["58214.36000000","0.00418000"],["51746.10000000","0.00000000"]],"a":[]}}
{"stream":"btcusdt@depth@100ms","data":{"e":"depthUpdate","E":1784410644314,"s":"BTCUSDT","U":97585365995,"u":97585366000,"b":[["58214.36000000","0.00418000"],["51746.00000000","0.00000000"]],"a":[]}}
{"stream":"btcusdt@depth@100ms","data":{"e":"depthUpdate","E":1784410644415,"s":"BTCUSDT","U":97585366001,"u":97585366004,"b":[["58214.36000000","0.00418000"]],"a":[]}}
{"stream":"btcusdt@depth@100ms","data":{"e":"depthUpdate","E":1784410644514,"s":"BTCUSDT","U":97585366005,"u":97585366010,"b":[["64681.95000000","0.00000000"],["64681.42000000","0.00773000"],["58214.36000000","0.00399000"],["51746.10000000","0.00038000"]],"a":[["64720.11000000","0.70000000"]]}}
{"stream":"btcusdt@depth@100ms","data":{"e":"depthUpdate","E":1784410644614,"s":"BTCUSDT","U":97585366011,"u":97585366025,"b":[["64682.61000000","0.16176000"],["64681.85000000","0.01248000"],["64665.57000000","0.00008000"],["58214.36000000","0.00418000"],["51746.10000000","0.00000000"]],"a":[["64704.39000000","0.00008000"]]}}
{"stream":"btcusdt@depth@100ms","data":{"e":"depthUpdate","E":1784410644714,"s":"BTCUSDT","U":97585366026,"u":97585366029,"b":[["58214.36000000","0.00418000"]],"a":[]}}
{"stream":"btcusdt@depth@100ms","data":{"e":"depthUpdate","E":1784410644814,"s":"BTCUSDT","U":97585366030,"u":97585366034,"b":[["58214.36000000","0.00418000"]],"a":[["64876.66000000","0.09248000"]]}}
{"stream":"btcusdt@depth@100ms","data":{"e":"depthUpdate","E":1784410644914,"s":"BTCUSDT","U":97585366035,"u":97585366042,"b":[["58214.36000000","0.00418000"],["58214.00000000","0.00000000"],["40000.00000000","261.36615000"]],"a":[]}}
{"stream":"btcusdt@depth@100ms","data":{"e":"depthUpdate","E":1784410645014,"s":"BTCUSDT","U":97585366043,"u":97585366048,"b":[["64557.76000000","0.09294000"],["58214.36000000","0.00418000"],["51746.10000000","0.00038000"]],"a":[]}}
{"stream":"btcusdt@depth@100ms","data":{"e":"depthUpdate","E":1784410645114,"s":"BTCUSDT","U":97585366049,"u":97585366073,"b":[["64674.12000000","0.00400000"],["64667.65000000","0.00400000"],["64661.18000000","0.00400000"],["64654.90000000","0.02577000"],["64654.71000000","0.01549000"],["63712.38000000","0.00030000"],["58214.36000000","0.00418000"],["58214.35000000","0.00255000"],["58214.34000000","0.00010000"]],"a":[["64682.63000000","0.18173000"],["64700.00000000","0.81300000"],["64706.47000000","0.00400000"],["64712.94000000","0.00800000"],["65652.87000000","0.00030000"]]}}
{"stream":"btcusdt@depth@100ms","data":{"e":"depthUpdate","E":1784410645215,"s":"BTCUSDT","U":97585366074,"u":97585366078,"b":[["58214.36000000","0.00418000"],["51746.10000000","0.00000000"]],"a":[]}}
{"stream":"btcusdt@depth@100ms","data":{"e":"depthUpdate","E":1784410645314,"s":"BTCUSDT","U":97585366079,"u":97585366086,"b":[["64681.39000000","0.05057000"],["64681.11000000","0.06724000"],["64671.36000000","0.00000000"],["58214.36000000","0.00418000"]],"a":[["64798.41000000","0.01867000"],["64817.96000000","0.00000000"]]}}
{"stream":"btcusdt@depth@100ms","data":{"e":"depthUpdate","E":1784410645415,"s":"BTCUSDT","U":97585366087,"u":97585366098,"b":[["64681.42000000","0.00791000"],["64681.39000000","0.05039000"],["64651.17000000","0.00000000"],["64644.00000000","0.23587000"],["64641.92000000","0.00000000"],["58214.36000000","0.00418000"]],"a":[]}}
{"stream":"btcusdt@depth@100ms","data":{"e":"depthUpdate","E":1784410645514,"s":"BTCUSDT","U":97585366099,"u":97585366105,"b":[["64654.90000000","0.00000000"],["58214.36000000","0.00418000"],["51746.10000000","0.00038000"]],"a":[["64876.66000000","0.00000000"]]}}
{"stream":"btcusdt@depth@100ms","data":{"e":"depthUpdate","E":1784410645614,"s":"BTCUSDT","U":97585366106,"u":97585366116,"b":[["64682.62000000","6.26418000"],["64665.57000000","0.00008000"],["64557.76000000","0.00000000"],["58214.36000000","0.00418000"],["51746.10000000","0.00000000"],["33000.00000000","32.31996000"]],"a":[["64704.39000000","0.00008000"]]}}
{"stream":"btcusdt@depth@100ms","data":{"e":"depthUpdate","E":1784410645715,"s":"BTCUSDT","U":97585366117,"u":97585366121,"b":[["58214.36000000","0.00418000"]],"a":[["77816.97000000","0.00000000"]]}}
{"stream":"btcusdt@depth@100ms","data":{"e":"depthUpdate","E":1784410645814,"s":"BTCUSDT","U":97585366122,"u":97585366125,"b":[["58214.36000000","0.00418000"]],"a":[]}}
{"stream":"btcusdt@depth@100ms","data":{"e":"depthUpdate","E":1784410645917,"s":"BTCUSDT","U":97585366126,"u":97585366133,"b":[["58214.36000000","0.00418000"],["58214.00000000","0.00000000"],["40000.00000000","261.36615000"]],"a":[]}}
{"stream":"btcusdt@depth@100ms","data":{"e":"depthUpdate","E":1784410646014,"s":"BTCUSDT","U":97585366134,"u":97585366138,"b":[["58214.36000000","0.00418000"],["51746.10000000","0.00038000"]],"a":[]}}
{"stream":"btcusdt@depth@100ms","data":{"e":"depthUpdate","E":1784410646114,"s":"BTCUSDT","U":97585366139,"u":97585366145,"b":[["63712.38000000","0.00030000"],["58214.36000000","0.00399000"]],"a":[["65652.87000000","0.00030000"]]}}
{"stream":"btcusdt@depth@100ms","data":{"e":"depthUpdate","E":1784410646216,"s":"BTCUSDT","U":97585366146,"u":97585366149,"b":[["58214.36000000","0.00418000"],["51746.10000000","0.00000000"]],"a":[]}}
{"stream":"btcusdt@depth@100ms","data":{"e":"depthUpdate","E":1784410646314,"s":"BTCUSDT","U":97585366150,"u":97585366155,"b":[["58214.36000000","0.00418000"],["51746.00000000","0.00000000"]],"a":[]}}
{"stream":"btcusdt@depth@100ms","data":{"e":"depthUpdate","E":1784410646414,"s":"BTCUSDT","U":97585366156,"u":97585366166,"b":[["64681.94000000","0.00773000"],["64681.75000000","0.00773000"],["64681.42000000","0.00018000"],["64681.41000000","0.00018000"],["64631.06000000","0.00384000"],["64630.58000000","0.05600000"],["58214.36000000","0.00418000"],["58214.34000000","0.00000000"]],"a":[["64682.63000000","0.18142000"],["64693.55000000","0.00773000"],["64693.56000000","0.00000000"],["64693.75000000","0.00773000"],["64693.99000000","0.00000000"]]}}
{"stream":"btcusdt@depth@100ms","data":{"e":"depthUpdate","E":1784410646515,"s":"BTCUSDT","U":97585366167,"u":97585366188,"b":[["64682.61000000","0.16176000"],["64681.94000000","0.00791000"],["64681.85000000","0.01248000"],["64681.75000000","0.00791000"],["64681.42000000","0.00000000"],["64681.41000000","0.00000000"],["64635.04000000","0.00386000"],["64634.75000000","0.00000000"],["58214.36000000","0.00418000"],["51746.10000000","0.00038000"]],"a":[]}}
{"stream":"btcusdt@depth@100ms","data":{"e":"depthUpdate","E":1784410646615,"s":"BTCUSDT","U":97585366189,"u":97585366195,"b":[["64665.57000000","0.00008000"],["58214.36000000","0.00399000"],["51746.10000000","0.00000000"]],"a":[["64704.39000000","0.00008000"]]}}
{"stream":"btcusdt@depth@100ms","data":{"e":"depthUpdate","E":1784410646715,"s":"BTCUSDT","U":97585366196,"u":97585366200,"b":[["64662.39000000","0.00000000"],["64651.86000000","0.00905000"],["58214.36000000","0.00418000"]],"a":[]}}
{"stream":"btcusdt@depth@100ms","data":{"e":"depthUpdate","E":1784410646814,"s":"BTCUSDT","U":97585366201,"u":97585366205,"b":[["58214.36000000","0.00428000"]],"a":[]}}
{"stream":"btcusdt@depth@100ms","data":{"e":"depthUpdate","E":1784410646915,"s":"BTCUSDT","U":97585366206,"u":97585366215,"b":[["64682.62000000","6.26408000"],["58214.36000000","0.00418000"],["58214.35000000","0.00265000"],["58214.00000000","0.00020000"],["40000.00000000","261.36615000"]],"a":[]}}
{"stream":"btcusdt@depth@100ms","data":{"e":"depthUpdate","E":1784410647015,"s":"BTCUSDT","U":97585366216,"u":97585366224,"b":[["59508.01000000","0.00017000"],["58214.36000000","0.00418000"],["58214.00000000","0.00000000"],["51746.10000000","0.00038000"]],"a":[["64693.48000000","0.00773000"],["64693.55000000","0.00000000"],["64693.75000000","0.00000000"],["64693.99000000","0.00773000"]]}}
{"stream":"btcusdt@depth@100ms","data":{"e":"depthUpdate","E":1784410647115,"s":"BTCUSDT","U":97585366225,"u":97585366232,"b":[["63712.38000000","0.00030000"],["58214.36000000","0.00418000"]],"a":[["65652.87000000","0.00030000"]]}}
{"stream":"btcusdt@depth@100ms","data":{"e":"depthUpdate","E":1784410647216,"s":"BTCUSDT","U":97585366233,"u":97585366241,"b":[["64681.92000000","0.15458000"],["64681.40000000","0.02536000"],["64654.37000000","0.05307000"],["58214.36000000","0.00418000"],["51746.10000000","0.00000000"]],"a":[["64703.88000000","0.00000000"],["64708.90000000","0.02846000"]]}}
{"stream":"btcusdt@depth@100ms","data":{"e":"depthUpdate","E":1784410647315,"s":"BTCUSDT","U":97585366242,"u":97585366249,"b":[["64682.62000000","6.25894000"],["64621.68000000","0.00015000"],["58214.36000000","0.00418000"],["58214.35000000","0.00255000"],["58214.34000000","0.00010000"]],"a":[["64706.06000000","0.00015000"]]}}
{"stream":"btcusdt@depth@100ms","data":{"e":"depthUpdate","E":1784410647414,"s":"BTCUSDT","U":97585366250,"u":97585366259,"b":[["64643.23000000","0.00000000"],["58214.36000000","0.00418000"],["51746.00000000","0.00000000"]],"a":[["64693.48000000","0.00000000"],["64693.56000000","0.00773000"]]}}
{"stream":"btcusdt@depth@100ms","data":{"e":"depthUpdate","E":1784410647514,"s":"BTCUSDT","U":97585366260,"u":97585366266,"b":[["64468.08000000","0.02422000"],["64415.31000000","0.00000000"],["58214.36000000","0.00418000"],["51746.10000000","0.00038000"]],"a":[]}}
{"stream":"btcusdt@depth@100ms","data":{"e":"depthUpdate","E":1784410647614,"s":"BTCUSDT","U":97585366267,"u":97585366275,"b":[["64665.57000000","0.00000000"],["59508.01000000","0.00000000"],["58214.36000000","0.00418000"],["51746.10000000","0.00000000"],["51746.00000000","0.00000000"]],"a":[["64704.39000000","0.00000000"]]}}
{"stream":"btcusdt@depth@100ms","data":{"e":"depthUpdate","E":1784410647714,"s":"BTCUSDT","U":97585366276,"u":97585366577,"b":[["64683.99000000","3.79721000"],["64683.98000000","0.00034000"],["64683.97000000","0.00016000"],["64683.85000000","0.00026000"],["64683.84000000","0.14162000"],["64683.64000000","0.00000000"],["64683.49000000","0.00000000"],["64683.33000000","0.00000000"],["64683.32000000","0.00000000"],["64683.18000000","0.00000000"],["64682.85000000","0.00000000"],["64682.64000000","1.58804000"],["64682.63000000","0.56474000"],["64682.62000000","2.54705000"],["64682.61000000","0.00026000"],["64682.60000000","0.00000000"],["64681.93000000","0.00000000"],["64681.92000000","0.00018000"],["64681.91000000","0.00000000"],["64681.90000000","0.18276000"],["64681.40000000","0.02518000"],["64681.39000000","0.05031000"],["64680.00000000","0.00008000"],["64679.32000000","0.06285000"],["64679.31000000","0.00000000"],["64677.68000000","0.15459000"],["64677.52000000","0.00009000"],["64676.72000000","0.00008000"],["64676.30000000","0.21416000"],["64676.23000000","0.00000000"],["64676.14000000","0.00000000"],["64674.92000000","0.00000000"],["64674.13000000","0.00000000"],["64671.48000000","0.00016000"],["64669.95000000","0.04509000"],["64669.82000000","0.00000000"],["64669.69000000","0.00000000"],["64665.57000000","0.00008000"],["64665.13000000","0.00000000"],["64662.00000000","0.02700000"],["64636.44000000","0.00386000"],["64635.04000000","0.00000000"],["64619.31000000","0.00009000"],["64612.73000000","0.00000000"],["64571.02000000","0.00154000"],["64570.02000000","0.00000000"],["64554.62000000","0.00009000"],["64548.06000000","0.00000000"],["64489.94000000","0.00009000"],["64483.38000000","0.00000000"],["64425.25000000","0.00009000"],["64418.70000000","0.00000000"],["64360.57000000","0.00009000"],["64354.02000000","0.00000000"],["64295.89000000","0.00009000"],["64289.35000000","0.00000000"],["64231.20000000","0.00009000"],["64224.67000000","0.00000000"],["64166.52000000","0.00009000"],["64159.99000000","0.00000000"],["63712.38000000","0.00000000"],["58214.36000000","0.00000000"],["58214.34000000","0.00000000"]],"a":[["64682.63000000","0.00000000"],["64682.64000000","0.00000000"],["64682.65000000","0.00000000"],["64682.86000000","0.00000000"],["64683.19000000","0.00000000"],["64683.33000000","0.00000000"],["64683.34000000","0.00000000"],["64683.50000000","0.00000000"],["64683.65000000","0.00000000"],["64683.85000000","0.00000000"],["64683.99000000","0.00000000"],["64684.00000000","0.57391000"],["64684.01000000","0.00058000"],["64684.77000000","0.18407000"],["64685.40000000","0.00008000"],["64685.79000000","0.00000000"],["64685.80000000","0.00018000"],["64686.00000000","0.02718000"],["64686.58000000","0.00000000"],["64687.10000000","0.00018000"],["64687.11000000","0.16424000"],["64687.52000000","0.00000000"],["64687.87000000","0.00000000"],["64688.00000000","0.02718000"],["64688.39000000","0.00008000"],["64688.78000000","0.00008000"],["64688.81000000","0.00000000"],["64690.12000000","0.13062000"],["64690.47000000","0.00009000"],["64690.98000000","0.00000000"],["64691.71000000","0.00171000"],["64693.56000000","0.00000000"],["64693.57000000","0.00000000"],["64693.99000000","0.00000000"],["64694.33000000","0.00773000"],["64694.79000000","0.00773000"],["64695.29000000","0.00008000"],["64695.57000000","0.00000000"],["64704.39000000","0.00008000"],["64715.00000000","0.12000000"],["64715.55000000","0.00008000"],["64717.00000000","0.01000000"],["64740.00000000","0.05940000"],["64742.10000000","0.00000000"],["64747.05000000","0.46051000"],["64748.59000000","0.00385000"],["64748.68000000","0.45359000"],["64806.77000000","0.00000000"],["64811.99000000","0.00000000"],["64813.37000000","0.00009000"],["64813.99000000","0.00154000"],["64871.45000000","0.00000000"],["64878.05000000","0.00009000"],["64936.13000000","0.00000000"],["64942.74000000","0.00009000"],["65000.81000000","0.00000000"],["65007.42000000","0.00009000"],["65065.48000000","0.00000000"],["65072.10000000","0.00009000"],["65130.16000000","0.00000000"],["65136.79000000","0.00009000"],["65194.84000000","0.00000000"],["65201.47000000","0.00009000"],["65652.87000000","0.00000000"]]}}
{"stream":"btcusdt@depth@100ms","data":{"e":"depthUpdate","E":1784410647815,"s":"BTCUSDT","U":97585366578,"u":97585366674,"b":[["64683.99000000","3.81353000"],["64683.98000000","0.00042000"],["64683.84000000","0.14196000"],["64683.28000000","0.00009000"],["64683.27000000","0.06575000"],["64682.66000000","0.00018000"],["64682.65000000","1.03299000"],["64682.64000000","0.00036000"],["64682.63000000","0.56500000"],["64682.62000000","2.53502000"],["64682.61000000","0.00000000"],["64681.94000000","0.00773000"],["64681.92000000","0.00000000"],["64681.91000000","0.38651000"],["64681.40000000","0.02500000"],["64681.11000000","0.06732000"],["64680.68000000","0.08227000"],["64679.32000000","0.10096000"],["64678.48000000","0.06400000"],["64678.09000000","0.08219000"],["64677.41000000","0.09934000"],["64675.50000000","0.09864000"],["64651.00000000","0.01000000"],["64650.00000000","0.28891000"],["58215.60000000","0.00068000"],["51747.00000000","0.00000000"]],"a":[["64684.00000000","0.57393000"],["64684.01000000","0.00066000"],["64684.30000000","0.00000000"],["64684.77000000","0.18399000"],["64684.95000000","0.00008000"],["64685.59000000","0.00000000"],["64685.80000000","0.00000000"],["64686.89000000","0.00008000"],["64687.11000000","0.16432000"],["64687.17000000","0.05792000"],["64688.01000000","0.13354000"],["64689.00000000","0.00025000"],["64689.09000000","0.10016000"],["64689.76000000","0.07240000"],["64691.32000000","0.00000000"],["64691.46000000","0.00400000"],["64692.35000000","0.07240000"],["64694.94000000","0.08688000"]]}}
{"stream":"btcusdt@depth@100ms","data":{"e":"depthUpdate","E":1784410647915,"s":"BTCUSDT","U":97585366675,"u":97585366722,"b":[["64683.99000000","3.81337000"],["64683.98000000","0.00034000"],["64683.84000000","0.14196000"],["64683.28000000","0.00018000"],["64683.27000000","0.06593000"],["64682.65000000","1.03317000"],["64682.64000000","0.00000000"],["64682.63000000","0.00036000"],["64681.94000000","0.00791000"],["64681.92000000","0.00000000"],["64681.91000000","0.00000000"],["64681.85000000","0.01230000"],["64681.75000000","0.00773000"],["64671.06000000","0.12250000"],["64669.95000000","0.04200000"],["64659.88000000","0.00015000"],["64658.51000000","0.00000000"],["64649.74000000","0.13078000"],["58215.60000000","0.00106000"],["40000.00000000","261.36615000"]],"a":[["64684.00000000","0.57582000"],["64687.12000000","2.12867000"],["64687.17000000","0.05810000"],["64688.01000000","0.13336000"],["64691.31000000","0.00000000"],["64721.08000000","0.00000000"],["64722.45000000","0.00015000"]]}}
{"stream":"btcusdt@depth@100ms","data":{"e":"depthUpdate","E":1784410648015,"s":"BTCUSDT","U":97585366723,"u":97585366752,"b":[["64682.65000000","1.03317000"],["64682.63000000","0.00018000"],["64682.62000000","0.22037000"],["64681.95000000","0.00773000"],["64681.94000000","0.00791000"],["64681.85000000","0.01248000"],["64681.75000000","0.00000000"],["64632.41000000","0.00384000"],["64631.06000000","0.00000000"],["64568.45000000","0.00154000"],["64566.84000000","0.00000000"],["64468.08000000","0.00000000"],["64415.31000000","0.02422000"],["58215.60000000","0.00144000"],["51747.20000000","0.00038000"]],"a":[["64693.75000000","0.00773000"],["64694.21000000","0.00773000"],["64694.33000000","0.00000000"],["64694.79000000","0.00000000"],["64741.61000000","0.00000000"],["64741.88000000","0.00386000"],["64805.81000000","0.00000000"],["64807.93000000","0.00154000"]]}}
{"stream":"btcusdt@depth@100ms","data":{"e":"depthUpdate","E":1784410648116,"s":"BTCUSDT","U":97585366753,"u":97585366776,"b":[["64683.27000000","0.06601000"],["64682.65000000","0.22747000"],["64682.62000000","0.22037000"],["64681.95000000","0.00791000"],["64681.91000000","0.00009000"],["64681.85000000","0.01230000"],["64654.90000000","0.02577000"],["64602.67000000","0.00030000"],["64601.30000000","0.00000000"],["63713.73000000","0.00030000"],["58215.60000000","0.00182000"],["58215.00000000","0.11017000"]],"a":[["64694.21000000","0.00000000"],["64694.33000000","0.00773000"],["64763.00000000","0.00000000"],["64764.38000000","0.00030000"],["65654.26000000","0.00030000"]]}}
{"stream":"btcusdt@depth@100ms","data":{"e":"depthUpdate","E":1784410648216,"s":"BTCUSDT","U":97585366777,"u":97585366781,"b":[["58215.60000000","0.00201000"],["51747.20000000","0.00000000"]],"a":[["64685.36000000","0.00306000"],["64685.40000000","0.00000000"],["64688.16000000","0.00175000"],["64691.71000000","0.00000000"]]}}
{"stream":"btcusdt@depth@100ms","data":{"e":"depthUpdate","E":1784410648314,"s":"BTCUSDT","U":97585366782,"u":97585366811,"b":[["64683.99000000","3.81299000"],["64679.32000000","0.18452000"],["64677.42000000","0.21415000"],["64677.41000000","0.09926000"],["64676.72000000","0.00000000"],["64676.30000000","0.00000000"],["64673.28000000","0.77348000"],["64671.92000000","0.95696000"],["64671.91000000","0.00000000"],["64654.90000000","0.00000000"],["64579.13000000","0.00000000"],["64359.21000000","0.00000000"],["58215.60000000","0.00239000"],["58215.59000000","0.00010000"],["51746.00000000","0.00000000"]],"a":[["64684.00000000","0.41901000"],["64693.75000000","0.00000000"],["64694.21000000","0.00773000"],["64694.33000000","0.00000000"],["64694.66000000","0.00773000"],["64699.13000000","0.00000000"],["64699.48000000","0.58010000"],["64700.13000000","0.00000000"],["64700.76000000","0.15163000"]]}}
{"stream":"btcusdt@depth@100ms","data":{"e":"depthUpdate","E":1784410648414,"s":"BTCUSDT","U":97585366812,"u":97585366824,"b":[["64683.01000000","0.00008000"],["64546.84000000","0.00000000"],["64339.90000000","0.00000000"],["64320.59000000","0.00009000"],["64100.48000000","0.00000000"],["58215.60000000","0.00277000"]],"a":[["64684.00000000","0.41893000"],["64689.09000000","0.00016000"],["64708.49000000","0.00000000"],["64727.90000000","0.00000000"],["64747.05000000","0.28844000"],["64747.31000000","0.00000000"]]}}
{"stream":"btcusdt@depth@100ms","data":{"e":"depthUpdate","E":1784410648514,"s":"BTCUSDT","U":97585366825,"u":97585366828,"b":[["64683.99000000","3.78206000"],["58215.60000000","0.00315000"],["51747.20000000","0.00038000"]],"a":[]}}
{"stream":"btcusdt@depth@100ms","data":{"e":"depthUpdate","E":1784410648615,"s":"BTCUSDT","U":97585366829,"u":97585366835,"b":[["64683.99000000","3.96587000"],["58215.60000000","0.00353000"],["51747.20000000","0.00000000"]],"a":[["64684.00000000","0.26162000"]]}}
{"stream":"btcusdt@depth@100ms","data":{"e":"depthUpdate","E":1784410648715,"s":"BTCUSDT","U":97585366836,"u":97585366841,"b":[["64666.94000000","0.00008000"],["64665.57000000","0.00000000"],["58215.60000000","0.00372000"]],"a":[["64684.00000000","0.41630000"],["64704.39000000","0.00000000"],["64705.76000000","0.00008000"]]}}
{"stream":"btcusdt@depth@100ms","data":{"e":"depthUpdate","E":1784410648814,"s":"BTCUSDT","U":97585366842,"u":97585366865,"b":[["64664.58000000","0.00015000"],["64658.01000000","0.00000000"],["64645.18000000","0.00015000"],["64638.60000000","0.00000000"],["64625.77000000","0.00015000"],["64619.20000000","0.00000000"],["64606.37000000","0.00015000"],["64599.80000000","0.00000000"],["64586.96000000","0.00015000"],["64580.39000000","0.00000000"],["58215.60000000","0.00410000"]],"a":[["64684.00000000","0.26162000"],["64696.82000000","0.00000000"],["64703.41000000","0.00015000"],["64716.23000000","0.00000000"],["64722.81000000","0.00015000"],["64735.63000000","0.00000000"],["64742.22000000","0.00015000"],["64755.03000000","0.00000000"],["64761.62000000","0.00015000"],["64774.44000000","0.00000000"],["64781.03000000","0.00015000"]]}}
{"stream":"btcusdt@depth@100ms","data":{"e":"depthUpdate","E":1784410648915,"s":"BTCUSDT","U":97585366866,"u":97585366871,"b":[["58215.60000000","0.00448000"],["51747.19000000","0.00000000"],["40000.00000000","261.36615000"]],"a":[]}}
{"stream":"btcusdt@depth@100ms","data":{"e":"depthUpdate","E":1784410649015,"s":"BTCUSDT","U":97585366872,"u":97585366882,"b":[["64683.99000000","4.42952000"],["64682.67000000","0.00773000"],["64681.94000000","0.00018000"],["64565.14000000","0.02422000"],["64553.30000000","0.00000000"],["58215.60000000","0.00448000"],["51747.20000000","0.00038000"]],"a":[["64685.59000000","0.00008000"]]}}
{"stream":"btcusdt@depth@100ms","data":{"e":"depthUpdate","E":1784410649114,"s":"BTCUSDT","U":97585366883,"u":97585366903,"b":[["64683.27000000","0.06601000"],["64683.19000000","0.00089000"],["64682.67000000","0.00791000"],["64681.95000000","0.00791000"],["64681.94000000","0.00000000"],["63713.73000000","0.00030000"],["58215.60000000","0.00448000"]],"a":[["65654.26000000","0.00030000"]]}}
{"stream":"btcusdt@depth@100ms","data":{"e":"depthUpdate","E":1784410649214,"s":"BTCUSDT","U":97585366904,"u":97585366915,"b":[["64666.23000000","0.00000000"],["64654.90000000","0.02577000"],["64646.83000000","0.00000000"],["64565.14000000","0.00000000"],["58215.60000000","0.00429000"],["58215.00000000","0.11037000"],["51747.20000000","0.00000000"]],"a":[["64685.31000000","0.00008000"],["64685.36000000","0.00000000"],["64702.70000000","0.00000000"],["64722.11000000","0.00000000"]]}}
{"stream":"btcusdt@depth@100ms","data":{"e":"depthUpdate","E":1784410649315,"s":"BTCUSDT","U":97585366916,"u":97585366929,"b":[["64683.99000000","4.42961000"],["64654.90000000","0.00000000"],["64580.50000000","0.00160000"],["64360.57000000","0.10009000"],["64341.26000000","0.30000000"],["64321.95000000","0.03046000"],["58215.60000000","0.00448000"],["58215.00000000","0.11017000"]],"a":[["64684.00000000","0.26178000"],["64684.01000000","0.00082000"],["64684.02000000","0.00016000"],["64690.46000000","0.10000000"]]}}
{"stream":"btcusdt@depth@100ms","data":{"e":"depthUpdate","E":1784410649414,"s":"BTCUSDT","U":97585366930,"u":97585366941,"b":[["64548.20000000","0.00160000"],["64101.83000000","0.00022000"],["58215.60000000","0.00448000"],["51747.00000000","0.00000000"]],"a":[["64709.86000000","0.30000000"],["64729.27000000","0.50000000"],["64748.67000000","0.33672000"],["64748.68000000","1.15359000"]]}}
{"stream":"btcusdt@depth@100ms","data":{"e":"depthUpdate","E":1784410649514,"s":"BTCUSDT","U":97585366942,"u":97585366958,"b":[["64683.99000000","4.89326000"],["64683.02000000","0.00773000"],["64682.68000000","0.00773000"],["64682.67000000","0.00018000"],["64681.95000000","0.00018000"],["64613.37000000","1.18468000"],["64611.26000000","0.18644000"],["64611.25000000","0.00036000"],["58215.60000000","0.00448000"],["51747.20000000","0.00038000"]],"a":[["64684.00000000","0.26188000"],["64685.59000000","0.00000000"],["64694.21000000","0.00000000"],["64694.33000000","0.00773000"],["64694.66000000","0.00000000"],["64695.28000000","0.00773000"],["64700.76000000","0.00000000"],["64701.52000000","0.26395000"]]}}
{"stream":"btcusdt@depth@100ms","data":{"e":"depthUpdate","E":1784410649616,"s":"BTCUSDT","U":97585366959,"u":97585366991,"b":[["64683.99000000","4.89292000"],["64683.36000000","0.00400000"],["64683.27000000","0.06601000"],["64683.02000000","0.00791000"],["64682.68000000","0.00791000"],["64682.67000000","0.00000000"],["64682.62000000","0.22045000"],["64681.95000000","0.00000000"],["64681.91000000","0.38660000"],["64666.51000000","0.33940000"],["64657.44000000","0.00000000"],["64647.11000000","0.72725000"],["58215.60000000","0.00448000"],["58215.59000000","0.00000000"],["58215.58000000","0.00010000"],["51747.20000000","0.00000000"]],"a":[["64684.00000000","0.25999000"],["64691.38000000","0.00190000"],["64703.10000000","0.34326000"],["64722.51000000","0.70238000"]]}}
{"stream":"btcusdt@depth@100ms","data":{"e":"depthUpdate","E":1784410649714,"s":"BTCUSDT","U":97585366992,"u":97585367011,"b":[["64683.99000000","4.89271000"],["64682.68000000","0.00018000"],["64682.62000000","0.22045000"],["64681.92000000","0.00773000"],["64666.94000000","0.00008000"],["58215.60000000","0.00448000"]],"a":[["64684.00000000","0.31392000"],["64695.46000000","0.00000000"],["64700.76000000","0.10428000"],["64701.52000000","0.00000000"],["64703.10000000","0.00000000"],["64705.76000000","0.00008000"]]}}
{"stream":"btcusdt@depth@100ms","data":{"e":"depthUpdate","E":1784410649815,"s":"BTCUSDT","U":97585367012,"u":97585367037,"b":[["64683.99000000","4.87071000"],["64683.02000000","0.00791000"],["64682.68000000","0.00000000"],["64682.62000000","0.22045000"],["64681.92000000","0.00791000"],["62871.05000000","0.00096000"],["58215.60000000","0.00448000"],["51747.00000000","0.00000000"]],"a":[["64691.38000000","0.00000000"],["64695.42000000","0.08359000"]]}}
{"stream":"btcusdt@depth@100ms","data":{"e":"depthUpdate","E":1784410649914,"s":"BTCUSDT","U":97585367038,"u":97585367056,"b":[["64683.02000000","0.00018000"],["64682.65000000","0.31378000"],["64681.93000000","0.00773000"],["64676.28000000","0.09166000"],["64675.00000000","0.00000000"],["64670.80000000","0.00000000"],["58215.60000000","0.00448000"],["51747.19000000","0.00000000"],["40000.00000000","261.36615000"]],"a":[["64684.00000000","0.31409000"],["64691.34000000","0.00188000"],["64694.33000000","0.00000000"],["64694.66000000","0.00773000"],["64700.76000000","0.00000000"],["64701.52000000","0.24014000"],["64703.03000000","0.34714000"]]}}
{"stream":"btcusdt@depth@100ms","data":{"e":"depthUpdate","E":1784410650015,"s":"BTCUSDT","U":97585367057,"u":97585367081,"b":[["64683.99000000","5.33436000"],["64683.37000000","0.00773000"],["64683.27000000","0.06601000"],["64683.02000000","0.00000000"],["64682.62000000","0.22045000"],["64681.93000000","0.00018000"],["64676.28000000","0.00000000"],["64675.73000000","0.17877000"],["64622.65000000","0.00000000"],["64594.17000000","0.00000000"],["64559.09000000","0.00000000"],["58215.60000000","0.00448000"],["51747.20000000","0.00038000"]],"a":[["64700.76000000","0.09394000"],["64701.52000000","0.00000000"]]}}
{"stream":"btcusdt@depth@100ms","data":{"e":"depthUpdate","E":1784410650114,"s":"BTCUSDT","U":97585367082,"u":97585367104,"b":[["64683.84000000","0.14196000"],["64683.37000000","0.00791000"],["64682.62000000","0.22045000"],["64681.93000000","0.00000000"],["64625.02000000","0.00386000"],["64599.35000000","0.04796000"],["64560.09000000","0.00154000"],["63713.73000000","0.00030000"],["58215.60000000","0.00448000"]],"a":[["65654.26000000","0.00030000"]]}}
{"stream":"btcusdt@depth@100ms","data":{"e":"depthUpdate","E":1784410650214,"s":"BTCUSDT","U":97585367105,"u":97585367124,"b":[["64683.75000000","0.01216000"],["64682.63000000","0.00791000"],["64681.92000000","0.00018000"],["64681.91000000","0.00009000"],["64681.11000000","0.06740000"],["64680.82000000","0.38652000"],["64642.73000000","0.02269000"],["64638.53000000","0.00000000"],["58215.60000000","0.00448000"],["51747.20000000","0.00000000"]],"a":[["64685.27000000","0.00306000"],["64685.31000000","0.00000000"],["64700.75000000","0.00000000"],["64700.76000000","0.07963000"],["64701.52000000","0.00000000"],["64705.33000000","0.00927000"],["64877.05000000","0.09248000"]]}}
{"stream":"btcusdt@depth@100ms","data":{"e":"depthUpdate","E":1784410650314,"s":"BTCUSDT","U":97585367125,"u":97585367147,"b":[["64683.84000000","0.14196000"],["64683.75000000","0.01234000"],["64682.65000000","0.31378000"],["64682.63000000","0.00809000"],["64682.62000000","0.22027000"],["64681.92000000","0.00000000"],["58215.60000000","0.00429000"],["58215.00000000","0.11017000"],["51747.00000000","0.00000000"]],"a":[]}}
{"stream":"btcusdt@depth@100ms","data":{"e":"depthUpdate","E":1784410650414,"s":"BTCUSDT","U":97585367148,"u":97585367157,"b":[["64682.63000000","0.00036000"],["64681.92000000","0.00773000"],["64673.23000000","1.58743000"],["64671.92000000","0.00000000"],["64671.59000000","0.88000000"],["64557.44000000","0.09294000"],["64537.27000000","0.00000000"],["58215.60000000","0.00448000"]],"a":[["64834.64000000","0.00000000"]]}}
{"stream":"btcusdt@depth@100ms","data":{"e":"depthUpdate","E":1784410650514,"s":"BTCUSDT","U":97585367158,"u":97585367172,"b":[["64683.99000000","5.79819000"],["64682.65000000","0.31378000"],["64682.63000000","0.00018000"],["64682.62000000","0.22045000"],["58215.60000000","0.00448000"],["51747.20000000","0.00038000"]],"a":[]}}
{"stream":"btcusdt@depth@100ms","data":{"e":"depthUpdate","E":1784410650615,"s":"BTCUSDT","U":97585367173,"u":97585367180,"b":[["64538.64000000","5.96277000"],["58215.60000000","0.00448000"],["51747.20000000","0.00000000"]],"a":[["64685.59000000","0.00008000"],["64834.53000000","5.85968000"]]}}
{"stream":"btcusdt@depth@100ms","data":{"e":"depthUpdate","E":1784410650715,"s":"BTCUSDT","U":97585367181,"u":97585367185,"b":[["64666.94000000","0.00000000"],["58215.60000000","0.00448000"]],"a":[["64705.76000000","0.00000000"]]}}
{"stream":"btcusdt@depth@100ms","data":{"e":"depthUpdate","E":1784410650814,"s":"BTCUSDT","U":97585367186,"u":97585367190,"b":[["64666.94000000","0.00008000"],["58215.60000000","0.00429000"]],"a":[["64705.76000000","0.00008000"]]}}
{"stream":"btcusdt@depth@100ms","data":{"e":"depthUpdate","E":1784410650915,"s":"BTCUSDT","U":97585367191,"u":97585367199,"b":[["58215.60000000","0.00448000"],["51747.00000000","0.00000000"],["40000.00000000","261.36615000"]],"a":[["64720.43000000","0.00000000"],["64736.50000000","0.07550000"]]}}
{"stream":"btcusdt@depth@100ms","data":{"e":"depthUpdate","E":1784410651016,"s":"BTCUSDT","U":97585367200,"u":97585367216,"b":[["64683.99000000","6.25778000"],["64682.64000000","0.00773000"],["64681.92000000","0.00000000"],["64677.69000000","0.15459000"],["64677.68000000","0.00000000"],["64557.44000000","0.00000000"],["58215.60000000","0.00448000"],["51747.20000000","0.00038000"]],"a":[["64690.12000000","0.08980000"],["64700.76000000","0.00000000"],["64701.52000000","0.28151000"],["64799.85000000","0.00000000"],["64808.81000000","0.57994000"],["64877.05000000","0.00000000"]]}}
{"stream":"btcusdt@depth@100ms","data":{"e":"depthUpdate","E":1784410651114,"s":"BTCUSDT","U":97585367217,"u":97585367238,"b":[["64682.65000000","0.31378000"],["64682.64000000","0.00791000"],["64682.62000000","0.22027000"],["64678.48000000","0.06392000"],["64671.37000000","0.00000000"],["63713.73000000","0.00030000"],["58215.60000000","0.00448000"],["58215.58000000","0.00000000"],["33000.00000000","32.31996000"]],"a":[["64684.00000000","0.31100000"],["65654.26000000","0.00030000"]]}}
{"stream":"btcusdt@depth@100ms","data":{"e":"depthUpdate","E":1784410651215,"s":"BTCUSDT","U":97585367239,"u":97585367244,"b":[["58215.60000000","0.00448000"],["51747.20000000","0.00000000"]],"a":[["64685.23000000","0.00008000"],["64685.27000000","0.00000000"]]}}
{"stream":"btcusdt@depth@100ms","data":{"e":"depthUpdate","E":1784410651314,"s":"BTCUSDT","U":97585367245,"u":97585367248,"b":[["58215.60000000","0.00429000"],["58215.59000000","0.00034000"]],"a":[]}}
{"stream":"btcusdt@depth@100ms","data":{"e":"depthUpdate","E":1784410651414,"s":"BTCUSDT","U":97585367249,"u":97585367254,"b":[["64678.04000000","0.00222000"],["58215.60000000","0.00448000"],["58215.00000000","0.11017000"]],"a":[]}}
{"stream":"btcusdt@depth@100ms","data":{"e":"depthUpdate","E":1784410651514,"s":"BTCUSDT","U":97585367255,"u":97585367287,"b":[["64683.99000000","6.25859000"],["64683.98000000","0.00090000"],["64683.37000000","0.00018000"],["64683.02000000","0.00773000"],["64682.64000000","0.00018000"],["64681.92000000","0.00773000"],["64678.48000000","0.06384000"],["64625.02000000","0.00000000"],["64560.09000000","0.00000000"],["58215.60000000","0.00448000"],["51747.20000000","0.00038000"]],"a":[["64684.00000000","0.63523000"],["64691.34000000","0.00000000"],["64700.76000000","0.10226000"],["64701.52000000","0.00000000"]]}}
{"stream":"btcusdt@depth@100ms","data":{"e":"depthUpdate","E":1784410651616,"s":"BTCUSDT","U":97585367288,"u":97585367338,"b":[["64683.99000000","6.25787000"],["64683.98000000","0.00034000"],["64683.75000000","0.01234000"],["64683.37000000","0.00000000"],["64683.27000000","0.06601000"],["64683.02000000","0.00791000"],["64682.65000000","0.31378000"],["64682.64000000","0.00000000"],["64682.62000000","0.22045000"],["64625.02000000","0.00386000"],["64560.09000000","0.00154000"],["58215.60000000","0.00448000"],["51747.20000000","0.00000000"]],"a":[["64684.00000000","0.48070000"]]}}
{"stream":"btcusdt@depth@100ms","data":{"e":"depthUpdate","E":1784410651714,"s":"BTCUSDT","U":97585367339,"u":97585367349,"b":[["64683.99000000","6.27483000"],["64613.37000000","0.00000000"],["64611.25000000","1.18504000"],["64574.65000000","0.02858000"],["64566.83000000","0.00000000"],["58215.60000000","0.00448000"]],"a":[["64684.00000000","0.47880000"],["64685.59000000","0.00000000"]]}}
{"stream":"btcusdt@depth@100ms","data":{"e":"depthUpdate","E":1784410651817,"s":"BTCUSDT","U":97585367350,"u":97585367364,"b":[["64666.94000000","0.00008000"],["64611.26000000","0.51623000"],["58215.60000000","0.00458000"]],"a":[["64684.00000000","0.31090000"],["64691.30000000","0.00188000"],["64705.76000000","0.00008000"],["71152.40000000","0.00008000"]]}}
{"stream":"btcusdt@depth@100ms","data":{"e":"depthUpdate","E":1784410651914,"s":"BTCUSDT","U":97585367365,"u":97585367369,"b":[["58215.60000000","0.00458000"],["40000.00000000","261.36615000"]],"a":[["71152.40000000","0.00000000"]]}}
{"stream":"btcusdt@depth@100ms","data":{"e":"depthUpdate","E":1784410652014,"s":"BTCUSDT","U":97585367370,"u":97585367378,"b":[["64683.76000000","0.00773000"],["64683.02000000","0.00018000"],["64682.67000000","0.00773000"],["64681.92000000","0.00000000"],["58215.60000000","0.00458000"],["51747.20000000","0.00038000"]],"a":[["64695.28000000","0.00000000"],["64695.99000000","0.00773000"],["64700.76000000","0.00000000"],["64701.52000000","0.25540000"]]}}
{"stream":"btcusdt@depth@100ms","data":{"e":"depthUpdate","E":1784410652115,"s":"BTCUSDT","U":97585367379,"u":97585367404,"b":[["64683.84000000","0.14196000"],["64683.76000000","0.00018000"],["64683.37000000","0.00773000"],["64683.27000000","0.06601000"],["64683.02000000","0.00000000"],["64682.67000000","0.00791000"],["64682.62000000","0.22027000"],["63713.73000000","0.00030000"],["58215.60000000","0.00458000"]],"a":[["64695.28000000","0.00773000"],["64695.99000000","0.00000000"],["65654.26000000","0.00030000"]]}}
{"stream":"btcusdt@depth@100ms","data":{"e":"depthUpdate","E":1784410652215,"s":"BTCUSDT","U":97585367405,"u":97585367421,"b":[["64683.84000000","0.14196000"],["64683.76000000","0.00000000"],["64683.75000000","0.01234000"],["64683.37000000","0.00791000"],["58215.60000000","0.00458000"],["51747.20000000","0.00000000"]],"a":[]}}
{"stream":"btcusdt@depth@100ms","data":{"e":"depthUpdate","E":1784410652315,"s":"BTCUSDT","U":97585367422,"u":97585367475,"b":[["64683.99000000","4.64969000"],["64683.98000000","0.00090000"],["64683.75000000","0.00018000"],["64683.37000000","0.00018000"],["64682.68000000","0.00773000"],["64682.67000000","0.00018000"],["64682.62000000","0.22036000"],["64681.92000000","0.00773000"],["64679.32000000","0.13410000"],["64677.71000000","0.15459000"],["64677.69000000","0.00000000"],["64677.42000000","0.00000000"],["64676.28000000","0.21416000"],["64675.73000000","0.00000000"],["64675.00000000","0.16558000"],["64524.30000000","0.02422000"],["58215.60000000","0.00448000"],["58215.59000000","0.00044000"],["51747.00000000","0.00000000"]],"a":[["64684.00000000","0.92669000"],["64684.90000000","0.00000000"],["64685.19000000","0.00306000"],["64685.23000000","0.00000000"],["64685.49000000","0.00124000"],["64685.71000000","0.00124000"],["64688.28000000","0.00015000"],["64689.09000000","0.00008000"],["64690.10000000","0.13781000"],["64690.12000000","0.00000000"],["64691.30000000","0.00000000"],["64700.76000000","0.08618000"],["64701.52000000","0.00000000"]]}}
{"stream":"btcusdt@depth@100ms","data":{"e":"depthUpdate","E":1784410652414,"s":"BTCUSDT","U":97585367476,"u":97585367519,"b":[["64683.99000000","4.70354000"],["64683.98000000","0.00082000"],["64683.84000000","0.14196000"],["64683.75000000","0.00000000"],["64683.37000000","0.00000000"],["64683.27000000","0.06601000"],["64682.68000000","0.00791000"],["64682.67000000","0.00000000"],["64682.62000000","0.22045000"],["64681.92000000","0.00791000"],["64681.85000000","0.01239000"],["64678.48000000","0.00973000"],["58215.60000000","0.00429000"]],"a":[["64684.00000000","0.92661000"],["64684.01000000","0.00082000"]]}}
{"stream":"btcusdt@depth@100ms","data":{"e":"depthUpdate","E":1784410652514,"s":"BTCUSDT","U":97585367520,"u":97585367528,"b":[["64683.99000000","4.71135000"],["58215.60000000","0.00448000"],["58215.59000000","0.00010000"],["58215.00000000","0.11017000"],["51747.20000000","0.00038000"]],"a":[]}}
{"stream":"btcusdt@depth@100ms","data":{"e":"depthUpdate","E":1784410652615,"s":"BTCUSDT","U":97585367529,"u":97585367539,"b":[["64654.90000000","0.02577000"],["64613.37000000","1.18468000"],["64611.26000000","0.18644000"],["64611.25000000","0.00036000"],["64588.25000000","0.00000000"],["59508.01000000","0.00017000"],["58215.60000000","0.00448000"],["51747.20000000","0.00000000"]],"a":[["64742.36000000","0.00000000"]]}}
{"stream":"btcusdt@depth@100ms","data":{"e":"depthUpdate","E":1784410652714,"s":"BTCUSDT","U":97585367540,"u":97585367547,"b":[["64654.90000000","0.00000000"],["64589.75000000","0.00111000"],["58215.60000000","0.00448000"]],"a":[["64742.36000000","0.00111000"],["64832.62000000","0.01866000"],["64856.88000000","0.00000000"]]}}
{"stream":"btcusdt@depth@100ms","data":{"e":"depthUpdate","E":1784410652815,"s":"BTCUSDT","U":97585367548,"u":97585367554,"b":[["64666.94000000","0.00008000"],["58215.60000000","0.00448000"]],"a":[["64705.76000000","0.00008000"]]}}
{"stream":"btcusdt@depth@100ms","data":{"e":"depthUpdate","E":1784410652915,"s":"BTCUSDT","U":97585367555,"u":97585367571,"b":[["64683.99000000","4.89491000"],["64683.98000000","0.00058000"],["58215.60000000","0.00429000"],["40000.00000000","261.36615000"]],"a":[["64684.00000000","0.76512000"],["64685.59000000","0.00008000"],["64688.28000000","0.00000000"]]}}
{"stream":"btcusdt@depth@100ms","data":{"e":"depthUpdate","E":1784410653014,"s":"BTCUSDT","U":97585367572,"u":97585367588,"b":[["64683.99000000","4.89468000"],["64683.98000000","0.00034000"],["58215.60000000","0.00448000"],["58215.59000000","0.00000000"],["51747.20000000","0.00038000"]],"a":[["64684.00000000","0.60561000"],["64691.28000000","0.00188000"]]}}
{"stream":"btcusdt@depth@100ms","data":{"e":"depthUpdate","E":1784410653116,"s":"BTCUSDT","U":97585367589,"u":97585367599,"b":[["63713.73000000","0.00030000"],["59508.01000000","0.00000000"],["58215.60000000","0.00448000"]],"a":[["64693.99000000","0.00773000"],["64694.66000000","0.00000000"],["65654.26000000","0.00030000"],["77816.97000000","0.00019000"]]}}
{"stream":"btcusdt@depth@100ms","data":{"e":"depthUpdate","E":1784410653214,"s":"BTCUSDT","U":97585367600,"u":97585367611,"b":[["64683.99000000","4.86375000"],["64682.65000000","0.22747000"],["64681.11000000","0.06732000"],["64680.82000000","0.00000000"],["64679.32000000","0.21618000"],["64677.72000000","0.38654000"],["64654.90000000","0.02577000"],["58215.60000000","0.00448000"],["51747.20000000","0.00000000"]],"a":[]}}
{"stream":"btcusdt@depth@100ms","data":{"e":"depthUpdate","E":1784410653314,"s":"BTCUSDT","U":97585367612,"u":97585367618,"b":[["64675.73000000","0.07818000"],["64675.00000000","0.00000000"],["64673.28000000","0.00000000"],["64672.68000000","0.77348000"],["64654.90000000","0.00000000"],["58215.60000000","0.00448000"]],"a":[]}}
{"stream":"btcusdt@depth@100ms","data":{"e":"depthUpdate","E":1784410653414,"s":"BTCUSDT","U":97585367619,"u":97585367641,"b":[["64683.99000000","4.86407000"],["64683.98000000","0.00058000"],["64682.68000000","0.00018000"],["64682.62000000","0.18045000"],["64681.93000000","0.00773000"],["64625.02000000","0.00000000"],["64560.09000000","0.00000000"],["58215.60000000","0.00429000"],["51747.00000000","0.00000000"]],"a":[["64684.00000000","0.93880000"],["64690.28000000","0.00025000"],["64691.28000000","0.00000000"],["64694.44000000","0.00773000"],["64695.28000000","0.00000000"]]}}
{"stream":"btcusdt@depth@100ms","data":{"e":"depthUpdate","E":1784410653514,"s":"BTCUSDT","U":97585367642,"u":97585367674,"b":[["64683.99000000","4.86375000"],["64683.98000000","0.00034000"],["64683.27000000","0.06601000"],["64682.68000000","0.00000000"],["64682.62000000","0.18045000"],["64681.93000000","0.00791000"],["64676.00000000","0.00106000"],["58215.60000000","0.00458000"],["58215.00000000","0.11037000"],["51747.20000000","0.00038000"]],"a":[["64684.00000000","0.53350000"],["64691.27000000","0.02187000"],["82071.40000000","0.00000000"]]}}
{"stream":"btcusdt@depth@100ms","data":{"e":"depthUpdate","E":1784410653614,"s":"BTCUSDT","U":97585367675,"u":97585367687,"b":[["64677.73000000","0.21415000"],["64676.28000000","0.00000000"],["64654.90000000","0.02577000"],["58215.60000000","0.00458000"],["58215.00000000","0.11017000"],["51747.20000000","0.00000000"],["51747.00000000","0.00000000"]],"a":[["64691.27000000","0.02000000"],["64691.28000000","0.00000000"]]}}
{"stream":"btcusdt@depth@100ms","data":{"e":"depthUpdate","E":1784410653715,"s":"BTCUSDT","U":97585367688,"u":97585367692,"b":[["58215.60000000","0.00458000"]],"a":[["64691.28000000","0.00188000"]]}}
{"stream":"btcusdt@depth@100ms","data":{"e":"depthUpdate","E":1784410653814,"s":"BTCUSDT","U":97585367693,"u":97585367700,"b":[["64666.94000000","0.00008000"],["64654.90000000","0.00000000"],["58215.60000000","0.00458000"]],"a":[["64705.76000000","0.00008000"]]}}
{"stream":"btcusdt@depth@100ms","data":{"e":"depthUpdate","E":1784410653914,"s":"BTCUSDT","U":97585367701,"u":97585367706,"b":[["58215.60000000","0.00458000"],["40000.00000000","261.36615000"]],"a":[]}}
{"stream":"btcusdt@depth@100ms","data":{"e":"depthUpdate","E":1784410654015,"s":"BTCUSDT","U":97585367707,"u":97585367715,"b":[["64683.02000000","0.00773000"],["64681.93000000","0.00018000"],["64677.73000000","0.00000000"],["64676.89000000","0.21415000"],["58215.60000000","0.00448000"],["58215.59000000","0.00010000"],["51747.20000000","0.00038000"]],"a":[["64684.00000000","0.53316000"],["64694.44000000","0.00000000"],["64694.79000000","0.00773000"],["82071.40000000","0.00010000"]]}}
{"stream":"btcusdt@depth@100ms","data":{"e":"depthUpdate","E":1784410654114,"s":"BTCUSDT","U":97585367716,"u":97585367736,"b":[["64683.99000000","4.86066000"],["64683.27000000","0.06601000"],["64683.02000000","0.00791000"],["64682.62000000","0.18045000"],["64681.93000000","0.00000000"],["63713.73000000","0.00030000"],["58215.60000000","0.00448000"]],"a":[["65654.26000000","0.00030000"]]}}
{"stream":"btcusdt@depth@100ms","data":{"e":"depthUpdate","E":1784410654215,"s":"BTCUSDT","U":97585367737,"u":97585367741,"b":[["58215.60000000","0.00448000"],["51747.20000000","0.00000000"]],"a":[]}}
{"stream":"btcusdt@depth@100ms","data":{"e":"depthUpdate","E":1784410654315,"s":"BTCUSDT","U":97585367742,"u":97585367747,"b":[["58215.60000000","0.00448000"],["51747.00000000","0.00000000"]],"a":[]}}
{"stream":"btcusdt@depth@100ms","data":{"e":"depthUpdate","E":1784410654414,"s":"BTCUSDT","U":97585367748,"u":97585367754,"b":[["64683.99000000","4.86089000"],["58215.60000000","0.00448000"]],"a":[["64684.00000000","0.53504000"],["64691.28000000","0.00000000"]]}}
{"stream":"btcusdt@depth@100ms","data":{"e":"depthUpdate","E":1784410654515,"s":"BTCUSDT","U":97585367755,"u":97585367762,"b":[["58215.60000000","0.00429000"],["51747.20000000","0.00038000"]],"a":[["64684.00000000","0.53316000"],["64691.28000000","0.00188000"]]}}
{"stream":"btcusdt@depth@100ms","data":{"e":"depthUpdate","E":1784410654614,"s":"BTCUSDT","U":97585367763,"u":97585367770,"b":[["64676.00000000","0.00606000"],["64644.81000000","0.00000000"],["58215.60000000","0.00448000"],["58215.00000000","0.11037000"],["51747.20000000","0.00000000"]],"a":[["64684.00000000","0.53290000"]]}}
{"stream":"btcusdt@depth@100ms","data":{"e":"depthUpdate","E":1784410654714,"s":"BTCUSDT","U":97585367771,"u":97585367779,"b":[["64683.99000000","4.86072000"],["64671.59000000","0.00000000"],["58215.60000000","0.00448000"],["58215.59000000","0.00000000"],["58215.00000000","0.11017000"]],"a":[["64695.42000000","0.00000000"]]}}
{"stream":"btcusdt@depth@100ms","data":{"e":"depthUpdate","E":1784410654814,"s":"BTCUSDT","U":97585367780,"u":97585367783,"b":[["58215.60000000","0.00448000"]],"a":[]}}
{"stream":"btcusdt@depth@100ms","data":{"e":"depthUpdate","E":1784410654914,"s":"BTCUSDT","U":97585367784,"u":97585367794,"b":[["64666.94000000","0.00008000"],["58215.60000000","0.00448000"],["51747.19000000","0.00000000"],["40000.00000000","261.36615000"]],"a":[["64705.76000000","0.00008000"]]}}
{"stream":"btcusdt@depth@100ms","data":{"e":"depthUpdate","E":1784410655017,"s":"BTCUSDT","U":97585367795,"u":97585367810,"b":[["64676.00000000","0.01406000"],["64671.56000000","0.87817000"],["58215.60000000","0.00429000"],["51747.20000000","0.00038000"],["51747.00000000","0.00000000"]],"a":[["64694.11000000","0.08000000"],["64694.79000000","0.00000000"],["64695.28000000","0.00773000"]]}}
{"stream":"btcusdt@depth@100ms","data":{"e":"depthUpdate","E":1784410655114,"s":"BTCUSDT","U":97585367811,"u":97585367819,"b":[["64683.99000000","4.85921000"],["63713.73000000","0.00030000"],["58215.60000000","0.00448000"],["58215.59000000","0.00010000"]],"a":[["65654.26000000","0.00030000"]]}}
{"stream":"btcusdt@depth@100ms","data":{"e":"depthUpdate","E":1784410655214,"s":"BTCUSDT","U":97585367820,"u":97585367827,"b":[["64683.60000000","0.01219000"],["58215.60000000","0.00448000"],["51747.20000000","0.00000000"]],"a":[["64684.00000000","0.52187000"],["64695.28000000","0.00000000"],["64695.99000000","0.00773000"]]}}
{"stream":"btcusdt@depth@100ms","data":{"e":"depthUpdate","E":1784410655314,"s":"BTCUSDT","U":97585367828,"u":97585367839,"b":[["64683.84000000","0.14196000"],["64683.60000000","0.01228000"],["64681.85000000","0.01230000"],["64654.90000000","0.02577000"],["58215.60000000","0.00448000"]],"a":[["64685.07000000","0.00008000"],["64685.19000000","0.00000000"]]}}
{"stream":"btcusdt@depth@100ms","data":{"e":"depthUpdate","E":1784410655414,"s":"BTCUSDT","U":97585367840,"u":97585367846,"b":[["64671.56000000","0.00000000"],["64666.51000000","0.00000000"],["64654.90000000","0.00000000"],["58215.60000000","0.00448000"]],"a":[]}}
{"stream":"btcusdt@depth@100ms","data":{"e":"depthUpdate","E":1784410655514,"s":"BTCUSDT","U":97585367847,"u":97585367853,"b":[["64683.99000000","4.95912000"],["64671.56000000","0.88000000"],["58215.60000000","0.00429000"],["51747.20000000","0.00038000"]],"a":[]}}
{"stream":"btcusdt@depth@100ms","data":{"e":"depthUpdate","E":1784410655616,"s":"BTCUSDT","U":97585367854,"u":97585367860,"b":[["58215.60000000","0.00448000"],["51747.20000000","0.00000000"]],"a":[["64684.00000000","0.52187000"],["64684.01000000","0.00074000"]]}}
{"stream":"btcusdt@depth@100ms","data":{"e":"depthUpdate","E":1784410655714,"s":"BTCUSDT","U":97585367861,"u":97585367867,"b":[["58215.60000000","0.00448000"],["58215.00000000","0.11037000"]],"a":[["64691.25000000","0.00192000"],["64691.28000000","0.00000000"]]}}
{"stream":"btcusdt@depth@100ms","data":{"e":"depthUpdate","E":1784410655814,"s":"BTCUSDT","U":97585367868,"u":97585367877,"b":[["64666.62000000","0.35103000"],["64557.49000000","0.09294000"],["64517.76000000","0.00000000"],["58215.60000000","0.00448000"],["58215.00000000","0.11017000"]],"a":[["64824.91000000","0.00000000"],["64877.06000000","0.09248000"]]}}
{"stream":"btcusdt@depth@100ms","data":{"e":"depthUpdate","E":1784410655914,"s":"BTCUSDT","U":97585367878,"u":97585367889,"b":[["64666.94000000","0.00008000"],["58215.60000000","0.00448000"],["51747.19000000","0.00020000"],["40000.00000000","261.36615000"]],"a":[["64691.25000000","0.00000000"],["64691.26000000","0.02219000"],["64705.76000000","0.00008000"]]}}
{"stream":"btcusdt@depth@100ms","data":{"e":"depthUpdate","E":1784410656014,"s":"BTCUSDT","U":97585367890,"u":97585367895,"b":[["58215.60000000","0.00448000"],["51747.20000000","0.00038000"],["51747.19000000","0.00000000"]],"a":[]}}
{"stream":"btcusdt@depth@100ms","data":{"e":"depthUpdate","E":1784410656115,"s":"BTCUSDT","U":97585367896,"u":97585367901,"b":[["63713.73000000","0.00030000"],["58215.60000000","0.00448000"]],"a":[["65654.26000000","0.00030000"]]}}
{"stream":"btcusdt@depth@100ms","data":{"e":"depthUpdate","E":1784410656215,"s":"BTCUSDT","U":97585367902,"u":97585367906,"b":[["58215.60000000","0.00448000"],["51747.20000000","0.00000000"]],"a":[]}}
{"stream":"btcusdt@depth@100ms","data":{"e":"depthUpdate","E":1784410656314,"s":"BTCUSDT","U":97585367907,"u":97585367919,"b":[["64683.99000000","4.95887000"],["58215.60000000","0.00448000"],["58215.59000000","0.00000000"],["58215.58000000","0.00010000"],["51747.00000000","0.00000000"]],"a":[["64684.00000000","0.52187000"],["64691.26000000","0.02032000"],["64691.27000000","0.02190000"]]}}
{"stream":"btcusdt@depth@100ms","data":{"e":"depthUpdate","E":1784410656414,"s":"BTCUSDT","U":97585367920,"u":97585367925,"b":[["64557.49000000","0.00000000"],["58215.60000000","0.00448000"]],"a":[["64877.06000000","0.00000000"]]}}
{"stream":"btcusdt@depth@100ms","data":{"e":"depthUpdate","E":1784410656514,"s":"BTCUSDT","U":97585367926,"u":97585367931,"b":[["64683.99000000","4.95856000"],["58215.60000000","0.00448000"],["51747.20000000","0.00038000"]],"a":[]}}
{"stream":"btcusdt@depth@100ms","data":{"e":"depthUpdate","E":1784410656614,"s":"BTCUSDT","U":97585367932,"u":97585367935,"b":[["58215.60000000","0.00448000"],["51747.20000000","0.00000000"],["33000.00000000","32.32056000"]],"a":[]}}
{"stream":"btcusdt@depth@100ms","data":{"e":"depthUpdate","E":1784410656714,"s":"BTCUSDT","U":97585367936,"u":97585367940,"b":[["58215.60000000","0.00448000"],["33000.00000000","32.31996000"]],"a":[]}}
{"stream":"btcusdt@depth@100ms","data":{"e":"depthUpdate","E":1784410656815,"s":"BTCUSDT","U":97585367941,"u":97585367945,"b":[["58215.60000000","0.00448000"],["58215.59000000","0.00010000"]],"a":[]}}
{"stream":"btcusdt@depth@100ms","data":{"e":"depthUpdate","E":1784410656916,"s":"BTCUSDT","U":97585367946,"u":97585367957,"b":[["64666.94000000","0.00008000"],["58215.60000000","0.00448000"],["58215.59000000","0.00000000"],["58215.00000000","0.11017000"],["40000.00000000","261.36615000"]],"a":[["64705.76000000","0.00008000"]]}}
{"stream":"btcusdt@depth@100ms","data":{"e":"depthUpdate","E":1784410657014,"s":"BTCUSDT","U":97585367958,"u":97585367963,"b":[["64676.00000000","0.02206000"],["58215.60000000","0.00448000"],["51747.20000000","0.00038000"]],"a":[]}}
{"stream":"btcusdt@depth@100ms","data":{"e":"depthUpdate","E":1784410657114,"s":"BTCUSDT","U":97585367964,"u":97585367972,"b":[["64659.88000000","0.00000000"],["63713.73000000","0.00030000"],["58215.60000000","0.00429000"]],"a":[["64722.45000000","0.00000000"],["65654.26000000","0.00030000"]]}}
{"stream":"btcusdt@depth@100ms","data":{"e":"depthUpdate","E":1784410657214,"s":"BTCUSDT","U":97585367973,"u":97585367979,"b":[["64676.18000000","0.00065000"],["64662.39000000","0.00905000"],["64651.86000000","0.00000000"],["58215.60000000","0.00448000"],["51747.20000000","0.00000000"]],"a":[]}}
{"stream":"btcusdt@depth@100ms","data":{"e":"depthUpdate","E":1784410657314,"s":"BTCUSDT","U":97585367980,"u":97585367983,"b":[["58215.60000000","0.00448000"]],"a":[]}}
{"stream":"btcusdt@depth@100ms","data":{"e":"depthUpdate","E":1784410657415,"s":"BTCUSDT","U":97585367984,"u":97585367995,"b":[["64683.99000000","4.95822000"],["64676.00000000","0.02700000"],["58215.60000000","0.00448000"],["58215.58000000","0.00000000"]],"a":[["64684.00000000","0.51913000"],["64691.27000000","0.02000000"],["64695.09000000","0.00773000"],["64695.99000000","0.00000000"]]}}
{"stream":"btcusdt@depth@100ms","data":{"e":"depthUpdate","E":1784410657514,"s":"BTCUSDT","U":97585367996,"u":97585368003,"b":[["58215.60000000","0.00448000"],["51747.20000000","0.00038000"]],"a":[["64684.00000000","0.51723000"],["64691.24000000","0.00000000"]]}}
{"stream":"btcusdt@depth@100ms","data":{"e":"depthUpdate","E":1784410657615,"s":"BTCUSDT","U":97585368004,"u":97585368008,"b":[["58215.60000000","0.00429000"],["51747.20000000","0.00000000"]],"a":[["64691.25000000","0.00190000"]]}}
{"stream":"btcusdt@depth@100ms","data":{"e":"depthUpdate","E":1784410657716,"s":"BTCUSDT","U":97585368009,"u":97585368011,"b":[["58215.60000000","0.00448000"]],"a":[]}}
{"stream":"btcusdt@depth@100ms","data":{"e":"depthUpdate","E":1784410657814,"s":"BTCUSDT","U":97585368012,"u":97585368019,"b":[["64538.64000000","0.00000000"],["58215.60000000","0.00458000"]],"a":[["64684.00000000","0.51414000"],["64834.53000000","0.00000000"]]}}
{"stream":"btcusdt@depth@100ms","data":{"e":"depthUpdate","E":1784410657914,"s":"BTCUSDT","U":97585368020,"u":97585368025,"b":[["58215.60000000","0.00458000"],["40000.00000000","261.36615000"]],"a":[]}}
{"stream":"btcusdt@depth@100ms","data":{"e":"depthUpdate","E":1784410658015,"s":"BTCUSDT","U":97585368026,"u":97585368037,"b":[["64666.94000000","0.00008000"],["64538.36000000","6.09640000"],["58215.60000000","0.00458000"],["58215.00000000","0.11017000"],["51747.20000000","0.00038000"]],"a":[["64705.76000000","0.00008000"],["64834.45000000","6.07365000"]]}}
{"stream":"btcusdt@depth@100ms","data":{"e":"depthUpdate","E":1784410658116,"s":"BTCUSDT","U":97585368038,"u":97585368048,"b":[["64654.90000000","0.02577000"],["64467.28000000","0.02422000"],["64415.31000000","0.00000000"],["63713.73000000","0.00030000"],["58215.60000000","0.00458000"]],"a":[["65654.26000000","0.00030000"]]}}
{"stream":"btcusdt@depth@100ms","data":{"e":"depthUpdate","E":1784410658214,"s":"BTCUSDT","U":97585368049,"u":97585368053,"b":[["64654.90000000","0.00000000"],["59508.01000000","0.00017000"],["58215.60000000","0.00458000"],["51747.20000000","0.00000000"]],"a":[]}}
{"stream":"btcusdt@depth@100ms","data":{"e":"depthUpdate","E":1784410658314,"s":"BTCUSDT","U":97585368054,"u":97585368078,"b":[["64683.99000000","4.92777000"],["64683.98000000","0.00074000"],["64683.02000000","0.00018000"],["64682.67000000","0.00773000"],["58215.60000000","0.00448000"],["58215.59000000","0.00010000"],["51747.00000000","0.00000000"]],"a":[["64684.00000000","0.84156000"],["64691.25000000","0.00000000"]]}}
{"stream":"btcusdt@depth@100ms","data":{"e":"depthUpdate","E":1784410658414,"s":"BTCUSDT","U":97585368079,"u":97585368094,"b":[["64683.99000000","4.92769000"],["64683.98000000","0.00066000"],["64683.60000000","0.01237000"],["64683.27000000","0.06601000"],["64683.02000000","0.00000000"],["64682.67000000","0.00782000"],["58215.60000000","0.00448000"]],"a":[["64684.00000000","0.66953000"]]}}
{"stream":"btcusdt@depth@100ms","data":{"e":"depthUpdate","E":1784410658516,"s":"BTCUSDT","U":97585368095,"u":97585368110,"b":[["64683.99000000","4.92729000"],["64683.98000000","0.00034000"],["58215.60000000","0.00448000"],["51747.20000000","0.00038000"]],"a":[["64684.00000000","0.51414000"]]}}
{"stream":"btcusdt@depth@100ms","data":{"e":"depthUpdate","E":1784410658614,"s":"BTCUSDT","U":97585368111,"u":97585368118,"b":[["58215.60000000","0.00448000"],["51747.20000000","0.00000000"]],"a":[["64684.00000000","0.51606000"],["64691.24000000","0.00000000"]]}}
{"stream":"btcusdt@depth@100ms","data":{"e":"depthUpdate","E":1784410658714,"s":"BTCUSDT","U":97585368119,"u":97585368123,"b":[["59508.01000000","0.00000000"],["58215.60000000","0.00448000"]],"a":[["64684.00000000","0.51602000"]]}}
{"stream":"btcusdt@depth@100ms","data":{"e":"depthUpdate","E":1784410658814,"s":"BTCUSDT","U":97585368124,"u":97585368134,"b":[["64467.28000000","0.00000000"],["64423.28000000","0.02422000"],["58215.60000000","0.00448000"]],"a":[["64684.00000000","0.51414000"],["64691.23000000","0.00000000"],["64691.24000000","0.00000000"]]}}
{"stream":"btcusdt@depth@100ms","data":{"e":"depthUpdate","E":1784410658914,"s":"BTCUSDT","U":97585368135,"u":97585368141,"b":[["58215.60000000","0.00448000"],["40000.00000000","261.36615000"]],"a":[["64691.22000000","0.00191000"]]}}
{"stream":"btcusdt@depth@100ms","data":{"e":"depthUpdate","E":1784410659014,"s":"BTCUSDT","U":97585368142,"u":97585368150,"b":[["64683.61000000","0.00773000"],["64682.67000000","0.00009000"],["64666.94000000","0.00008000"],["58215.60000000","0.00448000"],["51747.20000000","0.00038000"]],"a":[["64705.76000000","0.00008000"]]}}
{"stream":"btcusdt@depth@100ms","data":{"e":"depthUpdate","E":1784410659114,"s":"BTCUSDT","U":97585368151,"u":97585368174,"b":[["64683.84000000","0.14196000"],["64683.61000000","0.00791000"],["64683.60000000","0.00018000"],["64683.27000000","0.06592000"],["64682.67000000","0.00000000"],["63713.73000000","0.00030000"],["58215.60000000","0.00448000"]],"a":[["64684.00000000","0.51604000"],["64691.22000000","0.00000000"],["64695.09000000","0.00000000"],["64695.99000000","0.00773000"],["65654.26000000","0.00030000"]]}}
{"stream":"btcusdt@depth@100ms","data":{"e":"depthUpdate","E":1784410659216,"s":"BTCUSDT","U":97585368175,"u":97585368188,"b":[["64683.61000000","0.00791000"],["64683.60000000","0.00000000"],["64683.27000000","0.06601000"],["64681.85000000","0.01239000"],["58215.60000000","0.00429000"],["58215.00000000","0.11017000"],["51747.20000000","0.00000000"]],"a":[]}}
{"stream":"btcusdt@depth@100ms","data":{"e":"depthUpdate","E":1784410659314,"s":"BTCUSDT","U":97585368189,"u":97585368192,"b":[["58215.60000000","0.00448000"]],"a":[["64684.20000000","0.00021000"]]}}
{"stream":"btcusdt@depth@100ms","data":{"e":"depthUpdate","E":1784410659416,"s":"BTCUSDT","U":97585368193,"u":97585368200,"b":[["64683.99000000","4.92719000"],["58215.60000000","0.00448000"],["58215.59000000","0.00000000"],["51747.00000000","0.00000000"]],"a":[]}}
{"stream":"btcusdt@depth@100ms","data":{"e":"depthUpdate","E":1784410659514,"s":"BTCUSDT","U":97585368201,"u":97585368205,"b":[["58215.60000000","0.00448000"],["51747.20000000","0.00038000"]],"a":[]}}
{"stream":"btcusdt@depth@100ms","data":{"e":"depthUpdate","E":1784410659616,"s":"BTCUSDT","U":97585368206,"u":97585368212,"b":[["58215.60000000","0.00448000"],["51747.20000000","0.00000000"],["51747.00000000","0.00000000"]],"a":[]}}
{"stream":"btcusdt@depth@100ms","data":{"e":"depthUpdate","E":1784410659714,"s":"BTCUSDT","U":97585368213,"u":97585368216,"b":[["58215.60000000","0.00429000"],["51747.00000000","0.00200000"]],"a":[]}}
{"stream":"btcusdt@depth@100ms","data":{"e":"depthUpdate","E":1784410659814,"s":"BTCUSDT","U":97585368217,"u":97585368222,"b":[["64671.56000000","0.00000000"],["64666.62000000","0.00000000"],["58215.60000000","0.00448000"],["51747.00000000","0.00000000"]],"a":[]}}
{"stream":"btcusdt@depth@100ms","data":{"e":"depthUpdate","E":1784410659915,"s":"BTCUSDT","U":97585368223,"u":97585368231,"b":[["64671.56000000","0.88000000"],["64666.66000000","0.36452000"],["58215.60000000","0.00448000"],["40000.00000000","261.36615000"]],"a":[["68000.00000000","85.50828000"]]}}
{"stream":"btcusdt@depth@100ms","data":{"e":"depthUpdate","E":1784410660016,"s":"BTCUSDT","U":97585368232,"u":97585368240,"b":[["64666.94000000","0.00008000"],["64350.00000000","0.27100000"],["58215.60000000","0.00448000"],["51747.20000000","0.00038000"]],"a":[["64705.76000000","0.00008000"]]}}
{"stream":"btcusdt@depth@100ms","data":{"e":"depthUpdate","E":1784410660114,"s":"BTCUSDT","U":97585368241,"u":97585368248,"b":[["63713.73000000","0.00030000"],["58215.60000000","0.00448000"]],"a":[["65654.26000000","0.00030000"]]}}
{"stream":"btcusdt@depth@100ms","data":{"e":"depthUpdate","E":1784410660214,"s":"BTCUSDT","U":97585368249,"u":97585368257,"b":[["64683.99000000","4.93492000"],["64683.61000000","0.00018000"],["58215.60000000","0.00429000"],["58215.00000000","0.11037000"],["51747.20000000","0.00000000"]],"a":[["64684.00000000","0.51414000"],["64691.29000000","0.00189000"],["64693.99000000","0.00000000"],["64694.21000000","0.00773000"]]}}
{"stream":"btcusdt@depth@100ms","data":{"e":"depthUpdate","E":1784410660314,"s":"BTCUSDT","U":97585368258,"u":97585368275,"b":[["64683.99000000","4.92696000"],["64683.84000000","0.14196000"],["64683.62000000","0.00773000"],["64683.61000000","0.00000000"],["64681.85000000","0.01248000"],["64681.40000000","0.02509000"],["64580.50000000","0.00000000"],["58215.60000000","0.00448000"],["58215.00000000","0.11017000"],["51747.00000000","0.00000000"]],"a":[["64691.29000000","0.00000000"]]}}
{"stream":"btcusdt@depth@100ms","data":{"e":"depthUpdate","E":1784410660414,"s":"BTCUSDT","U":97585368276,"u":97585368295,"b":[["64683.99000000","4.92719000"],["64683.84000000","0.14196000"],["64683.62000000","0.00782000"],["64681.40000000","0.02500000"],["64647.37000000","0.42892000"],["64630.34000000","0.68956000"],["64628.29000000","0.00000000"],["64548.20000000","0.00000000"],["58215.60000000","0.00448000"]],"a":[["64684.00000000","0.51414000"],["64691.22000000","0.00187000"]]}}
{"stream":"btcusdt@depth@100ms","data":{"e":"depthUpdate","E":1784410660515,"s":"BTCUSDT","U":97585368296,"u":97585368303,"b":[["58215.60000000","0.00448000"],["51747.20000000","0.00038000"]],"a":[["64684.00000000","0.51602000"],["64691.22000000","0.00000000"],["77816.97000000","0.00000000"]]}}
{"stream":"btcusdt@depth@100ms","data":{"e":"depthUpdate","E":1784410660614,"s":"BTCUSDT","U":97585368304,"u":97585368310,"b":[["58215.60000000","0.00458000"],["51747.20000000","0.00000000"]],"a":[["64684.00000000","0.51568000"]]}}
{"stream":"btcusdt@depth@100ms","data":{"e":"depthUpdate","E":1784410660714,"s":"BTCUSDT","U":97585368311,"u":97585368317,"b":[["58215.60000000","0.00458000"]],"a":[["64684.00000000","0.51552000"]]}}
{"stream":"btcusdt@depth@100ms","data":{"e":"depthUpdate","E":1784410660818,"s":"BTCUSDT","U":97585368318,"u":97585368329,"b":[["64644.90000000","0.00250000"],["58215.60000000","0.00458000"]],"a":[["64684.00000000","0.51364000"],["64684.76000000","0.00000000"],["64684.77000000","0.00018000"],["64687.11000000","0.16441000"],["64687.72000000","0.00009000"],["64691.22000000","0.00188000"]]}}
{"stream":"btcusdt@depth@100ms","data":{"e":"depthUpdate","E":1784410660915,"s":"BTCUSDT","U":97585368330,"u":97585368349,"b":[["58215.60000000","0.00458000"],["51747.19000000","0.00000000"],["40000.00000000","261.36615000"]],"a":[["64684.00000000","0.51558000"],["64684.01000000","0.00074000"],["64684.77000000","0.00000000"],["64691.22000000","0.00000000"]]}}
{"stream":"btcusdt@depth@100ms","data":{"e":"depthUpdate","E":1784410661015,"s":"BTCUSDT","U":97585368350,"u":97585368356,"b":[["64557.49000000","0.09294000"],["58215.60000000","0.00458000"],["51747.20000000","0.00038000"]],"a":[["64877.06000000","0.09248000"]]}}
{"stream":"btcusdt@depth@100ms","data":{"e":"depthUpdate","E":1784410661114,"s":"BTCUSDT","U":97585368357,"u":97585368366,"b":[["64666.94000000","0.00008000"],["63713.73000000","0.00000000"],["58215.60000000","0.00458000"],["33000.00000000","32.32056000"]],"a":[["64705.76000000","0.00008000"],["65654.26000000","0.00000000"]]}}
{"stream":"btcusdt@depth@100ms","data":{"e":"depthUpdate","E":1784410661214,"s":"BTCUSDT","U":97585368367,"u":97585368378,"b":[["64683.98000000","0.00261000"],["63713.73000000","0.00030000"],["58215.60000000","0.00458000"],["51747.20000000","0.00000000"],["33000.00000000","32.31996000"]],"a":[["64705.33000000","0.00938000"],["65588.00000000","0.70080000"],["65654.26000000","0.00030000"]]}}
{"stream":"btcusdt@depth@100ms","data":{"e":"depthUpdate","E":1784410661314,"s":"BTCUSDT","U":97585368379,"u":97585368386,"b":[["64580.50000000","0.00154000"],["63296.78000000","0.00000000"],["58215.60000000","0.00439000"]],"a":[["64684.88000000","0.00306000"],["64684.95000000","0.00000000"],["64685.07000000","0.00000000"],["64689.76000000","0.07248000"]]}}
{"stream":"btcusdt@depth@100ms","data":{"e":"depthUpdate","E":1784410661414,"s":"BTCUSDT","U":97585368387,"u":97585368391,"b":[["58215.60000000","0.00458000"],["58215.00000000","0.11017000"]],"a":[]}}
{"stream":"btcusdt@depth@100ms","data":{"e":"depthUpdate","E":1784410661514,"s":"BTCUSDT","U":97585368392,"u":97585368403,"b":[["64683.99000000","4.92410000"],["64548.20000000","0.00154000"],["58215.60000000","0.00448000"],["58215.59000000","0.00010000"],["51747.20000000","0.00038000"]],"a":[["64684.00000000","0.51540000"],["64688.01000000","0.13354000"]]}}
{"stream":"btcusdt@depth@100ms","data":{"e":"depthUpdate","E":1784410661614,"s":"BTCUSDT","U":97585368404,"u":97585368412,"b":[["64683.99000000","4.93183000"],["64683.62000000","0.00009000"],["64557.49000000","0.00000000"],["63678.78000000","0.00039000"],["58215.60000000","0.00448000"],["51747.20000000","0.00000000"]],"a":[["64877.06000000","0.00000000"]]}}
{"stream":"btcusdt@depth@100ms","data":{"e":"depthUpdate","E":1784410661714,"s":"BTCUSDT","U":97585368413,"u":97585368427,"b":[["64683.84000000","0.14196000"],["64683.62000000","0.00000000"],["64681.40000000","0.02509000"],["64666.66000000","0.01874000"],["64654.90000000","0.02577000"],["64647.11000000","0.06000000"],["58215.60000000","0.00448000"]],"a":[["64703.03000000","0.00000000"],["64722.51000000","0.00000000"]]}}
{"stream":"btcusdt@depth@100ms","data":{"e":"depthUpdate","E":1784410661816,"s":"BTCUSDT","U":97585368428,"u":97585368441,"b":[["64654.90000000","0.00000000"],["58215.60000000","0.00429000"],["51747.00000000","0.00000000"]],"a":[["64684.95000000","0.00008000"],["71152.40000000","0.00008000"]]}}
{"stream":"btcusdt@depth@100ms","data":{"e":"depthUpdate","E":1784410661914,"s":"BTCUSDT","U":97585368442,"u":97585368447,"b":[["58215.60000000","0.00448000"],["40000.00000000","261.36615000"]],"a":[["71152.40000000","0.00000000"]]}}
{"stream":"btcusdt@depth@100ms","data":{"e":"depthUpdate","E":1784410662014,"s":"BTCUSDT","U":97585368448,"u":97585368461,"b":[["64683.99000000","4.92410000"],["64683.37000000","0.00773000"],["64666.68000000","0.34888000"],["64659.88000000","0.00015000"],["64647.28000000","0.70211000"],["58215.60000000","0.00448000"],["51747.20000000","0.00038000"],["51747.19000000","0.00000000"]],"a":[["64702.91000000","0.34634000"],["64722.32000000","0.69217000"],["64722.45000000","0.00015000"]]}}
{"stream":"btcusdt@depth@100ms","data":{"e":"depthUpdate","E":1784410662115,"s":"BTCUSDT","U":97585368462,"u":97585368478,"b":[["64683.99000000","4.92073000"],["64683.84000000","0.14196000"],["64683.37000000","0.00782000"],["64681.40000000","0.02500000"],["64666.94000000","0.00008000"],["58215.60000000","0.00448000"],["58215.59000000","0.00000000"]],"a":[["64684.00000000","0.51548000"],["64684.01000000","0.00082000"],["64705.76000000","0.00008000"]]}}
{"stream":"btcusdt@depth@100ms","data":{"e":"depthUpdate","E":1784410662214,"s":"BTCUSDT","U":97585368479,"u":97585368505,"b":[["64683.99000000","4.92121000"],["64683.98000000","0.00301000"],["64659.88000000","0.00000000"],["63713.73000000","0.00030000"],["58215.60000000","0.00448000"],["51747.20000000","0.00000000"]],"a":[["64684.00000000","0.68803000"],["64684.85000000","0.00008000"],["64684.88000000","0.00000000"],["64722.45000000","0.00000000"],["65250.18000000","0.00000000"],["65654.26000000","0.00030000"]]}}
{"stream":"btcusdt@depth@100ms","data":{"e":"depthUpdate","E":1784410662314,"s":"BTCUSDT","U":97585368506,"u":97585368515,"b":[["64683.98000000","0.00528000"],["64548.54000000","0.02422000"],["64524.30000000","0.00000000"],["58215.60000000","0.00429000"],["51747.00000000","0.00000000"]],"a":[["64684.00000000","0.68795000"],["64684.01000000","0.00074000"]]}}
{"stream":"btcusdt@depth@100ms","data":{"e":"depthUpdate","E":1784410662414,"s":"BTCUSDT","U":97585368516,"u":97585368525,"b":[["64683.99000000","4.92139000"],["64681.85000000","0.01230000"],["64659.88000000","0.00015000"],["58215.60000000","0.00448000"]],"a":[["64684.95000000","0.00000000"],["64722.45000000","0.00015000"]]}}
{"stream":"btcusdt@depth@100ms","data":{"e":"depthUpdate","E":1784410662514,"s":"BTCUSDT","U":97585368526,"u":97585368536,"b":[["64548.54000000","0.00000000"],["58215.60000000","0.00448000"],["58215.00000000","0.11017000"],["51747.20000000","0.00038000"]],"a":[["64686.12000000","0.18380000"],["64687.12000000","2.14000000"],["64751.81000000","0.00372000"]]}}
{"stream":"btcusdt@depth@100ms","data":{"e":"depthUpdate","E":1784410662615,"s":"BTCUSDT","U":97585368537,"u":97585368553,"b":[["58215.60000000","0.00448000"],["51747.20000000","0.00000000"]],"a":[["64684.00000000","0.68803000"],["64686.00000000","0.02718000"],["64686.11000000","0.00009000"],["64686.12000000","0.18398000"],["64687.72000000","0.00000000"],["64688.01000000","0.13336000"],["64881.39000000","0.00354000"]]}}
{"stream":"btcusdt@depth@100ms","data":{"e":"depthUpdate","E":1784410662714,"s":"BTCUSDT","U":97585368554,"u":97585368558,"b":[["58215.60000000","0.00448000"]],"a":[["65011.23000000","0.00257000"]]}}
{"stream":"btcusdt@depth@100ms","data":{"e":"depthUpdate","E":1784410662814,"s":"BTCUSDT","U":97585368559,"u":97585368564,"b":[["64660.46000000","0.10000000"],["64659.09000000","0.00000000"],["58215.60000000","0.00448000"]],"a":[]}}
{"stream":"btcusdt@depth@100ms","data":{"e":"depthUpdate","E":1784410662914,"s":"BTCUSDT","U":97585368565,"u":97585368570,"b":[["64683.99000000","4.92366000"],["61447.33000000","0.00000000"],["58215.60000000","0.00448000"],["40000.00000000","261.36615000"]],"a":[]}}
{"stream":"btcusdt@depth@100ms","data":{"e":"depthUpdate","E":1784410663014,"s":"BTCUSDT","U":97585368571,"u":97585368576,"b":[["58215.60000000","0.00448000"],["58214.35000000","0.00000000"],["51747.20000000","0.00038000"]],"a":[]}}
{"stream":"btcusdt@depth@100ms","data":{"e":"depthUpdate","E":1784410663116,"s":"BTCUSDT","U":97585368577,"u":97585368582,"b":[["64666.94000000","0.00000000"],["58215.60000000","0.00448000"]],"a":[["64705.76000000","0.00000000"],["65141.33000000","0.02159000"]]}}
{"stream":"btcusdt@depth@100ms","data":{"e":"depthUpdate","E":1784410663214,"s":"BTCUSDT","U":97585368583,"u":97585368607,"b":[["64683.99000000","4.92318000"],["64683.98000000","0.00488000"],["64666.94000000","0.00008000"],["63713.73000000","0.00030000"],["58215.60000000","0.00448000"],["51747.20000000","0.00000000"]],"a":[["64684.00000000","0.51548000"],["64684.82000000","0.00306000"],["64684.85000000","0.00000000"],["64705.76000000","0.00008000"],["65336.97000000","0.03387000"],["65654.26000000","0.00030000"]]}}
{"stream":"btcusdt@depth@100ms","data":{"e":"depthUpdate","E":1784410663314,"s":"BTCUSDT","U":97585368608,"u":97585368616,"b":[["64683.99000000","4.89998000"],["64683.37000000","0.00018000"],["58215.60000000","0.00448000"],["58215.59000000","0.00010000"]],"a":[["65402.31000000","0.00922000"]]}}
{"stream":"btcusdt@depth@100ms","data":{"e":"depthUpdate","E":1784410663414,"s":"BTCUSDT","U":97585368617,"u":97585368629,"b":[["64683.84000000","0.14196000"],["64683.37000000","0.00000000"],["64681.85000000","0.01248000"],["64654.90000000","0.02577000"],["58215.60000000","0.00429000"]],"a":[["65467.72000000","0.01137000"]]}}
{"stream":"btcusdt@depth@100ms","data":{"e":"depthUpdate","E":1784410663514,"s":"BTCUSDT","U":97585368630,"u":97585368637,"b":[["64683.55000000","0.01206000"],["64446.18000000","0.00000000"],["58215.60000000","0.00448000"],["51747.20000000","0.00038000"]],"a":[["64684.95000000","0.00008000"],["65533.19000000","0.01276000"]]}}
{"stream":"btcusdt@depth@100ms","data":{"e":"depthUpdate","E":1784410663615,"s":"BTCUSDT","U":97585368638,"u":97585368650,"b":[["64683.84000000","0.14196000"],["64654.90000000","0.00000000"],["64423.89000000","0.03099000"],["58215.60000000","0.00448000"],["58215.00000000","0.11017000"],["51747.20000000","0.00000000"]],"a":[]}}
{"stream":"btcusdt@depth@100ms","data":{"e":"depthUpdate","E":1784410663714,"s":"BTCUSDT","U":97585368651,"u":97585368654,"b":[["58215.60000000","0.00448000"]],"a":[]}}
{"stream":"btcusdt@depth@100ms","data":{"e":"depthUpdate","E":1784410663815,"s":"BTCUSDT","U":97585368655,"u":97585368658,"b":[["58215.60000000","0.00448000"]],"a":[]}}
{"stream":"btcusdt@depth@100ms","data":{"e":"depthUpdate","E":1784410663915,"s":"BTCUSDT","U":97585368659,"u":97585368663,"b":[["58215.60000000","0.00429000"],["40000.00000000","261.36615000"]],"a":[]}}
{"stream":"btcusdt@depth@100ms","data":{"e":"depthUpdate","E":1784410664014,"s":"BTCUSDT","U":97585368664,"u":97585368667,"b":[["58215.60000000","0.00448000"],["51747.20000000","0.00038000"]],"a":[]}}
{"stream":"btcusdt@depth@100ms","data":{"e":"depthUpdate","E":1784410664114,"s":"BTCUSDT","U":97585368668,"u":97585368673,"b":[["64683.99000000","4.89685000"],["58215.60000000","0.00448000"],["58215.59000000","0.00000000"],["58215.58000000","0.00010000"]],"a":[]}}
{"stream":"btcusdt@depth@100ms","data":{"e":"depthUpdate","E":1784410664214,"s":"BTCUSDT","U":97585368674,"u":97585368691,"b":[["64683.99000000","4.89667000"],["64683.55000000","0.01224000"],["64666.94000000","0.00008000"],["63713.73000000","0.00030000"],["58215.60000000","0.00448000"],["51747.20000000","0.00000000"]],"a":[["64684.00000000","0.51514000"],["64684.79000000","0.00008000"],["64684.82000000","0.00000000"],["64705.76000000","0.00008000"],["65654.26000000","0.00030000"]]}}
{"stream":"btcusdt@depth@100ms","data":{"e":"depthUpdate","E":1784410664315,"s":"BTCUSDT","U":97585368692,"u":97585368697,"b":[["58215.60000000","0.00448000"],["51747.00000000","0.00000000"]],"a":[]}}
{"stream":"btcusdt@depth@100ms","data":{"e":"depthUpdate","E":1784410664414,"s":"BTCUSDT","U":97585368698,"u":97585368700,"b":[["58215.60000000","0.00429000"]],"a":[]}}
{"stream":"btcusdt@depth@100ms","data":{"e":"depthUpdate","E":1784410664514,"s":"BTCUSDT","U":97585368701,"u":97585368706,"b":[["64654.90000000","0.02577000"],["58215.60000000","0.00448000"],["51747.20000000","0.00038000"]],"a":[["64684.95000000","0.00000000"]]}}
{"stream":"btcusdt@depth@100ms","data":{"e":"depthUpdate","E":1784410664616,"s":"BTCUSDT","U":97585368707,"u":97585368714,"b":[["64654.90000000","0.00000000"],["58215.60000000","0.00448000"],["58215.00000000","0.11017000"],["51747.20000000","0.00000000"]],"a":[]}}
{"stream":"btcusdt@depth@100ms","data":{"e":"depthUpdate","E":1784410664714,"s":"BTCUSDT","U":97585368715,"u":97585368718,"b":[["58215.60000000","0.00448000"]],"a":[]}}
{"stream":"btcusdt@depth@100ms","data":{"e":"depthUpdate","E":1784410664814,"s":"BTCUSDT","U":97585368719,"u":97585368722,"b":[["58215.60000000","0.00448000"]],"a":[]}}
{"stream":"btcusdt@depth@100ms","data":{"e":"depthUpdate","E":1784410664916,"s":"BTCUSDT","U":97585368723,"u":97585368729,"b":[["58215.60000000","0.00448000"],["40000.00000000","261.36615000"]],"a":[["64700.77000000","0.00000000"]]}}
{"stream":"btcusdt@depth@100ms","data":{"e":"depthUpdate","E":1784410665014,"s":"BTCUSDT","U":97585368730,"u":97585368734,"b":[["58215.60000000","0.00448000"],["51747.20000000","0.00038000"]],"a":[["64700.75000000","0.16032000"],["64700.76000000","0.00000000"],["64701.52000000","0.00000000"]]}}
{"stream":"btcusdt@depth@100ms","data":{"e":"depthUpdate","E":1784410665114,"s":"BTCUSDT","U":97585368735,"u":97585368738,"b":[["58215.60000000","0.00448000"]],"a":[]}}
{"stream":"btcusdt@depth@100ms","data":{"e":"depthUpdate","E":1784410665215,"s":"BTCUSDT","U":97585368739,"u":97585368761,"b":[["64674.12000000","0.00000000"],["64667.65000000","0.00000000"],["64666.94000000","0.00008000"],["64661.18000000","0.00000000"],["64654.71000000","0.01149000"],["64538.36000000","0.00000000"],["63713.73000000","0.00030000"],["58215.60000000","0.00448000"],["51747.20000000","0.00000000"]],"a":[["64684.77000000","0.00306000"],["64684.79000000","0.00000000"],["64700.00000000","0.80900000"],["64705.76000000","0.00008000"],["64706.47000000","0.00000000"],["64712.94000000","0.00000000"],["64834.45000000","0.00000000"],["65654.26000000","0.00030000"]]}}
{"stream":"btcusdt@depth@100ms","data":{"e":"depthUpdate","E":1784410665314,"s":"BTCUSDT","U":97585368762,"u":97585368775,"b":[["64674.12000000","0.00400000"],["64667.65000000","0.00400000"],["64661.18000000","0.00400000"],["64654.71000000","0.01549000"],["58215.60000000","0.00448000"]],"a":[["64684.00000000","0.51522000"],["64684.01000000","0.00082000"],["64700.00000000","0.81300000"],["64706.47000000","0.00400000"],["64712.94000000","0.00800000"]]}}
{"stream":"btcusdt@depth@100ms","data":{"e":"depthUpdate","E":1784410665415,"s":"BTCUSDT","U":97585368776,"u":97585368784,"b":[["64538.44000000","6.06122000"],["58215.60000000","0.00448000"],["51747.00000000","0.00000000"]],"a":[["64702.01000000","0.13340000"],["64832.97000000","5.98343000"]]}}
{"stream":"btcusdt@depth@100ms","data":{"e":"depthUpdate","E":1784410665514,"s":"BTCUSDT","U":97585368785,"u":97585368790,"b":[["64683.55000000","0.00018000"],["59508.01000000","0.00017000"],["58215.60000000","0.00429000"],["51747.20000000","0.00038000"]],"a":[]}}
{"stream":"btcusdt@depth@100ms","data":{"e":"depthUpdate","E":1784410665615,"s":"BTCUSDT","U":97585368791,"u":97585368807,"b":[["64683.84000000","0.14196000"],["64683.55000000","0.00000000"],["64681.40000000","0.02518000"],["64557.16000000","0.02422000"],["58215.60000000","0.00448000"],["51747.20000000","0.00000000"],["51747.00000000","0.00000000"],["33000.00000000","32.31996000"]],"a":[]}}
{"stream":"btcusdt@depth@100ms","data":{"e":"depthUpdate","E":1784410665714,"s":"BTCUSDT","U":97585368808,"u":97585368814,"b":[["58215.60000000","0.00448000"],["58215.00000000","0.11017000"]],"a":[["64684.95000000","0.00008000"]]}}
{"stream":"btcusdt@depth@100ms","data":{"e":"depthUpdate","E":1784410665814,"s":"BTCUSDT","U":97585368815,"u":97585368819,"b":[["64683.98000000","0.00715000"],["58215.60000000","0.00448000"]],"a":[]}}
{"stream":"btcusdt@depth@100ms","data":{"e":"depthUpdate","E":1784410665914,"s":"BTCUSDT","U":97585368820,"u":97585368833,"b":[["64683.99000000","4.89667000"],["64683.98000000","0.00733000"],["64681.40000000","0.02500000"],["58215.60000000","0.00448000"],["40000.00000000","261.36615000"]],"a":[]}}
{"stream":"btcusdt@depth@100ms","data":{"e":"depthUpdate","E":1784410666015,"s":"BTCUSDT","U":97585368834,"u":97585368839,"b":[["58215.60000000","0.00429000"],["51747.20000000","0.00038000"]],"a":[["64700.74000000","0.15568000"],["64700.75000000","0.00000000"],["64701.52000000","0.00000000"]]}}
{"stream":"btcusdt@depth@100ms","data":{"e":"depthUpdate","E":1784410666115,"s":"BTCUSDT","U":97585368840,"u":97585368845,"b":[["59508.01000000","0.00000000"],["58215.60000000","0.00448000"]],"a":[["64700.73000000","0.15556000"],["64700.74000000","0.00000000"],["64701.52000000","0.00000000"]]}}
{"stream":"btcusdt@depth@100ms","data":{"e":"depthUpdate","E":1784410666215,"s":"BTCUSDT","U":97585368846,"u":97585368856,"b":[["64666.94000000","0.00000000"],["63713.73000000","0.00030000"],["58215.60000000","0.00448000"],["51747.20000000","0.00000000"]],"a":[["64684.74000000","0.00008000"],["64684.77000000","0.00000000"],["64705.76000000","0.00000000"],["65654.26000000","0.00030000"]]}}
{"stream":"btcusdt@depth@100ms","data":{"e":"depthUpdate","E":1784410666315,"s":"BTCUSDT","U":97585368857,"u":97585368868,"b":[["64683.99000000","4.89644000"],["64666.94000000","0.00008000"],["58215.60000000","0.00448000"],["51747.00000000","0.00000000"]],"a":[["64684.00000000","0.51514000"],["64684.01000000","0.00074000"],["64684.95000000","0.00000000"],["64705.76000000","0.00008000"]]}}
{"stream":"btcusdt@depth@100ms","data":{"e":"depthUpdate","E":1784410666414,"s":"BTCUSDT","U":97585368869,"u":97585368884,"b":[["64683.99000000","4.77314000"],["64675.73000000","0.11471000"],["64673.28000000","0.77349000"],["64672.68000000","0.00000000"],["64671.57000000","0.53059000"],["64669.96000000","0.00000000"],["64557.49000000","0.09294000"],["58215.60000000","0.00448000"]],"a":[["64879.12000000","0.09247000"]]}}
{"stream":"btcusdt@depth@100ms","data":{"e":"depthUpdate","E":1784410666514,"s":"BTCUSDT","U":97585368885,"u":97585368888,"b":[["58215.60000000","0.00429000"],["51747.20000000","0.00038000"]],"a":[]}}
{"stream":"btcusdt@depth@100ms","data":{"e":"depthUpdate","E":1784410666619,"s":"BTCUSDT","U":97585368889,"u":97585368892,"b":[["58215.60000000","0.00448000"],["51747.20000000","0.00000000"]],"a":[]}}
{"stream":"btcusdt@depth@100ms","data":{"e":"depthUpdate","E":1784410666715,"s":"BTCUSDT","U":97585368893,"u":97585368896,"b":[["58215.60000000","0.00448000"]],"a":[]}}
{"stream":"btcusdt@depth@100ms","data":{"e":"depthUpdate","E":1784410666814,"s":"BTCUSDT","U":97585368897,"u":97585368903,"b":[["62727.67000000","0.00276000"],["58215.60000000","0.00448000"],["58215.59000000","0.00010000"],["58215.00000000","0.11037000"]],"a":[]}}
{"stream":"btcusdt@depth@100ms","data":{"e":"depthUpdate","E":1784410666915,"s":"BTCUSDT","U":97585368904,"u":97585368913,"b":[["58215.60000000","0.00448000"],["58215.59000000","0.00000000"],["58215.00000000","0.11017000"],["51747.19000000","0.00000000"],["40000.00000000","261.36615000"]],"a":[]}}
{"stream":"btcusdt@depth@100ms","data":{"e":"depthUpdate","E":1784410667014,"s":"BTCUSDT","U":97585368914,"u":97585368991,"b":[["64683.99000000","2.17282000"],["64683.98000000","0.00781000"],["64683.37000000","0.00000000"],["64682.67000000","0.00000000"],["64681.93000000","0.00773000"],["64681.90000000","0.10276000"],["64677.52000000","0.00809000"],["64676.89000000","0.00000000"],["64676.19000000","0.21416000"],["64675.73000000","0.00000000"],["64674.99000000","0.00000000"],["64674.56000000","0.18483000"],["64673.28000000","0.00000000"],["64671.94000000","0.77349000"],["64670.94000000","0.00000000"],["64654.90000000","0.02577000"],["64557.49000000","0.00000000"],["58215.60000000","0.00448000"],["51747.20000000","0.00038000"],["51747.00000000","0.00000000"]],"a":[["64684.00000000","0.67097000"],["64693.48000000","0.00773000"],["64694.21000000","0.00000000"],["64694.44000000","0.00773000"],["64695.99000000","0.00000000"],["64699.68000000","0.11483000"],["64700.73000000","0.00000000"],["64701.52000000","0.00000000"],["64879.12000000","0.00000000"]]}}
{"stream":"btcusdt@depth@100ms","data":{"e":"depthUpdate","E":1784410667115,"s":"BTCUSDT","U":97585368992,"u":97585369009,"b":[["64683.99000000","2.17266000"],["64683.98000000","0.00765000"],["64682.62000000","0.18045000"],["64681.93000000","0.00791000"],["64681.85000000","0.01230000"],["58215.60000000","0.00448000"]],"a":[["64689.84000000","0.00400000"],["64715.76000000","0.00000000"]]}}
{"stream":"btcusdt@depth@100ms","data":{"e":"depthUpdate","E":1784410667215,"s":"BTCUSDT","U":97585369010,"u":97585369022,"b":[["64662.39000000","0.00000000"],["64654.90000000","0.00000000"],["64651.87000000","0.00909000"],["63713.73000000","0.00030000"],["61449.79000000","0.00121000"],["58215.60000000","0.00448000"],["51747.20000000","0.00000000"]],"a":[["65654.26000000","0.00030000"]]}}
{"stream":"btcusdt@depth@100ms","data":{"e":"depthUpdate","E":1784410667315,"s":"BTCUSDT","U":97585369023,"u":97585369031,"b":[["64666.94000000","0.00008000"],["58215.60000000","0.00448000"],["51747.00000000","0.00000000"]],"a":[["64705.76000000","0.00008000"]]}}
{"stream":"btcusdt@depth@100ms","data":{"e":"depthUpdate","E":1784410667414,"s":"BTCUSDT","U":97585369032,"u":97585369062,"b":[["64683.99000000","2.13282000"],["64683.98000000","0.00781000"],["64674.56000000","0.00000000"],["64673.28000000","0.23533000"],["58215.60000000","0.00448000"]],"a":[["64684.00000000","0.85262000"],["64684.72000000","0.00306000"],["64684.74000000","0.00000000"],["64715.88000000","0.02999000"]]}}
{"stream":"btcusdt@depth@100ms","data":{"e":"depthUpdate","E":1784410667514,"s":"BTCUSDT","U":97585369063,"u":97585369077,"b":[["64663.59000000","0.00000000"],["64613.37000000","0.00000000"],["64611.26000000","0.51623000"],["64609.13000000","1.18468000"],["58215.60000000","0.00448000"],["51747.20000000","0.00038000"]],"a":[["64684.00000000","0.85318000"],["64684.01000000","0.00082000"],["64691.51000000","0.00000000"],["64718.06000000","0.00032000"],["77816.97000000","0.00019000"]]}}
{"stream":"btcusdt@depth@100ms","data":{"e":"depthUpdate","E":1784410667614,"s":"BTCUSDT","U":97585369078,"u":97585369085,"b":[["64633.99000000","0.00000000"],["58215.60000000","0.00429000"],["51747.20000000","0.00000000"]],"a":[["64686.11000000","0.00000000"],["64686.12000000","0.00018000"],["64687.72000000","0.00009000"]]}}
{"stream":"btcusdt@depth@100ms","data":{"e":"depthUpdate","E":1784410667714,"s":"BTCUSDT","U":97585369086,"u":97585369100,"b":[["64589.75000000","0.00111000"],["58215.60000000","0.00448000"]],"a":[["64684.00000000","0.85310000"],["64686.00000000","0.02718000"],["64686.12000000","0.00000000"],["64688.01000000","0.13354000"],["64742.36000000","0.00111000"]]}}
{"stream":"btcusdt@depth@100ms","data":{"e":"depthUpdate","E":1784410667814,"s":"BTCUSDT","U":97585369101,"u":97585369123,"b":[["64683.99000000","2.13282000"],["64683.98000000","0.00781000"],["58215.60000000","0.00448000"]],"a":[["64684.52000000","0.00124000"],["64685.71000000","0.00000000"],["65018.40000000","0.00299000"]]}}
{"stream":"btcusdt@depth@100ms","data":{"e":"depthUpdate","E":1784410667915,"s":"BTCUSDT","U":97585369124,"u":97585369131,"b":[["58215.60000000","0.00448000"],["58215.00000000","0.11017000"],["40000.00000000","261.36615000"]],"a":[]}}
{"stream":"btcusdt@depth@100ms","data":{"e":"depthUpdate","E":1784410668015,"s":"BTCUSDT","U":97585369132,"u":97585369155,"b":[["64683.99000000","3.02937000"],["64681.92000000","0.00018000"],["64680.69000000","0.00773000"],["64676.19000000","0.00000000"],["64675.51000000","0.21416000"],["64674.31000000","0.08462000"],["64673.28000000","0.00000000"],["64671.57000000","0.00000000"],["64671.06000000","0.11940000"],["64671.05000000","0.00000000"],["64669.46000000","0.53061000"],["64654.90000000","0.02577000"],["58215.60000000","0.00448000"],["58215.58000000","0.00000000"],["51747.20000000","0.00038000"],["51747.19000000","0.00000000"]],"a":[["64684.95000000","0.00008000"],["64692.69000000","0.00773000"],["64693.48000000","0.00000000"],["64693.75000000","0.00773000"],["64694.44000000","0.00000000"],["64696.94000000","0.58011000"],["64699.48000000","0.00000000"]]}}
{"stream":"btcusdt@depth@100ms","data":{"e":"depthUpdate","E":1784410668114,"s":"BTCUSDT","U":97585369156,"u":97585369167,"b":[["64681.93000000","0.00791000"],["64681.92000000","0.00000000"],["64681.85000000","0.01248000"],["64654.90000000","0.00000000"],["58215.60000000","0.00429000"]],"a":[]}}
{"stream":"btcusdt@depth@100ms","data":{"e":"depthUpdate","E":1784410668214,"s":"BTCUSDT","U":97585369168,"u":97585369195,"b":[["64683.99000000","3.02921000"],["64683.98000000","0.00765000"],["64671.06000000","0.12249000"],["63713.73000000","0.00030000"],["58215.60000000","0.00448000"],["51747.20000000","0.00000000"]],"a":[["64684.00000000","0.67097000"],["64684.01000000","0.00074000"],["64684.69000000","0.00008000"],["64684.72000000","0.00000000"],["64692.69000000","0.00000000"],["64692.94000000","0.00000000"],["64693.35000000","0.00773000"],["64693.75000000","0.00000000"],["64694.93000000","0.00773000"],["64696.94000000","0.00000000"],["64698.58000000","0.58011000"],["64698.59000000","0.00000000"],["65654.26000000","0.00030000"]]}}
{"stream":"btcusdt@depth@100ms","data":{"e":"depthUpdate","E":1784410668314,"s":"BTCUSDT","U":97585369196,"u":97585369215,"b":[["64683.99000000","3.02887000"],["64666.94000000","0.00008000"],["64611.25000000","1.18504000"],["64609.13000000","0.00000000"],["58215.60000000","0.00703000"],["58215.59000000","0.00010000"],["51747.00000000","0.00000000"]],"a":[["64684.00000000","0.67097000"],["64684.37000000","0.00124000"],["64691.13000000","0.00048000"],["64705.76000000","0.00008000"]]}}
{"stream":"btcusdt@depth@100ms","data":{"e":"depthUpdate","E":1784410668415,"s":"BTCUSDT","U":97585369216,"u":97585369229,"b":[["64683.99000000","3.02903000"],["64683.98000000","0.00781000"],["64633.99000000","0.00162000"],["58215.60000000","0.00703000"]],"a":[["64691.13000000","0.00000000"],["64691.15000000","0.00048000"],["64702.01000000","0.00000000"]]}}
{"stream":"btcusdt@depth@100ms","data":{"e":"depthUpdate","E":1784410668514,"s":"BTCUSDT","U":97585369230,"u":97585369241,"b":[["64683.99000000","3.33504000"],["58215.60000000","0.00703000"],["51747.20000000","0.00038000"]],"a":[["64691.15000000","0.00000000"],["64691.16000000","0.00048000"]]}}
{"stream":"btcusdt@depth@100ms","data":{"e":"depthUpdate","E":1784410668614,"s":"BTCUSDT","U":97585369242,"u":97585369260,"b":[["64683.99000000","3.33448000"],["64683.98000000","0.00733000"],["64654.90000000","0.02577000"],["58215.60000000","0.00684000"],["51747.20000000","0.00000000"]],"a":[["64684.00000000","0.51514000"]]}}
{"stream":"btcusdt@depth@100ms","data":{"e":"depthUpdate","E":1784410668716,"s":"BTCUSDT","U":97585369261,"u":97585369272,"b":[["64654.90000000","0.02577000"],["58215.60000000","0.00703000"]],"a":[["64684.00000000","0.51506000"]]}}
{"stream":"btcusdt@depth@100ms","data":{"e":"depthUpdate","E":1784410668816,"s":"BTCUSDT","U":97585369273,"u":97585369308,"b":[["64683.99000000","3.33560000"],["64683.98000000","0.00789000"],["64654.90000000","0.00000000"],["64472.46000000","0.02808000"],["64423.28000000","0.00000000"],["59674.29000000","0.00837000"],["58215.60000000","0.00703000"]],"a":[["64684.00000000","0.85116000"],["64691.16000000","0.00000000"]]}}
{"stream":"btcusdt@depth@100ms","data":{"e":"depthUpdate","E":1784410668914,"s":"BTCUSDT","U":97585369309,"u":97585369316,"b":[["58215.60000000","0.00703000"],["51747.00000000","0.00000000"],["40000.00000000","261.36615000"]],"a":[]}}
{"stream":"btcusdt@depth@100ms","data":{"e":"depthUpdate","E":1784410669014,"s":"BTCUSDT","U":97585369317,"u":97585369331,"b":[["64683.99000000","3.49333000"],["64681.41000000","0.00773000"],["64680.69000000","0.00000000"],["58215.60000000","0.00703000"],["58215.00000000","0.11017000"],["51747.20000000","0.00038000"]],"a":[["64684.00000000","0.85133000"],["64694.21000000","0.00773000"],["64694.93000000","0.00000000"],["64702.13000000","0.13045000"]]}}
{"stream":"btcusdt@depth@100ms","data":{"e":"depthUpdate","E":1784410669114,"s":"BTCUSDT","U":97585369332,"u":97585369347,"b":[["64683.99000000","3.49341000"],["64681.85000000","0.01248000"],["64681.75000000","0.00773000"],["64681.41000000","0.00000000"],["58215.60000000","0.00703000"]],"a":[["64684.00000000","0.69096000"],["64684.67000000","0.00306000"],["64684.69000000","0.00000000"],["64693.35000000","0.00000000"],["64693.48000000","0.00773000"],["64694.21000000","0.00000000"],["64694.33000000","0.00773000"]]}}
{"stream":"btcusdt@depth@100ms","data":{"e":"depthUpdate","E":1784410669215,"s":"BTCUSDT","U":97585369348,"u":97585369361,"b":[["64681.85000000","0.01248000"],["64658.24000000","0.00000000"],["64641.72000000","0.00000000"],["64625.19000000","0.00000000"],["64608.66000000","0.00000000"],["64592.13000000","0.00000000"],["64575.61000000","0.00000000"],["64559.08000000","0.00000000"],["64542.55000000","0.00000000"],["64526.02000000","0.00000000"],["64509.50000000","0.00000000"],["64492.97000000","0.00000000"],["64476.44000000","0.00000000"],["64459.91000000","0.00000000"],["64443.39000000","0.00000000"],["63713.73000000","0.00030000"],["58215.60000000","0.00703000"],["51747.20000000","0.00000000"]],"a":[["64684.00000000","0.69104000"],["64684.01000000","0.00082000"],["64707.83000000","0.00000000"],["65654.26000000","0.00030000"]]}}
{"stream":"btcusdt@depth@100ms","data":{"e":"depthUpdate","E":1784410669315,"s":"BTCUSDT","U":97585369362,"u":97585369369,"b":[["64683.98000000","0.01016000"],["64666.94000000","0.00008000"],["58215.60000000","0.00703000"]],"a":[["64705.76000000","0.00008000"]]}}
{"stream":"btcusdt@depth@100ms","data":{"e":"depthUpdate","E":1784410669415,"s":"BTCUSDT","U":97585369370,"u":97585369373,"b":[["58215.60000000","0.00703000"]],"a":[]}}
{"stream":"btcusdt@depth@100ms","data":{"e":"depthUpdate","E":1784410669514,"s":"BTCUSDT","U":97585369374,"u":97585369390,"b":[["64683.99000000","3.97598000"],["64676.65000000","0.21415000"],["64675.51000000","0.00000000"],["58215.60000000","0.00703000"],["51747.20000000","0.00038000"]],"a":[["64684.00000000","0.69056000"],["64691.14000000","0.00047000"],["64694.33000000","0.00000000"],["64694.69000000","0.00773000"],["64698.58000000","0.00000000"],["64699.13000000","0.58011000"]]}}
{"stream":"btcusdt@depth@100ms","data":{"e":"depthUpdate","E":1784410669615,"s":"BTCUSDT","U":97585369391,"u":97585369396,"b":[["58215.60000000","0.00703000"],["51747.20000000","0.00000000"]],"a":[["64702.13000000","0.00000000"]]}}
{"stream":"btcusdt@depth@100ms","data":{"e":"depthUpdate","E":1784410669714,"s":"BTCUSDT","U":97585369397,"u":97585369408,"b":[["64683.99000000","3.97598000"],["64664.57000000","0.00000000"],["64651.20000000","0.00000000"],["64637.84000000","0.00000000"],["64624.47000000","0.00000000"],["64611.10000000","0.00000000"],["64597.74000000","0.00000000"],["64584.37000000","0.00000000"],["64571.01000000","0.00000000"],["64557.64000000","0.00000000"],["64544.27000000","0.00000000"],["64530.91000000","0.00000000"],["64517.54000000","0.00000000"],["64504.18000000","0.00000000"],["64490.81000000","0.00000000"],["58215.60000000","0.00703000"]],"a":[["64684.00000000","0.69048000"],["64691.14000000","0.00000000"],["64691.15000000","0.00047000"],["64704.67000000","0.00000000"],["64718.03000000","0.00000000"]]}}
{"stream":"btcusdt@depth@100ms","data":{"e":"depthUpdate","E":1784410669814,"s":"BTCUSDT","U":97585369409,"u":97585369415,"b":[["64676.18000000","0.00000000"],["64571.03000000","0.00154000"],["64571.02000000","0.00000000"],["64570.02000000","0.00000000"],["58215.60000000","0.00703000"]],"a":[]}}
{"stream":"btcusdt@depth@100ms","data":{"e":"depthUpdate","E":1784410669914,"s":"BTCUSDT","U":97585369416,"u":97585369429,"b":[["64683.99000000","3.97564000"],["64472.46000000","0.00386000"],["64423.28000000","0.02422000"],["58215.60000000","0.00703000"],["58215.59000000","0.00000000"],["58215.58000000","0.00010000"],["40000.00000000","261.36615000"]],"a":[["64684.00000000","0.69056000"],["64684.57000000","0.00017000"],["64684.58000000","0.18380000"],["64687.72000000","0.00000000"]]}}
{"stream":"btcusdt@depth@100ms","data":{"e":"depthUpdate","E":1784410670014,"s":"BTCUSDT","U":97585369430,"u":97585369451,"b":[["64683.99000000","4.41626000"],["64682.67000000","0.00773000"],["64681.93000000","0.00018000"],["58215.60000000","0.00703000"],["58215.00000000","0.11017000"],["51747.20000000","0.00038000"]],"a":[["64684.00000000","0.69056000"],["64684.58000000","0.18398000"],["64688.01000000","0.13336000"],["64693.48000000","0.00000000"],["64693.75000000","0.00773000"],["64699.68000000","0.00000000"],["64701.52000000","0.44683000"]]}}
{"stream":"btcusdt@depth@100ms","data":{"e":"depthUpdate","E":1784410670114,"s":"BTCUSDT","U":97585369452,"u":97585369475,"b":[["64683.99000000","4.43311000"],["64683.98000000","0.01016000"],["64683.27000000","0.06601000"],["64682.67000000","0.00791000"],["64682.62000000","0.18045000"],["64681.93000000","0.00000000"],["58215.60000000","0.00703000"]],"a":[["64684.00000000","0.69064000"],["64684.01000000","0.00090000"],["64702.19000000","0.13157000"]]}}
{"stream":"btcusdt@depth@100ms","data":{"e":"depthUpdate","E":1784410670214,"s":"BTCUSDT","U":97585369476,"u":97585369491,"b":[["64438.86000000","0.00561000"],["63713.73000000","0.00030000"],["58215.60000000","0.00684000"],["58215.59000000","0.00000000"],["58215.58000000","0.00000000"],["51747.20000000","0.00000000"]],"a":[["64684.00000000","0.69063000"],["64684.65000000","0.00008000"],["64684.67000000","0.00000000"],["64764.54000000","0.00000000"],["65654.26000000","0.00030000"]]}}
{"stream":"btcusdt@depth@100ms","data":{"e":"depthUpdate","E":1784410670314,"s":"BTCUSDT","U":97585369492,"u":97585369503,"b":[["64666.94000000","0.00000000"],["64580.50000000","0.00000000"],["64455.45000000","0.00561000"],["58215.60000000","0.00703000"],["51747.00000000","0.00000000"]],"a":[["64684.00000000","0.69103000"],["64684.01000000","0.00082000"],["64691.15000000","0.00000000"],["64705.76000000","0.00000000"]]}}
{"stream":"btcusdt@depth@100ms","data":{"e":"depthUpdate","E":1784410670415,"s":"BTCUSDT","U":97585369504,"u":97585369515,"b":[["64666.94000000","0.00008000"],["64571.04000000","0.00154000"],["64571.03000000","0.00000000"],["64570.02000000","0.00000000"],["64548.20000000","0.00000000"],["64472.04000000","0.00561000"],["58215.60000000","0.00703000"],["51747.00000000","0.00000000"]],"a":[["64705.76000000","0.00008000"]]}}
{"stream":"btcusdt@depth@100ms","data":{"e":"depthUpdate","E":1784410670514,"s":"BTCUSDT","U":97585369516,"u":97585369521,"b":[["64488.63000000","0.00561000"],["58215.60000000","0.00703000"],["51747.20000000","0.00038000"]],"a":[]}}
{"stream":"btcusdt@depth@100ms","data":{"e":"depthUpdate","E":1784410670614,"s":"BTCUSDT","U":97585369522,"u":97585369527,"b":[["64505.22000000","0.00561000"],["58215.60000000","0.00703000"],["51747.20000000","0.00000000"]],"a":[]}}
{"stream":"btcusdt@depth@100ms","data":{"e":"depthUpdate","E":1784410670714,"s":"BTCUSDT","U":97585369528,"u":97585369538,"b":[["64683.99000000","4.43311000"],["64683.98000000","0.01016000"],["64683.02000000","0.00773000"],["64682.67000000","0.00018000"],["64521.81000000","0.00560000"],["64486.52000000","0.00561000"],["58215.60000000","0.00684000"]],"a":[["64764.54000000","0.09473000"]]}}
{"stream":"btcusdt@depth@100ms","data":{"e":"depthUpdate","E":1784410670814,"s":"BTCUSDT","U":97585369539,"u":97585369551,"b":[["64683.27000000","0.06601000"],["64683.02000000","0.00791000"],["64682.67000000","0.00000000"],["64538.40000000","0.00560000"],["64499.93000000","0.00561000"],["58215.60000000","0.00703000"]],"a":[]}}
{"stream":"btcusdt@depth@100ms","data":{"e":"depthUpdate","E":1784410670916,"s":"BTCUSDT","U":97585369552,"u":97585369560,"b":[["64554.99000000","0.01434000"],["64513.34000000","0.00560000"],["58215.60000000","0.00703000"],["40000.00000000","261.36615000"]],"a":[["64700.13000000","0.10611000"],["64701.52000000","0.00000000"]]}}
{"stream":"btcusdt@depth@100ms","data":{"e":"depthUpdate","E":1784410671015,"s":"BTCUSDT","U":97585369561,"u":97585369570,"b":[["64683.02000000","0.00018000"],["64682.67000000","0.00773000"],["64571.58000000","0.00560000"],["64526.75000000","0.00560000"],["58215.60000000","0.00703000"],["58215.00000000","0.11017000"],["51747.20000000","0.00038000"]],"a":[]}}
{"stream":"btcusdt@depth@100ms","data":{"e":"depthUpdate","E":1784410671114,"s":"BTCUSDT","U":97585369571,"u":97585369590,"b":[["64683.99000000","4.43311000"],["64683.98000000","0.01016000"],["64683.27000000","0.06601000"],["64683.02000000","0.00000000"],["64682.67000000","0.00791000"],["64671.56000000","0.00000000"],["64588.16000000","0.01120000"],["59508.01000000","0.00017000"],["58215.60000000","0.00703000"]],"a":[["64694.11000000","0.00000000"]]}}
{"stream":"btcusdt@depth@100ms","data":{"e":"depthUpdate","E":1784410671215,"s":"BTCUSDT","U":97585369591,"u":97585369602,"b":[["64604.75000000","0.00560000"],["64540.17000000","0.00560000"],["64057.23000000","0.00000000"],["63713.73000000","0.00030000"],["58215.60000000","0.00703000"],["51747.20000000","0.00000000"]],"a":[["65654.26000000","0.00030000"]]}}
{"stream":"btcusdt@depth@100ms","data":{"e":"depthUpdate","E":1784410671314,"s":"BTCUSDT","U":97585369603,"u":97585369608,"b":[["64621.34000000","0.01120000"],["64580.50000000","0.00154000"],["64553.58000000","0.00560000"],["58215.60000000","0.00703000"]],"a":[["64684.63000000","0.00306000"],["64684.65000000","0.00000000"]]}}
{"stream":"btcusdt@depth@100ms","data":{"e":"depthUpdate","E":1784410671415,"s":"BTCUSDT","U":97585369609,"u":97585369626,"b":[["64671.57000000","0.67325000"],["64666.94000000","0.00008000"],["64637.93000000","0.00559000"],["64566.99000000","0.00560000"],["64548.20000000","0.00154000"],["58215.60000000","0.00703000"],["51747.00000000","0.00000000"]],"a":[["64684.00000000","0.69111000"],["64684.01000000","0.00090000"],["64695.12000000","0.19934000"],["64705.76000000","0.00008000"]]}}
{"stream":"btcusdt@depth@100ms","data":{"e":"depthUpdate","E":1784410671514,"s":"BTCUSDT","U":97585369627,"u":97585369633,"b":[["64654.52000000","0.01118000"],["64580.40000000","0.00560000"],["58215.60000000","0.00703000"],["51747.20000000","0.00038000"]],"a":[]}}
{"stream":"btcusdt@depth@100ms","data":{"e":"depthUpdate","E":1784410671614,"s":"BTCUSDT","U":97585369634,"u":97585369651,"b":[["64681.75000000","0.00000000"],["64681.41000000","0.00773000"],["64611.25000000","0.00036000"],["64609.13000000","1.18468000"],["64593.81000000","0.00560000"],["64270.02000000","0.00038000"],["59508.01000000","0.00000000"],["58215.60000000","0.00703000"],["51747.20000000","0.00000000"],["51747.00000000","0.00000000"]],"a":[["64684.00000000","0.69111000"],["64693.35000000","0.00773000"],["64693.75000000","0.00000000"]]}}
{"stream":"btcusdt@depth@100ms","data":{"e":"depthUpdate","E":1784410671714,"s":"BTCUSDT","U":97585369652,"u":97585369663,"b":[["64681.85000000","0.01248000"],["64607.23000000","0.00560000"],["58215.60000000","0.00703000"],["33000.00000000","32.31996000"]],"a":[["64704.29000000","0.00559000"]]}}
{"stream":"btcusdt@depth@100ms","data":{"e":"depthUpdate","E":1784410671815,"s":"BTCUSDT","U":97585369664,"u":97585369669,"b":[["64683.99000000","4.43303000"],["64620.64000000","0.00560000"],["58215.60000000","0.00703000"]],"a":[["64879.12000000","0.09247000"],["71152.40000000","0.00008000"]]}}
{"stream":"btcusdt@depth@100ms","data":{"e":"depthUpdate","E":1784410671914,"s":"BTCUSDT","U":97585369670,"u":97585369685,"b":[["64683.99000000","4.43303000"],["64634.05000000","0.00560000"],["58215.60000000","0.00703000"],["40000.00000000","261.36615000"]],"a":[["64684.00000000","0.69103000"],["65422.03000000","0.00598000"],["71152.40000000","0.00000000"]]}}
{"stream":"btcusdt@depth@100ms","data":{"e":"depthUpdate","E":1784410672014,"s":"BTCUSDT","U":97585369686,"u":97585369696,"b":[["64683.99000000","4.37598000"],["64647.46000000","0.00559000"],["64572.14000000","0.00154000"],["64571.04000000","0.00000000"],["64557.49000000","0.09294000"],["58215.60000000","0.00703000"],["51747.20000000","0.00038000"]],"a":[["64693.35000000","0.00000000"],["64693.75000000","0.00773000"]]}}
{"stream":"btcusdt@depth@100ms","data":{"e":"depthUpdate","E":1784410672114,"s":"BTCUSDT","U":97585369697,"u":97585369713,"b":[["64683.99000000","4.37598000"],["64683.98000000","0.01016000"],["64683.02000000","0.00773000"],["64682.67000000","0.00018000"],["64660.88000000","0.00559000"],["58215.60000000","0.00703000"],["58215.00000000","0.11017000"]],"a":[["64684.00000000","0.69055000"],["64684.20000000","0.00000000"],["64691.22000000","0.00048000"],["64700.13000000","0.00000000"],["64701.52000000","0.44730000"],["64705.79000000","0.00000000"]]}}
{"stream":"btcusdt@depth@100ms","data":{"e":"depthUpdate","E":1784410672216,"s":"BTCUSDT","U":97585369714,"u":97585369733,"b":[["64683.27000000","0.06601000"],["64683.02000000","0.00791000"],["64682.67000000","0.00000000"],["63713.73000000","0.00030000"],["58215.60000000","0.00703000"],["51747.20000000","0.00000000"]],"a":[["64684.61000000","0.00008000"],["64684.63000000","0.00000000"],["64705.32000000","0.00922000"],["64705.33000000","0.00000000"],["65654.26000000","0.00030000"]]}}
{"stream":"btcusdt@depth@100ms","data":{"e":"depthUpdate","E":1784410672318,"s":"BTCUSDT","U":97585369734,"u":97585369744,"b":[["64683.99000000","4.37575000"],["64654.90000000","0.02577000"],["64647.53000000","0.00807000"],["64642.33000000","0.00000000"],["58215.60000000","0.00684000"],["51747.00000000","0.00000000"]],"a":[["64684.37000000","0.00000000"],["64701.11000000","0.00559000"]]}}
{"stream":"btcusdt@depth@100ms","data":{"e":"depthUpdate","E":1784410672417,"s":"BTCUSDT","U":97585369745,"u":97585369768,"b":[["64683.99000000","4.37575000"],["64666.94000000","0.00008000"],["64551.35000000","0.00807000"],["64546.37000000","0.00000000"],["58215.60000000","0.00713000"]],"a":[["64684.00000000","0.69032000"],["64684.01000000","0.00082000"],["64700.13000000","0.00000000"],["64701.51000000","0.43058000"],["64701.52000000","0.00000000"],["64705.76000000","0.00008000"],["64714.52000000","0.00559000"]]}}
{"stream":"btcusdt@depth@100ms","data":{"e":"depthUpdate","E":1784410672515,"s":"BTCUSDT","U":97585369769,"u":97585369775,"b":[["64683.99000000","4.36740000"],["64654.90000000","0.00000000"],["58215.60000000","0.00713000"],["51747.20000000","0.00038000"]],"a":[]}}
{"stream":"btcusdt@depth@100ms","data":{"e":"depthUpdate","E":1784410672614,"s":"BTCUSDT","U":97585369776,"u":97585369785,"b":[["64613.37000000","1.18468000"],["64611.26000000","0.18644000"],["64609.13000000","0.00000000"],["64557.49000000","0.00000000"],["58215.60000000","0.00713000"],["51747.20000000","0.00000000"]],"a":[["64879.12000000","0.00000000"]]}}
{"stream":"btcusdt@depth@100ms","data":{"e":"depthUpdate","E":1784410672714,"s":"BTCUSDT","U":97585369786,"u":97585369790,"b":[["64683.99000000","4.36967000"],["58215.60000000","0.00713000"]],"a":[]}}
{"stream":"btcusdt@depth@100ms","data":{"e":"depthUpdate","E":1784410672815,"s":"BTCUSDT","U":97585369791,"u":97585369793,"b":[["58215.60000000","0.00694000"]],"a":[]}}
{"stream":"btcusdt@depth@100ms","data":{"e":"depthUpdate","E":1784410672918,"s":"BTCUSDT","U":97585369794,"u":97585369803,"b":[["64683.99000000","4.33874000"],["64676.38000000","0.00065000"],["64654.90000000","0.00000000"],["58215.60000000","0.00703000"],["58215.59000000","0.00010000"],["40000.00000000","261.36615000"]],"a":[]}}
{"stream":"btcusdt@depth@100ms","data":{"e":"depthUpdate","E":1784410673014,"s":"BTCUSDT","U":97585369804,"u":97585369813,"b":[["64683.99000000","4.39579000"],["64681.92000000","0.00773000"],["64681.41000000","0.00000000"],["58215.60000000","0.00703000"],["51747.20000000","0.00038000"],["51747.19000000","0.00000000"]],"a":[["64694.69000000","0.00000000"],["64695.28000000","0.00773000"]]}}
{"stream":"btcusdt@depth@100ms","data":{"e":"depthUpdate","E":1784410673114,"s":"BTCUSDT","U":97585369814,"u":97585369827,"b":[["64682.62000000","0.18045000"],["64681.92000000","0.00791000"],["64681.85000000","0.01230000"],["58215.60000000","0.00703000"],["58215.00000000","0.11017000"]],"a":[]}}
{"stream":"btcusdt@depth@100ms","data":{"e":"depthUpdate","E":1784410673214,"s":"BTCUSDT","U":97585369828,"u":97585369836,"b":[["63713.73000000","0.00030000"],["58215.60000000","0.00703000"],["51747.20000000","0.00000000"]],"a":[["65654.26000000","0.00030000"]]}}
{"stream":"btcusdt@depth@100ms","data":{"e":"depthUpdate","E":1784410673314,"s":"BTCUSDT","U":97585369837,"u":97585369840,"b":[["58215.60000000","0.00684000"]],"a":[["64684.59000000","0.00306000"],["64684.61000000","0.00000000"]]}}
{"stream":"btcusdt@depth@100ms","data":{"e":"depthUpdate","E":1784410673414,"s":"BTCUSDT","U":97585369841,"u":97585369867,"b":[["64683.99000000","4.39491000"],["64683.98000000","0.00960000"],["64683.50000000","0.01245000"],["64666.94000000","0.00008000"],["58215.60000000","0.00703000"]],"a":[["64684.00000000","0.51490000"],["64695.28000000","0.00000000"],["64695.99000000","0.00773000"],["64705.76000000","0.00008000"]]}}
{"stream":"btcusdt@depth@100ms","data":{"e":"depthUpdate","E":1784410673514,"s":"BTCUSDT","U":97585369868,"u":97585369880,"b":[["64683.84000000","0.14196000"],["64683.50000000","0.01263000"],["64681.90000000","0.10258000"],["58215.60000000","0.00703000"],["51747.20000000","0.00038000"]],"a":[]}}
{"stream":"btcusdt@depth@100ms","data":{"e":"depthUpdate","E":1784410673614,"s":"BTCUSDT","U":97585369881,"u":97585369888,"b":[["64654.90000000","0.02577000"],["58215.60000000","0.00703000"],["51747.20000000","0.00000000"]],"a":[["64684.00000000","0.51498000"],["64684.01000000","0.00090000"]]}}
{"stream":"btcusdt@depth@100ms","data":{"e":"depthUpdate","E":1784410673714,"s":"BTCUSDT","U":97585369889,"u":97585369909,"b":[["64683.99000000","4.40231000"],["64683.02000000","0.00018000"],["64654.90000000","0.00000000"],["58215.60000000","0.00703000"],["58215.59000000","0.00000000"]],"a":[["64684.00000000","0.21985000"],["64684.57000000","0.00026000"],["64687.11000000","0.16423000"],["64687.12000000","0.01151000"],["64687.16000000","0.00017000"],["64688.01000000","0.13344000"],["64689.40000000","0.15721000"],["64690.09000000","0.17465000"],["64690.25000000","0.58010000"],["64690.26000000","0.00000000"],["64699.13000000","0.00000000"],["64699.48000000","0.00000000"]]}}
{"stream":"btcusdt@depth@100ms","data":{"e":"depthUpdate","E":1784410673814,"s":"BTCUSDT","U":97585369910,"u":97585369937,"b":[["64683.27000000","0.06601000"],["64683.02000000","0.00000000"],["64681.90000000","0.10276000"],["58215.60000000","0.00703000"],["51747.00000000","0.00000000"]],"a":[["64690.21000000","0.58011000"],["64690.22000000","0.00000000"],["64690.23000000","0.00000000"],["64690.24000000","0.00000000"],["64690.25000000","0.00000000"],["64699.48000000","0.00000000"]]}}
{"stream":"btcusdt@depth@100ms","data":{"e":"depthUpdate","E":1784410673915,"s":"BTCUSDT","U":97585369938,"u":97585369950,"b":[["58215.60000000","0.00703000"],["40000.00000000","261.36615000"]],"a":[["64684.52000000","0.00000000"],["64685.79000000","0.00124000"],["64690.18000000","0.00000000"],["64690.19000000","0.00008000"],["64690.20000000","0.00000000"],["64690.21000000","0.00000000"],["64699.48000000","0.58011000"]]}}
{"stream":"btcusdt@depth@100ms","data":{"e":"depthUpdate","E":1784410674014,"s":"BTCUSDT","U":97585369951,"u":97585369959,"b":[["58215.60000000","0.00703000"],["51747.20000000","0.00038000"],["51747.19000000","0.00000000"]],"a":[["64690.08000000","0.58010000"],["64693.75000000","0.00000000"],["64694.33000000","0.00773000"],["64699.48000000","0.00000000"]]}}
{"stream":"btcusdt@depth@100ms","data":{"e":"depthUpdate","E":1784410674115,"s":"BTCUSDT","U":97585369960,"u":97585369964,"b":[["58215.60000000","0.00703000"]],"a":[["64690.08000000","0.00000000"],["64699.48000000","0.58010000"]]}}
{"stream":"btcusdt@depth@100ms","data":{"e":"depthUpdate","E":1784410674215,"s":"BTCUSDT","U":97585369965,"u":97585369993,"b":[["64683.99000000","4.40240000"],["64683.51000000","0.00000000"],["64666.68000000","0.00190000"],["64664.58000000","0.00000000"],["64647.28000000","0.00009000"],["64645.18000000","0.00000000"],["64625.77000000","0.00000000"],["64606.37000000","0.00000000"],["64586.96000000","0.00000000"],["63713.73000000","0.00030000"],["58215.60000000","0.00703000"],["58215.00000000","0.11017000"],["51747.20000000","0.00000000"]],"a":[["64684.57000000","0.00034000"],["64684.59000000","0.00000000"],["64702.91000000","0.00000000"],["64703.41000000","0.00000000"],["64722.32000000","0.00000000"],["64722.81000000","0.00000000"],["64742.22000000","0.00000000"],["64761.62000000","0.00000000"],["64781.03000000","0.00000000"],["65654.26000000","0.00030000"]]}}
{"stream":"btcusdt@depth@100ms","data":{"e":"depthUpdate","E":1784410674314,"s":"BTCUSDT","U":97585369994,"u":97585370001,"b":[["58215.60000000","0.00713000"],["51747.00000000","0.00000000"]],"a":[["64684.00000000","0.21885000"]]}}
{"stream":"btcusdt@depth@100ms","data":{"e":"depthUpdate","E":1784410674414,"s":"BTCUSDT","U":97585370002,"u":97585370007,"b":[["58215.60000000","0.00694000"]],"a":[["64684.00000000","0.21885000"],["64684.01000000","0.00082000"]]}}
{"stream":"btcusdt@depth@100ms","data":{"e":"depthUpdate","E":1784410674514,"s":"BTCUSDT","U":97585370008,"u":97585370018,"b":[["64666.94000000","0.00008000"],["64666.80000000","0.35279000"],["64647.40000000","0.69452000"],["58215.60000000","0.00713000"],["51747.20000000","0.00038000"]],"a":[["64702.79000000","0.34483000"],["64705.76000000","0.00008000"],["64722.20000000","0.66992000"]]}}
{"stream":"btcusdt@depth@100ms","data":{"e":"depthUpdate","E":1784410674614,"s":"BTCUSDT","U":97585370019,"u":97585370025,"b":[["64683.99000000","4.40220000"],["58215.60000000","0.00703000"],["58215.59000000","0.00010000"],["51747.20000000","0.00000000"]],"a":[]}}
{"stream":"btcusdt@depth@100ms","data":{"e":"depthUpdate","E":1784410674714,"s":"BTCUSDT","U":97585370026,"u":97585370029,"b":[["58215.60000000","0.00703000"]],"a":[]}}
{"stream":"btcusdt@depth@100ms","data":{"e":"depthUpdate","E":1784410674814,"s":"BTCUSDT","U":97585370030,"u":97585370034,"b":[["58215.60000000","0.00703000"]],"a":[["77816.97000000","0.00000000"]]}}
{"stream":"btcusdt@depth@100ms","data":{"e":"depthUpdate","E":1784410674914,"s":"BTCUSDT","U":97585370035,"u":97585370039,"b":[["58215.60000000","0.00684000"],["40000.00000000","261.36615000"]],"a":[]}}
{"stream":"btcusdt@depth@100ms","data":{"e":"depthUpdate","E":1784410675014,"s":"BTCUSDT","U":97585370040,"u":97585370045,"b":[["64683.99000000","4.39447000"],["64683.51000000","0.00773000"],["64682.67000000","0.00773000"],["64681.92000000","0.00018000"],["58215.60000000","0.00703000"],["51747.20000000","0.00038000"]],"a":[]}}
{"stream":"btcusdt@depth@100ms","data":{"e":"depthUpdate","E":1784410675114,"s":"BTCUSDT","U":97585370046,"u":97585370069,"b":[["64683.84000000","0.14196000"],["64683.51000000","0.00791000"],["64683.27000000","0.06601000"],["64682.67000000","0.00791000"],["64682.62000000","0.18045000"],["64681.92000000","0.00000000"],["64681.90000000","0.10258000"],["58215.60000000","0.00703000"]],"a":[]}}
{"stream":"btcusdt@depth@100ms","data":{"e":"depthUpdate","E":1784410675214,"s":"BTCUSDT","U":97585370070,"u":97585370079,"b":[["63713.73000000","0.00030000"],["58215.60000000","0.00703000"],["51747.20000000","0.00000000"]],"a":[["64684.55000000","0.00306000"],["64684.57000000","0.00026000"],["65654.26000000","0.00030000"]]}}
{"stream":"btcusdt@depth@100ms","data":{"e":"depthUpdate","E":1784410675315,"s":"BTCUSDT","U":97585370080,"u":97585370088,"b":[["58215.60000000","0.00703000"],["58215.59000000","0.00000000"],["58215.00000000","0.11017000"]],"a":[["64684.00000000","0.21308000"]]}}
{"stream":"btcusdt@depth@100ms","data":{"e":"depthUpdate","E":1784410675414,"s":"BTCUSDT","U":97585370089,"u":97585370102,"b":[["64664.58000000","0.00015000"],["64645.18000000","0.00015000"],["64625.77000000","0.00015000"],["64606.37000000","0.00015000"],["64586.96000000","0.00015000"],["58215.60000000","0.00684000"]],"a":[["64702.19000000","0.00000000"],["64703.41000000","0.00015000"],["64722.81000000","0.00015000"],["64742.22000000","0.00015000"],["64761.62000000","0.00015000"],["64781.03000000","0.00015000"]]}}
{"stream":"btcusdt@depth@100ms","data":{"e":"depthUpdate","E":1784410675514,"s":"BTCUSDT","U":97585370103,"u":97585370109,"b":[["64666.94000000","0.00008000"],["58215.60000000","0.00703000"],["51747.20000000","0.00038000"]],"a":[["64705.76000000","0.00008000"]]}}
{"stream":"btcusdt@depth@100ms","data":{"e":"depthUpdate","E":1784410675614,"s":"BTCUSDT","U":97585370110,"u":97585370117,"b":[["64567.85000000","0.02422000"],["64557.16000000","0.00000000"],["58215.60000000","0.00703000"],["51747.20000000","0.00000000"]],"a":[["64702.28000000","0.12724000"]]}}
{"stream":"btcusdt@depth@100ms","data":{"e":"depthUpdate","E":1784410675714,"s":"BTCUSDT","U":97585370118,"u":97585370122,"b":[["58215.60000000","0.00703000"]],"a":[["65240.00000000","0.37780000"]]}}
{"stream":"btcusdt@depth@100ms","data":{"e":"depthUpdate","E":1784410675814,"s":"BTCUSDT","U":97585370123,"u":97585370127,"b":[["64567.85000000","0.00000000"],["58215.60000000","0.00703000"]],"a":[]}}
{"stream":"btcusdt@depth@100ms","data":{"e":"depthUpdate","E":1784410675915,"s":"BTCUSDT","U":97585370128,"u":97585370135,"b":[["64500.00000000","3.95726000"],["64050.00000000","0.88110000"],["58215.60000000","0.00703000"],["40000.00000000","261.36615000"]],"a":[["65781.90000000","0.00063000"]]}}
{"stream":"btcusdt@depth@100ms","data":{"e":"depthUpdate","E":1784410676014,"s":"BTCUSDT","U":97585370136,"u":97585370140,"b":[["64682.67000000","0.00018000"],["64681.92000000","0.00773000"],["58215.60000000","0.00703000"],["51747.20000000","0.00038000"]],"a":[["64690.08000000","0.58010000"],["64699.48000000","0.00000000"]]}}
{"stream":"btcusdt@depth@100ms","data":{"e":"depthUpdate","E":1784410676114,"s":"BTCUSDT","U":97585370141,"u":97585370166,"b":[["64683.27000000","0.06601000"],["64682.67000000","0.00000000"],["64682.62000000","0.18045000"],["64681.92000000","0.00791000"],["58215.60000000","0.00703000"],["33000.00000000","32.32056000"]],"a":[["64684.00000000","0.21300000"],["64684.01000000","0.00074000"],["64684.57000000","0.00008000"],["64684.58000000","0.00018000"],["64687.16000000","0.00026000"],["64687.72000000","0.00009000"],["64690.08000000","0.00000000"],["64690.09000000","0.75475000"],["64699.48000000","0.00000000"]]}}
{"stream":"btcusdt@depth@100ms","data":{"e":"depthUpdate","E":1784410676214,"s":"BTCUSDT","U":97585370167,"u":97585370183,"b":[["63713.73000000","0.00030000"],["58215.60000000","0.00703000"],["51747.20000000","0.00000000"],["33000.00000000","32.31996000"]],"a":[["64684.00000000","0.21310000"],["64684.53000000","0.00008000"],["64684.55000000","0.00000000"],["64684.58000000","0.00000000"],["64684.95000000","0.00000000"],["65654.26000000","0.00030000"]]}}
{"stream":"btcusdt@depth@100ms","data":{"e":"depthUpdate","E":1784410676314,"s":"BTCUSDT","U":97585370184,"u":97585370189,"b":[["58215.60000000","0.00703000"],["51747.00000000","0.00000000"]],"a":[]}}
{"stream":"btcusdt@depth@100ms","data":{"e":"depthUpdate","E":1784410676414,"s":"BTCUSDT","U":97585370190,"u":97585370195,"b":[["58215.60000000","0.00703000"],["58215.00000000","0.11017000"]],"a":[]}}
{"stream":"btcusdt@depth@100ms","data":{"e":"depthUpdate","E":1784410676514,"s":"BTCUSDT","U":97585370196,"u":97585370204,"b":[["64683.99000000","4.40220000"],["64683.51000000","0.00018000"],["64666.94000000","0.00000000"],["64613.37000000","0.00000000"],["64611.25000000","1.18504000"],["58215.60000000","0.00684000"],["51747.20000000","0.00038000"]],"a":[["64695.07000000","0.00773000"],["64695.99000000","0.00000000"],["64705.76000000","0.00000000"]]}}
{"stream":"btcusdt@depth@100ms","data":{"e":"depthUpdate","E":1784410676616,"s":"BTCUSDT","U":97585370205,"u":97585370221,"b":[["64683.84000000","0.14196000"],["64683.51000000","0.00000000"],["64666.94000000","0.00008000"],["64611.26000000","0.51456000"],["58215.60000000","0.00713000"],["51747.20000000","0.00000000"]],"a":[["64684.00000000","0.21299000"],["64688.01000000","0.13362000"],["64705.76000000","0.00008000"]]}}
{"stream":"btcusdt@depth@100ms","data":{"e":"depthUpdate","E":1784410676715,"s":"BTCUSDT","U":97585370222,"u":97585370226,"b":[["59509.28000000","0.00017000"],["58215.60000000","0.00713000"]],"a":[]}}
{"stream":"btcusdt@depth@100ms","data":{"e":"depthUpdate","E":1784410676816,"s":"BTCUSDT","U":97585370227,"u":97585370232,"b":[["58215.60000000","0.00713000"],["58215.59000000","0.00010000"]],"a":[["64684.00000000","0.21266000"]]}}
{"stream":"btcusdt@depth@100ms","data":{"e":"depthUpdate","E":1784410676916,"s":"BTCUSDT","U":97585370233,"u":97585370239,"b":[["58215.60000000","0.00713000"],["58215.59000000","0.00000000"],["40000.00000000","261.36615000"]],"a":[]}}
{"stream":"btcusdt@depth@100ms","data":{"e":"depthUpdate","E":1784410677014,"s":"BTCUSDT","U":97585370240,"u":97585370248,"b":[["64682.67000000","0.00773000"],["64681.92000000","0.00018000"],["64613.37000000","1.18468000"],["64611.26000000","0.18644000"],["64611.25000000","0.00036000"],["58215.60000000","0.00694000"],["51747.20000000","0.00038000"]],"a":[["64695.07000000","0.00000000"],["64695.99000000","0.00773000"]]}}
{"stream":"btcusdt@depth@100ms","data":{"e":"depthUpdate","E":1784410677114,"s":"BTCUSDT","U":97585370249,"u":97585370270,"b":[["64683.99000000","4.39447000"],["64683.51000000","0.00773000"],["64683.27000000","0.06601000"],["64682.67000000","0.00791000"],["64682.62000000","0.18045000"],["64681.92000000","0.00000000"],["64613.37000000","0.00000000"],["58215.60000000","0.00713000"]],"a":[["64684.00000000","0.21266000"],["64867.62000000","0.00000000"]]}}
{"stream":"btcusdt@depth@100ms","data":{"e":"depthUpdate","E":1784410677215,"s":"BTCUSDT","U":97585370271,"u":97585370281,"b":[["64683.84000000","0.14196000"],["63713.73000000","0.00000000"],["58215.60000000","0.00713000"],["51747.20000000","0.00000000"]],"a":[["65500.00000000","52.80247000"]]}}
{"stream":"btcusdt@depth@100ms","data":{"e":"depthUpdate","E":1784410677314,"s":"BTCUSDT","U":97585370282,"u":97585370289,"b":[["63713.73000000","0.00030000"],["59509.28000000","0.00000000"],["58215.60000000","0.00713000"]],"a":[["65654.26000000","0.00030000"]]}}
{"stream":"btcusdt@depth@100ms","data":{"e":"depthUpdate","E":1784410677414,"s":"BTCUSDT","U":97585370290,"u":97585370297,"b":[["64557.09000000","0.09294000"],["58215.60000000","0.00713000"],["58215.00000000","0.11017000"]],"a":[["64878.98000000","0.09247000"]]}}
{"stream":"btcusdt@depth@100ms","data":{"e":"depthUpdate","E":1784410677514,"s":"BTCUSDT","U":97585370298,"u":97585370303,"b":[["58215.60000000","0.00694000"],["51747.20000000","0.00038000"]],"a":[["64684.51000000","0.00306000"],["64684.53000000","0.00000000"],["64690.10000000","0.13531000"]]}}
{"stream":"btcusdt@depth@100ms","data":{"e":"depthUpdate","E":1784410677614,"s":"BTCUSDT","U":97585370304,"u":97585370313,"b":[["64666.94000000","0.00008000"],["64654.90000000","0.02577000"],["58215.60000000","0.00713000"],["51747.20000000","0.00000000"],["51747.00000000","0.00000000"]],"a":[["64705.76000000","0.00008000"]]}}
{"stream":"btcusdt@depth@100ms","data":{"e":"depthUpdate","E":1784410677714,"s":"BTCUSDT","U":97585370314,"u":97585370326,"b":[["64683.99000000","4.39439000"],["64683.51000000","0.00791000"],["64654.90000000","0.00000000"],["64613.37000000","1.18468000"],["58215.60000000","0.00703000"],["58215.59000000","0.00010000"],["51747.00000000","0.00200000"]],"a":[["64684.00000000","0.21248000"]]}}
{"stream":"btcusdt@depth@100ms","data":{"e":"depthUpdate","E":1784410677814,"s":"BTCUSDT","U":97585370327,"u":97585370333,"b":[["64683.99000000","4.36346000"],["58215.60000000","0.00703000"],["51747.00000000","0.00000000"]],"a":[["64684.95000000","0.00008000"]]}}
{"stream":"btcusdt@depth@100ms","data":{"e":"depthUpdate","E":1784410677914,"s":"BTCUSDT","U":97585370334,"u":97585370343,"b":[["64683.51000000","0.00018000"],["64683.02000000","0.00773000"],["58215.60000000","0.00703000"],["40000.00000000","261.36615000"]],"a":[["64684.00000000","0.38910000"],["64694.79000000","0.00773000"],["64695.99000000","0.00000000"]]}}
{"stream":"btcusdt@depth@100ms","data":{"e":"depthUpdate","E":1784410678014,"s":"BTCUSDT","U":97585370344,"u":97585370370,"b":[["64683.84000000","0.14196000"],["64683.51000000","0.00000000"],["64683.27000000","0.06601000"],["64683.02000000","0.00791000"],["64682.67000000","0.00018000"],["64681.92000000","0.00773000"],["64557.09000000","0.00000000"],["58215.60000000","0.00703000"],["58215.59000000","0.00000000"],["51747.20000000","0.00038000"]],"a":[["64684.00000000","0.38592000"],["64684.01000000","0.00082000"],["64878.98000000","0.00000000"]]}}
{"stream":"btcusdt@depth@100ms","data":{"e":"depthUpdate","E":1784410678116,"s":"BTCUSDT","U":97585370371,"u":97585370391,"b":[["64683.02000000","0.00018000"],["64682.67000000","0.00773000"],["64682.62000000","0.18045000"],["64681.92000000","0.00791000"],["58215.60000000","0.00703000"]],"a":[["64684.00000000","0.38584000"],["64694.79000000","0.00000000"],["64695.07000000","0.00773000"]]}}
{"stream":"btcusdt@depth@100ms","data":{"e":"depthUpdate","E":1784410678216,"s":"BTCUSDT","U":97585370392,"u":97585370406,"b":[["64683.27000000","0.06601000"],["64683.02000000","0.00000000"],["64682.67000000","0.00791000"],["64662.39000000","0.00952000"],["64651.87000000","0.00000000"],["58215.60000000","0.00703000"],["51747.20000000","0.00000000"]],"a":[]}}
{"stream":"btcusdt@depth@100ms","data":{"e":"depthUpdate","E":1784410678314,"s":"BTCUSDT","U":97585370407,"u":97585370419,"b":[["64683.86000000","0.00773000"],["64682.67000000","0.00018000"],["63713.73000000","0.00030000"],["58215.60000000","0.00703000"],["51747.00000000","0.00000000"]],"a":[["64684.50000000","0.00008000"],["64684.51000000","0.00000000"],["64695.07000000","0.00000000"],["64695.99000000","0.00773000"],["65654.26000000","0.00030000"]]}}
{"stream":"btcusdt@depth@100ms","data":{"e":"depthUpdate","E":1784410678415,"s":"BTCUSDT","U":97585370420,"u":97585370439,"b":[["64683.98000000","0.00960000"],["64683.86000000","0.00791000"],["64683.27000000","0.06601000"],["64682.67000000","0.00000000"],["58215.60000000","0.00703000"]],"a":[["64684.00000000","0.38584000"],["64684.01000000","0.00074000"],["64684.95000000","0.00000000"]]}}
{"stream":"btcusdt@depth@100ms","data":{"e":"depthUpdate","E":1784410678514,"s":"BTCUSDT","U":97585370440,"u":97585370446,"b":[["58215.60000000","0.00703000"],["58215.00000000","0.11017000"],["51747.20000000","0.00038000"]],"a":[]}}
{"stream":"btcusdt@depth@100ms","data":{"e":"depthUpdate","E":1784410678614,"s":"BTCUSDT","U":97585370447,"u":97585370453,"b":[["64666.94000000","0.00008000"],["58215.60000000","0.00684000"],["51747.20000000","0.00000000"]],"a":[["64705.76000000","0.00008000"]]}}
{"stream":"btcusdt@depth@100ms","data":{"e":"depthUpdate","E":1784410678715,"s":"BTCUSDT","U":97585370454,"u":97585370456,"b":[["58215.60000000","0.00703000"]],"a":[]}}
{"stream":"btcusdt@depth@100ms","data":{"e":"depthUpdate","E":1784410678814,"s":"BTCUSDT","U":97585370457,"u":97585370460,"b":[["58215.60000000","0.00703000"]],"a":[]}}
{"stream":"btcusdt@depth@100ms","data":{"e":"depthUpdate","E":1784410678917,"s":"BTCUSDT","U":97585370461,"u":97585370467,"b":[["64573.87000000","0.02422000"],["58215.60000000","0.00703000"],["40000.00000000","261.36615000"]],"a":[]}}
{"stream":"btcusdt@depth@100ms","data":{"e":"depthUpdate","E":1784410679014,"s":"BTCUSDT","U":97585370468,"u":97585370483,"b":[["64683.86000000","0.00018000"],["64683.51000000","0.00773000"],["58215.60000000","0.00703000"],["51747.20000000","0.00038000"],["51747.19000000","0.00000000"],["51747.00000000","0.00000000"]],"a":[]}}
{"stream":"btcusdt@depth@100ms","data":{"e":"depthUpdate","E":1784410679114,"s":"BTCUSDT","U":97585370484,"u":97585370507,"b":[["64683.98000000","0.00960000"],["64683.86000000","0.00000000"],["64683.84000000","0.14196000"],["64683.51000000","0.00791000"],["64683.50000000","0.00018000"],["64682.67000000","0.00773000"],["64681.92000000","0.00018000"],["58215.60000000","0.00694000"]],"a":[["64684.00000000","0.20801000"],["64684.48000000","0.00306000"],["64684.50000000","0.00000000"],["64685.50000000","0.18380000"],["64702.40000000","0.00000000"],["64704.37000000","0.00200000"]]}}
{"stream":"btcusdt@depth@100ms","data":{"e":"depthUpdate","E":1784410679214,"s":"BTCUSDT","U":97585370508,"u":97585370545,"b":[["64683.51000000","0.00791000"],["64683.50000000","0.00000000"],["64683.27000000","0.06601000"],["64682.67000000","0.00791000"],["64682.62000000","0.18045000"],["64681.92000000","0.00000000"],["64585.01000000","0.19774000"],["64583.14000000","0.57993000"],["64576.64000000","0.00000000"],["64576.63000000","0.00000000"],["58215.60000000","0.00713000"],["51747.20000000","0.00000000"]],"a":[["64684.00000000","0.20835000"],["64684.01000000","0.00082000"],["64685.49000000","0.00133000"],["64685.50000000","0.18398000"],["64687.72000000","0.00000000"],["64688.01000000","0.13344000"],["64690.09000000","0.17465000"],["64699.48000000","0.58010000"]]}}
{"stream":"btcusdt@depth@100ms","data":{"e":"depthUpdate","E":1784410679315,"s":"BTCUSDT","U":97585370546,"u":97585370559,"b":[["64683.99000000","4.36173000"],["64681.90000000","0.10276000"],["63713.73000000","0.00030000"],["58215.60000000","0.00713000"]],"a":[["64684.00000000","0.20725000"],["65654.26000000","0.00030000"]]}}
{"stream":"btcusdt@depth@100ms","data":{"e":"depthUpdate","E":1784410679414,"s":"BTCUSDT","U":97585370560,"u":97585370564,"b":[["58215.60000000","0.00713000"]],"a":[["64684.95000000","0.00008000"]]}}
{"stream":"btcusdt@depth@100ms","data":{"e":"depthUpdate","E":1784410679514,"s":"BTCUSDT","U":97585370565,"u":97585370569,"b":[["58215.60000000","0.00713000"],["51747.20000000","0.00038000"]],"a":[]}}
{"stream":"btcusdt@depth@100ms","data":{"e":"depthUpdate","E":1784410679614,"s":"BTCUSDT","U":97585370570,"u":97585370578,"b":[["64666.94000000","0.00000000"],["64662.39000000","0.00000000"],["64651.87000000","0.00927000"],["58215.60000000","0.00694000"],["58215.00000000","0.11017000"],["51747.20000000","0.00000000"]],"a":[["64705.76000000","0.00000000"]]}}
{"stream":"btcusdt@depth@100ms","data":{"e":"depthUpdate","E":1784410679714,"s":"BTCUSDT","U":97585370579,"u":97585370583,"b":[["64666.94000000","0.00008000"],["58215.60000000","0.00713000"]],"a":[["64705.76000000","0.00008000"]]}}
{"stream":"btcusdt@depth@100ms","data":{"e":"depthUpdate","E":1784410679816,"s":"BTCUSDT","U":97585370584,"u":97585370587,"b":[["58215.60000000","0.00713000"]],"a":[]}}
{"stream":"btcusdt@depth@100ms","data":{"e":"depthUpdate","E":1784410679916,"s":"BTCUSDT","U":97585370588,"u":97585370594,"b":[["64423.28000000","0.00000000"],["58215.60000000","0.00713000"],["40000.00000000","261.36615000"]],"a":[]}}
{"stream":"btcusdt@depth@100ms","data":{"e":"depthUpdate","E":1784410680015,"s":"BTCUSDT","U":97585370595,"u":97585370609,"b":[["64677.73000000","0.21415000"],["64676.65000000","0.00000000"],["64676.01000000","0.13074000"],["64674.31000000","0.00000000"],["64673.28000000","0.77349000"],["64671.94000000","0.00000000"],["64625.02000000","0.00386000"],["64560.09000000","0.00154000"],["64472.06000000","0.02422000"],["58215.60000000","0.00713000"],["51747.20000000","0.00038000"],["51747.19000000","0.00000000"]],"a":[["64701.51000000","0.00000000"],["64701.52000000","0.27371000"],["64703.38000000","0.00000000"],["64703.57000000","0.77349000"]]}}
{"stream":"btcusdt@depth@100ms","data":{"e":"depthUpdate","E":1784410680114,"s":"BTCUSDT","U":97585370610,"u":97585370615,"b":[["64671.57000000","0.00000000"],["64666.80000000","0.00010000"],["58215.60000000","0.00713000"]],"a":[]}}
{"stream":"btcusdt@depth@100ms","data":{"e":"depthUpdate","E":1784410680214,"s":"BTCUSDT","U":97585370616,"u":97585371652,"b":[["64689.75000000","1.31205000"],["64689.74000000","0.00034000"],["64689.73000000","0.00016000"],["64689.54000000","0.00000000"],["64689.39000000","0.00000000"],["64689.09000000","0.00018000"],["64689.08000000","0.33768000"],["64689.07000000","0.00000000"],["64689.06000000","0.00000000"],["64688.82000000","0.00124000"],["64688.77000000","0.00000000"],["64688.49000000","0.67119000"],["64688.43000000","0.00000000"],["64688.25000000","0.17405000"],["64688.01000000","0.00018000"],["64688.00000000","0.04018000"],["64687.99000000","0.00000000"],["64687.85000000","0.00000000"],["64687.73000000","0.00018000"],["64687.72000000","0.04026000"],["64687.17000000","0.00018000"],["64687.16000000","0.00000000"],["64687.13000000","0.00000000"],["64687.12000000","0.00009000"],["64687.11000000","0.00000000"],["64687.10000000","0.00000000"],["64687.09000000","0.00000000"],["64687.02000000","0.00008000"],["64687.01000000","0.00000000"],["64686.88000000","0.00000000"],["64686.19000000","0.00200000"],["64686.18000000","0.00000000"],["64686.00000000","0.00008000"],["64685.99000000","0.00000000"],["64685.98000000","0.00000000"],["64685.89000000","0.00000000"],["64685.78000000","0.00000000"],["64685.59000000","0.00000000"],["64685.58000000","0.04798000"],["64685.56000000","0.00000000"],["64685.51000000","0.00000000"],["64685.50000000","2.69647000"],["64685.49000000","0.20451000"],["64685.48000000","0.00000000"],["64685.47000000","0.00000000"],["64684.98000000","0.00400000"],["64684.94000000","0.00000000"],["64684.92000000","0.00000000"],["64684.56000000","0.00000000"],["64684.53000000","0.00032000"],["64684.49000000","0.00000000"],["64684.48000000","0.00000000"],["64684.47000000","0.00772000"],["64684.01000000","0.00000000"],["64684.00000000","0.02477000"],["64683.99000000","2.66995000"],["64683.98000000","0.00926000"],["64683.97000000","0.00000000"],["64683.89000000","0.00000000"],["64683.85000000","0.00008000"],["64683.84000000","0.00026000"],["64683.57000000","0.00000000"],["64683.51000000","0.00000000"],["64683.28000000","0.00409000"],["64683.27000000","0.00008000"],["64683.13000000","0.15458000"],["64682.85000000","0.00008000"],["64682.68000000","0.00773000"],["64682.67000000","0.00000000"],["64682.66000000","0.00000000"],["64682.65000000","0.16446000"],["64682.63000000","0.00000000"],["64682.62000000","0.14019000"],["64682.61000000","0.00400000"],["64681.92000000","0.00000000"],["64681.91000000","0.00000000"],["64681.90000000","0.06258000"],["64681.42000000","0.00078000"],["64681.39000000","0.01031000"],["64681.25000000","0.00000000"],["64680.92000000","0.00012000"],["64680.88000000","0.00008000"],["64680.68000000","0.00008000"],["64680.26000000","0.00008000"],["64680.10000000","0.00000000"],["64679.58000000","0.00010000"],["64679.55000000","0.00928000"],["64678.72000000","0.77361000"],["64678.67000000","2.12849000"],["64678.48000000","0.00000000"],["64678.09000000","0.00000000"],["64677.73000000","0.00000000"],["64677.72000000","0.00009000"],["64677.71000000","0.00000000"],["64677.67000000","0.00008000"],["64677.53000000","0.08658000"],["64677.52000000","0.00000000"],["64677.41000000","0.00032000"],["64676.29000000","0.55702000"],["64676.14000000","0.00009000"],["64676.01000000","0.00000000"],["64675.73000000","0.00000000"],["64675.50000000","0.00000000"],["64675.39000000","0.00000000"],["64675.35000000","0.00000000"],["64675.09000000","0.00000000"],["64675.08000000","0.00000000"],["64673.17000000","0.00200000"],["64672.91000000","0.00009000"],["64672.62000000","0.02021000"],["64672.56000000","0.00009000"],["64672.55000000","0.00000000"],["64672.49000000","0.00000000"],["64671.37000000","0.00200000"],["64671.06000000","0.11940000"],["64669.90000000","0.00000000"],["64669.67000000","0.00009000"],["64669.32000000","0.00000000"],["64669.16000000","0.00000000"],["64668.79000000","0.00200000"],["64668.67000000","0.00154000"],["64668.45000000","0.00000000"],["64668.09000000","0.00000000"],["64667.27000000","0.02030000"],["64666.44000000","0.00009000"],["64666.08000000","0.00000000"],["64665.22000000","0.00000000"],["64663.53000000","0.00000000"],["64663.20000000","0.00009000"],["64662.85000000","0.00000000"],["64662.49000000","0.00000000"],["64661.99000000","0.00000000"],["64660.61000000","1.53218000"],["64660.47000000","0.00000000"],["64660.45000000","0.00000000"],["64659.97000000","0.00009000"],["64659.62000000","0.00000000"],["64659.06000000","0.00000000"],["64658.75000000","0.00000000"],["64656.74000000","0.00009000"],["64656.38000000","0.00000000"],["64655.60000000","0.00000000"],["64655.52000000","0.00000000"],["64655.32000000","0.00000000"],["64653.15000000","0.00000000"],["64652.28000000","0.00000000"],["64652.15000000","0.00000000"],["64649.05000000","0.00000000"],["64645.52000000","0.00000000"],["64644.74000000","0.00000000"],["64642.03000000","0.00384000"],["64638.01000000","0.00000000"],["64636.44000000","0.00000000"],["64634.47000000","0.00386000"],["64632.41000000","0.00000000"],["64630.59000000","0.00385000"],["64625.02000000","0.00000000"],["64615.51000000","0.00000000"],["64613.37000000","0.00000000"],["64611.26000000","0.51456000"],["64611.25000000","1.18504000"],["64610.29000000","0.00000000"],["64607.78000000","0.00000000"],["64605.25000000","0.00000000"],["64577.12000000","0.00154000"],["64572.14000000","0.00000000"],["64569.74000000","0.00154000"],["64568.45000000","0.00000000"],["64371.27000000","0.00250000"],["64272.00000000","0.00000000"],["63713.73000000","0.00000000"],["58215.60000000","0.00285000"],["58215.59000000","0.00010000"],["51747.20000000","0.00000000"]],"a":[["64684.00000000","0.00000000"],["64684.01000000","0.00000000"],["64684.02000000","0.00000000"],["64684.46000000","0.00000000"],["64684.48000000","0.00000000"],["64684.57000000","0.00000000"],["64684.95000000","0.00000000"],["64685.00000000","0.00000000"],["64685.49000000","0.00000000"],["64685.50000000","0.00000000"],["64685.51000000","0.00000000"],["64685.52000000","0.00000000"],["64685.59000000","0.00000000"],["64685.79000000","0.00000000"],["64685.90000000","0.00000000"],["64685.99000000","0.00000000"],["64686.00000000","0.00000000"],["64686.19000000","0.00000000"],["64686.20000000","0.00000000"],["64686.89000000","0.00000000"],["64687.02000000","0.00000000"],["64687.10000000","0.00000000"],["64687.11000000","0.00000000"],["64687.12000000","0.00000000"],["64687.14000000","0.00000000"],["64687.16000000","0.00000000"],["64687.17000000","0.00000000"],["64687.72000000","0.00000000"],["64687.73000000","0.00000000"],["64687.86000000","0.00000000"],["64687.99000000","0.00000000"],["64688.00000000","0.00000000"],["64688.01000000","0.00000000"],["64688.16000000","0.00000000"],["64688.26000000","0.00000000"],["64688.39000000","0.00000000"],["64688.44000000","0.00000000"],["64688.50000000","0.00000000"],["64688.78000000","0.00000000"],["64689.00000000","0.00000000"],["64689.09000000","0.00000000"],["64689.31000000","0.00000000"],["64689.40000000","0.00000000"],["64689.76000000","0.88245000"],["64689.77000000","0.00074000"],["64689.99000000","0.00018000"],["64690.00000000","0.03718000"],["64690.08000000","0.00018000"],["64690.09000000","0.00036000"],["64690.10000000","0.00026000"],["64690.11000000","0.00000000"],["64690.26000000","0.00018000"],["64690.27000000","0.00018000"],["64690.28000000","0.00009000"],["64690.36000000","0.00000000"],["64690.46000000","0.10008000"],["64690.47000000","0.00000000"],["64690.54000000","0.00000000"],["64690.89000000","0.00026000"],["64690.96000000","0.00000000"],["64690.99000000","0.00000000"],["64691.08000000","0.00000000"],["64691.11000000","0.00000000"],["64691.22000000","0.00000000"],["64691.26000000","0.02000000"],["64691.30000000","0.00000000"],["64691.60000000","0.02000000"],["64691.95000000","0.03000000"],["64692.00000000","0.02700000"],["64692.10000000","0.00000000"],["64692.18000000","0.00000000"],["64692.20000000","0.00000000"],["64692.35000000","0.00000000"],["64692.51000000","0.00000000"],["64692.59000000","0.04000000"],["64692.70000000","0.12000000"],["64692.71000000","0.02000000"],["64692.94000000","2.58208000"],["64692.95000000","0.00000000"],["64692.97000000","0.00000000"],["64693.15000000","0.18224000"],["64693.81000000","0.00000000"],["64693.82000000","0.00000000"],["64694.20000000","0.00000000"],["64694.22000000","0.00000000"],["64694.33000000","0.00000000"],["64694.34000000","0.00000000"],["64694.94000000","0.00000000"],["64695.11000000","0.00000000"],["64695.12000000","0.00000000"],["64695.14000000","0.00078000"],["64695.60000000","0.15458000"],["64695.98000000","0.00000000"],["64695.99000000","0.00000000"],["64696.13000000","0.00000000"],["64696.23000000","0.00009000"],["64696.38000000","0.00000000"],["64696.51000000","2.12849000"],["64696.80000000","0.00000000"],["64696.94000000","0.00000000"],["64696.96000000","0.00000000"],["64697.57000000","0.00000000"],["64697.64000000","0.00800000"],["64697.88000000","0.00008000"],["64697.90000000","0.00000000"],["64698.08000000","0.00000000"],["64698.27000000","0.00000000"],["64698.31000000","0.00000000"],["64698.42000000","0.00000000"],["64698.43000000","0.00000000"],["64698.44000000","0.00000000"],["64698.75000000","0.00010000"],["64698.80000000","0.00000000"],["64699.13000000","0.00773000"],["64699.33000000","0.00000000"],["64699.34000000","0.00000000"],["64699.36000000","0.00000000"],["64699.46000000","0.00000000"],["64699.47000000","2.12849000"],["64699.48000000","0.00000000"],["64699.49000000","0.00000000"],["64699.71000000","0.00000000"],["64699.99000000","0.00773000"],["64700.28000000","0.00175000"],["64700.47000000","0.00008000"],["64700.67000000","0.00009000"],["64700.80000000","0.00000000"],["64701.52000000","0.00000000"],["64701.67000000","0.00000000"],["64701.86000000","0.00000000"],["64702.23000000","0.45350000"],["64702.25000000","2.12849000"],["64702.27000000","0.00000000"],["64702.28000000","0.00000000"],["64702.51000000","0.58011000"],["64702.52000000","0.00000000"],["64702.70000000","0.00009000"],["64702.79000000","0.00000000"],["64703.36000000","0.00000000"],["64703.57000000","0.00000000"],["64703.58000000","0.00008000"],["64704.04000000","0.00000000"],["64704.12000000","3.09195000"],["64704.23000000","0.00000000"],["64704.29000000","0.00559000"],["64704.37000000","0.00000000"],["64704.66000000","0.00000000"],["64704.91000000","0.00000000"],["64705.31000000","0.10461000"],["64705.32000000","0.00000000"],["64705.47000000","2.12849000"],["64705.48000000","0.00000000"],["64705.66000000","0.00000000"],["64705.92000000","0.00000000"],["64705.93000000","0.00009000"],["64705.97000000","0.00000000"],["64705.98000000","0.00009000"],["64706.13000000","0.00000000"],["64706.97000000","0.00000000"],["64707.27000000","0.00000000"],["64707.58000000","0.00000000"],["64707.65000000","0.00200000"],["64707.87000000","0.77350000"],["64707.96000000","0.00000000"],["64708.14000000","0.00000000"],["64708.16000000","2.12849000"],["64708.77000000","0.77325000"],["64708.97000000","0.00000000"],["64709.17000000","0.00009000"],["64709.67000000","0.00000000"],["64709.80000000","0.00000000"],["64710.00000000","0.03708000"],["64710.29000000","0.00000000"],["64710.30000000","0.00000000"],["64710.32000000","0.00000000"],["64710.33000000","0.04000000"],["64710.51000000","0.00000000"],["64710.58000000","0.00400000"],["64710.79000000","2.12849000"],["64710.83000000","0.00000000"],["64711.07000000","0.00000000"],["64711.11000000","0.55672000"],["64711.36000000","0.00000000"],["64711.37000000","0.00000000"],["64712.27000000","0.00000000"],["64712.30000000","0.00000000"],["64712.40000000","0.00009000"],["64712.44000000","0.00000000"],["64713.59000000","0.00900000"],["64713.68000000","2.12849000"],["64713.74000000","0.00000000"],["64713.93000000","0.53058000"],["64714.31000000","0.00000000"],["64714.49000000","0.00000000"],["64714.61000000","0.00000000"],["64714.67000000","0.00200000"],["64715.22000000","0.00200000"],["64715.64000000","0.00009000"],["64715.70000000","0.28413000"],["64716.34000000","2.12849000"],["64716.37000000","0.00000000"],["64717.00000000","0.00000000"],["64717.66000000","1.72482000"],["64717.84000000","0.00000000"],["64718.00000000","0.02700000"],["64718.54000000","0.00009000"],["64718.72000000","0.00016000"],["64718.87000000","0.00009000"],["64718.96000000","2.12849000"],["64720.09000000","0.00000000"],["64720.11000000","0.00000000"],["64720.34000000","0.00000000"],["64721.00000000","0.00000000"],["64721.57000000","0.00000000"],["64721.67000000","0.05846000"],["64721.87000000","2.12849000"],["64721.89000000","0.00008000"],["64722.10000000","0.00009000"],["64722.20000000","0.00000000"],["64722.52000000","0.77309000"],["64723.00000000","0.01000000"],["64723.58000000","0.00000000"],["64723.67000000","3.09195000"],["64725.20000000","0.00000000"],["64725.67000000","2.12849000"],["64726.62000000","0.00000000"],["64729.03000000","0.00000000"],["64732.28000000","0.00000000"],["64733.44000000","2.12849000"],["64734.09000000","0.07619000"],["64735.39000000","0.00000000"],["64736.50000000","0.00000000"],["64738.58000000","0.00000000"],["64740.05000000","2.12849000"],["64741.88000000","0.00000000"],["64743.44000000","3.09195000"],["64743.48000000","0.00396000"],["64746.35000000","2.12849000"],["64746.36000000","1.53015000"],["64747.06000000","0.00000000"],["64747.70000000","0.92825000"],["64748.59000000","0.00000000"],["64749.99000000","0.00000000"],["64752.11000000","0.00000000"],["64754.12000000","2.12849000"],["64754.25000000","0.00822000"],["64754.99000000","0.00383000"],["64755.39000000","0.00000000"],["64760.26000000","0.00000000"],["64761.89000000","2.12849000"],["64766.69000000","0.00000000"],["64769.62000000","2.12849000"],["64777.39000000","2.12849000"],["64785.16000000","0.00000000"],["64792.93000000","0.00000000"],["64799.46000000","0.00000000"],["64800.70000000","0.00000000"],["64807.93000000","0.00000000"],["64808.42000000","0.00154000"],["64808.47000000","0.00000000"],["64813.99000000","0.00000000"],["64814.99000000","0.00000000"],["64819.15000000","0.00154000"],["64974.54000000","0.00250000"],["65654.26000000","0.00000000"]]}}
