{"market":"0xab772601f501b265bfe8982eb61d5347ef9945de314bfdf4ac0189c288ffb0b3", "asset_id":"12935926064588426924078449947177910958215776269411501731627440228801766632772", "bids":[{"price":"0.01", "size":"14884.14"}, {"price":"0.02", "size":"3964.52"}, {"price":"0.03", "size":"2179.29"}, {"price":"0.04", "size":"1215.1"}, {"price":"0.05", "size":"1752.19"}, {"price":"0.06", "size":"1122.02"}, {"price":"0.07", "size":"953.49"}, {"price":"0.08", "size":"1234.38"}, {"price":"0.09", "size":"791.7"}, {"price":"0.1", "size":"561.2"}, {"price":"0.11", "size":"1502.1"}, {"price":"0.12", "size":"1112.05"}, {"price":"0.13", "size":"139.4"}, {"price":"0.14", "size":"281.8"}, {"price":"0.15", "size":"444.04"}, {"price":"0.16", "size":"147.1"}, {"price":"0.17", "size":"207.17"}, {"price":"0.18", "size":"150.7"}, {"price":"0.19", "size":"103.89"}, {"price":"0.2", "size":"246.2"}, {"price":"0.21", "size":"636.8"}, {"price":"0.22", "size":"135.5"}, {"price":"0.23", "size":"112.3"}, {"price":"0.24", "size":"162.22"}, {"price":"0.25", "size":"137.2"}, {"price":"0.26", "size":"134.3"}, {"price":"0.27", "size":"148.5"}, {"price":"0.28", "size":"146.77"}, {"price":"0.29", "size":"216.99"}, {"price":"0.3", "size":"207.81"}, {"price":"0.31", "size":"550.01"}, {"price":"0.32", "size":"236.69"}, {"price":"0.33", "size":"134.65"}, {"price":"0.34", "size":"125.76"}, {"price":"0.35", "size":"138.8"}, {"price":"0.36", "size":"211.77"}, {"price":"0.37", "size":"165.97"}, {"price":"0.38", "size":"394.01"}], "asks":[{"price":"0.99", "size":"13054.5"}, {"price":"0.98", "size":"3885.25"}, {"price":"0.97", "size":"2250.95"}, {"price":"0.96", "size":"1270.1"}, {"price":"0.95", "size":"1768.6"}, {"price":"0.94", "size":"1124.35"}, {"price":"0.93", "size":"959.2"}, {"price":"0.92", "size":"1225.88"}, {"price":"0.91", "size":"796.7"}, {"price":"0.9", "size":"365.2"}, {"price":"0.89", "size":"1502.1"}, {"price":"0.88", "size":"195.05"}, {"price":"0.87", "size":"147.4"}, {"price":"0.86", "size":"183.4"}, {"price":"0.85", "size":"469.43"}, {"price":"0.84", "size":"127.1"}, {"price":"0.83", "size":"107.69"}, {"price":"0.82", "size":"125.7"}, {"price":"0.81", "size":"98.89"}, {"price":"0.8", "size":"206.2"}, {"price":"0.79", "size":"616.8"}, {"price":"0.78", "size":"992.5"}, {"price":"0.77", "size":"82.3"}, {"price":"0.76", "size":"118.03"}, {"price":"0.75", "size":"92.2"}, {"price":"0.74", "size":"90.3"}, {"price":"0.73", "size":"70.3"}, {"price":"0.72", "size":"79.87"}, {"price":"0.71", "size":"74.39"}, {"price":"0.7", "size":"83"}, {"price":"0.69", "size":"89.7"}, {"price":"0.68", "size":"160.64"}, {"price":"0.67", "size":"113.1"}, {"price":"0.66", "size":"92.8"}, {"price":"0.65", "size":"84.6"}, {"price":"0.64", "size":"79.39"}, {"price":"0.63", "size":"194.2"}, {"price":"0.62", "size":"85"}, {"price":"0.61", "size":"69.8"}, {"price":"0.6", "size":"97.94"}, {"price":"0.59", "size":"75.5"}, {"price":"0.58", "size":"86.02"}, {"price":"0.57", "size":"75.3"}, {"price":"0.56", "size":"64.2"}, {"price":"0.55", "size":"204.71"}, {"price":"0.54", "size":"102.1"}, {"price":"0.53", "size":"72.1"}, {"price":"0.52", "size":"71"}, {"price":"0.51", "size":"71"}, {"price":"0.5", "size":"125.8"}, {"price":"0.49", "size":"415.92"}, {"price":"0.48", "size":"255.91"}, {"price":"0.47", "size":"467.7"}, {"price":"0.46", "size":"123.85"}, {"price":"0.45", "size":"226.69"}, {"price":"0.44", "size":"263.99"}, {"price":"0.43", "size":"139"}, {"price":"0.42", "size":"156.82"}, {"price":"0.41", "size":"155.04"}], "hash":"405cbad6e24f68b43c5aba39620c0765df6ecbc3", "timestamp":"1784449238547", "event_type":"book"}
{"market":"0xab772601f501b265bfe8982eb61d5347ef9945de314bfdf4ac0189c288ffb0b3", "asset_id":"17924629579804316786455515989238352689210911545477836576430679697715946894553", "bids":[{"price":"0.01", "size":"13054.5"}, {"price":"0.02", "size":"3885.25"}, {"price":"0.03", "size":"2250.95"}, {"price":"0.04", "size":"1270.1"}, {"price":"0.05", "size":"1768.6"}, {"price":"0.06", "size":"1124.35"}, {"price":"0.07", "size":"959.2"}, {"price":"0.08", "size":"1225.88"}, {"price":"0.09", "size":"796.7"}, {"price":"0.1", "size":"365.2"}, {"price":"0.11", "size":"1502.1"}, {"price":"0.12", "size":"195.05"}, {"price":"0.13", "size":"147.4"}, {"price":"0.14", "size":"183.4"}, {"price":"0.15", "size":"469.43"}, {"price":"0.16", "size":"127.1"}, {"price":"0.17", "size":"107.69"}, {"price":"0.18", "size":"125.7"}, {"price":"0.19", "size":"98.89"}, {"price":"0.2", "size":"206.2"}, {"price":"0.21", "size":"616.8"}, {"price":"0.22", "size":"992.5"}, {"price":"0.23", "size":"82.3"}, {"price":"0.24", "size":"118.03"}, {"price":"0.25", "size":"92.2"}, {"price":"0.26", "size":"90.3"}, {"price":"0.27", "size":"70.3"}, {"price":"0.28", "size":"79.87"}, {"price":"0.29", "size":"74.39"}, {"price":"0.3", "size":"83"}, {"price":"0.31", "size":"89.7"}, {"price":"0.32", "size":"160.64"}, {"price":"0.33", "size":"113.1"}, {"price":"0.34", "size":"92.8"}, {"price":"0.35", "size":"84.6"}, {"price":"0.36", "size":"79.39"}, {"price":"0.37", "size":"194.2"}, {"price":"0.38", "size":"85"}, {"price":"0.39", "size":"69.8"}, {"price":"0.4", "size":"97.94"}, {"price":"0.41", "size":"75.5"}, {"price":"0.42", "size":"86.02"}, {"price":"0.43", "size":"75.3"}, {"price":"0.44", "size":"64.2"}, {"price":"0.45", "size":"204.71"}, {"price":"0.46", "size":"102.1"}, {"price":"0.47", "size":"72.1"}, {"price":"0.48", "size":"71"}, {"price":"0.49", "size":"71"}, {"price":"0.5", "size":"125.8"}, {"price":"0.51", "size":"415.92"}, {"price":"0.52", "size":"255.91"}, {"price":"0.53", "size":"467.7"}, {"price":"0.54", "size":"123.85"}, {"price":"0.55", "size":"226.69"}, {"price":"0.56", "size":"263.99"}, {"price":"0.57", "size":"139"}, {"price":"0.58", "size":"156.82"}, {"price":"0.59", "size":"155.04"}], "asks":[{"price":"0.99", "size":"14884.14"}, {"price":"0.98", "size":"3964.52"}, {"price":"0.97", "size":"2179.29"}, {"price":"0.96", "size":"1215.1"}, {"price":"0.95", "size":"1752.19"}, {"price":"0.94", "size":"1122.02"}, {"price":"0.93", "size":"953.49"}, {"price":"0.92", "size":"1234.38"}, {"price":"0.91", "size":"791.7"}, {"price":"0.9", "size":"561.2"}, {"price":"0.89", "size":"1502.1"}, {"price":"0.88", "size":"1112.05"}, {"price":"0.87", "size":"139.4"}, {"price":"0.86", "size":"281.8"}, {"price":"0.85", "size":"444.04"}, {"price":"0.84", "size":"147.1"}, {"price":"0.83", "size":"207.17"}, {"price":"0.82", "size":"150.7"}, {"price":"0.81", "size":"103.89"}, {"price":"0.8", "size":"246.2"}, {"price":"0.79", "size":"636.8"}, {"price":"0.78", "size":"135.5"}, {"price":"0.77", "size":"112.3"}, {"price":"0.76", "size":"162.22"}, {"price":"0.75", "size":"137.2"}, {"price":"0.74", "size":"134.3"}, {"price":"0.73", "size":"148.5"}, {"price":"0.72", "size":"146.77"}, {"price":"0.71", "size":"216.99"}, {"price":"0.7", "size":"207.81"}, {"price":"0.69", "size":"550.01"}, {"price":"0.68", "size":"236.69"}, {"price":"0.67", "size":"134.65"}, {"price":"0.66", "size":"125.76"}, {"price":"0.65", "size":"138.8"}, {"price":"0.64", "size":"211.77"}, {"price":"0.63", "size":"165.97"}, {"price":"0.62", "size":"394.01"}], "hash":"8b7d2b3bac69b201d218328e7f200e149aabcec5", "timestamp":"1784449238547", "event_type":"book"}
{"market":"0xab772601f501b265bfe8982eb61d5347ef9945de314bfdf4ac0189c288ffb0b3", "price_changes":[{"asset_id":"17924629579804316786455515989238352689210911545477836576430679697715946894553", "price":"0.5", "size":"97", "side":"BUY", "hash":"a95f2d6a29233da3d8fcb40c7a29a8c0c0762b65", "best_bid":"0.59", "best_ask":"0.62"}, {"asset_id":"12935926064588426924078449947177910958215776269411501731627440228801766632772", "price":"0.5", "size":"97", "side":"SELL", "hash":"4f8a85d784ee4c84077eac86ca9f12ff0554d172", "best_bid":"0.38", "best_ask":"0.41"}], "timestamp":"1784449238552", "event_type":"price_change"}
{"market":"0xab772601f501b265bfe8982eb61d5347ef9945de314bfdf4ac0189c288ffb0b3", "price_changes":[{"asset_id":"12935926064588426924078449947177910958215776269411501731627440228801766632772", "price":"0.39", "size":"50", "side":"BUY", "hash":"3eae915b8bd335d464b9760796af1a6f52aa96cb", "best_bid":"0.39", "best_ask":"0.41"}, {"asset_id":"17924629579804316786455515989238352689210911545477836576430679697715946894553", "price":"0.61", "size":"50", "side":"SELL", "hash":"01b0b7aeaed7fa5de85faab99d7d3805b92bf1bd", "best_bid":"0.59", "best_ask":"0.61"}], "timestamp":"1784449238552", "event_type":"price_change"}
{"market":"0xab772601f501b265bfe8982eb61d5347ef9945de314bfdf4ac0189c288ffb0b3", "price_changes":[{"asset_id":"17924629579804316786455515989238352689210911545477836576430679697715946894553", "price":"0.57", "size":"144", "side":"BUY", "hash":"7c2850a1159a00cc3a9b3ca23c046b50b255b9bf", "best_bid":"0.59", "best_ask":"0.61"}, {"asset_id":"12935926064588426924078449947177910958215776269411501731627440228801766632772", "price":"0.43", "size":"144", "side":"SELL", "hash":"44c3d0e11bb426c763069f1669ea3f94e8449830", "best_bid":"0.39", "best_ask":"0.41"}], "timestamp":"1784449238553", "event_type":"price_change"}
{"market":"0xab772601f501b265bfe8982eb61d5347ef9945de314bfdf4ac0189c288ffb0b3", "price_changes":[{"asset_id":"12935926064588426924078449947177910958215776269411501731627440228801766632772", "price":"0.39", "size":"66.66", "side":"BUY", "hash":"fd62730901d326dee8c8db0aa66fa33108779c45", "best_bid":"0.39", "best_ask":"0.41"}, {"asset_id":"17924629579804316786455515989238352689210911545477836576430679697715946894553", "price":"0.61", "size":"66.66", "side":"SELL", "hash":"ab8cc888c5841de391497f7f4b1e593c008a4490", "best_bid":"0.59", "best_ask":"0.61"}], "timestamp":"1784449238558", "event_type":"price_change"}
{"market":"0xab772601f501b265bfe8982eb61d5347ef9945de314bfdf4ac0189c288ffb0b3", "price_changes":[{"asset_id":"12935926064588426924078449947177910958215776269411501731627440228801766632772", "price":"0.4", "size":"16.66", "side":"BUY", "hash":"ec4bbb19d5f69522311439150985cc40c29c0e1f", "best_bid":"0.4", "best_ask":"0.41"}, {"asset_id":"17924629579804316786455515989238352689210911545477836576430679697715946894553", "price":"0.6", "size":"16.66", "side":"SELL", "hash":"5ab39b3627035d9c0b6ccb1a992ceb3c29a01a91", "best_bid":"0.59", "best_ask":"0.6"}], "timestamp":"1784449238558", "event_type":"price_change"}
{"market":"0xab772601f501b265bfe8982eb61d5347ef9945de314bfdf4ac0189c288ffb0b3", "price_changes":[{"asset_id":"12935926064588426924078449947177910958215776269411501731627440228801766632772", "price":"0.39", "size":"79.99", "side":"BUY", "hash":"5800f6ac4b3dcaeb60a071e5e0952e612987e109", "best_bid":"0.4", "best_ask":"0.41"}, {"asset_id":"17924629579804316786455515989238352689210911545477836576430679697715946894553", "price":"0.61", "size":"79.99", "side":"SELL", "hash":"87c5c5aa09f5fa05e32a02f6cc0e0420c231efa8", "best_bid":"0.59", "best_ask":"0.6"}], "timestamp":"1784449238559", "event_type":"price_change"}
{"market":"0xab772601f501b265bfe8982eb61d5347ef9945de314bfdf4ac0189c288ffb0b3", "price_changes":[{"asset_id":"12935926064588426924078449947177910958215776269411501731627440228801766632772", "price":"0.4", "size":"29.99", "side":"BUY", "hash":"b38fcd105718ddebe707f7a732dd9385747c3293", "best_bid":"0.4", "best_ask":"0.41"}, {"asset_id":"17924629579804316786455515989238352689210911545477836576430679697715946894553", "price":"0.6", "size":"29.99", "side":"SELL", "hash":"7844bd4137eab661829994e6ce7d12b4fe8acdfe", "best_bid":"0.59", "best_ask":"0.6"}], "timestamp":"1784449238559", "event_type":"price_change"}
{"market":"0xab772601f501b265bfe8982eb61d5347ef9945de314bfdf4ac0189c288ffb0b3", "price_changes":[{"asset_id":"12935926064588426924078449947177910958215776269411501731627440228801766632772", "price":"0.39", "size":"104.99", "side":"BUY", "hash":"2352be9a51dbe0e2881683e4aedb5baadbb2ff93", "best_bid":"0.4", "best_ask":"0.41"}, {"asset_id":"17924629579804316786455515989238352689210911545477836576430679697715946894553", "price":"0.61", "size":"104.99", "side":"SELL", "hash":"cce29f3c9b7f774a6f641b553cb1b73a54b9c26b", "best_bid":"0.59", "best_ask":"0.6"}], "timestamp":"1784449238560", "event_type":"price_change"}
{"market":"0xab772601f501b265bfe8982eb61d5347ef9945de314bfdf4ac0189c288ffb0b3", "price_changes":[{"asset_id":"12935926064588426924078449947177910958215776269411501731627440228801766632772", "price":"0.39", "size":"121.65", "side":"BUY", "hash":"9816d2259d002865cd0228b6800cf6b91bedb21f", "best_bid":"0.4", "best_ask":"0.41"}, {"asset_id":"17924629579804316786455515989238352689210911545477836576430679697715946894553", "price":"0.61", "size":"121.65", "side":"SELL", "hash":"7b1d4ed782d08f1b6ee532cac1c47f95ab10f933", "best_bid":"0.59", "best_ask":"0.6"}], "timestamp":"1784449238561", "event_type":"price_change"}
{"market":"0xab772601f501b265bfe8982eb61d5347ef9945de314bfdf4ac0189c288ffb0b3", "price_changes":[{"asset_id":"12935926064588426924078449947177910958215776269411501731627440228801766632772", "price":"0.01", "size":"14889.14", "side":"BUY", "hash":"65f34469dc3e91b6cbf5dadd4621e115134e479f", "best_bid":"0.4", "best_ask":"0.41"}, {"asset_id":"17924629579804316786455515989238352689210911545477836576430679697715946894553", "price":"0.99", "size":"14889.14", "side":"SELL", "hash":"f0a19681e6131ed154cfc89e7a2c7ef0d51a9c2f", "best_bid":"0.59", "best_ask":"0.6"}], "timestamp":"1784449238561", "event_type":"price_change"}
{"market":"0xab772601f501b265bfe8982eb61d5347ef9945de314bfdf4ac0189c288ffb0b3", "price_changes":[{"asset_id":"12935926064588426924078449947177910958215776269411501731627440228801766632772", "price":"0.4", "size":"46.65", "side":"BUY", "hash":"7b9bc9d5e43cf8dd4843350c315cf5f4c7aa4c84", "best_bid":"0.4", "best_ask":"0.41"}, {"asset_id":"17924629579804316786455515989238352689210911545477836576430679697715946894553", "price":"0.6", "size":"46.65", "side":"SELL", "hash":"0df8670eb0500861560580ee13257922d85a6ea6", "best_bid":"0.59", "best_ask":"0.6"}], "timestamp":"1784449238562", "event_type":"price_change"}
{"market":"0xab772601f501b265bfe8982eb61d5347ef9945de314bfdf4ac0189c288ffb0b3", "price_changes":[{"asset_id":"12935926064588426924078449947177910958215776269411501731627440228801766632772", "price":"0.01", "size":"14894.14", "side":"BUY", "hash":"caf27ce3b69e570ec3511fe61f937d4363fcbf15", "best_bid":"0.4", "best_ask":"0.41"}, {"asset_id":"17924629579804316786455515989238352689210911545477836576430679697715946894553", "price":"0.99", "size":"14894.14", "side":"SELL", "hash":"4d3efffad44cae6731fa643a3ff05c53d73645cd", "best_bid":"0.59", "best_ask":"0.6"}], "timestamp":"1784449238562", "event_type":"price_change"}
{"market":"0xab772601f501b265bfe8982eb61d5347ef9945de314bfdf4ac0189c288ffb0b3", "price_changes":[{"asset_id":"12935926064588426924078449947177910958215776269411501731627440228801766632772", "price":"0.22", "size":"115.5", "side":"BUY", "hash":"881bc69894aa2819e508f5b16c6d66ced5a71ff5", "best_bid":"0.4", "best_ask":"0.41"}, {"asset_id":"17924629579804316786455515989238352689210911545477836576430679697715946894553", "price":"0.78", "size":"115.5", "side":"SELL", "hash":"ee3b24a76cee9faff29f1b6ca44b50b96e92383f", "best_bid":"0.59", "best_ask":"0.6"}], "timestamp":"1784449238563", "event_type":"price_change"}
{"market":"0xab772601f501b265bfe8982eb61d5347ef9945de314bfdf4ac0189c288ffb0b3", "price_changes":[{"asset_id":"17924629579804316786455515989238352689210911545477836576430679697715946894553", "price":"0.01", "size":"13059.5", "side":"BUY", "hash":"52b0057eecedd842bb792460eddbc2ca238709dc", "best_bid":"0.59", "best_ask":"0.6"}, {"asset_id":"12935926064588426924078449947177910958215776269411501731627440228801766632772", "price":"0.99", "size":"13059.5", "side":"SELL", "hash":"c09d93fda4c5e6f3efff5ccb86212eea6382e997", "best_bid":"0.4", "best_ask":"0.41"}], "timestamp":"1784449238563", "event_type":"price_change"}
{"market":"0xab772601f501b265bfe8982eb61d5347ef9945de314bfdf4ac0189c288ffb0b3", "price_changes":[{"asset_id":"12935926064588426924078449947177910958215776269411501731627440228801766632772", "price":"0.01", "size":"14899.14", "side":"BUY", "hash":"5ba97c031b011381e16330239276f14c6a67975d", "best_bid":"0.4", "best_ask":"0.41"}, {"asset_id":"17924629579804316786455515989238352689210911545477836576430679697715946894553", "price":"0.99", "size":"14899.14", "side":"SELL", "hash":"686544df0fc910269250e1c8c97ea689d496dbc5", "best_bid":"0.59", "best_ask":"0.6"}], "timestamp":"1784449238564", "event_type":"price_change"}
{"market":"0xab772601f501b265bfe8982eb61d5347ef9945de314bfdf4ac0189c288ffb0b3", "price_changes":[{"asset_id":"17924629579804316786455515989238352689210911545477836576430679697715946894553", "price":"0.01", "size":"13064.5", "side":"BUY", "hash":"7b55597de4b12f0a7262971d5772e2e139a4a110", "best_bid":"0.59", "best_ask":"0.6"}, {"asset_id":"12935926064588426924078449947177910958215776269411501731627440228801766632772", "price":"0.99", "size":"13064.5", "side":"SELL", "hash":"72c2ae4e214fc63beca5450da9de6412efe03ef1", "best_bid":"0.4", "best_ask":"0.41"}], "timestamp":"1784449238565", "event_type":"price_change"}
{"market":"0xab772601f501b265bfe8982eb61d5347ef9945de314bfdf4ac0189c288ffb0b3", "price_changes":[{"asset_id":"12935926064588426924078449947177910958215776269411501731627440228801766632772", "price":"0.39", "size":"221.65", "side":"BUY", "hash":"5d1db6baab759b3bdef69fdf9f737126a6a6b6d2", "best_bid":"0.4", "best_ask":"0.41"}, {"asset_id":"17924629579804316786455515989238352689210911545477836576430679697715946894553", "price":"0.61", "size":"221.65", "side":"SELL", "hash":"5612dea92db4a1a0ceecb67c47d222fb88fab3d5", "best_bid":"0.59", "best_ask":"0.6"}], "timestamp":"1784449238565", "event_type":"price_change"}
{"market":"0xab772601f501b265bfe8982eb61d5347ef9945de314bfdf4ac0189c288ffb0b3", "price_changes":[{"asset_id":"17924629579804316786455515989238352689210911545477836576430679697715946894553", "price":"0.58", "size":"141.82", "side":"BUY", "hash":"c7a9ef3bf766aae7886249a8a899cd1833d82f94", "best_bid":"0.59", "best_ask":"0.6"}, {"asset_id":"12935926064588426924078449947177910958215776269411501731627440228801766632772", "price":"0.42", "size":"141.82", "side":"SELL", "hash":"c6be569195c3b1aa34ee615b8305c0a5eb95eb4a", "best_bid":"0.4", "best_ask":"0.41"}], "timestamp":"1784449238566", "event_type":"price_change"}
{"market":"0xab772601f501b265bfe8982eb61d5347ef9945de314bfdf4ac0189c288ffb0b3", "price_changes":[{"asset_id":"17924629579804316786455515989238352689210911545477836576430679697715946894553", "price":"0.01", "size":"13069.5", "side":"BUY", "hash":"5c8c21736d2e140265f85ecde6deed698167e20d", "best_bid":"0.59", "best_ask":"0.6"}, {"asset_id":"12935926064588426924078449947177910958215776269411501731627440228801766632772", "price":"0.99", "size":"13069.5", "side":"SELL", "hash":"5b2a7f98e605f11cc6ec0831725b7d5834f07305", "best_bid":"0.4", "best_ask":"0.41"}], "timestamp":"1784449238566", "event_type":"price_change"}
{"market":"0xab772601f501b265bfe8982eb61d5347ef9945de314bfdf4ac0189c288ffb0b3", "price_changes":[{"asset_id":"12935926064588426924078449947177910958215776269411501731627440228801766632772", "price":"0.13", "size":"124.4", "side":"BUY", "hash":"4111e96d97e72366a2c468e3926405bd8eadd749", "best_bid":"0.4", "best_ask":"0.41"}, {"asset_id":"17924629579804316786455515989238352689210911545477836576430679697715946894553", "price":"0.87", "size":"124.4", "side":"SELL", "hash":"9224f2434ddbd9d891441d1b7913196d4e183e98", "best_bid":"0.59", "best_ask":"0.6"}], "timestamp":"1784449238567", "event_type":"price_change"}
{"market":"0xab772601f501b265bfe8982eb61d5347ef9945de314bfdf4ac0189c288ffb0b3", "price_changes":[{"asset_id":"12935926064588426924078449947177910958215776269411501731627440228801766632772", "price":"0.4", "size":"146.65", "side":"BUY", "hash":"886dab4a8cfc53661296d342197d46342f4b02fa", "best_bid":"0.4", "best_ask":"0.41"}, {"asset_id":"17924629579804316786455515989238352689210911545477836576430679697715946894553", "price":"0.6", "size":"146.65", "side":"SELL", "hash":"43e91596174c914358fe5b0f0cf56b8b0dc90a8a", "best_bid":"0.59", "best_ask":"0.6"}], "timestamp":"1784449238568", "event_type":"price_change"}
{"market":"0xab772601f501b265bfe8982eb61d5347ef9945de314bfdf4ac0189c288ffb0b3", "price_changes":[{"asset_id":"12935926064588426924078449947177910958215776269411501731627440228801766632772", "price":"0.23", "size":"155.8", "side":"BUY", "hash":"39fd65e5ec4f51668a71904ba022e477e562266f", "best_bid":"0.4", "best_ask":"0.41"}, {"asset_id":"17924629579804316786455515989238352689210911545477836576430679697715946894553", "price":"0.77", "size":"155.8", "side":"SELL", "hash":"b7b9b9b14260a5c83da28e786ea6f9fb648b9b91", "best_bid":"0.59", "best_ask":"0.6"}], "timestamp":"1784449238568", "event_type":"price_change"}
{"market":"0xab772601f501b265bfe8982eb61d5347ef9945de314bfdf4ac0189c288ffb0b3", "price_changes":[{"asset_id":"17924629579804316786455515989238352689210911545477836576430679697715946894553", "price":"0.52", "size":"230.91", "side":"BUY", "hash":"af14317f3b939f91690c54bb067aff4d2cf2bdea", "best_bid":"0.59", "best_ask":"0.6"}, {"asset_id":"12935926064588426924078449947177910958215776269411501731627440228801766632772", "price":"0.48", "size":"230.91", "side":"SELL", "hash":"d4304c542893681ed8420da9849d5a11b4186a46", "best_bid":"0.4", "best_ask":"0.41"}], "timestamp":"1784449238570", "event_type":"price_change"}
{"market":"0xab772601f501b265bfe8982eb61d5347ef9945de314bfdf4ac0189c288ffb0b3", "price_changes":[{"asset_id":"12935926064588426924078449947177910958215776269411501731627440228801766632772", "price":"0.38", "size":"409.01", "side":"BUY", "hash":"f8b4c485f32fccfdb7c1c8074f3f1816bb5c89d0", "best_bid":"0.4", "best_ask":"0.41"}, {"asset_id":"17924629579804316786455515989238352689210911545477836576430679697715946894553", "price":"0.62", "size":"409.01", "side":"SELL", "hash":"1b7e7bc1456e35d7bc7aefa7071552db580b801c", "best_bid":"0.59", "best_ask":"0.6"}], "timestamp":"1784449238571", "event_type":"price_change"}
{"market":"0xab772601f501b265bfe8982eb61d5347ef9945de314bfdf4ac0189c288ffb0b3", "price_changes":[{"asset_id":"12935926064588426924078449947177910958215776269411501731627440228801766632772", "price":"0.14", "size":"266.8", "side":"BUY", "hash":"8ae16f0ec271aa17f84a4f7fdf35eca2063be4ca", "best_bid":"0.4", "best_ask":"0.41"}, {"asset_id":"17924629579804316786455515989238352689210911545477836576430679697715946894553", "price":"0.86", "size":"266.8", "side":"SELL", "hash":"bb22056cdb79a6194eb29247e40b5099fd1f3804", "best_bid":"0.59", "best_ask":"0.6"}], "timestamp":"1784449238572", "event_type":"price_change"}
{"market":"0xab772601f501b265bfe8982eb61d5347ef9945de314bfdf4ac0189c288ffb0b3", "price_changes":[{"asset_id":"12935926064588426924078449947177910958215776269411501731627440228801766632772", "price":"0.38", "size":"394.01", "side":"BUY", "hash":"1a1fe836d61124b023c546bd33fe2c1da6ee8490", "best_bid":"0.4", "best_ask":"0.41"}, {"asset_id":"17924629579804316786455515989238352689210911545477836576430679697715946894553", "price":"0.62", "size":"394.01", "side":"SELL", "hash":"b0b3eb58d909800f3040182fe8261a1d53f6d8d7", "best_bid":"0.59", "best_ask":"0.6"}], "timestamp":"1784449238572", "event_type":"price_change"}
{"market":"0xab772601f501b265bfe8982eb61d5347ef9945de314bfdf4ac0189c288ffb0b3", "price_changes":[{"asset_id":"17924629579804316786455515989238352689210911545477836576430679697715946894553", "price":"0.01", "size":"13074.5", "side":"BUY", "hash":"acdfc4f0c24eca78027e016d8365d33d39056ded", "best_bid":"0.59", "best_ask":"0.6"}, {"asset_id":"12935926064588426924078449947177910958215776269411501731627440228801766632772", "price":"0.99", "size":"13074.5", "side":"SELL", "hash":"855095b437bf92fbf099d44f411c805af36b1540", "best_bid":"0.4", "best_ask":"0.41"}], "timestamp":"1784449238572", "event_type":"price_change"}
{"market":"0xab772601f501b265bfe8982eb61d5347ef9945de314bfdf4ac0189c288ffb0b3", "price_changes":[{"asset_id":"12935926064588426924078449947177910958215776269411501731627440228801766632772", "price":"0.35", "size":"133.8", "side":"BUY", "hash":"4396bf5c216801701017827a8cd9244e7eb593da", "best_bid":"0.4", "best_ask":"0.41"}, {"asset_id":"17924629579804316786455515989238352689210911545477836576430679697715946894553", "price":"0.65", "size":"133.8", "side":"SELL", "hash":"a9b465f4a2d7da3aa9c7c7d598c9673308a2c4ff", "best_bid":"0.59", "best_ask":"0.6"}], "timestamp":"1784449238573", "event_type":"price_change"}
{"market":"0xab772601f501b265bfe8982eb61d5347ef9945de314bfdf4ac0189c288ffb0b3", "price_changes":[{"asset_id":"12935926064588426924078449947177910958215776269411501731627440228801766632772", "price":"0.36", "size":"206.77", "side":"BUY", "hash":"4396bf5c216801701017827a8cd9244e7eb593da", "best_bid":"0.4", "best_ask":"0.41"}, {"asset_id":"17924629579804316786455515989238352689210911545477836576430679697715946894553", "price":"0.64", "size":"206.77", "side":"SELL", "hash":"a9b465f4a2d7da3aa9c7c7d598c9673308a2c4ff", "best_bid":"0.59", "best_ask":"0.6"}], "timestamp":"1784449238573", "event_type":"price_change"}
{"market":"0xab772601f501b265bfe8982eb61d5347ef9945de314bfdf4ac0189c288ffb0b3", "price_changes":[{"asset_id":"17924629579804316786455515989238352689210911545477836576430679697715946894553", "price":"0.59", "size":"150.04", "side":"BUY", "hash":"86fb44551625596801d6f5432dd72e7d693f756e", "best_bid":"0.59", "best_ask":"0.6"}, {"asset_id":"12935926064588426924078449947177910958215776269411501731627440228801766632772", "price":"0.41", "size":"150.04", "side":"SELL", "hash":"940185dabc0e318818277867c0f7f0022b858a89", "best_bid":"0.4", "best_ask":"0.41"}], "timestamp":"1784449238573", "event_type":"price_change"}
{"market":"0xab772601f501b265bfe8982eb61d5347ef9945de314bfdf4ac0189c288ffb0b3", "price_changes":[{"asset_id":"17924629579804316786455515989238352689210911545477836576430679697715946894553", "price":"0.58", "size":"136.82", "side":"BUY", "hash":"86fb44551625596801d6f5432dd72e7d693f756e", "best_bid":"0.59", "best_ask":"0.6"}, {"asset_id":"12935926064588426924078449947177910958215776269411501731627440228801766632772", "price":"0.42", "size":"136.82", "side":"SELL", "hash":"940185dabc0e318818277867c0f7f0022b858a89", "best_bid":"0.4", "best_ask":"0.41"}], "timestamp":"1784449238573", "event_type":"price_change"}
{"market":"0xab772601f501b265bfe8982eb61d5347ef9945de314bfdf4ac0189c288ffb0b3", "price_changes":[{"asset_id":"12935926064588426924078449947177910958215776269411501731627440228801766632772", "price":"0.38", "size":"399.01", "side":"BUY", "hash":"c23c7cc1d6d142c0e4fd33f3ac5bf1d7dc0d3590", "best_bid":"0.4", "best_ask":"0.41"}, {"asset_id":"17924629579804316786455515989238352689210911545477836576430679697715946894553", "price":"0.62", "size":"399.01", "side":"SELL", "hash":"89a51dc8dbb0169bc2afd1b86db3f86d07a25bf1", "best_bid":"0.59", "best_ask":"0.6"}], "timestamp":"1784449238574", "event_type":"price_change"}
{"market":"0xab772601f501b265bfe8982eb61d5347ef9945de314bfdf4ac0189c288ffb0b3", "price_changes":[{"asset_id":"12935926064588426924078449947177910958215776269411501731627440228801766632772", "price":"0.39", "size":"226.65", "side":"BUY", "hash":"901d64718d907a7023a77a6f51ef0dbd405b6856", "best_bid":"0.4", "best_ask":"0.41"}, {"asset_id":"17924629579804316786455515989238352689210911545477836576430679697715946894553", "price":"0.61", "size":"226.65", "side":"SELL", "hash":"083f9e44bfc5ba15d2725df5c5e84d56aa159edc", "best_bid":"0.59", "best_ask":"0.6"}], "timestamp":"1784449238574", "event_type":"price_change"}
{"market":"0xab772601f501b265bfe8982eb61d5347ef9945de314bfdf4ac0189c288ffb0b3", "price_changes":[{"asset_id":"17924629579804316786455515989238352689210911545477836576430679697715946894553", "price":"0.55", "size":"208.69", "side":"BUY", "hash":"00234dc3e845c2d2516eeb19aa84b0510c440e34", "best_bid":"0.59", "best_ask":"0.6"}, {"asset_id":"12935926064588426924078449947177910958215776269411501731627440228801766632772", "price":"0.45", "size":"208.69", "side":"SELL", "hash":"26c93c6c7ecfaaac449fc711ae72e70691ea8d84", "best_bid":"0.4", "best_ask":"0.41"}], "timestamp":"1784449238575", "event_type":"price_change"}
{"market":"0xab772601f501b265bfe8982eb61d5347ef9945de314bfdf4ac0189c288ffb0b3", "price_changes":[{"asset_id":"17924629579804316786455515989238352689210911545477836576430679697715946894553", "price":"0.56", "size":"251.99", "side":"BUY", "hash":"00234dc3e845c2d2516eeb19aa84b0510c440e34", "best_bid":"0.59", "best_ask":"0.6"}, {"asset_id":"12935926064588426924078449947177910958215776269411501731627440228801766632772", "price":"0.44", "size":"251.99", "side":"SELL", "hash":"26c93c6c7ecfaaac449fc711ae72e70691ea8d84", "best_bid":"0.4", "best_ask":"0.41"}], "timestamp":"1784449238575", "event_type":"price_change"}
{"market":"0xab772601f501b265bfe8982eb61d5347ef9945de314bfdf4ac0189c288ffb0b3", "price_changes":[{"asset_id":"17924629579804316786455515989238352689210911545477836576430679697715946894553", "price":"0.58", "size":"131.82", "side":"BUY", "hash":"00234dc3e845c2d2516eeb19aa84b0510c440e34", "best_bid":"0.59", "best_ask":"0.6"}, {"asset_id":"12935926064588426924078449947177910958215776269411501731627440228801766632772", "price":"0.42", "size":"131.82", "side":"SELL", "hash":"26c93c6c7ecfaaac449fc711ae72e70691ea8d84", "best_bid":"0.4", "best_ask":"0.41"}], "timestamp":"1784449238575", "event_type":"price_change"}
{"market":"0xab772601f501b265bfe8982eb61d5347ef9945de314bfdf4ac0189c288ffb0b3", "price_changes":[{"asset_id":"17924629579804316786455515989238352689210911545477836576430679697715946894553", "price":"0.57", "size":"136", "side":"BUY", "hash":"00234dc3e845c2d2516eeb19aa84b0510c440e34", "best_bid":"0.59", "best_ask":"0.6"}, {"asset_id":"12935926064588426924078449947177910958215776269411501731627440228801766632772", "price":"0.43", "size":"136", "side":"SELL", "hash":"26c93c6c7ecfaaac449fc711ae72e70691ea8d84", "best_bid":"0.4", "best_ask":"0.41"}], "timestamp":"1784449238575", "event_type":"price_change"}
{"market":"0xab772601f501b265bfe8982eb61d5347ef9945de314bfdf4ac0189c288ffb0b3", "price_changes":[{"asset_id":"12935926064588426924078449947177910958215776269411501731627440228801766632772", "price":"0.38", "size":"394.01", "side":"BUY", "hash":"2ae4f63d0ef633f3d231518cb76a630b3085c9ec", "best_bid":"0.4", "best_ask":"0.41"}, {"asset_id":"17924629579804316786455515989238352689210911545477836576430679697715946894553", "price":"0.62", "size":"394.01", "side":"SELL", "hash":"e5c0842d9ce52f4f8bf82cd8dd581010be3096e9", "best_bid":"0.59", "best_ask":"0.6"}], "timestamp":"1784449238575", "event_type":"price_change"}
{"market":"0xab772601f501b265bfe8982eb61d5347ef9945de314bfdf4ac0189c288ffb0b3", "price_changes":[{"asset_id":"12935926064588426924078449947177910958215776269411501731627440228801766632772", "price":"0.39", "size":"231.65", "side":"BUY", "hash":"01ea8e7d6aac34741046660e994e38470848827d", "best_bid":"0.4", "best_ask":"0.41"}, {"asset_id":"17924629579804316786455515989238352689210911545477836576430679697715946894553", "price":"0.61", "size":"231.65", "side":"SELL", "hash":"dc1edd337385cfaadfd4cbc34012a9cb2f407dae", "best_bid":"0.59", "best_ask":"0.6"}], "timestamp":"1784449238575", "event_type":"price_change"}
{"market":"0xab772601f501b265bfe8982eb61d5347ef9945de314bfdf4ac0189c288ffb0b3", "price_changes":[{"asset_id":"17924629579804316786455515989238352689210911545477836576430679697715946894553", "price":"0.53", "size":"485.7", "side":"BUY", "hash":"7d05ec11b0317f998022ffb5352fa6b5bfe46546", "best_bid":"0.59", "best_ask":"0.6"}, {"asset_id":"12935926064588426924078449947177910958215776269411501731627440228801766632772", "price":"0.47", "size":"485.7", "side":"SELL", "hash":"ad326b7ae71a77a650d4197aa896c1bfe7593ded", "best_bid":"0.4", "best_ask":"0.41"}], "timestamp":"1784449238576", "event_type":"price_change"}
{"market":"0xab772601f501b265bfe8982eb61d5347ef9945de314bfdf4ac0189c288ffb0b3", "price_changes":[{"asset_id":"12935926064588426924078449947177910958215776269411501731627440228801766632772", "price":"0.39", "size":"236.65", "side":"BUY", "hash":"44c181fd8f2d7b6dd70fe319912dd6323f337c4b", "best_bid":"0.4", "best_ask":"0.41"}, {"asset_id":"17924629579804316786455515989238352689210911545477836576430679697715946894553", "price":"0.61", "size":"236.65", "side":"SELL", "hash":"0c5ed3ef50a41c054fde3a0cde588c476bd01c00", "best_bid":"0.59", "best_ask":"0.6"}], "timestamp":"1784449238577", "event_type":"price_change"}
{"market":"0xab772601f501b265bfe8982eb61d5347ef9945de314bfdf4ac0189c288ffb0b3", "price_changes":[{"asset_id":"17924629579804316786455515989238352689210911545477836576430679697715946894553", "price":"0.54", "size":"135.85", "side":"BUY", "hash":"d68d262b46622006e5b78fdb867c649537d66eda", "best_bid":"0.59", "best_ask":"0.6"}, {"asset_id":"12935926064588426924078449947177910958215776269411501731627440228801766632772", "price":"0.46", "size":"135.85", "side":"SELL", "hash":"eaea641f9eacc987346a64b370c1c71fabb2becb", "best_bid":"0.4", "best_ask":"0.41"}], "timestamp":"1784449238578", "event_type":"price_change"}
{"market":"0xab772601f501b265bfe8982eb61d5347ef9945de314bfdf4ac0189c288ffb0b3", "price_changes":[{"asset_id":"17924629579804316786455515989238352689210911545477836576430679697715946894553", "price":"0.57", "size":"141", "side":"BUY", "hash":"f76c0cf5e7aca9905f2e83582419e2c2cd6f56ff", "best_bid":"0.59", "best_ask":"0.6"}, {"asset_id":"12935926064588426924078449947177910958215776269411501731627440228801766632772", "price":"0.43", "size":"141", "side":"SELL", "hash":"4034723d15661baa9c9940c8eacc07a8743c4ab5", "best_bid":"0.4", "best_ask":"0.41"}], "timestamp":"1784449238578", "event_type":"price_change"}
{"market":"0xab772601f501b265bfe8982eb61d5347ef9945de314bfdf4ac0189c288ffb0b3", "price_changes":[{"asset_id":"12935926064588426924078449947177910958215776269411501731627440228801766632772", "price":"0.39", "size":"246.65", "side":"BUY", "hash":"60377329b0a8aa16ecf01dd240b4b73494439b46", "best_bid":"0.4", "best_ask":"0.41"}, {"asset_id":"17924629579804316786455515989238352689210911545477836576430679697715946894553", "price":"0.61", "size":"246.65", "side":"SELL", "hash":"19305fdf1e580bf763c1122ec74333ee042aa928", "best_bid":"0.59", "best_ask":"0.6"}], "timestamp":"1784449238579", "event_type":"price_change"}
{"market":"0xab772601f501b265bfe8982eb61d5347ef9945de314bfdf4ac0189c288ffb0b3", "price_changes":[{"asset_id":"17924629579804316786455515989238352689210911545477836576430679697715946894553", "price":"0.56", "size":"256.99", "side":"BUY", "hash":"f97810f298b042bda9f2f13fb52519d83e27d533", "best_bid":"0.59", "best_ask":"0.6"}, {"asset_id":"12935926064588426924078449947177910958215776269411501731627440228801766632772", "price":"0.44", "size":"256.99", "side":"SELL", "hash":"1ceff02813033168cd1e1285dcec2b9d8fb815fb", "best_bid":"0.4", "best_ask":"0.41"}], "timestamp":"1784449238579", "event_type":"price_change"}
{"market":"0xab772601f501b265bfe8982eb61d5347ef9945de314bfdf4ac0189c288ffb0b3", "price_changes":[{"asset_id":"12935926064588426924078449947177910958215776269411501731627440228801766632772", "price":"0.39", "size":"221.65", "side":"BUY", "hash":"d72e438b43ce460aab6fe0547269747f79952cea", "best_bid":"0.4", "best_ask":"0.41"}, {"asset_id":"17924629579804316786455515989238352689210911545477836576430679697715946894553", "price":"0.61", "size":"221.65", "side":"SELL", "hash":"25fee0f0f3eb8409a19a36cd130b34949515088f", "best_bid":"0.59", "best_ask":"0.6"}], "timestamp":"1784449238580", "event_type":"price_change"}
{"market":"0xab772601f501b265bfe8982eb61d5347ef9945de314bfdf4ac0189c288ffb0b3", "price_changes":[{"asset_id":"17924629579804316786455515989238352689210911545477836576430679697715946894553", "price":"0.5", "size":"129.39", "side":"BUY", "hash":"9fb4f673a0e3a9474c653d8060b9bd165f74054e", "best_bid":"0.59", "best_ask":"0.6"}, {"asset_id":"12935926064588426924078449947177910958215776269411501731627440228801766632772", "price":"0.5", "size":"129.39", "side":"SELL", "hash":"9301c9c15b2178f6c8b8834a36ae5651c320cf0c", "best_bid":"0.4", "best_ask":"0.41"}], "timestamp":"1784449238580", "event_type":"price_change"}
{"market":"0xab772601f501b265bfe8982eb61d5347ef9945de314bfdf4ac0189c288ffb0b3", "price_changes":[{"asset_id":"17924629579804316786455515989238352689210911545477836576430679697715946894553", "price":"0.37", "size":"94.2", "side":"BUY", "hash":"fd539a6794be54172f1ad7270f21af3652defcac", "best_bid":"0.59", "best_ask":"0.6"}, {"asset_id":"12935926064588426924078449947177910958215776269411501731627440228801766632772", "price":"0.63", "size":"94.2", "side":"SELL", "hash":"f437857c37327e13d911365b14a41de91171e363", "best_bid":"0.4", "best_ask":"0.41"}], "timestamp":"1784449238580", "event_type":"price_change"}
{"market":"0xab772601f501b265bfe8982eb61d5347ef9945de314bfdf4ac0189c288ffb0b3", "price_changes":[{"asset_id":"17924629579804316786455515989238352689210911545477836576430679697715946894553", "price":"0.34", "size":"67.8", "side":"BUY", "hash":"db6ee7ccd2e28ee4723c70bd1b3571d8ca9cf9f8", "best_bid":"0.59", "best_ask":"0.6"}, {"asset_id":"12935926064588426924078449947177910958215776269411501731627440228801766632772", "price":"0.66", "size":"67.8", "side":"SELL", "hash":"dc0e2ac4713181350c95db794ae7a5262ecf010b", "best_bid":"0.4", "best_ask":"0.41"}], "timestamp":"1784449238581", "event_type":"price_change"}
{"market":"0xab772601f501b265bfe8982eb61d5347ef9945de314bfdf4ac0189c288ffb0b3", "price_changes":[{"asset_id":"17924629579804316786455515989238352689210911545477836576430679697715946894553", "price":"0.55", "size":"213.69", "side":"BUY", "hash":"d3a3dfd95d2591f4c466b3e4688f347d6a8e4ae3", "best_bid":"0.59", "best_ask":"0.6"}, {"asset_id":"12935926064588426924078449947177910958215776269411501731627440228801766632772", "price":"0.45", "size":"213.69", "side":"SELL", "hash":"eee41e53a75500b9bd1f2b6403aba33d65825bdb", "best_bid":"0.4", "best_ask":"0.41"}], "timestamp":"1784449238581", "event_type":"price_change"}
{"market":"0xab772601f501b265bfe8982eb61d5347ef9945de314bfdf4ac0189c288ffb0b3", "price_changes":[{"asset_id":"12935926064588426924078449947177910958215776269411501731627440228801766632772", "price":"0.31", "size":"544.58", "side":"BUY", "hash":"29f84d346fb915f2dfd2bbfcf41e6d2304adaf43", "best_bid":"0.4", "best_ask":"0.41"}, {"asset_id":"17924629579804316786455515989238352689210911545477836576430679697715946894553", "price":"0.69", "size":"544.58", "side":"SELL", "hash":"e0f34e9695adda476e0d64d7c0088e653a9926a0", "best_bid":"0.59", "best_ask":"0.6"}], "timestamp":"1784449238581", "event_type":"price_change"}
{"market":"0xab772601f501b265bfe8982eb61d5347ef9945de314bfdf4ac0189c288ffb0b3", "price_changes":[{"asset_id":"12935926064588426924078449947177910958215776269411501731627440228801766632772", "price":"0.14", "size":"166.8", "side":"BUY", "hash":"6c7f82008b66e983597c8473f9c12cecdec450a8", "best_bid":"0.4", "best_ask":"0.41"}, {"asset_id":"17924629579804316786455515989238352689210911545477836576430679697715946894553", "price":"0.86", "size":"166.8", "side":"SELL", "hash":"df26f26318b1220f3f25096c475f6d5a9e8e8d7b", "best_bid":"0.59", "best_ask":"0.6"}], "timestamp":"1784449238581", "event_type":"price_change"}
{"market":"0xab772601f501b265bfe8982eb61d5347ef9945de314bfdf4ac0189c288ffb0b3", "price_changes":[{"asset_id":"12935926064588426924078449947177910958215776269411501731627440228801766632772", "price":"0.34", "size":"100.76", "side":"BUY", "hash":"0c3d81697bbc75e61d1e0362d2bc27c8d0504bfd", "best_bid":"0.4", "best_ask":"0.41"}, {"asset_id":"17924629579804316786455515989238352689210911545477836576430679697715946894553", "price":"0.66", "size":"100.76", "side":"SELL", "hash":"b8565f618f3546ca9afd16cf11dcf3245946e2e7", "best_bid":"0.59", "best_ask":"0.6"}], "timestamp":"1784449238581", "event_type":"price_change"}
{"market":"0xab772601f501b265bfe8982eb61d5347ef9945de314bfdf4ac0189c288ffb0b3", "price_changes":[{"asset_id":"12935926064588426924078449947177910958215776269411501731627440228801766632772", "price":"0.4", "size":"152.36", "side":"BUY", "hash":"a1cb8be457e8d5bcd6b4a140009c79014f2550ba", "best_bid":"0.4", "best_ask":"0.41"}, {"asset_id":"17924629579804316786455515989238352689210911545477836576430679697715946894553", "price":"0.6", "size":"152.36", "side":"SELL", "hash":"c09ad8583fbc84113fc8a0e0f37df2957f8652cd", "best_bid":"0.59", "best_ask":"0.6"}], "timestamp":"1784449238582", "event_type":"price_change"}
{"market":"0xab772601f501b265bfe8982eb61d5347ef9945de314bfdf4ac0189c288ffb0b3", "price_changes":[{"asset_id":"17924629579804316786455515989238352689210911545477836576430679697715946894553", "price":"0.56", "size":"261.99", "side":"BUY", "hash":"ae16d6575e5bf4075e338a697c8cd12fd2e86328", "best_bid":"0.59", "best_ask":"0.6"}, {"asset_id":"12935926064588426924078449947177910958215776269411501731627440228801766632772", "price":"0.44", "size":"261.99", "side":"SELL", "hash":"46aa50e1eab4ff8e0247bab25d71a13e31442048", "best_bid":"0.4", "best_ask":"0.41"}], "timestamp":"1784449238582", "event_type":"price_change"}
{"market":"0xab772601f501b265bfe8982eb61d5347ef9945de314bfdf4ac0189c288ffb0b3", "price_changes":[{"asset_id":"17924629579804316786455515989238352689210911545477836576430679697715946894553", "price":"0.62", "size":"389.01", "side":"SELL", "hash":"6c0e84241082b3940029d2201e617d65242b8682", "best_bid":"0.59", "best_ask":"0.6"}, {"asset_id":"12935926064588426924078449947177910958215776269411501731627440228801766632772", "price":"0.38", "size":"389.01", "side":"BUY", "hash":"dd2ac5a7c1aec6fa4a5122163f4d3c4961e2c1d7", "best_bid":"0.4", "best_ask":"0.41"}], "timestamp":"1784449238583", "event_type":"price_change"}
{"market":"0xab772601f501b265bfe8982eb61d5347ef9945de314bfdf4ac0189c288ffb0b3", "price_changes":[{"asset_id":"12935926064588426924078449947177910958215776269411501731627440228801766632772", "price":"0.4", "size":"150.69", "side":"BUY", "hash":"5a473be7f8205c39df288e10a02722228ccc980d", "best_bid":"0.4", "best_ask":"0.41"}, {"asset_id":"17924629579804316786455515989238352689210911545477836576430679697715946894553", "price":"0.6", "size":"150.69", "side":"SELL", "hash":"a7968b4e43d23d7ae7ca5c3b53618ce656299e50", "best_bid":"0.59", "best_ask":"0.6"}], "timestamp":"1784449238585", "event_type":"price_change"}
{"market":"0xab772601f501b265bfe8982eb61d5347ef9945de314bfdf4ac0189c288ffb0b3", "asset_id":"12935926064588426924078449947177910958215776269411501731627440228801766632772", "bids":[{"price":"0.01", "size":"14899.14"}, {"price":"0.02", "size":"3964.52"}, {"price":"0.03", "size":"2179.29"}, {"price":"0.04", "size":"1215.1"}, {"price":"0.05", "size":"1752.19"}, {"price":"0.06", "size":"1122.02"}, {"price":"0.07", "size":"953.49"}, {"price":"0.08", "size":"1234.38"}, {"price":"0.09", "size":"791.7"}, {"price":"0.1", "size":"561.2"}, {"price":"0.11", "size":"1502.1"}, {"price":"0.12", "size":"1112.05"}, {"price":"0.13", "size":"124.4"}, {"price":"0.14", "size":"166.8"}, {"price":"0.15", "size":"444.04"}, {"price":"0.16", "size":"147.1"}, {"price":"0.17", "size":"207.17"}, {"price":"0.18", "size":"150.7"}, {"price":"0.19", "size":"103.89"}, {"price":"0.2", "size":"246.2"}, {"price":"0.21", "size":"636.8"}, {"price":"0.22", "size":"115.5"}, {"price":"0.23", "size":"155.8"}, {"price":"0.24", "size":"162.22"}, {"price":"0.25", "size":"137.2"}, {"price":"0.26", "size":"134.3"}, {"price":"0.27", "size":"148.5"}, {"price":"0.28", "size":"146.77"}, {"price":"0.29", "size":"216.99"}, {"price":"0.3", "size":"207.81"}, {"price":"0.31", "size":"544.58"}, {"price":"0.32", "size":"236.69"}, {"price":"0.33", "size":"134.65"}, {"price":"0.34", "size":"100.76"}, {"price":"0.35", "size":"133.8"}, {"price":"0.36", "size":"206.77"}, {"price":"0.37", "size":"165.97"}, {"price":"0.38", "size":"389.01"}, {"price":"0.39", "size":"221.65"}, {"price":"0.4", "size":"150.69"}], "asks":[{"price":"0.99", "size":"13074.5"}, {"price":"0.98", "size":"3885.25"}, {"price":"0.97", "size":"2250.95"}, {"price":"0.96", "size":"1270.1"}, {"price":"0.95", "size":"1768.6"}, {"price":"0.94", "size":"1124.35"}, {"price":"0.93", "size":"959.2"}, {"price":"0.92", "size":"1225.88"}, {"price":"0.91", "size":"796.7"}, {"price":"0.9", "size":"365.2"}, {"price":"0.89", "size":"1502.1"}, {"price":"0.88", "size":"195.05"}, {"price":"0.87", "size":"147.4"}, {"price":"0.86", "size":"183.4"}, {"price":"0.85", "size":"469.43"}, {"price":"0.84", "size":"127.1"}, {"price":"0.83", "size":"107.69"}, {"price":"0.82", "size":"125.7"}, {"price":"0.81", "size":"98.89"}, {"price":"0.8", "size":"206.2"}, {"price":"0.79", "size":"616.8"}, {"price":"0.78", "size":"992.5"}, {"price":"0.77", "size":"82.3"}, {"price":"0.76", "size":"118.03"}, {"price":"0.75", "size":"92.2"}, {"price":"0.74", "size":"90.3"}, {"price":"0.73", "size":"70.3"}, {"price":"0.72", "size":"79.87"}, {"price":"0.71", "size":"74.39"}, {"price":"0.7", "size":"83"}, {"price":"0.69", "size":"89.7"}, {"price":"0.68", "size":"160.64"}, {"price":"0.67", "size":"113.1"}, {"price":"0.66", "size":"67.8"}, {"price":"0.65", "size":"84.6"}, {"price":"0.64", "size":"79.39"}, {"price":"0.63", "size":"94.2"}, {"price":"0.62", "size":"85"}, {"price":"0.61", "size":"69.8"}, {"price":"0.6", "size":"97.94"}, {"price":"0.59", "size":"75.5"}, {"price":"0.58", "size":"86.02"}, {"price":"0.57", "size":"75.3"}, {"price":"0.56", "size":"64.2"}, {"price":"0.55", "size":"204.71"}, {"price":"0.54", "size":"102.1"}, {"price":"0.53", "size":"72.1"}, {"price":"0.52", "size":"71"}, {"price":"0.51", "size":"71"}, {"price":"0.5", "size":"129.39"}, {"price":"0.49", "size":"415.92"}, {"price":"0.48", "size":"230.91"}, {"price":"0.47", "size":"485.7"}, {"price":"0.46", "size":"135.85"}, {"price":"0.45", "size":"213.69"}, {"price":"0.44", "size":"261.99"}, {"price":"0.43", "size":"141"}, {"price":"0.42", "size":"131.82"}, {"price":"0.41", "size":"150.04"}], "hash":"5a473be7f8205c39df288e10a02722228ccc980d", "timestamp":"1784449238585", "event_type":"book"}
{"market":"0xab772601f501b265bfe8982eb61d5347ef9945de314bfdf4ac0189c288ffb0b3", "asset_id":"17924629579804316786455515989238352689210911545477836576430679697715946894553", "bids":[{"price":"0.01", "size":"13074.5"}, {"price":"0.02", "size":"3885.25"}, {"price":"0.03", "size":"2250.95"}, {"price":"0.04", "size":"1270.1"}, {"price":"0.05", "size":"1768.6"}, {"price":"0.06", "size":"1124.35"}, {"price":"0.07", "size":"959.2"}, {"price":"0.08", "size":"1225.88"}, {"price":"0.09", "size":"796.7"}, {"price":"0.1", "size":"365.2"}, {"price":"0.11", "size":"1502.1"}, {"price":"0.12", "size":"195.05"}, {"price":"0.13", "size":"147.4"}, {"price":"0.14", "size":"183.4"}, {"price":"0.15", "size":"469.43"}, {"price":"0.16", "size":"127.1"}, {"price":"0.17", "size":"107.69"}, {"price":"0.18", "size":"125.7"}, {"price":"0.19", "size":"98.89"}, {"price":"0.2", "size":"206.2"}, {"price":"0.21", "size":"616.8"}, {"price":"0.22", "size":"992.5"}, {"price":"0.23", "size":"82.3"}, {"price":"0.24", "size":"118.03"}, {"price":"0.25", "size":"92.2"}, {"price":"0.26", "size":"90.3"}, {"price":"0.27", "size":"70.3"}, {"price":"0.28", "size":"79.87"}, {"price":"0.29", "size":"74.39"}, {"price":"0.3", "size":"83"}, {"price":"0.31", "size":"89.7"}, {"price":"0.32", "size":"160.64"}, {"price":"0.33", "size":"113.1"}, {"price":"0.34", "size":"67.8"}, {"price":"0.35", "size":"84.6"}, {"price":"0.36", "size":"79.39"}, {"price":"0.37", "size":"94.2"}, {"price":"0.38", "size":"85"}, {"price":"0.39", "size":"69.8"}, {"price":"0.4", "size":"97.94"}, {"price":"0.41", "size":"75.5"}, {"price":"0.42", "size":"86.02"}, {"price":"0.43", "size":"75.3"}, {"price":"0.44", "size":"64.2"}, {"price":"0.45", "size":"204.71"}, {"price":"0.46", "size":"102.1"}, {"price":"0.47", "size":"72.1"}, {"price":"0.48", "size":"71"}, {"price":"0.49", "size":"71"}, {"price":"0.5", "size":"129.39"}, {"price":"0.51", "size":"415.92"}, {"price":"0.52", "size":"230.91"}, {"price":"0.53", "size":"485.7"}, {"price":"0.54", "size":"135.85"}, {"price":"0.55", "size":"213.69"}, {"price":"0.56", "size":"261.99"}, {"price":"0.57", "size":"141"}, {"price":"0.58", "size":"131.82"}, {"price":"0.59", "size":"150.04"}], "asks":[{"price":"0.99", "size":"14899.14"}, {"price":"0.98", "size":"3964.52"}, {"price":"0.97", "size":"2179.29"}, {"price":"0.96", "size":"1215.1"}, {"price":"0.95", "size":"1752.19"}, {"price":"0.94", "size":"1122.02"}, {"price":"0.93", "size":"953.49"}, {"price":"0.92", "size":"1234.38"}, {"price":"0.91", "size":"791.7"}, {"price":"0.9", "size":"561.2"}, {"price":"0.89", "size":"1502.1"}, {"price":"0.88", "size":"1112.05"}, {"price":"0.87", "size":"124.4"}, {"price":"0.86", "size":"166.8"}, {"price":"0.85", "size":"444.04"}, {"price":"0.84", "size":"147.1"}, {"price":"0.83", "size":"207.17"}, {"price":"0.82", "size":"150.7"}, {"price":"0.81", "size":"103.89"}, {"price":"0.8", "size":"246.2"}, {"price":"0.79", "size":"636.8"}, {"price":"0.78", "size":"115.5"}, {"price":"0.77", "size":"155.8"}, {"price":"0.76", "size":"162.22"}, {"price":"0.75", "size":"137.2"}, {"price":"0.74", "size":"134.3"}, {"price":"0.73", "size":"148.5"}, {"price":"0.72", "size":"146.77"}, {"price":"0.71", "size":"216.99"}, {"price":"0.7", "size":"207.81"}, {"price":"0.69", "size":"544.58"}, {"price":"0.68", "size":"236.69"}, {"price":"0.67", "size":"134.65"}, {"price":"0.66", "size":"100.76"}, {"price":"0.65", "size":"133.8"}, {"price":"0.64", "size":"206.77"}, {"price":"0.63", "size":"165.97"}, {"price":"0.62", "size":"389.01"}, {"price":"0.61", "size":"221.65"}, {"price":"0.6", "size":"150.69"}], "hash":"a7968b4e43d23d7ae7ca5c3b53618ce656299e50", "timestamp":"1784449238585", "event_type":"book"}
{"market":"0xab772601f501b265bfe8982eb61d5347ef9945de314bfdf4ac0189c288ffb0b3", "price_changes":[{"asset_id":"17924629579804316786455515989238352689210911545477836576430679697715946894553", "price":"0.31", "size":"64.7", "side":"BUY", "hash":"b4a2baff4f8a500f632a9e374a18c0e01ebdb614", "best_bid":"0.59", "best_ask":"0.6"}, {"asset_id":"12935926064588426924078449947177910958215776269411501731627440228801766632772", "price":"0.69", "size":"64.7", "side":"SELL", "hash":"3c310146bc19e97202dab2f7570220901346e5c8", "best_bid":"0.4", "best_ask":"0.41"}], "timestamp":"1784449238588", "event_type":"price_change"}
{"market":"0xab772601f501b265bfe8982eb61d5347ef9945de314bfdf4ac0189c288ffb0b3", "price_changes":[{"asset_id":"17924629579804316786455515989238352689210911545477836576430679697715946894553", "price":"0.05", "size":"1753.6", "side":"BUY", "hash":"9418bc4312df4d7958a27069829d09e1f32bc11e", "best_bid":"0.59", "best_ask":"0.6"}, {"asset_id":"12935926064588426924078449947177910958215776269411501731627440228801766632772", "price":"0.95", "size":"1753.6", "side":"SELL", "hash":"b0b01b945113fc91dbc7b548636b7c10b0f44d5b", "best_bid":"0.4", "best_ask":"0.41"}], "timestamp":"1784449238588", "event_type":"price_change"}
{"market":"0xab772601f501b265bfe8982eb61d5347ef9945de314bfdf4ac0189c288ffb0b3", "price_changes":[{"asset_id":"12935926064588426924078449947177910958215776269411501731627440228801766632772", "price":"0.39", "size":"262.53", "side":"BUY", "hash":"ee24464553d59e7e8a0ac1f7116c440cc49a1607", "best_bid":"0.4", "best_ask":"0.41"}, {"asset_id":"17924629579804316786455515989238352689210911545477836576430679697715946894553", "price":"0.61", "size":"262.53", "side":"SELL", "hash":"970441f02b9ffb7e276373ab53eb827d53d86b0b", "best_bid":"0.59", "best_ask":"0.6"}], "timestamp":"1784449238588", "event_type":"price_change"}
{"market":"0xab772601f501b265bfe8982eb61d5347ef9945de314bfdf4ac0189c288ffb0b3", "price_changes":[{"asset_id":"12935926064588426924078449947177910958215776269411501731627440228801766632772", "price":"0.37", "size":"140.97", "side":"BUY", "hash":"9ee1adddf03e57ae90ab2c1419290d143a5e6f14", "best_bid":"0.4", "best_ask":"0.41"}, {"asset_id":"17924629579804316786455515989238352689210911545477836576430679697715946894553", "price":"0.63", "size":"140.97", "side":"SELL", "hash":"2c4da49c9ec19d81d266c9bc20bceae79cda49d7", "best_bid":"0.59", "best_ask":"0.6"}], "timestamp":"1784449238589", "event_type":"price_change"}
{"market":"0xab772601f501b265bfe8982eb61d5347ef9945de314bfdf4ac0189c288ffb0b3", "price_changes":[{"asset_id":"12935926064588426924078449947177910958215776269411501731627440228801766632772", "price":"0.38", "size":"380.99", "side":"BUY", "hash":"94924694cc5ef86894db054f35cccded8e61675b", "best_bid":"0.4", "best_ask":"0.41"}, {"asset_id":"17924629579804316786455515989238352689210911545477836576430679697715946894553", "price":"0.62", "size":"380.99", "side":"SELL", "hash":"96792b95e23105910e48a171583901dbdaf9a204", "best_bid":"0.59", "best_ask":"0.6"}], "timestamp":"1784449238589", "event_type":"price_change"}
{"market":"0xab772601f501b265bfe8982eb61d5347ef9945de314bfdf4ac0189c288ffb0b3", "price_changes":[{"asset_id":"17924629579804316786455515989238352689210911545477836576430679697715946894553", "price":"0.55", "size":"221.69", "side":"BUY", "hash":"260343c6beb03855f4e2414dbc65d25f191635dc", "best_bid":"0.59", "best_ask":"0.6"}, {"asset_id":"12935926064588426924078449947177910958215776269411501731627440228801766632772", "price":"0.45", "size":"221.69", "side":"SELL", "hash":"f717ae9d0a6d1f77965f34ce1049b081a84731b7", "best_bid":"0.4", "best_ask":"0.41"}], "timestamp":"1784449238590", "event_type":"price_change"}
{"market":"0xab772601f501b265bfe8982eb61d5347ef9945de314bfdf4ac0189c288ffb0b3", "price_changes":[{"asset_id":"17924629579804316786455515989238352689210911545477836576430679697715946894553", "price":"0.54", "size":"160.85", "side":"BUY", "hash":"85b5c6cbac91668220863487de6484d2a483f503", "best_bid":"0.59", "best_ask":"0.6"}, {"asset_id":"12935926064588426924078449947177910958215776269411501731627440228801766632772", "price":"0.46", "size":"160.85", "side":"SELL", "hash":"b49897034d93a722aedc99d863f7ccfe3ee0a060", "best_bid":"0.4", "best_ask":"0.41"}], "timestamp":"1784449238590", "event_type":"price_change"}
{"market":"0xab772601f501b265bfe8982eb61d5347ef9945de314bfdf4ac0189c288ffb0b3", "price_changes":[{"asset_id":"17924629579804316786455515989238352689210911545477836576430679697715946894553", "price":"0.41", "size":"100.5", "side":"BUY", "hash":"8863ccda26736406a272a940660204c3aaabcccf", "best_bid":"0.59", "best_ask":"0.6"}, {"asset_id":"12935926064588426924078449947177910958215776269411501731627440228801766632772", "price":"0.59", "size":"100.5", "side":"SELL", "hash":"9659df7969066ddb4964a88fbd380cd9058c5e14", "best_bid":"0.4", "best_ask":"0.41"}], "timestamp":"1784449238591", "event_type":"price_change"}
{"market":"0xab772601f501b265bfe8982eb61d5347ef9945de314bfdf4ac0189c288ffb0b3", "price_changes":[{"asset_id":"12935926064588426924078449947177910958215776269411501731627440228801766632772", "price":"0.25", "size":"127.2", "side":"BUY", "hash":"37768e295488f82e2c9d171e4a7e34242a4ac670", "best_bid":"0.4", "best_ask":"0.41"}, {"asset_id":"17924629579804316786455515989238352689210911545477836576430679697715946894553", "price":"0.75", "size":"127.2", "side":"SELL", "hash":"05968302d2a42d70ac5fe905e46e861a47afd24c", "best_bid":"0.59", "best_ask":"0.6"}], "timestamp":"1784449238591", "event_type":"price_change"}
{"market":"0xab772601f501b265bfe8982eb61d5347ef9945de314bfdf4ac0189c288ffb0b3", "price_changes":[{"asset_id":"12935926064588426924078449947177910958215776269411501731627440228801766632772", "price":"0.39", "size":"249.2", "side":"BUY", "hash":"e20b2df4a509dabd9405e8e6919554ce9ebca1cb", "best_bid":"0.4", "best_ask":"0.41"}, {"asset_id":"17924629579804316786455515989238352689210911545477836576430679697715946894553", "price":"0.61", "size":"249.2", "side":"SELL", "hash":"39b14a11f10e6805f2b7ca3de9bdbe9d16e175db", "best_bid":"0.59", "best_ask":"0.6"}], "timestamp":"1784449238591", "event_type":"price_change"}
{"market":"0xab772601f501b265bfe8982eb61d5347ef9945de314bfdf4ac0189c288ffb0b3", "price_changes":[{"asset_id":"12935926064588426924078449947177910958215776269411501731627440228801766632772", "price":"0.39", "size":"149.2", "side":"BUY", "hash":"4296d1fd67b55bd512616ae576ce30ee41bb82f0", "best_bid":"0.4", "best_ask":"0.41"}, {"asset_id":"17924629579804316786455515989238352689210911545477836576430679697715946894553", "price":"0.61", "size":"149.2", "side":"SELL", "hash":"dd827bb593ffaaa33518606f5fc9332891f67797", "best_bid":"0.59", "best_ask":"0.6"}], "timestamp":"1784449238591", "event_type":"price_change"}
{"market":"0xab772601f501b265bfe8982eb61d5347ef9945de314bfdf4ac0189c288ffb0b3", "price_changes":[{"asset_id":"17924629579804316786455515989238352689210911545477836576430679697715946894553", "price":"0.06", "size":"1109.35", "side":"BUY", "hash":"cafab42cdbdf328827ebd8c1ccd3f667c36584b3", "best_bid":"0.59", "best_ask":"0.6"}, {"asset_id":"12935926064588426924078449947177910958215776269411501731627440228801766632772", "price":"0.94", "size":"1109.35", "side":"SELL", "hash":"9814a329685efd3a4a465b31bf2608c2fb8a62d7", "best_bid":"0.4", "best_ask":"0.41"}], "timestamp":"1784449238592", "event_type":"price_change"}
{"market":"0xab772601f501b265bfe8982eb61d5347ef9945de314bfdf4ac0189c288ffb0b3", "price_changes":[{"asset_id":"12935926064588426924078449947177910958215776269411501731627440228801766632772", "price":"0.4", "size":"250.69", "side":"BUY", "hash":"cd5d3341f64fa025615aa84094d4b50f3b949fa7", "best_bid":"0.4", "best_ask":"0.41"}, {"asset_id":"17924629579804316786455515989238352689210911545477836576430679697715946894553", "price":"0.6", "size":"250.69", "side":"SELL", "hash":"fd8c3805f2e67da3994ebd5dcd1e9876b0e485cc", "best_bid":"0.59", "best_ask":"0.6"}], "timestamp":"1784449238592", "event_type":"price_change"}
{"market":"0xab772601f501b265bfe8982eb61d5347ef9945de314bfdf4ac0189c288ffb0b3", "price_changes":[{"asset_id":"17924629579804316786455515989238352689210911545477836576430679697715946894553", "price":"0.57", "size":"135", "side":"BUY", "hash":"650d9f3fc8113de4b7762a601389df01d6338077", "best_bid":"0.59", "best_ask":"0.6"}, {"asset_id":"12935926064588426924078449947177910958215776269411501731627440228801766632772", "price":"0.43", "size":"135", "side":"SELL", "hash":"ae2c03c4b5f18799beef29d76451d4e7eb5a934e", "best_bid":"0.4", "best_ask":"0.41"}], "timestamp":"1784449238592", "event_type":"price_change"}
{"market":"0xab772601f501b265bfe8982eb61d5347ef9945de314bfdf4ac0189c288ffb0b3", "price_changes":[{"asset_id":"12935926064588426924078449947177910958215776269411501731627440228801766632772", "price":"0.38", "size":"370.99", "side":"BUY", "hash":"c6a38be57ed1bdae47611834d24614daee305763", "best_bid":"0.4", "best_ask":"0.41"}, {"asset_id":"17924629579804316786455515989238352689210911545477836576430679697715946894553", "price":"0.62", "size":"370.99", "side":"SELL", "hash":"fa86367243e099d2c91615bd69909bed3240f6a5", "best_bid":"0.59", "best_ask":"0.6"}], "timestamp":"1784449238593", "event_type":"price_change"}
{"market":"0xab772601f501b265bfe8982eb61d5347ef9945de314bfdf4ac0189c288ffb0b3", "price_changes":[{"asset_id":"12935926064588426924078449947177910958215776269411501731627440228801766632772", "price":"0.4", "size":"291.57", "side":"BUY", "hash":"d1dedb52bcfaf89ea1e6bdac4d54c0dfb203a16c", "best_bid":"0.4", "best_ask":"0.41"}, {"asset_id":"17924629579804316786455515989238352689210911545477836576430679697715946894553", "price":"0.6", "size":"291.57", "side":"SELL", "hash":"a974dd972caeb29f06826b68b511a174e002872b", "best_bid":"0.59", "best_ask":"0.6"}], "timestamp":"1784449238593", "event_type":"price_change"}
{"market":"0xab772601f501b265bfe8982eb61d5347ef9945de314bfdf4ac0189c288ffb0b3", "price_changes":[{"asset_id":"12935926064588426924078449947177910958215776269411501731627440228801766632772", "price":"0.39", "size":"132.54", "side":"BUY", "hash":"c7b9217029ad518f1a3d968ef68e47a4da8d736d", "best_bid":"0.4", "best_ask":"0.41"}, {"asset_id":"17924629579804316786455515989238352689210911545477836576430679697715946894553", "price":"0.61", "size":"132.54", "side":"SELL", "hash":"88a8dea2df7a83ce4d44ed597372864dd171fd73", "best_bid":"0.59", "best_ask":"0.6"}], "timestamp":"1784449238595", "event_type":"price_change"}
{"market":"0xab772601f501b265bfe8982eb61d5347ef9945de314bfdf4ac0189c288ffb0b3", "price_changes":[{"asset_id":"12935926064588426924078449947177910958215776269411501731627440228801766632772", "price":"0.39", "size":"115.88", "side":"BUY", "hash":"77df1671ffee3399775419b6c3676975054c6b6f", "best_bid":"0.4", "best_ask":"0.41"}, {"asset_id":"17924629579804316786455515989238352689210911545477836576430679697715946894553", "price":"0.61", "size":"115.88", "side":"SELL", "hash":"cc4a7805db9dba96f3bd5d3fabcd447ebe613e8e", "best_bid":"0.59", "best_ask":"0.6"}], "timestamp":"1784449238595", "event_type":"price_change"}
{"market":"0xab772601f501b265bfe8982eb61d5347ef9945de314bfdf4ac0189c288ffb0b3", "price_changes":[{"asset_id":"12935926064588426924078449947177910958215776269411501731627440228801766632772", "price":"0.33", "size":"159.65", "side":"BUY", "hash":"83b9be51da8d207d294af7de33df3c7d3b93de71", "best_bid":"0.4", "best_ask":"0.41"}, {"asset_id":"17924629579804316786455515989238352689210911545477836576430679697715946894553", "price":"0.67", "size":"159.65", "side":"SELL", "hash":"aa32f4a01515edb43133418aeceb8c6e2b2971a0", "best_bid":"0.59", "best_ask":"0.6"}], "timestamp":"1784449238595", "event_type":"price_change"}
{"market":"0xab772601f501b265bfe8982eb61d5347ef9945de314bfdf4ac0189c288ffb0b3", "price_changes":[{"asset_id":"12935926064588426924078449947177910958215776269411501731627440228801766632772", "price":"0.38", "size":"363.28", "side":"BUY", "hash":"7c930a300b2322956113f669c9b2aaca95260763", "best_bid":"0.4", "best_ask":"0.41"}, {"asset_id":"17924629579804316786455515989238352689210911545477836576430679697715946894553", "price":"0.62", "size":"363.28", "side":"SELL", "hash":"937c3e4e8958dd3c4739a7e55dc37125ecef511a", "best_bid":"0.59", "best_ask":"0.6"}], "timestamp":"1784449238596", "event_type":"price_change"}
{"market":"0xab772601f501b265bfe8982eb61d5347ef9945de314bfdf4ac0189c288ffb0b3", "price_changes":[{"asset_id":"17924629579804316786455515989238352689210911545477836576430679697715946894553", "price":"0.41", "size":"75.5", "side":"BUY", "hash":"36b6b2ec67845600153003a590c9440688dafbc7", "best_bid":"0.59", "best_ask":"0.6"}, {"asset_id":"12935926064588426924078449947177910958215776269411501731627440228801766632772", "price":"0.59", "size":"75.5", "side":"SELL", "hash":"241313a1ae8950100dc38d3d5862bb86f4817d01", "best_bid":"0.4", "best_ask":"0.41"}], "timestamp":"1784449238596", "event_type":"price_change"}
{"market":"0xab772601f501b265bfe8982eb61d5347ef9945de314bfdf4ac0189c288ffb0b3", "price_changes":[{"asset_id":"12935926064588426924078449947177910958215776269411501731627440228801766632772", "price":"0.4", "size":"191.57", "side":"BUY", "hash":"7dc8f8c16b0a80a502ab345c4e3a0c093ce8e1be", "best_bid":"0.4", "best_ask":"0.41"}, {"asset_id":"17924629579804316786455515989238352689210911545477836576430679697715946894553", "price":"0.6", "size":"191.57", "side":"SELL", "hash":"1980642e05b94ce5eeb3df29e72ef299cfbd2ed8", "best_bid":"0.59", "best_ask":"0.6"}], "timestamp":"1784449238596", "event_type":"price_change"}
{"market":"0xab772601f501b265bfe8982eb61d5347ef9945de314bfdf4ac0189c288ffb0b3", "price_changes":[{"asset_id":"17924629579804316786455515989238352689210911545477836576430679697715946894553", "price":"0.57", "size":"160", "side":"BUY", "hash":"8e28beb77cf74c359b50be5d99c11c76e828598e", "best_bid":"0.59", "best_ask":"0.6"}, {"asset_id":"12935926064588426924078449947177910958215776269411501731627440228801766632772", "price":"0.43", "size":"160", "side":"SELL", "hash":"9e5ee57e93a901ad4605302fe757637fcb1029a3", "best_bid":"0.4", "best_ask":"0.41"}], "timestamp":"1784449238597", "event_type":"price_change"}
{"market":"0xab772601f501b265bfe8982eb61d5347ef9945de314bfdf4ac0189c288ffb0b3", "price_changes":[{"asset_id":"17924629579804316786455515989238352689210911545477836576430679697715946894553", "price":"0.07", "size":"944.2", "side":"BUY", "hash":"1d1c4c4f981043bbf1726a784c2f67e58e65fd31", "best_bid":"0.59", "best_ask":"0.6"}, {"asset_id":"12935926064588426924078449947177910958215776269411501731627440228801766632772", "price":"0.93", "size":"944.2", "side":"SELL", "hash":"ef29a3babe6bf36ba73c2f29bb832732b4bcce9e", "best_bid":"0.4", "best_ask":"0.41"}], "timestamp":"1784449238597", "event_type":"price_change"}
{"market":"0xab772601f501b265bfe8982eb61d5347ef9945de314bfdf4ac0189c288ffb0b3", "price_changes":[{"asset_id":"17924629579804316786455515989238352689210911545477836576430679697715946894553", "price":"0.01", "size":"12974.5", "side":"BUY", "hash":"bdfa94e61d0fcef9bfbc2a718f0c43f8aff97da5", "best_bid":"0.59", "best_ask":"0.6"}, {"asset_id":"12935926064588426924078449947177910958215776269411501731627440228801766632772", "price":"0.99", "size":"12974.5", "side":"SELL", "hash":"708f3a921a51e1ee75e81f531cbe6a3ea7b72a1b", "best_bid":"0.4", "best_ask":"0.41"}], "timestamp":"1784449238597", "event_type":"price_change"}
{"market":"0xab772601f501b265bfe8982eb61d5347ef9945de314bfdf4ac0189c288ffb0b3", "price_changes":[{"asset_id":"17924629579804316786455515989238352689210911545477836576430679697715946894553", "price":"0.49", "size":"96.92", "side":"BUY", "hash":"22c5f1d9696f32568fef4f26c23af00d7ccd790f", "best_bid":"0.59", "best_ask":"0.6"}, {"asset_id":"12935926064588426924078449947177910958215776269411501731627440228801766632772", "price":"0.51", "size":"96.92", "side":"SELL", "hash":"006f2c27c7632bd62aee2e97ab78353d22015ff9", "best_bid":"0.4", "best_ask":"0.41"}], "timestamp":"1784449238597", "event_type":"price_change"}
{"market":"0xab772601f501b265bfe8982eb61d5347ef9945de314bfdf4ac0189c288ffb0b3", "price_changes":[{"asset_id":"12935926064588426924078449947177910958215776269411501731627440228801766632772", "price":"0.26", "size":"159.3", "side":"BUY", "hash":"9743470605f27e4c2e965e210cf16f96f1d06597", "best_bid":"0.4", "best_ask":"0.41"}, {"asset_id":"17924629579804316786455515989238352689210911545477836576430679697715946894553", "price":"0.74", "size":"159.3", "side":"SELL", "hash":"fd1d12fba10376793073370821fcd4345709388c", "best_bid":"0.59", "best_ask":"0.6"}], "timestamp":"1784449238598", "event_type":"price_change"}
{"market":"0xab772601f501b265bfe8982eb61d5347ef9945de314bfdf4ac0189c288ffb0b3", "price_changes":[{"asset_id":"17924629579804316786455515989238352689210911545477836576430679697715946894553", "price":"0.58", "size":"126.82", "side":"BUY", "hash":"1d0ea0684343f647b17cbf873e7da3d9b0cee8f0", "best_bid":"0.59", "best_ask":"0.6"}, {"asset_id":"12935926064588426924078449947177910958215776269411501731627440228801766632772", "price":"0.42", "size":"126.82", "side":"SELL", "hash":"545bc1b33aaf11fb511def770aa4c13e8b5b4d92", "best_bid":"0.4", "best_ask":"0.41"}], "timestamp":"1784449238599", "event_type":"price_change"}
{"market":"0xab772601f501b265bfe8982eb61d5347ef9945de314bfdf4ac0189c288ffb0b3", "price_changes":[{"asset_id":"12935926064588426924078449947177910958215776269411501731627440228801766632772", "price":"0.24", "size":"152.22", "side":"BUY", "hash":"92dc354790b7a2a9efbd8988a5ff09d83e45bd04", "best_bid":"0.4", "best_ask":"0.41"}, {"asset_id":"17924629579804316786455515989238352689210911545477836576430679697715946894553", "price":"0.76", "size":"152.22", "side":"SELL", "hash":"3c2a6ee674cf010deebd1772a7fa35fd26858f70", "best_bid":"0.59", "best_ask":"0.6"}], "timestamp":"1784449238599", "event_type":"price_change"}
{"market":"0xab772601f501b265bfe8982eb61d5347ef9945de314bfdf4ac0189c288ffb0b3", "price_changes":[{"asset_id":"12935926064588426924078449947177910958215776269411501731627440228801766632772", "price":"0.22", "size":"140.5", "side":"BUY", "hash":"c7b65b3df0d8e7e771b56abe52e14672f43f7f4a", "best_bid":"0.4", "best_ask":"0.41"}, {"asset_id":"17924629579804316786455515989238352689210911545477836576430679697715946894553", "price":"0.78", "size":"140.5", "side":"SELL", "hash":"4a1453ee8a45d1dda1d2a2128b524217a4ea0379", "best_bid":"0.59", "best_ask":"0.6"}], "timestamp":"1784449238599", "event_type":"price_change"}
{"market":"0xab772601f501b265bfe8982eb61d5347ef9945de314bfdf4ac0189c288ffb0b3", "price_changes":[{"asset_id":"17924629579804316786455515989238352689210911545477836576430679697715946894553", "price":"0.56", "size":"266.99", "side":"BUY", "hash":"00730ffe9d3d5c96803695d246a1f6353e5d9576", "best_bid":"0.59", "best_ask":"0.6"}, {"asset_id":"12935926064588426924078449947177910958215776269411501731627440228801766632772", "price":"0.44", "size":"266.99", "side":"SELL", "hash":"6a8f9078a61a838f9e86d5edf2953c45f6af7b89", "best_bid":"0.4", "best_ask":"0.41"}], "timestamp":"1784449238600", "event_type":"price_change"}
{"market":"0xab772601f501b265bfe8982eb61d5347ef9945de314bfdf4ac0189c288ffb0b3", "price_changes":[{"asset_id":"12935926064588426924078449947177910958215776269411501731627440228801766632772", "price":"0.23", "size":"145.8", "side":"BUY", "hash":"ed914ba5494b5d678cf0c239d693ad1529744d88", "best_bid":"0.4", "best_ask":"0.41"}, {"asset_id":"17924629579804316786455515989238352689210911545477836576430679697715946894553", "price":"0.77", "size":"145.8", "side":"SELL", "hash":"eca7771f3956ba67d86aafc9c201294404868a1a", "best_bid":"0.59", "best_ask":"0.6"}], "timestamp":"1784449238600", "event_type":"price_change"}
{"market":"0xab772601f501b265bfe8982eb61d5347ef9945de314bfdf4ac0189c288ffb0b3", "price_changes":[{"asset_id":"12935926064588426924078449947177910958215776269411501731627440228801766632772", "price":"0.32", "size":"231.69", "side":"BUY", "hash":"bf46e7f7200ba8d10aaa7515fc34bd6e524fd0fa", "best_bid":"0.4", "best_ask":"0.41"}, {"asset_id":"17924629579804316786455515989238352689210911545477836576430679697715946894553", "price":"0.68", "size":"231.69", "side":"SELL", "hash":"10a40389362d35413635c6401049e82e0e1ba45e", "best_bid":"0.59", "best_ask":"0.6"}], "timestamp":"1784449238600", "event_type":"price_change"}
{"market":"0xab772601f501b265bfe8982eb61d5347ef9945de314bfdf4ac0189c288ffb0b3", "price_changes":[{"asset_id":"17924629579804316786455515989238352689210911545477836576430679697715946894553", "price":"0.54", "size":"135.85", "side":"BUY", "hash":"b8f76dbc678b136bb385edc7689f5153027b0018", "best_bid":"0.59", "best_ask":"0.6"}, {"asset_id":"12935926064588426924078449947177910958215776269411501731627440228801766632772", "price":"0.46", "size":"135.85", "side":"SELL", "hash":"a521f9f1f6524f991152d9496f89e10e17dfecd7", "best_bid":"0.4", "best_ask":"0.41"}], "timestamp":"1784449238600", "event_type":"price_change"}
{"market":"0xab772601f501b265bfe8982eb61d5347ef9945de314bfdf4ac0189c288ffb0b3", "price_changes":[{"asset_id":"17924629579804316786455515989238352689210911545477836576430679697715946894553", "price":"0.32", "size":"175.64", "side":"BUY", "hash":"7434ce2429eead256bd94409f1d2f3be7070e6ef", "best_bid":"0.59", "best_ask":"0.6"}, {"asset_id":"12935926064588426924078449947177910958215776269411501731627440228801766632772", "price":"0.68", "size":"175.64", "side":"SELL", "hash":"3a6779af75030ab10994484999961d2d03aae6e1", "best_bid":"0.4", "best_ask":"0.41"}], "timestamp":"1784449238601", "event_type":"price_change"}
{"market":"0xab772601f501b265bfe8982eb61d5347ef9945de314bfdf4ac0189c288ffb0b3", "price_changes":[{"asset_id":"12935926064588426924078449947177910958215776269411501731627440228801766632772", "price":"0.34", "size":"105.77", "side":"BUY", "hash":"5b7998fc437b02d856c59aeef7a2f79855eb2a9e", "best_bid":"0.4", "best_ask":"0.41"}, {"asset_id":"17924629579804316786455515989238352689210911545477836576430679697715946894553", "price":"0.66", "size":"105.77", "side":"SELL", "hash":"89994e4c4d98cf260e114d613224a1c32ac863db", "best_bid":"0.59", "best_ask":"0.6"}], "timestamp":"1784449238601", "event_type":"price_change"}
{"market":"0xab772601f501b265bfe8982eb61d5347ef9945de314bfdf4ac0189c288ffb0b3", "price_changes":[{"asset_id":"12935926064588426924078449947177910958215776269411501731627440228801766632772", "price":"0.01", "size":"14894.14", "side":"BUY", "hash":"5bda05ba099fec71f9dd82928489feca2aeba144", "best_bid":"0.4", "best_ask":"0.41"}, {"asset_id":"17924629579804316786455515989238352689210911545477836576430679697715946894553", "price":"0.99", "size":"14894.14", "side":"SELL", "hash":"dc4ffc9941436afabfaa52f5afbd47cdacc205be", "best_bid":"0.59", "best_ask":"0.6"}], "timestamp":"1784449238602", "event_type":"price_change"}
{"market":"0xab772601f501b265bfe8982eb61d5347ef9945de314bfdf4ac0189c288ffb0b3", "price_changes":[{"asset_id":"12935926064588426924078449947177910958215776269411501731627440228801766632772", "price":"0.33", "size":"134.65", "side":"BUY", "hash":"807bdfed297e63e69a5fecc0d8f6ba76c35691cd", "best_bid":"0.4", "best_ask":"0.41"}, {"asset_id":"17924629579804316786455515989238352689210911545477836576430679697715946894553", "price":"0.67", "size":"134.65", "side":"SELL", "hash":"bdb5fbcf958725cca40ae280ec2160438f8dded1", "best_bid":"0.59", "best_ask":"0.6"}], "timestamp":"1784449238602", "event_type":"price_change"}
{"market":"0xab772601f501b265bfe8982eb61d5347ef9945de314bfdf4ac0189c288ffb0b3", "price_changes":[{"asset_id":"17924629579804316786455515989238352689210911545477836576430679697715946894553", "price":"0.57", "size":"135", "side":"BUY", "hash":"fd02c0b0ca02cf86bcd766f2bcc587e70e96748e", "best_bid":"0.59", "best_ask":"0.6"}, {"asset_id":"12935926064588426924078449947177910958215776269411501731627440228801766632772", "price":"0.43", "size":"135", "side":"SELL", "hash":"11de610b25ff70376fb30b9ee10565129256a4f3", "best_bid":"0.4", "best_ask":"0.41"}], "timestamp":"1784449238602", "event_type":"price_change"}
{"market":"0xab772601f501b265bfe8982eb61d5347ef9945de314bfdf4ac0189c288ffb0b3", "price_changes":[{"asset_id":"17924629579804316786455515989238352689210911545477836576430679697715946894553", "price":"0.5", "size":"139.39", "side":"BUY", "hash":"548a25cab9a213600a0ef30d908de22712f9411d", "best_bid":"0.59", "best_ask":"0.6"}, {"asset_id":"12935926064588426924078449947177910958215776269411501731627440228801766632772", "price":"0.5", "size":"139.39", "side":"SELL", "hash":"b522587dd747b0853cc28fb32af9e22cb92ec656", "best_bid":"0.4", "best_ask":"0.41"}], "timestamp":"1784449238602", "event_type":"price_change"}
{"market":"0xab772601f501b265bfe8982eb61d5347ef9945de314bfdf4ac0189c288ffb0b3", "price_changes":[{"asset_id":"12935926064588426924078449947177910958215776269411501731627440228801766632772", "price":"0.4", "size":"178.24", "side":"BUY", "hash":"3f4a80a15524c94813ff3c2f04772e3be5f6bb96", "best_bid":"0.4", "best_ask":"0.41"}, {"asset_id":"17924629579804316786455515989238352689210911545477836576430679697715946894553", "price":"0.6", "size":"178.24", "side":"SELL", "hash":"d7a0ac4849fc1f3684a0065aa2f857a9d5c21898", "best_bid":"0.59", "best_ask":"0.6"}], "timestamp":"1784449238603", "event_type":"price_change"}
{"market":"0xab772601f501b265bfe8982eb61d5347ef9945de314bfdf4ac0189c288ffb0b3", "price_changes":[{"asset_id":"17924629579804316786455515989238352689210911545477836576430679697715946894553", "price":"0.58", "size":"121.82", "side":"BUY", "hash":"03c1af2ccfe5de0e0f99646a8851f30285aeefb0", "best_bid":"0.59", "best_ask":"0.6"}, {"asset_id":"12935926064588426924078449947177910958215776269411501731627440228801766632772", "price":"0.42", "size":"121.82", "side":"SELL", "hash":"c85b5932bb9d491af154ea4aefa851fd7643d2d9", "best_bid":"0.4", "best_ask":"0.41"}], "timestamp":"1784449238603", "event_type":"price_change"}
{"market":"0xab772601f501b265bfe8982eb61d5347ef9945de314bfdf4ac0189c288ffb0b3", "price_changes":[{"asset_id":"12935926064588426924078449947177910958215776269411501731627440228801766632772", "price":"0.4", "size":"203.24", "side":"BUY", "hash":"e0536e0fd7fd7d09a6af2c9ce761c2e0509a60c6", "best_bid":"0.4", "best_ask":"0.41"}, {"asset_id":"17924629579804316786455515989238352689210911545477836576430679697715946894553", "price":"0.6", "size":"203.24", "side":"SELL", "hash":"16153405d2c3c71def7935b181cf99860e97e97d", "best_bid":"0.59", "best_ask":"0.6"}], "timestamp":"1784449238603", "event_type":"price_change"}
{"market":"0xab772601f501b265bfe8982eb61d5347ef9945de314bfdf4ac0189c288ffb0b3", "price_changes":[{"asset_id":"17924629579804316786455515989238352689210911545477836576430679697715946894553", "price":"0.56", "size":"272.99", "side":"BUY", "hash":"4d071006c60a8db14e525215541be087a7fed380", "best_bid":"0.59", "best_ask":"0.6"}, {"asset_id":"12935926064588426924078449947177910958215776269411501731627440228801766632772", "price":"0.44", "size":"272.99", "side":"SELL", "hash":"331fe53ddb5f6c35b2cc108fda7cf4cfe81f806c", "best_bid":"0.4", "best_ask":"0.41"}], "timestamp":"1784449238604", "event_type":"price_change"}
{"market":"0xab772601f501b265bfe8982eb61d5347ef9945de314bfdf4ac0189c288ffb0b3", "price_changes":[{"asset_id":"12935926064588426924078449947177910958215776269411501731627440228801766632772", "price":"0.37", "size":"135.91", "side":"BUY", "hash":"2b475ff0c528d2abf3a4b167de603331971ef6db", "best_bid":"0.4", "best_ask":"0.41"}, {"asset_id":"17924629579804316786455515989238352689210911545477836576430679697715946894553", "price":"0.63", "size":"135.91", "side":"SELL", "hash":"40cb3596c88c1ebdc3d24f71fc512149479324fd", "best_bid":"0.59", "best_ask":"0.6"}], "timestamp":"1784449238604", "event_type":"price_change"}
{"market":"0xab772601f501b265bfe8982eb61d5347ef9945de314bfdf4ac0189c288ffb0b3", "price_changes":[{"asset_id":"17924629579804316786455515989238352689210911545477836576430679697715946894553", "price":"0.38", "size":"60", "side":"BUY", "hash":"8c14c0d311ef690cd79a4857630a4d68d9c85c09", "best_bid":"0.59", "best_ask":"0.6"}, {"asset_id":"12935926064588426924078449947177910958215776269411501731627440228801766632772", "price":"0.62", "size":"60", "side":"SELL", "hash":"625d81cc7ddc463200abdea0a2cc4cb3e9529fa5", "best_bid":"0.4", "best_ask":"0.41"}], "timestamp":"1784449238604", "event_type":"price_change"}
{"market":"0xab772601f501b265bfe8982eb61d5347ef9945de314bfdf4ac0189c288ffb0b3", "price_changes":[{"asset_id":"17924629579804316786455515989238352689210911545477836576430679697715946894553", "price":"0.59", "size":"140.04", "side":"BUY", "hash":"2abf7d381902ed3366e16af68985129e4eff8548", "best_bid":"0.59", "best_ask":"0.6"}, {"asset_id":"12935926064588426924078449947177910958215776269411501731627440228801766632772", "price":"0.41", "size":"140.04", "side":"SELL", "hash":"711fd8cc76de1051bd0015ddefe8adc708adc372", "best_bid":"0.4", "best_ask":"0.41"}], "timestamp":"1784449238604", "event_type":"price_change"}
{"market":"0xab772601f501b265bfe8982eb61d5347ef9945de314bfdf4ac0189c288ffb0b3", "price_changes":[{"asset_id":"12935926064588426924078449947177910958215776269411501731627440228801766632772", "price":"0.4", "size":"103.24", "side":"BUY", "hash":"958b2a657ca0978966e315b3e2799b0bc5107b9e", "best_bid":"0.4", "best_ask":"0.41"}, {"asset_id":"17924629579804316786455515989238352689210911545477836576430679697715946894553", "price":"0.6", "size":"103.24", "side":"SELL", "hash":"ecdebbf2f9fb520847ac6bfd74f30c396d650f03", "best_bid":"0.59", "best_ask":"0.6"}], "timestamp":"1784449238605", "event_type":"price_change"}
{"market":"0xab772601f501b265bfe8982eb61d5347ef9945de314bfdf4ac0189c288ffb0b3", "price_changes":[{"asset_id":"12935926064588426924078449947177910958215776269411501731627440228801766632772", "price":"0.33", "size":"144.65", "side":"BUY", "hash":"99e0b7c9dbea62536ef2f66965d28a631cab25c2", "best_bid":"0.4", "best_ask":"0.41"}, {"asset_id":"17924629579804316786455515989238352689210911545477836576430679697715946894553", "price":"0.67", "size":"144.65", "side":"SELL", "hash":"8a82885e4183bbf4dd2c4270ca31df801fbfcb84", "best_bid":"0.59", "best_ask":"0.6"}], "timestamp":"1784449238605", "event_type":"price_change"}
{"market":"0xab772601f501b265bfe8982eb61d5347ef9945de314bfdf4ac0189c288ffb0b3", "price_changes":[{"asset_id":"12935926064588426924078449947177910958215776269411501731627440228801766632772", "price":"0.22", "size":"115.5", "side":"BUY", "hash":"f8149a169a7d7b17caddeb0c2d6f178111c88183", "best_bid":"0.4", "best_ask":"0.41"}, {"asset_id":"17924629579804316786455515989238352689210911545477836576430679697715946894553", "price":"0.78", "size":"115.5", "side":"SELL", "hash":"3e2a0fd11dca55a3d3bf459f6b0b38d828e60170", "best_bid":"0.59", "best_ask":"0.6"}], "timestamp":"1784449238605", "event_type":"price_change"}
{"market":"0xab772601f501b265bfe8982eb61d5347ef9945de314bfdf4ac0189c288ffb0b3", "price_changes":[{"asset_id":"12935926064588426924078449947177910958215776269411501731627440228801766632772", "price":"0.38", "size":"346.23", "side":"BUY", "hash":"8c9e5fd12c5a311aef1bbaa42d9c8fedcf8e37db", "best_bid":"0.4", "best_ask":"0.41"}, {"asset_id":"17924629579804316786455515989238352689210911545477836576430679697715946894553", "price":"0.62", "size":"346.23", "side":"SELL", "hash":"3b800c2e1b8f736f03e6b9f2d8cf50a505fd2ffc", "best_bid":"0.59", "best_ask":"0.6"}], "timestamp":"1784449238606", "event_type":"price_change"}
{"market":"0xab772601f501b265bfe8982eb61d5347ef9945de314bfdf4ac0189c288ffb0b3", "price_changes":[{"asset_id":"12935926064588426924078449947177910958215776269411501731627440228801766632772", "price":"0.26", "size":"134.3", "side":"BUY", "hash":"55d4898e1435cc2062cc2423bee55eb948450f02", "best_bid":"0.4", "best_ask":"0.41"}, {"asset_id":"17924629579804316786455515989238352689210911545477836576430679697715946894553", "price":"0.74", "size":"134.3", "side":"SELL", "hash":"d718350c834e3255b1c6fe917f6ce421edfac167", "best_bid":"0.59", "best_ask":"0.6"}], "timestamp":"1784449238606", "event_type":"price_change"}
{"market":"0xab772601f501b265bfe8982eb61d5347ef9945de314bfdf4ac0189c288ffb0b3", "price_changes":[{"asset_id":"12935926064588426924078449947177910958215776269411501731627440228801766632772", "price":"0.4", "size":"108.24", "side":"BUY", "hash":"5f47f16ddf24144e9b3899cda02cb6e33a1b6daf", "best_bid":"0.4", "best_ask":"0.41"}, {"asset_id":"17924629579804316786455515989238352689210911545477836576430679697715946894553", "price":"0.6", "size":"108.24", "side":"SELL", "hash":"9c1075af5659d820c85c7ee474bf21d74d046ed1", "best_bid":"0.59", "best_ask":"0.6"}], "timestamp":"1784449238606", "event_type":"price_change"}
{"market":"0xab772601f501b265bfe8982eb61d5347ef9945de314bfdf4ac0189c288ffb0b3", "price_changes":[{"asset_id":"17924629579804316786455515989238352689210911545477836576430679697715946894553", "price":"0.51", "size":"425.92", "side":"BUY", "hash":"864a806d6f34f3389a83455c8c4c4571c8e383ff", "best_bid":"0.59", "best_ask":"0.6"}, {"asset_id":"12935926064588426924078449947177910958215776269411501731627440228801766632772", "price":"0.49", "size":"425.92", "side":"SELL", "hash":"75559c3f00bef8cad5a4851abbc62a05de8956b7", "best_bid":"0.4", "best_ask":"0.41"}], "timestamp":"1784449238607", "event_type":"price_change"}
{"market":"0xab772601f501b265bfe8982eb61d5347ef9945de314bfdf4ac0189c288ffb0b3", "price_changes":[{"asset_id":"17924629579804316786455515989238352689210911545477836576430679697715946894553", "price":"0.01", "size":"12980.5", "side":"BUY", "hash":"03e8e67243d8422755e332fc3d6f74a42da04a7e", "best_bid":"0.59", "best_ask":"0.6"}, {"asset_id":"12935926064588426924078449947177910958215776269411501731627440228801766632772", "price":"0.99", "size":"12980.5", "side":"SELL", "hash":"c7599d4eae1453e767088e849c92f2d047375f58", "best_bid":"0.4", "best_ask":"0.41"}], "timestamp":"1784449238608", "event_type":"price_change"}
{"market":"0xab772601f501b265bfe8982eb61d5347ef9945de314bfdf4ac0189c288ffb0b3", "price_changes":[{"asset_id":"12935926064588426924078449947177910958215776269411501731627440228801766632772", "price":"0.36", "size":"221.77", "side":"BUY", "hash":"989e22399ac6dea338490db79923a697e4626197", "best_bid":"0.4", "best_ask":"0.41"}, {"asset_id":"17924629579804316786455515989238352689210911545477836576430679697715946894553", "price":"0.64", "size":"221.77", "side":"SELL", "hash":"1796fda1a394622f6e6b252e681192baca383c6b", "best_bid":"0.59", "best_ask":"0.6"}], "timestamp":"1784449238611", "event_type":"price_change"}
{"market":"0xab772601f501b265bfe8982eb61d5347ef9945de314bfdf4ac0189c288ffb0b3", "price_changes":[{"asset_id":"12935926064588426924078449947177910958215776269411501731627440228801766632772", "price":"0.31", "size":"554.58", "side":"BUY", "hash":"168104db2263c318f8baa68aa7511ee323cd730f", "best_bid":"0.4", "best_ask":"0.41"}, {"asset_id":"17924629579804316786455515989238352689210911545477836576430679697715946894553", "price":"0.69", "size":"554.58", "side":"SELL", "hash":"d08606aab6370cb4a0df68e969ad9e7b282d2f06", "best_bid":"0.59", "best_ask":"0.6"}], "timestamp":"1784449238611", "event_type":"price_change"}
{"market":"0xab772601f501b265bfe8982eb61d5347ef9945de314bfdf4ac0189c288ffb0b3", "price_changes":[{"asset_id":"12935926064588426924078449947177910958215776269411501731627440228801766632772", "price":"0.39", "size":"110.88", "side":"BUY", "hash":"e18690b462a95d414f0e694f59a6a175eea30615", "best_bid":"0.4", "best_ask":"0.41"}, {"asset_id":"17924629579804316786455515989238352689210911545477836576430679697715946894553", "price":"0.61", "size":"110.88", "side":"SELL", "hash":"f88c92493c881f819b74865323990c5eb8967b2c", "best_bid":"0.59", "best_ask":"0.6"}], "timestamp":"1784449238612", "event_type":"price_change"}
{"market":"0xab772601f501b265bfe8982eb61d5347ef9945de314bfdf4ac0189c288ffb0b3", "price_changes":[{"asset_id":"12935926064588426924078449947177910958215776269411501731627440228801766632772", "price":"0.34", "size":"130.77", "side":"BUY", "hash":"318db63d54dc81e88eb29b13948c08df8737daed", "best_bid":"0.4", "best_ask":"0.41"}, {"asset_id":"17924629579804316786455515989238352689210911545477836576430679697715946894553", "price":"0.66", "size":"130.77", "side":"SELL", "hash":"e3554797aab5b1e4960da8d573afd5e9bf4b21ff", "best_bid":"0.59", "best_ask":"0.6"}], "timestamp":"1784449238612", "event_type":"price_change"}
{"market":"0xab772601f501b265bfe8982eb61d5347ef9945de314bfdf4ac0189c288ffb0b3", "price_changes":[{"asset_id":"12935926064588426924078449947177910958215776269411501731627440228801766632772", "price":"0.16", "size":"247.1", "side":"BUY", "hash":"55e74d143a9a93c6a40cd29893e254e6b1f4c8ca", "best_bid":"0.4", "best_ask":"0.41"}, {"asset_id":"17924629579804316786455515989238352689210911545477836576430679697715946894553", "price":"0.84", "size":"247.1", "side":"SELL", "hash":"973ca6965408cbd41867e89b7fba60e01344b7e7", "best_bid":"0.59", "best_ask":"0.6"}], "timestamp":"1784449238613", "event_type":"price_change"}
{"market":"0xab772601f501b265bfe8982eb61d5347ef9945de314bfdf4ac0189c288ffb0b3", "price_changes":[{"asset_id":"12935926064588426924078449947177910958215776269411501731627440228801766632772", "price":"0.39", "size":"115.88", "side":"BUY", "hash":"5f33552c03e6b1c73ae9e70726105154e7790e01", "best_bid":"0.4", "best_ask":"0.41"}, {"asset_id":"17924629579804316786455515989238352689210911545477836576430679697715946894553", "price":"0.61", "size":"115.88", "side":"SELL", "hash":"ec6e0d3416fea22197b4e8b24f4fb8f3343894a4", "best_bid":"0.59", "best_ask":"0.6"}], "timestamp":"1784449238613", "event_type":"price_change"}
{"market":"0xab772601f501b265bfe8982eb61d5347ef9945de314bfdf4ac0189c288ffb0b3", "price_changes":[{"asset_id":"12935926064588426924078449947177910958215776269411501731627440228801766632772", "price":"0.4", "size":"102.53", "side":"BUY", "hash":"9356f4ae976e0ef80317ace9252222027a480ba5", "best_bid":"0.4", "best_ask":"0.41"}, {"asset_id":"17924629579804316786455515989238352689210911545477836576430679697715946894553", "price":"0.6", "size":"102.53", "side":"SELL", "hash":"590477fa4305d4da15c7ed95e6e8ac3225f9894f", "best_bid":"0.59", "best_ask":"0.6"}], "timestamp":"1784449238614", "event_type":"price_change"}
{"market":"0xab772601f501b265bfe8982eb61d5347ef9945de314bfdf4ac0189c288ffb0b3", "price_changes":[{"asset_id":"12935926064588426924078449947177910958215776269411501731627440228801766632772", "price":"0.37", "size":"150.91", "side":"BUY", "hash":"94363af1d1d1144fa76c3b54b099915be6e4577b", "best_bid":"0.4", "best_ask":"0.41"}, {"asset_id":"17924629579804316786455515989238352689210911545477836576430679697715946894553", "price":"0.63", "size":"150.91", "side":"SELL", "hash":"05b24d503bdc02a8a6286423758bf3040cad3caa", "best_bid":"0.59", "best_ask":"0.6"}], "timestamp":"1784449238614", "event_type":"price_change"}
{"market":"0xab772601f501b265bfe8982eb61d5347ef9945de314bfdf4ac0189c288ffb0b3", "price_changes":[{"asset_id":"12935926064588426924078449947177910958215776269411501731627440228801766632772", "price":"0.32", "size":"241.69", "side":"BUY", "hash":"5438372009fa10bb18f57867e4599cb79413d918", "best_bid":"0.4", "best_ask":"0.41"}, {"asset_id":"17924629579804316786455515989238352689210911545477836576430679697715946894553", "price":"0.68", "size":"241.69", "side":"SELL", "hash":"119df9c1febb889ac71a03755e30d63cc4cd4562", "best_bid":"0.59", "best_ask":"0.6"}], "timestamp":"1784449238615", "event_type":"price_change"}
{"market":"0xab772601f501b265bfe8982eb61d5347ef9945de314bfdf4ac0189c288ffb0b3", "price_changes":[{"asset_id":"17924629579804316786455515989238352689210911545477836576430679697715946894553", "price":"0.31", "size":"89.7", "side":"BUY", "hash":"5ab4f958c7ed3047714b1bd4cb87893332804aa4", "best_bid":"0.59", "best_ask":"0.6"}, {"asset_id":"12935926064588426924078449947177910958215776269411501731627440228801766632772", "price":"0.69", "size":"89.7", "side":"SELL", "hash":"d642261646f7cdffef6c3ce16631014a716ef332", "best_bid":"0.4", "best_ask":"0.41"}], "timestamp":"1784449238615", "event_type":"price_change"}
{"market":"0xab772601f501b265bfe8982eb61d5347ef9945de314bfdf4ac0189c288ffb0b3", "price_changes":[{"asset_id":"17924629579804316786455515989238352689210911545477836576430679697715946894553", "price":"0.35", "size":"184.6", "side":"BUY", "hash":"e3eb3110b327ffbb47e14c78a49e48f005d9d1a9", "best_bid":"0.59", "best_ask":"0.6"}, {"asset_id":"12935926064588426924078449947177910958215776269411501731627440228801766632772", "price":"0.65", "size":"184.6", "side":"SELL", "hash":"9cb0d319ec76b49bc2be70f8e7450dce728a7e8d", "best_bid":"0.4", "best_ask":"0.41"}], "timestamp":"1784449238615", "event_type":"price_change"}
{"market":"0xab772601f501b265bfe8982eb61d5347ef9945de314bfdf4ac0189c288ffb0b3", "price_changes":[{"asset_id":"12935926064588426924078449947177910958215776269411501731627440228801766632772", "price":"0.01", "size":"14889.14", "side":"BUY", "hash":"3a3cf07278e76517e4c37ec4076a9eac4a39d489", "best_bid":"0.4", "best_ask":"0.41"}, {"asset_id":"17924629579804316786455515989238352689210911545477836576430679697715946894553", "price":"0.99", "size":"14889.14", "side":"SELL", "hash":"277ba43db889f3c49c8f84d01710a6f4f54f935a", "best_bid":"0.59", "best_ask":"0.6"}], "timestamp":"1784449238616", "event_type":"price_change"}
{"market":"0xab772601f501b265bfe8982eb61d5347ef9945de314bfdf4ac0189c288ffb0b3", "price_changes":[{"asset_id":"12935926064588426924078449947177910958215776269411501731627440228801766632772", "price":"0.4", "size":"77.53", "side":"BUY", "hash":"1774e97fc63cbfc47cd9a5dcd6239fec86344f30", "best_bid":"0.4", "best_ask":"0.41"}, {"asset_id":"17924629579804316786455515989238352689210911545477836576430679697715946894553", "price":"0.6", "size":"77.53", "side":"SELL", "hash":"c578bf0258c89a89a52501459f1736ddd5f449cf", "best_bid":"0.59", "best_ask":"0.6"}], "timestamp":"1784449238616", "event_type":"price_change"}
{"market":"0xab772601f501b265bfe8982eb61d5347ef9945de314bfdf4ac0189c288ffb0b3", "price_changes":[{"asset_id":"12935926064588426924078449947177910958215776269411501731627440228801766632772", "price":"0.39", "size":"135.88", "side":"BUY", "hash":"e78a4d630725f9e05864d12cdf982bc90da5a0b0", "best_bid":"0.4", "best_ask":"0.41"}, {"asset_id":"17924629579804316786455515989238352689210911545477836576430679697715946894553", "price":"0.61", "size":"135.88", "side":"SELL", "hash":"ff4569645eef56eba20972d1e15d49b3fe1c6cde", "best_bid":"0.59", "best_ask":"0.6"}], "timestamp":"1784449238617", "event_type":"price_change"}
{"market":"0xab772601f501b265bfe8982eb61d5347ef9945de314bfdf4ac0189c288ffb0b3", "price_changes":[{"asset_id":"12935926064588426924078449947177910958215776269411501731627440228801766632772", "price":"0.39", "size":"160.88", "side":"BUY", "hash":"39387b6675b150aff016f469c16215f5fb0c414f", "best_bid":"0.4", "best_ask":"0.41"}, {"asset_id":"17924629579804316786455515989238352689210911545477836576430679697715946894553", "price":"0.61", "size":"160.88", "side":"SELL", "hash":"7ec572d3d3f3468e0d7c5141f8e4c90d741ee70b", "best_bid":"0.59", "best_ask":"0.6"}], "timestamp":"1784449238618", "event_type":"price_change"}
{"market":"0xab772601f501b265bfe8982eb61d5347ef9945de314bfdf4ac0189c288ffb0b3", "price_changes":[{"asset_id":"17924629579804316786455515989238352689210911545477836576430679697715946894553", "price":"0.6", "size":"82.53", "side":"SELL", "hash":"279fc1cc25ad019e1d3aaabc1a78caec55d25bd2", "best_bid":"0.59", "best_ask":"0.6"}, {"asset_id":"12935926064588426924078449947177910958215776269411501731627440228801766632772", "price":"0.4", "size":"82.53", "side":"BUY", "hash":"14eff9364f3dfede656d59a57822f97f859de553", "best_bid":"0.4", "best_ask":"0.41"}], "timestamp":"1784449238618", "event_type":"price_change"}
{"market":"0xab772601f501b265bfe8982eb61d5347ef9945de314bfdf4ac0189c288ffb0b3", "price_changes":[{"asset_id":"12935926064588426924078449947177910958215776269411501731627440228801766632772", "price":"0.37", "size":"175.91", "side":"BUY", "hash":"520f6e6106e030219af5ba06b615ad026079ac5c", "best_bid":"0.4", "best_ask":"0.41"}, {"asset_id":"17924629579804316786455515989238352689210911545477836576430679697715946894553", "price":"0.63", "size":"175.91", "side":"SELL", "hash":"99cd002043f173895a30c763081e2ae614d8b1f9", "best_bid":"0.59", "best_ask":"0.6"}], "timestamp":"1784449238619", "event_type":"price_change"}
{"market":"0xab772601f501b265bfe8982eb61d5347ef9945de314bfdf4ac0189c288ffb0b3", "price_changes":[{"asset_id":"12935926064588426924078449947177910958215776269411501731627440228801766632772", "price":"0.01", "size":"14884.14", "side":"BUY", "hash":"4387c7e8d21a770b199e1e118d1a0fd82210ac76", "best_bid":"0.4", "best_ask":"0.41"}, {"asset_id":"17924629579804316786455515989238352689210911545477836576430679697715946894553", "price":"0.99", "size":"14884.14", "side":"SELL", "hash":"0bc7416f9c22b163ce92eccea1f330bd6241e14b", "best_bid":"0.59", "best_ask":"0.6"}], "timestamp":"1784449238619", "event_type":"price_change"}
{"market":"0xab772601f501b265bfe8982eb61d5347ef9945de314bfdf4ac0189c288ffb0b3", "price_changes":[{"asset_id":"17924629579804316786455515989238352689210911545477836576430679697715946894553", "price":"0.01", "size":"13080.5", "side":"BUY", "hash":"400cef663be9feb33b05b0e9d9fb36c91d24dee3", "best_bid":"0.59", "best_ask":"0.6"}, {"asset_id":"12935926064588426924078449947177910958215776269411501731627440228801766632772", "price":"0.99", "size":"13080.5", "side":"SELL", "hash":"1d0e25501d0cae8471c9690b62c3900a1179ca03", "best_bid":"0.4", "best_ask":"0.41"}], "timestamp":"1784449238620", "event_type":"price_change"}
{"market":"0xab772601f501b265bfe8982eb61d5347ef9945de314bfdf4ac0189c288ffb0b3", "price_changes":[{"asset_id":"12935926064588426924078449947177910958215776269411501731627440228801766632772", "price":"0.4", "size":"102.53", "side":"BUY", "hash":"68a0def65f379c2c4bdef6c25e017f7feeca0b13", "best_bid":"0.4", "best_ask":"0.41"}, {"asset_id":"17924629579804316786455515989238352689210911545477836576430679697715946894553", "price":"0.6", "size":"102.53", "side":"SELL", "hash":"749a2645f5ccb0dc1fec3e02b951bf415b3e505f", "best_bid":"0.59", "best_ask":"0.6"}], "timestamp":"1784449238620", "event_type":"price_change"}
{"market":"0xab772601f501b265bfe8982eb61d5347ef9945de314bfdf4ac0189c288ffb0b3", "price_changes":[{"asset_id":"12935926064588426924078449947177910958215776269411501731627440228801766632772", "price":"0.01", "size":"14889.14", "side":"BUY", "hash":"d34bf9c5d489d3b317400120ffa6241b3d5bd4d3", "best_bid":"0.4", "best_ask":"0.41"}, {"asset_id":"17924629579804316786455515989238352689210911545477836576430679697715946894553", "price":"0.99", "size":"14889.14", "side":"SELL", "hash":"610ec92f4f9a84f5413717f927997db6d48b810e", "best_bid":"0.59", "best_ask":"0.6"}], "timestamp":"1784449238622", "event_type":"price_change"}
{"market":"0xab772601f501b265bfe8982eb61d5347ef9945de314bfdf4ac0189c288ffb0b3", "price_changes":[{"asset_id":"12935926064588426924078449947177910958215776269411501731627440228801766632772", "price":"0.01", "size":"14894.14", "side":"BUY", "hash":"0e0a14b458c2e3e22247442267db29dc0bc8211f", "best_bid":"0.4", "best_ask":"0.41"}, {"asset_id":"17924629579804316786455515989238352689210911545477836576430679697715946894553", "price":"0.99", "size":"14894.14", "side":"SELL", "hash":"8fecd00fd044921bac7bff5b2f0a093e8ed8898a", "best_bid":"0.59", "best_ask":"0.6"}], "timestamp":"1784449238622", "event_type":"price_change"}
{"market":"0xab772601f501b265bfe8982eb61d5347ef9945de314bfdf4ac0189c288ffb0b3", "price_changes":[{"asset_id":"12935926064588426924078449947177910958215776269411501731627440228801766632772", "price":"0.01", "size":"14899.14", "side":"BUY", "hash":"c675293505fdfb682536f3810364b584766c0f31", "best_bid":"0.4", "best_ask":"0.41"}, {"asset_id":"17924629579804316786455515989238352689210911545477836576430679697715946894553", "price":"0.99", "size":"14899.14", "side":"SELL", "hash":"2b70216d68f51c73704adc200b0e993a2c8bc6fb", "best_bid":"0.59", "best_ask":"0.6"}], "timestamp":"1784449238623", "event_type":"price_change"}
{"market":"0xab772601f501b265bfe8982eb61d5347ef9945de314bfdf4ac0189c288ffb0b3", "price_changes":[{"asset_id":"12935926064588426924078449947177910958215776269411501731627440228801766632772", "price":"0.01", "size":"14894.14", "side":"BUY", "hash":"7a6df6025a39fc7f2b71ec2b5df9c911e3270641", "best_bid":"0.4", "best_ask":"0.41"}, {"asset_id":"17924629579804316786455515989238352689210911545477836576430679697715946894553", "price":"0.99", "size":"14894.14", "side":"SELL", "hash":"eb2ec6f73e136476c99bfead64dd05cbf83122b3", "best_bid":"0.59", "best_ask":"0.6"}], "timestamp":"1784449238623", "event_type":"price_change"}
{"market":"0xab772601f501b265bfe8982eb61d5347ef9945de314bfdf4ac0189c288ffb0b3", "price_changes":[{"asset_id":"17924629579804316786455515989238352689210911545477836576430679697715946894553", "price":"0.34", "size":"92.8", "side":"BUY", "hash":"753fe1d9f8682a68bae4e4913d3a620e662fdf91", "best_bid":"0.59", "best_ask":"0.6"}, {"asset_id":"12935926064588426924078449947177910958215776269411501731627440228801766632772", "price":"0.66", "size":"92.8", "side":"SELL", "hash":"059eba34199b1be5a556917b031713a444685294", "best_bid":"0.4", "best_ask":"0.41"}], "timestamp":"1784449238624", "event_type":"price_change"}
{"market":"0xab772601f501b265bfe8982eb61d5347ef9945de314bfdf4ac0189c288ffb0b3", "price_changes":[{"asset_id":"17924629579804316786455515989238352689210911545477836576430679697715946894553", "price":"0.58", "size":"111.82", "side":"BUY", "hash":"dbbc0c7354f47f6dc42f5e467be724f67e7444e8", "best_bid":"0.59", "best_ask":"0.6"}, {"asset_id":"12935926064588426924078449947177910958215776269411501731627440228801766632772", "price":"0.42", "size":"111.82", "side":"SELL", "hash":"58bf7ec38e5d5d01fcc68374982db313732aa5f2", "best_bid":"0.4", "best_ask":"0.41"}], "timestamp":"1784449238626", "event_type":"price_change"}
{"market":"0xab772601f501b265bfe8982eb61d5347ef9945de314bfdf4ac0189c288ffb0b3", "price_changes":[{"asset_id":"12935926064588426924078449947177910958215776269411501731627440228801766632772", "price":"0.35", "size":"97.8", "side":"BUY", "hash":"c72ce5e85c0f73bd179b35c74fdc87450c7170da", "best_bid":"0.4", "best_ask":"0.41"}, {"asset_id":"17924629579804316786455515989238352689210911545477836576430679697715946894553", "price":"0.65", "size":"97.8", "side":"SELL", "hash":"592b1bf4be132d91720e6204f6ba1f404e808b09", "best_bid":"0.59", "best_ask":"0.6"}], "timestamp":"1784449238626", "event_type":"price_change"}
{"market":"0xab772601f501b265bfe8982eb61d5347ef9945de314bfdf4ac0189c288ffb0b3", "price_changes":[{"asset_id":"12935926064588426924078449947177910958215776269411501731627440228801766632772", "price":"0.36", "size":"185.77", "side":"BUY", "hash":"c72ce5e85c0f73bd179b35c74fdc87450c7170da", "best_bid":"0.4", "best_ask":"0.41"}, {"asset_id":"17924629579804316786455515989238352689210911545477836576430679697715946894553", "price":"0.64", "size":"185.77", "side":"SELL", "hash":"592b1bf4be132d91720e6204f6ba1f404e808b09", "best_bid":"0.59", "best_ask":"0.6"}], "timestamp":"1784449238626", "event_type":"price_change"}
{"market":"0xab772601f501b265bfe8982eb61d5347ef9945de314bfdf4ac0189c288ffb0b3", "price_changes":[{"asset_id":"12935926064588426924078449947177910958215776269411501731627440228801766632772", "price":"0.51", "size":"106.92", "side":"SELL", "hash":"2c53b09c62d74b94fc53de360ff3ce39746d7cdf", "best_bid":"0.4", "best_ask":"0.41"}, {"asset_id":"17924629579804316786455515989238352689210911545477836576430679697715946894553", "price":"0.49", "size":"106.92", "side":"BUY", "hash":"a813c0a03f412565296e7aa2abe8b9f7e939818a", "best_bid":"0.59", "best_ask":"0.6"}], "timestamp":"1784449238627", "event_type":"price_change"}
{"market":"0xab772601f501b265bfe8982eb61d5347ef9945de314bfdf4ac0189c288ffb0b3", "price_changes":[{"asset_id":"17924629579804316786455515989238352689210911545477836576430679697715946894553", "price":"0.49", "size":"81", "side":"BUY", "hash":"8c17ca706e9662799d79994a1b54289fb783911f", "best_bid":"0.59", "best_ask":"0.6"}, {"asset_id":"12935926064588426924078449947177910958215776269411501731627440228801766632772", "price":"0.51", "size":"81", "side":"SELL", "hash":"faa12316d3da623a8987ab252d2a1c50b1d59910", "best_bid":"0.4", "best_ask":"0.41"}], "timestamp":"1784449238628", "event_type":"price_change"}
{"market":"0xab772601f501b265bfe8982eb61d5347ef9945de314bfdf4ac0189c288ffb0b3", "price_changes":[{"asset_id":"17924629579804316786455515989238352689210911545477836576430679697715946894553", "price":"0.01", "size":"13074.5", "side":"BUY", "hash":"d0a1e31d3f1ae0927fbc381e3618cb0bd693a02d", "best_bid":"0.59", "best_ask":"0.6"}, {"asset_id":"12935926064588426924078449947177910958215776269411501731627440228801766632772", "price":"0.99", "size":"13074.5", "side":"SELL", "hash":"cdc7b18de1a7d42756e1c3786df26f32e1525c8a", "best_bid":"0.4", "best_ask":"0.41"}], "timestamp":"1784449238630", "event_type":"price_change"}
{"market":"0xab772601f501b265bfe8982eb61d5347ef9945de314bfdf4ac0189c288ffb0b3", "price_changes":[{"asset_id":"12935926064588426924078449947177910958215776269411501731627440228801766632772", "price":"0.37", "size":"150.91", "side":"BUY", "hash":"372bc4d38e5ff9612b8906d5eeda3efb686e13e6", "best_bid":"0.4", "best_ask":"0.41"}, {"asset_id":"17924629579804316786455515989238352689210911545477836576430679697715946894553", "price":"0.63", "size":"150.91", "side":"SELL", "hash":"67443f364fb4170424642b94ce64a52ccfffaca7", "best_bid":"0.59", "best_ask":"0.6"}], "timestamp":"1784449238634", "event_type":"price_change"}
{"market":"0xab772601f501b265bfe8982eb61d5347ef9945de314bfdf4ac0189c288ffb0b3", "price_changes":[{"asset_id":"17924629579804316786455515989238352689210911545477836576430679697715946894553", "price":"0.01", "size":"13069.5", "side":"BUY", "hash":"6908b26907ef47d651876bffeb13740e2d7ba228", "best_bid":"0.59", "best_ask":"0.6"}, {"asset_id":"12935926064588426924078449947177910958215776269411501731627440228801766632772", "price":"0.99", "size":"13069.5", "side":"SELL", "hash":"f1c9b53d6587623e70da84e9c6df9721649767de", "best_bid":"0.4", "best_ask":"0.41"}], "timestamp":"1784449238635", "event_type":"price_change"}
{"market":"0xab772601f501b265bfe8982eb61d5347ef9945de314bfdf4ac0189c288ffb0b3", "price_changes":[{"asset_id":"12935926064588426924078449947177910958215776269411501731627440228801766632772", "price":"0.4", "size":"120.61", "side":"BUY", "hash":"15ac5c4785bb0b227499387c4e873d013a81c0b1", "best_bid":"0.4", "best_ask":"0.41"}, {"asset_id":"17924629579804316786455515989238352689210911545477836576430679697715946894553", "price":"0.6", "size":"120.61", "side":"SELL", "hash":"d08cfb3a54e22bdb494df2cbe952e51417580c19", "best_bid":"0.59", "best_ask":"0.6"}], "timestamp":"1784449238637", "event_type":"price_change"}
{"market":"0xab772601f501b265bfe8982eb61d5347ef9945de314bfdf4ac0189c288ffb0b3", "price_changes":[{"asset_id":"12935926064588426924078449947177910958215776269411501731627440228801766632772", "price":"0.34", "size":"150.77", "side":"BUY", "hash":"b344c04cfb911999c34a34bb06af440d6d225d12", "best_bid":"0.4", "best_ask":"0.41"}, {"asset_id":"17924629579804316786455515989238352689210911545477836576430679697715946894553", "price":"0.66", "size":"150.77", "side":"SELL", "hash":"ee1ef64d0abb63adaf507f026a9bdfe586192b14", "best_bid":"0.59", "best_ask":"0.6"}], "timestamp":"1784449238642", "event_type":"price_change"}
{"market":"0xab772601f501b265bfe8982eb61d5347ef9945de314bfdf4ac0189c288ffb0b3", "price_changes":[{"asset_id":"17924629579804316786455515989238352689210911545477836576430679697715946894553", "price":"0.36", "size":"104.39", "side":"BUY", "hash":"a38ab0831ad5a526ebb9a1250008dcbff1ff2ba2", "best_bid":"0.59", "best_ask":"0.6"}, {"asset_id":"12935926064588426924078449947177910958215776269411501731627440228801766632772", "price":"0.64", "size":"104.39", "side":"SELL", "hash":"ee91bcde26c2cc53e5c9393ff5f2963c39578376", "best_bid":"0.4", "best_ask":"0.41"}], "timestamp":"1784449238643", "event_type":"price_change"}
{"market":"0xab772601f501b265bfe8982eb61d5347ef9945de314bfdf4ac0189c288ffb0b3", "price_changes":[{"asset_id":"17924629579804316786455515989238352689210911545477836576430679697715946894553", "price":"0.01", "size":"13064.5", "side":"BUY", "hash":"e7f0d50a7781c6e688b4bd75577831b4d397d340", "best_bid":"0.59", "best_ask":"0.6"}, {"asset_id":"12935926064588426924078449947177910958215776269411501731627440228801766632772", "price":"0.99", "size":"13064.5", "side":"SELL", "hash":"56df639ee59c934f52b780013db2e99f97381d63", "best_bid":"0.4", "best_ask":"0.41"}], "timestamp":"1784449238645", "event_type":"price_change"}
{"market":"0xab772601f501b265bfe8982eb61d5347ef9945de314bfdf4ac0189c288ffb0b3", "price_changes":[{"asset_id":"12935926064588426924078449947177910958215776269411501731627440228801766632772", "price":"0.33", "size":"149.65", "side":"BUY", "hash":"7dc284e230a3407d62f1d0132b31b13ee505e69b", "best_bid":"0.4", "best_ask":"0.41"}, {"asset_id":"17924629579804316786455515989238352689210911545477836576430679697715946894553", "price":"0.67", "size":"149.65", "side":"SELL", "hash":"a168b545b9e465027e3a0a3f5817958ae187c0b2", "best_bid":"0.59", "best_ask":"0.6"}], "timestamp":"1784449238648", "event_type":"price_change"}
{"market":"0xab772601f501b265bfe8982eb61d5347ef9945de314bfdf4ac0189c288ffb0b3", "price_changes":[{"asset_id":"17924629579804316786455515989238352689210911545477836576430679697715946894553", "price":"0.57", "size":"140", "side":"BUY", "hash":"ea378a8409a4368954ee0ab39004122f398b912e", "best_bid":"0.59", "best_ask":"0.6"}, {"asset_id":"12935926064588426924078449947177910958215776269411501731627440228801766632772", "price":"0.43", "size":"140", "side":"SELL", "hash":"126253342e8d8b51ab98042ce75dab1d10d1b4b2", "best_bid":"0.4", "best_ask":"0.41"}], "timestamp":"1784449238652", "event_type":"price_change"}
{"market":"0xab772601f501b265bfe8982eb61d5347ef9945de314bfdf4ac0189c288ffb0b3", "price_changes":[{"asset_id":"17924629579804316786455515989238352689210911545477836576430679697715946894553", "price":"0.57", "size":"135", "side":"BUY", "hash":"7bfd144704a0fa6091f3f6e88085d3f54d3c5566", "best_bid":"0.59", "best_ask":"0.6"}, {"asset_id":"12935926064588426924078449947177910958215776269411501731627440228801766632772", "price":"0.43", "size":"135", "side":"SELL", "hash":"b525d29fee0085350c3393d8354a23480e47b606", "best_bid":"0.4", "best_ask":"0.41"}], "timestamp":"1784449238652", "event_type":"price_change"}
{"market":"0xab772601f501b265bfe8982eb61d5347ef9945de314bfdf4ac0189c288ffb0b3", "price_changes":[{"asset_id":"17924629579804316786455515989238352689210911545477836576430679697715946894553", "price":"0.52", "size":"235.91", "side":"BUY", "hash":"8ca071cbe6d247919a5cf3e26e398c1acc2618a3", "best_bid":"0.59", "best_ask":"0.6"}, {"asset_id":"12935926064588426924078449947177910958215776269411501731627440228801766632772", "price":"0.48", "size":"235.91", "side":"SELL", "hash":"ac286d1c3b12dc6a670a92815019e01cdc08c029", "best_bid":"0.4", "best_ask":"0.41"}], "timestamp":"1784449238653", "event_type":"price_change"}
{"market":"0xab772601f501b265bfe8982eb61d5347ef9945de314bfdf4ac0189c288ffb0b3", "price_changes":[{"asset_id":"12935926064588426924078449947177910958215776269411501731627440228801766632772", "price":"0.38", "size":"351.23", "side":"BUY", "hash":"b53482d5589de29f722ba652721147b1e48f6467", "best_bid":"0.4", "best_ask":"0.41"}, {"asset_id":"17924629579804316786455515989238352689210911545477836576430679697715946894553", "price":"0.62", "size":"351.23", "side":"SELL", "hash":"68a073e077385f0418096a8e1c6ec257278f2543", "best_bid":"0.59", "best_ask":"0.6"}], "timestamp":"1784449238654", "event_type":"price_change"}
{"market":"0xab772601f501b265bfe8982eb61d5347ef9945de314bfdf4ac0189c288ffb0b3", "price_changes":[{"asset_id":"17924629579804316786455515989238352689210911545477836576430679697715946894553", "price":"0.56", "size":"267.99", "side":"BUY", "hash":"c8f653cf1fefc1d2ef6e1f48e6abf3610361f7ba", "best_bid":"0.59", "best_ask":"0.6"}, {"asset_id":"12935926064588426924078449947177910958215776269411501731627440228801766632772", "price":"0.44", "size":"267.99", "side":"SELL", "hash":"37dea92bb44af147ee13dc07f94802dba6610094", "best_bid":"0.4", "best_ask":"0.41"}], "timestamp":"1784449238655", "event_type":"price_change"}
{"market":"0xab772601f501b265bfe8982eb61d5347ef9945de314bfdf4ac0189c288ffb0b3", "price_changes":[{"asset_id":"12935926064588426924078449947177910958215776269411501731627440228801766632772", "price":"0.34", "size":"145.76", "side":"BUY", "hash":"0e58b09eb12ee451d53611f981cb0a9e7f11d605", "best_bid":"0.4", "best_ask":"0.41"}, {"asset_id":"17924629579804316786455515989238352689210911545477836576430679697715946894553", "price":"0.66", "size":"145.76", "side":"SELL", "hash":"26e8bfb2c288166774c1e25be67aa5e80fcaa460", "best_bid":"0.59", "best_ask":"0.6"}], "timestamp":"1784449238655", "event_type":"price_change"}
{"market":"0xab772601f501b265bfe8982eb61d5347ef9945de314bfdf4ac0189c288ffb0b3", "price_changes":[{"asset_id":"12935926064588426924078449947177910958215776269411501731627440228801766632772", "price":"0.3", "size":"202.81", "side":"BUY", "hash":"417841c14b783d5ac7bef21e6ef8620146bb155c", "best_bid":"0.4", "best_ask":"0.41"}, {"asset_id":"17924629579804316786455515989238352689210911545477836576430679697715946894553", "price":"0.7", "size":"202.81", "side":"SELL", "hash":"4dde9b56cf79d328d30bf0769a3fff4abb7f97ff", "best_bid":"0.59", "best_ask":"0.6"}], "timestamp":"1784449238656", "event_type":"price_change"}
{"market":"0xab772601f501b265bfe8982eb61d5347ef9945de314bfdf4ac0189c288ffb0b3", "price_changes":[{"asset_id":"17924629579804316786455515989238352689210911545477836576430679697715946894553", "price":"0.01", "size":"12964.5", "side":"BUY", "hash":"b84c0312c2034ac446d2a2dca99d8b2a42dc2976", "best_bid":"0.59", "best_ask":"0.6"}, {"asset_id":"12935926064588426924078449947177910958215776269411501731627440228801766632772", "price":"0.99", "size":"12964.5", "side":"SELL", "hash":"0364416bde518fc3b3d83c4ae3929998668a9503", "best_bid":"0.4", "best_ask":"0.41"}], "timestamp":"1784449238657", "event_type":"price_change"}
{"market":"0xab772601f501b265bfe8982eb61d5347ef9945de314bfdf4ac0189c288ffb0b3", "asset_id":"17924629579804316786455515989238352689210911545477836576430679697715946894553", "price":"0.6", "size":"1.666665", "fee_rate_bps":"0", "side":"BUY", "timestamp":"1784449238658", "event_type":"last_trade_price", "transaction_hash":"0xc409563cc17d6f9da40c452a3c9024df38a5fb49274370d8a56f863a2ca997c7"}
{"market":"0xab772601f501b265bfe8982eb61d5347ef9945de314bfdf4ac0189c288ffb0b3", "price_changes":[{"asset_id":"17924629579804316786455515989238352689210911545477836576430679697715946894553", "price":"0.01", "size":"12969.51", "side":"BUY", "hash":"b2ae2590efc66710db879aee7e937ad089fc6e8d", "best_bid":"0.59", "best_ask":"0.6"}, {"asset_id":"12935926064588426924078449947177910958215776269411501731627440228801766632772", "price":"0.99", "size":"12969.51", "side":"SELL", "hash":"d0658cf9699f0b8d55c96f9e5e2c6da3c62e77a6", "best_bid":"0.4", "best_ask":"0.41"}], "timestamp":"1784449238664", "event_type":"price_change"}
{"market":"0xab772601f501b265bfe8982eb61d5347ef9945de314bfdf4ac0189c288ffb0b3", "price_changes":[{"asset_id":"12935926064588426924078449947177910958215776269411501731627440228801766632772", "price":"0.37", "size":"175.91", "side":"BUY", "hash":"05ae670aee75ab6df8cb4215a938d4b3663ac7d8", "best_bid":"0.4", "best_ask":"0.41"}, {"asset_id":"17924629579804316786455515989238352689210911545477836576430679697715946894553", "price":"0.63", "size":"175.91", "side":"SELL", "hash":"c5068800831a1dd1cabbdf5a5a7ac4b2225aeda1", "best_bid":"0.59", "best_ask":"0.6"}], "timestamp":"1784449238665", "event_type":"price_change"}
{"market":"0xab772601f501b265bfe8982eb61d5347ef9945de314bfdf4ac0189c288ffb0b3", "price_changes":[{"asset_id":"12935926064588426924078449947177910958215776269411501731627440228801766632772", "price":"0.35", "size":"122.8", "side":"BUY", "hash":"7e57bcfa31260beb2428c4f8dfc0feaa5a1bd095", "best_bid":"0.4", "best_ask":"0.41"}, {"asset_id":"17924629579804316786455515989238352689210911545477836576430679697715946894553", "price":"0.65", "size":"122.8", "side":"SELL", "hash":"f675b2a80c66b2467a83a26e3c6ebe46c834a21a", "best_bid":"0.59", "best_ask":"0.6"}], "timestamp":"1784449238667", "event_type":"price_change"}
{"market":"0xab772601f501b265bfe8982eb61d5347ef9945de314bfdf4ac0189c288ffb0b3", "price_changes":[{"asset_id":"12935926064588426924078449947177910958215776269411501731627440228801766632772", "price":"0.34", "size":"120.76", "side":"BUY", "hash":"ac5bcb913eb1911c5b844b1a257d7464483315be", "best_bid":"0.4", "best_ask":"0.41"}, {"asset_id":"17924629579804316786455515989238352689210911545477836576430679697715946894553", "price":"0.66", "size":"120.76", "side":"SELL", "hash":"0650fca72f68033cb5b9d760006527ce6736511f", "best_bid":"0.59", "best_ask":"0.6"}], "timestamp":"1784449238668", "event_type":"price_change"}
{"market":"0xab772601f501b265bfe8982eb61d5347ef9945de314bfdf4ac0189c288ffb0b3", "price_changes":[{"asset_id":"12935926064588426924078449947177910958215776269411501731627440228801766632772", "price":"0.01", "size":"14889.14", "side":"BUY", "hash":"48d84f342e1f4125acf0eb1d76c5836506f0af9e", "best_bid":"0.4", "best_ask":"0.41"}, {"asset_id":"17924629579804316786455515989238352689210911545477836576430679697715946894553", "price":"0.99", "size":"14889.14", "side":"SELL", "hash":"553a9d71197398e9a71018eb6846cdd1390ee600", "best_bid":"0.59", "best_ask":"0.6"}], "timestamp":"1784449238669", "event_type":"price_change"}
{"market":"0xab772601f501b265bfe8982eb61d5347ef9945de314bfdf4ac0189c288ffb0b3", "price_changes":[{"asset_id":"12935926064588426924078449947177910958215776269411501731627440228801766632772", "price":"0.38", "size":"356.23", "side":"BUY", "hash":"a978765910a9f3ed2820d7460470c40eb14830b8", "best_bid":"0.4", "best_ask":"0.41"}, {"asset_id":"17924629579804316786455515989238352689210911545477836576430679697715946894553", "price":"0.62", "size":"356.23", "side":"SELL", "hash":"25adbd26cc8fb6f4869c657bd9bdc2fa99457cd8", "best_bid":"0.59", "best_ask":"0.6"}], "timestamp":"1784449238675", "event_type":"price_change"}
{"market":"0xab772601f501b265bfe8982eb61d5347ef9945de314bfdf4ac0189c288ffb0b3", "price_changes":[{"asset_id":"17924629579804316786455515989238352689210911545477836576430679697715946894553", "price":"0.49", "size":"106.92", "side":"BUY", "hash":"b04f314b836bf53d3db9d330fd4629c3cf67b4eb", "best_bid":"0.59", "best_ask":"0.6"}, {"asset_id":"12935926064588426924078449947177910958215776269411501731627440228801766632772", "price":"0.51", "size":"106.92", "side":"SELL", "hash":"002cc562865f2487b84c1d46c659dd9ae195b723", "best_bid":"0.4", "best_ask":"0.41"}], "timestamp":"1784449238690", "event_type":"price_change"}
{"market":"0xab772601f501b265bfe8982eb61d5347ef9945de314bfdf4ac0189c288ffb0b3", "price_changes":[{"asset_id":"17924629579804316786455515989238352689210911545477836576430679697715946894553", "price":"0.01", "size":"12964.5", "side":"BUY", "hash":"53852928ea75169e8432739cc94139ed9cab40cf", "best_bid":"0.59", "best_ask":"0.6"}, {"asset_id":"12935926064588426924078449947177910958215776269411501731627440228801766632772", "price":"0.99", "size":"12964.5", "side":"SELL", "hash":"41db035a7d8ec4c145d005136bf2524aee48f387", "best_bid":"0.4", "best_ask":"0.41"}], "timestamp":"1784449238692", "event_type":"price_change"}
{"market":"0xab772601f501b265bfe8982eb61d5347ef9945de314bfdf4ac0189c288ffb0b3", "price_changes":[{"asset_id":"17924629579804316786455515989238352689210911545477836576430679697715946894553", "price":"0.01", "size":"13064.5", "side":"BUY", "hash":"3351cb53999ad2dd79c3f242d900c3d3ed3ccf93", "best_bid":"0.59", "best_ask":"0.6"}, {"asset_id":"12935926064588426924078449947177910958215776269411501731627440228801766632772", "price":"0.99", "size":"13064.5", "side":"SELL", "hash":"3a33f74a2205343b5df02a5948eab64f96288a6f", "best_bid":"0.4", "best_ask":"0.41"}], "timestamp":"1784449238698", "event_type":"price_change"}
{"market":"0xab772601f501b265bfe8982eb61d5347ef9945de314bfdf4ac0189c288ffb0b3", "price_changes":[{"asset_id":"12935926064588426924078449947177910958215776269411501731627440228801766632772", "price":"0.33", "size":"144.65", "side":"BUY", "hash":"7157230be9a7e08028e50875e1fea705534970bc", "best_bid":"0.4", "best_ask":"0.41"}, {"asset_id":"17924629579804316786455515989238352689210911545477836576430679697715946894553", "price":"0.67", "size":"144.65", "side":"SELL", "hash":"f8644657b4d4fd24e0d165da5813fc5ea7f552ce", "best_bid":"0.59", "best_ask":"0.6"}], "timestamp":"1784449238702", "event_type":"price_change"}
{"market":"0xab772601f501b265bfe8982eb61d5347ef9945de314bfdf4ac0189c288ffb0b3", "price_changes":[{"asset_id":"17924629579804316786455515989238352689210911545477836576430679697715946894553", "price":"0.01", "size":"13059.5", "side":"BUY", "hash":"86567250cfb27a9edc9a10809985377a80ffe1d4", "best_bid":"0.59", "best_ask":"0.6"}, {"asset_id":"12935926064588426924078449947177910958215776269411501731627440228801766632772", "price":"0.99", "size":"13059.5", "side":"SELL", "hash":"f42e8f32df5d2e5cb937d2c22c3a6de21baee806", "best_bid":"0.4", "best_ask":"0.41"}], "timestamp":"1784449238703", "event_type":"price_change"}
{"market":"0xab772601f501b265bfe8982eb61d5347ef9945de314bfdf4ac0189c288ffb0b3", "price_changes":[{"asset_id":"17924629579804316786455515989238352689210911545477836576430679697715946894553", "price":"0.01", "size":"13065.5", "side":"BUY", "hash":"5ebb3e97454d4922357ea272616c1b0fa18d5ec6", "best_bid":"0.59", "best_ask":"0.6"}, {"asset_id":"12935926064588426924078449947177910958215776269411501731627440228801766632772", "price":"0.99", "size":"13065.5", "side":"SELL", "hash":"96a3f8392685ba2f236c25e4d2d87bd59cc14601", "best_bid":"0.4", "best_ask":"0.41"}], "timestamp":"1784449238705", "event_type":"price_change"}
{"market":"0xab772601f501b265bfe8982eb61d5347ef9945de314bfdf4ac0189c288ffb0b3", "price_changes":[{"asset_id":"17924629579804316786455515989238352689210911545477836576430679697715946894553", "price":"0.57", "size":"130", "side":"BUY", "hash":"82f6c5399e204d37090e37e25db2074075e6bfec", "best_bid":"0.59", "best_ask":"0.6"}, {"asset_id":"12935926064588426924078449947177910958215776269411501731627440228801766632772", "price":"0.43", "size":"130", "side":"SELL", "hash":"33807f15bb5efbff3ef4da55561551601330f22a", "best_bid":"0.4", "best_ask":"0.41"}], "timestamp":"1784449238709", "event_type":"price_change"}
{"market":"0xab772601f501b265bfe8982eb61d5347ef9945de314bfdf4ac0189c288ffb0b3", "price_changes":[{"asset_id":"17924629579804316786455515989238352689210911545477836576430679697715946894553", "price":"0.01", "size":"13070.5", "side":"BUY", "hash":"16fb1b8b1b24c747dde963c0178c75bff874f05b", "best_bid":"0.59", "best_ask":"0.6"}, {"asset_id":"12935926064588426924078449947177910958215776269411501731627440228801766632772", "price":"0.99", "size":"13070.5", "side":"SELL", "hash":"ada237f8d51c8f0eb3435a3d96c003e677fe35b1", "best_bid":"0.4", "best_ask":"0.41"}], "timestamp":"1784449238711", "event_type":"price_change"}
{"market":"0xab772601f501b265bfe8982eb61d5347ef9945de314bfdf4ac0189c288ffb0b3", "price_changes":[{"asset_id":"17924629579804316786455515989238352689210911545477836576430679697715946894553", "price":"0.01", "size":"13064.5", "side":"BUY", "hash":"0c5474d0debd7e65137723a8fcd6eae92803c88b", "best_bid":"0.59", "best_ask":"0.6"}, {"asset_id":"12935926064588426924078449947177910958215776269411501731627440228801766632772", "price":"0.99", "size":"13064.5", "side":"SELL", "hash":"f810c8e6149bbbc37f00a1d3295ecfbf0dd0a82f", "best_bid":"0.4", "best_ask":"0.41"}], "timestamp":"1784449238726", "event_type":"price_change"}
{"market":"0xab772601f501b265bfe8982eb61d5347ef9945de314bfdf4ac0189c288ffb0b3", "price_changes":[{"asset_id":"17924629579804316786455515989238352689210911545477836576430679697715946894553", "price":"0.04", "size":"1275.1", "side":"BUY", "hash":"a93457ef0516d3e80264c30f82b38b6d06cf67c5", "best_bid":"0.59", "best_ask":"0.6"}, {"asset_id":"12935926064588426924078449947177910958215776269411501731627440228801766632772", "price":"0.96", "size":"1275.1", "side":"SELL", "hash":"a5d48cf8c1638759e162939c85ed511fba5bd8ec", "best_bid":"0.4", "best_ask":"0.41"}], "timestamp":"1784449238727", "event_type":"price_change"}
{"market":"0xab772601f501b265bfe8982eb61d5347ef9945de314bfdf4ac0189c288ffb0b3", "price_changes":[{"asset_id":"12935926064588426924078449947177910958215776269411501731627440228801766632772", "price":"0.5", "size":"129.39", "side":"SELL", "hash":"a6e9ec07e15df3ba4e4adaf2bbc108eb5321a292", "best_bid":"0.4", "best_ask":"0.41"}, {"asset_id":"17924629579804316786455515989238352689210911545477836576430679697715946894553", "price":"0.5", "size":"129.39", "side":"BUY", "hash":"a68e923a6e26bf1191ae00cdd93b4f74ef8f77e8", "best_bid":"0.59", "best_ask":"0.6"}], "timestamp":"1784449238731", "event_type":"price_change"}
{"market":"0xab772601f501b265bfe8982eb61d5347ef9945de314bfdf4ac0189c288ffb0b3", "price_changes":[{"asset_id":"17924629579804316786455515989238352689210911545477836576430679697715946894553", "price":"0.01", "size":"13059.5", "side":"BUY", "hash":"89b5e534e8f9880900a5bb67f48f66b4c63f5254", "best_bid":"0.59", "best_ask":"0.6"}, {"asset_id":"12935926064588426924078449947177910958215776269411501731627440228801766632772", "price":"0.99", "size":"13059.5", "side":"SELL", "hash":"b5e662a7ed9905c95203c8f72498ded4102fa2ac", "best_bid":"0.4", "best_ask":"0.41"}], "timestamp":"1784449238732", "event_type":"price_change"}
{"market":"0xab772601f501b265bfe8982eb61d5347ef9945de314bfdf4ac0189c288ffb0b3", "price_changes":[{"asset_id":"17924629579804316786455515989238352689210911545477836576430679697715946894553", "price":"0.56", "size":"247.99", "side":"BUY", "hash":"4ea4919e6da8579d55ce46fe3a8ea0bd0ed7500a", "best_bid":"0.59", "best_ask":"0.6"}, {"asset_id":"12935926064588426924078449947177910958215776269411501731627440228801766632772", "price":"0.44", "size":"247.99", "side":"SELL", "hash":"39e584941b46964012ec31203b73b16b2c53e675", "best_bid":"0.4", "best_ask":"0.41"}], "timestamp":"1784449238732", "event_type":"price_change"}
{"market":"0xab772601f501b265bfe8982eb61d5347ef9945de314bfdf4ac0189c288ffb0b3", "price_changes":[{"asset_id":"17924629579804316786455515989238352689210911545477836576430679697715946894553", "price":"0.38", "size":"55", "side":"BUY", "hash":"2d94cf2c4905902a1ca059a3db9bfb7b29e01791", "best_bid":"0.59", "best_ask":"0.6"}, {"asset_id":"12935926064588426924078449947177910958215776269411501731627440228801766632772", "price":"0.62", "size":"55", "side":"SELL", "hash":"aef461e263afdc192996909e4c6d183b71b0cf47", "best_bid":"0.4", "best_ask":"0.41"}], "timestamp":"1784449238733", "event_type":"price_change"}
{"market":"0xab772601f501b265bfe8982eb61d5347ef9945de314bfdf4ac0189c288ffb0b3", "price_changes":[{"asset_id":"12935926064588426924078449947177910958215776269411501731627440228801766632772", "price":"0.01", "size":"14884.14", "side":"BUY", "hash":"673d43da93c0d7e15b708d1e1e093e7e2b810190", "best_bid":"0.4", "best_ask":"0.41"}, {"asset_id":"17924629579804316786455515989238352689210911545477836576430679697715946894553", "price":"0.99", "size":"14884.14", "side":"SELL", "hash":"5a7ed9ed23afbf3ccba1dfa90351130a99d07805", "best_bid":"0.59", "best_ask":"0.6"}], "timestamp":"1784449238735", "event_type":"price_change"}
{"market":"0xab772601f501b265bfe8982eb61d5347ef9945de314bfdf4ac0189c288ffb0b3", "price_changes":[{"asset_id":"17924629579804316786455515989238352689210911545477836576430679697715946894553", "price":"0.32", "size":"160.64", "side":"BUY", "hash":"f4aa4ade682980417c76cb71325fb263e3806e4a", "best_bid":"0.59", "best_ask":"0.6"}, {"asset_id":"12935926064588426924078449947177910958215776269411501731627440228801766632772", "price":"0.68", "size":"160.64", "side":"SELL", "hash":"e2dd5d494c3e28fb7fa4b5f7579f72f7f83f67e4", "best_bid":"0.4", "best_ask":"0.41"}], "timestamp":"1784449238739", "event_type":"price_change"}
{"market":"0xab772601f501b265bfe8982eb61d5347ef9945de314bfdf4ac0189c288ffb0b3", "price_changes":[{"asset_id":"17924629579804316786455515989238352689210911545477836576430679697715946894553", "price":"0.27", "size":"83.5", "side":"BUY", "hash":"52da70023c7f266c0b5c190031f8ff0dd6cae449", "best_bid":"0.59", "best_ask":"0.6"}, {"asset_id":"12935926064588426924078449947177910958215776269411501731627440228801766632772", "price":"0.73", "size":"83.5", "side":"SELL", "hash":"cc854674c1826304d3a83b6874ae4af6b0a081f8", "best_bid":"0.4", "best_ask":"0.41"}], "timestamp":"1784449238740", "event_type":"price_change"}
{"market":"0xab772601f501b265bfe8982eb61d5347ef9945de314bfdf4ac0189c288ffb0b3", "price_changes":[{"asset_id":"17924629579804316786455515989238352689210911545477836576430679697715946894553", "price":"0.01", "size":"12959.5", "side":"BUY", "hash":"5fec758eab9bf4c205d56057ea5794417309b4a2", "best_bid":"0.59", "best_ask":"0.6"}, {"asset_id":"12935926064588426924078449947177910958215776269411501731627440228801766632772", "price":"0.99", "size":"12959.5", "side":"SELL", "hash":"90eaa967bc721e04c72050aa84cf45ed829099c9", "best_bid":"0.4", "best_ask":"0.41"}], "timestamp":"1784449238746", "event_type":"price_change"}
{"market":"0xab772601f501b265bfe8982eb61d5347ef9945de314bfdf4ac0189c288ffb0b3", "price_changes":[{"asset_id":"12935926064588426924078449947177910958215776269411501731627440228801766632772", "price":"0.34", "size":"125.76", "side":"BUY", "hash":"dbe927fce78bbe570c146b7944d136496eb40ec3", "best_bid":"0.4", "best_ask":"0.41"}, {"asset_id":"17924629579804316786455515989238352689210911545477836576430679697715946894553", "price":"0.66", "size":"125.76", "side":"SELL", "hash":"59cdee0f7110c8d8d3ee973ebbbe54036be3bf44", "best_bid":"0.59", "best_ask":"0.6"}], "timestamp":"1784449238748", "event_type":"price_change"}
{"market":"0xab772601f501b265bfe8982eb61d5347ef9945de314bfdf4ac0189c288ffb0b3", "price_changes":[{"asset_id":"17924629579804316786455515989238352689210911545477836576430679697715946894553", "price":"0.56", "size":"252.99", "side":"BUY", "hash":"920cb08a4f4c0d005b60a03c6223e26693cdbe80", "best_bid":"0.59", "best_ask":"0.6"}, {"asset_id":"12935926064588426924078449947177910958215776269411501731627440228801766632772", "price":"0.44", "size":"252.99", "side":"SELL", "hash":"a1db2a986838526f7769c023cfd449f5a812c2f9", "best_bid":"0.4", "best_ask":"0.41"}], "timestamp":"1784449238749", "event_type":"price_change"}
{"market":"0xab772601f501b265bfe8982eb61d5347ef9945de314bfdf4ac0189c288ffb0b3", "price_changes":[{"asset_id":"17924629579804316786455515989238352689210911545477836576430679697715946894553", "price":"0.58", "size":"126.82", "side":"BUY", "hash":"04ba082b333d32a15ac050b12a2a84000e747533", "best_bid":"0.59", "best_ask":"0.6"}, {"asset_id":"12935926064588426924078449947177910958215776269411501731627440228801766632772", "price":"0.42", "size":"126.82", "side":"SELL", "hash":"9a94bc8f4b053be92cf98a1ffd64c0f7ef4d56a0", "best_bid":"0.4", "best_ask":"0.41"}], "timestamp":"1784449238750", "event_type":"price_change"}
{"market":"0xab772601f501b265bfe8982eb61d5347ef9945de314bfdf4ac0189c288ffb0b3", "price_changes":[{"asset_id":"17924629579804316786455515989238352689210911545477836576430679697715946894553", "price":"0.49", "size":"81", "side":"BUY", "hash":"b133d00a4df124ae53b77b64dc8a3a6b62e16d47", "best_bid":"0.59", "best_ask":"0.6"}, {"asset_id":"12935926064588426924078449947177910958215776269411501731627440228801766632772", "price":"0.51", "size":"81", "side":"SELL", "hash":"d4074e48c4c8a4af58672106e2d9c4f549862085", "best_bid":"0.4", "best_ask":"0.41"}], "timestamp":"1784449238751", "event_type":"price_change"}
{"market":"0xab772601f501b265bfe8982eb61d5347ef9945de314bfdf4ac0189c288ffb0b3", "asset_id":"12935926064588426924078449947177910958215776269411501731627440228801766632772", "price":"0.4", "size":"104", "fee_rate_bps":"0", "side":"BUY", "timestamp":"1784449238754", "event_type":"last_trade_price", "transaction_hash":"0xeca4f4af08bf448b43d74327148be21206fba0137732acb2e2027156cc4ee14c"}
{"market":"0xab772601f501b265bfe8982eb61d5347ef9945de314bfdf4ac0189c288ffb0b3", "price_changes":[{"asset_id":"17924629579804316786455515989238352689210911545477836576430679697715946894553", "price":"0.4", "size":"122.94", "side":"BUY", "hash":"5c1818fd951505d947761dc4e343298612bbd2eb", "best_bid":"0.59", "best_ask":"0.6"}, {"asset_id":"12935926064588426924078449947177910958215776269411501731627440228801766632772", "price":"0.6", "size":"122.94", "side":"SELL", "hash":"c3788d74a6f287165c9acdee57ce21fc7d1e021d", "best_bid":"0.4", "best_ask":"0.41"}], "timestamp":"1784449238757", "event_type":"price_change"}
{"market":"0xab772601f501b265bfe8982eb61d5347ef9945de314bfdf4ac0189c288ffb0b3", "price_changes":[{"asset_id":"12935926064588426924078449947177910958215776269411501731627440228801766632772", "price":"0.13", "size":"147.4", "side":"BUY", "hash":"40a58e25b3eb8331cb1f00257e028d14760fc594", "best_bid":"0.4", "best_ask":"0.41"}, {"asset_id":"17924629579804316786455515989238352689210911545477836576430679697715946894553", "price":"0.87", "size":"147.4", "side":"SELL", "hash":"eb694b514e29f16c2cb54a5a2e778f60bc1db891", "best_bid":"0.59", "best_ask":"0.6"}], "timestamp":"1784449238757", "event_type":"price_change"}
{"market":"0xab772601f501b265bfe8982eb61d5347ef9945de314bfdf4ac0189c288ffb0b3", "price_changes":[{"asset_id":"17924629579804316786455515989238352689210911545477836576430679697715946894553", "price":"0.01", "size":"12954.5", "side":"BUY", "hash":"37dcd144981cc3fc96e110d1f8f5a866f0fa28e4", "best_bid":"0.59", "best_ask":"0.6"}, {"asset_id":"12935926064588426924078449947177910958215776269411501731627440228801766632772", "price":"0.99", "size":"12954.5", "side":"SELL", "hash":"25c6509260ba3b23da3a6257a4c58867fc27da01", "best_bid":"0.4", "best_ask":"0.41"}], "timestamp":"1784449238768", "event_type":"price_change"}
{"market":"0xab772601f501b265bfe8982eb61d5347ef9945de314bfdf4ac0189c288ffb0b3", "price_changes":[{"asset_id":"17924629579804316786455515989238352689210911545477836576430679697715946894553", "price":"0.01", "size":"13054.5", "side":"BUY", "hash":"446f70189f55c5d74808c304fa2b858c5a06d620", "best_bid":"0.59", "best_ask":"0.6"}, {"asset_id":"12935926064588426924078449947177910958215776269411501731627440228801766632772", "price":"0.99", "size":"13054.5", "side":"SELL", "hash":"3d471dde2d53f82fe62fc6e49c9b0d04de4a882e", "best_bid":"0.4", "best_ask":"0.41"}], "timestamp":"1784449238778", "event_type":"price_change"}
{"market":"0xab772601f501b265bfe8982eb61d5347ef9945de314bfdf4ac0189c288ffb0b3", "price_changes":[{"asset_id":"17924629579804316786455515989238352689210911545477836576430679697715946894553", "price":"0.04", "size":"1270.1", "side":"BUY", "hash":"48bec197a079933e26483c27f2ab4b25aaffc373", "best_bid":"0.59", "best_ask":"0.6"}, {"asset_id":"12935926064588426924078449947177910958215776269411501731627440228801766632772", "price":"0.96", "size":"1270.1", "side":"SELL", "hash":"69d6cd809e08ff4fccc6b8dd05775b631a56d644", "best_bid":"0.4", "best_ask":"0.41"}], "timestamp":"1784449238779", "event_type":"price_change"}
{"market":"0xab772601f501b265bfe8982eb61d5347ef9945de314bfdf4ac0189c288ffb0b3", "price_changes":[{"asset_id":"12935926064588426924078449947177910958215776269411501731627440228801766632772", "price":"0.39", "size":"165.88", "side":"BUY", "hash":"be7140eaf94d4f3045b282c8347d87079dba9200", "best_bid":"0.4", "best_ask":"0.41"}, {"asset_id":"17924629579804316786455515989238352689210911545477836576430679697715946894553", "price":"0.61", "size":"165.88", "side":"SELL", "hash":"e1ca116b0b802fd82377f27a15c9a7948da5a15a", "best_bid":"0.59", "best_ask":"0.6"}], "timestamp":"1784449238781", "event_type":"price_change"}
{"market":"0xab772601f501b265bfe8982eb61d5347ef9945de314bfdf4ac0189c288ffb0b3", "price_changes":[{"asset_id":"17924629579804316786455515989238352689210911545477836576430679697715946894553", "price":"0.49", "size":"99.14", "side":"BUY", "hash":"a6b112100d74e1d35a48606049373aa590d7bc07", "best_bid":"0.59", "best_ask":"0.6"}, {"asset_id":"12935926064588426924078449947177910958215776269411501731627440228801766632772", "price":"0.51", "size":"99.14", "side":"SELL", "hash":"c5147e0700a2808e62e8921be5aa179b84b054fd", "best_bid":"0.4", "best_ask":"0.41"}], "timestamp":"1784449238785", "event_type":"price_change"}
{"market":"0xab772601f501b265bfe8982eb61d5347ef9945de314bfdf4ac0189c288ffb0b3", "price_changes":[{"asset_id":"12935926064588426924078449947177910958215776269411501731627440228801766632772", "price":"0.23", "size":"165.8", "side":"BUY", "hash":"c66d14e4bd2c047dacf3cb52d6942ee1f853faf7", "best_bid":"0.4", "best_ask":"0.41"}, {"asset_id":"17924629579804316786455515989238352689210911545477836576430679697715946894553", "price":"0.77", "size":"165.8", "side":"SELL", "hash":"7742f1faaaf9e58e682ead23dc6b90b8a7fea56c", "best_bid":"0.59", "best_ask":"0.6"}], "timestamp":"1784449238786", "event_type":"price_change"}
{"market":"0xab772601f501b265bfe8982eb61d5347ef9945de314bfdf4ac0189c288ffb0b3", "price_changes":[{"asset_id":"17924629579804316786455515989238352689210911545477836576430679697715946894553", "price":"0.41", "size":"100.5", "side":"BUY", "hash":"4cbaec956bdd6c9d3d4296b6c616b11cc41c904f", "best_bid":"0.59", "best_ask":"0.6"}, {"asset_id":"12935926064588426924078449947177910958215776269411501731627440228801766632772", "price":"0.59", "size":"100.5", "side":"SELL", "hash":"4f3a904574dc3982954d191c5c25fb498088f2b8", "best_bid":"0.4", "best_ask":"0.41"}], "timestamp":"1784449238787", "event_type":"price_change"}
{"market":"0xab772601f501b265bfe8982eb61d5347ef9945de314bfdf4ac0189c288ffb0b3", "price_changes":[{"asset_id":"17924629579804316786455515989238352689210911545477836576430679697715946894553", "price":"0.49", "size":"81", "side":"BUY", "hash":"792d22d8c4267ffe66cb53932f939df0e2f3aa00", "best_bid":"0.59", "best_ask":"0.6"}, {"asset_id":"12935926064588426924078449947177910958215776269411501731627440228801766632772", "price":"0.51", "size":"81", "side":"SELL", "hash":"ed3e7457102fe607f5d76630d6a732c1ce35850b", "best_bid":"0.4", "best_ask":"0.41"}], "timestamp":"1784449238791", "event_type":"price_change"}
{"market":"0xab772601f501b265bfe8982eb61d5347ef9945de314bfdf4ac0189c288ffb0b3", "price_changes":[{"asset_id":"17924629579804316786455515989238352689210911545477836576430679697715946894553", "price":"0.01", "size":"13060.5", "side":"BUY", "hash":"77e0d8dd80dd429f01fa051536c9451a06ebe8e2", "best_bid":"0.59", "best_ask":"0.6"}, {"asset_id":"12935926064588426924078449947177910958215776269411501731627440228801766632772", "price":"0.99", "size":"13060.5", "side":"SELL", "hash":"f0eef7fa301e37f2e9ea0dcac65a4cafd3003dce", "best_bid":"0.4", "best_ask":"0.41"}], "timestamp":"1784449238799", "event_type":"price_change"}
{"market":"0xab772601f501b265bfe8982eb61d5347ef9945de314bfdf4ac0189c288ffb0b3", "price_changes":[{"asset_id":"17924629579804316786455515989238352689210911545477836576430679697715946894553", "price":"0.01", "size":"12960.5", "side":"BUY", "hash":"139a3b84c579840ddc06cfe3640f8c2fbcf3f1dd", "best_bid":"0.59", "best_ask":"0.6"}, {"asset_id":"12935926064588426924078449947177910958215776269411501731627440228801766632772", "price":"0.99", "size":"12960.5", "side":"SELL", "hash":"e28daad282d3f7434fe0735a0b284186e915e498", "best_bid":"0.4", "best_ask":"0.41"}], "timestamp":"1784449238810", "event_type":"price_change"}
{"market":"0xab772601f501b265bfe8982eb61d5347ef9945de314bfdf4ac0189c288ffb0b3", "price_changes":[{"asset_id":"17924629579804316786455515989238352689210911545477836576430679697715946894553", "price":"0.01", "size":"12955.5", "side":"BUY", "hash":"d05728a0d3d868e29595a50238d703521642eeb2", "best_bid":"0.59", "best_ask":"0.6"}, {"asset_id":"12935926064588426924078449947177910958215776269411501731627440228801766632772", "price":"0.99", "size":"12955.5", "side":"SELL", "hash":"a508aa1b9a7f267ec1b23ff3201568bad62e251c", "best_bid":"0.4", "best_ask":"0.41"}], "timestamp":"1784449238816", "event_type":"price_change"}
{"market":"0xab772601f501b265bfe8982eb61d5347ef9945de314bfdf4ac0189c288ffb0b3", "price_changes":[{"asset_id":"17924629579804316786455515989238352689210911545477836576430679697715946894553", "price":"0.49", "size":"99.14", "side":"BUY", "hash":"ad7fcdf133a8c107c83f7a78ad86a169cbd082c4", "best_bid":"0.59", "best_ask":"0.6"}, {"asset_id":"12935926064588426924078449947177910958215776269411501731627440228801766632772", "price":"0.51", "size":"99.14", "side":"SELL", "hash":"2b7262af03c4940954107ff3dd4fd2318de09310", "best_bid":"0.4", "best_ask":"0.41"}], "timestamp":"1784449238818", "event_type":"price_change"}
{"market":"0xab772601f501b265bfe8982eb61d5347ef9945de314bfdf4ac0189c288ffb0b3", "price_changes":[{"asset_id":"17924629579804316786455515989238352689210911545477836576430679697715946894553", "price":"0.01", "size":"12950.5", "side":"BUY", "hash":"7c812c40681ae1cd3e5c5276648d47273e744841", "best_bid":"0.59", "best_ask":"0.6"}, {"asset_id":"12935926064588426924078449947177910958215776269411501731627440228801766632772", "price":"0.99", "size":"12950.5", "side":"SELL", "hash":"197036d6faf6592ae4bcbc8c652a422bbfbbf3c3", "best_bid":"0.4", "best_ask":"0.41"}], "timestamp":"1784449238820", "event_type":"price_change"}
{"market":"0xab772601f501b265bfe8982eb61d5347ef9945de314bfdf4ac0189c288ffb0b3", "price_changes":[{"asset_id":"17924629579804316786455515989238352689210911545477836576430679697715946894553", "price":"0.53", "size":"560.7", "side":"BUY", "hash":"89e9e0b2d00276dcf61714b3c086d91fa1230b1d", "best_bid":"0.59", "best_ask":"0.6"}, {"asset_id":"12935926064588426924078449947177910958215776269411501731627440228801766632772", "price":"0.47", "size":"560.7", "side":"SELL", "hash":"92224b50b7c7686c1964f6aade4fdbda3b06038a", "best_bid":"0.4", "best_ask":"0.41"}], "timestamp":"1784449238820", "event_type":"price_change"}
{"market":"0xab772601f501b265bfe8982eb61d5347ef9945de314bfdf4ac0189c288ffb0b3", "price_changes":[{"asset_id":"17924629579804316786455515989238352689210911545477836576430679697715946894553", "price":"0.01", "size":"12955.5", "side":"BUY", "hash":"545389936787c8e9f6ed604f30927743e35b1b5d", "best_bid":"0.59", "best_ask":"0.6"}, {"asset_id":"12935926064588426924078449947177910958215776269411501731627440228801766632772", "price":"0.99", "size":"12955.5", "side":"SELL", "hash":"f667e469a7a3c6a670f5d07a228508a9cdddaec7", "best_bid":"0.4", "best_ask":"0.41"}], "timestamp":"1784449238822", "event_type":"price_change"}
{"market":"0xab772601f501b265bfe8982eb61d5347ef9945de314bfdf4ac0189c288ffb0b3", "price_changes":[{"asset_id":"17924629579804316786455515989238352689210911545477836576430679697715946894553", "price":"0.01", "size":"12960.5", "side":"BUY", "hash":"fed9ebe784f1f4efce7785af74c21024c1bee5dc", "best_bid":"0.59", "best_ask":"0.6"}, {"asset_id":"12935926064588426924078449947177910958215776269411501731627440228801766632772", "price":"0.99", "size":"12960.5", "side":"SELL", "hash":"b873031834796c964d77eb738d610683fbf2586c", "best_bid":"0.4", "best_ask":"0.41"}], "timestamp":"1784449238825", "event_type":"price_change"}
{"market":"0xab772601f501b265bfe8982eb61d5347ef9945de314bfdf4ac0189c288ffb0b3", "price_changes":[{"asset_id":"17924629579804316786455515989238352689210911545477836576430679697715946894553", "price":"0.01", "size":"12955.5", "side":"BUY", "hash":"2eabb48698f9297123dc0e391f9e263f142c02f6", "best_bid":"0.59", "best_ask":"0.6"}, {"asset_id":"12935926064588426924078449947177910958215776269411501731627440228801766632772", "price":"0.99", "size":"12955.5", "side":"SELL", "hash":"764b3a2e38057e4ae3845b3be1070f5a3e92c3b7", "best_bid":"0.4", "best_ask":"0.41"}], "timestamp":"1784449238826", "event_type":"price_change"}
{"market":"0xab772601f501b265bfe8982eb61d5347ef9945de314bfdf4ac0189c288ffb0b3", "price_changes":[{"asset_id":"17924629579804316786455515989238352689210911545477836576430679697715946894553", "price":"0.01", "size":"12960.5", "side":"BUY", "hash":"36e517af71241b6e60f37e52ba2072e7958439aa", "best_bid":"0.59", "best_ask":"0.6"}, {"asset_id":"12935926064588426924078449947177910958215776269411501731627440228801766632772", "price":"0.99", "size":"12960.5", "side":"SELL", "hash":"9d7ffcb51bef8591492c7f8350a8bc93499b7ec9", "best_bid":"0.4", "best_ask":"0.41"}], "timestamp":"1784449238828", "event_type":"price_change"}
{"market":"0xab772601f501b265bfe8982eb61d5347ef9945de314bfdf4ac0189c288ffb0b3", "price_changes":[{"asset_id":"17924629579804316786455515989238352689210911545477836576430679697715946894553", "price":"0.01", "size":"12954.5", "side":"BUY", "hash":"c0c2712fa36c9a7aee5248ee760c7b2a6409dee1", "best_bid":"0.59", "best_ask":"0.6"}, {"asset_id":"12935926064588426924078449947177910958215776269411501731627440228801766632772", "price":"0.99", "size":"12954.5", "side":"SELL", "hash":"846ca07d9b45a3659bdd34e962d32937cbdb030a", "best_bid":"0.4", "best_ask":"0.41"}], "timestamp":"1784449238830", "event_type":"price_change"}
{"market":"0xab772601f501b265bfe8982eb61d5347ef9945de314bfdf4ac0189c288ffb0b3", "price_changes":[{"asset_id":"17924629579804316786455515989238352689210911545477836576430679697715946894553", "price":"0.5", "size":"119.39", "side":"BUY", "hash":"bd1940f945407d3f49bfde4fdd14e9a1ad41819a", "best_bid":"0.59", "best_ask":"0.6"}, {"asset_id":"12935926064588426924078449947177910958215776269411501731627440228801766632772", "price":"0.5", "size":"119.39", "side":"SELL", "hash":"aa01ddb095d1acd5df699103ee4ffff56c987e91", "best_bid":"0.4", "best_ask":"0.41"}], "timestamp":"1784449238832", "event_type":"price_change"}
{"market":"0xab772601f501b265bfe8982eb61d5347ef9945de314bfdf4ac0189c288ffb0b3", "price_changes":[{"asset_id":"17924629579804316786455515989238352689210911545477836576430679697715946894553", "price":"0.59", "size":"132.72", "side":"BUY", "hash":"abb58b7f904a68b23faf72754048c3255f603977", "best_bid":"0.59", "best_ask":"0.6"}, {"asset_id":"12935926064588426924078449947177910958215776269411501731627440228801766632772", "price":"0.41", "size":"132.72", "side":"SELL", "hash":"64b53fa3a809e88a67ae1406157326c284ee3553", "best_bid":"0.4", "best_ask":"0.41"}], "timestamp":"1784449238832", "event_type":"price_change"}
{"market":"0xab772601f501b265bfe8982eb61d5347ef9945de314bfdf4ac0189c288ffb0b3", "asset_id":"12935926064588426924078449947177910958215776269411501731627440228801766632772", "bids":[{"price":"0.01", "size":"14884.14"}, {"price":"0.02", "size":"3964.52"}, {"price":"0.03", "size":"2179.29"}, {"price":"0.04", "size":"1215.1"}, {"price":"0.05", "size":"1752.19"}, {"price":"0.06", "size":"1122.02"}, {"price":"0.07", "size":"953.49"}, {"price":"0.08", "size":"1234.38"}, {"price":"0.09", "size":"791.7"}, {"price":"0.1", "size":"561.2"}, {"price":"0.11", "size":"1502.1"}, {"price":"0.12", "size":"1112.05"}, {"price":"0.13", "size":"147.4"}, {"price":"0.14", "size":"166.8"}, {"price":"0.15", "size":"444.04"}, {"price":"0.16", "size":"247.1"}, {"price":"0.17", "size":"207.17"}, {"price":"0.18", "size":"150.7"}, {"price":"0.19", "size":"103.89"}, {"price":"0.2", "size":"246.2"}, {"price":"0.21", "size":"636.8"}, {"price":"0.22", "size":"115.5"}, {"price":"0.23", "size":"165.8"}, {"price":"0.24", "size":"152.22"}, {"price":"0.25", "size":"127.2"}, {"price":"0.26", "size":"134.3"}, {"price":"0.27", "size":"148.5"}, {"price":"0.28", "size":"146.77"}, {"price":"0.29", "size":"216.99"}, {"price":"0.3", "size":"202.81"}, {"price":"0.31", "size":"554.58"}, {"price":"0.32", "size":"241.69"}, {"price":"0.33", "size":"144.65"}, {"price":"0.34", "size":"125.76"}, {"price":"0.35", "size":"122.8"}, {"price":"0.36", "size":"185.77"}, {"price":"0.37", "size":"175.91"}, {"price":"0.38", "size":"356.23"}, {"price":"0.39", "size":"165.88"}, {"price":"0.4", "size":"120.61"}], "asks":[{"price":"0.99", "size":"12954.5"}, {"price":"0.98", "size":"3885.25"}, {"price":"0.97", "size":"2250.95"}, {"price":"0.96", "size":"1270.1"}, {"price":"0.95", "size":"1753.6"}, {"price":"0.94", "size":"1109.35"}, {"price":"0.93", "size":"944.2"}, {"price":"0.92", "size":"1225.88"}, {"price":"0.91", "size":"796.7"}, {"price":"0.9", "size":"365.2"}, {"price":"0.89", "size":"1502.1"}, {"price":"0.88", "size":"195.05"}, {"price":"0.87", "size":"147.4"}, {"price":"0.86", "size":"183.4"}, {"price":"0.85", "size":"469.43"}, {"price":"0.84", "size":"127.1"}, {"price":"0.83", "size":"107.69"}, {"price":"0.82", "size":"125.7"}, {"price":"0.81", "size":"98.89"}, {"price":"0.8", "size":"206.2"}, {"price":"0.79", "size":"616.8"}, {"price":"0.78", "size":"992.5"}, {"price":"0.77", "size":"82.3"}, {"price":"0.76", "size":"118.03"}, {"price":"0.75", "size":"92.2"}, {"price":"0.74", "size":"90.3"}, {"price":"0.73", "size":"83.5"}, {"price":"0.72", "size":"79.87"}, {"price":"0.71", "size":"74.39"}, {"price":"0.7", "size":"83"}, {"price":"0.69", "size":"89.7"}, {"price":"0.68", "size":"160.64"}, {"price":"0.67", "size":"113.1"}, {"price":"0.66", "size":"92.8"}, {"price":"0.65", "size":"184.6"}, {"price":"0.64", "size":"104.39"}, {"price":"0.63", "size":"94.2"}, {"price":"0.62", "size":"55"}, {"price":"0.61", "size":"69.8"}, {"price":"0.6", "size":"122.94"}, {"price":"0.59", "size":"100.5"}, {"price":"0.58", "size":"86.02"}, {"price":"0.57", "size":"75.3"}, {"price":"0.56", "size":"64.2"}, {"price":"0.55", "size":"204.71"}, {"price":"0.54", "size":"102.1"}, {"price":"0.53", "size":"72.1"}, {"price":"0.52", "size":"71"}, {"price":"0.51", "size":"99.14"}, {"price":"0.5", "size":"119.39"}, {"price":"0.49", "size":"425.92"}, {"price":"0.48", "size":"235.91"}, {"price":"0.47", "size":"560.7"}, {"price":"0.46", "size":"135.85"}, {"price":"0.45", "size":"221.69"}, {"price":"0.44", "size":"252.99"}, {"price":"0.43", "size":"130"}, {"price":"0.42", "size":"126.82"}, {"price":"0.41", "size":"132.72"}], "hash":"64b53fa3a809e88a67ae1406157326c284ee3553", "timestamp":"1784449238832", "event_type":"book"}
{"market":"0xab772601f501b265bfe8982eb61d5347ef9945de314bfdf4ac0189c288ffb0b3", "asset_id":"17924629579804316786455515989238352689210911545477836576430679697715946894553", "bids":[{"price":"0.01", "size":"12954.5"}, {"price":"0.02", "size":"3885.25"}, {"price":"0.03", "size":"2250.95"}, {"price":"0.04", "size":"1270.1"}, {"price":"0.05", "size":"1753.6"}, {"price":"0.06", "size":"1109.35"}, {"price":"0.07", "size":"944.2"}, {"price":"0.08", "size":"1225.88"}, {"price":"0.09", "size":"796.7"}, {"price":"0.1", "size":"365.2"}, {"price":"0.11", "size":"1502.1"}, {"price":"0.12", "size":"195.05"}, {"price":"0.13", "size":"147.4"}, {"price":"0.14", "size":"183.4"}, {"price":"0.15", "size":"469.43"}, {"price":"0.16", "size":"127.1"}, {"price":"0.17", "size":"107.69"}, {"price":"0.18", "size":"125.7"}, {"price":"0.19", "size":"98.89"}, {"price":"0.2", "size":"206.2"}, {"price":"0.21", "size":"616.8"}, {"price":"0.22", "size":"992.5"}, {"price":"0.23", "size":"82.3"}, {"price":"0.24", "size":"118.03"}, {"price":"0.25", "size":"92.2"}, {"price":"0.26", "size":"90.3"}, {"price":"0.27", "size":"83.5"}, {"price":"0.28", "size":"79.87"}, {"price":"0.29", "size":"74.39"}, {"price":"0.3", "size":"83"}, {"price":"0.31", "size":"89.7"}, {"price":"0.32", "size":"160.64"}, {"price":"0.33", "size":"113.1"}, {"price":"0.34", "size":"92.8"}, {"price":"0.35", "size":"184.6"}, {"price":"0.36", "size":"104.39"}, {"price":"0.37", "size":"94.2"}, {"price":"0.38", "size":"55"}, {"price":"0.39", "size":"69.8"}, {"price":"0.4", "size":"122.94"}, {"price":"0.41", "size":"100.5"}, {"price":"0.42", "size":"86.02"}, {"price":"0.43", "size":"75.3"}, {"price":"0.44", "size":"64.2"}, {"price":"0.45", "size":"204.71"}, {"price":"0.46", "size":"102.1"}, {"price":"0.47", "size":"72.1"}, {"price":"0.48", "size":"71"}, {"price":"0.49", "size":"99.14"}, {"price":"0.5", "size":"119.39"}, {"price":"0.51", "size":"425.92"}, {"price":"0.52", "size":"235.91"}, {"price":"0.53", "size":"560.7"}, {"price":"0.54", "size":"135.85"}, {"price":"0.55", "size":"221.69"}, {"price":"0.56", "size":"252.99"}, {"price":"0.57", "size":"130"}, {"price":"0.58", "size":"126.82"}, {"price":"0.59", "size":"132.72"}], "asks":[{"price":"0.99", "size":"14884.14"}, {"price":"0.98", "size":"3964.52"}, {"price":"0.97", "size":"2179.29"}, {"price":"0.96", "size":"1215.1"}, {"price":"0.95", "size":"1752.19"}, {"price":"0.94", "size":"1122.02"}, {"price":"0.93", "size":"953.49"}, {"price":"0.92", "size":"1234.38"}, {"price":"0.91", "size":"791.7"}, {"price":"0.9", "size":"561.2"}, {"price":"0.89", "size":"1502.1"}, {"price":"0.88", "size":"1112.05"}, {"price":"0.87", "size":"147.4"}, {"price":"0.86", "size":"166.8"}, {"price":"0.85", "size":"444.04"}, {"price":"0.84", "size":"247.1"}, {"price":"0.83", "size":"207.17"}, {"price":"0.82", "size":"150.7"}, {"price":"0.81", "size":"103.89"}, {"price":"0.8", "size":"246.2"}, {"price":"0.79", "size":"636.8"}, {"price":"0.78", "size":"115.5"}, {"price":"0.77", "size":"165.8"}, {"price":"0.76", "size":"152.22"}, {"price":"0.75", "size":"127.2"}, {"price":"0.74", "size":"134.3"}, {"price":"0.73", "size":"148.5"}, {"price":"0.72", "size":"146.77"}, {"price":"0.71", "size":"216.99"}, {"price":"0.7", "size":"202.81"}, {"price":"0.69", "size":"554.58"}, {"price":"0.68", "size":"241.69"}, {"price":"0.67", "size":"144.65"}, {"price":"0.66", "size":"125.76"}, {"price":"0.65", "size":"122.8"}, {"price":"0.64", "size":"185.77"}, {"price":"0.63", "size":"175.91"}, {"price":"0.62", "size":"356.23"}, {"price":"0.61", "size":"165.88"}, {"price":"0.6", "size":"120.61"}], "hash":"abb58b7f904a68b23faf72754048c3255f603977", "timestamp":"1784449238832", "event_type":"book"}
{"market":"0xab772601f501b265bfe8982eb61d5347ef9945de314bfdf4ac0189c288ffb0b3", "price_changes":[{"asset_id":"17924629579804316786455515989238352689210911545477836576430679697715946894553", "price":"0.01", "size":"12959.5", "side":"BUY", "hash":"82f33d5f0d8ac0f2754cd973ddeffb0a6a60fb84", "best_bid":"0.59", "best_ask":"0.6"}, {"asset_id":"12935926064588426924078449947177910958215776269411501731627440228801766632772", "price":"0.99", "size":"12959.5", "side":"SELL", "hash":"109ede52abf0b2f0a9d50f30b17284cc62232ddf", "best_bid":"0.4", "best_ask":"0.41"}], "timestamp":"1784449238836", "event_type":"price_change"}
{"market":"0xab772601f501b265bfe8982eb61d5347ef9945de314bfdf4ac0189c288ffb0b3", "price_changes":[{"asset_id":"17924629579804316786455515989238352689210911545477836576430679697715946894553", "price":"0.58", "size":"136.82", "side":"BUY", "hash":"b5419bd028b98ad4e45c76ab63bcc0d2a9282df5", "best_bid":"0.59", "best_ask":"0.6"}, {"asset_id":"12935926064588426924078449947177910958215776269411501731627440228801766632772", "price":"0.42", "size":"136.82", "side":"SELL", "hash":"61d5a77d2b71cf28ec132639e6d97ddf8d63668c", "best_bid":"0.4", "best_ask":"0.41"}], "timestamp":"1784449238841", "event_type":"price_change"}
{"market":"0xab772601f501b265bfe8982eb61d5347ef9945de314bfdf4ac0189c288ffb0b3", "price_changes":[{"asset_id":"17924629579804316786455515989238352689210911545477836576430679697715946894553", "price":"0.01", "size":"12954.5", "side":"BUY", "hash":"747ca8589955a69583e903f7e73f363605c0cd3a", "best_bid":"0.59", "best_ask":"0.6"}, {"asset_id":"12935926064588426924078449947177910958215776269411501731627440228801766632772", "price":"0.99", "size":"12954.5", "side":"SELL", "hash":"56edaef164913d67c17340abe67530e2928ad017", "best_bid":"0.4", "best_ask":"0.41"}], "timestamp":"1784449238847", "event_type":"price_change"}
{"market":"0xab772601f501b265bfe8982eb61d5347ef9945de314bfdf4ac0189c288ffb0b3", "price_changes":[{"asset_id":"12935926064588426924078449947177910958215776269411501731627440228801766632772", "price":"0.4", "size":"115.61", "side":"BUY", "hash":"f24fdf36b349096dafa5b1b09ad0eae3ca9af97c", "best_bid":"0.4", "best_ask":"0.41"}, {"asset_id":"17924629579804316786455515989238352689210911545477836576430679697715946894553", "price":"0.6", "size":"115.61", "side":"SELL", "hash":"a3bcb984f19bc86da3bfbab5ebd449543719e335", "best_bid":"0.59", "best_ask":"0.6"}], "timestamp":"1784449238850", "event_type":"price_change"}
{"market":"0xab772601f501b265bfe8982eb61d5347ef9945de314bfdf4ac0189c288ffb0b3", "price_changes":[{"asset_id":"17924629579804316786455515989238352689210911545477836576430679697715946894553", "price":"0.01", "size":"13054.5", "side":"BUY", "hash":"fc6c8969a0ccc505a129cd552323d7153a5c7d4f", "best_bid":"0.59", "best_ask":"0.6"}, {"asset_id":"12935926064588426924078449947177910958215776269411501731627440228801766632772", "price":"0.99", "size":"13054.5", "side":"SELL", "hash":"fbf95f4b79017d56e1b673111ff3377d123b6400", "best_bid":"0.4", "best_ask":"0.41"}], "timestamp":"1784449238855", "event_type":"price_change"}
{"market":"0xab772601f501b265bfe8982eb61d5347ef9945de314bfdf4ac0189c288ffb0b3", "price_changes":[{"asset_id":"17924629579804316786455515989238352689210911545477836576430679697715946894553", "price":"0.04", "size":"1275.1", "side":"BUY", "hash":"f6463cd4c2be26c1a0eba0498321565f86769628", "best_bid":"0.59", "best_ask":"0.6"}, {"asset_id":"12935926064588426924078449947177910958215776269411501731627440228801766632772", "price":"0.96", "size":"1275.1", "side":"SELL", "hash":"d8036dacb62d46d30ab25ff9dd81e26a7152cb73", "best_bid":"0.4", "best_ask":"0.41"}], "timestamp":"1784449238858", "event_type":"price_change"}
{"market":"0xab772601f501b265bfe8982eb61d5347ef9945de314bfdf4ac0189c288ffb0b3", "price_changes":[{"asset_id":"17924629579804316786455515989238352689210911545477836576430679697715946894553", "price":"0.01", "size":"13059.51", "side":"BUY", "hash":"4f1ff49ccd6a9b4af972cec01ae96c0cd4bb3412", "best_bid":"0.59", "best_ask":"0.6"}, {"asset_id":"12935926064588426924078449947177910958215776269411501731627440228801766632772", "price":"0.99", "size":"13059.51", "side":"SELL", "hash":"1256b5f1f223079758c7466f5e6a16eef9863480", "best_bid":"0.4", "best_ask":"0.41"}], "timestamp":"1784449238862", "event_type":"price_change"}
{"market":"0xab772601f501b265bfe8982eb61d5347ef9945de314bfdf4ac0189c288ffb0b3", "price_changes":[{"asset_id":"17924629579804316786455515989238352689210911545477836576430679697715946894553", "price":"0.49", "size":"81", "side":"BUY", "hash":"cca9b07dc9e7749434ea6101a9723475b02c68bb", "best_bid":"0.59", "best_ask":"0.6"}, {"asset_id":"12935926064588426924078449947177910958215776269411501731627440228801766632772", "price":"0.51", "size":"81", "side":"SELL", "hash":"324b375b98cf62890f1c2b5383c3cce366de4202", "best_bid":"0.4", "best_ask":"0.41"}], "timestamp":"1784449238875", "event_type":"price_change"}
{"market":"0xab772601f501b265bfe8982eb61d5347ef9945de314bfdf4ac0189c288ffb0b3", "price_changes":[{"asset_id":"12935926064588426924078449947177910958215776269411501731627440228801766632772", "price":"0.37", "size":"170.91", "side":"BUY", "hash":"b06ef7ccb2eeacadbcb3759332a3dab157c97c32", "best_bid":"0.4", "best_ask":"0.41"}, {"asset_id":"17924629579804316786455515989238352689210911545477836576430679697715946894553", "price":"0.63", "size":"170.91", "side":"SELL", "hash":"ce4abdcb2a891021fc187caa6b7cf4b410f2c58c", "best_bid":"0.59", "best_ask":"0.6"}], "timestamp":"1784449238877", "event_type":"price_change"}
{"market":"0xab772601f501b265bfe8982eb61d5347ef9945de314bfdf4ac0189c288ffb0b3", "price_changes":[{"asset_id":"17924629579804316786455515989238352689210911545477836576430679697715946894553", "price":"0.59", "size":"127.72", "side":"BUY", "hash":"68e9e04c42929b7779a8053e20bc5a1e23290f40", "best_bid":"0.59", "best_ask":"0.6"}, {"asset_id":"12935926064588426924078449947177910958215776269411501731627440228801766632772", "price":"0.41", "size":"127.72", "side":"SELL", "hash":"03e760795c1620d13ae242a249ae731ce3ff6896", "best_bid":"0.4", "best_ask":"0.41"}], "timestamp":"1784449238877", "event_type":"price_change"}
{"market":"0xab772601f501b265bfe8982eb61d5347ef9945de314bfdf4ac0189c288ffb0b3", "price_changes":[{"asset_id":"12935926064588426924078449947177910958215776269411501731627440228801766632772", "price":"0.5", "size":"129.39", "side":"SELL", "hash":"bcbaa44305f4b34ffe9ace3bc5612e15fda1fc96", "best_bid":"0.4", "best_ask":"0.41"}, {"asset_id":"17924629579804316786455515989238352689210911545477836576430679697715946894553", "price":"0.5", "size":"129.39", "side":"BUY", "hash":"ca78a135e2268c523980bbd79a3edc4c55c5dfac", "best_bid":"0.59", "best_ask":"0.6"}], "timestamp":"1784449238878", "event_type":"price_change"}
{"market":"0xab772601f501b265bfe8982eb61d5347ef9945de314bfdf4ac0189c288ffb0b3", "price_changes":[{"asset_id":"17924629579804316786455515989238352689210911545477836576430679697715946894553", "price":"0.01", "size":"13064.51", "side":"BUY", "hash":"d797cf4ad9f5318106befdc46ca36610380eacd7", "best_bid":"0.59", "best_ask":"0.6"}, {"asset_id":"12935926064588426924078449947177910958215776269411501731627440228801766632772", "price":"0.99", "size":"13064.51", "side":"SELL", "hash":"6df11562281174231347be903aaa52ce708253a8", "best_bid":"0.4", "best_ask":"0.41"}], "timestamp":"1784449238888", "event_type":"price_change"}
{"market":"0xab772601f501b265bfe8982eb61d5347ef9945de314bfdf4ac0189c288ffb0b3", "price_changes":[{"asset_id":"17924629579804316786455515989238352689210911545477836576430679697715946894553", "price":"0.01", "size":"13069.51", "side":"BUY", "hash":"f1a60f0083165abd82ed36653aab7d0bff1df228", "best_bid":"0.59", "best_ask":"0.6"}, {"asset_id":"12935926064588426924078449947177910958215776269411501731627440228801766632772", "price":"0.99", "size":"13069.51", "side":"SELL", "hash":"5f7ed2f9811bec39b2996f6ddb5813d0d5d437a3", "best_bid":"0.4", "best_ask":"0.41"}], "timestamp":"1784449238889", "event_type":"price_change"}
{"market":"0xab772601f501b265bfe8982eb61d5347ef9945de314bfdf4ac0189c288ffb0b3", "price_changes":[{"asset_id":"17924629579804316786455515989238352689210911545477836576430679697715946894553", "price":"0.01", "size":"13064.5", "side":"BUY", "hash":"07e7e62b30dee855148d3e53e461877fa6d19303", "best_bid":"0.59", "best_ask":"0.6"}, {"asset_id":"12935926064588426924078449947177910958215776269411501731627440228801766632772", "price":"0.99", "size":"13064.5", "side":"SELL", "hash":"83092add6c4240e80ca89f7fdd53f67136531e4e", "best_bid":"0.4", "best_ask":"0.41"}], "timestamp":"1784449238889", "event_type":"price_change"}
{"market":"0xab772601f501b265bfe8982eb61d5347ef9945de314bfdf4ac0189c288ffb0b3", "price_changes":[{"asset_id":"12935926064588426924078449947177910958215776269411501731627440228801766632772", "price":"0.01", "size":"14889.14", "side":"BUY", "hash":"e45ff2dba73e5e62fdfafd281debc160a38d2bde", "best_bid":"0.4", "best_ask":"0.41"}, {"asset_id":"17924629579804316786455515989238352689210911545477836576430679697715946894553", "price":"0.99", "size":"14889.14", "side":"SELL", "hash":"2b8f48e311ad93ab2a54465d7360c6f5b9cd6ff2", "best_bid":"0.59", "best_ask":"0.6"}], "timestamp":"1784449238890", "event_type":"price_change"}
{"market":"0xab772601f501b265bfe8982eb61d5347ef9945de314bfdf4ac0189c288ffb0b3", "price_changes":[{"asset_id":"12935926064588426924078449947177910958215776269411501731627440228801766632772", "price":"0.01", "size":"14894.14", "side":"BUY", "hash":"c5c2a15c63077f461d507f4aece221d182879e78", "best_bid":"0.4", "best_ask":"0.41"}, {"asset_id":"17924629579804316786455515989238352689210911545477836576430679697715946894553", "price":"0.99", "size":"14894.14", "side":"SELL", "hash":"f425876dcbfbfc5396629bd21d9d8aebe8c0b726", "best_bid":"0.59", "best_ask":"0.6"}], "timestamp":"1784449238891", "event_type":"price_change"}
{"market":"0xab772601f501b265bfe8982eb61d5347ef9945de314bfdf4ac0189c288ffb0b3", "price_changes":[{"asset_id":"17924629579804316786455515989238352689210911545477836576430679697715946894553", "price":"0.01", "size":"12964.5", "side":"BUY", "hash":"a5fe79f1fa534b54e21f8aeafa3cf91a1d7e1a50", "best_bid":"0.59", "best_ask":"0.6"}, {"asset_id":"12935926064588426924078449947177910958215776269411501731627440228801766632772", "price":"0.99", "size":"12964.5", "side":"SELL", "hash":"7e958a3e7d582ac8e341a1c0061daa3ca53c31f6", "best_bid":"0.4", "best_ask":"0.41"}], "timestamp":"1784449238891", "event_type":"price_change"}
{"market":"0xab772601f501b265bfe8982eb61d5347ef9945de314bfdf4ac0189c288ffb0b3", "price_changes":[{"asset_id":"17924629579804316786455515989238352689210911545477836576430679697715946894553", "price":"0.01", "size":"12969.5", "side":"BUY", "hash":"88194b11ed91c7b66827927bfe1af51c6ffa89b2", "best_bid":"0.59", "best_ask":"0.6"}, {"asset_id":"12935926064588426924078449947177910958215776269411501731627440228801766632772", "price":"0.99", "size":"12969.5", "side":"SELL", "hash":"c7de96a64bcf0bd26e9da1d242bb5a14da2b3725", "best_bid":"0.4", "best_ask":"0.41"}], "timestamp":"1784449238892", "event_type":"price_change"}
{"market":"0xab772601f501b265bfe8982eb61d5347ef9945de314bfdf4ac0189c288ffb0b3", "price_changes":[{"asset_id":"12935926064588426924078449947177910958215776269411501731627440228801766632772", "price":"0.01", "size":"14899.14", "side":"BUY", "hash":"7fe437bb6d62bf0eaf5005d4fa0c9e278154f123", "best_bid":"0.4", "best_ask":"0.41"}, {"asset_id":"17924629579804316786455515989238352689210911545477836576430679697715946894553", "price":"0.99", "size":"14899.14", "side":"SELL", "hash":"bae3eb38d8aac10905047ddb168b865072822e6c", "best_bid":"0.59", "best_ask":"0.6"}], "timestamp":"1784449238892", "event_type":"price_change"}
{"market":"0xab772601f501b265bfe8982eb61d5347ef9945de314bfdf4ac0189c288ffb0b3", "price_changes":[{"asset_id":"12935926064588426924078449947177910958215776269411501731627440228801766632772", "price":"0.38", "size":"361.23", "side":"BUY", "hash":"d041261ea97d5d2de91141b48494bdc5176c0dd8", "best_bid":"0.4", "best_ask":"0.41"}, {"asset_id":"17924629579804316786455515989238352689210911545477836576430679697715946894553", "price":"0.62", "size":"361.23", "side":"SELL", "hash":"013637c75aafb455ffc3887638bd1fcceea645da", "best_bid":"0.59", "best_ask":"0.6"}], "timestamp":"1784449238893", "event_type":"price_change"}
{"market":"0xab772601f501b265bfe8982eb61d5347ef9945de314bfdf4ac0189c288ffb0b3", "price_changes":[{"asset_id":"17924629579804316786455515989238352689210911545477836576430679697715946894553", "price":"0.58", "size":"141.82", "side":"BUY", "hash":"c1f45b5deeab67e89a903b748d52c81d7a0b7871", "best_bid":"0.59", "best_ask":"0.6"}, {"asset_id":"12935926064588426924078449947177910958215776269411501731627440228801766632772", "price":"0.42", "size":"141.82", "side":"SELL", "hash":"5d7a74c87dbb8fd5dde7cd96ee65cc1823afa364", "best_bid":"0.4", "best_ask":"0.41"}], "timestamp":"1784449238894", "event_type":"price_change"}
{"market":"0xab772601f501b265bfe8982eb61d5347ef9945de314bfdf4ac0189c288ffb0b3", "price_changes":[{"asset_id":"17924629579804316786455515989238352689210911545477836576430679697715946894553", "price":"0.01", "size":"12975.5", "side":"BUY", "hash":"f44731155dca9cea298a5c65725a8360f736fb19", "best_bid":"0.59", "best_ask":"0.6"}, {"asset_id":"12935926064588426924078449947177910958215776269411501731627440228801766632772", "price":"0.99", "size":"12975.5", "side":"SELL", "hash":"cd8370a9bfe67525713bd4f75a0b4e31ea694514", "best_bid":"0.4", "best_ask":"0.41"}], "timestamp":"1784449238899", "event_type":"price_change"}
{"market":"0xab772601f501b265bfe8982eb61d5347ef9945de314bfdf4ac0189c288ffb0b3", "price_changes":[{"asset_id":"17924629579804316786455515989238352689210911545477836576430679697715946894553", "price":"0.04", "size":"1270.1", "side":"BUY", "hash":"b0884f3b92f6c025c37f33cc62e6980cf37b3ca4", "best_bid":"0.59", "best_ask":"0.6"}, {"asset_id":"12935926064588426924078449947177910958215776269411501731627440228801766632772", "price":"0.96", "size":"1270.1", "side":"SELL", "hash":"a66f1236fa15bc861ff8c6be9915cc8187a32885", "best_bid":"0.4", "best_ask":"0.41"}], "timestamp":"1784449238916", "event_type":"price_change"}
{"market":"0xab772601f501b265bfe8982eb61d5347ef9945de314bfdf4ac0189c288ffb0b3", "price_changes":[{"asset_id":"17924629579804316786455515989238352689210911545477836576430679697715946894553", "price":"0.01", "size":"12970.5", "side":"BUY", "hash":"a5453ccd2ddb156a1bb71b5de0010605018b4206", "best_bid":"0.59", "best_ask":"0.6"}, {"asset_id":"12935926064588426924078449947177910958215776269411501731627440228801766632772", "price":"0.99", "size":"12970.5", "side":"SELL", "hash":"2c9960f429b57f3c1874ef8a482422b9b5448a84", "best_bid":"0.4", "best_ask":"0.41"}], "timestamp":"1784449238920", "event_type":"price_change"}
{"market":"0xab772601f501b265bfe8982eb61d5347ef9945de314bfdf4ac0189c288ffb0b3", "price_changes":[{"asset_id":"17924629579804316786455515989238352689210911545477836576430679697715946894553", "price":"0.01", "size":"12964.5", "side":"BUY", "hash":"ede45b279efe4d2b2189932b5b8b27e38948b4f3", "best_bid":"0.59", "best_ask":"0.6"}, {"asset_id":"12935926064588426924078449947177910958215776269411501731627440228801766632772", "price":"0.99", "size":"12964.5", "side":"SELL", "hash":"a31feb763c29b8746374e4205afbfb6dd5b3099f", "best_bid":"0.4", "best_ask":"0.41"}], "timestamp":"1784449238927", "event_type":"price_change"}
{"market":"0xab772601f501b265bfe8982eb61d5347ef9945de314bfdf4ac0189c288ffb0b3", "price_changes":[{"asset_id":"17924629579804316786455515989238352689210911545477836576430679697715946894553", "price":"0.01", "size":"13064.5", "side":"BUY", "hash":"42b611f6d8f647ddd8a16671e540b3ee4dccd161", "best_bid":"0.59", "best_ask":"0.6"}, {"asset_id":"12935926064588426924078449947177910958215776269411501731627440228801766632772", "price":"0.99", "size":"13064.5", "side":"SELL", "hash":"07f0f0892b1d6deaf16edb32b9aa982ceeb1744f", "best_bid":"0.4", "best_ask":"0.41"}], "timestamp":"1784449238936", "event_type":"price_change"}
{"market":"0xab772601f501b265bfe8982eb61d5347ef9945de314bfdf4ac0189c288ffb0b3", "price_changes":[{"asset_id":"17924629579804316786455515989238352689210911545477836576430679697715946894553", "price":"0.28", "size":"92.77", "side":"BUY", "hash":"ec9c64a5286bbc9f451420df6582e2c0bf4fb190", "best_bid":"0.59", "best_ask":"0.6"}, {"asset_id":"12935926064588426924078449947177910958215776269411501731627440228801766632772", "price":"0.72", "size":"92.77", "side":"SELL", "hash":"edc06b8b0c0df4c1a7218f3e4a1233b90ecd60d3", "best_bid":"0.4", "best_ask":"0.41"}], "timestamp":"1784449238942", "event_type":"price_change"}
{"market":"0xab772601f501b265bfe8982eb61d5347ef9945de314bfdf4ac0189c288ffb0b3", "price_changes":[{"asset_id":"17924629579804316786455515989238352689210911545477836576430679697715946894553", "price":"0.33", "size":"108.1", "side":"BUY", "hash":"67c3eb1d14c682ce1b6c10ab14ebbf230fa6840c", "best_bid":"0.59", "best_ask":"0.6"}, {"asset_id":"12935926064588426924078449947177910958215776269411501731627440228801766632772", "price":"0.67", "size":"108.1", "side":"SELL", "hash":"7287c98c18ae550204b15cb615743f36725813f1", "best_bid":"0.4", "best_ask":"0.41"}], "timestamp":"1784449238955", "event_type":"price_change"}
{"market":"0xab772601f501b265bfe8982eb61d5347ef9945de314bfdf4ac0189c288ffb0b3", "price_changes":[{"asset_id":"17924629579804316786455515989238352689210911545477836576430679697715946894553", "price":"0.01", "size":"13059.5", "side":"BUY", "hash":"3574ea3596cf2aabd6e20ea04eb93fad95f5d99f", "best_bid":"0.59", "best_ask":"0.6"}, {"asset_id":"12935926064588426924078449947177910958215776269411501731627440228801766632772", "price":"0.99", "size":"13059.5", "side":"SELL", "hash":"f30ac80e7ab4b6622d952e3c43d2eb3756c6cbe4", "best_bid":"0.4", "best_ask":"0.41"}], "timestamp":"1784449238960", "event_type":"price_change"}
{"market":"0xab772601f501b265bfe8982eb61d5347ef9945de314bfdf4ac0189c288ffb0b3", "price_changes":[{"asset_id":"17924629579804316786455515989238352689210911545477836576430679697715946894553", "price":"0.59", "size":"125.28", "side":"BUY", "hash":"f60f6b322c85c0202f206c7237ab216cc530cfcc", "best_bid":"0.59", "best_ask":"0.6"}, {"asset_id":"12935926064588426924078449947177910958215776269411501731627440228801766632772", "price":"0.41", "size":"125.28", "side":"SELL", "hash":"6e16efa8e46051b67463a46eb6295bf1ec8bb101", "best_bid":"0.4", "best_ask":"0.41"}], "timestamp":"1784449238976", "event_type":"price_change"}
