{"market":"0x982eae4503214e5d7992668e93f48f42e4707b92e23bb45f8d52d321f643cbe3", "price_changes":[{"asset_id":"37613674580450069178400687025689415665506452565086963049482350052080099056186", "price":"0.11", "size":"490.73", "side":"BUY", "hash":"96673d6c373ac06b7e773256590c0bf8c937798b", "best_bid":"0.18", "best_ask":"0.19"}, {"asset_id":"74913635031537477155015393896000154190746945075332596665612975928350948042868", "price":"0.89", "size":"490.73", "side":"SELL", "hash":"b7d77d7e8ccf19fa8f9f6d363697a095cc6fc09b", "best_bid":"0.81", "best_ask":"0.82"}], "timestamp":"1784449595787", "event_type":"price_change"}
{"market":"0x982eae4503214e5d7992668e93f48f42e4707b92e23bb45f8d52d321f643cbe3", "price_changes":[{"asset_id":"74913635031537477155015393896000154190746945075332596665612975928350948042868", "price":"0.02", "size":"3289.11", "side":"BUY", "hash":"0ae2a3fb2091f49eca099fe50a365007b26f0776", "best_bid":"0.81", "best_ask":"0.82"}, {"asset_id":"37613674580450069178400687025689415665506452565086963049482350052080099056186", "price":"0.98", "size":"3289.11", "side":"SELL", "hash":"ae06f9efab10c3079bf9d64247e1cdf8faeb62a8", "best_bid":"0.18", "best_ask":"0.19"}], "timestamp":"1784449595787", "event_type":"price_change"}
{"market":"0x982eae4503214e5d7992668e93f48f42e4707b92e23bb45f8d52d321f643cbe3", "price_changes":[{"asset_id":"74913635031537477155015393896000154190746945075332596665612975928350948042868", "price":"0.01", "size":"16769.13", "side":"BUY", "hash":"768e9ff8df074ed8d57996492601dbe418a4e326", "best_bid":"0.81", "best_ask":"0.82"}, {"asset_id":"37613674580450069178400687025689415665506452565086963049482350052080099056186", "price":"0.99", "size":"16769.13", "side":"SELL", "hash":"36cc2b3555d99ad9a165fe796034e5231dd04867", "best_bid":"0.18", "best_ask":"0.19"}], "timestamp":"1784449595790", "event_type":"price_change"}
{"market":"0x982eae4503214e5d7992668e93f48f42e4707b92e23bb45f8d52d321f643cbe3", "price_changes":[{"asset_id":"74913635031537477155015393896000154190746945075332596665612975928350948042868", "price":"0.63", "size":"150.6", "side":"BUY", "hash":"aad929b858def0b052f6e6d0762fff1284f52ace", "best_bid":"0.81", "best_ask":"0.82"}, {"asset_id":"37613674580450069178400687025689415665506452565086963049482350052080099056186", "price":"0.37", "size":"150.6", "side":"SELL", "hash":"188499027fa53c7331c9d67f462608a16df2dcdc", "best_bid":"0.18", "best_ask":"0.19"}], "timestamp":"1784449595800", "event_type":"price_change"}
{"market":"0x982eae4503214e5d7992668e93f48f42e4707b92e23bb45f8d52d321f643cbe3", "price_changes":[{"asset_id":"74913635031537477155015393896000154190746945075332596665612975928350948042868", "price":"0.55", "size":"485.2", "side":"BUY", "hash":"fd3c655e275e2919f8757476ec617d59cd7595ba", "best_bid":"0.81", "best_ask":"0.82"}, {"asset_id":"37613674580450069178400687025689415665506452565086963049482350052080099056186", "price":"0.45", "size":"485.2", "side":"SELL", "hash":"cba9b2aedc4cf86721e4fca759a5504960b81a4e", "best_bid":"0.18", "best_ask":"0.19"}], "timestamp":"1784449595803", "event_type":"price_change"}
{"market":"0x982eae4503214e5d7992668e93f48f42e4707b92e23bb45f8d52d321f643cbe3", "price_changes":[{"asset_id":"37613674580450069178400687025689415665506452565086963049482350052080099056186", "price":"0.01", "size":"17929.98", "side":"BUY", "hash":"c490e43258c95c79b19757c4cd9891151420d7d1", "best_bid":"0.18", "best_ask":"0.19"}, {"asset_id":"74913635031537477155015393896000154190746945075332596665612975928350948042868", "price":"0.99", "size":"17929.98", "side":"SELL", "hash":"289358bee437196db8f42e5a98c5a8ff161095b0", "best_bid":"0.81", "best_ask":"0.82"}], "timestamp":"1784449595817", "event_type":"price_change"}
{"market":"0x982eae4503214e5d7992668e93f48f42e4707b92e23bb45f8d52d321f643cbe3", "price_changes":[{"asset_id":"37613674580450069178400687025689415665506452565086963049482350052080099056186", "price":"0.01", "size":"17924.98", "side":"BUY", "hash":"e681dbb033bdf9971fd1e1a868663e12b9b24f0f", "best_bid":"0.18", "best_ask":"0.19"}, {"asset_id":"74913635031537477155015393896000154190746945075332596665612975928350948042868", "price":"0.99", "size":"17924.98", "side":"SELL", "hash":"c9c27683e88eb77f6ac560a1c50303779877c3e8", "best_bid":"0.81", "best_ask":"0.82"}], "timestamp":"1784449595817", "event_type":"price_change"}
{"market":"0x982eae4503214e5d7992668e93f48f42e4707b92e23bb45f8d52d321f643cbe3", "price_changes":[{"asset_id":"74913635031537477155015393896000154190746945075332596665612975928350948042868", "price":"0.01", "size":"16774.13", "side":"BUY", "hash":"4f9ba754505b0029923e354c23952bbdff47014f", "best_bid":"0.81", "best_ask":"0.82"}, {"asset_id":"37613674580450069178400687025689415665506452565086963049482350052080099056186", "price":"0.99", "size":"16774.13", "side":"SELL", "hash":"d1acd665f1e463600eb239dad32905217196c6b9", "best_bid":"0.18", "best_ask":"0.19"}], "timestamp":"1784449595825", "event_type":"price_change"}
{"market":"0x982eae4503214e5d7992668e93f48f42e4707b92e23bb45f8d52d321f643cbe3", "price_changes":[{"asset_id":"74913635031537477155015393896000154190746945075332596665612975928350948042868", "price":"0.01", "size":"16779.13", "side":"BUY", "hash":"693d178faabfd2007f139ae9833d1dc61f010ac7", "best_bid":"0.81", "best_ask":"0.82"}, {"asset_id":"37613674580450069178400687025689415665506452565086963049482350052080099056186", "price":"0.99", "size":"16779.13", "side":"SELL", "hash":"9a5667a7b341816b1ffb503b79070a0342bd2578", "best_bid":"0.18", "best_ask":"0.19"}], "timestamp":"1784449595826", "event_type":"price_change"}
{"market":"0x982eae4503214e5d7992668e93f48f42e4707b92e23bb45f8d52d321f643cbe3", "price_changes":[{"asset_id":"37613674580450069178400687025689415665506452565086963049482350052080099056186", "price":"0.01", "size":"17919.98", "side":"BUY", "hash":"e9dd33255d9ae40a4c3610b4925fc11dbef9c467", "best_bid":"0.18", "best_ask":"0.19"}, {"asset_id":"74913635031537477155015393896000154190746945075332596665612975928350948042868", "price":"0.99", "size":"17919.98", "side":"SELL", "hash":"9526685d3683e53b48a8664c57b6e10196626e36", "best_bid":"0.81", "best_ask":"0.82"}], "timestamp":"1784449595826", "event_type":"price_change"}
{"market":"0x982eae4503214e5d7992668e93f48f42e4707b92e23bb45f8d52d321f643cbe3", "price_changes":[{"asset_id":"74913635031537477155015393896000154190746945075332596665612975928350948042868", "price":"0.01", "size":"16784.13", "side":"BUY", "hash":"b8ec634dc234e7282e4d3b5ebd5933c7068c2321", "best_bid":"0.81", "best_ask":"0.82"}, {"asset_id":"37613674580450069178400687025689415665506452565086963049482350052080099056186", "price":"0.99", "size":"16784.13", "side":"SELL", "hash":"2c11d5e64443526d3ce0b2093ecb70c44be360b9", "best_bid":"0.18", "best_ask":"0.19"}], "timestamp":"1784449595827", "event_type":"price_change"}
{"market":"0x982eae4503214e5d7992668e93f48f42e4707b92e23bb45f8d52d321f643cbe3", "price_changes":[{"asset_id":"74913635031537477155015393896000154190746945075332596665612975928350948042868", "price":"0.01", "size":"16284.13", "side":"BUY", "hash":"63d775eabb259141c6cee187164528c8cfede17b", "best_bid":"0.81", "best_ask":"0.82"}, {"asset_id":"37613674580450069178400687025689415665506452565086963049482350052080099056186", "price":"0.99", "size":"16284.13", "side":"SELL", "hash":"8c366b4b900dbd147339301c5c9e7218063dd652", "best_bid":"0.18", "best_ask":"0.19"}], "timestamp":"1784449595829", "event_type":"price_change"}
{"market":"0x982eae4503214e5d7992668e93f48f42e4707b92e23bb45f8d52d321f643cbe3", "price_changes":[{"asset_id":"74913635031537477155015393896000154190746945075332596665612975928350948042868", "price":"0.01", "size":"16289.13", "side":"BUY", "hash":"f8245d3bfc60ab8ab7bf40997ab9a825383ec689", "best_bid":"0.81", "best_ask":"0.82"}, {"asset_id":"37613674580450069178400687025689415665506452565086963049482350052080099056186", "price":"0.99", "size":"16289.13", "side":"SELL", "hash":"abec8b4ed81f2ff6f79f6d1906179f9f35682690", "best_bid":"0.18", "best_ask":"0.19"}], "timestamp":"1784449595830", "event_type":"price_change"}
{"market":"0x982eae4503214e5d7992668e93f48f42e4707b92e23bb45f8d52d321f643cbe3", "price_changes":[{"asset_id":"74913635031537477155015393896000154190746945075332596665612975928350948042868", "price":"0.01", "size":"16294.13", "side":"BUY", "hash":"0c8d8283394f9fe3661d52aaef54122354f76d74", "best_bid":"0.81", "best_ask":"0.82"}, {"asset_id":"37613674580450069178400687025689415665506452565086963049482350052080099056186", "price":"0.99", "size":"16294.13", "side":"SELL", "hash":"e6fcf015b28e37dd17e0b795908fd1d3eeafc4ba", "best_bid":"0.18", "best_ask":"0.19"}], "timestamp":"1784449595831", "event_type":"price_change"}
{"market":"0x982eae4503214e5d7992668e93f48f42e4707b92e23bb45f8d52d321f643cbe3", "price_changes":[{"asset_id":"74913635031537477155015393896000154190746945075332596665612975928350948042868", "price":"0.01", "size":"16299.13", "side":"BUY", "hash":"8d1d1120df9cea8d49fbbfc5611b656000b6f789", "best_bid":"0.81", "best_ask":"0.82"}, {"asset_id":"37613674580450069178400687025689415665506452565086963049482350052080099056186", "price":"0.99", "size":"16299.13", "side":"SELL", "hash":"e8064c58d2d77b4ea6f686322fa3d4d60f937af9", "best_bid":"0.18", "best_ask":"0.19"}], "timestamp":"1784449595831", "event_type":"price_change"}
{"market":"0x982eae4503214e5d7992668e93f48f42e4707b92e23bb45f8d52d321f643cbe3", "price_changes":[{"asset_id":"74913635031537477155015393896000154190746945075332596665612975928350948042868", "price":"0.01", "size":"16199.13", "side":"BUY", "hash":"ece4e6836fc937c5df0a68a15e1193de5f82da52", "best_bid":"0.81", "best_ask":"0.82"}, {"asset_id":"37613674580450069178400687025689415665506452565086963049482350052080099056186", "price":"0.99", "size":"16199.13", "side":"SELL", "hash":"1c8b23e04d79c8ab18474d0102b0ce356ea456d3", "best_bid":"0.18", "best_ask":"0.19"}], "timestamp":"1784449595834", "event_type":"price_change"}
{"market":"0x982eae4503214e5d7992668e93f48f42e4707b92e23bb45f8d52d321f643cbe3", "price_changes":[{"asset_id":"37613674580450069178400687025689415665506452565086963049482350052080099056186", "price":"0.14", "size":"164.34", "side":"BUY", "hash":"27e0e499152492bdb00250de5b75c1e0549b6a0e", "best_bid":"0.18", "best_ask":"0.19"}, {"asset_id":"74913635031537477155015393896000154190746945075332596665612975928350948042868", "price":"0.86", "size":"164.34", "side":"SELL", "hash":"43d5bc848f6fb9efe14e606cb77c0f1dbe0677d8", "best_bid":"0.81", "best_ask":"0.82"}], "timestamp":"1784449595840", "event_type":"price_change"}
{"market":"0x982eae4503214e5d7992668e93f48f42e4707b92e23bb45f8d52d321f643cbe3", "price_changes":[{"asset_id":"37613674580450069178400687025689415665506452565086963049482350052080099056186", "price":"0.15", "size":"127.71", "side":"BUY", "hash":"9b8a058401c7bdd336771b9d5ddb674c51f3a24f", "best_bid":"0.18", "best_ask":"0.19"}, {"asset_id":"74913635031537477155015393896000154190746945075332596665612975928350948042868", "price":"0.85", "size":"127.71", "side":"SELL", "hash":"16baa4f3ce088c2a2f2cebe06f91d8eae08789ce", "best_bid":"0.81", "best_ask":"0.82"}], "timestamp":"1784449595841", "event_type":"price_change"}
{"market":"0x982eae4503214e5d7992668e93f48f42e4707b92e23bb45f8d52d321f643cbe3", "price_changes":[{"asset_id":"74913635031537477155015393896000154190746945075332596665612975928350948042868", "price":"0.01", "size":"16204.13", "side":"BUY", "hash":"e921c5e96630680842bd9e0913c048e83f3233f8", "best_bid":"0.81", "best_ask":"0.82"}, {"asset_id":"37613674580450069178400687025689415665506452565086963049482350052080099056186", "price":"0.99", "size":"16204.13", "side":"SELL", "hash":"5dfcdb246aeb8a53e839ebe43919ed726d18641f", "best_bid":"0.18", "best_ask":"0.19"}], "timestamp":"1784449595841", "event_type":"price_change"}
{"market":"0x982eae4503214e5d7992668e93f48f42e4707b92e23bb45f8d52d321f643cbe3", "price_changes":[{"asset_id":"74913635031537477155015393896000154190746945075332596665612975928350948042868", "price":"0.68", "size":"106.29", "side":"BUY", "hash":"55805d94fa46b9c0e55d2de9c4b712aaff17164b", "best_bid":"0.81", "best_ask":"0.82"}, {"asset_id":"37613674580450069178400687025689415665506452565086963049482350052080099056186", "price":"0.32", "size":"106.29", "side":"SELL", "hash":"0775524d58ea207876e275663d052e5985baf39a", "best_bid":"0.18", "best_ask":"0.19"}], "timestamp":"1784449595842", "event_type":"price_change"}
{"market":"0x982eae4503214e5d7992668e93f48f42e4707b92e23bb45f8d52d321f643cbe3", "price_changes":[{"asset_id":"37613674580450069178400687025689415665506452565086963049482350052080099056186", "price":"0.11", "size":"530.73", "side":"BUY", "hash":"1697d116e197935af489fdcbe61fbf1b579835ae", "best_bid":"0.18", "best_ask":"0.19"}, {"asset_id":"74913635031537477155015393896000154190746945075332596665612975928350948042868", "price":"0.89", "size":"530.73", "side":"SELL", "hash":"0b3f6866597d060426b16d9e35fb49f00d1d3b4c", "best_bid":"0.81", "best_ask":"0.82"}], "timestamp":"1784449595845", "event_type":"price_change"}
{"market":"0x982eae4503214e5d7992668e93f48f42e4707b92e23bb45f8d52d321f643cbe3", "price_changes":[{"asset_id":"37613674580450069178400687025689415665506452565086963049482350052080099056186", "price":"0.1", "size":"618.32", "side":"BUY", "hash":"764ac6cee656c8d33f14e3845837f0612fff5bbf", "best_bid":"0.18", "best_ask":"0.19"}, {"asset_id":"74913635031537477155015393896000154190746945075332596665612975928350948042868", "price":"0.9", "size":"618.32", "side":"SELL", "hash":"c50a24a7813fefe681f416080d84bd4b9a52f75a", "best_bid":"0.81", "best_ask":"0.82"}], "timestamp":"1784449595846", "event_type":"price_change"}
{"market":"0x982eae4503214e5d7992668e93f48f42e4707b92e23bb45f8d52d321f643cbe3", "price_changes":[{"asset_id":"37613674580450069178400687025689415665506452565086963049482350052080099056186", "price":"0.12", "size":"207.17", "side":"BUY", "hash":"2afa5ec89ae829ab8a4a0dc13ed4f0dc5ba5b3f1", "best_bid":"0.18", "best_ask":"0.19"}, {"asset_id":"74913635031537477155015393896000154190746945075332596665612975928350948042868", "price":"0.88", "size":"207.17", "side":"SELL", "hash":"69b521b4ab6862b64286a476df246dacbf859341", "best_bid":"0.81", "best_ask":"0.82"}], "timestamp":"1784449595848", "event_type":"price_change"}
{"market":"0x982eae4503214e5d7992668e93f48f42e4707b92e23bb45f8d52d321f643cbe3", "price_changes":[{"asset_id":"74913635031537477155015393896000154190746945075332596665612975928350948042868", "price":"0.01", "size":"16209.14", "side":"BUY", "hash":"39268706493f3bcbef7b20d95710a440439de340", "best_bid":"0.81", "best_ask":"0.82"}, {"asset_id":"37613674580450069178400687025689415665506452565086963049482350052080099056186", "price":"0.99", "size":"16209.14", "side":"SELL", "hash":"52b997f7ac0aa7313bc7ab68b8c5bbeb7777338b", "best_bid":"0.18", "best_ask":"0.19"}], "timestamp":"1784449595860", "event_type":"price_change"}
{"market":"0x982eae4503214e5d7992668e93f48f42e4707b92e23bb45f8d52d321f643cbe3", "price_changes":[{"asset_id":"74913635031537477155015393896000154190746945075332596665612975928350948042868", "price":"0.01", "size":"16204.14", "side":"BUY", "hash":"092febecf7c9f9007c1865921767ee47a305666a", "best_bid":"0.81", "best_ask":"0.82"}, {"asset_id":"37613674580450069178400687025689415665506452565086963049482350052080099056186", "price":"0.99", "size":"16204.14", "side":"SELL", "hash":"0c140b1d65eb421156bb0da51218ad926dc9ff62", "best_bid":"0.18", "best_ask":"0.19"}], "timestamp":"1784449595862", "event_type":"price_change"}
{"market":"0x982eae4503214e5d7992668e93f48f42e4707b92e23bb45f8d52d321f643cbe3", "price_changes":[{"asset_id":"74913635031537477155015393896000154190746945075332596665612975928350948042868", "price":"0.01", "size":"16199.14", "side":"BUY", "hash":"d3dfe66e17bc2e60d0f75f83dca023b23db774e3", "best_bid":"0.81", "best_ask":"0.82"}, {"asset_id":"37613674580450069178400687025689415665506452565086963049482350052080099056186", "price":"0.99", "size":"16199.14", "side":"SELL", "hash":"50609331f0fc7f5cb97c96e25d2be46c50067132", "best_bid":"0.18", "best_ask":"0.19"}], "timestamp":"1784449595865", "event_type":"price_change"}
{"market":"0x982eae4503214e5d7992668e93f48f42e4707b92e23bb45f8d52d321f643cbe3", "price_changes":[{"asset_id":"74913635031537477155015393896000154190746945075332596665612975928350948042868", "price":"0.01", "size":"16204.14", "side":"BUY", "hash":"46c4ac87b6340e8a8c872d73371a87b338321511", "best_bid":"0.81", "best_ask":"0.82"}, {"asset_id":"37613674580450069178400687025689415665506452565086963049482350052080099056186", "price":"0.99", "size":"16204.14", "side":"SELL", "hash":"030c16e3a28e89afc963f07907b21186a5427757", "best_bid":"0.18", "best_ask":"0.19"}], "timestamp":"1784449595869", "event_type":"price_change"}
{"market":"0x982eae4503214e5d7992668e93f48f42e4707b92e23bb45f8d52d321f643cbe3", "price_changes":[{"asset_id":"74913635031537477155015393896000154190746945075332596665612975928350948042868", "price":"0.01", "size":"16304.14", "side":"BUY", "hash":"7b63462d8c7943956a946aebd257d9d3a960f705", "best_bid":"0.81", "best_ask":"0.82"}, {"asset_id":"37613674580450069178400687025689415665506452565086963049482350052080099056186", "price":"0.99", "size":"16304.14", "side":"SELL", "hash":"4dc1f271acce636075ca1e09ccd0665c2e5aca43", "best_bid":"0.18", "best_ask":"0.19"}], "timestamp":"1784449595874", "event_type":"price_change"}
{"market":"0x982eae4503214e5d7992668e93f48f42e4707b92e23bb45f8d52d321f643cbe3", "asset_id":"74913635031537477155015393896000154190746945075332596665612975928350948042868", "price":"0.82", "size":"12", "fee_rate_bps":"0", "side":"BUY", "timestamp":"1784449595840", "event_type":"last_trade_price", "transaction_hash":"0x08da0ff9c0d32d8344ac4e6cffab397568888a25e590248568119331b94d0d12"}
{"market":"0x982eae4503214e5d7992668e93f48f42e4707b92e23bb45f8d52d321f643cbe3", "price_changes":[{"asset_id":"74913635031537477155015393896000154190746945075332596665612975928350948042868", "price":"0.01", "size":"16299.13", "side":"BUY", "hash":"299a09c4c8322e0002c54e236dac96089a647d10", "best_bid":"0.81", "best_ask":"0.82"}, {"asset_id":"37613674580450069178400687025689415665506452565086963049482350052080099056186", "price":"0.99", "size":"16299.13", "side":"SELL", "hash":"fe611c3c95acb5fbcd07b093a35e3691c60532ed", "best_bid":"0.18", "best_ask":"0.19"}], "timestamp":"1784449595886", "event_type":"price_change"}
{"market":"0x982eae4503214e5d7992668e93f48f42e4707b92e23bb45f8d52d321f643cbe3", "price_changes":[{"asset_id":"37613674580450069178400687025689415665506452565086963049482350052080099056186", "price":"0.18", "size":"33.34", "side":"BUY", "hash":"03520df37c45ebb8e25a3e04e020450f87c7baf1", "best_bid":"0.18", "best_ask":"0.19"}, {"asset_id":"74913635031537477155015393896000154190746945075332596665612975928350948042868", "price":"0.82", "size":"33.34", "side":"SELL", "hash":"9cc522dc49e59f436e9e5d418f7a3be983587af5", "best_bid":"0.81", "best_ask":"0.82"}], "timestamp":"1784449595895", "event_type":"price_change"}
{"market":"0x982eae4503214e5d7992668e93f48f42e4707b92e23bb45f8d52d321f643cbe3", "asset_id":"74913635031537477155015393896000154190746945075332596665612975928350948042868", "bids":[{"price":"0.01", "size":"16299.13"}, {"price":"0.02", "size":"3289.11"}, {"price":"0.03", "size":"2085.95"}, {"price":"0.04", "size":"1462.1"}, {"price":"0.05", "size":"1953.67"}, {"price":"0.06", "size":"1377.35"}, {"price":"0.07", "size":"1155.2"}, {"price":"0.08", "size":"1325.88"}, {"price":"0.09", "size":"1027.7"}, {"price":"0.1", "size":"528.2"}, {"price":"0.11", "size":"454.1"}, {"price":"0.12", "size":"203.05"}, {"price":"0.13", "size":"179.4"}, {"price":"0.14", "size":"159.4"}, {"price":"0.15", "size":"149.23"}, {"price":"0.16", "size":"150.4"}, {"price":"0.17", "size":"105.08"}, {"price":"0.18", "size":"127.3"}, {"price":"0.19", "size":"99.78"}, {"price":"0.2", "size":"181.4"}, {"price":"0.21", "size":"111.5"}, {"price":"0.22", "size":"125.7"}, {"price":"0.23", "size":"92"}, {"price":"0.24", "size":"111.5"}, {"price":"0.25", "size":"843.6"}, {"price":"0.26", "size":"128.8"}, {"price":"0.27", "size":"86.7"}, {"price":"0.28", "size":"106.67"}, {"price":"0.29", "size":"84.59"}, {"price":"0.3", "size":"107.8"}, {"price":"0.31", "size":"79.1"}, {"price":"0.32", "size":"107.19"}, {"price":"0.33", "size":"76.7"}, {"price":"0.34", "size":"89"}, {"price":"0.35", "size":"84.4"}, {"price":"0.36", "size":"86.99"}, {"price":"0.37", "size":"73.6"}, {"price":"0.38", "size":"85"}, {"price":"0.39", "size":"71.6"}, {"price":"0.4", "size":"88.3"}, {"price":"0.41", "size":"94.3"}, {"price":"0.42", "size":"142.27"}, {"price":"0.43", "size":"86.5"}, {"price":"0.44", "size":"91.08"}, {"price":"0.45", "size":"104.31"}, {"price":"0.46", "size":"80.1"}, {"price":"0.47", "size":"94.9"}, {"price":"0.48", "size":"88.8"}, {"price":"0.49", "size":"99.36"}, {"price":"0.5", "size":"102.8"}, {"price":"0.51", "size":"100.8"}, {"price":"0.52", "size":"100.8"}, {"price":"0.53", "size":"99.9"}, {"price":"0.54", "size":"92.1"}, {"price":"0.55", "size":"485.2"}, {"price":"0.56", "size":"105.4"}, {"price":"0.57", "size":"95.5"}, {"price":"0.58", "size":"111.12"}, {"price":"0.59", "size":"94.9"}, {"price":"0.6", "size":"197.58"}, {"price":"0.61", "size":"100.6"}, {"price":"0.62", "size":"115"}, {"price":"0.63", "size":"150.6"}, {"price":"0.64", "size":"482.99"}, {"price":"0.65", "size":"92.4"}, {"price":"0.66", "size":"133.24"}, {"price":"0.67", "size":"302.58"}, {"price":"0.68", "size":"106.29"}, {"price":"0.69", "size":"85.7"}, {"price":"0.7", "size":"100.04"}, {"price":"0.71", "size":"78"}, {"price":"0.72", "size":"279"}, {"price":"0.73", "size":"146.41"}, {"price":"0.74", "size":"146.85"}, {"price":"0.75", "size":"162.84"}, {"price":"0.76", "size":"175.24"}, {"price":"0.77", "size":"189.66"}, {"price":"0.78", "size":"228.41"}, {"price":"0.79", "size":"98.19"}, {"price":"0.8", "size":"185.84"}, {"price":"0.81", "size":"405.96"}], "asks":[{"price":"0.99", "size":"17919.98"}, {"price":"0.98", "size":"3156.06"}, {"price":"0.97", "size":"3788.29"}, {"price":"0.96", "size":"1529.1"}, {"price":"0.95", "size":"1723.6"}, {"price":"0.94", "size":"1221.35"}, {"price":"0.93", "size":"1167.2"}, {"price":"0.92", "size":"1310"}, {"price":"0.91", "size":"942.82"}, {"price":"0.9", "size":"618.32"}, {"price":"0.89", "size":"530.73"}, {"price":"0.88", "size":"207.17"}, {"price":"0.87", "size":"366.4"}, {"price":"0.86", "size":"164.34"}, {"price":"0.85", "size":"127.71"}, {"price":"0.84", "size":"81.17"}, {"price":"0.82", "size":"33.34"}], "hash":"9cc522dc49e59f436e9e5d418f7a3be983587af5", "timestamp":"1784449595895", "event_type":"book"}
{"market":"0x982eae4503214e5d7992668e93f48f42e4707b92e23bb45f8d52d321f643cbe3", "asset_id":"37613674580450069178400687025689415665506452565086963049482350052080099056186", "bids":[{"price":"0.01", "size":"17919.98"}, {"price":"0.02", "size":"3156.06"}, {"price":"0.03", "size":"3788.29"}, {"price":"0.04", "size":"1529.1"}, {"price":"0.05", "size":"1723.6"}, {"price":"0.06", "size":"1221.35"}, {"price":"0.07", "size":"1167.2"}, {"price":"0.08", "size":"1310"}, {"price":"0.09", "size":"942.82"}, {"price":"0.1", "size":"618.32"}, {"price":"0.11", "size":"530.73"}, {"price":"0.12", "size":"207.17"}, {"price":"0.13", "size":"366.4"}, {"price":"0.14", "size":"164.34"}, {"price":"0.15", "size":"127.71"}, {"price":"0.16", "size":"81.17"}, {"price":"0.18", "size":"33.34"}], "asks":[{"price":"0.99", "size":"16299.13"}, {"price":"0.98", "size":"3289.11"}, {"price":"0.97", "size":"2085.95"}, {"price":"0.96", "size":"1462.1"}, {"price":"0.95", "size":"1953.67"}, {"price":"0.94", "size":"1377.35"}, {"price":"0.93", "size":"1155.2"}, {"price":"0.92", "size":"1325.88"}, {"price":"0.91", "size":"1027.7"}, {"price":"0.9", "size":"528.2"}, {"price":"0.89", "size":"454.1"}, {"price":"0.88", "size":"203.05"}, {"price":"0.87", "size":"179.4"}, {"price":"0.86", "size":"159.4"}, {"price":"0.85", "size":"149.23"}, {"price":"0.84", "size":"150.4"}, {"price":"0.83", "size":"105.08"}, {"price":"0.82", "size":"127.3"}, {"price":"0.81", "size":"99.78"}, {"price":"0.8", "size":"181.4"}, {"price":"0.79", "size":"111.5"}, {"price":"0.78", "size":"125.7"}, {"price":"0.77", "size":"92"}, {"price":"0.76", "size":"111.5"}, {"price":"0.75", "size":"843.6"}, {"price":"0.74", "size":"128.8"}, {"price":"0.73", "size":"86.7"}, {"price":"0.72", "size":"106.67"}, {"price":"0.71", "size":"84.59"}, {"price":"0.7", "size":"107.8"}, {"price":"0.69", "size":"79.1"}, {"price":"0.68", "size":"107.19"}, {"price":"0.67", "size":"76.7"}, {"price":"0.66", "size":"89"}, {"price":"0.65", "size":"84.4"}, {"price":"0.64", "size":"86.99"}, {"price":"0.63", "size":"73.6"}, {"price":"0.62", "size":"85"}, {"price":"0.61", "size":"71.6"}, {"price":"0.6", "size":"88.3"}, {"price":"0.59", "size":"94.3"}, {"price":"0.58", "size":"142.27"}, {"price":"0.57", "size":"86.5"}, {"price":"0.56", "size":"91.08"}, {"price":"0.55", "size":"104.31"}, {"price":"0.54", "size":"80.1"}, {"price":"0.53", "size":"94.9"}, {"price":"0.52", "size":"88.8"}, {"price":"0.51", "size":"99.36"}, {"price":"0.5", "size":"102.8"}, {"price":"0.49", "size":"100.8"}, {"price":"0.48", "size":"100.8"}, {"price":"0.47", "size":"99.9"}, {"price":"0.46", "size":"92.1"}, {"price":"0.45", "size":"485.2"}, {"price":"0.44", "size":"105.4"}, {"price":"0.43", "size":"95.5"}, {"price":"0.42", "size":"111.12"}, {"price":"0.41", "size":"94.9"}, {"price":"0.4", "size":"197.58"}, {"price":"0.39", "size":"100.6"}, {"price":"0.38", "size":"115"}, {"price":"0.37", "size":"150.6"}, {"price":"0.36", "size":"482.99"}, {"price":"0.35", "size":"92.4"}, {"price":"0.34", "size":"133.24"}, {"price":"0.33", "size":"302.58"}, {"price":"0.32", "size":"106.29"}, {"price":"0.31", "size":"85.7"}, {"price":"0.3", "size":"100.04"}, {"price":"0.29", "size":"78"}, {"price":"0.28", "size":"279"}, {"price":"0.27", "size":"146.41"}, {"price":"0.26", "size":"146.85"}, {"price":"0.25", "size":"162.84"}, {"price":"0.24", "size":"175.24"}, {"price":"0.23", "size":"189.66"}, {"price":"0.22", "size":"228.41"}, {"price":"0.21", "size":"98.19"}, {"price":"0.2", "size":"185.84"}, {"price":"0.19", "size":"405.96"}], "hash":"03520df37c45ebb8e25a3e04e020450f87c7baf1", "timestamp":"1784449595895", "event_type":"book"}
{"market":"0x982eae4503214e5d7992668e93f48f42e4707b92e23bb45f8d52d321f643cbe3", "price_changes":[{"asset_id":"74913635031537477155015393896000154190746945075332596665612975928350948042868", "price":"0.01", "size":"16294.13", "side":"BUY", "hash":"00c376c63c1e133df629691116f922a758b716e0", "best_bid":"0.81", "best_ask":"0.82"}, {"asset_id":"37613674580450069178400687025689415665506452565086963049482350052080099056186", "price":"0.99", "size":"16294.13", "side":"SELL", "hash":"08bf5bb46fe41ce835bbb46303eff49194452837", "best_bid":"0.18", "best_ask":"0.19"}], "timestamp":"1784449595898", "event_type":"price_change"}
{"market":"0x982eae4503214e5d7992668e93f48f42e4707b92e23bb45f8d52d321f643cbe3", "price_changes":[{"asset_id":"74913635031537477155015393896000154190746945075332596665612975928350948042868", "price":"0.01", "size":"16794.13", "side":"BUY", "hash":"aee59e3c6b04e019feb173b9946c75eb442a1835", "best_bid":"0.81", "best_ask":"0.82"}, {"asset_id":"37613674580450069178400687025689415665506452565086963049482350052080099056186", "price":"0.99", "size":"16794.13", "side":"SELL", "hash":"0320276fb324fbb24bd6c1183245d6e93f6649da", "best_bid":"0.18", "best_ask":"0.19"}], "timestamp":"1784449595901", "event_type":"price_change"}
{"market":"0x982eae4503214e5d7992668e93f48f42e4707b92e23bb45f8d52d321f643cbe3", "price_changes":[{"asset_id":"74913635031537477155015393896000154190746945075332596665612975928350948042868", "price":"0.6", "size":"182.58", "side":"BUY", "hash":"8e0df079eb87ed0a516a80022b1dcfe8efc28a5c", "best_bid":"0.81", "best_ask":"0.82"}, {"asset_id":"37613674580450069178400687025689415665506452565086963049482350052080099056186", "price":"0.4", "size":"182.58", "side":"SELL", "hash":"3024449a6ef10b86f0fb173e676fd8271807d83b", "best_bid":"0.18", "best_ask":"0.19"}], "timestamp":"1784449595907", "event_type":"price_change"}
{"market":"0x982eae4503214e5d7992668e93f48f42e4707b92e23bb45f8d52d321f643cbe3", "price_changes":[{"asset_id":"74913635031537477155015393896000154190746945075332596665612975928350948042868", "price":"0.01", "size":"16694.13", "side":"BUY", "hash":"1997959c4182a9aeddef23ac209972841a01fbae", "best_bid":"0.81", "best_ask":"0.82"}, {"asset_id":"37613674580450069178400687025689415665506452565086963049482350052080099056186", "price":"0.99", "size":"16694.13", "side":"SELL", "hash":"7e7ecf432422ae9f7258715f5bfb1df38049629c", "best_bid":"0.18", "best_ask":"0.19"}], "timestamp":"1784449595911", "event_type":"price_change"}
{"market":"0x982eae4503214e5d7992668e93f48f42e4707b92e23bb45f8d52d321f643cbe3", "price_changes":[{"asset_id":"74913635031537477155015393896000154190746945075332596665612975928350948042868", "price":"0.01", "size":"16689.13", "side":"BUY", "hash":"c528b4acad2998ba100a2e583d9a33745e3a26e9", "best_bid":"0.81", "best_ask":"0.82"}, {"asset_id":"37613674580450069178400687025689415665506452565086963049482350052080099056186", "price":"0.99", "size":"16689.13", "side":"SELL", "hash":"22ef266365ea2f058003fbc69f198ddc512c9b96", "best_bid":"0.18", "best_ask":"0.19"}], "timestamp":"1784449595921", "event_type":"price_change"}
{"market":"0x982eae4503214e5d7992668e93f48f42e4707b92e23bb45f8d52d321f643cbe3", "price_changes":[{"asset_id":"74913635031537477155015393896000154190746945075332596665612975928350948042868", "price":"0.01", "size":"16684.13", "side":"BUY", "hash":"149930f8829d99856911d3053076a41e668a4376", "best_bid":"0.81", "best_ask":"0.82"}, {"asset_id":"37613674580450069178400687025689415665506452565086963049482350052080099056186", "price":"0.99", "size":"16684.13", "side":"SELL", "hash":"73e3f6f6d7a419de0a0381749024da26c53ffce3", "best_bid":"0.18", "best_ask":"0.19"}], "timestamp":"1784449595931", "event_type":"price_change"}
{"market":"0x982eae4503214e5d7992668e93f48f42e4707b92e23bb45f8d52d321f643cbe3", "price_changes":[{"asset_id":"74913635031537477155015393896000154190746945075332596665612975928350948042868", "price":"0.01", "size":"16184.13", "side":"BUY", "hash":"1ee4452332b7aeeee6f9f9200a4750e678fbd105", "best_bid":"0.81", "best_ask":"0.82"}, {"asset_id":"37613674580450069178400687025689415665506452565086963049482350052080099056186", "price":"0.99", "size":"16184.13", "side":"SELL", "hash":"c7c27acbcf9cac8988b7988532254934a26e96a4", "best_bid":"0.18", "best_ask":"0.19"}], "timestamp":"1784449595934", "event_type":"price_change"}
{"market":"0x982eae4503214e5d7992668e93f48f42e4707b92e23bb45f8d52d321f643cbe3", "price_changes":[{"asset_id":"74913635031537477155015393896000154190746945075332596665612975928350948042868", "price":"0.81", "size":"385.96", "side":"BUY", "hash":"84177964f38291be34335e277f7a711668ae1d4f", "best_bid":"0.81", "best_ask":"0.82"}, {"asset_id":"37613674580450069178400687025689415665506452565086963049482350052080099056186", "price":"0.19", "size":"385.96", "side":"SELL", "hash":"9cba1edb6a9cff14f7f65dcfdd05f362b82b83c3", "best_bid":"0.18", "best_ask":"0.19"}], "timestamp":"1784449595946", "event_type":"price_change"}
{"market":"0x982eae4503214e5d7992668e93f48f42e4707b92e23bb45f8d52d321f643cbe3", "price_changes":[{"asset_id":"37613674580450069178400687025689415665506452565086963049482350052080099056186", "price":"0.11", "size":"490.73", "side":"BUY", "hash":"0d1c181601a70ffbd12f56dab99a4f3a8b7a4f21", "best_bid":"0.18", "best_ask":"0.19"}, {"asset_id":"74913635031537477155015393896000154190746945075332596665612975928350948042868", "price":"0.89", "size":"490.73", "side":"SELL", "hash":"a70d47b0b57bb3e1775d821b53a90bdc22e1dc6d", "best_bid":"0.81", "best_ask":"0.82"}], "timestamp":"1784449595952", "event_type":"price_change"}
{"market":"0x982eae4503214e5d7992668e93f48f42e4707b92e23bb45f8d52d321f643cbe3", "price_changes":[{"asset_id":"37613674580450069178400687025689415665506452565086963049482350052080099056186", "price":"0.12", "size":"247.17", "side":"BUY", "hash":"32e43af811efd5e1c48be9e3bfa1c5bd5b16c948", "best_bid":"0.18", "best_ask":"0.19"}, {"asset_id":"74913635031537477155015393896000154190746945075332596665612975928350948042868", "price":"0.88", "size":"247.17", "side":"SELL", "hash":"9e599781e7b574462875f85e35bdacb3c268b7d1", "best_bid":"0.81", "best_ask":"0.82"}], "timestamp":"1784449595953", "event_type":"price_change"}
{"market":"0x982eae4503214e5d7992668e93f48f42e4707b92e23bb45f8d52d321f643cbe3", "price_changes":[{"asset_id":"74913635031537477155015393896000154190746945075332596665612975928350948042868", "price":"0.01", "size":"16284.13", "side":"BUY", "hash":"b34b85d71dac9253f9b126bbc44f3ad55837f9e3", "best_bid":"0.81", "best_ask":"0.82"}, {"asset_id":"37613674580450069178400687025689415665506452565086963049482350052080099056186", "price":"0.99", "size":"16284.13", "side":"SELL", "hash":"2763c5b33051c3a328de39433f0ab841d888ea1e", "best_bid":"0.18", "best_ask":"0.19"}], "timestamp":"1784449595955", "event_type":"price_change"}
{"market":"0x982eae4503214e5d7992668e93f48f42e4707b92e23bb45f8d52d321f643cbe3", "price_changes":[{"asset_id":"74913635031537477155015393896000154190746945075332596665612975928350948042868", "price":"0.65", "size":"107.4", "side":"BUY", "hash":"8f086690c7249d85bef4ec18fcb2eb9f6fd5de94", "best_bid":"0.81", "best_ask":"0.82"}, {"asset_id":"37613674580450069178400687025689415665506452565086963049482350052080099056186", "price":"0.35", "size":"107.4", "side":"SELL", "hash":"cc44be6fc653017f16e13693903bb2b911656bf5", "best_bid":"0.18", "best_ask":"0.19"}], "timestamp":"1784449595967", "event_type":"price_change"}
{"market":"0x982eae4503214e5d7992668e93f48f42e4707b92e23bb45f8d52d321f643cbe3", "asset_id":"74913635031537477155015393896000154190746945075332596665612975928350948042868", "price":"0.82", "size":"1.804877", "fee_rate_bps":"0", "side":"BUY", "timestamp":"1784449595967", "event_type":"last_trade_price", "transaction_hash":"0x8a589be3411a6b1a4a843b2b248c1de2ab1ae8234035f31ef108bd42d7bb2d00"}
{"market":"0x982eae4503214e5d7992668e93f48f42e4707b92e23bb45f8d52d321f643cbe3", "price_changes":[{"asset_id":"74913635031537477155015393896000154190746945075332596665612975928350948042868", "price":"0.41", "size":"69.9", "side":"BUY", "hash":"f4f045066e0d28a639f95292acbf14636d1398e3", "best_bid":"0.81", "best_ask":"0.82"}, {"asset_id":"37613674580450069178400687025689415665506452565086963049482350052080099056186", "price":"0.59", "size":"69.9", "side":"SELL", "hash":"d702d7440a720e2632db75aa0ed2ea33dfe3d92a", "best_bid":"0.18", "best_ask":"0.19"}], "timestamp":"1784449595981", "event_type":"price_change"}
{"market":"0x982eae4503214e5d7992668e93f48f42e4707b92e23bb45f8d52d321f643cbe3", "price_changes":[{"asset_id":"74913635031537477155015393896000154190746945075332596665612975928350948042868", "price":"0.81", "size":"378.96", "side":"BUY", "hash":"8b11eddb45dc5c645a0afa6aed49cff182244b5e", "best_bid":"0.81", "best_ask":"0.82"}, {"asset_id":"37613674580450069178400687025689415665506452565086963049482350052080099056186", "price":"0.19", "size":"378.96", "side":"SELL", "hash":"6eeab6be3f36f84cd790bd8373e24572309111c2", "best_bid":"0.18", "best_ask":"0.19"}], "timestamp":"1784449595981", "event_type":"price_change"}
{"market":"0x982eae4503214e5d7992668e93f48f42e4707b92e23bb45f8d52d321f643cbe3", "asset_id":"74913635031537477155015393896000154190746945075332596665612975928350948042868", "bids":[{"price":"0.01", "size":"16284.13"}, {"price":"0.02", "size":"3289.11"}, {"price":"0.03", "size":"2085.95"}, {"price":"0.04", "size":"1462.1"}, {"price":"0.05", "size":"1953.67"}, {"price":"0.06", "size":"1377.35"}, {"price":"0.07", "size":"1155.2"}, {"price":"0.08", "size":"1325.88"}, {"price":"0.09", "size":"1027.7"}, {"price":"0.1", "size":"528.2"}, {"price":"0.11", "size":"454.1"}, {"price":"0.12", "size":"203.05"}, {"price":"0.13", "size":"179.4"}, {"price":"0.14", "size":"159.4"}, {"price":"0.15", "size":"149.23"}, {"price":"0.16", "size":"150.4"}, {"price":"0.17", "size":"105.08"}, {"price":"0.18", "size":"127.3"}, {"price":"0.19", "size":"99.78"}, {"price":"0.2", "size":"181.4"}, {"price":"0.21", "size":"111.5"}, {"price":"0.22", "size":"125.7"}, {"price":"0.23", "size":"92"}, {"price":"0.24", "size":"111.5"}, {"price":"0.25", "size":"843.6"}, {"price":"0.26", "size":"128.8"}, {"price":"0.27", "size":"86.7"}, {"price":"0.28", "size":"106.67"}, {"price":"0.29", "size":"84.59"}, {"price":"0.3", "size":"107.8"}, {"price":"0.31", "size":"79.1"}, {"price":"0.32", "size":"107.19"}, {"price":"0.33", "size":"76.7"}, {"price":"0.34", "size":"89"}, {"price":"0.35", "size":"84.4"}, {"price":"0.36", "size":"86.99"}, {"price":"0.37", "size":"73.6"}, {"price":"0.38", "size":"85"}, {"price":"0.39", "size":"71.6"}, {"price":"0.4", "size":"88.3"}, {"price":"0.41", "size":"69.9"}, {"price":"0.42", "size":"142.27"}, {"price":"0.43", "size":"86.5"}, {"price":"0.44", "size":"91.08"}, {"price":"0.45", "size":"104.31"}, {"price":"0.46", "size":"80.1"}, {"price":"0.47", "size":"94.9"}, {"price":"0.48", "size":"88.8"}, {"price":"0.49", "size":"99.36"}, {"price":"0.5", "size":"102.8"}, {"price":"0.51", "size":"100.8"}, {"price":"0.52", "size":"100.8"}, {"price":"0.53", "size":"99.9"}, {"price":"0.54", "size":"92.1"}, {"price":"0.55", "size":"485.2"}, {"price":"0.56", "size":"105.4"}, {"price":"0.57", "size":"95.5"}, {"price":"0.58", "size":"111.12"}, {"price":"0.59", "size":"94.9"}, {"price":"0.6", "size":"182.58"}, {"price":"0.61", "size":"100.6"}, {"price":"0.62", "size":"115"}, {"price":"0.63", "size":"150.6"}, {"price":"0.64", "size":"482.99"}, {"price":"0.65", "size":"107.4"}, {"price":"0.66", "size":"133.24"}, {"price":"0.67", "size":"302.58"}, {"price":"0.68", "size":"106.29"}, {"price":"0.69", "size":"85.7"}, {"price":"0.7", "size":"100.04"}, {"price":"0.71", "size":"78"}, {"price":"0.72", "size":"279"}, {"price":"0.73", "size":"146.41"}, {"price":"0.74", "size":"146.85"}, {"price":"0.75", "size":"162.84"}, {"price":"0.76", "size":"175.24"}, {"price":"0.77", "size":"189.66"}, {"price":"0.78", "size":"228.41"}, {"price":"0.79", "size":"98.19"}, {"price":"0.8", "size":"185.84"}, {"price":"0.81", "size":"378.96"}], "asks":[{"price":"0.99", "size":"17919.98"}, {"price":"0.98", "size":"3156.06"}, {"price":"0.97", "size":"3788.29"}, {"price":"0.96", "size":"1529.1"}, {"price":"0.95", "size":"1723.6"}, {"price":"0.94", "size":"1221.35"}, {"price":"0.93", "size":"1167.2"}, {"price":"0.92", "size":"1310"}, {"price":"0.91", "size":"942.82"}, {"price":"0.9", "size":"618.32"}, {"price":"0.89", "size":"490.73"}, {"price":"0.88", "size":"247.17"}, {"price":"0.87", "size":"366.4"}, {"price":"0.86", "size":"164.34"}, {"price":"0.85", "size":"127.71"}, {"price":"0.84", "size":"81.17"}, {"price":"0.82", "size":"33.34"}], "hash":"8b11eddb45dc5c645a0afa6aed49cff182244b5e", "timestamp":"1784449595981", "event_type":"book"}
{"market":"0x982eae4503214e5d7992668e93f48f42e4707b92e23bb45f8d52d321f643cbe3", "asset_id":"37613674580450069178400687025689415665506452565086963049482350052080099056186", "bids":[{"price":"0.01", "size":"17919.98"}, {"price":"0.02", "size":"3156.06"}, {"price":"0.03", "size":"3788.29"}, {"price":"0.04", "size":"1529.1"}, {"price":"0.05", "size":"1723.6"}, {"price":"0.06", "size":"1221.35"}, {"price":"0.07", "size":"1167.2"}, {"price":"0.08", "size":"1310"}, {"price":"0.09", "size":"942.82"}, {"price":"0.1", "size":"618.32"}, {"price":"0.11", "size":"490.73"}, {"price":"0.12", "size":"247.17"}, {"price":"0.13", "size":"366.4"}, {"price":"0.14", "size":"164.34"}, {"price":"0.15", "size":"127.71"}, {"price":"0.16", "size":"81.17"}, {"price":"0.18", "size":"33.34"}], "asks":[{"price":"0.99", "size":"16284.13"}, {"price":"0.98", "size":"3289.11"}, {"price":"0.97", "size":"2085.95"}, {"price":"0.96", "size":"1462.1"}, {"price":"0.95", "size":"1953.67"}, {"price":"0.94", "size":"1377.35"}, {"price":"0.93", "size":"1155.2"}, {"price":"0.92", "size":"1325.88"}, {"price":"0.91", "size":"1027.7"}, {"price":"0.9", "size":"528.2"}, {"price":"0.89", "size":"454.1"}, {"price":"0.88", "size":"203.05"}, {"price":"0.87", "size":"179.4"}, {"price":"0.86", "size":"159.4"}, {"price":"0.85", "size":"149.23"}, {"price":"0.84", "size":"150.4"}, {"price":"0.83", "size":"105.08"}, {"price":"0.82", "size":"127.3"}, {"price":"0.81", "size":"99.78"}, {"price":"0.8", "size":"181.4"}, {"price":"0.79", "size":"111.5"}, {"price":"0.78", "size":"125.7"}, {"price":"0.77", "size":"92"}, {"price":"0.76", "size":"111.5"}, {"price":"0.75", "size":"843.6"}, {"price":"0.74", "size":"128.8"}, {"price":"0.73", "size":"86.7"}, {"price":"0.72", "size":"106.67"}, {"price":"0.71", "size":"84.59"}, {"price":"0.7", "size":"107.8"}, {"price":"0.69", "size":"79.1"}, {"price":"0.68", "size":"107.19"}, {"price":"0.67", "size":"76.7"}, {"price":"0.66", "size":"89"}, {"price":"0.65", "size":"84.4"}, {"price":"0.64", "size":"86.99"}, {"price":"0.63", "size":"73.6"}, {"price":"0.62", "size":"85"}, {"price":"0.61", "size":"71.6"}, {"price":"0.6", "size":"88.3"}, {"price":"0.59", "size":"69.9"}, {"price":"0.58", "size":"142.27"}, {"price":"0.57", "size":"86.5"}, {"price":"0.56", "size":"91.08"}, {"price":"0.55", "size":"104.31"}, {"price":"0.54", "size":"80.1"}, {"price":"0.53", "size":"94.9"}, {"price":"0.52", "size":"88.8"}, {"price":"0.51", "size":"99.36"}, {"price":"0.5", "size":"102.8"}, {"price":"0.49", "size":"100.8"}, {"price":"0.48", "size":"100.8"}, {"price":"0.47", "size":"99.9"}, {"price":"0.46", "size":"92.1"}, {"price":"0.45", "size":"485.2"}, {"price":"0.44", "size":"105.4"}, {"price":"0.43", "size":"95.5"}, {"price":"0.42", "size":"111.12"}, {"price":"0.41", "size":"94.9"}, {"price":"0.4", "size":"182.58"}, {"price":"0.39", "size":"100.6"}, {"price":"0.38", "size":"115"}, {"price":"0.37", "size":"150.6"}, {"price":"0.36", "size":"482.99"}, {"price":"0.35", "size":"107.4"}, {"price":"0.34", "size":"133.24"}, {"price":"0.33", "size":"302.58"}, {"price":"0.32", "size":"106.29"}, {"price":"0.31", "size":"85.7"}, {"price":"0.3", "size":"100.04"}, {"price":"0.29", "size":"78"}, {"price":"0.28", "size":"279"}, {"price":"0.27", "size":"146.41"}, {"price":"0.26", "size":"146.85"}, {"price":"0.25", "size":"162.84"}, {"price":"0.24", "size":"175.24"}, {"price":"0.23", "size":"189.66"}, {"price":"0.22", "size":"228.41"}, {"price":"0.21", "size":"98.19"}, {"price":"0.2", "size":"185.84"}, {"price":"0.19", "size":"378.96"}], "hash":"6eeab6be3f36f84cd790bd8373e24572309111c2", "timestamp":"1784449595981", "event_type":"book"}
{"market":"0x982eae4503214e5d7992668e93f48f42e4707b92e23bb45f8d52d321f643cbe3", "price_changes":[{"asset_id":"74913635031537477155015393896000154190746945075332596665612975928350948042868", "price":"0.76", "size":"170.24", "side":"BUY", "hash":"48fdb2010bfbd7f790fc30c57cc866d96765c7e3", "best_bid":"0.81", "best_ask":"0.82"}, {"asset_id":"37613674580450069178400687025689415665506452565086963049482350052080099056186", "price":"0.24", "size":"170.24", "side":"SELL", "hash":"706d34c4a555873b3356cdfbbb7d0dd7a9b51f23", "best_bid":"0.18", "best_ask":"0.19"}], "timestamp":"1784449595987", "event_type":"price_change"}
{"market":"0x982eae4503214e5d7992668e93f48f42e4707b92e23bb45f8d52d321f643cbe3", "price_changes":[{"asset_id":"37613674580450069178400687025689415665506452565086963049482350052080099056186", "price":"0.06", "size":"1201.35", "side":"BUY", "hash":"46e46dfbeebdfbd99fc9323e6467312b2b68f430", "best_bid":"0.18", "best_ask":"0.19"}, {"asset_id":"74913635031537477155015393896000154190746945075332596665612975928350948042868", "price":"0.94", "size":"1201.35", "side":"SELL", "hash":"edfae6c024b20d94509604a41d4583beb2ea9cec", "best_bid":"0.81", "best_ask":"0.82"}], "timestamp":"1784449595992", "event_type":"price_change"}
{"market":"0x982eae4503214e5d7992668e93f48f42e4707b92e23bb45f8d52d321f643cbe3", "price_changes":[{"asset_id":"74913635031537477155015393896000154190746945075332596665612975928350948042868", "price":"0.01", "size":"16184.13", "side":"BUY", "hash":"6b3019fce3d3cfb12ab7dfbf3cc73d1cccc2d8d8", "best_bid":"0.81", "best_ask":"0.82"}, {"asset_id":"37613674580450069178400687025689415665506452565086963049482350052080099056186", "price":"0.99", "size":"16184.13", "side":"SELL", "hash":"b7af64661020d31f4f1dd74ee0126485d9d6d0a9", "best_bid":"0.18", "best_ask":"0.19"}], "timestamp":"1784449595993", "event_type":"price_change"}
{"market":"0x982eae4503214e5d7992668e93f48f42e4707b92e23bb45f8d52d321f643cbe3", "price_changes":[{"asset_id":"74913635031537477155015393896000154190746945075332596665612975928350948042868", "price":"0.73", "size":"141.41", "side":"BUY", "hash":"4e8a5279151b9e4ff85311d7c073c249417b24f2", "best_bid":"0.81", "best_ask":"0.82"}, {"asset_id":"37613674580450069178400687025689415665506452565086963049482350052080099056186", "price":"0.27", "size":"141.41", "side":"SELL", "hash":"e669e54f7630659fc6744c288ac2217e535bd0cf", "best_bid":"0.18", "best_ask":"0.19"}], "timestamp":"1784449595998", "event_type":"price_change"}
{"market":"0x982eae4503214e5d7992668e93f48f42e4707b92e23bb45f8d52d321f643cbe3", "price_changes":[{"asset_id":"74913635031537477155015393896000154190746945075332596665612975928350948042868", "price":"0.72", "size":"271", "side":"BUY", "hash":"4e8a5279151b9e4ff85311d7c073c249417b24f2", "best_bid":"0.81", "best_ask":"0.82"}, {"asset_id":"37613674580450069178400687025689415665506452565086963049482350052080099056186", "price":"0.28", "size":"271", "side":"SELL", "hash":"e669e54f7630659fc6744c288ac2217e535bd0cf", "best_bid":"0.18", "best_ask":"0.19"}], "timestamp":"1784449595998", "event_type":"price_change"}
{"market":"0x982eae4503214e5d7992668e93f48f42e4707b92e23bb45f8d52d321f643cbe3", "price_changes":[{"asset_id":"74913635031537477155015393896000154190746945075332596665612975928350948042868", "price":"0.71", "size":"66", "side":"BUY", "hash":"4e8a5279151b9e4ff85311d7c073c249417b24f2", "best_bid":"0.81", "best_ask":"0.82"}, {"asset_id":"37613674580450069178400687025689415665506452565086963049482350052080099056186", "price":"0.29", "size":"66", "side":"SELL", "hash":"e669e54f7630659fc6744c288ac2217e535bd0cf", "best_bid":"0.18", "best_ask":"0.19"}], "timestamp":"1784449595998", "event_type":"price_change"}
{"market":"0x982eae4503214e5d7992668e93f48f42e4707b92e23bb45f8d52d321f643cbe3", "price_changes":[{"asset_id":"74913635031537477155015393896000154190746945075332596665612975928350948042868", "price":"0.7", "size":"82.04", "side":"BUY", "hash":"4e8a5279151b9e4ff85311d7c073c249417b24f2", "best_bid":"0.81", "best_ask":"0.82"}, {"asset_id":"37613674580450069178400687025689415665506452565086963049482350052080099056186", "price":"0.3", "size":"82.04", "side":"SELL", "hash":"e669e54f7630659fc6744c288ac2217e535bd0cf", "best_bid":"0.18", "best_ask":"0.19"}], "timestamp":"1784449595998", "event_type":"price_change"}
{"market":"0x982eae4503214e5d7992668e93f48f42e4707b92e23bb45f8d52d321f643cbe3", "price_changes":[{"asset_id":"74913635031537477155015393896000154190746945075332596665612975928350948042868", "price":"0.06", "size":"1677.35", "side":"BUY", "hash":"d1ecbf2d68689c2e19fd30554dc47358e82d69fa", "best_bid":"0.81", "best_ask":"0.82"}, {"asset_id":"37613674580450069178400687025689415665506452565086963049482350052080099056186", "price":"0.94", "size":"1677.35", "side":"SELL", "hash":"b5b62bc1965475af0ca71df6c4c6a4166116e659", "best_bid":"0.18", "best_ask":"0.19"}], "timestamp":"1784449596003", "event_type":"price_change"}
{"market":"0x982eae4503214e5d7992668e93f48f42e4707b92e23bb45f8d52d321f643cbe3", "price_changes":[{"asset_id":"74913635031537477155015393896000154190746945075332596665612975928350948042868", "price":"0.01", "size":"16684.13", "side":"BUY", "hash":"aeb4df4ec47ccc34a474f4f98e630047c8f5d9ca", "best_bid":"0.81", "best_ask":"0.82"}, {"asset_id":"37613674580450069178400687025689415665506452565086963049482350052080099056186", "price":"0.99", "size":"16684.13", "side":"SELL", "hash":"da76a47d312df0fb1247cc5997e0780533851e08", "best_bid":"0.18", "best_ask":"0.19"}], "timestamp":"1784449596013", "event_type":"price_change"}
{"market":"0x982eae4503214e5d7992668e93f48f42e4707b92e23bb45f8d52d321f643cbe3", "price_changes":[{"asset_id":"74913635031537477155015393896000154190746945075332596665612975928350948042868", "price":"0.73", "size":"151.41", "side":"BUY", "hash":"e95ddfb8ba97601d684f4776bbcc88dd45919c59", "best_bid":"0.81", "best_ask":"0.82"}, {"asset_id":"37613674580450069178400687025689415665506452565086963049482350052080099056186", "price":"0.27", "size":"151.41", "side":"SELL", "hash":"5e3c2b3936f37d21ee47229bf2eec0573677048b", "best_bid":"0.18", "best_ask":"0.19"}], "timestamp":"1784449596022", "event_type":"price_change"}
{"market":"0x982eae4503214e5d7992668e93f48f42e4707b92e23bb45f8d52d321f643cbe3", "price_changes":[{"asset_id":"74913635031537477155015393896000154190746945075332596665612975928350948042868", "price":"0.73", "size":"146.41", "side":"BUY", "hash":"ce23b21649a74daee3aa0f54bbe66fedbad4cfaf", "best_bid":"0.81", "best_ask":"0.82"}, {"asset_id":"37613674580450069178400687025689415665506452565086963049482350052080099056186", "price":"0.27", "size":"146.41", "side":"SELL", "hash":"5cf3384c469655193b4c54dea867204cb2f5ee48", "best_bid":"0.18", "best_ask":"0.19"}], "timestamp":"1784449596023", "event_type":"price_change"}
{"market":"0x982eae4503214e5d7992668e93f48f42e4707b92e23bb45f8d52d321f643cbe3", "price_changes":[{"asset_id":"74913635031537477155015393896000154190746945075332596665612975928350948042868", "price":"0.71", "size":"84", "side":"BUY", "hash":"c699e0b3811d7fe881978b92cfdc59f8e08fb71a", "best_bid":"0.81", "best_ask":"0.82"}, {"asset_id":"37613674580450069178400687025689415665506452565086963049482350052080099056186", "price":"0.29", "size":"84", "side":"SELL", "hash":"fafaab2da681d0e63f6ab6249a06fac1ef2cf71a", "best_bid":"0.18", "best_ask":"0.19"}], "timestamp":"1784449596029", "event_type":"price_change"}
{"market":"0x982eae4503214e5d7992668e93f48f42e4707b92e23bb45f8d52d321f643cbe3", "price_changes":[{"asset_id":"74913635031537477155015393896000154190746945075332596665612975928350948042868", "price":"0.01", "size":"16679.13", "side":"BUY", "hash":"76548b5adac131ff292a8fbf5684e4e6fdf60dac", "best_bid":"0.81", "best_ask":"0.82"}, {"asset_id":"37613674580450069178400687025689415665506452565086963049482350052080099056186", "price":"0.99", "size":"16679.13", "side":"SELL", "hash":"3667668d323a2aaa6b4dfc159d060421840a3eab", "best_bid":"0.18", "best_ask":"0.19"}], "timestamp":"1784449596029", "event_type":"price_change"}
{"market":"0x982eae4503214e5d7992668e93f48f42e4707b92e23bb45f8d52d321f643cbe3", "price_changes":[{"asset_id":"74913635031537477155015393896000154190746945075332596665612975928350948042868", "price":"0.01", "size":"16674.13", "side":"BUY", "hash":"c98df860a2ff249993fa3a297df6b117c90a38ce", "best_bid":"0.81", "best_ask":"0.82"}, {"asset_id":"37613674580450069178400687025689415665506452565086963049482350052080099056186", "price":"0.99", "size":"16674.13", "side":"SELL", "hash":"e68648e069f145a24aee88f0b8a76552ce12535c", "best_bid":"0.18", "best_ask":"0.19"}], "timestamp":"1784449596030", "event_type":"price_change"}
{"market":"0x982eae4503214e5d7992668e93f48f42e4707b92e23bb45f8d52d321f643cbe3", "price_changes":[{"asset_id":"74913635031537477155015393896000154190746945075332596665612975928350948042868", "price":"0.04", "size":"1467.1", "side":"BUY", "hash":"6386031fab9236d52b5998e517bb682c058cdbcc", "best_bid":"0.81", "best_ask":"0.82"}, {"asset_id":"37613674580450069178400687025689415665506452565086963049482350052080099056186", "price":"0.96", "size":"1467.1", "side":"SELL", "hash":"e586d93e17ee3c8056ffb41912fd1c77fa6c72f0", "best_bid":"0.18", "best_ask":"0.19"}], "timestamp":"1784449596030", "event_type":"price_change"}
{"market":"0x982eae4503214e5d7992668e93f48f42e4707b92e23bb45f8d52d321f643cbe3", "price_changes":[{"asset_id":"74913635031537477155015393896000154190746945075332596665612975928350948042868", "price":"0.01", "size":"16669.13", "side":"BUY", "hash":"d7ebc53d4ed3f294ab71c14b80b5ba25bf57e421", "best_bid":"0.81", "best_ask":"0.82"}, {"asset_id":"37613674580450069178400687025689415665506452565086963049482350052080099056186", "price":"0.99", "size":"16669.13", "side":"SELL", "hash":"213c5bd39b330f5da14dd1a94b4db529f9f890e1", "best_bid":"0.18", "best_ask":"0.19"}], "timestamp":"1784449596032", "event_type":"price_change"}
{"market":"0x982eae4503214e5d7992668e93f48f42e4707b92e23bb45f8d52d321f643cbe3", "price_changes":[{"asset_id":"37613674580450069178400687025689415665506452565086963049482350052080099056186", "price":"0.01", "size":"17924.98", "side":"BUY", "hash":"9254769d152111e9c20092ffbe1a0db52ae1bb45", "best_bid":"0.18", "best_ask":"0.19"}, {"asset_id":"74913635031537477155015393896000154190746945075332596665612975928350948042868", "price":"0.99", "size":"17924.98", "side":"SELL", "hash":"269ec2097c669aef5c81e9291810a76af3c50162", "best_bid":"0.81", "best_ask":"0.82"}], "timestamp":"1784449596032", "event_type":"price_change"}
{"market":"0x982eae4503214e5d7992668e93f48f42e4707b92e23bb45f8d52d321f643cbe3", "price_changes":[{"asset_id":"37613674580450069178400687025689415665506452565086963049482350052080099056186", "price":"0.01", "size":"17929.98", "side":"BUY", "hash":"0c2d79148af4587c4ec88bcbafd8f30b2adbd919", "best_bid":"0.18", "best_ask":"0.19"}, {"asset_id":"74913635031537477155015393896000154190746945075332596665612975928350948042868", "price":"0.99", "size":"17929.98", "side":"SELL", "hash":"c21547ff764b77a2f28b87f370a9ef5fd718df87", "best_bid":"0.81", "best_ask":"0.82"}], "timestamp":"1784449596033", "event_type":"price_change"}
{"market":"0x982eae4503214e5d7992668e93f48f42e4707b92e23bb45f8d52d321f643cbe3", "price_changes":[{"asset_id":"37613674580450069178400687025689415665506452565086963049482350052080099056186", "price":"0.01", "size":"17934.98", "side":"BUY", "hash":"e22122d992156ccc90321b5d9ee0c9f4ca2989d2", "best_bid":"0.18", "best_ask":"0.19"}, {"asset_id":"74913635031537477155015393896000154190746945075332596665612975928350948042868", "price":"0.99", "size":"17934.98", "side":"SELL", "hash":"49c82fb4e3ca16d4775124d5d3ebc585ab087464", "best_bid":"0.81", "best_ask":"0.82"}], "timestamp":"1784449596033", "event_type":"price_change"}
{"market":"0x982eae4503214e5d7992668e93f48f42e4707b92e23bb45f8d52d321f643cbe3", "price_changes":[{"asset_id":"37613674580450069178400687025689415665506452565086963049482350052080099056186", "price":"0.01", "size":"17939.98", "side":"BUY", "hash":"fcf7813be69cbc3e5490af12735100f69750f375", "best_bid":"0.18", "best_ask":"0.19"}, {"asset_id":"74913635031537477155015393896000154190746945075332596665612975928350948042868", "price":"0.99", "size":"17939.98", "side":"SELL", "hash":"a0caabad2197681bd0d8583182e1a75b2a982912", "best_bid":"0.81", "best_ask":"0.82"}], "timestamp":"1784449596034", "event_type":"price_change"}
{"market":"0x982eae4503214e5d7992668e93f48f42e4707b92e23bb45f8d52d321f643cbe3", "price_changes":[{"asset_id":"74913635031537477155015393896000154190746945075332596665612975928350948042868", "price":"0.74", "size":"151.85", "side":"BUY", "hash":"36b6b031976a9661c076bd407d8b155ffad91b34", "best_bid":"0.81", "best_ask":"0.82"}, {"asset_id":"37613674580450069178400687025689415665506452565086963049482350052080099056186", "price":"0.26", "size":"151.85", "side":"SELL", "hash":"1a1f877d02d124125a13d8bf405a54469463e5fc", "best_bid":"0.18", "best_ask":"0.19"}], "timestamp":"1784449596035", "event_type":"price_change"}
{"market":"0x982eae4503214e5d7992668e93f48f42e4707b92e23bb45f8d52d321f643cbe3", "price_changes":[{"asset_id":"37613674580450069178400687025689415665506452565086963049482350052080099056186", "price":"0.01", "size":"17944.98", "side":"BUY", "hash":"99171bcabd161972df27443eb585f12ee65487c6", "best_bid":"0.18", "best_ask":"0.19"}, {"asset_id":"74913635031537477155015393896000154190746945075332596665612975928350948042868", "price":"0.99", "size":"17944.98", "side":"SELL", "hash":"2621cc0353ebe1e5cba84930498ec42ef0e1e714", "best_bid":"0.81", "best_ask":"0.82"}], "timestamp":"1784449596036", "event_type":"price_change"}
{"market":"0x982eae4503214e5d7992668e93f48f42e4707b92e23bb45f8d52d321f643cbe3", "price_changes":[{"asset_id":"74913635031537477155015393896000154190746945075332596665612975928350948042868", "price":"0.01", "size":"16674.13", "side":"BUY", "hash":"902f2d6e48960cb8224199258f5be203ac0ab082", "best_bid":"0.81", "best_ask":"0.82"}, {"asset_id":"37613674580450069178400687025689415665506452565086963049482350052080099056186", "price":"0.99", "size":"16674.13", "side":"SELL", "hash":"7fc7c0023db427ea747ec38084036817da29afd4", "best_bid":"0.18", "best_ask":"0.19"}], "timestamp":"1784449596037", "event_type":"price_change"}
{"market":"0x982eae4503214e5d7992668e93f48f42e4707b92e23bb45f8d52d321f643cbe3", "price_changes":[{"asset_id":"74913635031537477155015393896000154190746945075332596665612975928350948042868", "price":"0.01", "size":"16679.13", "side":"BUY", "hash":"ab3cccb52749fbeeb1959a451107244d5e1839e5", "best_bid":"0.81", "best_ask":"0.82"}, {"asset_id":"37613674580450069178400687025689415665506452565086963049482350052080099056186", "price":"0.99", "size":"16679.13", "side":"SELL", "hash":"92fa07cceba11e8f5083a274a29b1c10d9cb52b3", "best_bid":"0.18", "best_ask":"0.19"}], "timestamp":"1784449596038", "event_type":"price_change"}
{"market":"0x982eae4503214e5d7992668e93f48f42e4707b92e23bb45f8d52d321f643cbe3", "price_changes":[{"asset_id":"74913635031537477155015393896000154190746945075332596665612975928350948042868", "price":"0.01", "size":"16779.13", "side":"BUY", "hash":"d9c7dc46f0b3eea1e4de00d1d97b393ec0032214", "best_bid":"0.81", "best_ask":"0.82"}, {"asset_id":"37613674580450069178400687025689415665506452565086963049482350052080099056186", "price":"0.99", "size":"16779.13", "side":"SELL", "hash":"70f02dac11fd9514a8b9aaa67a1d500f10231b03", "best_bid":"0.18", "best_ask":"0.19"}], "timestamp":"1784449596038", "event_type":"price_change"}
{"market":"0x982eae4503214e5d7992668e93f48f42e4707b92e23bb45f8d52d321f643cbe3", "price_changes":[{"asset_id":"74913635031537477155015393896000154190746945075332596665612975928350948042868", "price":"0.73", "size":"154.41", "side":"BUY", "hash":"83bd56a999aaa2ea966b982dffe57c6b0d7f2db4", "best_bid":"0.81", "best_ask":"0.82"}, {"asset_id":"37613674580450069178400687025689415665506452565086963049482350052080099056186", "price":"0.27", "size":"154.41", "side":"SELL", "hash":"c3ee6216c82a6e212cb5ed312fa156c0e7a686de", "best_bid":"0.18", "best_ask":"0.19"}], "timestamp":"1784449596039", "event_type":"price_change"}
{"market":"0x982eae4503214e5d7992668e93f48f42e4707b92e23bb45f8d52d321f643cbe3", "price_changes":[{"asset_id":"74913635031537477155015393896000154190746945075332596665612975928350948042868", "price":"0.01", "size":"16784.13", "side":"BUY", "hash":"4e35fa387bd3dc4fb113031f016f5094f801ba0d", "best_bid":"0.81", "best_ask":"0.82"}, {"asset_id":"37613674580450069178400687025689415665506452565086963049482350052080099056186", "price":"0.99", "size":"16784.13", "side":"SELL", "hash":"9a33415f9c7b2405a3f920dadfaa6381ca236126", "best_bid":"0.18", "best_ask":"0.19"}], "timestamp":"1784449596040", "event_type":"price_change"}
{"market":"0x982eae4503214e5d7992668e93f48f42e4707b92e23bb45f8d52d321f643cbe3", "price_changes":[{"asset_id":"74913635031537477155015393896000154190746945075332596665612975928350948042868", "price":"0.72", "size":"283", "side":"BUY", "hash":"f4b6d4f4346c6086f57b143b2145af11ed9f219a", "best_bid":"0.81", "best_ask":"0.82"}, {"asset_id":"37613674580450069178400687025689415665506452565086963049482350052080099056186", "price":"0.28", "size":"283", "side":"SELL", "hash":"767d1180fd192ab3d65f625c52ee0a5f08e1d707", "best_bid":"0.18", "best_ask":"0.19"}], "timestamp":"1784449596041", "event_type":"price_change"}
{"market":"0x982eae4503214e5d7992668e93f48f42e4707b92e23bb45f8d52d321f643cbe3", "price_changes":[{"asset_id":"74913635031537477155015393896000154190746945075332596665612975928350948042868", "price":"0.01", "size":"16789.13", "side":"BUY", "hash":"1dc2a78a0be357df4f67ea97eb5a5ad4eb5b39ef", "best_bid":"0.81", "best_ask":"0.82"}, {"asset_id":"37613674580450069178400687025689415665506452565086963049482350052080099056186", "price":"0.99", "size":"16789.13", "side":"SELL", "hash":"5ec5065e930f525c7ec74ddee517022add5dc35c", "best_bid":"0.18", "best_ask":"0.19"}], "timestamp":"1784449596042", "event_type":"price_change"}
{"market":"0x982eae4503214e5d7992668e93f48f42e4707b92e23bb45f8d52d321f643cbe3", "price_changes":[{"asset_id":"37613674580450069178400687025689415665506452565086963049482350052080099056186", "price":"0.13", "size":"386.4", "side":"BUY", "hash":"413156884518ef6e3925fbb9ce7744623f695550", "best_bid":"0.18", "best_ask":"0.19"}, {"asset_id":"74913635031537477155015393896000154190746945075332596665612975928350948042868", "price":"0.87", "size":"386.4", "side":"SELL", "hash":"8f8a2c36e960623e6977415ca141056265785e65", "best_bid":"0.81", "best_ask":"0.82"}], "timestamp":"1784449596054", "event_type":"price_change"}
{"market":"0x982eae4503214e5d7992668e93f48f42e4707b92e23bb45f8d52d321f643cbe3", "price_changes":[{"asset_id":"37613674580450069178400687025689415665506452565086963049482350052080099056186", "price":"0.27", "size":"159.41", "side":"SELL", "hash":"dba46319a3bfc1de9b9c823a5360036f8fd6e742", "best_bid":"0.18", "best_ask":"0.19"}, {"asset_id":"74913635031537477155015393896000154190746945075332596665612975928350948042868", "price":"0.73", "size":"159.41", "side":"BUY", "hash":"4c7a07584d1ec809879e84304a8eb69889576adf", "best_bid":"0.81", "best_ask":"0.82"}], "timestamp":"1784449596056", "event_type":"price_change"}
{"market":"0x982eae4503214e5d7992668e93f48f42e4707b92e23bb45f8d52d321f643cbe3", "price_changes":[{"asset_id":"74913635031537477155015393896000154190746945075332596665612975928350948042868", "price":"0.01", "size":"16784.13", "side":"BUY", "hash":"dba71bee4c400d64230cc1ec1a3a76fcb8a1a21f", "best_bid":"0.81", "best_ask":"0.82"}, {"asset_id":"37613674580450069178400687025689415665506452565086963049482350052080099056186", "price":"0.99", "size":"16784.13", "side":"SELL", "hash":"43248a3bf65b62e5e9b68fc2fdfd9af8f5afc4d8", "best_bid":"0.18", "best_ask":"0.19"}], "timestamp":"1784449596060", "event_type":"price_change"}
{"market":"0x982eae4503214e5d7992668e93f48f42e4707b92e23bb45f8d52d321f643cbe3", "price_changes":[{"asset_id":"74913635031537477155015393896000154190746945075332596665612975928350948042868", "price":"0.62", "size":"125", "side":"BUY", "hash":"81e9219d240f64c21bb45bd8ee05fc559859a184", "best_bid":"0.81", "best_ask":"0.82"}, {"asset_id":"37613674580450069178400687025689415665506452565086963049482350052080099056186", "price":"0.38", "size":"125", "side":"SELL", "hash":"8f607b0d7fefb17ca3e9e03a7389d43fa46c5614", "best_bid":"0.18", "best_ask":"0.19"}], "timestamp":"1784449596061", "event_type":"price_change"}
{"market":"0x982eae4503214e5d7992668e93f48f42e4707b92e23bb45f8d52d321f643cbe3", "price_changes":[{"asset_id":"74913635031537477155015393896000154190746945075332596665612975928350948042868", "price":"0.01", "size":"16789.14", "side":"BUY", "hash":"81ba6a468b25dc6d3dc7fac20c547915f803ce35", "best_bid":"0.81", "best_ask":"0.82"}, {"asset_id":"37613674580450069178400687025689415665506452565086963049482350052080099056186", "price":"0.99", "size":"16789.14", "side":"SELL", "hash":"acd6eb558183983c218cf10137248faf88d2917a", "best_bid":"0.18", "best_ask":"0.19"}], "timestamp":"1784449596065", "event_type":"price_change"}
{"market":"0x982eae4503214e5d7992668e93f48f42e4707b92e23bb45f8d52d321f643cbe3", "price_changes":[{"asset_id":"74913635031537477155015393896000154190746945075332596665612975928350948042868", "price":"0.01", "size":"16784.14", "side":"BUY", "hash":"c3608b23acaf05a024e31145888111b6a32b05c1", "best_bid":"0.81", "best_ask":"0.82"}, {"asset_id":"37613674580450069178400687025689415665506452565086963049482350052080099056186", "price":"0.99", "size":"16784.14", "side":"SELL", "hash":"4c984e50e2a8ed129b87f4602ec33ef9a3a312ca", "best_bid":"0.18", "best_ask":"0.19"}], "timestamp":"1784449596065", "event_type":"price_change"}
{"market":"0x982eae4503214e5d7992668e93f48f42e4707b92e23bb45f8d52d321f643cbe3", "price_changes":[{"asset_id":"37613674580450069178400687025689415665506452565086963049482350052080099056186", "price":"0.44", "size":"95.4", "side":"SELL", "hash":"f3c5c1599dd13cf84c355b1e208a2ffaa1eb42f9", "best_bid":"0.18", "best_ask":"0.19"}, {"asset_id":"74913635031537477155015393896000154190746945075332596665612975928350948042868", "price":"0.56", "size":"95.4", "side":"BUY", "hash":"632b2595e26bfffd773d9ca39267ac0eed7585e2", "best_bid":"0.81", "best_ask":"0.82"}], "timestamp":"1784449596065", "event_type":"price_change"}
{"market":"0x982eae4503214e5d7992668e93f48f42e4707b92e23bb45f8d52d321f643cbe3", "price_changes":[{"asset_id":"37613674580450069178400687025689415665506452565086963049482350052080099056186", "price":"0.01", "size":"17939.98", "side":"BUY", "hash":"ee6f037b0f399ff76312218b895e276b485ba0e4", "best_bid":"0.18", "best_ask":"0.19"}, {"asset_id":"74913635031537477155015393896000154190746945075332596665612975928350948042868", "price":"0.99", "size":"17939.98", "side":"SELL", "hash":"394833764360f3ef24327c7a78bc0e731f09399b", "best_bid":"0.81", "best_ask":"0.82"}], "timestamp":"1784449596072", "event_type":"price_change"}
{"market":"0x982eae4503214e5d7992668e93f48f42e4707b92e23bb45f8d52d321f643cbe3", "price_changes":[{"asset_id":"74913635031537477155015393896000154190746945075332596665612975928350948042868", "price":"0.69", "size":"97.9", "side":"BUY", "hash":"79e0bb5c12cd18eab8b25dd85bee6e8120cedcf3", "best_bid":"0.81", "best_ask":"0.82"}, {"asset_id":"37613674580450069178400687025689415665506452565086963049482350052080099056186", "price":"0.31", "size":"97.9", "side":"SELL", "hash":"e3bb3b7b53cb1d5ada6f968e8582877adbdcd6c9", "best_bid":"0.18", "best_ask":"0.19"}], "timestamp":"1784449596076", "event_type":"price_change"}
{"market":"0x982eae4503214e5d7992668e93f48f42e4707b92e23bb45f8d52d321f643cbe3", "price_changes":[{"asset_id":"37613674580450069178400687025689415665506452565086963049482350052080099056186", "price":"0.18", "size":"23.34", "side":"BUY", "hash":"0ba16aca49d3e91673bb87cf872e0de70ba0251e", "best_bid":"0.18", "best_ask":"0.19"}, {"asset_id":"74913635031537477155015393896000154190746945075332596665612975928350948042868", "price":"0.82", "size":"23.34", "side":"SELL", "hash":"1123d10ceecf884f2a115a27c0aaddf008ba93a0", "best_bid":"0.81", "best_ask":"0.82"}], "timestamp":"1784449596078", "event_type":"price_change"}
{"market":"0x982eae4503214e5d7992668e93f48f42e4707b92e23bb45f8d52d321f643cbe3", "asset_id":"74913635031537477155015393896000154190746945075332596665612975928350948042868", "bids":[{"price":"0.01", "size":"16784.14"}, {"price":"0.02", "size":"3289.11"}, {"price":"0.03", "size":"2085.95"}, {"price":"0.04", "size":"1467.1"}, {"price":"0.05", "size":"1953.67"}, {"price":"0.06", "size":"1677.35"}, {"price":"0.07", "size":"1155.2"}, {"price":"0.08", "size":"1325.88"}, {"price":"0.09", "size":"1027.7"}, {"price":"0.1", "size":"528.2"}, {"price":"0.11", "size":"454.1"}, {"price":"0.12", "size":"203.05"}, {"price":"0.13", "size":"179.4"}, {"price":"0.14", "size":"159.4"}, {"price":"0.15", "size":"149.23"}, {"price":"0.16", "size":"150.4"}, {"price":"0.17", "size":"105.08"}, {"price":"0.18", "size":"127.3"}, {"price":"0.19", "size":"99.78"}, {"price":"0.2", "size":"181.4"}, {"price":"0.21", "size":"111.5"}, {"price":"0.22", "size":"125.7"}, {"price":"0.23", "size":"92"}, {"price":"0.24", "size":"111.5"}, {"price":"0.25", "size":"843.6"}, {"price":"0.26", "size":"128.8"}, {"price":"0.27", "size":"86.7"}, {"price":"0.28", "size":"106.67"}, {"price":"0.29", "size":"84.59"}, {"price":"0.3", "size":"107.8"}, {"price":"0.31", "size":"79.1"}, {"price":"0.32", "size":"107.19"}, {"price":"0.33", "size":"76.7"}, {"price":"0.34", "size":"89"}, {"price":"0.35", "size":"84.4"}, {"price":"0.36", "size":"86.99"}, {"price":"0.37", "size":"73.6"}, {"price":"0.38", "size":"85"}, {"price":"0.39", "size":"71.6"}, {"price":"0.4", "size":"88.3"}, {"price":"0.41", "size":"69.9"}, {"price":"0.42", "size":"142.27"}, {"price":"0.43", "size":"86.5"}, {"price":"0.44", "size":"91.08"}, {"price":"0.45", "size":"104.31"}, {"price":"0.46", "size":"80.1"}, {"price":"0.47", "size":"94.9"}, {"price":"0.48", "size":"88.8"}, {"price":"0.49", "size":"99.36"}, {"price":"0.5", "size":"102.8"}, {"price":"0.51", "size":"100.8"}, {"price":"0.52", "size":"100.8"}, {"price":"0.53", "size":"99.9"}, {"price":"0.54", "size":"92.1"}, {"price":"0.55", "size":"485.2"}, {"price":"0.56", "size":"95.4"}, {"price":"0.57", "size":"95.5"}, {"price":"0.58", "size":"111.12"}, {"price":"0.59", "size":"94.9"}, {"price":"0.6", "size":"182.58"}, {"price":"0.61", "size":"100.6"}, {"price":"0.62", "size":"125"}, {"price":"0.63", "size":"150.6"}, {"price":"0.64", "size":"482.99"}, {"price":"0.65", "size":"107.4"}, {"price":"0.66", "size":"133.24"}, {"price":"0.67", "size":"302.58"}, {"price":"0.68", "size":"106.29"}, {"price":"0.69", "size":"97.9"}, {"price":"0.7", "size":"82.04"}, {"price":"0.71", "size":"84"}, {"price":"0.72", "size":"283"}, {"price":"0.73", "size":"159.41"}, {"price":"0.74", "size":"151.85"}, {"price":"0.75", "size":"162.84"}, {"price":"0.76", "size":"170.24"}, {"price":"0.77", "size":"189.66"}, {"price":"0.78", "size":"228.41"}, {"price":"0.79", "size":"98.19"}, {"price":"0.8", "size":"185.84"}, {"price":"0.81", "size":"378.96"}], "asks":[{"price":"0.99", "size":"17939.98"}, {"price":"0.98", "size":"3156.06"}, {"price":"0.97", "size":"3788.29"}, {"price":"0.96", "size":"1529.1"}, {"price":"0.95", "size":"1723.6"}, {"price":"0.94", "size":"1201.35"}, {"price":"0.93", "size":"1167.2"}, {"price":"0.92", "size":"1310"}, {"price":"0.91", "size":"942.82"}, {"price":"0.9", "size":"618.32"}, {"price":"0.89", "size":"490.73"}, {"price":"0.88", "size":"247.17"}, {"price":"0.87", "size":"386.4"}, {"price":"0.86", "size":"164.34"}, {"price":"0.85", "size":"127.71"}, {"price":"0.84", "size":"81.17"}, {"price":"0.82", "size":"23.34"}], "hash":"1123d10ceecf884f2a115a27c0aaddf008ba93a0", "timestamp":"1784449596078", "event_type":"book"}
{"market":"0x982eae4503214e5d7992668e93f48f42e4707b92e23bb45f8d52d321f643cbe3", "asset_id":"37613674580450069178400687025689415665506452565086963049482350052080099056186", "bids":[{"price":"0.01", "size":"17939.98"}, {"price":"0.02", "size":"3156.06"}, {"price":"0.03", "size":"3788.29"}, {"price":"0.04", "size":"1529.1"}, {"price":"0.05", "size":"1723.6"}, {"price":"0.06", "size":"1201.35"}, {"price":"0.07", "size":"1167.2"}, {"price":"0.08", "size":"1310"}, {"price":"0.09", "size":"942.82"}, {"price":"0.1", "size":"618.32"}, {"price":"0.11", "size":"490.73"}, {"price":"0.12", "size":"247.17"}, {"price":"0.13", "size":"386.4"}, {"price":"0.14", "size":"164.34"}, {"price":"0.15", "size":"127.71"}, {"price":"0.16", "size":"81.17"}, {"price":"0.18", "size":"23.34"}], "asks":[{"price":"0.99", "size":"16784.14"}, {"price":"0.98", "size":"3289.11"}, {"price":"0.97", "size":"2085.95"}, {"price":"0.96", "size":"1467.1"}, {"price":"0.95", "size":"1953.67"}, {"price":"0.94", "size":"1677.35"}, {"price":"0.93", "size":"1155.2"}, {"price":"0.92", "size":"1325.88"}, {"price":"0.91", "size":"1027.7"}, {"price":"0.9", "size":"528.2"}, {"price":"0.89", "size":"454.1"}, {"price":"0.88", "size":"203.05"}, {"price":"0.87", "size":"179.4"}, {"price":"0.86", "size":"159.4"}, {"price":"0.85", "size":"149.23"}, {"price":"0.84", "size":"150.4"}, {"price":"0.83", "size":"105.08"}, {"price":"0.82", "size":"127.3"}, {"price":"0.81", "size":"99.78"}, {"price":"0.8", "size":"181.4"}, {"price":"0.79", "size":"111.5"}, {"price":"0.78", "size":"125.7"}, {"price":"0.77", "size":"92"}, {"price":"0.76", "size":"111.5"}, {"price":"0.75", "size":"843.6"}, {"price":"0.74", "size":"128.8"}, {"price":"0.73", "size":"86.7"}, {"price":"0.72", "size":"106.67"}, {"price":"0.71", "size":"84.59"}, {"price":"0.7", "size":"107.8"}, {"price":"0.69", "size":"79.1"}, {"price":"0.68", "size":"107.19"}, {"price":"0.67", "size":"76.7"}, {"price":"0.66", "size":"89"}, {"price":"0.65", "size":"84.4"}, {"price":"0.64", "size":"86.99"}, {"price":"0.63", "size":"73.6"}, {"price":"0.62", "size":"85"}, {"price":"0.61", "size":"71.6"}, {"price":"0.6", "size":"88.3"}, {"price":"0.59", "size":"69.9"}, {"price":"0.58", "size":"142.27"}, {"price":"0.57", "size":"86.5"}, {"price":"0.56", "size":"91.08"}, {"price":"0.55", "size":"104.31"}, {"price":"0.54", "size":"80.1"}, {"price":"0.53", "size":"94.9"}, {"price":"0.52", "size":"88.8"}, {"price":"0.51", "size":"99.36"}, {"price":"0.5", "size":"102.8"}, {"price":"0.49", "size":"100.8"}, {"price":"0.48", "size":"100.8"}, {"price":"0.47", "size":"99.9"}, {"price":"0.46", "size":"92.1"}, {"price":"0.45", "size":"485.2"}, {"price":"0.44", "size":"95.4"}, {"price":"0.43", "size":"95.5"}, {"price":"0.42", "size":"111.12"}, {"price":"0.41", "size":"94.9"}, {"price":"0.4", "size":"182.58"}, {"price":"0.39", "size":"100.6"}, {"price":"0.38", "size":"125"}, {"price":"0.37", "size":"150.6"}, {"price":"0.36", "size":"482.99"}, {"price":"0.35", "size":"107.4"}, {"price":"0.34", "size":"133.24"}, {"price":"0.33", "size":"302.58"}, {"price":"0.32", "size":"106.29"}, {"price":"0.31", "size":"97.9"}, {"price":"0.3", "size":"82.04"}, {"price":"0.29", "size":"84"}, {"price":"0.28", "size":"283"}, {"price":"0.27", "size":"159.41"}, {"price":"0.26", "size":"151.85"}, {"price":"0.25", "size":"162.84"}, {"price":"0.24", "size":"170.24"}, {"price":"0.23", "size":"189.66"}, {"price":"0.22", "size":"228.41"}, {"price":"0.21", "size":"98.19"}, {"price":"0.2", "size":"185.84"}, {"price":"0.19", "size":"378.96"}], "hash":"0ba16aca49d3e91673bb87cf872e0de70ba0251e", "timestamp":"1784449596078", "event_type":"book"}
{"market":"0x982eae4503214e5d7992668e93f48f42e4707b92e23bb45f8d52d321f643cbe3", "price_changes":[{"asset_id":"74913635031537477155015393896000154190746945075332596665612975928350948042868", "price":"0.01", "size":"16684.14", "side":"BUY", "hash":"bec600ad1931564847dcf2ae90571de458018378", "best_bid":"0.81", "best_ask":"0.82"}, {"asset_id":"37613674580450069178400687025689415665506452565086963049482350052080099056186", "price":"0.99", "size":"16684.14", "side":"SELL", "hash":"38086b2bf139421590657f9fe3a97d4fb2e474d1", "best_bid":"0.18", "best_ask":"0.19"}], "timestamp":"1784449596083", "event_type":"price_change"}
{"market":"0x982eae4503214e5d7992668e93f48f42e4707b92e23bb45f8d52d321f643cbe3", "price_changes":[{"asset_id":"74913635031537477155015393896000154190746945075332596665612975928350948042868", "price":"0.81", "size":"398.96", "side":"BUY", "hash":"4acf589d4fe6da430a900c67c309d70a00fdc3cb", "best_bid":"0.81", "best_ask":"0.82"}, {"asset_id":"37613674580450069178400687025689415665506452565086963049482350052080099056186", "price":"0.19", "size":"398.96", "side":"SELL", "hash":"93bdb81af86c1c1f44c65e64d13af64b970e982e", "best_bid":"0.18", "best_ask":"0.19"}], "timestamp":"1784449596087", "event_type":"price_change"}
{"market":"0x982eae4503214e5d7992668e93f48f42e4707b92e23bb45f8d52d321f643cbe3", "price_changes":[{"asset_id":"74913635031537477155015393896000154190746945075332596665612975928350948042868", "price":"0.04", "size":"1462.1", "side":"BUY", "hash":"3b983978d3da473915772b36cacde363ab8f5cd4", "best_bid":"0.81", "best_ask":"0.82"}, {"asset_id":"37613674580450069178400687025689415665506452565086963049482350052080099056186", "price":"0.96", "size":"1462.1", "side":"SELL", "hash":"cc11b01b8c07bcdd8379a9c40ebe66cafdd56e79", "best_bid":"0.18", "best_ask":"0.19"}], "timestamp":"1784449596089", "event_type":"price_change"}
{"market":"0x982eae4503214e5d7992668e93f48f42e4707b92e23bb45f8d52d321f643cbe3", "price_changes":[{"asset_id":"74913635031537477155015393896000154190746945075332596665612975928350948042868", "price":"0.01", "size":"16679.13", "side":"BUY", "hash":"ae441e01e3d94cb54633ba1c2049f0746f5b388d", "best_bid":"0.81", "best_ask":"0.82"}, {"asset_id":"37613674580450069178400687025689415665506452565086963049482350052080099056186", "price":"0.99", "size":"16679.13", "side":"SELL", "hash":"96c27c8d408f540730a8b28e6c877f8d94701883", "best_bid":"0.18", "best_ask":"0.19"}], "timestamp":"1784449596090", "event_type":"price_change"}
{"market":"0x982eae4503214e5d7992668e93f48f42e4707b92e23bb45f8d52d321f643cbe3", "price_changes":[{"asset_id":"37613674580450069178400687025689415665506452565086963049482350052080099056186", "price":"0.18", "size":"17.24", "side":"BUY", "hash":"ab35cf172ce7748289f4e41e4fce336e34613674", "best_bid":"0.18", "best_ask":"0.19"}, {"asset_id":"74913635031537477155015393896000154190746945075332596665612975928350948042868", "price":"0.82", "size":"17.24", "side":"SELL", "hash":"2819004433fe53219976d86bfc7fced0de04a9d6", "best_bid":"0.81", "best_ask":"0.82"}], "timestamp":"1784449596092", "event_type":"price_change"}
{"market":"0x982eae4503214e5d7992668e93f48f42e4707b92e23bb45f8d52d321f643cbe3", "asset_id":"74913635031537477155015393896000154190746945075332596665612975928350948042868", "bids":[{"price":"0.01", "size":"16679.13"}, {"price":"0.02", "size":"3289.11"}, {"price":"0.03", "size":"2085.95"}, {"price":"0.04", "size":"1462.1"}, {"price":"0.05", "size":"1953.67"}, {"price":"0.06", "size":"1677.35"}, {"price":"0.07", "size":"1155.2"}, {"price":"0.08", "size":"1325.88"}, {"price":"0.09", "size":"1027.7"}, {"price":"0.1", "size":"528.2"}, {"price":"0.11", "size":"454.1"}, {"price":"0.12", "size":"203.05"}, {"price":"0.13", "size":"179.4"}, {"price":"0.14", "size":"159.4"}, {"price":"0.15", "size":"149.23"}, {"price":"0.16", "size":"150.4"}, {"price":"0.17", "size":"105.08"}, {"price":"0.18", "size":"127.3"}, {"price":"0.19", "size":"99.78"}, {"price":"0.2", "size":"181.4"}, {"price":"0.21", "size":"111.5"}, {"price":"0.22", "size":"125.7"}, {"price":"0.23", "size":"92"}, {"price":"0.24", "size":"111.5"}, {"price":"0.25", "size":"843.6"}, {"price":"0.26", "size":"128.8"}, {"price":"0.27", "size":"86.7"}, {"price":"0.28", "size":"106.67"}, {"price":"0.29", "size":"84.59"}, {"price":"0.3", "size":"107.8"}, {"price":"0.31", "size":"79.1"}, {"price":"0.32", "size":"107.19"}, {"price":"0.33", "size":"76.7"}, {"price":"0.34", "size":"89"}, {"price":"0.35", "size":"84.4"}, {"price":"0.36", "size":"86.99"}, {"price":"0.37", "size":"73.6"}, {"price":"0.38", "size":"85"}, {"price":"0.39", "size":"71.6"}, {"price":"0.4", "size":"88.3"}, {"price":"0.41", "size":"69.9"}, {"price":"0.42", "size":"142.27"}, {"price":"0.43", "size":"86.5"}, {"price":"0.44", "size":"91.08"}, {"price":"0.45", "size":"104.31"}, {"price":"0.46", "size":"80.1"}, {"price":"0.47", "size":"94.9"}, {"price":"0.48", "size":"88.8"}, {"price":"0.49", "size":"99.36"}, {"price":"0.5", "size":"102.8"}, {"price":"0.51", "size":"100.8"}, {"price":"0.52", "size":"100.8"}, {"price":"0.53", "size":"99.9"}, {"price":"0.54", "size":"92.1"}, {"price":"0.55", "size":"485.2"}, {"price":"0.56", "size":"95.4"}, {"price":"0.57", "size":"95.5"}, {"price":"0.58", "size":"111.12"}, {"price":"0.59", "size":"94.9"}, {"price":"0.6", "size":"182.58"}, {"price":"0.61", "size":"100.6"}, {"price":"0.62", "size":"125"}, {"price":"0.63", "size":"150.6"}, {"price":"0.64", "size":"482.99"}, {"price":"0.65", "size":"107.4"}, {"price":"0.66", "size":"133.24"}, {"price":"0.67", "size":"302.58"}, {"price":"0.68", "size":"106.29"}, {"price":"0.69", "size":"97.9"}, {"price":"0.7", "size":"82.04"}, {"price":"0.71", "size":"84"}, {"price":"0.72", "size":"283"}, {"price":"0.73", "size":"159.41"}, {"price":"0.74", "size":"151.85"}, {"price":"0.75", "size":"162.84"}, {"price":"0.76", "size":"170.24"}, {"price":"0.77", "size":"189.66"}, {"price":"0.78", "size":"228.41"}, {"price":"0.79", "size":"98.19"}, {"price":"0.8", "size":"185.84"}, {"price":"0.81", "size":"398.96"}], "asks":[{"price":"0.99", "size":"17939.98"}, {"price":"0.98", "size":"3156.06"}, {"price":"0.97", "size":"3788.29"}, {"price":"0.96", "size":"1529.1"}, {"price":"0.95", "size":"1723.6"}, {"price":"0.94", "size":"1201.35"}, {"price":"0.93", "size":"1167.2"}, {"price":"0.92", "size":"1310"}, {"price":"0.91", "size":"942.82"}, {"price":"0.9", "size":"618.32"}, {"price":"0.89", "size":"490.73"}, {"price":"0.88", "size":"247.17"}, {"price":"0.87", "size":"386.4"}, {"price":"0.86", "size":"164.34"}, {"price":"0.85", "size":"127.71"}, {"price":"0.84", "size":"81.17"}, {"price":"0.82", "size":"17.24"}], "hash":"2819004433fe53219976d86bfc7fced0de04a9d6", "timestamp":"1784449596092", "event_type":"book"}
{"market":"0x982eae4503214e5d7992668e93f48f42e4707b92e23bb45f8d52d321f643cbe3", "asset_id":"37613674580450069178400687025689415665506452565086963049482350052080099056186", "bids":[{"price":"0.01", "size":"17939.98"}, {"price":"0.02", "size":"3156.06"}, {"price":"0.03", "size":"3788.29"}, {"price":"0.04", "size":"1529.1"}, {"price":"0.05", "size":"1723.6"}, {"price":"0.06", "size":"1201.35"}, {"price":"0.07", "size":"1167.2"}, {"price":"0.08", "size":"1310"}, {"price":"0.09", "size":"942.82"}, {"price":"0.1", "size":"618.32"}, {"price":"0.11", "size":"490.73"}, {"price":"0.12", "size":"247.17"}, {"price":"0.13", "size":"386.4"}, {"price":"0.14", "size":"164.34"}, {"price":"0.15", "size":"127.71"}, {"price":"0.16", "size":"81.17"}, {"price":"0.18", "size":"17.24"}], "asks":[{"price":"0.99", "size":"16679.13"}, {"price":"0.98", "size":"3289.11"}, {"price":"0.97", "size":"2085.95"}, {"price":"0.96", "size":"1462.1"}, {"price":"0.95", "size":"1953.67"}, {"price":"0.94", "size":"1677.35"}, {"price":"0.93", "size":"1155.2"}, {"price":"0.92", "size":"1325.88"}, {"price":"0.91", "size":"1027.7"}, {"price":"0.9", "size":"528.2"}, {"price":"0.89", "size":"454.1"}, {"price":"0.88", "size":"203.05"}, {"price":"0.87", "size":"179.4"}, {"price":"0.86", "size":"159.4"}, {"price":"0.85", "size":"149.23"}, {"price":"0.84", "size":"150.4"}, {"price":"0.83", "size":"105.08"}, {"price":"0.82", "size":"127.3"}, {"price":"0.81", "size":"99.78"}, {"price":"0.8", "size":"181.4"}, {"price":"0.79", "size":"111.5"}, {"price":"0.78", "size":"125.7"}, {"price":"0.77", "size":"92"}, {"price":"0.76", "size":"111.5"}, {"price":"0.75", "size":"843.6"}, {"price":"0.74", "size":"128.8"}, {"price":"0.73", "size":"86.7"}, {"price":"0.72", "size":"106.67"}, {"price":"0.71", "size":"84.59"}, {"price":"0.7", "size":"107.8"}, {"price":"0.69", "size":"79.1"}, {"price":"0.68", "size":"107.19"}, {"price":"0.67", "size":"76.7"}, {"price":"0.66", "size":"89"}, {"price":"0.65", "size":"84.4"}, {"price":"0.64", "size":"86.99"}, {"price":"0.63", "size":"73.6"}, {"price":"0.62", "size":"85"}, {"price":"0.61", "size":"71.6"}, {"price":"0.6", "size":"88.3"}, {"price":"0.59", "size":"69.9"}, {"price":"0.58", "size":"142.27"}, {"price":"0.57", "size":"86.5"}, {"price":"0.56", "size":"91.08"}, {"price":"0.55", "size":"104.31"}, {"price":"0.54", "size":"80.1"}, {"price":"0.53", "size":"94.9"}, {"price":"0.52", "size":"88.8"}, {"price":"0.51", "size":"99.36"}, {"price":"0.5", "size":"102.8"}, {"price":"0.49", "size":"100.8"}, {"price":"0.48", "size":"100.8"}, {"price":"0.47", "size":"99.9"}, {"price":"0.46", "size":"92.1"}, {"price":"0.45", "size":"485.2"}, {"price":"0.44", "size":"95.4"}, {"price":"0.43", "size":"95.5"}, {"price":"0.42", "size":"111.12"}, {"price":"0.41", "size":"94.9"}, {"price":"0.4", "size":"182.58"}, {"price":"0.39", "size":"100.6"}, {"price":"0.38", "size":"125"}, {"price":"0.37", "size":"150.6"}, {"price":"0.36", "size":"482.99"}, {"price":"0.35", "size":"107.4"}, {"price":"0.34", "size":"133.24"}, {"price":"0.33", "size":"302.58"}, {"price":"0.32", "size":"106.29"}, {"price":"0.31", "size":"97.9"}, {"price":"0.3", "size":"82.04"}, {"price":"0.29", "size":"84"}, {"price":"0.28", "size":"283"}, {"price":"0.27", "size":"159.41"}, {"price":"0.26", "size":"151.85"}, {"price":"0.25", "size":"162.84"}, {"price":"0.24", "size":"170.24"}, {"price":"0.23", "size":"189.66"}, {"price":"0.22", "size":"228.41"}, {"price":"0.21", "size":"98.19"}, {"price":"0.2", "size":"185.84"}, {"price":"0.19", "size":"398.96"}], "hash":"ab35cf172ce7748289f4e41e4fce336e34613674", "timestamp":"1784449596092", "event_type":"book"}
{"market":"0x982eae4503214e5d7992668e93f48f42e4707b92e23bb45f8d52d321f643cbe3", "price_changes":[{"asset_id":"74913635031537477155015393896000154190746945075332596665612975928350948042868", "price":"0.8", "size":"205.84", "side":"BUY", "hash":"dd97dabb3f95a6da519a1a1d91c832a79d145167", "best_bid":"0.81", "best_ask":"0.82"}, {"asset_id":"37613674580450069178400687025689415665506452565086963049482350052080099056186", "price":"0.2", "size":"205.84", "side":"SELL", "hash":"e38673c6f0d640bf36bcb95751b810ca5d40e3dc", "best_bid":"0.18", "best_ask":"0.19"}], "timestamp":"1784449596096", "event_type":"price_change"}
{"market":"0x982eae4503214e5d7992668e93f48f42e4707b92e23bb45f8d52d321f643cbe3", "price_changes":[{"asset_id":"74913635031537477155015393896000154190746945075332596665612975928350948042868", "price":"0.01", "size":"16674.13", "side":"BUY", "hash":"88c547b7d06e35057864f1f768b59325acfa348a", "best_bid":"0.81", "best_ask":"0.82"}, {"asset_id":"37613674580450069178400687025689415665506452565086963049482350052080099056186", "price":"0.99", "size":"16674.13", "side":"SELL", "hash":"a059eb60f1d0a17ba572feeded096b7f64cfdeee", "best_bid":"0.18", "best_ask":"0.19"}], "timestamp":"1784449596099", "event_type":"price_change"}
{"market":"0x982eae4503214e5d7992668e93f48f42e4707b92e23bb45f8d52d321f643cbe3", "price_changes":[{"asset_id":"74913635031537477155015393896000154190746945075332596665612975928350948042868", "price":"0.01", "size":"16774.13", "side":"BUY", "hash":"383e38eed761ff672aa7ae200e2f918d517ffb9c", "best_bid":"0.81", "best_ask":"0.82"}, {"asset_id":"37613674580450069178400687025689415665506452565086963049482350052080099056186", "price":"0.99", "size":"16774.13", "side":"SELL", "hash":"20dd24115401159ba5bd0861dd74202a57f1e631", "best_bid":"0.18", "best_ask":"0.19"}], "timestamp":"1784449596110", "event_type":"price_change"}
{"market":"0x982eae4503214e5d7992668e93f48f42e4707b92e23bb45f8d52d321f643cbe3", "price_changes":[{"asset_id":"74913635031537477155015393896000154190746945075332596665612975928350948042868", "price":"0.8", "size":"200.84", "side":"BUY", "hash":"1ac8024f3623acfdbcb3eb4267d3c0a1e70a9c90", "best_bid":"0.81", "best_ask":"0.82"}, {"asset_id":"37613674580450069178400687025689415665506452565086963049482350052080099056186", "price":"0.2", "size":"200.84", "side":"SELL", "hash":"062f6dbc1eed1024523d59f390e5965115be2b48", "best_bid":"0.18", "best_ask":"0.19"}], "timestamp":"1784449596111", "event_type":"price_change"}
{"market":"0x982eae4503214e5d7992668e93f48f42e4707b92e23bb45f8d52d321f643cbe3", "price_changes":[{"asset_id":"37613674580450069178400687025689415665506452565086963049482350052080099056186", "price":"0.1", "size":"518.32", "side":"BUY", "hash":"46c13116669b508207ccb8a01aec35bb89571593", "best_bid":"0.18", "best_ask":"0.19"}, {"asset_id":"74913635031537477155015393896000154190746945075332596665612975928350948042868", "price":"0.9", "size":"518.32", "side":"SELL", "hash":"d85032e8b3c0ae2ff94fb157a94b583c24da0802", "best_bid":"0.81", "best_ask":"0.82"}], "timestamp":"1784449596117", "event_type":"price_change"}
{"market":"0x982eae4503214e5d7992668e93f48f42e4707b92e23bb45f8d52d321f643cbe3", "price_changes":[{"asset_id":"37613674580450069178400687025689415665506452565086963049482350052080099056186", "price":"0.08", "size":"1410", "side":"BUY", "hash":"b1e91e1d61240b2685b61f817acfdfd022dd99e9", "best_bid":"0.18", "best_ask":"0.19"}, {"asset_id":"74913635031537477155015393896000154190746945075332596665612975928350948042868", "price":"0.92", "size":"1410", "side":"SELL", "hash":"e797be10a076fd506bd3858407f995be89d4c991", "best_bid":"0.81", "best_ask":"0.82"}], "timestamp":"1784449596125", "event_type":"price_change"}
{"market":"0x982eae4503214e5d7992668e93f48f42e4707b92e23bb45f8d52d321f643cbe3", "price_changes":[{"asset_id":"74913635031537477155015393896000154190746945075332596665612975928350948042868", "price":"0.01", "size":"16769.13", "side":"BUY", "hash":"c1ca9891212fbbe1289e4763ed7f9fdaeecde4ef", "best_bid":"0.81", "best_ask":"0.82"}, {"asset_id":"37613674580450069178400687025689415665506452565086963049482350052080099056186", "price":"0.99", "size":"16769.13", "side":"SELL", "hash":"689e885022124c9a01299a137ec5ab8e6da040c7", "best_bid":"0.18", "best_ask":"0.19"}], "timestamp":"1784449596131", "event_type":"price_change"}
{"market":"0x982eae4503214e5d7992668e93f48f42e4707b92e23bb45f8d52d321f643cbe3", "price_changes":[{"asset_id":"74913635031537477155015393896000154190746945075332596665612975928350948042868", "price":"0.01", "size":"16269.13", "side":"BUY", "hash":"c56c90913ed02d13d14a7c463ee2422524d95f0f", "best_bid":"0.81", "best_ask":"0.82"}, {"asset_id":"37613674580450069178400687025689415665506452565086963049482350052080099056186", "price":"0.99", "size":"16269.13", "side":"SELL", "hash":"06b560e4f8eefe716a1a406dfc334b761ceeb7cd", "best_bid":"0.18", "best_ask":"0.19"}], "timestamp":"1784449596133", "event_type":"price_change"}
{"market":"0x982eae4503214e5d7992668e93f48f42e4707b92e23bb45f8d52d321f643cbe3", "asset_id":"37613674580450069178400687025689415665506452565086963049482350052080099056186", "price":"0.19", "size":"7", "fee_rate_bps":"0", "side":"BUY", "timestamp":"1784449596132", "event_type":"last_trade_price", "transaction_hash":"0xc220ea0154ac653dc8f3479682afd81b32db2eb5cf8f6cdd4860f2dffd7ee8ba"}
{"market":"0x982eae4503214e5d7992668e93f48f42e4707b92e23bb45f8d52d321f643cbe3", "price_changes":[{"asset_id":"74913635031537477155015393896000154190746945075332596665612975928350948042868", "price":"0.01", "size":"16169.13", "side":"BUY", "hash":"40002f885118f1972f4f3ac51e17295290e08d5e", "best_bid":"0.81", "best_ask":"0.82"}, {"asset_id":"37613674580450069178400687025689415665506452565086963049482350052080099056186", "price":"0.99", "size":"16169.13", "side":"SELL", "hash":"5f33876bb39e4d41bf91a644cb2b261c80ebdb00", "best_bid":"0.18", "best_ask":"0.19"}], "timestamp":"1784449596141", "event_type":"price_change"}
{"market":"0x982eae4503214e5d7992668e93f48f42e4707b92e23bb45f8d52d321f643cbe3", "price_changes":[{"asset_id":"37613674580450069178400687025689415665506452565086963049482350052080099056186", "price":"0.18", "size":"13.64", "side":"BUY", "hash":"f7581d6101a1c842db265404d61fd4c12767e9de", "best_bid":"0.18", "best_ask":"0.19"}, {"asset_id":"74913635031537477155015393896000154190746945075332596665612975928350948042868", "price":"0.82", "size":"13.64", "side":"SELL", "hash":"f551e54a5799be551ed079113f0fd66b4b23f573", "best_bid":"0.81", "best_ask":"0.82"}], "timestamp":"1784449596143", "event_type":"price_change"}
{"market":"0x982eae4503214e5d7992668e93f48f42e4707b92e23bb45f8d52d321f643cbe3", "asset_id":"74913635031537477155015393896000154190746945075332596665612975928350948042868", "bids":[{"price":"0.01", "size":"16169.13"}, {"price":"0.02", "size":"3289.11"}, {"price":"0.03", "size":"2085.95"}, {"price":"0.04", "size":"1462.1"}, {"price":"0.05", "size":"1953.67"}, {"price":"0.06", "size":"1677.35"}, {"price":"0.07", "size":"1155.2"}, {"price":"0.08", "size":"1325.88"}, {"price":"0.09", "size":"1027.7"}, {"price":"0.1", "size":"528.2"}, {"price":"0.11", "size":"454.1"}, {"price":"0.12", "size":"203.05"}, {"price":"0.13", "size":"179.4"}, {"price":"0.14", "size":"159.4"}, {"price":"0.15", "size":"149.23"}, {"price":"0.16", "size":"150.4"}, {"price":"0.17", "size":"105.08"}, {"price":"0.18", "size":"127.3"}, {"price":"0.19", "size":"99.78"}, {"price":"0.2", "size":"181.4"}, {"price":"0.21", "size":"111.5"}, {"price":"0.22", "size":"125.7"}, {"price":"0.23", "size":"92"}, {"price":"0.24", "size":"111.5"}, {"price":"0.25", "size":"843.6"}, {"price":"0.26", "size":"128.8"}, {"price":"0.27", "size":"86.7"}, {"price":"0.28", "size":"106.67"}, {"price":"0.29", "size":"84.59"}, {"price":"0.3", "size":"107.8"}, {"price":"0.31", "size":"79.1"}, {"price":"0.32", "size":"107.19"}, {"price":"0.33", "size":"76.7"}, {"price":"0.34", "size":"89"}, {"price":"0.35", "size":"84.4"}, {"price":"0.36", "size":"86.99"}, {"price":"0.37", "size":"73.6"}, {"price":"0.38", "size":"85"}, {"price":"0.39", "size":"71.6"}, {"price":"0.4", "size":"88.3"}, {"price":"0.41", "size":"69.9"}, {"price":"0.42", "size":"142.27"}, {"price":"0.43", "size":"86.5"}, {"price":"0.44", "size":"91.08"}, {"price":"0.45", "size":"104.31"}, {"price":"0.46", "size":"80.1"}, {"price":"0.47", "size":"94.9"}, {"price":"0.48", "size":"88.8"}, {"price":"0.49", "size":"99.36"}, {"price":"0.5", "size":"102.8"}, {"price":"0.51", "size":"100.8"}, {"price":"0.52", "size":"100.8"}, {"price":"0.53", "size":"99.9"}, {"price":"0.54", "size":"92.1"}, {"price":"0.55", "size":"485.2"}, {"price":"0.56", "size":"95.4"}, {"price":"0.57", "size":"95.5"}, {"price":"0.58", "size":"111.12"}, {"price":"0.59", "size":"94.9"}, {"price":"0.6", "size":"182.58"}, {"price":"0.61", "size":"100.6"}, {"price":"0.62", "size":"125"}, {"price":"0.63", "size":"150.6"}, {"price":"0.64", "size":"482.99"}, {"price":"0.65", "size":"107.4"}, {"price":"0.66", "size":"133.24"}, {"price":"0.67", "size":"302.58"}, {"price":"0.68", "size":"106.29"}, {"price":"0.69", "size":"97.9"}, {"price":"0.7", "size":"82.04"}, {"price":"0.71", "size":"84"}, {"price":"0.72", "size":"283"}, {"price":"0.73", "size":"159.41"}, {"price":"0.74", "size":"151.85"}, {"price":"0.75", "size":"162.84"}, {"price":"0.76", "size":"170.24"}, {"price":"0.77", "size":"189.66"}, {"price":"0.78", "size":"228.41"}, {"price":"0.79", "size":"98.19"}, {"price":"0.8", "size":"200.84"}, {"price":"0.81", "size":"398.96"}], "asks":[{"price":"0.99", "size":"17939.98"}, {"price":"0.98", "size":"3156.06"}, {"price":"0.97", "size":"3788.29"}, {"price":"0.96", "size":"1529.1"}, {"price":"0.95", "size":"1723.6"}, {"price":"0.94", "size":"1201.35"}, {"price":"0.93", "size":"1167.2"}, {"price":"0.92", "size":"1410"}, {"price":"0.91", "size":"942.82"}, {"price":"0.9", "size":"518.32"}, {"price":"0.89", "size":"490.73"}, {"price":"0.88", "size":"247.17"}, {"price":"0.87", "size":"386.4"}, {"price":"0.86", "size":"164.34"}, {"price":"0.85", "size":"127.71"}, {"price":"0.84", "size":"81.17"}, {"price":"0.82", "size":"13.64"}], "hash":"f551e54a5799be551ed079113f0fd66b4b23f573", "timestamp":"1784449596143", "event_type":"book"}
{"market":"0x982eae4503214e5d7992668e93f48f42e4707b92e23bb45f8d52d321f643cbe3", "asset_id":"37613674580450069178400687025689415665506452565086963049482350052080099056186", "bids":[{"price":"0.01", "size":"17939.98"}, {"price":"0.02", "size":"3156.06"}, {"price":"0.03", "size":"3788.29"}, {"price":"0.04", "size":"1529.1"}, {"price":"0.05", "size":"1723.6"}, {"price":"0.06", "size":"1201.35"}, {"price":"0.07", "size":"1167.2"}, {"price":"0.08", "size":"1410"}, {"price":"0.09", "size":"942.82"}, {"price":"0.1", "size":"518.32"}, {"price":"0.11", "size":"490.73"}, {"price":"0.12", "size":"247.17"}, {"price":"0.13", "size":"386.4"}, {"price":"0.14", "size":"164.34"}, {"price":"0.15", "size":"127.71"}, {"price":"0.16", "size":"81.17"}, {"price":"0.18", "size":"13.64"}], "asks":[{"price":"0.99", "size":"16169.13"}, {"price":"0.98", "size":"3289.11"}, {"price":"0.97", "size":"2085.95"}, {"price":"0.96", "size":"1462.1"}, {"price":"0.95", "size":"1953.67"}, {"price":"0.94", "size":"1677.35"}, {"price":"0.93", "size":"1155.2"}, {"price":"0.92", "size":"1325.88"}, {"price":"0.91", "size":"1027.7"}, {"price":"0.9", "size":"528.2"}, {"price":"0.89", "size":"454.1"}, {"price":"0.88", "size":"203.05"}, {"price":"0.87", "size":"179.4"}, {"price":"0.86", "size":"159.4"}, {"price":"0.85", "size":"149.23"}, {"price":"0.84", "size":"150.4"}, {"price":"0.83", "size":"105.08"}, {"price":"0.82", "size":"127.3"}, {"price":"0.81", "size":"99.78"}, {"price":"0.8", "size":"181.4"}, {"price":"0.79", "size":"111.5"}, {"price":"0.78", "size":"125.7"}, {"price":"0.77", "size":"92"}, {"price":"0.76", "size":"111.5"}, {"price":"0.75", "size":"843.6"}, {"price":"0.74", "size":"128.8"}, {"price":"0.73", "size":"86.7"}, {"price":"0.72", "size":"106.67"}, {"price":"0.71", "size":"84.59"}, {"price":"0.7", "size":"107.8"}, {"price":"0.69", "size":"79.1"}, {"price":"0.68", "size":"107.19"}, {"price":"0.67", "size":"76.7"}, {"price":"0.66", "size":"89"}, {"price":"0.65", "size":"84.4"}, {"price":"0.64", "size":"86.99"}, {"price":"0.63", "size":"73.6"}, {"price":"0.62", "size":"85"}, {"price":"0.61", "size":"71.6"}, {"price":"0.6", "size":"88.3"}, {"price":"0.59", "size":"69.9"}, {"price":"0.58", "size":"142.27"}, {"price":"0.57", "size":"86.5"}, {"price":"0.56", "size":"91.08"}, {"price":"0.55", "size":"104.31"}, {"price":"0.54", "size":"80.1"}, {"price":"0.53", "size":"94.9"}, {"price":"0.52", "size":"88.8"}, {"price":"0.51", "size":"99.36"}, {"price":"0.5", "size":"102.8"}, {"price":"0.49", "size":"100.8"}, {"price":"0.48", "size":"100.8"}, {"price":"0.47", "size":"99.9"}, {"price":"0.46", "size":"92.1"}, {"price":"0.45", "size":"485.2"}, {"price":"0.44", "size":"95.4"}, {"price":"0.43", "size":"95.5"}, {"price":"0.42", "size":"111.12"}, {"price":"0.41", "size":"94.9"}, {"price":"0.4", "size":"182.58"}, {"price":"0.39", "size":"100.6"}, {"price":"0.38", "size":"125"}, {"price":"0.37", "size":"150.6"}, {"price":"0.36", "size":"482.99"}, {"price":"0.35", "size":"107.4"}, {"price":"0.34", "size":"133.24"}, {"price":"0.33", "size":"302.58"}, {"price":"0.32", "size":"106.29"}, {"price":"0.31", "size":"97.9"}, {"price":"0.3", "size":"82.04"}, {"price":"0.29", "size":"84"}, {"price":"0.28", "size":"283"}, {"price":"0.27", "size":"159.41"}, {"price":"0.26", "size":"151.85"}, {"price":"0.25", "size":"162.84"}, {"price":"0.24", "size":"170.24"}, {"price":"0.23", "size":"189.66"}, {"price":"0.22", "size":"228.41"}, {"price":"0.21", "size":"98.19"}, {"price":"0.2", "size":"200.84"}, {"price":"0.19", "size":"398.96"}], "hash":"f7581d6101a1c842db265404d61fd4c12767e9de", "timestamp":"1784449596143", "event_type":"book"}
{"market":"0x982eae4503214e5d7992668e93f48f42e4707b92e23bb45f8d52d321f643cbe3", "price_changes":[{"asset_id":"74913635031537477155015393896000154190746945075332596665612975928350948042868", "price":"0.8", "size":"180.84", "side":"BUY", "hash":"78bd7c6a998126ff65d442183168786030934e7e", "best_bid":"0.81", "best_ask":"0.82"}, {"asset_id":"37613674580450069178400687025689415665506452565086963049482350052080099056186", "price":"0.2", "size":"180.84", "side":"SELL", "hash":"ae745852f006d0ec9a0ea81e8da86197f11eea32", "best_bid":"0.18", "best_ask":"0.19"}], "timestamp":"1784449596146", "event_type":"price_change"}
{"market":"0x982eae4503214e5d7992668e93f48f42e4707b92e23bb45f8d52d321f643cbe3", "price_changes":[{"asset_id":"37613674580450069178400687025689415665506452565086963049482350052080099056186", "price":"0.14", "size":"131.14", "side":"BUY", "hash":"646553cb9dda87f765b4b127cfbee28bc02d4efd", "best_bid":"0.18", "best_ask":"0.19"}, {"asset_id":"74913635031537477155015393896000154190746945075332596665612975928350948042868", "price":"0.86", "size":"131.14", "side":"SELL", "hash":"7026294105e532d227fac6ebc6fca80f19736bbc", "best_bid":"0.81", "best_ask":"0.82"}], "timestamp":"1784449596146", "event_type":"price_change"}
{"market":"0x982eae4503214e5d7992668e93f48f42e4707b92e23bb45f8d52d321f643cbe3", "price_changes":[{"asset_id":"37613674580450069178400687025689415665506452565086963049482350052080099056186", "price":"0.12", "size":"262.17", "side":"BUY", "hash":"e9442ad65a93683d39c9483775702a1254af4c53", "best_bid":"0.18", "best_ask":"0.19"}, {"asset_id":"74913635031537477155015393896000154190746945075332596665612975928350948042868", "price":"0.88", "size":"262.17", "side":"SELL", "hash":"bdf3ec3b0e10fcbfe552406737c0bbfff254b53d", "best_bid":"0.81", "best_ask":"0.82"}], "timestamp":"1784449596161", "event_type":"price_change"}
{"market":"0x982eae4503214e5d7992668e93f48f42e4707b92e23bb45f8d52d321f643cbe3", "price_changes":[{"asset_id":"74913635031537477155015393896000154190746945075332596665612975928350948042868", "price":"0.02", "size":"3294.11", "side":"BUY", "hash":"7e7a8c6d8992b93d91360e3fc66121461cf57de7", "best_bid":"0.81", "best_ask":"0.82"}, {"asset_id":"37613674580450069178400687025689415665506452565086963049482350052080099056186", "price":"0.98", "size":"3294.11", "side":"SELL", "hash":"09bda30b6b3cb47448b39ca27f78c912a748d8c5", "best_bid":"0.18", "best_ask":"0.19"}], "timestamp":"1784449596167", "event_type":"price_change"}
{"market":"0x982eae4503214e5d7992668e93f48f42e4707b92e23bb45f8d52d321f643cbe3", "price_changes":[{"asset_id":"37613674580450069178400687025689415665506452565086963049482350052080099056186", "price":"0.12", "size":"247.17", "side":"BUY", "hash":"151364eff503037f5d25d8ef0dcbfe6b2465d577", "best_bid":"0.18", "best_ask":"0.19"}, {"asset_id":"74913635031537477155015393896000154190746945075332596665612975928350948042868", "price":"0.88", "size":"247.17", "side":"SELL", "hash":"70270a052e940e8cd77b5cfaf4154385a6379775", "best_bid":"0.81", "best_ask":"0.82"}], "timestamp":"1784449596171", "event_type":"price_change"}
{"market":"0x982eae4503214e5d7992668e93f48f42e4707b92e23bb45f8d52d321f643cbe3", "price_changes":[{"asset_id":"37613674580450069178400687025689415665506452565086963049482350052080099056186", "price":"0.11", "size":"475.73", "side":"BUY", "hash":"93603e87bd7e0f40e3a3ced501367abe10b74d68", "best_bid":"0.18", "best_ask":"0.19"}, {"asset_id":"74913635031537477155015393896000154190746945075332596665612975928350948042868", "price":"0.89", "size":"475.73", "side":"SELL", "hash":"ebfeeaa98da73b9920377c5c344e345689832c0a", "best_bid":"0.81", "best_ask":"0.82"}], "timestamp":"1784449596172", "event_type":"price_change"}
{"market":"0x982eae4503214e5d7992668e93f48f42e4707b92e23bb45f8d52d321f643cbe3", "price_changes":[{"asset_id":"37613674580450069178400687025689415665506452565086963049482350052080099056186", "price":"0.16", "size":"91.17", "side":"BUY", "hash":"81e7a03e00f76bd623511ca556ea192e0a520b85", "best_bid":"0.18", "best_ask":"0.19"}, {"asset_id":"74913635031537477155015393896000154190746945075332596665612975928350948042868", "price":"0.84", "size":"91.17", "side":"SELL", "hash":"2012071862d9735c5427929e381d555f63ff8720", "best_bid":"0.81", "best_ask":"0.82"}], "timestamp":"1784449596191", "event_type":"price_change"}
{"market":"0x982eae4503214e5d7992668e93f48f42e4707b92e23bb45f8d52d321f643cbe3", "price_changes":[{"asset_id":"74913635031537477155015393896000154190746945075332596665612975928350948042868", "price":"0.01", "size":"16269.13", "side":"BUY", "hash":"2062d87957b86cf5051c5bae7ddbc84d1a51ca1a", "best_bid":"0.81", "best_ask":"0.82"}, {"asset_id":"37613674580450069178400687025689415665506452565086963049482350052080099056186", "price":"0.99", "size":"16269.13", "side":"SELL", "hash":"5d38332d811621985450a588ae961c93f546481b", "best_bid":"0.18", "best_ask":"0.19"}], "timestamp":"1784449596194", "event_type":"price_change"}
{"market":"0x982eae4503214e5d7992668e93f48f42e4707b92e23bb45f8d52d321f643cbe3", "price_changes":[{"asset_id":"37613674580450069178400687025689415665506452565086963049482350052080099056186", "price":"0.08", "size":"1404.88", "side":"BUY", "hash":"be7234a7532784517b6ba89d2b1dd93e839572bd", "best_bid":"0.18", "best_ask":"0.19"}, {"asset_id":"74913635031537477155015393896000154190746945075332596665612975928350948042868", "price":"0.92", "size":"1404.88", "side":"SELL", "hash":"7b48382506d2238f490a7d4883daf640fb1cb482", "best_bid":"0.81", "best_ask":"0.82"}], "timestamp":"1784449596195", "event_type":"price_change"}
{"market":"0x982eae4503214e5d7992668e93f48f42e4707b92e23bb45f8d52d321f643cbe3", "price_changes":[{"asset_id":"37613674580450069178400687025689415665506452565086963049482350052080099056186", "price":"0.01", "size":"17934.98", "side":"BUY", "hash":"a73f38311ffcb5a59fa0c9d594885bda3eb6fcbd", "best_bid":"0.18", "best_ask":"0.19"}, {"asset_id":"74913635031537477155015393896000154190746945075332596665612975928350948042868", "price":"0.99", "size":"17934.98", "side":"SELL", "hash":"0fcae67f968bcc99a3449211f7364de949530a56", "best_bid":"0.81", "best_ask":"0.82"}], "timestamp":"1784449596199", "event_type":"price_change"}
{"market":"0x982eae4503214e5d7992668e93f48f42e4707b92e23bb45f8d52d321f643cbe3", "price_changes":[{"asset_id":"74913635031537477155015393896000154190746945075332596665612975928350948042868", "price":"0.01", "size":"16769.13", "side":"BUY", "hash":"3e381e7cb4c6a9e0d538d6ed96f2331cf3c6262c", "best_bid":"0.81", "best_ask":"0.82"}, {"asset_id":"37613674580450069178400687025689415665506452565086963049482350052080099056186", "price":"0.99", "size":"16769.13", "side":"SELL", "hash":"01d330aa7da39578edb0d218387006b24c5bc6a5", "best_bid":"0.18", "best_ask":"0.19"}], "timestamp":"1784449596199", "event_type":"price_change"}
{"market":"0x982eae4503214e5d7992668e93f48f42e4707b92e23bb45f8d52d321f643cbe3", "price_changes":[{"asset_id":"74913635031537477155015393896000154190746945075332596665612975928350948042868", "price":"0.6", "size":"193.58", "side":"BUY", "hash":"9e64ed91e8ed5940366fedf437ab3041bbea8b53", "best_bid":"0.81", "best_ask":"0.82"}, {"asset_id":"37613674580450069178400687025689415665506452565086963049482350052080099056186", "price":"0.4", "size":"193.58", "side":"SELL", "hash":"8154d62287c0f7bb23e3b4e43ead2b72bf5c9e0a", "best_bid":"0.18", "best_ask":"0.19"}], "timestamp":"1784449596201", "event_type":"price_change"}
{"market":"0x982eae4503214e5d7992668e93f48f42e4707b92e23bb45f8d52d321f643cbe3", "price_changes":[{"asset_id":"74913635031537477155015393896000154190746945075332596665612975928350948042868", "price":"0.81", "size":"377.9", "side":"BUY", "hash":"1fa2b8a1cfb9181abe36945fdf0479a7d088584b", "best_bid":"0.81", "best_ask":"0.82"}, {"asset_id":"37613674580450069178400687025689415665506452565086963049482350052080099056186", "price":"0.19", "size":"377.9", "side":"SELL", "hash":"543039444f0f3a522d41b96b76e69dc1d714fd06", "best_bid":"0.18", "best_ask":"0.19"}], "timestamp":"1784449596207", "event_type":"price_change"}
{"market":"0x982eae4503214e5d7992668e93f48f42e4707b92e23bb45f8d52d321f643cbe3", "asset_id":"74913635031537477155015393896000154190746945075332596665612975928350948042868", "bids":[{"price":"0.01", "size":"16769.13"}, {"price":"0.02", "size":"3294.11"}, {"price":"0.03", "size":"2085.95"}, {"price":"0.04", "size":"1462.1"}, {"price":"0.05", "size":"1953.67"}, {"price":"0.06", "size":"1677.35"}, {"price":"0.07", "size":"1155.2"}, {"price":"0.08", "size":"1325.88"}, {"price":"0.09", "size":"1027.7"}, {"price":"0.1", "size":"528.2"}, {"price":"0.11", "size":"454.1"}, {"price":"0.12", "size":"203.05"}, {"price":"0.13", "size":"179.4"}, {"price":"0.14", "size":"159.4"}, {"price":"0.15", "size":"149.23"}, {"price":"0.16", "size":"150.4"}, {"price":"0.17", "size":"105.08"}, {"price":"0.18", "size":"127.3"}, {"price":"0.19", "size":"99.78"}, {"price":"0.2", "size":"181.4"}, {"price":"0.21", "size":"111.5"}, {"price":"0.22", "size":"125.7"}, {"price":"0.23", "size":"92"}, {"price":"0.24", "size":"111.5"}, {"price":"0.25", "size":"843.6"}, {"price":"0.26", "size":"128.8"}, {"price":"0.27", "size":"86.7"}, {"price":"0.28", "size":"106.67"}, {"price":"0.29", "size":"84.59"}, {"price":"0.3", "size":"107.8"}, {"price":"0.31", "size":"79.1"}, {"price":"0.32", "size":"107.19"}, {"price":"0.33", "size":"76.7"}, {"price":"0.34", "size":"89"}, {"price":"0.35", "size":"84.4"}, {"price":"0.36", "size":"86.99"}, {"price":"0.37", "size":"73.6"}, {"price":"0.38", "size":"85"}, {"price":"0.39", "size":"71.6"}, {"price":"0.4", "size":"88.3"}, {"price":"0.41", "size":"69.9"}, {"price":"0.42", "size":"142.27"}, {"price":"0.43", "size":"86.5"}, {"price":"0.44", "size":"91.08"}, {"price":"0.45", "size":"104.31"}, {"price":"0.46", "size":"80.1"}, {"price":"0.47", "size":"94.9"}, {"price":"0.48", "size":"88.8"}, {"price":"0.49", "size":"99.36"}, {"price":"0.5", "size":"102.8"}, {"price":"0.51", "size":"100.8"}, {"price":"0.52", "size":"100.8"}, {"price":"0.53", "size":"99.9"}, {"price":"0.54", "size":"92.1"}, {"price":"0.55", "size":"485.2"}, {"price":"0.56", "size":"95.4"}, {"price":"0.57", "size":"95.5"}, {"price":"0.58", "size":"111.12"}, {"price":"0.59", "size":"94.9"}, {"price":"0.6", "size":"193.58"}, {"price":"0.61", "size":"100.6"}, {"price":"0.62", "size":"125"}, {"price":"0.63", "size":"150.6"}, {"price":"0.64", "size":"482.99"}, {"price":"0.65", "size":"107.4"}, {"price":"0.66", "size":"133.24"}, {"price":"0.67", "size":"302.58"}, {"price":"0.68", "size":"106.29"}, {"price":"0.69", "size":"97.9"}, {"price":"0.7", "size":"82.04"}, {"price":"0.71", "size":"84"}, {"price":"0.72", "size":"283"}, {"price":"0.73", "size":"159.41"}, {"price":"0.74", "size":"151.85"}, {"price":"0.75", "size":"162.84"}, {"price":"0.76", "size":"170.24"}, {"price":"0.77", "size":"189.66"}, {"price":"0.78", "size":"228.41"}, {"price":"0.79", "size":"98.19"}, {"price":"0.8", "size":"180.84"}, {"price":"0.81", "size":"377.9"}], "asks":[{"price":"0.99", "size":"17934.98"}, {"price":"0.98", "size":"3156.06"}, {"price":"0.97", "size":"3788.29"}, {"price":"0.96", "size":"1529.1"}, {"price":"0.95", "size":"1723.6"}, {"price":"0.94", "size":"1201.35"}, {"price":"0.93", "size":"1167.2"}, {"price":"0.92", "size":"1404.88"}, {"price":"0.91", "size":"942.82"}, {"price":"0.9", "size":"518.32"}, {"price":"0.89", "size":"475.73"}, {"price":"0.88", "size":"247.17"}, {"price":"0.87", "size":"386.4"}, {"price":"0.86", "size":"131.14"}, {"price":"0.85", "size":"127.71"}, {"price":"0.84", "size":"91.17"}, {"price":"0.82", "size":"13.64"}], "hash":"1fa2b8a1cfb9181abe36945fdf0479a7d088584b", "timestamp":"1784449596207", "event_type":"book"}
{"market":"0x982eae4503214e5d7992668e93f48f42e4707b92e23bb45f8d52d321f643cbe3", "asset_id":"37613674580450069178400687025689415665506452565086963049482350052080099056186", "bids":[{"price":"0.01", "size":"17934.98"}, {"price":"0.02", "size":"3156.06"}, {"price":"0.03", "size":"3788.29"}, {"price":"0.04", "size":"1529.1"}, {"price":"0.05", "size":"1723.6"}, {"price":"0.06", "size":"1201.35"}, {"price":"0.07", "size":"1167.2"}, {"price":"0.08", "size":"1404.88"}, {"price":"0.09", "size":"942.82"}, {"price":"0.1", "size":"518.32"}, {"price":"0.11", "size":"475.73"}, {"price":"0.12", "size":"247.17"}, {"price":"0.13", "size":"386.4"}, {"price":"0.14", "size":"131.14"}, {"price":"0.15", "size":"127.71"}, {"price":"0.16", "size":"91.17"}, {"price":"0.18", "size":"13.64"}], "asks":[{"price":"0.99", "size":"16769.13"}, {"price":"0.98", "size":"3294.11"}, {"price":"0.97", "size":"2085.95"}, {"price":"0.96", "size":"1462.1"}, {"price":"0.95", "size":"1953.67"}, {"price":"0.94", "size":"1677.35"}, {"price":"0.93", "size":"1155.2"}, {"price":"0.92", "size":"1325.88"}, {"price":"0.91", "size":"1027.7"}, {"price":"0.9", "size":"528.2"}, {"price":"0.89", "size":"454.1"}, {"price":"0.88", "size":"203.05"}, {"price":"0.87", "size":"179.4"}, {"price":"0.86", "size":"159.4"}, {"price":"0.85", "size":"149.23"}, {"price":"0.84", "size":"150.4"}, {"price":"0.83", "size":"105.08"}, {"price":"0.82", "size":"127.3"}, {"price":"0.81", "size":"99.78"}, {"price":"0.8", "size":"181.4"}, {"price":"0.79", "size":"111.5"}, {"price":"0.78", "size":"125.7"}, {"price":"0.77", "size":"92"}, {"price":"0.76", "size":"111.5"}, {"price":"0.75", "size":"843.6"}, {"price":"0.74", "size":"128.8"}, {"price":"0.73", "size":"86.7"}, {"price":"0.72", "size":"106.67"}, {"price":"0.71", "size":"84.59"}, {"price":"0.7", "size":"107.8"}, {"price":"0.69", "size":"79.1"}, {"price":"0.68", "size":"107.19"}, {"price":"0.67", "size":"76.7"}, {"price":"0.66", "size":"89"}, {"price":"0.65", "size":"84.4"}, {"price":"0.64", "size":"86.99"}, {"price":"0.63", "size":"73.6"}, {"price":"0.62", "size":"85"}, {"price":"0.61", "size":"71.6"}, {"price":"0.6", "size":"88.3"}, {"price":"0.59", "size":"69.9"}, {"price":"0.58", "size":"142.27"}, {"price":"0.57", "size":"86.5"}, {"price":"0.56", "size":"91.08"}, {"price":"0.55", "size":"104.31"}, {"price":"0.54", "size":"80.1"}, {"price":"0.53", "size":"94.9"}, {"price":"0.52", "size":"88.8"}, {"price":"0.51", "size":"99.36"}, {"price":"0.5", "size":"102.8"}, {"price":"0.49", "size":"100.8"}, {"price":"0.48", "size":"100.8"}, {"price":"0.47", "size":"99.9"}, {"price":"0.46", "size":"92.1"}, {"price":"0.45", "size":"485.2"}, {"price":"0.44", "size":"95.4"}, {"price":"0.43", "size":"95.5"}, {"price":"0.42", "size":"111.12"}, {"price":"0.41", "size":"94.9"}, {"price":"0.4", "size":"193.58"}, {"price":"0.39", "size":"100.6"}, {"price":"0.38", "size":"125"}, {"price":"0.37", "size":"150.6"}, {"price":"0.36", "size":"482.99"}, {"price":"0.35", "size":"107.4"}, {"price":"0.34", "size":"133.24"}, {"price":"0.33", "size":"302.58"}, {"price":"0.32", "size":"106.29"}, {"price":"0.31", "size":"97.9"}, {"price":"0.3", "size":"82.04"}, {"price":"0.29", "size":"84"}, {"price":"0.28", "size":"283"}, {"price":"0.27", "size":"159.41"}, {"price":"0.26", "size":"151.85"}, {"price":"0.25", "size":"162.84"}, {"price":"0.24", "size":"170.24"}, {"price":"0.23", "size":"189.66"}, {"price":"0.22", "size":"228.41"}, {"price":"0.21", "size":"98.19"}, {"price":"0.2", "size":"180.84"}, {"price":"0.19", "size":"377.9"}], "hash":"543039444f0f3a522d41b96b76e69dc1d714fd06", "timestamp":"1784449596207", "event_type":"book"}
{"market":"0x982eae4503214e5d7992668e93f48f42e4707b92e23bb45f8d52d321f643cbe3", "price_changes":[{"asset_id":"74913635031537477155015393896000154190746945075332596665612975928350948042868", "price":"0.68", "size":"118.19", "side":"BUY", "hash":"b8e9be50f0f988e9022351dc6d14c8c64c18962d", "best_bid":"0.81", "best_ask":"0.82"}, {"asset_id":"37613674580450069178400687025689415665506452565086963049482350052080099056186", "price":"0.32", "size":"118.19", "side":"SELL", "hash":"690d2079f63937708733900cae9a1a141308f7a5", "best_bid":"0.18", "best_ask":"0.19"}], "timestamp":"1784449596213", "event_type":"price_change"}
{"market":"0x982eae4503214e5d7992668e93f48f42e4707b92e23bb45f8d52d321f643cbe3", "price_changes":[{"asset_id":"37613674580450069178400687025689415665506452565086963049482350052080099056186", "price":"0.01", "size":"17929.98", "side":"BUY", "hash":"3c220dfae6129e95420543ad1010af9236e03c00", "best_bid":"0.18", "best_ask":"0.19"}, {"asset_id":"74913635031537477155015393896000154190746945075332596665612975928350948042868", "price":"0.99", "size":"17929.98", "side":"SELL", "hash":"a7605a47c5cf23d7596983ffd28e6dc68c60e1d8", "best_bid":"0.81", "best_ask":"0.82"}], "timestamp":"1784449596216", "event_type":"price_change"}
{"market":"0x982eae4503214e5d7992668e93f48f42e4707b92e23bb45f8d52d321f643cbe3", "price_changes":[{"asset_id":"37613674580450069178400687025689415665506452565086963049482350052080099056186", "price":"0.01", "size":"17924.98", "side":"BUY", "hash":"6e7a14ba7f1551a63e9b9a776013fb896a389d9e", "best_bid":"0.18", "best_ask":"0.19"}, {"asset_id":"74913635031537477155015393896000154190746945075332596665612975928350948042868", "price":"0.99", "size":"17924.98", "side":"SELL", "hash":"567759fe7863b513a35763888ef940235bac47c4", "best_bid":"0.81", "best_ask":"0.82"}], "timestamp":"1784449596216", "event_type":"price_change"}
{"market":"0x982eae4503214e5d7992668e93f48f42e4707b92e23bb45f8d52d321f643cbe3", "price_changes":[{"asset_id":"74913635031537477155015393896000154190746945075332596665612975928350948042868", "price":"0.02", "size":"3289.11", "side":"BUY", "hash":"429fd42c0de0348361c1e9bbe241b95f3a8aeb11", "best_bid":"0.81", "best_ask":"0.82"}, {"asset_id":"37613674580450069178400687025689415665506452565086963049482350052080099056186", "price":"0.98", "size":"3289.11", "side":"SELL", "hash":"c7a4a6ff4b12b20e0d16e5647fe15296cd81da72", "best_bid":"0.18", "best_ask":"0.19"}], "timestamp":"1784449596219", "event_type":"price_change"}
{"market":"0x982eae4503214e5d7992668e93f48f42e4707b92e23bb45f8d52d321f643cbe3", "price_changes":[{"asset_id":"74913635031537477155015393896000154190746945075332596665612975928350948042868", "price":"0.01", "size":"16774.13", "side":"BUY", "hash":"5ad1bd5a0cee5648982721a127cded7fad0aeebd", "best_bid":"0.81", "best_ask":"0.82"}, {"asset_id":"37613674580450069178400687025689415665506452565086963049482350052080099056186", "price":"0.99", "size":"16774.13", "side":"SELL", "hash":"da33db86894692601aa728dbc39cfeb9605f231e", "best_bid":"0.18", "best_ask":"0.19"}], "timestamp":"1784449596219", "event_type":"price_change"}
{"market":"0x982eae4503214e5d7992668e93f48f42e4707b92e23bb45f8d52d321f643cbe3", "price_changes":[{"asset_id":"37613674580450069178400687025689415665506452565086963049482350052080099056186", "price":"0.01", "size":"17919.98", "side":"BUY", "hash":"cee70146ffbfec8c853f39503a4381cdbe939d7b", "best_bid":"0.18", "best_ask":"0.19"}, {"asset_id":"74913635031537477155015393896000154190746945075332596665612975928350948042868", "price":"0.99", "size":"17919.98", "side":"SELL", "hash":"bddd9bf1df633d4d6db02c00402225207529d00e", "best_bid":"0.81", "best_ask":"0.82"}], "timestamp":"1784449596221", "event_type":"price_change"}
{"market":"0x982eae4503214e5d7992668e93f48f42e4707b92e23bb45f8d52d321f643cbe3", "price_changes":[{"asset_id":"74913635031537477155015393896000154190746945075332596665612975928350948042868", "price":"0.01", "size":"16779.13", "side":"BUY", "hash":"29728f34b98183b7cf7fedc430b4c6f201f22031", "best_bid":"0.81", "best_ask":"0.82"}, {"asset_id":"37613674580450069178400687025689415665506452565086963049482350052080099056186", "price":"0.99", "size":"16779.13", "side":"SELL", "hash":"c2d05812a5ab3d7ae920b931be98bdaef45a8e21", "best_bid":"0.18", "best_ask":"0.19"}], "timestamp":"1784449596221", "event_type":"price_change"}
{"market":"0xab772601f501b265bfe8982eb61d5347ef9945de314bfdf4ac0189c288ffb0b3", "price_changes":[{"asset_id":"17924629579804316786455515989238352689210911545477836576430679697715946894553", "price":"0.44", "size":"0", "side":"BUY", "hash":"4830d436968b3501089b7ee6af1508629fd486e1", "best_bid":"0.99", "best_ask":"1"}, {"asset_id":"12935926064588426924078449947177910958215776269411501731627440228801766632772", "price":"0.56", "size":"0", "side":"SELL", "hash":"eef8dafd42f9ebea00651572ecd92a61a79fa546", "best_bid":"0", "best_ask":"0.01"}], "timestamp":"1784449596223", "event_type":"price_change"}
{"market":"0x982eae4503214e5d7992668e93f48f42e4707b92e23bb45f8d52d321f643cbe3", "price_changes":[{"asset_id":"74913635031537477155015393896000154190746945075332596665612975928350948042868", "price":"0.81", "size":"392.9", "side":"BUY", "hash":"b7ad148122f5777767d1b036857b29f67b3ae3dc", "best_bid":"0.81", "best_ask":"0.82"}, {"asset_id":"37613674580450069178400687025689415665506452565086963049482350052080099056186", "price":"0.19", "size":"392.9", "side":"SELL", "hash":"cd36a181a32ab08af215ea04e6ea402af3d572a1", "best_bid":"0.18", "best_ask":"0.19"}], "timestamp":"1784449596223", "event_type":"price_change"}
{"market":"0x982eae4503214e5d7992668e93f48f42e4707b92e23bb45f8d52d321f643cbe3", "price_changes":[{"asset_id":"74913635031537477155015393896000154190746945075332596665612975928350948042868", "price":"0.01", "size":"16784.13", "side":"BUY", "hash":"c269809ac875cc6b8a35e26ef41d3cf583a0dffe", "best_bid":"0.81", "best_ask":"0.82"}, {"asset_id":"37613674580450069178400687025689415665506452565086963049482350052080099056186", "price":"0.99", "size":"16784.13", "side":"SELL", "hash":"af5c25f4961c4e2c8f129fd1458a3ae1c8b7b29e", "best_bid":"0.18", "best_ask":"0.19"}], "timestamp":"1784449596224", "event_type":"price_change"}
{"market":"0x982eae4503214e5d7992668e93f48f42e4707b92e23bb45f8d52d321f643cbe3", "price_changes":[{"asset_id":"74913635031537477155015393896000154190746945075332596665612975928350948042868", "price":"0.61", "size":"95.6", "side":"BUY", "hash":"d679ade67028ffdd98bf36b829c80bd4378b9c07", "best_bid":"0.81", "best_ask":"0.82"}, {"asset_id":"37613674580450069178400687025689415665506452565086963049482350052080099056186", "price":"0.39", "size":"95.6", "side":"SELL", "hash":"ff247be12128f05327559d4c4eb24aa3c0c1cdf7", "best_bid":"0.18", "best_ask":"0.19"}], "timestamp":"1784449596228", "event_type":"price_change"}
{"market":"0x982eae4503214e5d7992668e93f48f42e4707b92e23bb45f8d52d321f643cbe3", "price_changes":[{"asset_id":"37613674580450069178400687025689415665506452565086963049482350052080099056186", "price":"0.08", "size":"1411.35", "side":"BUY", "hash":"2e5e1108276f8f3dfeea4e5056d2030d8a5ea746", "best_bid":"0.18", "best_ask":"0.19"}, {"asset_id":"74913635031537477155015393896000154190746945075332596665612975928350948042868", "price":"0.92", "size":"1411.35", "side":"SELL", "hash":"df7beea4fcbf974dccc30100f252277b6ec93def", "best_bid":"0.81", "best_ask":"0.82"}], "timestamp":"1784449596229", "event_type":"price_change"}
{"market":"0x982eae4503214e5d7992668e93f48f42e4707b92e23bb45f8d52d321f643cbe3", "price_changes":[{"asset_id":"74913635031537477155015393896000154190746945075332596665612975928350948042868", "price":"0.01", "size":"16284.13", "side":"BUY", "hash":"47b9f8e66669f4aaa864d3976b83edaae8e7fabb", "best_bid":"0.81", "best_ask":"0.82"}, {"asset_id":"37613674580450069178400687025689415665506452565086963049482350052080099056186", "price":"0.99", "size":"16284.13", "side":"SELL", "hash":"c314fce809ce5bf3e2b1d222eb21533cbb01425d", "best_bid":"0.18", "best_ask":"0.19"}], "timestamp":"1784449596231", "event_type":"price_change"}
{"market":"0x982eae4503214e5d7992668e93f48f42e4707b92e23bb45f8d52d321f643cbe3", "price_changes":[{"asset_id":"74913635031537477155015393896000154190746945075332596665612975928350948042868", "price":"0.01", "size":"16289.13", "side":"BUY", "hash":"f782b96cc19f0f9c3238a0cd431e962648c4cfb7", "best_bid":"0.81", "best_ask":"0.82"}, {"asset_id":"37613674580450069178400687025689415665506452565086963049482350052080099056186", "price":"0.99", "size":"16289.13", "side":"SELL", "hash":"90fa2e585cf858d486724fd61a922bd4db2564cf", "best_bid":"0.18", "best_ask":"0.19"}], "timestamp":"1784449596232", "event_type":"price_change"}
{"market":"0x982eae4503214e5d7992668e93f48f42e4707b92e23bb45f8d52d321f643cbe3", "price_changes":[{"asset_id":"74913635031537477155015393896000154190746945075332596665612975928350948042868", "price":"0.01", "size":"16294.13", "side":"BUY", "hash":"116dd1162f42bce066124399c5ba992a4097b050", "best_bid":"0.81", "best_ask":"0.82"}, {"asset_id":"37613674580450069178400687025689415665506452565086963049482350052080099056186", "price":"0.99", "size":"16294.13", "side":"SELL", "hash":"de4ca4f7c50077eaae88b5fb700a9b1b22a336c4", "best_bid":"0.18", "best_ask":"0.19"}], "timestamp":"1784449596232", "event_type":"price_change"}
{"market":"0x982eae4503214e5d7992668e93f48f42e4707b92e23bb45f8d52d321f643cbe3", "price_changes":[{"asset_id":"74913635031537477155015393896000154190746945075332596665612975928350948042868", "price":"0.01", "size":"16299.13", "side":"BUY", "hash":"553ff028718f9f50fb72a8a20074cacc1e5b0c60", "best_bid":"0.81", "best_ask":"0.82"}, {"asset_id":"37613674580450069178400687025689415665506452565086963049482350052080099056186", "price":"0.99", "size":"16299.13", "side":"SELL", "hash":"6d19d30f36be72d937d65723d55d81c5e7eecadd", "best_bid":"0.18", "best_ask":"0.19"}], "timestamp":"1784449596233", "event_type":"price_change"}
{"market":"0x982eae4503214e5d7992668e93f48f42e4707b92e23bb45f8d52d321f643cbe3", "price_changes":[{"asset_id":"74913635031537477155015393896000154190746945075332596665612975928350948042868", "price":"0.8", "size":"158.28", "side":"BUY", "hash":"16e9366a7baebbcd8d348ba96987b005bc702cd2", "best_bid":"0.81", "best_ask":"0.82"}, {"asset_id":"37613674580450069178400687025689415665506452565086963049482350052080099056186", "price":"0.2", "size":"158.28", "side":"SELL", "hash":"16489bfdea88643564954a45f5a242e204563c9f", "best_bid":"0.18", "best_ask":"0.19"}], "timestamp":"1784449596237", "event_type":"price_change"}
{"market":"0x982eae4503214e5d7992668e93f48f42e4707b92e23bb45f8d52d321f643cbe3", "price_changes":[{"asset_id":"74913635031537477155015393896000154190746945075332596665612975928350948042868", "price":"0.78", "size":"213.41", "side":"BUY", "hash":"b9f270bd51aa65f707834be5cad7b3c4686730de", "best_bid":"0.81", "best_ask":"0.82"}, {"asset_id":"37613674580450069178400687025689415665506452565086963049482350052080099056186", "price":"0.22", "size":"213.41", "side":"SELL", "hash":"82e8da9f55cb3dd2d30636ff3277cb2f4233e2e7", "best_bid":"0.18", "best_ask":"0.19"}], "timestamp":"1784449596240", "event_type":"price_change"}
{"market":"0x982eae4503214e5d7992668e93f48f42e4707b92e23bb45f8d52d321f643cbe3", "price_changes":[{"asset_id":"37613674580450069178400687025689415665506452565086963049482350052080099056186", "price":"0.12", "size":"207.17", "side":"BUY", "hash":"35cc7df0331366b49b8ebede442084df5bb23d19", "best_bid":"0.18", "best_ask":"0.19"}, {"asset_id":"74913635031537477155015393896000154190746945075332596665612975928350948042868", "price":"0.88", "size":"207.17", "side":"SELL", "hash":"406850f795552ae74882d66338fc70cb68f42cab", "best_bid":"0.81", "best_ask":"0.82"}], "timestamp":"1784449596240", "event_type":"price_change"}
{"market":"0x982eae4503214e5d7992668e93f48f42e4707b92e23bb45f8d52d321f643cbe3", "price_changes":[{"asset_id":"74913635031537477155015393896000154190746945075332596665612975928350948042868", "price":"0.01", "size":"16199.13", "side":"BUY", "hash":"72f6441024380949f8c38caf1b5f9fbac023fe75", "best_bid":"0.81", "best_ask":"0.82"}, {"asset_id":"37613674580450069178400687025689415665506452565086963049482350052080099056186", "price":"0.99", "size":"16199.13", "side":"SELL", "hash":"e87d063a0b7b1d24fa4b8851901bb73460f09f24", "best_bid":"0.18", "best_ask":"0.19"}], "timestamp":"1784449596243", "event_type":"price_change"}
{"market":"0x982eae4503214e5d7992668e93f48f42e4707b92e23bb45f8d52d321f643cbe3", "price_changes":[{"asset_id":"37613674580450069178400687025689415665506452565086963049482350052080099056186", "price":"0.14", "size":"164.34", "side":"BUY", "hash":"5ce699662c671f90d5607f87f59840772c510da3", "best_bid":"0.18", "best_ask":"0.19"}, {"asset_id":"74913635031537477155015393896000154190746945075332596665612975928350948042868", "price":"0.86", "size":"164.34", "side":"SELL", "hash":"9fa4d9a0c2fda5b069e5d3ae05ae3fcdc5af1f18", "best_bid":"0.81", "best_ask":"0.82"}], "timestamp":"1784449596245", "event_type":"price_change"}
{"market":"0x982eae4503214e5d7992668e93f48f42e4707b92e23bb45f8d52d321f643cbe3", "price_changes":[{"asset_id":"37613674580450069178400687025689415665506452565086963049482350052080099056186", "price":"0.13", "size":"426.4", "side":"BUY", "hash":"dbe470928a50db46cf276a2962199da7b3fe7eb6", "best_bid":"0.18", "best_ask":"0.19"}, {"asset_id":"74913635031537477155015393896000154190746945075332596665612975928350948042868", "price":"0.87", "size":"426.4", "side":"SELL", "hash":"08bc5a69f1a98c12f247e9f0b2195ace4f5a08f1", "best_bid":"0.81", "best_ask":"0.82"}], "timestamp":"1784449596246", "event_type":"price_change"}
{"market":"0x982eae4503214e5d7992668e93f48f42e4707b92e23bb45f8d52d321f643cbe3", "price_changes":[{"asset_id":"37613674580450069178400687025689415665506452565086963049482350052080099056186", "price":"0.14", "size":"184.34", "side":"BUY", "hash":"823f4d5d8ca7686e48617ceaf699dff1a393cf3f", "best_bid":"0.18", "best_ask":"0.19"}, {"asset_id":"74913635031537477155015393896000154190746945075332596665612975928350948042868", "price":"0.86", "size":"184.34", "side":"SELL", "hash":"07efab85fb695f24431e976584ff99cefe7266e4", "best_bid":"0.81", "best_ask":"0.82"}], "timestamp":"1784449596248", "event_type":"price_change"}
{"market":"0x982eae4503214e5d7992668e93f48f42e4707b92e23bb45f8d52d321f643cbe3", "price_changes":[{"asset_id":"37613674580450069178400687025689415665506452565086963049482350052080099056186", "price":"0.11", "size":"490.73", "side":"BUY", "hash":"04a51b2dc2d938ee95698e054a81b177bac3f97c", "best_bid":"0.18", "best_ask":"0.19"}, {"asset_id":"74913635031537477155015393896000154190746945075332596665612975928350948042868", "price":"0.89", "size":"490.73", "side":"SELL", "hash":"5e26a7c6e77679376da4614b2a01cdf9fdfdfeb5", "best_bid":"0.81", "best_ask":"0.82"}], "timestamp":"1784449596248", "event_type":"price_change"}
{"market":"0x982eae4503214e5d7992668e93f48f42e4707b92e23bb45f8d52d321f643cbe3", "asset_id":"37613674580450069178400687025689415665506452565086963049482350052080099056186", "price":"0.18", "size":"10", "fee_rate_bps":"0", "side":"SELL", "timestamp":"1784449596247", "event_type":"last_trade_price", "transaction_hash":"0x3a4d6f55e4962574159624155a1068a5dd3e9efaf1a38729a648a8e944e0019c"}
{"market":"0x982eae4503214e5d7992668e93f48f42e4707b92e23bb45f8d52d321f643cbe3", "price_changes":[{"asset_id":"37613674580450069178400687025689415665506452565086963049482350052080099056186", "price":"0.08", "size":"1404.88", "side":"BUY", "hash":"3bed058948bf1ac0f370d3df95782c03538cb1ba", "best_bid":"0.18", "best_ask":"0.19"}, {"asset_id":"74913635031537477155015393896000154190746945075332596665612975928350948042868", "price":"0.92", "size":"1404.88", "side":"SELL", "hash":"05fc0d678546f9bc5ad47e75779abd6df3f8e260", "best_bid":"0.81", "best_ask":"0.82"}], "timestamp":"1784449596252", "event_type":"price_change"}
{"market":"0x982eae4503214e5d7992668e93f48f42e4707b92e23bb45f8d52d321f643cbe3", "price_changes":[{"asset_id":"74913635031537477155015393896000154190746945075332596665612975928350948042868", "price":"0.68", "size":"93.19", "side":"BUY", "hash":"1ef3032ccd03b032f459dedb8ce9ac66b4e37f26", "best_bid":"0.81", "best_ask":"0.82"}, {"asset_id":"37613674580450069178400687025689415665506452565086963049482350052080099056186", "price":"0.32", "size":"93.19", "side":"SELL", "hash":"65168d8030b8ef105a4595adb0fa7edeaddf2c40", "best_bid":"0.18", "best_ask":"0.19"}], "timestamp":"1784449596253", "event_type":"price_change"}
{"market":"0x982eae4503214e5d7992668e93f48f42e4707b92e23bb45f8d52d321f643cbe3", "price_changes":[{"asset_id":"74913635031537477155015393896000154190746945075332596665612975928350948042868", "price":"0.79", "size":"118.19", "side":"BUY", "hash":"f244e10f178e4a3d58debea46eb728c8a29ad18c", "best_bid":"0.81", "best_ask":"0.82"}, {"asset_id":"37613674580450069178400687025689415665506452565086963049482350052080099056186", "price":"0.21", "size":"118.19", "side":"SELL", "hash":"f52b68138d9a50e941bc0918a825dcd2dd576b90", "best_bid":"0.18", "best_ask":"0.19"}], "timestamp":"1784449596253", "event_type":"price_change"}
{"market":"0x982eae4503214e5d7992668e93f48f42e4707b92e23bb45f8d52d321f643cbe3", "price_changes":[{"asset_id":"74913635031537477155015393896000154190746945075332596665612975928350948042868", "price":"0.69", "size":"122.9", "side":"BUY", "hash":"0b5eb539812f2cff498f059ec59f35bf9946c7b8", "best_bid":"0.81", "best_ask":"0.82"}, {"asset_id":"37613674580450069178400687025689415665506452565086963049482350052080099056186", "price":"0.31", "size":"122.9", "side":"SELL", "hash":"d789cf83f5f358366621ccc6d4b5b63f73a23885", "best_bid":"0.18", "best_ask":"0.19"}], "timestamp":"1784449596256", "event_type":"price_change"}
{"market":"0x982eae4503214e5d7992668e93f48f42e4707b92e23bb45f8d52d321f643cbe3", "asset_id":"74913635031537477155015393896000154190746945075332596665612975928350948042868", "price":"0.82", "size":"3.597555", "fee_rate_bps":"0", "side":"BUY", "timestamp":"1784449596253", "event_type":"last_trade_price", "transaction_hash":"0x45b32cfdef50b958b2ee22a0da351f3122d55eafa5d6d6131233e60167d5aa9a"}
{"market":"0x982eae4503214e5d7992668e93f48f42e4707b92e23bb45f8d52d321f643cbe3", "price_changes":[{"asset_id":"74913635031537477155015393896000154190746945075332596665612975928350948042868", "price":"0.69", "size":"97.9", "side":"BUY", "hash":"fce2edaa7280591123aa021b6787e5e1d1a4eb66", "best_bid":"0.81", "best_ask":"0.82"}, {"asset_id":"37613674580450069178400687025689415665506452565086963049482350052080099056186", "price":"0.31", "size":"97.9", "side":"SELL", "hash":"952a825c9d031224c288a8a110491cae45d48aa8", "best_bid":"0.18", "best_ask":"0.19"}], "timestamp":"1784449596257", "event_type":"price_change"}
{"market":"0x982eae4503214e5d7992668e93f48f42e4707b92e23bb45f8d52d321f643cbe3", "price_changes":[{"asset_id":"37613674580450069178400687025689415665506452565086963049482350052080099056186", "price":"0.27", "size":"154.41", "side":"SELL", "hash":"d06c3ec5407d3202c94413b90ed0d50bb6d22165", "best_bid":"0.18", "best_ask":"0.19"}, {"asset_id":"74913635031537477155015393896000154190746945075332596665612975928350948042868", "price":"0.73", "size":"154.41", "side":"BUY", "hash":"7c32f241e85fb1a43e8595cc9d597dfc700a59b2", "best_bid":"0.81", "best_ask":"0.82"}], "timestamp":"1784449596258", "event_type":"price_change"}
{"market":"0x982eae4503214e5d7992668e93f48f42e4707b92e23bb45f8d52d321f643cbe3", "price_changes":[{"asset_id":"74913635031537477155015393896000154190746945075332596665612975928350948042868", "price":"0.01", "size":"16204.14", "side":"BUY", "hash":"c9ab706eec2136d64b50248c008b01d871fe40cc", "best_bid":"0.81", "best_ask":"0.82"}, {"asset_id":"37613674580450069178400687025689415665506452565086963049482350052080099056186", "price":"0.99", "size":"16204.14", "side":"SELL", "hash":"f14c9f31f57f51a71f9dcb747615e185ed4aeddf", "best_bid":"0.18", "best_ask":"0.19"}], "timestamp":"1784449596263", "event_type":"price_change"}
{"market":"0x982eae4503214e5d7992668e93f48f42e4707b92e23bb45f8d52d321f643cbe3", "price_changes":[{"asset_id":"74913635031537477155015393896000154190746945075332596665612975928350948042868", "price":"0.01", "size":"16199.14", "side":"BUY", "hash":"c610b68e22440077a7267b6a268d2bbf6cd90b7f", "best_bid":"0.81", "best_ask":"0.82"}, {"asset_id":"37613674580450069178400687025689415665506452565086963049482350052080099056186", "price":"0.99", "size":"16199.14", "side":"SELL", "hash":"004b34e7ff7c2f76b641c5650a1c70a4a12a83c2", "best_bid":"0.18", "best_ask":"0.19"}], "timestamp":"1784449596264", "event_type":"price_change"}
{"market":"0x982eae4503214e5d7992668e93f48f42e4707b92e23bb45f8d52d321f643cbe3", "price_changes":[{"asset_id":"74913635031537477155015393896000154190746945075332596665612975928350948042868", "price":"0.71", "size":"99", "side":"BUY", "hash":"5a75815a08149a6eac95bb68990b31e61cb4dbee", "best_bid":"0.81", "best_ask":"0.82"}, {"asset_id":"37613674580450069178400687025689415665506452565086963049482350052080099056186", "price":"0.29", "size":"99", "side":"SELL", "hash":"165d7fcad215d2871eb2a78bf39aaadcff0fab26", "best_bid":"0.18", "best_ask":"0.19"}], "timestamp":"1784449596265", "event_type":"price_change"}
{"market":"0xab772601f501b265bfe8982eb61d5347ef9945de314bfdf4ac0189c288ffb0b3", "price_changes":[{"asset_id":"17924629579804316786455515989238352689210911545477836576430679697715946894553", "price":"0.37", "size":"5", "side":"BUY", "hash":"f98a6f743ba745b4ee102664cfc71c9cee2e9965", "best_bid":"0.99", "best_ask":"1"}, {"asset_id":"12935926064588426924078449947177910958215776269411501731627440228801766632772", "price":"0.63", "size":"5", "side":"SELL", "hash":"d322f50b29e28cb404813c0cb260bfa696b625fa", "best_bid":"0", "best_ask":"0.01"}], "timestamp":"1784449596268", "event_type":"price_change"}
{"market":"0x982eae4503214e5d7992668e93f48f42e4707b92e23bb45f8d52d321f643cbe3", "asset_id":"74913635031537477155015393896000154190746945075332596665612975928350948042868", "price":"0.82", "size":"6.097555", "fee_rate_bps":"0", "side":"BUY", "timestamp":"1784449596268", "event_type":"last_trade_price", "transaction_hash":"0x341cb37b8ebb22a4133c6afb5e453b52933227c1eed325ff6545b4e7212b7c22"}
{"market":"0x982eae4503214e5d7992668e93f48f42e4707b92e23bb45f8d52d321f643cbe3", "price_changes":[{"asset_id":"74913635031537477155015393896000154190746945075332596665612975928350948042868", "price":"0.01", "size":"16299.14", "side":"BUY", "hash":"b93f6b12f94fe1b597670ba1fc197dda15ce0ce0", "best_bid":"0.81", "best_ask":"0.82"}, {"asset_id":"37613674580450069178400687025689415665506452565086963049482350052080099056186", "price":"0.99", "size":"16299.14", "side":"SELL", "hash":"410046568ccd7a87c36dd14f7c0fe5121f7a63c4", "best_bid":"0.18", "best_ask":"0.19"}], "timestamp":"1784449596272", "event_type":"price_change"}
{"market":"0x982eae4503214e5d7992668e93f48f42e4707b92e23bb45f8d52d321f643cbe3", "price_changes":[{"asset_id":"74913635031537477155015393896000154190746945075332596665612975928350948042868", "price":"0.69", "size":"85.7", "side":"BUY", "hash":"2e6ec0ac72209444c977a70e4789cad97b9c8c83", "best_bid":"0.81", "best_ask":"0.82"}, {"asset_id":"37613674580450069178400687025689415665506452565086963049482350052080099056186", "price":"0.31", "size":"85.7", "side":"SELL", "hash":"d9c8cce3d876ecef75252e15cf1c94ac048f5899", "best_bid":"0.18", "best_ask":"0.19"}], "timestamp":"1784449596274", "event_type":"price_change"}
{"market":"0x982eae4503214e5d7992668e93f48f42e4707b92e23bb45f8d52d321f643cbe3", "price_changes":[{"asset_id":"37613674580450069178400687025689415665506452565086963049482350052080099056186", "price":"0.17", "size":"10", "side":"BUY", "hash":"8f0586631d3785644121deb991c59def8e592fce", "best_bid":"0.18", "best_ask":"0.19"}, {"asset_id":"74913635031537477155015393896000154190746945075332596665612975928350948042868", "price":"0.83", "size":"10", "side":"SELL", "hash":"f876effb01489eb9f0a045722b047e819896dbcf", "best_bid":"0.81", "best_ask":"0.82"}], "timestamp":"1784449596278", "event_type":"price_change"}
{"market":"0x982eae4503214e5d7992668e93f48f42e4707b92e23bb45f8d52d321f643cbe3", "price_changes":[{"asset_id":"74913635031537477155015393896000154190746945075332596665612975928350948042868", "price":"0.68", "size":"118.19", "side":"BUY", "hash":"6dc4017de769ab012da79682a55ea429a825306e", "best_bid":"0.81", "best_ask":"0.82"}, {"asset_id":"37613674580450069178400687025689415665506452565086963049482350052080099056186", "price":"0.32", "size":"118.19", "side":"SELL", "hash":"e825fd40a6a1a91d97c671272ca4d826c52b3a3d", "best_bid":"0.18", "best_ask":"0.19"}], "timestamp":"1784449596280", "event_type":"price_change"}
{"market":"0x982eae4503214e5d7992668e93f48f42e4707b92e23bb45f8d52d321f643cbe3", "price_changes":[{"asset_id":"37613674580450069178400687025689415665506452565086963049482350052080099056186", "price":"0.18", "size":"18.64", "side":"BUY", "hash":"262aa21c26d3c157fea137d629d70d79aa3f44a9", "best_bid":"0.18", "best_ask":"0.19"}, {"asset_id":"74913635031537477155015393896000154190746945075332596665612975928350948042868", "price":"0.82", "size":"18.64", "side":"SELL", "hash":"0f0f29659f6ef2dacffd8b557e299f1d411cddb1", "best_bid":"0.81", "best_ask":"0.82"}], "timestamp":"1784449596281", "event_type":"price_change"}
{"market":"0x982eae4503214e5d7992668e93f48f42e4707b92e23bb45f8d52d321f643cbe3", "price_changes":[{"asset_id":"74913635031537477155015393896000154190746945075332596665612975928350948042868", "price":"0.73", "size":"159.41", "side":"BUY", "hash":"5b71af60fb3251131dcf1bc794e82712b3f13a80", "best_bid":"0.81", "best_ask":"0.82"}, {"asset_id":"37613674580450069178400687025689415665506452565086963049482350052080099056186", "price":"0.27", "size":"159.41", "side":"SELL", "hash":"27bc7a13526193d90a55d69681d7ed774b2f13ed", "best_bid":"0.18", "best_ask":"0.19"}], "timestamp":"1784449596286", "event_type":"price_change"}
{"market":"0x982eae4503214e5d7992668e93f48f42e4707b92e23bb45f8d52d321f643cbe3", "price_changes":[{"asset_id":"74913635031537477155015393896000154190746945075332596665612975928350948042868", "price":"0.01", "size":"16294.13", "side":"BUY", "hash":"8c767f06916b31a5a4520390b50ec0c9473b0a36", "best_bid":"0.81", "best_ask":"0.82"}, {"asset_id":"37613674580450069178400687025689415665506452565086963049482350052080099056186", "price":"0.99", "size":"16294.13", "side":"SELL", "hash":"442d812a1d0ddf776586bd4f3bcd2342d334b52f", "best_bid":"0.18", "best_ask":"0.19"}], "timestamp":"1784449596290", "event_type":"price_change"}
{"market":"0x982eae4503214e5d7992668e93f48f42e4707b92e23bb45f8d52d321f643cbe3", "price_changes":[{"asset_id":"74913635031537477155015393896000154190746945075332596665612975928350948042868", "price":"0.03", "size":"2090.95", "side":"BUY", "hash":"62346ae2ebbfe305537a1b088c6d9ff3818993ac", "best_bid":"0.81", "best_ask":"0.82"}, {"asset_id":"37613674580450069178400687025689415665506452565086963049482350052080099056186", "price":"0.97", "size":"2090.95", "side":"SELL", "hash":"6590af2f2bf8777bd96aaf79a14aaa387ab39355", "best_bid":"0.18", "best_ask":"0.19"}], "timestamp":"1784449596295", "event_type":"price_change"}
{"market":"0x982eae4503214e5d7992668e93f48f42e4707b92e23bb45f8d52d321f643cbe3", "price_changes":[{"asset_id":"74913635031537477155015393896000154190746945075332596665612975928350948042868", "price":"0.01", "size":"16289.13", "side":"BUY", "hash":"9be0c18e4f40a55795d91cb2788289c05c0fcd06", "best_bid":"0.81", "best_ask":"0.82"}, {"asset_id":"37613674580450069178400687025689415665506452565086963049482350052080099056186", "price":"0.99", "size":"16289.13", "side":"SELL", "hash":"c1a3948405ee28b39324bf69e1968e593a0be69b", "best_bid":"0.18", "best_ask":"0.19"}], "timestamp":"1784449596296", "event_type":"price_change"}
{"market":"0x982eae4503214e5d7992668e93f48f42e4707b92e23bb45f8d52d321f643cbe3", "price_changes":[{"asset_id":"74913635031537477155015393896000154190746945075332596665612975928350948042868", "price":"0.68", "size":"93.19", "side":"BUY", "hash":"00c61ab27b6d8a84adde7fb29473e22f1146c178", "best_bid":"0.81", "best_ask":"0.82"}, {"asset_id":"37613674580450069178400687025689415665506452565086963049482350052080099056186", "price":"0.32", "size":"93.19", "side":"SELL", "hash":"fed0e373c476cd0b3b79adb5e257e37564a9d388", "best_bid":"0.18", "best_ask":"0.19"}], "timestamp":"1784449596298", "event_type":"price_change"}
{"market":"0x982eae4503214e5d7992668e93f48f42e4707b92e23bb45f8d52d321f643cbe3", "price_changes":[{"asset_id":"74913635031537477155015393896000154190746945075332596665612975928350948042868", "price":"0.69", "size":"110.7", "side":"BUY", "hash":"4924b741f8978565f004fe7dc2d9cc22f423601b", "best_bid":"0.81", "best_ask":"0.82"}, {"asset_id":"37613674580450069178400687025689415665506452565086963049482350052080099056186", "price":"0.31", "size":"110.7", "side":"SELL", "hash":"4ab04fabae62bc3d2fa703d7e9c96bfe820b6257", "best_bid":"0.18", "best_ask":"0.19"}], "timestamp":"1784449596302", "event_type":"price_change"}
{"market":"0x982eae4503214e5d7992668e93f48f42e4707b92e23bb45f8d52d321f643cbe3", "price_changes":[{"asset_id":"74913635031537477155015393896000154190746945075332596665612975928350948042868", "price":"0.01", "size":"16789.13", "side":"BUY", "hash":"64c9f83a7f8d0bb7845052e109fb95ccb820c44b", "best_bid":"0.81", "best_ask":"0.82"}, {"asset_id":"37613674580450069178400687025689415665506452565086963049482350052080099056186", "price":"0.99", "size":"16789.13", "side":"SELL", "hash":"b9895484f8b9096799d564c1430acf9365191674", "best_bid":"0.18", "best_ask":"0.19"}], "timestamp":"1784449596305", "event_type":"price_change"}
{"market":"0x982eae4503214e5d7992668e93f48f42e4707b92e23bb45f8d52d321f643cbe3", "price_changes":[{"asset_id":"74913635031537477155015393896000154190746945075332596665612975928350948042868", "price":"0.69", "size":"85.7", "side":"BUY", "hash":"a664118840d1200e1f517f185590909381af0d33", "best_bid":"0.81", "best_ask":"0.82"}, {"asset_id":"37613674580450069178400687025689415665506452565086963049482350052080099056186", "price":"0.31", "size":"85.7", "side":"SELL", "hash":"62ce6d0495a08b9a2a4648f2a5c94c5cb9273284", "best_bid":"0.18", "best_ask":"0.19"}], "timestamp":"1784449596305", "event_type":"price_change"}
{"market":"0x982eae4503214e5d7992668e93f48f42e4707b92e23bb45f8d52d321f643cbe3", "price_changes":[{"asset_id":"37613674580450069178400687025689415665506452565086963049482350052080099056186", "price":"0.17", "size":"16.31", "side":"BUY", "hash":"af7a0d41e65876ae1a58e616d1db65b681a95e36", "best_bid":"0.18", "best_ask":"0.19"}, {"asset_id":"74913635031537477155015393896000154190746945075332596665612975928350948042868", "price":"0.83", "size":"16.31", "side":"SELL", "hash":"52391039b4ecc5501fb022df5f5c1f07c7af05d9", "best_bid":"0.81", "best_ask":"0.82"}], "timestamp":"1784449596312", "event_type":"price_change"}
{"market":"0x982eae4503214e5d7992668e93f48f42e4707b92e23bb45f8d52d321f643cbe3", "price_changes":[{"asset_id":"74913635031537477155015393896000154190746945075332596665612975928350948042868", "price":"0.01", "size":"16689.13", "side":"BUY", "hash":"35400d7e3fc4e8fb849bf839c3eafaf11bc68ee2", "best_bid":"0.81", "best_ask":"0.82"}, {"asset_id":"37613674580450069178400687025689415665506452565086963049482350052080099056186", "price":"0.99", "size":"16689.13", "side":"SELL", "hash":"0808e30fd46fd10b8632f38a8e9583ea1810778f", "best_bid":"0.18", "best_ask":"0.19"}], "timestamp":"1784449596312", "event_type":"price_change"}
{"market":"0x982eae4503214e5d7992668e93f48f42e4707b92e23bb45f8d52d321f643cbe3", "asset_id":"37613674580450069178400687025689415665506452565086963049482350052080099056186", "price":"0.19", "size":"21.05263", "fee_rate_bps":"0", "side":"BUY", "timestamp":"1784449596310", "event_type":"last_trade_price", "transaction_hash":"0x71f92d16b8488cec47f73339cd7375e6f8aee01203e1987045e5237a88465ea7"}
{"market":"0x982eae4503214e5d7992668e93f48f42e4707b92e23bb45f8d52d321f643cbe3", "price_changes":[{"asset_id":"37613674580450069178400687025689415665506452565086963049482350052080099056186", "price":"0.43", "size":"85.5", "side":"SELL", "hash":"4c2ea7176d55419d96510c1c579a4bcc21c84911", "best_bid":"0.18", "best_ask":"0.19"}, {"asset_id":"74913635031537477155015393896000154190746945075332596665612975928350948042868", "price":"0.57", "size":"85.5", "side":"BUY", "hash":"d61c22d705f9fb4d2d23b00e991dde3a89d9ec0c", "best_bid":"0.81", "best_ask":"0.82"}], "timestamp":"1784449596314", "event_type":"price_change"}
{"market":"0x982eae4503214e5d7992668e93f48f42e4707b92e23bb45f8d52d321f643cbe3", "price_changes":[{"asset_id":"37613674580450069178400687025689415665506452565086963049482350052080099056186", "price":"0.18", "size":"13.64", "side":"BUY", "hash":"c6add8b837a3018968624cdc8e1f67658dbef6e2", "best_bid":"0.18", "best_ask":"0.19"}, {"asset_id":"74913635031537477155015393896000154190746945075332596665612975928350948042868", "price":"0.82", "size":"13.64", "side":"SELL", "hash":"aee615cff1e563e483903432379954e5a77f8d37", "best_bid":"0.81", "best_ask":"0.82"}], "timestamp":"1784449596316", "event_type":"price_change"}
{"market":"0x982eae4503214e5d7992668e93f48f42e4707b92e23bb45f8d52d321f643cbe3", "price_changes":[{"asset_id":"37613674580450069178400687025689415665506452565086963049482350052080099056186", "price":"0.39", "size":"105.6", "side":"SELL", "hash":"dff608d5efcf17f926068dd58835beb77c3ab94d", "best_bid":"0.18", "best_ask":"0.19"}, {"asset_id":"74913635031537477155015393896000154190746945075332596665612975928350948042868", "price":"0.61", "size":"105.6", "side":"BUY", "hash":"79fe30359aa24343c92c4c35e77adb06796665b5", "best_bid":"0.81", "best_ask":"0.82"}], "timestamp":"1784449596317", "event_type":"price_change"}
{"market":"0x982eae4503214e5d7992668e93f48f42e4707b92e23bb45f8d52d321f643cbe3", "price_changes":[{"asset_id":"74913635031537477155015393896000154190746945075332596665612975928350948042868", "price":"0.01", "size":"16684.13", "side":"BUY", "hash":"d5ad04c26b2ffadd5bec49f065c82462c45ab07a", "best_bid":"0.81", "best_ask":"0.82"}, {"asset_id":"37613674580450069178400687025689415665506452565086963049482350052080099056186", "price":"0.99", "size":"16684.13", "side":"SELL", "hash":"fa7b78abe413b3801ba4eeb4818695a2eb089679", "best_bid":"0.18", "best_ask":"0.19"}], "timestamp":"1784449596327", "event_type":"price_change"}
{"market":"0xab772601f501b265bfe8982eb61d5347ef9945de314bfdf4ac0189c288ffb0b3", "price_changes":[{"asset_id":"12935926064588426924078449947177910958215776269411501731627440228801766632772", "price":"0.02", "size":"0", "side":"SELL", "hash":"83c229e44ec5b0cb50b9d2a7acc64e02889a33ee", "best_bid":"0", "best_ask":"1"}, {"asset_id":"17924629579804316786455515989238352689210911545477836576430679697715946894553", "price":"0.98", "size":"0", "side":"BUY", "hash":"fc5288624f8f32bd1694129695ea302dad940bf3", "best_bid":"0", "best_ask":"1"}], "timestamp":"1784449596326", "event_type":"price_change"}
{"market":"0xab772601f501b265bfe8982eb61d5347ef9945de314bfdf4ac0189c288ffb0b3", "price_changes":[{"asset_id":"12935926064588426924078449947177910958215776269411501731627440228801766632772", "price":"0.5", "size":"0", "side":"SELL", "hash":"83c229e44ec5b0cb50b9d2a7acc64e02889a33ee", "best_bid":"0", "best_ask":"1"}, {"asset_id":"17924629579804316786455515989238352689210911545477836576430679697715946894553", "price":"0.5", "size":"0", "side":"BUY", "hash":"fc5288624f8f32bd1694129695ea302dad940bf3", "best_bid":"0", "best_ask":"1"}], "timestamp":"1784449596326", "event_type":"price_change"}
{"market":"0xab772601f501b265bfe8982eb61d5347ef9945de314bfdf4ac0189c288ffb0b3", "price_changes":[{"asset_id":"12935926064588426924078449947177910958215776269411501731627440228801766632772", "price":"0.7", "size":"0", "side":"SELL", "hash":"83c229e44ec5b0cb50b9d2a7acc64e02889a33ee", "best_bid":"0", "best_ask":"1"}, {"asset_id":"17924629579804316786455515989238352689210911545477836576430679697715946894553", "price":"0.3", "size":"0", "side":"BUY", "hash":"fc5288624f8f32bd1694129695ea302dad940bf3", "best_bid":"0", "best_ask":"1"}], "timestamp":"1784449596326", "event_type":"price_change"}
{"market":"0xab772601f501b265bfe8982eb61d5347ef9945de314bfdf4ac0189c288ffb0b3", "price_changes":[{"asset_id":"12935926064588426924078449947177910958215776269411501731627440228801766632772", "price":"0.8", "size":"0", "side":"SELL", "hash":"83c229e44ec5b0cb50b9d2a7acc64e02889a33ee", "best_bid":"0", "best_ask":"1"}, {"asset_id":"17924629579804316786455515989238352689210911545477836576430679697715946894553", "price":"0.2", "size":"0", "side":"BUY", "hash":"fc5288624f8f32bd1694129695ea302dad940bf3", "best_bid":"0", "best_ask":"1"}], "timestamp":"1784449596326", "event_type":"price_change"}
{"market":"0xab772601f501b265bfe8982eb61d5347ef9945de314bfdf4ac0189c288ffb0b3", "price_changes":[{"asset_id":"12935926064588426924078449947177910958215776269411501731627440228801766632772", "price":"0.84", "size":"0", "side":"SELL", "hash":"83c229e44ec5b0cb50b9d2a7acc64e02889a33ee", "best_bid":"0", "best_ask":"1"}, {"asset_id":"17924629579804316786455515989238352689210911545477836576430679697715946894553", "price":"0.16", "size":"0", "side":"BUY", "hash":"fc5288624f8f32bd1694129695ea302dad940bf3", "best_bid":"0", "best_ask":"1"}], "timestamp":"1784449596326", "event_type":"price_change"}
{"market":"0xab772601f501b265bfe8982eb61d5347ef9945de314bfdf4ac0189c288ffb0b3", "price_changes":[{"asset_id":"12935926064588426924078449947177910958215776269411501731627440228801766632772", "price":"0.85", "size":"0", "side":"SELL", "hash":"83c229e44ec5b0cb50b9d2a7acc64e02889a33ee", "best_bid":"0", "best_ask":"1"}, {"asset_id":"17924629579804316786455515989238352689210911545477836576430679697715946894553", "price":"0.15", "size":"0", "side":"BUY", "hash":"fc5288624f8f32bd1694129695ea302dad940bf3", "best_bid":"0", "best_ask":"1"}], "timestamp":"1784449596326", "event_type":"price_change"}
{"market":"0xab772601f501b265bfe8982eb61d5347ef9945de314bfdf4ac0189c288ffb0b3", "price_changes":[{"asset_id":"12935926064588426924078449947177910958215776269411501731627440228801766632772", "price":"0.9", "size":"0", "side":"SELL", "hash":"83c229e44ec5b0cb50b9d2a7acc64e02889a33ee", "best_bid":"0", "best_ask":"1"}, {"asset_id":"17924629579804316786455515989238352689210911545477836576430679697715946894553", "price":"0.1", "size":"0", "side":"BUY", "hash":"fc5288624f8f32bd1694129695ea302dad940bf3", "best_bid":"0", "best_ask":"1"}], "timestamp":"1784449596326", "event_type":"price_change"}
{"market":"0xab772601f501b265bfe8982eb61d5347ef9945de314bfdf4ac0189c288ffb0b3", "price_changes":[{"asset_id":"12935926064588426924078449947177910958215776269411501731627440228801766632772", "price":"0.97", "size":"0", "side":"SELL", "hash":"83c229e44ec5b0cb50b9d2a7acc64e02889a33ee", "best_bid":"0", "best_ask":"1"}, {"asset_id":"17924629579804316786455515989238352689210911545477836576430679697715946894553", "price":"0.03", "size":"0", "side":"BUY", "hash":"fc5288624f8f32bd1694129695ea302dad940bf3", "best_bid":"0", "best_ask":"1"}], "timestamp":"1784449596326", "event_type":"price_change"}
{"market":"0xab772601f501b265bfe8982eb61d5347ef9945de314bfdf4ac0189c288ffb0b3", "price_changes":[{"asset_id":"12935926064588426924078449947177910958215776269411501731627440228801766632772", "price":"0.99", "size":"0", "side":"SELL", "hash":"83c229e44ec5b0cb50b9d2a7acc64e02889a33ee", "best_bid":"0", "best_ask":"1"}, {"asset_id":"17924629579804316786455515989238352689210911545477836576430679697715946894553", "price":"0.01", "size":"0", "side":"BUY", "hash":"fc5288624f8f32bd1694129695ea302dad940bf3", "best_bid":"0", "best_ask":"1"}], "timestamp":"1784449596326", "event_type":"price_change"}
{"market":"0x982eae4503214e5d7992668e93f48f42e4707b92e23bb45f8d52d321f643cbe3", "price_changes":[{"asset_id":"74913635031537477155015393896000154190746945075332596665612975928350948042868", "price":"0.68", "size":"118.19", "side":"BUY", "hash":"3f8453edd6618547cbee36d61f016128e2609111", "best_bid":"0.81", "best_ask":"0.82"}, {"asset_id":"37613674580450069178400687025689415665506452565086963049482350052080099056186", "price":"0.32", "size":"118.19", "side":"SELL", "hash":"3acd5dbca9b7aa82cce8543ca8c7da6b765e6e2b", "best_bid":"0.18", "best_ask":"0.19"}], "timestamp":"1784449596328", "event_type":"price_change"}
{"market":"0x982eae4503214e5d7992668e93f48f42e4707b92e23bb45f8d52d321f643cbe3", "price_changes":[{"asset_id":"74913635031537477155015393896000154190746945075332596665612975928350948042868", "price":"0.01", "size":"16184.13", "side":"BUY", "hash":"22d8af672f3601420d3490144cfa489b6ea2e984", "best_bid":"0.81", "best_ask":"0.82"}, {"asset_id":"37613674580450069178400687025689415665506452565086963049482350052080099056186", "price":"0.99", "size":"16184.13", "side":"SELL", "hash":"e53aaf7200bac1d069fd4eedb51ddd1980cf540e", "best_bid":"0.18", "best_ask":"0.19"}], "timestamp":"1784449596328", "event_type":"price_change"}
{"market":"0xab772601f501b265bfe8982eb61d5347ef9945de314bfdf4ac0189c288ffb0b3", "price_changes":[{"asset_id":"17924629579804316786455515989238352689210911545477836576430679697715946894553", "price":"0.99", "size":"0", "side":"BUY", "hash":"fc5288624f8f32bd1694129695ea302dad940bf3", "best_bid":"0", "best_ask":"1"}, {"asset_id":"12935926064588426924078449947177910958215776269411501731627440228801766632772", "price":"0.01", "size":"0", "side":"SELL", "hash":"83c229e44ec5b0cb50b9d2a7acc64e02889a33ee", "best_bid":"0", "best_ask":"1"}], "timestamp":"1784449596326", "event_type":"price_change"}
{"market":"0xab772601f501b265bfe8982eb61d5347ef9945de314bfdf4ac0189c288ffb0b3", "price_changes":[{"asset_id":"17924629579804316786455515989238352689210911545477836576430679697715946894553", "price":"0.98", "size":"0", "side":"BUY", "hash":"fc5288624f8f32bd1694129695ea302dad940bf3", "best_bid":"0", "best_ask":"1"}, {"asset_id":"12935926064588426924078449947177910958215776269411501731627440228801766632772", "price":"0.02", "size":"0", "side":"SELL", "hash":"83c229e44ec5b0cb50b9d2a7acc64e02889a33ee", "best_bid":"0", "best_ask":"1"}], "timestamp":"1784449596326", "event_type":"price_change"}
{"market":"0xab772601f501b265bfe8982eb61d5347ef9945de314bfdf4ac0189c288ffb0b3", "price_changes":[{"asset_id":"17924629579804316786455515989238352689210911545477836576430679697715946894553", "price":"0.97", "size":"0", "side":"BUY", "hash":"fc5288624f8f32bd1694129695ea302dad940bf3", "best_bid":"0", "best_ask":"1"}, {"asset_id":"12935926064588426924078449947177910958215776269411501731627440228801766632772", "price":"0.03", "size":"0", "side":"SELL", "hash":"83c229e44ec5b0cb50b9d2a7acc64e02889a33ee", "best_bid":"0", "best_ask":"1"}], "timestamp":"1784449596326", "event_type":"price_change"}
{"market":"0xab772601f501b265bfe8982eb61d5347ef9945de314bfdf4ac0189c288ffb0b3", "price_changes":[{"asset_id":"17924629579804316786455515989238352689210911545477836576430679697715946894553", "price":"0.96", "size":"0", "side":"BUY", "hash":"fc5288624f8f32bd1694129695ea302dad940bf3", "best_bid":"0", "best_ask":"1"}, {"asset_id":"12935926064588426924078449947177910958215776269411501731627440228801766632772", "price":"0.04", "size":"0", "side":"SELL", "hash":"83c229e44ec5b0cb50b9d2a7acc64e02889a33ee", "best_bid":"0", "best_ask":"1"}], "timestamp":"1784449596326", "event_type":"price_change"}
{"market":"0xab772601f501b265bfe8982eb61d5347ef9945de314bfdf4ac0189c288ffb0b3", "price_changes":[{"asset_id":"17924629579804316786455515989238352689210911545477836576430679697715946894553", "price":"0.95", "size":"0", "side":"BUY", "hash":"fc5288624f8f32bd1694129695ea302dad940bf3", "best_bid":"0", "best_ask":"1"}, {"asset_id":"12935926064588426924078449947177910958215776269411501731627440228801766632772", "price":"0.05", "size":"0", "side":"SELL", "hash":"83c229e44ec5b0cb50b9d2a7acc64e02889a33ee", "best_bid":"0", "best_ask":"1"}], "timestamp":"1784449596326", "event_type":"price_change"}
{"market":"0xab772601f501b265bfe8982eb61d5347ef9945de314bfdf4ac0189c288ffb0b3", "price_changes":[{"asset_id":"17924629579804316786455515989238352689210911545477836576430679697715946894553", "price":"0.94", "size":"0", "side":"BUY", "hash":"fc5288624f8f32bd1694129695ea302dad940bf3", "best_bid":"0", "best_ask":"1"}, {"asset_id":"12935926064588426924078449947177910958215776269411501731627440228801766632772", "price":"0.06", "size":"0", "side":"SELL", "hash":"83c229e44ec5b0cb50b9d2a7acc64e02889a33ee", "best_bid":"0", "best_ask":"1"}], "timestamp":"1784449596326", "event_type":"price_change"}
{"market":"0xab772601f501b265bfe8982eb61d5347ef9945de314bfdf4ac0189c288ffb0b3", "price_changes":[{"asset_id":"17924629579804316786455515989238352689210911545477836576430679697715946894553", "price":"0.93", "size":"0", "side":"BUY", "hash":"fc5288624f8f32bd1694129695ea302dad940bf3", "best_bid":"0", "best_ask":"1"}, {"asset_id":"12935926064588426924078449947177910958215776269411501731627440228801766632772", "price":"0.07", "size":"0", "side":"SELL", "hash":"83c229e44ec5b0cb50b9d2a7acc64e02889a33ee", "best_bid":"0", "best_ask":"1"}], "timestamp":"1784449596326", "event_type":"price_change"}
{"market":"0xab772601f501b265bfe8982eb61d5347ef9945de314bfdf4ac0189c288ffb0b3", "price_changes":[{"asset_id":"17924629579804316786455515989238352689210911545477836576430679697715946894553", "price":"0.92", "size":"0", "side":"BUY", "hash":"fc5288624f8f32bd1694129695ea302dad940bf3", "best_bid":"0", "best_ask":"1"}, {"asset_id":"12935926064588426924078449947177910958215776269411501731627440228801766632772", "price":"0.08", "size":"0", "side":"SELL", "hash":"83c229e44ec5b0cb50b9d2a7acc64e02889a33ee", "best_bid":"0", "best_ask":"1"}], "timestamp":"1784449596326", "event_type":"price_change"}
{"market":"0xab772601f501b265bfe8982eb61d5347ef9945de314bfdf4ac0189c288ffb0b3", "price_changes":[{"asset_id":"17924629579804316786455515989238352689210911545477836576430679697715946894553", "price":"0.91", "size":"0", "side":"BUY", "hash":"fc5288624f8f32bd1694129695ea302dad940bf3", "best_bid":"0", "best_ask":"1"}, {"asset_id":"12935926064588426924078449947177910958215776269411501731627440228801766632772", "price":"0.09", "size":"0", "side":"SELL", "hash":"83c229e44ec5b0cb50b9d2a7acc64e02889a33ee", "best_bid":"0", "best_ask":"1"}], "timestamp":"1784449596326", "event_type":"price_change"}
{"market":"0xab772601f501b265bfe8982eb61d5347ef9945de314bfdf4ac0189c288ffb0b3", "price_changes":[{"asset_id":"17924629579804316786455515989238352689210911545477836576430679697715946894553", "price":"0.9", "size":"0", "side":"BUY", "hash":"fc5288624f8f32bd1694129695ea302dad940bf3", "best_bid":"0", "best_ask":"1"}, {"asset_id":"12935926064588426924078449947177910958215776269411501731627440228801766632772", "price":"0.1", "size":"0", "side":"SELL", "hash":"83c229e44ec5b0cb50b9d2a7acc64e02889a33ee", "best_bid":"0", "best_ask":"1"}], "timestamp":"1784449596326", "event_type":"price_change"}
{"market":"0xab772601f501b265bfe8982eb61d5347ef9945de314bfdf4ac0189c288ffb0b3", "price_changes":[{"asset_id":"17924629579804316786455515989238352689210911545477836576430679697715946894553", "price":"0.89", "size":"0", "side":"BUY", "hash":"fc5288624f8f32bd1694129695ea302dad940bf3", "best_bid":"0", "best_ask":"1"}, {"asset_id":"12935926064588426924078449947177910958215776269411501731627440228801766632772", "price":"0.11", "size":"0", "side":"SELL", "hash":"83c229e44ec5b0cb50b9d2a7acc64e02889a33ee", "best_bid":"0", "best_ask":"1"}], "timestamp":"1784449596326", "event_type":"price_change"}
{"market":"0xab772601f501b265bfe8982eb61d5347ef9945de314bfdf4ac0189c288ffb0b3", "price_changes":[{"asset_id":"17924629579804316786455515989238352689210911545477836576430679697715946894553", "price":"0.86", "size":"0", "side":"BUY", "hash":"fc5288624f8f32bd1694129695ea302dad940bf3", "best_bid":"0", "best_ask":"1"}, {"asset_id":"12935926064588426924078449947177910958215776269411501731627440228801766632772", "price":"0.14", "size":"0", "side":"SELL", "hash":"83c229e44ec5b0cb50b9d2a7acc64e02889a33ee", "best_bid":"0", "best_ask":"1"}], "timestamp":"1784449596326", "event_type":"price_change"}
{"market":"0x982eae4503214e5d7992668e93f48f42e4707b92e23bb45f8d52d321f643cbe3", "price_changes":[{"asset_id":"74913635031537477155015393896000154190746945075332596665612975928350948042868", "price":"0.25", "size":"823.6", "side":"BUY", "hash":"c932a88f5ae3d523290b5cc9b00173b8a8859895", "best_bid":"0.81", "best_ask":"0.82"}, {"asset_id":"37613674580450069178400687025689415665506452565086963049482350052080099056186", "price":"0.75", "size":"823.6", "side":"SELL", "hash":"fb194d6529639b1efaa7cbab8f7f43e89bd3137f", "best_bid":"0.18", "best_ask":"0.19"}], "timestamp":"1784449596334", "event_type":"price_change"}
{"market":"0xab772601f501b265bfe8982eb61d5347ef9945de314bfdf4ac0189c288ffb0b3", "price_changes":[{"asset_id":"17924629579804316786455515989238352689210911545477836576430679697715946894553", "price":"0.85", "size":"0", "side":"BUY", "hash":"fc5288624f8f32bd1694129695ea302dad940bf3", "best_bid":"0", "best_ask":"1"}, {"asset_id":"12935926064588426924078449947177910958215776269411501731627440228801766632772", "price":"0.15", "size":"0", "side":"SELL", "hash":"83c229e44ec5b0cb50b9d2a7acc64e02889a33ee", "best_bid":"0", "best_ask":"1"}], "timestamp":"1784449596326", "event_type":"price_change"}
{"market":"0x982eae4503214e5d7992668e93f48f42e4707b92e23bb45f8d52d321f643cbe3", "price_changes":[{"asset_id":"74913635031537477155015393896000154190746945075332596665612975928350948042868", "price":"0.69", "size":"110.7", "side":"BUY", "hash":"8ed7aee05acbd959de735b117e3eb19f791da0fa", "best_bid":"0.81", "best_ask":"0.82"}, {"asset_id":"37613674580450069178400687025689415665506452565086963049482350052080099056186", "price":"0.31", "size":"110.7", "side":"SELL", "hash":"531fec0639868e968c0a03b389bdd83a3a938847", "best_bid":"0.18", "best_ask":"0.19"}], "timestamp":"1784449596335", "event_type":"price_change"}
{"market":"0x982eae4503214e5d7992668e93f48f42e4707b92e23bb45f8d52d321f643cbe3", "price_changes":[{"asset_id":"74913635031537477155015393896000154190746945075332596665612975928350948042868", "price":"0.68", "size":"93.19", "side":"BUY", "hash":"edecb6fa7a87eb4a75f5ec8dcfe61333ec6eb717", "best_bid":"0.81", "best_ask":"0.82"}, {"asset_id":"37613674580450069178400687025689415665506452565086963049482350052080099056186", "price":"0.32", "size":"93.19", "side":"SELL", "hash":"fd32e3dc4b79fcb3ebbbd23c6cde10e0cebe883c", "best_bid":"0.18", "best_ask":"0.19"}], "timestamp":"1784449596335", "event_type":"price_change"}
{"market":"0xab772601f501b265bfe8982eb61d5347ef9945de314bfdf4ac0189c288ffb0b3", "price_changes":[{"asset_id":"17924629579804316786455515989238352689210911545477836576430679697715946894553", "price":"0.84", "size":"0", "side":"BUY", "hash":"fc5288624f8f32bd1694129695ea302dad940bf3", "best_bid":"0", "best_ask":"1"}, {"asset_id":"12935926064588426924078449947177910958215776269411501731627440228801766632772", "price":"0.16", "size":"0", "side":"SELL", "hash":"83c229e44ec5b0cb50b9d2a7acc64e02889a33ee", "best_bid":"0", "best_ask":"1"}], "timestamp":"1784449596326", "event_type":"price_change"}
{"market":"0xab772601f501b265bfe8982eb61d5347ef9945de314bfdf4ac0189c288ffb0b3", "price_changes":[{"asset_id":"17924629579804316786455515989238352689210911545477836576430679697715946894553", "price":"0.83", "size":"0", "side":"BUY", "hash":"fc5288624f8f32bd1694129695ea302dad940bf3", "best_bid":"0", "best_ask":"1"}, {"asset_id":"12935926064588426924078449947177910958215776269411501731627440228801766632772", "price":"0.17", "size":"0", "side":"SELL", "hash":"83c229e44ec5b0cb50b9d2a7acc64e02889a33ee", "best_bid":"0", "best_ask":"1"}], "timestamp":"1784449596326", "event_type":"price_change"}
{"market":"0xab772601f501b265bfe8982eb61d5347ef9945de314bfdf4ac0189c288ffb0b3", "price_changes":[{"asset_id":"17924629579804316786455515989238352689210911545477836576430679697715946894553", "price":"0.82", "size":"0", "side":"BUY", "hash":"fc5288624f8f32bd1694129695ea302dad940bf3", "best_bid":"0", "best_ask":"1"}, {"asset_id":"12935926064588426924078449947177910958215776269411501731627440228801766632772", "price":"0.18", "size":"0", "side":"SELL", "hash":"83c229e44ec5b0cb50b9d2a7acc64e02889a33ee", "best_bid":"0", "best_ask":"1"}], "timestamp":"1784449596326", "event_type":"price_change"}
{"market":"0xab772601f501b265bfe8982eb61d5347ef9945de314bfdf4ac0189c288ffb0b3", "price_changes":[{"asset_id":"17924629579804316786455515989238352689210911545477836576430679697715946894553", "price":"0.81", "size":"0", "side":"BUY", "hash":"fc5288624f8f32bd1694129695ea302dad940bf3", "best_bid":"0", "best_ask":"1"}, {"asset_id":"12935926064588426924078449947177910958215776269411501731627440228801766632772", "price":"0.19", "size":"0", "side":"SELL", "hash":"83c229e44ec5b0cb50b9d2a7acc64e02889a33ee", "best_bid":"0", "best_ask":"1"}], "timestamp":"1784449596326", "event_type":"price_change"}
{"market":"0xab772601f501b265bfe8982eb61d5347ef9945de314bfdf4ac0189c288ffb0b3", "price_changes":[{"asset_id":"17924629579804316786455515989238352689210911545477836576430679697715946894553", "price":"0.79", "size":"0", "side":"BUY", "hash":"fc5288624f8f32bd1694129695ea302dad940bf3", "best_bid":"0", "best_ask":"1"}, {"asset_id":"12935926064588426924078449947177910958215776269411501731627440228801766632772", "price":"0.21", "size":"0", "side":"SELL", "hash":"83c229e44ec5b0cb50b9d2a7acc64e02889a33ee", "best_bid":"0", "best_ask":"1"}], "timestamp":"1784449596326", "event_type":"price_change"}
{"market":"0xab772601f501b265bfe8982eb61d5347ef9945de314bfdf4ac0189c288ffb0b3", "price_changes":[{"asset_id":"17924629579804316786455515989238352689210911545477836576430679697715946894553", "price":"0.78", "size":"0", "side":"BUY", "hash":"fc5288624f8f32bd1694129695ea302dad940bf3", "best_bid":"0", "best_ask":"1"}, {"asset_id":"12935926064588426924078449947177910958215776269411501731627440228801766632772", "price":"0.22", "size":"0", "side":"SELL", "hash":"83c229e44ec5b0cb50b9d2a7acc64e02889a33ee", "best_bid":"0", "best_ask":"1"}], "timestamp":"1784449596326", "event_type":"price_change"}
{"market":"0xab772601f501b265bfe8982eb61d5347ef9945de314bfdf4ac0189c288ffb0b3", "price_changes":[{"asset_id":"17924629579804316786455515989238352689210911545477836576430679697715946894553", "price":"0.77", "size":"0", "side":"BUY", "hash":"fc5288624f8f32bd1694129695ea302dad940bf3", "best_bid":"0", "best_ask":"1"}, {"asset_id":"12935926064588426924078449947177910958215776269411501731627440228801766632772", "price":"0.23", "size":"0", "side":"SELL", "hash":"83c229e44ec5b0cb50b9d2a7acc64e02889a33ee", "best_bid":"0", "best_ask":"1"}], "timestamp":"1784449596326", "event_type":"price_change"}
{"market":"0xab772601f501b265bfe8982eb61d5347ef9945de314bfdf4ac0189c288ffb0b3", "price_changes":[{"asset_id":"17924629579804316786455515989238352689210911545477836576430679697715946894553", "price":"0.75", "size":"0", "side":"BUY", "hash":"fc5288624f8f32bd1694129695ea302dad940bf3", "best_bid":"0", "best_ask":"1"}, {"asset_id":"12935926064588426924078449947177910958215776269411501731627440228801766632772", "price":"0.25", "size":"0", "side":"SELL", "hash":"83c229e44ec5b0cb50b9d2a7acc64e02889a33ee", "best_bid":"0", "best_ask":"1"}], "timestamp":"1784449596326", "event_type":"price_change"}
{"market":"0xab772601f501b265bfe8982eb61d5347ef9945de314bfdf4ac0189c288ffb0b3", "price_changes":[{"asset_id":"17924629579804316786455515989238352689210911545477836576430679697715946894553", "price":"0.73", "size":"0", "side":"BUY", "hash":"fc5288624f8f32bd1694129695ea302dad940bf3", "best_bid":"0", "best_ask":"1"}, {"asset_id":"12935926064588426924078449947177910958215776269411501731627440228801766632772", "price":"0.27", "size":"0", "side":"SELL", "hash":"83c229e44ec5b0cb50b9d2a7acc64e02889a33ee", "best_bid":"0", "best_ask":"1"}], "timestamp":"1784449596326", "event_type":"price_change"}
{"market":"0xab772601f501b265bfe8982eb61d5347ef9945de314bfdf4ac0189c288ffb0b3", "price_changes":[{"asset_id":"17924629579804316786455515989238352689210911545477836576430679697715946894553", "price":"0.71", "size":"0", "side":"BUY", "hash":"fc5288624f8f32bd1694129695ea302dad940bf3", "best_bid":"0", "best_ask":"1"}, {"asset_id":"12935926064588426924078449947177910958215776269411501731627440228801766632772", "price":"0.29", "size":"0", "side":"SELL", "hash":"83c229e44ec5b0cb50b9d2a7acc64e02889a33ee", "best_bid":"0", "best_ask":"1"}], "timestamp":"1784449596326", "event_type":"price_change"}
{"market":"0xab772601f501b265bfe8982eb61d5347ef9945de314bfdf4ac0189c288ffb0b3", "price_changes":[{"asset_id":"17924629579804316786455515989238352689210911545477836576430679697715946894553", "price":"0.68", "size":"0", "side":"BUY", "hash":"fc5288624f8f32bd1694129695ea302dad940bf3", "best_bid":"0", "best_ask":"1"}, {"asset_id":"12935926064588426924078449947177910958215776269411501731627440228801766632772", "price":"0.32", "size":"0", "side":"SELL", "hash":"83c229e44ec5b0cb50b9d2a7acc64e02889a33ee", "best_bid":"0", "best_ask":"1"}], "timestamp":"1784449596326", "event_type":"price_change"}
{"market":"0xab772601f501b265bfe8982eb61d5347ef9945de314bfdf4ac0189c288ffb0b3", "price_changes":[{"asset_id":"17924629579804316786455515989238352689210911545477836576430679697715946894553", "price":"0.66", "size":"0", "side":"BUY", "hash":"fc5288624f8f32bd1694129695ea302dad940bf3", "best_bid":"0", "best_ask":"1"}, {"asset_id":"12935926064588426924078449947177910958215776269411501731627440228801766632772", "price":"0.34", "size":"0", "side":"SELL", "hash":"83c229e44ec5b0cb50b9d2a7acc64e02889a33ee", "best_bid":"0", "best_ask":"1"}], "timestamp":"1784449596326", "event_type":"price_change"}
{"market":"0xab772601f501b265bfe8982eb61d5347ef9945de314bfdf4ac0189c288ffb0b3", "price_changes":[{"asset_id":"17924629579804316786455515989238352689210911545477836576430679697715946894553", "price":"0.65", "size":"0", "side":"BUY", "hash":"fc5288624f8f32bd1694129695ea302dad940bf3", "best_bid":"0", "best_ask":"1"}, {"asset_id":"12935926064588426924078449947177910958215776269411501731627440228801766632772", "price":"0.35", "size":"0", "side":"SELL", "hash":"83c229e44ec5b0cb50b9d2a7acc64e02889a33ee", "best_bid":"0", "best_ask":"1"}], "timestamp":"1784449596326", "event_type":"price_change"}
{"market":"0xab772601f501b265bfe8982eb61d5347ef9945de314bfdf4ac0189c288ffb0b3", "price_changes":[{"asset_id":"17924629579804316786455515989238352689210911545477836576430679697715946894553", "price":"0.61", "size":"0", "side":"BUY", "hash":"fc5288624f8f32bd1694129695ea302dad940bf3", "best_bid":"0", "best_ask":"1"}, {"asset_id":"12935926064588426924078449947177910958215776269411501731627440228801766632772", "price":"0.39", "size":"0", "side":"SELL", "hash":"83c229e44ec5b0cb50b9d2a7acc64e02889a33ee", "best_bid":"0", "best_ask":"1"}], "timestamp":"1784449596326", "event_type":"price_change"}
{"market":"0xab772601f501b265bfe8982eb61d5347ef9945de314bfdf4ac0189c288ffb0b3", "price_changes":[{"asset_id":"17924629579804316786455515989238352689210911545477836576430679697715946894553", "price":"0.58", "size":"0", "side":"BUY", "hash":"fc5288624f8f32bd1694129695ea302dad940bf3", "best_bid":"0", "best_ask":"1"}, {"asset_id":"12935926064588426924078449947177910958215776269411501731627440228801766632772", "price":"0.42", "size":"0", "side":"SELL", "hash":"83c229e44ec5b0cb50b9d2a7acc64e02889a33ee", "best_bid":"0", "best_ask":"1"}], "timestamp":"1784449596326", "event_type":"price_change"}
{"market":"0xab772601f501b265bfe8982eb61d5347ef9945de314bfdf4ac0189c288ffb0b3", "price_changes":[{"asset_id":"17924629579804316786455515989238352689210911545477836576430679697715946894553", "price":"0.57", "size":"0", "side":"BUY", "hash":"fc5288624f8f32bd1694129695ea302dad940bf3", "best_bid":"0", "best_ask":"1"}, {"asset_id":"12935926064588426924078449947177910958215776269411501731627440228801766632772", "price":"0.43", "size":"0", "side":"SELL", "hash":"83c229e44ec5b0cb50b9d2a7acc64e02889a33ee", "best_bid":"0", "best_ask":"1"}], "timestamp":"1784449596326", "event_type":"price_change"}
{"market":"0xab772601f501b265bfe8982eb61d5347ef9945de314bfdf4ac0189c288ffb0b3", "price_changes":[{"asset_id":"17924629579804316786455515989238352689210911545477836576430679697715946894553", "price":"0.55", "size":"0", "side":"BUY", "hash":"fc5288624f8f32bd1694129695ea302dad940bf3", "best_bid":"0", "best_ask":"1"}, {"asset_id":"12935926064588426924078449947177910958215776269411501731627440228801766632772", "price":"0.45", "size":"0", "side":"SELL", "hash":"83c229e44ec5b0cb50b9d2a7acc64e02889a33ee", "best_bid":"0", "best_ask":"1"}], "timestamp":"1784449596326", "event_type":"price_change"}
{"market":"0xab772601f501b265bfe8982eb61d5347ef9945de314bfdf4ac0189c288ffb0b3", "price_changes":[{"asset_id":"17924629579804316786455515989238352689210911545477836576430679697715946894553", "price":"0.53", "size":"0", "side":"BUY", "hash":"fc5288624f8f32bd1694129695ea302dad940bf3", "best_bid":"0", "best_ask":"1"}, {"asset_id":"12935926064588426924078449947177910958215776269411501731627440228801766632772", "price":"0.47", "size":"0", "side":"SELL", "hash":"83c229e44ec5b0cb50b9d2a7acc64e02889a33ee", "best_bid":"0", "best_ask":"1"}], "timestamp":"1784449596326", "event_type":"price_change"}
{"market":"0xab772601f501b265bfe8982eb61d5347ef9945de314bfdf4ac0189c288ffb0b3", "price_changes":[{"asset_id":"17924629579804316786455515989238352689210911545477836576430679697715946894553", "price":"0.52", "size":"0", "side":"BUY", "hash":"fc5288624f8f32bd1694129695ea302dad940bf3", "best_bid":"0", "best_ask":"1"}, {"asset_id":"12935926064588426924078449947177910958215776269411501731627440228801766632772", "price":"0.48", "size":"0", "side":"SELL", "hash":"83c229e44ec5b0cb50b9d2a7acc64e02889a33ee", "best_bid":"0", "best_ask":"1"}], "timestamp":"1784449596326", "event_type":"price_change"}
{"market":"0xab772601f501b265bfe8982eb61d5347ef9945de314bfdf4ac0189c288ffb0b3", "price_changes":[{"asset_id":"17924629579804316786455515989238352689210911545477836576430679697715946894553", "price":"0.51", "size":"0", "side":"BUY", "hash":"fc5288624f8f32bd1694129695ea302dad940bf3", "best_bid":"0", "best_ask":"1"}, {"asset_id":"12935926064588426924078449947177910958215776269411501731627440228801766632772", "price":"0.49", "size":"0", "side":"SELL", "hash":"83c229e44ec5b0cb50b9d2a7acc64e02889a33ee", "best_bid":"0", "best_ask":"1"}], "timestamp":"1784449596326", "event_type":"price_change"}
{"market":"0xab772601f501b265bfe8982eb61d5347ef9945de314bfdf4ac0189c288ffb0b3", "price_changes":[{"asset_id":"17924629579804316786455515989238352689210911545477836576430679697715946894553", "price":"0.46", "size":"0", "side":"BUY", "hash":"fc5288624f8f32bd1694129695ea302dad940bf3", "best_bid":"0", "best_ask":"1"}, {"asset_id":"12935926064588426924078449947177910958215776269411501731627440228801766632772", "price":"0.54", "size":"0", "side":"SELL", "hash":"83c229e44ec5b0cb50b9d2a7acc64e02889a33ee", "best_bid":"0", "best_ask":"1"}], "timestamp":"1784449596326", "event_type":"price_change"}
{"market":"0xab772601f501b265bfe8982eb61d5347ef9945de314bfdf4ac0189c288ffb0b3", "price_changes":[{"asset_id":"17924629579804316786455515989238352689210911545477836576430679697715946894553", "price":"0.45", "size":"0", "side":"BUY", "hash":"fc5288624f8f32bd1694129695ea302dad940bf3", "best_bid":"0", "best_ask":"1"}, {"asset_id":"12935926064588426924078449947177910958215776269411501731627440228801766632772", "price":"0.55", "size":"0", "side":"SELL", "hash":"83c229e44ec5b0cb50b9d2a7acc64e02889a33ee", "best_bid":"0", "best_ask":"1"}], "timestamp":"1784449596326", "event_type":"price_change"}
{"market":"0xab772601f501b265bfe8982eb61d5347ef9945de314bfdf4ac0189c288ffb0b3", "price_changes":[{"asset_id":"17924629579804316786455515989238352689210911545477836576430679697715946894553", "price":"0.43", "size":"0", "side":"BUY", "hash":"fc5288624f8f32bd1694129695ea302dad940bf3", "best_bid":"0", "best_ask":"1"}, {"asset_id":"12935926064588426924078449947177910958215776269411501731627440228801766632772", "price":"0.57", "size":"0", "side":"SELL", "hash":"83c229e44ec5b0cb50b9d2a7acc64e02889a33ee", "best_bid":"0", "best_ask":"1"}], "timestamp":"1784449596326", "event_type":"price_change"}
{"market":"0xab772601f501b265bfe8982eb61d5347ef9945de314bfdf4ac0189c288ffb0b3", "price_changes":[{"asset_id":"17924629579804316786455515989238352689210911545477836576430679697715946894553", "price":"0.42", "size":"0", "side":"BUY", "hash":"fc5288624f8f32bd1694129695ea302dad940bf3", "best_bid":"0", "best_ask":"1"}, {"asset_id":"12935926064588426924078449947177910958215776269411501731627440228801766632772", "price":"0.58", "size":"0", "side":"SELL", "hash":"83c229e44ec5b0cb50b9d2a7acc64e02889a33ee", "best_bid":"0", "best_ask":"1"}], "timestamp":"1784449596326", "event_type":"price_change"}
{"market":"0xab772601f501b265bfe8982eb61d5347ef9945de314bfdf4ac0189c288ffb0b3", "price_changes":[{"asset_id":"17924629579804316786455515989238352689210911545477836576430679697715946894553", "price":"0.41", "size":"0", "side":"BUY", "hash":"fc5288624f8f32bd1694129695ea302dad940bf3", "best_bid":"0", "best_ask":"1"}, {"asset_id":"12935926064588426924078449947177910958215776269411501731627440228801766632772", "price":"0.59", "size":"0", "side":"SELL", "hash":"83c229e44ec5b0cb50b9d2a7acc64e02889a33ee", "best_bid":"0", "best_ask":"1"}], "timestamp":"1784449596326", "event_type":"price_change"}
{"market":"0xab772601f501b265bfe8982eb61d5347ef9945de314bfdf4ac0189c288ffb0b3", "price_changes":[{"asset_id":"17924629579804316786455515989238352689210911545477836576430679697715946894553", "price":"0.4", "size":"0", "side":"BUY", "hash":"fc5288624f8f32bd1694129695ea302dad940bf3", "best_bid":"0", "best_ask":"1"}, {"asset_id":"12935926064588426924078449947177910958215776269411501731627440228801766632772", "price":"0.6", "size":"0", "side":"SELL", "hash":"83c229e44ec5b0cb50b9d2a7acc64e02889a33ee", "best_bid":"0", "best_ask":"1"}], "timestamp":"1784449596326", "event_type":"price_change"}
{"market":"0xab772601f501b265bfe8982eb61d5347ef9945de314bfdf4ac0189c288ffb0b3", "price_changes":[{"asset_id":"17924629579804316786455515989238352689210911545477836576430679697715946894553", "price":"0.37", "size":"0", "side":"BUY", "hash":"fc5288624f8f32bd1694129695ea302dad940bf3", "best_bid":"0", "best_ask":"1"}, {"asset_id":"12935926064588426924078449947177910958215776269411501731627440228801766632772", "price":"0.63", "size":"0", "side":"SELL", "hash":"83c229e44ec5b0cb50b9d2a7acc64e02889a33ee", "best_bid":"0", "best_ask":"1"}], "timestamp":"1784449596326", "event_type":"price_change"}
{"market":"0xab772601f501b265bfe8982eb61d5347ef9945de314bfdf4ac0189c288ffb0b3", "price_changes":[{"asset_id":"17924629579804316786455515989238352689210911545477836576430679697715946894553", "price":"0.36", "size":"0", "side":"BUY", "hash":"fc5288624f8f32bd1694129695ea302dad940bf3", "best_bid":"0", "best_ask":"1"}, {"asset_id":"12935926064588426924078449947177910958215776269411501731627440228801766632772", "price":"0.64", "size":"0", "side":"SELL", "hash":"83c229e44ec5b0cb50b9d2a7acc64e02889a33ee", "best_bid":"0", "best_ask":"1"}], "timestamp":"1784449596326", "event_type":"price_change"}
{"market":"0xab772601f501b265bfe8982eb61d5347ef9945de314bfdf4ac0189c288ffb0b3", "price_changes":[{"asset_id":"17924629579804316786455515989238352689210911545477836576430679697715946894553", "price":"0.35", "size":"0", "side":"BUY", "hash":"fc5288624f8f32bd1694129695ea302dad940bf3", "best_bid":"0", "best_ask":"1"}, {"asset_id":"12935926064588426924078449947177910958215776269411501731627440228801766632772", "price":"0.65", "size":"0", "side":"SELL", "hash":"83c229e44ec5b0cb50b9d2a7acc64e02889a33ee", "best_bid":"0", "best_ask":"1"}], "timestamp":"1784449596326", "event_type":"price_change"}
{"market":"0xab772601f501b265bfe8982eb61d5347ef9945de314bfdf4ac0189c288ffb0b3", "price_changes":[{"asset_id":"17924629579804316786455515989238352689210911545477836576430679697715946894553", "price":"0.34", "size":"0", "side":"BUY", "hash":"fc5288624f8f32bd1694129695ea302dad940bf3", "best_bid":"0", "best_ask":"1"}, {"asset_id":"12935926064588426924078449947177910958215776269411501731627440228801766632772", "price":"0.66", "size":"0", "side":"SELL", "hash":"83c229e44ec5b0cb50b9d2a7acc64e02889a33ee", "best_bid":"0", "best_ask":"1"}], "timestamp":"1784449596326", "event_type":"price_change"}
{"market":"0xab772601f501b265bfe8982eb61d5347ef9945de314bfdf4ac0189c288ffb0b3", "price_changes":[{"asset_id":"17924629579804316786455515989238352689210911545477836576430679697715946894553", "price":"0.33", "size":"0", "side":"BUY", "hash":"fc5288624f8f32bd1694129695ea302dad940bf3", "best_bid":"0", "best_ask":"1"}, {"asset_id":"12935926064588426924078449947177910958215776269411501731627440228801766632772", "price":"0.67", "size":"0", "side":"SELL", "hash":"83c229e44ec5b0cb50b9d2a7acc64e02889a33ee", "best_bid":"0", "best_ask":"1"}], "timestamp":"1784449596326", "event_type":"price_change"}
{"market":"0xab772601f501b265bfe8982eb61d5347ef9945de314bfdf4ac0189c288ffb0b3", "price_changes":[{"asset_id":"17924629579804316786455515989238352689210911545477836576430679697715946894553", "price":"0.31", "size":"0", "side":"BUY", "hash":"fc5288624f8f32bd1694129695ea302dad940bf3", "best_bid":"0", "best_ask":"1"}, {"asset_id":"12935926064588426924078449947177910958215776269411501731627440228801766632772", "price":"0.69", "size":"0", "side":"SELL", "hash":"83c229e44ec5b0cb50b9d2a7acc64e02889a33ee", "best_bid":"0", "best_ask":"1"}], "timestamp":"1784449596326", "event_type":"price_change"}
{"market":"0xab772601f501b265bfe8982eb61d5347ef9945de314bfdf4ac0189c288ffb0b3", "price_changes":[{"asset_id":"17924629579804316786455515989238352689210911545477836576430679697715946894553", "price":"0.3", "size":"0", "side":"BUY", "hash":"fc5288624f8f32bd1694129695ea302dad940bf3", "best_bid":"0", "best_ask":"1"}, {"asset_id":"12935926064588426924078449947177910958215776269411501731627440228801766632772", "price":"0.7", "size":"0", "side":"SELL", "hash":"83c229e44ec5b0cb50b9d2a7acc64e02889a33ee", "best_bid":"0", "best_ask":"1"}], "timestamp":"1784449596326", "event_type":"price_change"}
{"market":"0xab772601f501b265bfe8982eb61d5347ef9945de314bfdf4ac0189c288ffb0b3", "price_changes":[{"asset_id":"17924629579804316786455515989238352689210911545477836576430679697715946894553", "price":"0.27", "size":"0", "side":"BUY", "hash":"fc5288624f8f32bd1694129695ea302dad940bf3", "best_bid":"0", "best_ask":"1"}, {"asset_id":"12935926064588426924078449947177910958215776269411501731627440228801766632772", "price":"0.73", "size":"0", "side":"SELL", "hash":"83c229e44ec5b0cb50b9d2a7acc64e02889a33ee", "best_bid":"0", "best_ask":"1"}], "timestamp":"1784449596326", "event_type":"price_change"}
{"market":"0xab772601f501b265bfe8982eb61d5347ef9945de314bfdf4ac0189c288ffb0b3", "price_changes":[{"asset_id":"17924629579804316786455515989238352689210911545477836576430679697715946894553", "price":"0.26", "size":"0", "side":"BUY", "hash":"fc5288624f8f32bd1694129695ea302dad940bf3", "best_bid":"0", "best_ask":"1"}, {"asset_id":"12935926064588426924078449947177910958215776269411501731627440228801766632772", "price":"0.74", "size":"0", "side":"SELL", "hash":"83c229e44ec5b0cb50b9d2a7acc64e02889a33ee", "best_bid":"0", "best_ask":"1"}], "timestamp":"1784449596326", "event_type":"price_change"}
{"market":"0xab772601f501b265bfe8982eb61d5347ef9945de314bfdf4ac0189c288ffb0b3", "price_changes":[{"asset_id":"17924629579804316786455515989238352689210911545477836576430679697715946894553", "price":"0.24", "size":"0", "side":"BUY", "hash":"fc5288624f8f32bd1694129695ea302dad940bf3", "best_bid":"0", "best_ask":"1"}, {"asset_id":"12935926064588426924078449947177910958215776269411501731627440228801766632772", "price":"0.76", "size":"0", "side":"SELL", "hash":"83c229e44ec5b0cb50b9d2a7acc64e02889a33ee", "best_bid":"0", "best_ask":"1"}], "timestamp":"1784449596326", "event_type":"price_change"}
{"market":"0xab772601f501b265bfe8982eb61d5347ef9945de314bfdf4ac0189c288ffb0b3", "price_changes":[{"asset_id":"17924629579804316786455515989238352689210911545477836576430679697715946894553", "price":"0.21", "size":"0", "side":"BUY", "hash":"fc5288624f8f32bd1694129695ea302dad940bf3", "best_bid":"0", "best_ask":"1"}, {"asset_id":"12935926064588426924078449947177910958215776269411501731627440228801766632772", "price":"0.79", "size":"0", "side":"SELL", "hash":"83c229e44ec5b0cb50b9d2a7acc64e02889a33ee", "best_bid":"0", "best_ask":"1"}], "timestamp":"1784449596326", "event_type":"price_change"}
{"market":"0xab772601f501b265bfe8982eb61d5347ef9945de314bfdf4ac0189c288ffb0b3", "price_changes":[{"asset_id":"17924629579804316786455515989238352689210911545477836576430679697715946894553", "price":"0.2", "size":"0", "side":"BUY", "hash":"fc5288624f8f32bd1694129695ea302dad940bf3", "best_bid":"0", "best_ask":"1"}, {"asset_id":"12935926064588426924078449947177910958215776269411501731627440228801766632772", "price":"0.8", "size":"0", "side":"SELL", "hash":"83c229e44ec5b0cb50b9d2a7acc64e02889a33ee", "best_bid":"0", "best_ask":"1"}], "timestamp":"1784449596326", "event_type":"price_change"}
{"market":"0xab772601f501b265bfe8982eb61d5347ef9945de314bfdf4ac0189c288ffb0b3", "price_changes":[{"asset_id":"17924629579804316786455515989238352689210911545477836576430679697715946894553", "price":"0.19", "size":"0", "side":"BUY", "hash":"fc5288624f8f32bd1694129695ea302dad940bf3", "best_bid":"0", "best_ask":"1"}, {"asset_id":"12935926064588426924078449947177910958215776269411501731627440228801766632772", "price":"0.81", "size":"0", "side":"SELL", "hash":"83c229e44ec5b0cb50b9d2a7acc64e02889a33ee", "best_bid":"0", "best_ask":"1"}], "timestamp":"1784449596326", "event_type":"price_change"}
{"market":"0xab772601f501b265bfe8982eb61d5347ef9945de314bfdf4ac0189c288ffb0b3", "price_changes":[{"asset_id":"17924629579804316786455515989238352689210911545477836576430679697715946894553", "price":"0.18", "size":"0", "side":"BUY", "hash":"fc5288624f8f32bd1694129695ea302dad940bf3", "best_bid":"0", "best_ask":"1"}, {"asset_id":"12935926064588426924078449947177910958215776269411501731627440228801766632772", "price":"0.82", "size":"0", "side":"SELL", "hash":"83c229e44ec5b0cb50b9d2a7acc64e02889a33ee", "best_bid":"0", "best_ask":"1"}], "timestamp":"1784449596326", "event_type":"price_change"}
{"market":"0xab772601f501b265bfe8982eb61d5347ef9945de314bfdf4ac0189c288ffb0b3", "price_changes":[{"asset_id":"17924629579804316786455515989238352689210911545477836576430679697715946894553", "price":"0.16", "size":"0", "side":"BUY", "hash":"fc5288624f8f32bd1694129695ea302dad940bf3", "best_bid":"0", "best_ask":"1"}, {"asset_id":"12935926064588426924078449947177910958215776269411501731627440228801766632772", "price":"0.84", "size":"0", "side":"SELL", "hash":"83c229e44ec5b0cb50b9d2a7acc64e02889a33ee", "best_bid":"0", "best_ask":"1"}], "timestamp":"1784449596326", "event_type":"price_change"}
{"market":"0xab772601f501b265bfe8982eb61d5347ef9945de314bfdf4ac0189c288ffb0b3", "price_changes":[{"asset_id":"17924629579804316786455515989238352689210911545477836576430679697715946894553", "price":"0.14", "size":"0", "side":"BUY", "hash":"fc5288624f8f32bd1694129695ea302dad940bf3", "best_bid":"0", "best_ask":"1"}, {"asset_id":"12935926064588426924078449947177910958215776269411501731627440228801766632772", "price":"0.86", "size":"0", "side":"SELL", "hash":"83c229e44ec5b0cb50b9d2a7acc64e02889a33ee", "best_bid":"0", "best_ask":"1"}], "timestamp":"1784449596326", "event_type":"price_change"}
{"market":"0xab772601f501b265bfe8982eb61d5347ef9945de314bfdf4ac0189c288ffb0b3", "price_changes":[{"asset_id":"17924629579804316786455515989238352689210911545477836576430679697715946894553", "price":"0.12", "size":"0", "side":"BUY", "hash":"fc5288624f8f32bd1694129695ea302dad940bf3", "best_bid":"0", "best_ask":"1"}, {"asset_id":"12935926064588426924078449947177910958215776269411501731627440228801766632772", "price":"0.88", "size":"0", "side":"SELL", "hash":"83c229e44ec5b0cb50b9d2a7acc64e02889a33ee", "best_bid":"0", "best_ask":"1"}], "timestamp":"1784449596326", "event_type":"price_change"}
{"market":"0xab772601f501b265bfe8982eb61d5347ef9945de314bfdf4ac0189c288ffb0b3", "price_changes":[{"asset_id":"17924629579804316786455515989238352689210911545477836576430679697715946894553", "price":"0.11", "size":"0", "side":"BUY", "hash":"fc5288624f8f32bd1694129695ea302dad940bf3", "best_bid":"0", "best_ask":"1"}, {"asset_id":"12935926064588426924078449947177910958215776269411501731627440228801766632772", "price":"0.89", "size":"0", "side":"SELL", "hash":"83c229e44ec5b0cb50b9d2a7acc64e02889a33ee", "best_bid":"0", "best_ask":"1"}], "timestamp":"1784449596326", "event_type":"price_change"}
{"market":"0xab772601f501b265bfe8982eb61d5347ef9945de314bfdf4ac0189c288ffb0b3", "price_changes":[{"asset_id":"17924629579804316786455515989238352689210911545477836576430679697715946894553", "price":"0.1", "size":"0", "side":"BUY", "hash":"fc5288624f8f32bd1694129695ea302dad940bf3", "best_bid":"0", "best_ask":"1"}, {"asset_id":"12935926064588426924078449947177910958215776269411501731627440228801766632772", "price":"0.9", "size":"0", "side":"SELL", "hash":"83c229e44ec5b0cb50b9d2a7acc64e02889a33ee", "best_bid":"0", "best_ask":"1"}], "timestamp":"1784449596326", "event_type":"price_change"}
{"market":"0xab772601f501b265bfe8982eb61d5347ef9945de314bfdf4ac0189c288ffb0b3", "price_changes":[{"asset_id":"17924629579804316786455515989238352689210911545477836576430679697715946894553", "price":"0.09", "size":"0", "side":"BUY", "hash":"fc5288624f8f32bd1694129695ea302dad940bf3", "best_bid":"0", "best_ask":"1"}, {"asset_id":"12935926064588426924078449947177910958215776269411501731627440228801766632772", "price":"0.91", "size":"0", "side":"SELL", "hash":"83c229e44ec5b0cb50b9d2a7acc64e02889a33ee", "best_bid":"0", "best_ask":"1"}], "timestamp":"1784449596326", "event_type":"price_change"}
{"market":"0xab772601f501b265bfe8982eb61d5347ef9945de314bfdf4ac0189c288ffb0b3", "price_changes":[{"asset_id":"17924629579804316786455515989238352689210911545477836576430679697715946894553", "price":"0.08", "size":"0", "side":"BUY", "hash":"fc5288624f8f32bd1694129695ea302dad940bf3", "best_bid":"0", "best_ask":"1"}, {"asset_id":"12935926064588426924078449947177910958215776269411501731627440228801766632772", "price":"0.92", "size":"0", "side":"SELL", "hash":"83c229e44ec5b0cb50b9d2a7acc64e02889a33ee", "best_bid":"0", "best_ask":"1"}], "timestamp":"1784449596326", "event_type":"price_change"}
{"market":"0xab772601f501b265bfe8982eb61d5347ef9945de314bfdf4ac0189c288ffb0b3", "price_changes":[{"asset_id":"17924629579804316786455515989238352689210911545477836576430679697715946894553", "price":"0.07", "size":"0", "side":"BUY", "hash":"fc5288624f8f32bd1694129695ea302dad940bf3", "best_bid":"0", "best_ask":"1"}, {"asset_id":"12935926064588426924078449947177910958215776269411501731627440228801766632772", "price":"0.93", "size":"0", "side":"SELL", "hash":"83c229e44ec5b0cb50b9d2a7acc64e02889a33ee", "best_bid":"0", "best_ask":"1"}], "timestamp":"1784449596326", "event_type":"price_change"}
{"market":"0xab772601f501b265bfe8982eb61d5347ef9945de314bfdf4ac0189c288ffb0b3", "price_changes":[{"asset_id":"17924629579804316786455515989238352689210911545477836576430679697715946894553", "price":"0.06", "size":"0", "side":"BUY", "hash":"fc5288624f8f32bd1694129695ea302dad940bf3", "best_bid":"0", "best_ask":"1"}, {"asset_id":"12935926064588426924078449947177910958215776269411501731627440228801766632772", "price":"0.94", "size":"0", "side":"SELL", "hash":"83c229e44ec5b0cb50b9d2a7acc64e02889a33ee", "best_bid":"0", "best_ask":"1"}], "timestamp":"1784449596326", "event_type":"price_change"}
{"market":"0xab772601f501b265bfe8982eb61d5347ef9945de314bfdf4ac0189c288ffb0b3", "price_changes":[{"asset_id":"17924629579804316786455515989238352689210911545477836576430679697715946894553", "price":"0.05", "size":"0", "side":"BUY", "hash":"fc5288624f8f32bd1694129695ea302dad940bf3", "best_bid":"0", "best_ask":"1"}, {"asset_id":"12935926064588426924078449947177910958215776269411501731627440228801766632772", "price":"0.95", "size":"0", "side":"SELL", "hash":"83c229e44ec5b0cb50b9d2a7acc64e02889a33ee", "best_bid":"0", "best_ask":"1"}], "timestamp":"1784449596326", "event_type":"price_change"}
{"market":"0xab772601f501b265bfe8982eb61d5347ef9945de314bfdf4ac0189c288ffb0b3", "price_changes":[{"asset_id":"17924629579804316786455515989238352689210911545477836576430679697715946894553", "price":"0.04", "size":"0", "side":"BUY", "hash":"fc5288624f8f32bd1694129695ea302dad940bf3", "best_bid":"0", "best_ask":"1"}, {"asset_id":"12935926064588426924078449947177910958215776269411501731627440228801766632772", "price":"0.96", "size":"0", "side":"SELL", "hash":"83c229e44ec5b0cb50b9d2a7acc64e02889a33ee", "best_bid":"0", "best_ask":"1"}], "timestamp":"1784449596326", "event_type":"price_change"}
{"market":"0xab772601f501b265bfe8982eb61d5347ef9945de314bfdf4ac0189c288ffb0b3", "price_changes":[{"asset_id":"17924629579804316786455515989238352689210911545477836576430679697715946894553", "price":"0.03", "size":"0", "side":"BUY", "hash":"fc5288624f8f32bd1694129695ea302dad940bf3", "best_bid":"0", "best_ask":"1"}, {"asset_id":"12935926064588426924078449947177910958215776269411501731627440228801766632772", "price":"0.97", "size":"0", "side":"SELL", "hash":"83c229e44ec5b0cb50b9d2a7acc64e02889a33ee", "best_bid":"0", "best_ask":"1"}], "timestamp":"1784449596326", "event_type":"price_change"}
{"market":"0xab772601f501b265bfe8982eb61d5347ef9945de314bfdf4ac0189c288ffb0b3", "price_changes":[{"asset_id":"17924629579804316786455515989238352689210911545477836576430679697715946894553", "price":"0.02", "size":"0", "side":"BUY", "hash":"fc5288624f8f32bd1694129695ea302dad940bf3", "best_bid":"0", "best_ask":"1"}, {"asset_id":"12935926064588426924078449947177910958215776269411501731627440228801766632772", "price":"0.98", "size":"0", "side":"SELL", "hash":"83c229e44ec5b0cb50b9d2a7acc64e02889a33ee", "best_bid":"0", "best_ask":"1"}], "timestamp":"1784449596326", "event_type":"price_change"}
{"market":"0xab772601f501b265bfe8982eb61d5347ef9945de314bfdf4ac0189c288ffb0b3", "price_changes":[{"asset_id":"17924629579804316786455515989238352689210911545477836576430679697715946894553", "price":"0.01", "size":"0", "side":"BUY", "hash":"fc5288624f8f32bd1694129695ea302dad940bf3", "best_bid":"0", "best_ask":"1"}, {"asset_id":"12935926064588426924078449947177910958215776269411501731627440228801766632772", "price":"0.99", "size":"0", "side":"SELL", "hash":"83c229e44ec5b0cb50b9d2a7acc64e02889a33ee", "best_bid":"0", "best_ask":"1"}], "timestamp":"1784449596326", "event_type":"price_change"}
{"market":"0x982eae4503214e5d7992668e93f48f42e4707b92e23bb45f8d52d321f643cbe3", "price_changes":[{"asset_id":"74913635031537477155015393896000154190746945075332596665612975928350948042868", "price":"0.72", "size":"313.22", "side":"BUY", "hash":"ac97960eba2c40f3374ca989ae3e5f85ce8d2617", "best_bid":"0.81", "best_ask":"0.82"}, {"asset_id":"37613674580450069178400687025689415665506452565086963049482350052080099056186", "price":"0.28", "size":"313.22", "side":"SELL", "hash":"80f2d491c2de8987b2ea077ff1379dada25b58c7", "best_bid":"0.18", "best_ask":"0.19"}], "timestamp":"1784449596340", "event_type":"price_change"}
{"market":"0x982eae4503214e5d7992668e93f48f42e4707b92e23bb45f8d52d321f643cbe3", "price_changes":[{"asset_id":"74913635031537477155015393896000154190746945075332596665612975928350948042868", "price":"0.69", "size":"85.7", "side":"BUY", "hash":"a10979364725986b611eeea95e10f75c8476e2f0", "best_bid":"0.81", "best_ask":"0.82"}, {"asset_id":"37613674580450069178400687025689415665506452565086963049482350052080099056186", "price":"0.31", "size":"85.7", "side":"SELL", "hash":"d88ea1d6c12097de20748ea5cd9fd1e2c8428f14", "best_bid":"0.18", "best_ask":"0.19"}], "timestamp":"1784449596340", "event_type":"price_change"}
{"market":"0x982eae4503214e5d7992668e93f48f42e4707b92e23bb45f8d52d321f643cbe3", "price_changes":[{"asset_id":"37613674580450069178400687025689415665506452565086963049482350052080099056186", "price":"0.18", "size":"7.03", "side":"BUY", "hash":"1716570ecebba959cdeef59f7992116cc6891f01", "best_bid":"0.18", "best_ask":"0.19"}, {"asset_id":"74913635031537477155015393896000154190746945075332596665612975928350948042868", "price":"0.82", "size":"7.03", "side":"SELL", "hash":"7abd6ff2eaa80bf01f7cad1538159a7df2685592", "best_bid":"0.81", "best_ask":"0.82"}], "timestamp":"1784449596344", "event_type":"price_change"}
