{"market":"0xab772601f501b265bfe8982eb61d5347ef9945de314bfdf4ac0189c288ffb0b3", "asset_id":"12935926064588426924078449947177910958215776269411501731627440228801766632772", "bids":[{"price":"0.01", "size":"14899.14"}, {"price":"0.02", "size":"3964.52"}, {"price":"0.03", "size":"2179.29"}, {"price":"0.04", "size":"1215.1"}, {"price":"0.05", "size":"1752.19"}, {"price":"0.06", "size":"1122.02"}, {"price":"0.07", "size":"953.49"}, {"price":"0.08", "size":"1234.38"}, {"price":"0.09", "size":"791.7"}, {"price":"0.1", "size":"561.2"}, {"price":"0.11", "size":"1502.1"}, {"price":"0.12", "size":"1112.05"}, {"price":"0.13", "size":"147.4"}, {"price":"0.14", "size":"166.8"}, {"price":"0.15", "size":"444.04"}, {"price":"0.16", "size":"247.1"}, {"price":"0.17", "size":"207.17"}, {"price":"0.18", "size":"150.7"}, {"price":"0.19", "size":"103.89"}, {"price":"0.2", "size":"246.2"}, {"price":"0.21", "size":"636.8"}, {"price":"0.22", "size":"115.5"}, {"price":"0.23", "size":"165.8"}, {"price":"0.24", "size":"152.22"}, {"price":"0.25", "size":"127.2"}, {"price":"0.26", "size":"134.3"}, {"price":"0.27", "size":"148.5"}, {"price":"0.28", "size":"146.77"}, {"price":"0.29", "size":"216.99"}, {"price":"0.3", "size":"202.81"}, {"price":"0.31", "size":"554.58"}, {"price":"0.32", "size":"241.69"}, {"price":"0.33", "size":"144.65"}, {"price":"0.34", "size":"125.76"}, {"price":"0.35", "size":"122.8"}, {"price":"0.36", "size":"185.77"}, {"price":"0.37", "size":"170.91"}, {"price":"0.38", "size":"361.23"}, {"price":"0.39", "size":"165.88"}, {"price":"0.4", "size":"115.61"}], "asks":[{"price":"0.99", "size":"13059.5"}, {"price":"0.98", "size":"3885.25"}, {"price":"0.97", "size":"2250.95"}, {"price":"0.96", "size":"1270.1"}, {"price":"0.95", "size":"1753.6"}, {"price":"0.94", "size":"1109.35"}, {"price":"0.93", "size":"944.2"}, {"price":"0.92", "size":"1225.88"}, {"price":"0.91", "size":"796.7"}, {"price":"0.9", "size":"365.2"}, {"price":"0.89", "size":"1502.1"}, {"price":"0.88", "size":"195.05"}, {"price":"0.87", "size":"147.4"}, {"price":"0.86", "size":"183.4"}, {"price":"0.85", "size":"469.43"}, {"price":"0.84", "size":"127.1"}, {"price":"0.83", "size":"107.69"}, {"price":"0.82", "size":"125.7"}, {"price":"0.81", "size":"98.89"}, {"price":"0.8", "size":"206.2"}, {"price":"0.79", "size":"616.8"}, {"price":"0.78", "size":"992.5"}, {"price":"0.77", "size":"82.3"}, {"price":"0.76", "size":"118.03"}, {"price":"0.75", "size":"92.2"}, {"price":"0.74", "size":"90.3"}, {"price":"0.73", "size":"83.5"}, {"price":"0.72", "size":"92.77"}, {"price":"0.71", "size":"74.39"}, {"price":"0.7", "size":"83"}, {"price":"0.69", "size":"89.7"}, {"price":"0.68", "size":"160.64"}, {"price":"0.67", "size":"108.1"}, {"price":"0.66", "size":"92.8"}, {"price":"0.65", "size":"184.6"}, {"price":"0.64", "size":"104.39"}, {"price":"0.63", "size":"94.2"}, {"price":"0.62", "size":"55"}, {"price":"0.61", "size":"69.8"}, {"price":"0.6", "size":"122.94"}, {"price":"0.59", "size":"100.5"}, {"price":"0.58", "size":"86.02"}, {"price":"0.57", "size":"75.3"}, {"price":"0.56", "size":"64.2"}, {"price":"0.55", "size":"204.71"}, {"price":"0.54", "size":"102.1"}, {"price":"0.53", "size":"72.1"}, {"price":"0.52", "size":"71"}, {"price":"0.51", "size":"81"}, {"price":"0.5", "size":"129.39"}, {"price":"0.49", "size":"425.92"}, {"price":"0.48", "size":"235.91"}, {"price":"0.47", "size":"560.7"}, {"price":"0.46", "size":"135.85"}, {"price":"0.45", "size":"221.69"}, {"price":"0.44", "size":"252.99"}, {"price":"0.43", "size":"130"}, {"price":"0.42", "size":"141.82"}, {"price":"0.41", "size":"125.28"}], "hash":"6e16efa8e46051b67463a46eb6295bf1ec8bb101", "timestamp":"1784449238976", "event_type":"book"}
{"market":"0xab772601f501b265bfe8982eb61d5347ef9945de314bfdf4ac0189c288ffb0b3", "asset_id":"17924629579804316786455515989238352689210911545477836576430679697715946894553", "bids":[{"price":"0.01", "size":"13059.5"}, {"price":"0.02", "size":"3885.25"}, {"price":"0.03", "size":"2250.95"}, {"price":"0.04", "size":"1270.1"}, {"price":"0.05", "size":"1753.6"}, {"price":"0.06", "size":"1109.35"}, {"price":"0.07", "size":"944.2"}, {"price":"0.08", "size":"1225.88"}, {"price":"0.09", "size":"796.7"}, {"price":"0.1", "size":"365.2"}, {"price":"0.11", "size":"1502.1"}, {"price":"0.12", "size":"195.05"}, {"price":"0.13", "size":"147.4"}, {"price":"0.14", "size":"183.4"}, {"price":"0.15", "size":"469.43"}, {"price":"0.16", "size":"127.1"}, {"price":"0.17", "size":"107.69"}, {"price":"0.18", "size":"125.7"}, {"price":"0.19", "size":"98.89"}, {"price":"0.2", "size":"206.2"}, {"price":"0.21", "size":"616.8"}, {"price":"0.22", "size":"992.5"}, {"price":"0.23", "size":"82.3"}, {"price":"0.24", "size":"118.03"}, {"price":"0.25", "size":"92.2"}, {"price":"0.26", "size":"90.3"}, {"price":"0.27", "size":"83.5"}, {"price":"0.28", "size":"92.77"}, {"price":"0.29", "size":"74.39"}, {"price":"0.3", "size":"83"}, {"price":"0.31", "size":"89.7"}, {"price":"0.32", "size":"160.64"}, {"price":"0.33", "size":"108.1"}, {"price":"0.34", "size":"92.8"}, {"price":"0.35", "size":"184.6"}, {"price":"0.36", "size":"104.39"}, {"price":"0.37", "size":"94.2"}, {"price":"0.38", "size":"55"}, {"price":"0.39", "size":"69.8"}, {"price":"0.4", "size":"122.94"}, {"price":"0.41", "size":"100.5"}, {"price":"0.42", "size":"86.02"}, {"price":"0.43", "size":"75.3"}, {"price":"0.44", "size":"64.2"}, {"price":"0.45", "size":"204.71"}, {"price":"0.46", "size":"102.1"}, {"price":"0.47", "size":"72.1"}, {"price":"0.48", "size":"71"}, {"price":"0.49", "size":"81"}, {"price":"0.5", "size":"129.39"}, {"price":"0.51", "size":"425.92"}, {"price":"0.52", "size":"235.91"}, {"price":"0.53", "size":"560.7"}, {"price":"0.54", "size":"135.85"}, {"price":"0.55", "size":"221.69"}, {"price":"0.56", "size":"252.99"}, {"price":"0.57", "size":"130"}, {"price":"0.58", "size":"141.82"}, {"price":"0.59", "size":"125.28"}], "asks":[{"price":"0.99", "size":"14899.14"}, {"price":"0.98", "size":"3964.52"}, {"price":"0.97", "size":"2179.29"}, {"price":"0.96", "size":"1215.1"}, {"price":"0.95", "size":"1752.19"}, {"price":"0.94", "size":"1122.02"}, {"price":"0.93", "size":"953.49"}, {"price":"0.92", "size":"1234.38"}, {"price":"0.91", "size":"791.7"}, {"price":"0.9", "size":"561.2"}, {"price":"0.89", "size":"1502.1"}, {"price":"0.88", "size":"1112.05"}, {"price":"0.87", "size":"147.4"}, {"price":"0.86", "size":"166.8"}, {"price":"0.85", "size":"444.04"}, {"price":"0.84", "size":"247.1"}, {"price":"0.83", "size":"207.17"}, {"price":"0.82", "size":"150.7"}, {"price":"0.81", "size":"103.89"}, {"price":"0.8", "size":"246.2"}, {"price":"0.79", "size":"636.8"}, {"price":"0.78", "size":"115.5"}, {"price":"0.77", "size":"165.8"}, {"price":"0.76", "size":"152.22"}, {"price":"0.75", "size":"127.2"}, {"price":"0.74", "size":"134.3"}, {"price":"0.73", "size":"148.5"}, {"price":"0.72", "size":"146.77"}, {"price":"0.71", "size":"216.99"}, {"price":"0.7", "size":"202.81"}, {"price":"0.69", "size":"554.58"}, {"price":"0.68", "size":"241.69"}, {"price":"0.67", "size":"144.65"}, {"price":"0.66", "size":"125.76"}, {"price":"0.65", "size":"122.8"}, {"price":"0.64", "size":"185.77"}, {"price":"0.63", "size":"170.91"}, {"price":"0.62", "size":"361.23"}, {"price":"0.61", "size":"165.88"}, {"price":"0.6", "size":"115.61"}], "hash":"f60f6b322c85c0202f206c7237ab216cc530cfcc", "timestamp":"1784449238976", "event_type":"book"}
{"market":"0xab772601f501b265bfe8982eb61d5347ef9945de314bfdf4ac0189c288ffb0b3", "price_changes":[{"asset_id":"17924629579804316786455515989238352689210911545477836576430679697715946894553", "price":"0.01", "size":"12959.5", "side":"BUY", "hash":"051edac9246a9c171eb8d922480f59c8e9087b52", "best_bid":"0.59", "best_ask":"0.6"}, {"asset_id":"12935926064588426924078449947177910958215776269411501731627440228801766632772", "price":"0.99", "size":"12959.5", "side":"SELL", "hash":"f608c8cfbb600917e02a0924658d5fe84f4f2e8c", "best_bid":"0.4", "best_ask":"0.41"}], "timestamp":"1784449238979", "event_type":"price_change"}
{"market":"0xab772601f501b265bfe8982eb61d5347ef9945de314bfdf4ac0189c288ffb0b3", "price_changes":[{"asset_id":"12935926064588426924078449947177910958215776269411501731627440228801766632772", "price":"0.01", "size":"14894.14", "side":"BUY", "hash":"a189798827945f249d580a760fbbb6a7f4eed634", "best_bid":"0.4", "best_ask":"0.41"}, {"asset_id":"17924629579804316786455515989238352689210911545477836576430679697715946894553", "price":"0.99", "size":"14894.14", "side":"SELL", "hash":"4714df8dc18563b5bfd0f3b64ee31330079c7a8a", "best_bid":"0.59", "best_ask":"0.6"}], "timestamp":"1784449238996", "event_type":"price_change"}
{"market":"0xab772601f501b265bfe8982eb61d5347ef9945de314bfdf4ac0189c288ffb0b3", "price_changes":[{"asset_id":"17924629579804316786455515989238352689210911545477836576430679697715946894553", "price":"0.01", "size":"12964.5", "side":"BUY", "hash":"86cd287767f92d1eb3e936865223028ce30a17ba", "best_bid":"0.59", "best_ask":"0.6"}, {"asset_id":"12935926064588426924078449947177910958215776269411501731627440228801766632772", "price":"0.99", "size":"12964.5", "side":"SELL", "hash":"dd4d1ce9208f725d963595c1ce198799ac234eb7", "best_bid":"0.4", "best_ask":"0.41"}], "timestamp":"1784449239004", "event_type":"price_change"}
{"market":"0xab772601f501b265bfe8982eb61d5347ef9945de314bfdf4ac0189c288ffb0b3", "price_changes":[{"asset_id":"17924629579804316786455515989238352689210911545477836576430679697715946894553", "price":"0.01", "size":"12970.5", "side":"BUY", "hash":"fdda78882e95f36d1f7472a2a780874fa8d2e0cf", "best_bid":"0.59", "best_ask":"0.6"}, {"asset_id":"12935926064588426924078449947177910958215776269411501731627440228801766632772", "price":"0.99", "size":"12970.5", "side":"SELL", "hash":"db2bd7122006c38a3426b5f574eba6ad744fdcf3", "best_bid":"0.4", "best_ask":"0.41"}], "timestamp":"1784449239006", "event_type":"price_change"}
{"market":"0xab772601f501b265bfe8982eb61d5347ef9945de314bfdf4ac0189c288ffb0b3", "price_changes":[{"asset_id":"12935926064588426924078449947177910958215776269411501731627440228801766632772", "price":"0.01", "size":"14899.14", "side":"BUY", "hash":"13003d9c26393436e0982362669141a7ffdd3c08", "best_bid":"0.4", "best_ask":"0.41"}, {"asset_id":"17924629579804316786455515989238352689210911545477836576430679697715946894553", "price":"0.99", "size":"14899.14", "side":"SELL", "hash":"f3a3d94fc0545bd112fac8ad6b1c4d2272c152d5", "best_bid":"0.59", "best_ask":"0.6"}], "timestamp":"1784449239016", "event_type":"price_change"}
{"market":"0xab772601f501b265bfe8982eb61d5347ef9945de314bfdf4ac0189c288ffb0b3", "price_changes":[{"asset_id":"12935926064588426924078449947177910958215776269411501731627440228801766632772", "price":"0.4", "size":"121.06", "side":"BUY", "hash":"3b64b9532236c494326c45e4cca1838c0a38f891", "best_bid":"0.4", "best_ask":"0.41"}, {"asset_id":"17924629579804316786455515989238352689210911545477836576430679697715946894553", "price":"0.6", "size":"121.06", "side":"SELL", "hash":"641f0e7755c13adcac5627591054399462f605d3", "best_bid":"0.59", "best_ask":"0.6"}], "timestamp":"1784449239017", "event_type":"price_change"}
{"market":"0xab772601f501b265bfe8982eb61d5347ef9945de314bfdf4ac0189c288ffb0b3", "price_changes":[{"asset_id":"12935926064588426924078449947177910958215776269411501731627440228801766632772", "price":"0.01", "size":"14894.14", "side":"BUY", "hash":"37bb187b3f72d0624ed46ad652351423506e53a8", "best_bid":"0.4", "best_ask":"0.41"}, {"asset_id":"17924629579804316786455515989238352689210911545477836576430679697715946894553", "price":"0.99", "size":"14894.14", "side":"SELL", "hash":"8f02ad578df1cdb664c0ec07cf0aa33a93a5a60b", "best_bid":"0.59", "best_ask":"0.6"}], "timestamp":"1784449239020", "event_type":"price_change"}
{"market":"0xab772601f501b265bfe8982eb61d5347ef9945de314bfdf4ac0189c288ffb0b3", "price_changes":[{"asset_id":"12935926064588426924078449947177910958215776269411501731627440228801766632772", "price":"0.01", "size":"14899.14", "side":"BUY", "hash":"87b9dcbaddb3cea02bcd4aa78aecbd2a87c1ad4a", "best_bid":"0.4", "best_ask":"0.41"}, {"asset_id":"17924629579804316786455515989238352689210911545477836576430679697715946894553", "price":"0.99", "size":"14899.14", "side":"SELL", "hash":"ea8ac29293800fbf1a26b4b716866d557b6688eb", "best_bid":"0.59", "best_ask":"0.6"}], "timestamp":"1784449239021", "event_type":"price_change"}
{"market":"0xab772601f501b265bfe8982eb61d5347ef9945de314bfdf4ac0189c288ffb0b3", "price_changes":[{"asset_id":"17924629579804316786455515989238352689210911545477836576430679697715946894553", "price":"0.01", "size":"13070.5", "side":"BUY", "hash":"bec5942fc291583718c93d99a38a1082068702d6", "best_bid":"0.59", "best_ask":"0.6"}, {"asset_id":"12935926064588426924078449947177910958215776269411501731627440228801766632772", "price":"0.99", "size":"13070.5", "side":"SELL", "hash":"551a124284815b51e00b3ed9d5548ac6862bb5f4", "best_bid":"0.4", "best_ask":"0.41"}], "timestamp":"1784449239023", "event_type":"price_change"}
{"market":"0xab772601f501b265bfe8982eb61d5347ef9945de314bfdf4ac0189c288ffb0b3", "price_changes":[{"asset_id":"12935926064588426924078449947177910958215776269411501731627440228801766632772", "price":"0.01", "size":"14894.14", "side":"BUY", "hash":"cf11e88a03fe87e5c107636c937d87b87a525649", "best_bid":"0.4", "best_ask":"0.41"}, {"asset_id":"17924629579804316786455515989238352689210911545477836576430679697715946894553", "price":"0.99", "size":"14894.14", "side":"SELL", "hash":"eeb0e2dae3b3a594c7a99f120c54936ac73265b3", "best_bid":"0.59", "best_ask":"0.6"}], "timestamp":"1784449239023", "event_type":"price_change"}
{"market":"0xab772601f501b265bfe8982eb61d5347ef9945de314bfdf4ac0189c288ffb0b3", "price_changes":[{"asset_id":"12935926064588426924078449947177910958215776269411501731627440228801766632772", "price":"0.01", "size":"14889.14", "side":"BUY", "hash":"e09f5f15d8e61c6162dab2b0849995af58623556", "best_bid":"0.4", "best_ask":"0.41"}, {"asset_id":"17924629579804316786455515989238352689210911545477836576430679697715946894553", "price":"0.99", "size":"14889.14", "side":"SELL", "hash":"6aef42bc396e59e2b5aed7b18c201aed655d187a", "best_bid":"0.59", "best_ask":"0.6"}], "timestamp":"1784449239024", "event_type":"price_change"}
{"market":"0xab772601f501b265bfe8982eb61d5347ef9945de314bfdf4ac0189c288ffb0b3", "price_changes":[{"asset_id":"12935926064588426924078449947177910958215776269411501731627440228801766632772", "price":"0.01", "size":"14894.14", "side":"BUY", "hash":"92f129afe6939164d52f5f15f10d69116f01ad5c", "best_bid":"0.4", "best_ask":"0.41"}, {"asset_id":"17924629579804316786455515989238352689210911545477836576430679697715946894553", "price":"0.99", "size":"14894.14", "side":"SELL", "hash":"f1473d8ffc9b77085df725c3392ca179103ac1b2", "best_bid":"0.59", "best_ask":"0.6"}], "timestamp":"1784449239027", "event_type":"price_change"}
{"market":"0xab772601f501b265bfe8982eb61d5347ef9945de314bfdf4ac0189c288ffb0b3", "price_changes":[{"asset_id":"12935926064588426924078449947177910958215776269411501731627440228801766632772", "price":"0.39", "size":"140.88", "side":"BUY", "hash":"e5602d9480d516716c9cf5cc91d5bddf7b7a74a0", "best_bid":"0.4", "best_ask":"0.41"}, {"asset_id":"17924629579804316786455515989238352689210911545477836576430679697715946894553", "price":"0.61", "size":"140.88", "side":"SELL", "hash":"c627ef13c0551b56106b83edb572c1a92660a28f", "best_bid":"0.59", "best_ask":"0.6"}], "timestamp":"1784449239028", "event_type":"price_change"}
{"market":"0xab772601f501b265bfe8982eb61d5347ef9945de314bfdf4ac0189c288ffb0b3", "price_changes":[{"asset_id":"12935926064588426924078449947177910958215776269411501731627440228801766632772", "price":"0.01", "size":"14899.14", "side":"BUY", "hash":"3f7d43bad3e5daa7aecddb4cd65cce11b03a272e", "best_bid":"0.4", "best_ask":"0.41"}, {"asset_id":"17924629579804316786455515989238352689210911545477836576430679697715946894553", "price":"0.99", "size":"14899.14", "side":"SELL", "hash":"a73d6505d68684f964842419b39b8bda1f6b0657", "best_bid":"0.59", "best_ask":"0.6"}], "timestamp":"1784449239029", "event_type":"price_change"}
{"market":"0xab772601f501b265bfe8982eb61d5347ef9945de314bfdf4ac0189c288ffb0b3", "price_changes":[{"asset_id":"12935926064588426924078449947177910958215776269411501731627440228801766632772", "price":"0.4", "size":"146.06", "side":"BUY", "hash":"2f3d12297cee54c9a5e88b5b77a9860f4d3e0718", "best_bid":"0.4", "best_ask":"0.41"}, {"asset_id":"17924629579804316786455515989238352689210911545477836576430679697715946894553", "price":"0.6", "size":"146.06", "side":"SELL", "hash":"a6ec1feeb1bd9dd6e270fb9d081f80db296dc79f", "best_bid":"0.59", "best_ask":"0.6"}], "timestamp":"1784449239031", "event_type":"price_change"}
{"market":"0xab772601f501b265bfe8982eb61d5347ef9945de314bfdf4ac0189c288ffb0b3", "price_changes":[{"asset_id":"12935926064588426924078449947177910958215776269411501731627440228801766632772", "price":"0.25", "size":"137.2", "side":"BUY", "hash":"1f41a7ae01b34d838bdf6f299b96216d39e41903", "best_bid":"0.4", "best_ask":"0.41"}, {"asset_id":"17924629579804316786455515989238352689210911545477836576430679697715946894553", "price":"0.75", "size":"137.2", "side":"SELL", "hash":"c7da01964bdba7fbffce81aa92b319ae56906468", "best_bid":"0.59", "best_ask":"0.6"}], "timestamp":"1784449239032", "event_type":"price_change"}
{"market":"0xab772601f501b265bfe8982eb61d5347ef9945de314bfdf4ac0189c288ffb0b3", "price_changes":[{"asset_id":"17924629579804316786455515989238352689210911545477836576430679697715946894553", "price":"0.01", "size":"13065.5", "side":"BUY", "hash":"bd6af6ad8d10c4be7ed38b07175e9aeafe3437c7", "best_bid":"0.59", "best_ask":"0.6"}, {"asset_id":"12935926064588426924078449947177910958215776269411501731627440228801766632772", "price":"0.99", "size":"13065.5", "side":"SELL", "hash":"f4dcfc7ad426c6cd4323fe831d42c6087e79aee5", "best_bid":"0.4", "best_ask":"0.41"}], "timestamp":"1784449239032", "event_type":"price_change"}
{"market":"0xab772601f501b265bfe8982eb61d5347ef9945de314bfdf4ac0189c288ffb0b3", "price_changes":[{"asset_id":"12935926064588426924078449947177910958215776269411501731627440228801766632772", "price":"0.19", "size":"113.89", "side":"BUY", "hash":"d3db726c186b7264234a19c6f02210336bb6a365", "best_bid":"0.4", "best_ask":"0.41"}, {"asset_id":"17924629579804316786455515989238352689210911545477836576430679697715946894553", "price":"0.81", "size":"113.89", "side":"SELL", "hash":"604dbfe6963faed8f75fedfdae856ecd4ece20ec", "best_bid":"0.59", "best_ask":"0.6"}], "timestamp":"1784449239033", "event_type":"price_change"}
{"market":"0xab772601f501b265bfe8982eb61d5347ef9945de314bfdf4ac0189c288ffb0b3", "price_changes":[{"asset_id":"12935926064588426924078449947177910958215776269411501731627440228801766632772", "price":"0.01", "size":"14904.14", "side":"BUY", "hash":"f5420220f733bf01b9612f07ea79934810cb3c50", "best_bid":"0.4", "best_ask":"0.41"}, {"asset_id":"17924629579804316786455515989238352689210911545477836576430679697715946894553", "price":"0.99", "size":"14904.14", "side":"SELL", "hash":"703f8be2ee43465717324eb156eb453a3d286cdd", "best_bid":"0.59", "best_ask":"0.6"}], "timestamp":"1784449239033", "event_type":"price_change"}
{"market":"0xab772601f501b265bfe8982eb61d5347ef9945de314bfdf4ac0189c288ffb0b3", "price_changes":[{"asset_id":"12935926064588426924078449947177910958215776269411501731627440228801766632772", "price":"0.18", "size":"160.7", "side":"BUY", "hash":"b5800e1aba01787188ee47acc710f98fe1ab7162", "best_bid":"0.4", "best_ask":"0.41"}, {"asset_id":"17924629579804316786455515989238352689210911545477836576430679697715946894553", "price":"0.82", "size":"160.7", "side":"SELL", "hash":"40c36782a2480a0fc9ac51b84ffaf3b539c6dc26", "best_bid":"0.59", "best_ask":"0.6"}], "timestamp":"1784449239034", "event_type":"price_change"}
{"market":"0xab772601f501b265bfe8982eb61d5347ef9945de314bfdf4ac0189c288ffb0b3", "price_changes":[{"asset_id":"12935926064588426924078449947177910958215776269411501731627440228801766632772", "price":"0.2", "size":"256.2", "side":"BUY", "hash":"2740dc1ba33fad48265084025fc1d589ebe0e629", "best_bid":"0.4", "best_ask":"0.41"}, {"asset_id":"17924629579804316786455515989238352689210911545477836576430679697715946894553", "price":"0.8", "size":"256.2", "side":"SELL", "hash":"13aeaaf9a3a362cd26ff71c08961c44f84b07086", "best_bid":"0.59", "best_ask":"0.6"}], "timestamp":"1784449239034", "event_type":"price_change"}
{"market":"0xab772601f501b265bfe8982eb61d5347ef9945de314bfdf4ac0189c288ffb0b3", "asset_id":"12935926064588426924078449947177910958215776269411501731627440228801766632772", "price":"0.41", "size":"7.317072", "fee_rate_bps":"0", "side":"BUY", "timestamp":"1784449239032", "event_type":"last_trade_price", "transaction_hash":"0x2ea952922e2fa73887e884304986caf10934634e75a243fe877e144032a92d84"}
{"market":"0xab772601f501b265bfe8982eb61d5347ef9945de314bfdf4ac0189c288ffb0b3", "price_changes":[{"asset_id":"12935926064588426924078449947177910958215776269411501731627440228801766632772", "price":"0.16", "size":"257.1", "side":"BUY", "hash":"c5454d56e02088d6f2b4b6cc5c838438961189e1", "best_bid":"0.4", "best_ask":"0.41"}, {"asset_id":"17924629579804316786455515989238352689210911545477836576430679697715946894553", "price":"0.84", "size":"257.1", "side":"SELL", "hash":"92e7639614afdea3905fc792da47025ec5aa40c7", "best_bid":"0.59", "best_ask":"0.6"}], "timestamp":"1784449239035", "event_type":"price_change"}
{"market":"0xab772601f501b265bfe8982eb61d5347ef9945de314bfdf4ac0189c288ffb0b3", "price_changes":[{"asset_id":"12935926064588426924078449947177910958215776269411501731627440228801766632772", "price":"0.15", "size":"454.04", "side":"BUY", "hash":"469ea1b55b5331bd88b410d85dd3a35c955e0e9d", "best_bid":"0.4", "best_ask":"0.41"}, {"asset_id":"17924629579804316786455515989238352689210911545477836576430679697715946894553", "price":"0.85", "size":"454.04", "side":"SELL", "hash":"daf142ea00d352d5eca86b0c5974ceb6e06c2649", "best_bid":"0.59", "best_ask":"0.6"}], "timestamp":"1784449239035", "event_type":"price_change"}
{"market":"0xab772601f501b265bfe8982eb61d5347ef9945de314bfdf4ac0189c288ffb0b3", "price_changes":[{"asset_id":"12935926064588426924078449947177910958215776269411501731627440228801766632772", "price":"0.17", "size":"217.17", "side":"BUY", "hash":"6701f63f005e7bee8649dcd8de6822db054885bc", "best_bid":"0.4", "best_ask":"0.41"}, {"asset_id":"17924629579804316786455515989238352689210911545477836576430679697715946894553", "price":"0.83", "size":"217.17", "side":"SELL", "hash":"b09d3bd4bbf324f41ebe9e65244b3fe7515cbe55", "best_bid":"0.59", "best_ask":"0.6"}], "timestamp":"1784449239036", "event_type":"price_change"}
{"market":"0xab772601f501b265bfe8982eb61d5347ef9945de314bfdf4ac0189c288ffb0b3", "price_changes":[{"asset_id":"17924629579804316786455515989238352689210911545477836576430679697715946894553", "price":"0.01", "size":"13059.5", "side":"BUY", "hash":"e175a5e8c3ee31e92b9e68dc0a1dad93759fbdbb", "best_bid":"0.59", "best_ask":"0.6"}, {"asset_id":"12935926064588426924078449947177910958215776269411501731627440228801766632772", "price":"0.99", "size":"13059.5", "side":"SELL", "hash":"abab417782caa8971112c90326cec3ed516a9959", "best_bid":"0.4", "best_ask":"0.41"}], "timestamp":"1784449239036", "event_type":"price_change"}
{"market":"0xab772601f501b265bfe8982eb61d5347ef9945de314bfdf4ac0189c288ffb0b3", "price_changes":[{"asset_id":"12935926064588426924078449947177910958215776269411501731627440228801766632772", "price":"0.26", "size":"144.3", "side":"BUY", "hash":"34e5864dc86b3ad67118d4c76c37aa513159104c", "best_bid":"0.4", "best_ask":"0.41"}, {"asset_id":"17924629579804316786455515989238352689210911545477836576430679697715946894553", "price":"0.74", "size":"144.3", "side":"SELL", "hash":"f2e31060916cb0c67fa1bdce2429773d94190474", "best_bid":"0.59", "best_ask":"0.6"}], "timestamp":"1784449239037", "event_type":"price_change"}
{"market":"0xab772601f501b265bfe8982eb61d5347ef9945de314bfdf4ac0189c288ffb0b3", "price_changes":[{"asset_id":"12935926064588426924078449947177910958215776269411501731627440228801766632772", "price":"0.4", "size":"121.06", "side":"BUY", "hash":"7e832de202183521e41d815d5e1a57c41b71d1f5", "best_bid":"0.4", "best_ask":"0.41"}, {"asset_id":"17924629579804316786455515989238352689210911545477836576430679697715946894553", "price":"0.6", "size":"121.06", "side":"SELL", "hash":"10e5dc6c445fb3b2c2e7d5857eede2646c6eb6d8", "best_bid":"0.59", "best_ask":"0.6"}], "timestamp":"1784449239040", "event_type":"price_change"}
{"market":"0xab772601f501b265bfe8982eb61d5347ef9945de314bfdf4ac0189c288ffb0b3", "price_changes":[{"asset_id":"12935926064588426924078449947177910958215776269411501731627440228801766632772", "price":"0.01", "size":"14899.14", "side":"BUY", "hash":"a085fd9492f5df5fc7ce851b23462a8e59368a8e", "best_bid":"0.4", "best_ask":"0.41"}, {"asset_id":"17924629579804316786455515989238352689210911545477836576430679697715946894553", "price":"0.99", "size":"14899.14", "side":"SELL", "hash":"e6420acb979609f6c43f781cec92c9027e88a465", "best_bid":"0.59", "best_ask":"0.6"}], "timestamp":"1784449239041", "event_type":"price_change"}
{"market":"0xab772601f501b265bfe8982eb61d5347ef9945de314bfdf4ac0189c288ffb0b3", "price_changes":[{"asset_id":"17924629579804316786455515989238352689210911545477836576430679697715946894553", "price":"0.49", "size":"99.14", "side":"BUY", "hash":"306cdaf21e4d6ed3ffcf9d8337137f95dad3267e", "best_bid":"0.59", "best_ask":"0.6"}, {"asset_id":"12935926064588426924078449947177910958215776269411501731627440228801766632772", "price":"0.51", "size":"99.14", "side":"SELL", "hash":"1ab22662f2e012544d32000c2f2ec63d736cc1d6", "best_bid":"0.4", "best_ask":"0.41"}], "timestamp":"1784449239043", "event_type":"price_change"}
{"market":"0xab772601f501b265bfe8982eb61d5347ef9945de314bfdf4ac0189c288ffb0b3", "price_changes":[{"asset_id":"17924629579804316786455515989238352689210911545477836576430679697715946894553", "price":"0.49", "size":"81", "side":"BUY", "hash":"32132fd9b4592f425cd7245764e139d4711dd5ee", "best_bid":"0.59", "best_ask":"0.6"}, {"asset_id":"12935926064588426924078449947177910958215776269411501731627440228801766632772", "price":"0.51", "size":"81", "side":"SELL", "hash":"afe8ac82e6115be0029c5b45e38e3be7716618f7", "best_bid":"0.4", "best_ask":"0.41"}], "timestamp":"1784449239046", "event_type":"price_change"}
{"market":"0xab772601f501b265bfe8982eb61d5347ef9945de314bfdf4ac0189c288ffb0b3", "price_changes":[{"asset_id":"12935926064588426924078449947177910958215776269411501731627440228801766632772", "price":"0.23", "size":"145.8", "side":"BUY", "hash":"84ec3aa40b60dc3c1bfbe5169422aac823f8b626", "best_bid":"0.4", "best_ask":"0.41"}, {"asset_id":"17924629579804316786455515989238352689210911545477836576430679697715946894553", "price":"0.77", "size":"145.8", "side":"SELL", "hash":"42c08f9c565283761abead702c54ca20164a7cb5", "best_bid":"0.59", "best_ask":"0.6"}], "timestamp":"1784449239048", "event_type":"price_change"}
{"market":"0xab772601f501b265bfe8982eb61d5347ef9945de314bfdf4ac0189c288ffb0b3", "price_changes":[{"asset_id":"17924629579804316786455515989238352689210911545477836576430679697715946894553", "price":"0.31", "size":"94.7", "side":"BUY", "hash":"f551d6ae6d7b5e908a0e8a76a4ae7ad9d8f15407", "best_bid":"0.59", "best_ask":"0.6"}, {"asset_id":"12935926064588426924078449947177910958215776269411501731627440228801766632772", "price":"0.69", "size":"94.7", "side":"SELL", "hash":"b47f81b38899e9736c712c5bbd689ae7b572a059", "best_bid":"0.4", "best_ask":"0.41"}], "timestamp":"1784449239052", "event_type":"price_change"}
{"market":"0xab772601f501b265bfe8982eb61d5347ef9945de314bfdf4ac0189c288ffb0b3", "price_changes":[{"asset_id":"12935926064588426924078449947177910958215776269411501731627440228801766632772", "price":"0.39", "size":"165.88", "side":"BUY", "hash":"190efe25d43b923797d6456a857019bc38ca0e72", "best_bid":"0.4", "best_ask":"0.41"}, {"asset_id":"17924629579804316786455515989238352689210911545477836576430679697715946894553", "price":"0.61", "size":"165.88", "side":"SELL", "hash":"8e4d9cb8e2dfe57ebeaa5f843a69c1dee0654046", "best_bid":"0.59", "best_ask":"0.6"}], "timestamp":"1784449239054", "event_type":"price_change"}
{"market":"0xab772601f501b265bfe8982eb61d5347ef9945de314bfdf4ac0189c288ffb0b3", "price_changes":[{"asset_id":"17924629579804316786455515989238352689210911545477836576430679697715946894553", "price":"0.01", "size":"13054.5", "side":"BUY", "hash":"01a69bdb2cf4c1f6fc1f63a91379869744688700", "best_bid":"0.59", "best_ask":"0.6"}, {"asset_id":"12935926064588426924078449947177910958215776269411501731627440228801766632772", "price":"0.99", "size":"13054.5", "side":"SELL", "hash":"7991f7783e22ad66cc5cc4c6b09f71da51df10f0", "best_bid":"0.4", "best_ask":"0.41"}], "timestamp":"1784449239056", "event_type":"price_change"}
{"market":"0xab772601f501b265bfe8982eb61d5347ef9945de314bfdf4ac0189c288ffb0b3", "price_changes":[{"asset_id":"17924629579804316786455515989238352689210911545477836576430679697715946894553", "price":"0.01", "size":"12954.5", "side":"BUY", "hash":"763492e662915f15a7613e7377496e7c06f4ceca", "best_bid":"0.59", "best_ask":"0.6"}, {"asset_id":"12935926064588426924078449947177910958215776269411501731627440228801766632772", "price":"0.99", "size":"12954.5", "side":"SELL", "hash":"23e6e6b3b7660fcce20928bd441c3a0afab279f5", "best_bid":"0.4", "best_ask":"0.41"}], "timestamp":"1784449239057", "event_type":"price_change"}
{"market":"0xab772601f501b265bfe8982eb61d5347ef9945de314bfdf4ac0189c288ffb0b3", "price_changes":[{"asset_id":"17924629579804316786455515989238352689210911545477836576430679697715946894553", "price":"0.01", "size":"12959.51", "side":"BUY", "hash":"87fb70d1298251a14bedcfbcc6e84eda0701050e", "best_bid":"0.59", "best_ask":"0.6"}, {"asset_id":"12935926064588426924078449947177910958215776269411501731627440228801766632772", "price":"0.99", "size":"12959.51", "side":"SELL", "hash":"18140767f4b17cfe96ee7b84f02dc62c9ff9afca", "best_bid":"0.4", "best_ask":"0.41"}], "timestamp":"1784449239063", "event_type":"price_change"}
{"market":"0xab772601f501b265bfe8982eb61d5347ef9945de314bfdf4ac0189c288ffb0b3", "price_changes":[{"asset_id":"12935926064588426924078449947177910958215776269411501731627440228801766632772", "price":"0.01", "size":"14894.14", "side":"BUY", "hash":"14d6b71fc612883ee69830f53a66a24f7fa28e8c", "best_bid":"0.4", "best_ask":"0.41"}, {"asset_id":"17924629579804316786455515989238352689210911545477836576430679697715946894553", "price":"0.99", "size":"14894.14", "side":"SELL", "hash":"2bfb1d27bcebdceda54de0e70a79a62fd4d7c2fd", "best_bid":"0.59", "best_ask":"0.6"}], "timestamp":"1784449239064", "event_type":"price_change"}
{"market":"0xab772601f501b265bfe8982eb61d5347ef9945de314bfdf4ac0189c288ffb0b3", "price_changes":[{"asset_id":"12935926064588426924078449947177910958215776269411501731627440228801766632772", "price":"0.39", "size":"140.88", "side":"BUY", "hash":"87d717f049ab15ad9f6e97ee022da280ce6afd24", "best_bid":"0.4", "best_ask":"0.41"}, {"asset_id":"17924629579804316786455515989238352689210911545477836576430679697715946894553", "price":"0.61", "size":"140.88", "side":"SELL", "hash":"3aeae6b1e056d89341fe86b29b9c2ddc57334654", "best_bid":"0.59", "best_ask":"0.6"}], "timestamp":"1784449239068", "event_type":"price_change"}
{"market":"0xab772601f501b265bfe8982eb61d5347ef9945de314bfdf4ac0189c288ffb0b3", "price_changes":[{"asset_id":"17924629579804316786455515989238352689210911545477836576430679697715946894553", "price":"0.01", "size":"12954.5", "side":"BUY", "hash":"768362faa51f9228e5fda6c0c3b4c07fd75b215a", "best_bid":"0.59", "best_ask":"0.6"}, {"asset_id":"12935926064588426924078449947177910958215776269411501731627440228801766632772", "price":"0.99", "size":"12954.5", "side":"SELL", "hash":"79761a7e42daf31b1828200938e91147c907ba78", "best_bid":"0.4", "best_ask":"0.41"}], "timestamp":"1784449239090", "event_type":"price_change"}
{"market":"0xab772601f501b265bfe8982eb61d5347ef9945de314bfdf4ac0189c288ffb0b3", "price_changes":[{"asset_id":"12935926064588426924078449947177910958215776269411501731627440228801766632772", "price":"0.01", "size":"14889.14", "side":"BUY", "hash":"9d9e669c4a13005899d141e34d5eaf68bdb9b163", "best_bid":"0.4", "best_ask":"0.41"}, {"asset_id":"17924629579804316786455515989238352689210911545477836576430679697715946894553", "price":"0.99", "size":"14889.14", "side":"SELL", "hash":"f2176c2d411eda6ff443e305f190960fa810314c", "best_bid":"0.59", "best_ask":"0.6"}], "timestamp":"1784449239099", "event_type":"price_change"}
{"market":"0xab772601f501b265bfe8982eb61d5347ef9945de314bfdf4ac0189c288ffb0b3", "price_changes":[{"asset_id":"17924629579804316786455515989238352689210911545477836576430679697715946894553", "price":"0.01", "size":"13054.5", "side":"BUY", "hash":"d084307b3a896112e08bda595a3a056cfd087d05", "best_bid":"0.59", "best_ask":"0.6"}, {"asset_id":"12935926064588426924078449947177910958215776269411501731627440228801766632772", "price":"0.99", "size":"13054.5", "side":"SELL", "hash":"30a643d57007cbaa24bcc03e4d6c437e64a3480c", "best_bid":"0.4", "best_ask":"0.41"}], "timestamp":"1784449239100", "event_type":"price_change"}
{"market":"0xab772601f501b265bfe8982eb61d5347ef9945de314bfdf4ac0189c288ffb0b3", "price_changes":[{"asset_id":"17924629579804316786455515989238352689210911545477836576430679697715946894553", "price":"0.01", "size":"13060.5", "side":"BUY", "hash":"87ffc7738c2beaf29dbdd2f619e43bbb1b6a1ee4", "best_bid":"0.59", "best_ask":"0.6"}, {"asset_id":"12935926064588426924078449947177910958215776269411501731627440228801766632772", "price":"0.99", "size":"13060.5", "side":"SELL", "hash":"4507bb25a4972ddb1b5809c1df872b88b102ef35", "best_bid":"0.4", "best_ask":"0.41"}], "timestamp":"1784449239103", "event_type":"price_change"}
{"market":"0xab772601f501b265bfe8982eb61d5347ef9945de314bfdf4ac0189c288ffb0b3", "price_changes":[{"asset_id":"12935926064588426924078449947177910958215776269411501731627440228801766632772", "price":"0.39", "size":"165.88", "side":"BUY", "hash":"5e2cdf32c6f613e00c587718040860ba9afe6e79", "best_bid":"0.4", "best_ask":"0.41"}, {"asset_id":"17924629579804316786455515989238352689210911545477836576430679697715946894553", "price":"0.61", "size":"165.88", "side":"SELL", "hash":"b61ddb709e09952272e7962f5b4b912e52b2a1d3", "best_bid":"0.59", "best_ask":"0.6"}], "timestamp":"1784449239105", "event_type":"price_change"}
{"market":"0xab772601f501b265bfe8982eb61d5347ef9945de314bfdf4ac0189c288ffb0b3", "price_changes":[{"asset_id":"12935926064588426924078449947177910958215776269411501731627440228801766632772", "price":"0.39", "size":"140.88", "side":"BUY", "hash":"afb5ec38a2e1536db09c5b13b790d812b55eab4c", "best_bid":"0.4", "best_ask":"0.41"}, {"asset_id":"17924629579804316786455515989238352689210911545477836576430679697715946894553", "price":"0.61", "size":"140.88", "side":"SELL", "hash":"157ba2ec9c808e1f8dab2039d8d48de2db47d307", "best_bid":"0.59", "best_ask":"0.6"}], "timestamp":"1784449239119", "event_type":"price_change"}
{"market":"0xab772601f501b265bfe8982eb61d5347ef9945de314bfdf4ac0189c288ffb0b3", "price_changes":[{"asset_id":"17924629579804316786455515989238352689210911545477836576430679697715946894553", "price":"0.49", "size":"99.14", "side":"BUY", "hash":"c7ed39aa297f02ba2df7ae7292a28e370ccb7f61", "best_bid":"0.59", "best_ask":"0.6"}, {"asset_id":"12935926064588426924078449947177910958215776269411501731627440228801766632772", "price":"0.51", "size":"99.14", "side":"SELL", "hash":"bc5064a1538d1c422452a9dccfb77957fc21d5bb", "best_bid":"0.4", "best_ask":"0.41"}], "timestamp":"1784449239119", "event_type":"price_change"}
{"market":"0xab772601f501b265bfe8982eb61d5347ef9945de314bfdf4ac0189c288ffb0b3", "price_changes":[{"asset_id":"17924629579804316786455515989238352689210911545477836576430679697715946894553", "price":"0.49", "size":"81", "side":"BUY", "hash":"7f60aa646e4afc0697aad4c5f729e059c8854a26", "best_bid":"0.59", "best_ask":"0.6"}, {"asset_id":"12935926064588426924078449947177910958215776269411501731627440228801766632772", "price":"0.51", "size":"81", "side":"SELL", "hash":"4ad0ffe1b7b98bf67cd279afc236c39d6e3aa650", "best_bid":"0.4", "best_ask":"0.41"}], "timestamp":"1784449239122", "event_type":"price_change"}
{"market":"0xab772601f501b265bfe8982eb61d5347ef9945de314bfdf4ac0189c288ffb0b3", "price_changes":[{"asset_id":"12935926064588426924078449947177910958215776269411501731627440228801766632772", "price":"0.4", "size":"146.06", "side":"BUY", "hash":"ed5e2a520f9101b3dde05d2ac3497b34f4f44da0", "best_bid":"0.4", "best_ask":"0.41"}, {"asset_id":"17924629579804316786455515989238352689210911545477836576430679697715946894553", "price":"0.6", "size":"146.06", "side":"SELL", "hash":"cf19b66bfe32d633f203c72f7c83c71a8ef8e141", "best_bid":"0.59", "best_ask":"0.6"}], "timestamp":"1784449239128", "event_type":"price_change"}
{"market":"0xab772601f501b265bfe8982eb61d5347ef9945de314bfdf4ac0189c288ffb0b3", "price_changes":[{"asset_id":"17924629579804316786455515989238352689210911545477836576430679697715946894553", "price":"0.01", "size":"13054.5", "side":"BUY", "hash":"419d893b8d919d65b140905a02455f92573cbe3a", "best_bid":"0.59", "best_ask":"0.6"}, {"asset_id":"12935926064588426924078449947177910958215776269411501731627440228801766632772", "price":"0.99", "size":"13054.5", "side":"SELL", "hash":"befb1da1fffc9106be83d26e838723b2c6fae95a", "best_bid":"0.4", "best_ask":"0.41"}], "timestamp":"1784449239130", "event_type":"price_change"}
{"market":"0xab772601f501b265bfe8982eb61d5347ef9945de314bfdf4ac0189c288ffb0b3", "price_changes":[{"asset_id":"12935926064588426924078449947177910958215776269411501731627440228801766632772", "price":"0.4", "size":"121.06", "side":"BUY", "hash":"90c7cef526fb09bbafc16830fd965ed3b15b61b3", "best_bid":"0.4", "best_ask":"0.41"}, {"asset_id":"17924629579804316786455515989238352689210911545477836576430679697715946894553", "price":"0.6", "size":"121.06", "side":"SELL", "hash":"bd1f3e76b83fffedace7f34eef8309cb4ec6989c", "best_bid":"0.59", "best_ask":"0.6"}], "timestamp":"1784449239130", "event_type":"price_change"}
{"market":"0xab772601f501b265bfe8982eb61d5347ef9945de314bfdf4ac0189c288ffb0b3", "price_changes":[{"asset_id":"12935926064588426924078449947177910958215776269411501731627440228801766632772", "price":"0.4", "size":"101.06", "side":"BUY", "hash":"b27e03195b336613bdf47ae4d1f34f33481a23e1", "best_bid":"0.4", "best_ask":"0.41"}, {"asset_id":"17924629579804316786455515989238352689210911545477836576430679697715946894553", "price":"0.6", "size":"101.06", "side":"SELL", "hash":"78a676848de0635226cb07e6df8a2cf643e64786", "best_bid":"0.59", "best_ask":"0.6"}], "timestamp":"1784449239132", "event_type":"price_change"}
{"market":"0xab772601f501b265bfe8982eb61d5347ef9945de314bfdf4ac0189c288ffb0b3", "asset_id":"12935926064588426924078449947177910958215776269411501731627440228801766632772", "bids":[{"price":"0.01", "size":"14889.14"}, {"price":"0.02", "size":"3964.52"}, {"price":"0.03", "size":"2179.29"}, {"price":"0.04", "size":"1215.1"}, {"price":"0.05", "size":"1752.19"}, {"price":"0.06", "size":"1122.02"}, {"price":"0.07", "size":"953.49"}, {"price":"0.08", "size":"1234.38"}, {"price":"0.09", "size":"791.7"}, {"price":"0.1", "size":"561.2"}, {"price":"0.11", "size":"1502.1"}, {"price":"0.12", "size":"1112.05"}, {"price":"0.13", "size":"147.4"}, {"price":"0.14", "size":"166.8"}, {"price":"0.15", "size":"454.04"}, {"price":"0.16", "size":"257.1"}, {"price":"0.17", "size":"217.17"}, {"price":"0.18", "size":"160.7"}, {"price":"0.19", "size":"113.89"}, {"price":"0.2", "size":"256.2"}, {"price":"0.21", "size":"636.8"}, {"price":"0.22", "size":"115.5"}, {"price":"0.23", "size":"145.8"}, {"price":"0.24", "size":"152.22"}, {"price":"0.25", "size":"137.2"}, {"price":"0.26", "size":"144.3"}, {"price":"0.27", "size":"148.5"}, {"price":"0.28", "size":"146.77"}, {"price":"0.29", "size":"216.99"}, {"price":"0.3", "size":"202.81"}, {"price":"0.31", "size":"554.58"}, {"price":"0.32", "size":"241.69"}, {"price":"0.33", "size":"144.65"}, {"price":"0.34", "size":"125.76"}, {"price":"0.35", "size":"122.8"}, {"price":"0.36", "size":"185.77"}, {"price":"0.37", "size":"170.91"}, {"price":"0.38", "size":"361.23"}, {"price":"0.39", "size":"140.88"}, {"price":"0.4", "size":"101.06"}], "asks":[{"price":"0.99", "size":"13054.5"}, {"price":"0.98", "size":"3885.25"}, {"price":"0.97", "size":"2250.95"}, {"price":"0.96", "size":"1270.1"}, {"price":"0.95", "size":"1753.6"}, {"price":"0.94", "size":"1109.35"}, {"price":"0.93", "size":"944.2"}, {"price":"0.92", "size":"1225.88"}, {"price":"0.91", "size":"796.7"}, {"price":"0.9", "size":"365.2"}, {"price":"0.89", "size":"1502.1"}, {"price":"0.88", "size":"195.05"}, {"price":"0.87", "size":"147.4"}, {"price":"0.86", "size":"183.4"}, {"price":"0.85", "size":"469.43"}, {"price":"0.84", "size":"127.1"}, {"price":"0.83", "size":"107.69"}, {"price":"0.82", "size":"125.7"}, {"price":"0.81", "size":"98.89"}, {"price":"0.8", "size":"206.2"}, {"price":"0.79", "size":"616.8"}, {"price":"0.78", "size":"992.5"}, {"price":"0.77", "size":"82.3"}, {"price":"0.76", "size":"118.03"}, {"price":"0.75", "size":"92.2"}, {"price":"0.74", "size":"90.3"}, {"price":"0.73", "size":"83.5"}, {"price":"0.72", "size":"92.77"}, {"price":"0.71", "size":"74.39"}, {"price":"0.7", "size":"83"}, {"price":"0.69", "size":"94.7"}, {"price":"0.68", "size":"160.64"}, {"price":"0.67", "size":"108.1"}, {"price":"0.66", "size":"92.8"}, {"price":"0.65", "size":"184.6"}, {"price":"0.64", "size":"104.39"}, {"price":"0.63", "size":"94.2"}, {"price":"0.62", "size":"55"}, {"price":"0.61", "size":"69.8"}, {"price":"0.6", "size":"122.94"}, {"price":"0.59", "size":"100.5"}, {"price":"0.58", "size":"86.02"}, {"price":"0.57", "size":"75.3"}, {"price":"0.56", "size":"64.2"}, {"price":"0.55", "size":"204.71"}, {"price":"0.54", "size":"102.1"}, {"price":"0.53", "size":"72.1"}, {"price":"0.52", "size":"71"}, {"price":"0.51", "size":"81"}, {"price":"0.5", "size":"129.39"}, {"price":"0.49", "size":"425.92"}, {"price":"0.48", "size":"235.91"}, {"price":"0.47", "size":"560.7"}, {"price":"0.46", "size":"135.85"}, {"price":"0.45", "size":"221.69"}, {"price":"0.44", "size":"252.99"}, {"price":"0.43", "size":"130"}, {"price":"0.42", "size":"141.82"}, {"price":"0.41", "size":"125.28"}], "hash":"b27e03195b336613bdf47ae4d1f34f33481a23e1", "timestamp":"1784449239132", "event_type":"book"}
{"market":"0xab772601f501b265bfe8982eb61d5347ef9945de314bfdf4ac0189c288ffb0b3", "asset_id":"17924629579804316786455515989238352689210911545477836576430679697715946894553", "bids":[{"price":"0.01", "size":"13054.5"}, {"price":"0.02", "size":"3885.25"}, {"price":"0.03", "size":"2250.95"}, {"price":"0.04", "size":"1270.1"}, {"price":"0.05", "size":"1753.6"}, {"price":"0.06", "size":"1109.35"}, {"price":"0.07", "size":"944.2"}, {"price":"0.08", "size":"1225.88"}, {"price":"0.09", "size":"796.7"}, {"price":"0.1", "size":"365.2"}, {"price":"0.11", "size":"1502.1"}, {"price":"0.12", "size":"195.05"}, {"price":"0.13", "size":"147.4"}, {"price":"0.14", "size":"183.4"}, {"price":"0.15", "size":"469.43"}, {"price":"0.16", "size":"127.1"}, {"price":"0.17", "size":"107.69"}, {"price":"0.18", "size":"125.7"}, {"price":"0.19", "size":"98.89"}, {"price":"0.2", "size":"206.2"}, {"price":"0.21", "size":"616.8"}, {"price":"0.22", "size":"992.5"}, {"price":"0.23", "size":"82.3"}, {"price":"0.24", "size":"118.03"}, {"price":"0.25", "size":"92.2"}, {"price":"0.26", "size":"90.3"}, {"price":"0.27", "size":"83.5"}, {"price":"0.28", "size":"92.77"}, {"price":"0.29", "size":"74.39"}, {"price":"0.3", "size":"83"}, {"price":"0.31", "size":"94.7"}, {"price":"0.32", "size":"160.64"}, {"price":"0.33", "size":"108.1"}, {"price":"0.34", "size":"92.8"}, {"price":"0.35", "size":"184.6"}, {"price":"0.36", "size":"104.39"}, {"price":"0.37", "size":"94.2"}, {"price":"0.38", "size":"55"}, {"price":"0.39", "size":"69.8"}, {"price":"0.4", "size":"122.94"}, {"price":"0.41", "size":"100.5"}, {"price":"0.42", "size":"86.02"}, {"price":"0.43", "size":"75.3"}, {"price":"0.44", "size":"64.2"}, {"price":"0.45", "size":"204.71"}, {"price":"0.46", "size":"102.1"}, {"price":"0.47", "size":"72.1"}, {"price":"0.48", "size":"71"}, {"price":"0.49", "size":"81"}, {"price":"0.5", "size":"129.39"}, {"price":"0.51", "size":"425.92"}, {"price":"0.52", "size":"235.91"}, {"price":"0.53", "size":"560.7"}, {"price":"0.54", "size":"135.85"}, {"price":"0.55", "size":"221.69"}, {"price":"0.56", "size":"252.99"}, {"price":"0.57", "size":"130"}, {"price":"0.58", "size":"141.82"}, {"price":"0.59", "size":"125.28"}], "asks":[{"price":"0.99", "size":"14889.14"}, {"price":"0.98", "size":"3964.52"}, {"price":"0.97", "size":"2179.29"}, {"price":"0.96", "size":"1215.1"}, {"price":"0.95", "size":"1752.19"}, {"price":"0.94", "size":"1122.02"}, {"price":"0.93", "size":"953.49"}, {"price":"0.92", "size":"1234.38"}, {"price":"0.91", "size":"791.7"}, {"price":"0.9", "size":"561.2"}, {"price":"0.89", "size":"1502.1"}, {"price":"0.88", "size":"1112.05"}, {"price":"0.87", "size":"147.4"}, {"price":"0.86", "size":"166.8"}, {"price":"0.85", "size":"454.04"}, {"price":"0.84", "size":"257.1"}, {"price":"0.83", "size":"217.17"}, {"price":"0.82", "size":"160.7"}, {"price":"0.81", "size":"113.89"}, {"price":"0.8", "size":"256.2"}, {"price":"0.79", "size":"636.8"}, {"price":"0.78", "size":"115.5"}, {"price":"0.77", "size":"145.8"}, {"price":"0.76", "size":"152.22"}, {"price":"0.75", "size":"137.2"}, {"price":"0.74", "size":"144.3"}, {"price":"0.73", "size":"148.5"}, {"price":"0.72", "size":"146.77"}, {"price":"0.71", "size":"216.99"}, {"price":"0.7", "size":"202.81"}, {"price":"0.69", "size":"554.58"}, {"price":"0.68", "size":"241.69"}, {"price":"0.67", "size":"144.65"}, {"price":"0.66", "size":"125.76"}, {"price":"0.65", "size":"122.8"}, {"price":"0.64", "size":"185.77"}, {"price":"0.63", "size":"170.91"}, {"price":"0.62", "size":"361.23"}, {"price":"0.61", "size":"140.88"}, {"price":"0.6", "size":"101.06"}], "hash":"78a676848de0635226cb07e6df8a2cf643e64786", "timestamp":"1784449239132", "event_type":"book"}
{"market":"0xab772601f501b265bfe8982eb61d5347ef9945de314bfdf4ac0189c288ffb0b3", "price_changes":[{"asset_id":"17924629579804316786455515989238352689210911545477836576430679697715946894553", "price":"0.01", "size":"13154.5", "side":"BUY", "hash":"6ddf8bfd3d34f8fb98bb1f12f109c3d831583677", "best_bid":"0.59", "best_ask":"0.6"}, {"asset_id":"12935926064588426924078449947177910958215776269411501731627440228801766632772", "price":"0.99", "size":"13154.5", "side":"SELL", "hash":"86d6779e192bf639a29d56bd24e432b9524364e8", "best_bid":"0.4", "best_ask":"0.41"}], "timestamp":"1784449239137", "event_type":"price_change"}
{"market":"0xab772601f501b265bfe8982eb61d5347ef9945de314bfdf4ac0189c288ffb0b3", "price_changes":[{"asset_id":"17924629579804316786455515989238352689210911545477836576430679697715946894553", "price":"0.01", "size":"13054.5", "side":"BUY", "hash":"806af9025874782de9be91a1c67ea2a36694c0d5", "best_bid":"0.59", "best_ask":"0.6"}, {"asset_id":"12935926064588426924078449947177910958215776269411501731627440228801766632772", "price":"0.99", "size":"13054.5", "side":"SELL", "hash":"e32645c3a637e701eac013d75f13cd8403fe3828", "best_bid":"0.4", "best_ask":"0.41"}], "timestamp":"1784449239138", "event_type":"price_change"}
{"market":"0xab772601f501b265bfe8982eb61d5347ef9945de314bfdf4ac0189c288ffb0b3", "price_changes":[{"asset_id":"12935926064588426924078449947177910958215776269411501731627440228801766632772", "price":"0.01", "size":"14884.14", "side":"BUY", "hash":"d7e3e7635cb98d305403babcbd780abb9ae0ecf0", "best_bid":"0.4", "best_ask":"0.41"}, {"asset_id":"17924629579804316786455515989238352689210911545477836576430679697715946894553", "price":"0.99", "size":"14884.14", "side":"SELL", "hash":"27054ad98a989f5ca6df5c9dcb0a31e97e21694e", "best_bid":"0.59", "best_ask":"0.6"}], "timestamp":"1784449239140", "event_type":"price_change"}
{"market":"0xab772601f501b265bfe8982eb61d5347ef9945de314bfdf4ac0189c288ffb0b3", "price_changes":[{"asset_id":"12935926064588426924078449947177910958215776269411501731627440228801766632772", "price":"0.35", "size":"142.8", "side":"BUY", "hash":"1e13bfe42916024fad5f22e1df2c735b318eba55", "best_bid":"0.4", "best_ask":"0.41"}, {"asset_id":"17924629579804316786455515989238352689210911545477836576430679697715946894553", "price":"0.65", "size":"142.8", "side":"SELL", "hash":"43f563be458274a9194df184d99342525b060574", "best_bid":"0.59", "best_ask":"0.6"}], "timestamp":"1784449239142", "event_type":"price_change"}
{"market":"0xab772601f501b265bfe8982eb61d5347ef9945de314bfdf4ac0189c288ffb0b3", "asset_id":"12935926064588426924078449947177910958215776269411501731627440228801766632772", "price":"0.41", "size":"2.439023", "fee_rate_bps":"0", "side":"BUY", "timestamp":"1784449239145", "event_type":"last_trade_price", "transaction_hash":"0xa4f9da1fa73c3474aa1444607b6317b572bb61d38806f7ae60593956dfe42c2d"}
{"market":"0xab772601f501b265bfe8982eb61d5347ef9945de314bfdf4ac0189c288ffb0b3", "price_changes":[{"asset_id":"17924629579804316786455515989238352689210911545477836576430679697715946894553", "price":"0.04", "size":"1275.1", "side":"BUY", "hash":"bde922c1605c1e51a9816d2d35749fc65ddec3e4", "best_bid":"0.59", "best_ask":"0.6"}, {"asset_id":"12935926064588426924078449947177910958215776269411501731627440228801766632772", "price":"0.96", "size":"1275.1", "side":"SELL", "hash":"b7191c63110b5e353469c0c0af8268a4a1f06cd6", "best_bid":"0.4", "best_ask":"0.41"}], "timestamp":"1784449239148", "event_type":"price_change"}
{"market":"0xab772601f501b265bfe8982eb61d5347ef9945de314bfdf4ac0189c288ffb0b3", "price_changes":[{"asset_id":"12935926064588426924078449947177910958215776269411501731627440228801766632772", "price":"0.39", "size":"165.88", "side":"BUY", "hash":"f38ae26ff10f8836b21cb8b6e641edf1dc0fe159", "best_bid":"0.4", "best_ask":"0.41"}, {"asset_id":"17924629579804316786455515989238352689210911545477836576430679697715946894553", "price":"0.61", "size":"165.88", "side":"SELL", "hash":"ada2cd6eeae90b0cec8eb6f5e2f20a91e45766af", "best_bid":"0.59", "best_ask":"0.6"}], "timestamp":"1784449239149", "event_type":"price_change"}
{"market":"0xab772601f501b265bfe8982eb61d5347ef9945de314bfdf4ac0189c288ffb0b3", "price_changes":[{"asset_id":"12935926064588426924078449947177910958215776269411501731627440228801766632772", "price":"0.39", "size":"140.88", "side":"BUY", "hash":"e4c69478ddeb90e10c67d6ebf762b75be7a8ff7d", "best_bid":"0.4", "best_ask":"0.41"}, {"asset_id":"17924629579804316786455515989238352689210911545477836576430679697715946894553", "price":"0.61", "size":"140.88", "side":"SELL", "hash":"e40e9b82eeb795c2ebfdf9c8c0e239f06ae98c44", "best_bid":"0.59", "best_ask":"0.6"}], "timestamp":"1784449239151", "event_type":"price_change"}
{"market":"0xab772601f501b265bfe8982eb61d5347ef9945de314bfdf4ac0189c288ffb0b3", "asset_id":"17924629579804316786455515989238352689210911545477836576430679697715946894553", "price":"0.6", "size":"20", "fee_rate_bps":"0", "side":"BUY", "timestamp":"1784449239164", "event_type":"last_trade_price", "transaction_hash":"0x2bce494e106bb30d136e56f2c6d9e82133fd1693f907f7a5f247ab2a70bdf8f9"}
{"market":"0xab772601f501b265bfe8982eb61d5347ef9945de314bfdf4ac0189c288ffb0b3", "price_changes":[{"asset_id":"12935926064588426924078449947177910958215776269411501731627440228801766632772", "price":"0.32", "size":"166.69", "side":"BUY", "hash":"df85bf7b129c20c1fdc7dbf08a4301da5d0a2fea", "best_bid":"0.4", "best_ask":"0.41"}, {"asset_id":"17924629579804316786455515989238352689210911545477836576430679697715946894553", "price":"0.68", "size":"166.69", "side":"SELL", "hash":"39e9d5df825e3211a6722cf82951fb7d1e9d32b7", "best_bid":"0.59", "best_ask":"0.6"}], "timestamp":"1784449239173", "event_type":"price_change"}
{"market":"0xab772601f501b265bfe8982eb61d5347ef9945de314bfdf4ac0189c288ffb0b3", "price_changes":[{"asset_id":"12935926064588426924078449947177910958215776269411501731627440228801766632772", "price":"0.29", "size":"141.99", "side":"BUY", "hash":"df85bf7b129c20c1fdc7dbf08a4301da5d0a2fea", "best_bid":"0.4", "best_ask":"0.41"}, {"asset_id":"17924629579804316786455515989238352689210911545477836576430679697715946894553", "price":"0.71", "size":"141.99", "side":"SELL", "hash":"39e9d5df825e3211a6722cf82951fb7d1e9d32b7", "best_bid":"0.59", "best_ask":"0.6"}], "timestamp":"1784449239173", "event_type":"price_change"}
{"market":"0xab772601f501b265bfe8982eb61d5347ef9945de314bfdf4ac0189c288ffb0b3", "price_changes":[{"asset_id":"12935926064588426924078449947177910958215776269411501731627440228801766632772", "price":"0.37", "size":"155.91", "side":"BUY", "hash":"df85bf7b129c20c1fdc7dbf08a4301da5d0a2fea", "best_bid":"0.4", "best_ask":"0.41"}, {"asset_id":"17924629579804316786455515989238352689210911545477836576430679697715946894553", "price":"0.63", "size":"155.91", "side":"SELL", "hash":"39e9d5df825e3211a6722cf82951fb7d1e9d32b7", "best_bid":"0.59", "best_ask":"0.6"}], "timestamp":"1784449239173", "event_type":"price_change"}
{"market":"0xab772601f501b265bfe8982eb61d5347ef9945de314bfdf4ac0189c288ffb0b3", "price_changes":[{"asset_id":"17924629579804316786455515989238352689210911545477836576430679697715946894553", "price":"0.59", "size":"131.47", "side":"BUY", "hash":"53691a428d338814ea12ba9a1e92302697c6a067", "best_bid":"0.59", "best_ask":"0.6"}, {"asset_id":"12935926064588426924078449947177910958215776269411501731627440228801766632772", "price":"0.41", "size":"131.47", "side":"SELL", "hash":"b96dc2bffc44f652e1a82179c878252a00cdfb98", "best_bid":"0.4", "best_ask":"0.41"}], "timestamp":"1784449239177", "event_type":"price_change"}
{"market":"0xab772601f501b265bfe8982eb61d5347ef9945de314bfdf4ac0189c288ffb0b3", "price_changes":[{"asset_id":"17924629579804316786455515989238352689210911545477836576430679697715946894553", "price":"0.01", "size":"13154.5", "side":"BUY", "hash":"27018e3fce6ef4830867908e72d4a8917b23dbe2", "best_bid":"0.59", "best_ask":"0.6"}, {"asset_id":"12935926064588426924078449947177910958215776269411501731627440228801766632772", "price":"0.99", "size":"13154.5", "side":"SELL", "hash":"b3d791520dc04922b4ac8320bceb765370accd22", "best_bid":"0.4", "best_ask":"0.41"}], "timestamp":"1784449239179", "event_type":"price_change"}
{"market":"0xab772601f501b265bfe8982eb61d5347ef9945de314bfdf4ac0189c288ffb0b3", "price_changes":[{"asset_id":"12935926064588426924078449947177910958215776269411501731627440228801766632772", "price":"0.39", "size":"165.88", "side":"BUY", "hash":"38b7462dd6c6f7ed2c00416dcb1c72fc01b3e978", "best_bid":"0.4", "best_ask":"0.41"}, {"asset_id":"17924629579804316786455515989238352689210911545477836576430679697715946894553", "price":"0.61", "size":"165.88", "side":"SELL", "hash":"ed286dd21caf296954563beec7415283c9c8999c", "best_bid":"0.59", "best_ask":"0.6"}], "timestamp":"1784449239183", "event_type":"price_change"}
{"market":"0xab772601f501b265bfe8982eb61d5347ef9945de314bfdf4ac0189c288ffb0b3", "price_changes":[{"asset_id":"17924629579804316786455515989238352689210911545477836576430679697715946894553", "price":"0.01", "size":"13054.5", "side":"BUY", "hash":"55852a6940c6b492bd853aab45621c7a2b405e64", "best_bid":"0.59", "best_ask":"0.6"}, {"asset_id":"12935926064588426924078449947177910958215776269411501731627440228801766632772", "price":"0.99", "size":"13054.5", "side":"SELL", "hash":"811d073271915d1e4f05feddad25bc7b91e52029", "best_bid":"0.4", "best_ask":"0.41"}], "timestamp":"1784449239184", "event_type":"price_change"}
{"market":"0xab772601f501b265bfe8982eb61d5347ef9945de314bfdf4ac0189c288ffb0b3", "price_changes":[{"asset_id":"12935926064588426924078449947177910958215776269411501731627440228801766632772", "price":"0.39", "size":"178.88", "side":"BUY", "hash":"5c1bb8d615be4d948c6b72376824012ffff6b93d", "best_bid":"0.4", "best_ask":"0.41"}, {"asset_id":"17924629579804316786455515989238352689210911545477836576430679697715946894553", "price":"0.61", "size":"178.88", "side":"SELL", "hash":"4f48bc847f164971bef4bd05c665b5b6b23593de", "best_bid":"0.59", "best_ask":"0.6"}], "timestamp":"1784449239198", "event_type":"price_change"}
{"market":"0xab772601f501b265bfe8982eb61d5347ef9945de314bfdf4ac0189c288ffb0b3", "price_changes":[{"asset_id":"17924629579804316786455515989238352689210911545477836576430679697715946894553", "price":"0.01", "size":"13060.5", "side":"BUY", "hash":"4a9e70eabf111d3de058233a27da6eca4c035c50", "best_bid":"0.59", "best_ask":"0.6"}, {"asset_id":"12935926064588426924078449947177910958215776269411501731627440228801766632772", "price":"0.99", "size":"13060.5", "side":"SELL", "hash":"2f87ed51e3ba276ae68634153f5930d4b11a02e6", "best_bid":"0.4", "best_ask":"0.41"}], "timestamp":"1784449239198", "event_type":"price_change"}
{"market":"0xab772601f501b265bfe8982eb61d5347ef9945de314bfdf4ac0189c288ffb0b3", "price_changes":[{"asset_id":"17924629579804316786455515989238352689210911545477836576430679697715946894553", "price":"0.04", "size":"1270.1", "side":"BUY", "hash":"76ea8a265fc3e5c2a2880ed72e450c13dba0e886", "best_bid":"0.59", "best_ask":"0.6"}, {"asset_id":"12935926064588426924078449947177910958215776269411501731627440228801766632772", "price":"0.96", "size":"1270.1", "side":"SELL", "hash":"65c4c12dde177888ab3a4fb4ddd982130042d89c", "best_bid":"0.4", "best_ask":"0.41"}], "timestamp":"1784449239199", "event_type":"price_change"}
{"market":"0xab772601f501b265bfe8982eb61d5347ef9945de314bfdf4ac0189c288ffb0b3", "price_changes":[{"asset_id":"12935926064588426924078449947177910958215776269411501731627440228801766632772", "price":"0.39", "size":"193.88", "side":"BUY", "hash":"1acc3b318639979e801ea2460167ef3a72fddf48", "best_bid":"0.4", "best_ask":"0.41"}, {"asset_id":"17924629579804316786455515989238352689210911545477836576430679697715946894553", "price":"0.61", "size":"193.88", "side":"SELL", "hash":"c72822d178614c677bd92a5535378dda099e4b0d", "best_bid":"0.59", "best_ask":"0.6"}], "timestamp":"1784449239199", "event_type":"price_change"}
{"market":"0xab772601f501b265bfe8982eb61d5347ef9945de314bfdf4ac0189c288ffb0b3", "price_changes":[{"asset_id":"12935926064588426924078449947177910958215776269411501731627440228801766632772", "price":"0.33", "size":"219.65", "side":"BUY", "hash":"3f367b7a10fc18431959711fdac053431f7f1249", "best_bid":"0.4", "best_ask":"0.41"}, {"asset_id":"17924629579804316786455515989238352689210911545477836576430679697715946894553", "price":"0.67", "size":"219.65", "side":"SELL", "hash":"2fafc8b903250ce83039f90852300b30f62fdfa5", "best_bid":"0.59", "best_ask":"0.6"}], "timestamp":"1784449239206", "event_type":"price_change"}
{"market":"0xab772601f501b265bfe8982eb61d5347ef9945de314bfdf4ac0189c288ffb0b3", "price_changes":[{"asset_id":"17924629579804316786455515989238352689210911545477836576430679697715946894553", "price":"0.01", "size":"12960.5", "side":"BUY", "hash":"8ba0bea99a82fb3139d14029fd30f1923ae33ed5", "best_bid":"0.59", "best_ask":"0.6"}, {"asset_id":"12935926064588426924078449947177910958215776269411501731627440228801766632772", "price":"0.99", "size":"12960.5", "side":"SELL", "hash":"da8217ddf6a8d13ef9984fad90f6b0e658ecf69c", "best_bid":"0.4", "best_ask":"0.41"}], "timestamp":"1784449239210", "event_type":"price_change"}
{"market":"0xab772601f501b265bfe8982eb61d5347ef9945de314bfdf4ac0189c288ffb0b3", "price_changes":[{"asset_id":"17924629579804316786455515989238352689210911545477836576430679697715946894553", "price":"0.29", "size":"86.99", "side":"BUY", "hash":"28751d97dce75067d96eb3be4393ab015e328f28", "best_bid":"0.59", "best_ask":"0.6"}, {"asset_id":"12935926064588426924078449947177910958215776269411501731627440228801766632772", "price":"0.71", "size":"86.99", "side":"SELL", "hash":"ca91efc973ae95719c581b20f28ec96684476e98", "best_bid":"0.4", "best_ask":"0.41"}], "timestamp":"1784449239211", "event_type":"price_change"}
{"market":"0xab772601f501b265bfe8982eb61d5347ef9945de314bfdf4ac0189c288ffb0b3", "price_changes":[{"asset_id":"17924629579804316786455515989238352689210911545477836576430679697715946894553", "price":"0.01", "size":"12965.5", "side":"BUY", "hash":"a7c5e8783cb0406caf1a4c07666bd2ce73e5a1a7", "best_bid":"0.59", "best_ask":"0.6"}, {"asset_id":"12935926064588426924078449947177910958215776269411501731627440228801766632772", "price":"0.99", "size":"12965.5", "side":"SELL", "hash":"2e133176ad47f8e523d8019546a98f41f3be3b2d", "best_bid":"0.4", "best_ask":"0.41"}], "timestamp":"1784449239212", "event_type":"price_change"}
{"market":"0xab772601f501b265bfe8982eb61d5347ef9945de314bfdf4ac0189c288ffb0b3", "price_changes":[{"asset_id":"12935926064588426924078449947177910958215776269411501731627440228801766632772", "price":"0.36", "size":"260.77", "side":"BUY", "hash":"50bc8fda9a8fe4853ae374204fef672f00c16e14", "best_bid":"0.4", "best_ask":"0.41"}, {"asset_id":"17924629579804316786455515989238352689210911545477836576430679697715946894553", "price":"0.64", "size":"260.77", "side":"SELL", "hash":"6a35ffb2086994173e0d6ef243ffa0e6eb005ed0", "best_bid":"0.59", "best_ask":"0.6"}], "timestamp":"1784449239213", "event_type":"price_change"}
{"market":"0xab772601f501b265bfe8982eb61d5347ef9945de314bfdf4ac0189c288ffb0b3", "price_changes":[{"asset_id":"17924629579804316786455515989238352689210911545477836576430679697715946894553", "price":"0.01", "size":"12960.5", "side":"BUY", "hash":"e7abe749f0e59ffbd79ce878379560576b0e36fc", "best_bid":"0.59", "best_ask":"0.6"}, {"asset_id":"12935926064588426924078449947177910958215776269411501731627440228801766632772", "price":"0.99", "size":"12960.5", "side":"SELL", "hash":"0d2409ae4d9b149c4bdfe29bf5d123650b362e6b", "best_bid":"0.4", "best_ask":"0.41"}], "timestamp":"1784449239221", "event_type":"price_change"}
{"market":"0xab772601f501b265bfe8982eb61d5347ef9945de314bfdf4ac0189c288ffb0b3", "price_changes":[{"asset_id":"17924629579804316786455515989238352689210911545477836576430679697715946894553", "price":"0.01", "size":"12955.5", "side":"BUY", "hash":"02874fc37bbea32c5c7b9d0dfa732890bf13cdc2", "best_bid":"0.59", "best_ask":"0.6"}, {"asset_id":"12935926064588426924078449947177910958215776269411501731627440228801766632772", "price":"0.99", "size":"12955.5", "side":"SELL", "hash":"b189ee83625e24c1388b07f297b52de916d02f04", "best_bid":"0.4", "best_ask":"0.41"}], "timestamp":"1784449239223", "event_type":"price_change"}
{"market":"0xab772601f501b265bfe8982eb61d5347ef9945de314bfdf4ac0189c288ffb0b3", "price_changes":[{"asset_id":"17924629579804316786455515989238352689210911545477836576430679697715946894553", "price":"0.01", "size":"12960.5", "side":"BUY", "hash":"73a7c90e90633d3e9f3c83d84033f4e65ed36adf", "best_bid":"0.59", "best_ask":"0.6"}, {"asset_id":"12935926064588426924078449947177910958215776269411501731627440228801766632772", "price":"0.99", "size":"12960.5", "side":"SELL", "hash":"b711848dff5ba36264e14a452fd956716f7d3baa", "best_bid":"0.4", "best_ask":"0.41"}], "timestamp":"1784449239223", "event_type":"price_change"}
{"market":"0xab772601f501b265bfe8982eb61d5347ef9945de314bfdf4ac0189c288ffb0b3", "price_changes":[{"asset_id":"12935926064588426924078449947177910958215776269411501731627440228801766632772", "price":"0.01", "size":"14889.14", "side":"BUY", "hash":"b90be47aa2675e32203671ab9628e821676cd2f0", "best_bid":"0.4", "best_ask":"0.41"}, {"asset_id":"17924629579804316786455515989238352689210911545477836576430679697715946894553", "price":"0.99", "size":"14889.14", "side":"SELL", "hash":"8f9941035968453c5ecdfdc3bae1d40339356519", "best_bid":"0.59", "best_ask":"0.6"}], "timestamp":"1784449239224", "event_type":"price_change"}
{"market":"0xab772601f501b265bfe8982eb61d5347ef9945de314bfdf4ac0189c288ffb0b3", "price_changes":[{"asset_id":"17924629579804316786455515989238352689210911545477836576430679697715946894553", "price":"0.01", "size":"12965.5", "side":"BUY", "hash":"a5d25164b8d20ff7bfb6369b4d46e7b21b91417f", "best_bid":"0.59", "best_ask":"0.6"}, {"asset_id":"12935926064588426924078449947177910958215776269411501731627440228801766632772", "price":"0.99", "size":"12965.5", "side":"SELL", "hash":"4500dda2579d2c1b478d9e165bbab237362630eb", "best_bid":"0.4", "best_ask":"0.41"}], "timestamp":"1784449239225", "event_type":"price_change"}
{"market":"0xab772601f501b265bfe8982eb61d5347ef9945de314bfdf4ac0189c288ffb0b3", "price_changes":[{"asset_id":"17924629579804316786455515989238352689210911545477836576430679697715946894553", "price":"0.01", "size":"12970.5", "side":"BUY", "hash":"4cc1ef95b5f5fba3eb19caa1998fbb8ba62ccf9e", "best_bid":"0.59", "best_ask":"0.6"}, {"asset_id":"12935926064588426924078449947177910958215776269411501731627440228801766632772", "price":"0.99", "size":"12970.5", "side":"SELL", "hash":"db518b8c0b63728621fd8f520f52f41754809704", "best_bid":"0.4", "best_ask":"0.41"}], "timestamp":"1784449239225", "event_type":"price_change"}
{"market":"0xab772601f501b265bfe8982eb61d5347ef9945de314bfdf4ac0189c288ffb0b3", "price_changes":[{"asset_id":"17924629579804316786455515989238352689210911545477836576430679697715946894553", "price":"0.01", "size":"12975.5", "side":"BUY", "hash":"ec8d757d752e01d2c7baac8f9cbbe6d645b0a917", "best_bid":"0.59", "best_ask":"0.6"}, {"asset_id":"12935926064588426924078449947177910958215776269411501731627440228801766632772", "price":"0.99", "size":"12975.5", "side":"SELL", "hash":"0e670b5b59eb9dc426a1359dc1475204f890ae77", "best_bid":"0.4", "best_ask":"0.41"}], "timestamp":"1784449239226", "event_type":"price_change"}
{"market":"0xab772601f501b265bfe8982eb61d5347ef9945de314bfdf4ac0189c288ffb0b3", "price_changes":[{"asset_id":"17924629579804316786455515989238352689210911545477836576430679697715946894553", "price":"0.01", "size":"12970.5", "side":"BUY", "hash":"e4dcb70177f2ac4aa9f66b6d138e29fb50974c92", "best_bid":"0.59", "best_ask":"0.6"}, {"asset_id":"12935926064588426924078449947177910958215776269411501731627440228801766632772", "price":"0.99", "size":"12970.5", "side":"SELL", "hash":"5ef66613c48b940db3ce1412402ac5c20ecc2148", "best_bid":"0.4", "best_ask":"0.41"}], "timestamp":"1784449239226", "event_type":"price_change"}
{"market":"0xab772601f501b265bfe8982eb61d5347ef9945de314bfdf4ac0189c288ffb0b3", "price_changes":[{"asset_id":"17924629579804316786455515989238352689210911545477836576430679697715946894553", "price":"0.01", "size":"12975.5", "side":"BUY", "hash":"e2978d247f63ce296d8bd968276468a58f544cbc", "best_bid":"0.59", "best_ask":"0.6"}, {"asset_id":"12935926064588426924078449947177910958215776269411501731627440228801766632772", "price":"0.99", "size":"12975.5", "side":"SELL", "hash":"b034d7c8866cfe431f78c1d2fe201f94e6e36ce7", "best_bid":"0.4", "best_ask":"0.41"}], "timestamp":"1784449239227", "event_type":"price_change"}
{"market":"0xab772601f501b265bfe8982eb61d5347ef9945de314bfdf4ac0189c288ffb0b3", "price_changes":[{"asset_id":"17924629579804316786455515989238352689210911545477836576430679697715946894553", "price":"0.01", "size":"12980.5", "side":"BUY", "hash":"ae58cffa9ed67e41f3b5f81838aceba1cc6c3020", "best_bid":"0.59", "best_ask":"0.6"}, {"asset_id":"12935926064588426924078449947177910958215776269411501731627440228801766632772", "price":"0.99", "size":"12980.5", "side":"SELL", "hash":"26a7a4e2443ce4b73bfea6e8be58121c007c68a1", "best_bid":"0.4", "best_ask":"0.41"}], "timestamp":"1784449239227", "event_type":"price_change"}
{"market":"0xab772601f501b265bfe8982eb61d5347ef9945de314bfdf4ac0189c288ffb0b3", "price_changes":[{"asset_id":"12935926064588426924078449947177910958215776269411501731627440228801766632772", "price":"0.01", "size":"14894.14", "side":"BUY", "hash":"bdcdf6885e811bf1b2fd5ec9d12543fcb3a0b26c", "best_bid":"0.4", "best_ask":"0.41"}, {"asset_id":"17924629579804316786455515989238352689210911545477836576430679697715946894553", "price":"0.99", "size":"14894.14", "side":"SELL", "hash":"b126ca0b2ba0dee1ff7c81d975df4b1c3dff284f", "best_bid":"0.59", "best_ask":"0.6"}], "timestamp":"1784449239228", "event_type":"price_change"}
{"market":"0xab772601f501b265bfe8982eb61d5347ef9945de314bfdf4ac0189c288ffb0b3", "price_changes":[{"asset_id":"12935926064588426924078449947177910958215776269411501731627440228801766632772", "price":"0.39", "size":"168.88", "side":"BUY", "hash":"7d6a13b140622deafe5794163597c6ebf9d078fe", "best_bid":"0.4", "best_ask":"0.41"}, {"asset_id":"17924629579804316786455515989238352689210911545477836576430679697715946894553", "price":"0.61", "size":"168.88", "side":"SELL", "hash":"b9c6b6bafa00ecb53fa35861ee655a7f92184556", "best_bid":"0.59", "best_ask":"0.6"}], "timestamp":"1784449239228", "event_type":"price_change"}
{"market":"0xab772601f501b265bfe8982eb61d5347ef9945de314bfdf4ac0189c288ffb0b3", "price_changes":[{"asset_id":"12935926064588426924078449947177910958215776269411501731627440228801766632772", "price":"0.01", "size":"14899.14", "side":"BUY", "hash":"1fa2b1a207903846a80a55858d3fe98904a974fd", "best_bid":"0.4", "best_ask":"0.41"}, {"asset_id":"17924629579804316786455515989238352689210911545477836576430679697715946894553", "price":"0.99", "size":"14899.14", "side":"SELL", "hash":"7a43624f0f7908f64981ceeaab3396ab50b08b5a", "best_bid":"0.59", "best_ask":"0.6"}], "timestamp":"1784449239229", "event_type":"price_change"}
{"market":"0xab772601f501b265bfe8982eb61d5347ef9945de314bfdf4ac0189c288ffb0b3", "price_changes":[{"asset_id":"17924629579804316786455515989238352689210911545477836576430679697715946894553", "price":"0.01", "size":"12985.5", "side":"BUY", "hash":"a3dc4f75de84df6c2ee44390b05e8e82dedb514c", "best_bid":"0.59", "best_ask":"0.6"}, {"asset_id":"12935926064588426924078449947177910958215776269411501731627440228801766632772", "price":"0.99", "size":"12985.5", "side":"SELL", "hash":"d22a2e904f98a664537ae2eb4514183c325245ec", "best_bid":"0.4", "best_ask":"0.41"}], "timestamp":"1784449239229", "event_type":"price_change"}
{"market":"0xab772601f501b265bfe8982eb61d5347ef9945de314bfdf4ac0189c288ffb0b3", "price_changes":[{"asset_id":"17924629579804316786455515989238352689210911545477836576430679697715946894553", "price":"0.01", "size":"12979.5", "side":"BUY", "hash":"d42d46227266e4e20936251a980606248b786dee", "best_bid":"0.59", "best_ask":"0.6"}, {"asset_id":"12935926064588426924078449947177910958215776269411501731627440228801766632772", "price":"0.99", "size":"12979.5", "side":"SELL", "hash":"4c9128b4a4ae17bf67beeb0a013455c142321444", "best_bid":"0.4", "best_ask":"0.41"}], "timestamp":"1784449239230", "event_type":"price_change"}
{"market":"0xab772601f501b265bfe8982eb61d5347ef9945de314bfdf4ac0189c288ffb0b3", "price_changes":[{"asset_id":"17924629579804316786455515989238352689210911545477836576430679697715946894553", "price":"0.01", "size":"12974.5", "side":"BUY", "hash":"a9ffed51c32b4670aa5da3f08b69f5cd7aefdfb4", "best_bid":"0.59", "best_ask":"0.6"}, {"asset_id":"12935926064588426924078449947177910958215776269411501731627440228801766632772", "price":"0.99", "size":"12974.5", "side":"SELL", "hash":"6c80f1804cf0f135af8e5050b79524745a80fb74", "best_bid":"0.4", "best_ask":"0.41"}], "timestamp":"1784449239233", "event_type":"price_change"}
{"market":"0xab772601f501b265bfe8982eb61d5347ef9945de314bfdf4ac0189c288ffb0b3", "price_changes":[{"asset_id":"12935926064588426924078449947177910958215776269411501731627440228801766632772", "price":"0.4", "size":"126.06", "side":"BUY", "hash":"8655fd65f0347d7720a9a71736a7b410cf23dca4", "best_bid":"0.4", "best_ask":"0.41"}, {"asset_id":"17924629579804316786455515989238352689210911545477836576430679697715946894553", "price":"0.6", "size":"126.06", "side":"SELL", "hash":"c69ad0bb264dd975c849979f0398b1df788cfaf4", "best_bid":"0.59", "best_ask":"0.6"}], "timestamp":"1784449239236", "event_type":"price_change"}
{"market":"0xab772601f501b265bfe8982eb61d5347ef9945de314bfdf4ac0189c288ffb0b3", "price_changes":[{"asset_id":"17924629579804316786455515989238352689210911545477836576430679697715946894553", "price":"0.44", "size":"84.2", "side":"BUY", "hash":"26847bd12aeffde88415ec147683dc6ae7787682", "best_bid":"0.59", "best_ask":"0.6"}, {"asset_id":"12935926064588426924078449947177910958215776269411501731627440228801766632772", "price":"0.56", "size":"84.2", "side":"SELL", "hash":"134a669f2dccfd3b931e053ed3b19f1021bab939", "best_bid":"0.4", "best_ask":"0.41"}], "timestamp":"1784449239239", "event_type":"price_change"}
{"market":"0xab772601f501b265bfe8982eb61d5347ef9945de314bfdf4ac0189c288ffb0b3", "price_changes":[{"asset_id":"12935926064588426924078449947177910958215776269411501731627440228801766632772", "price":"0.4", "size":"101.06", "side":"BUY", "hash":"9c2a4fd9139c8e90fbcc92391bcdb644f26b0be0", "best_bid":"0.4", "best_ask":"0.41"}, {"asset_id":"17924629579804316786455515989238352689210911545477836576430679697715946894553", "price":"0.6", "size":"101.06", "side":"SELL", "hash":"b797cdeb199849a40093c45198c3eb5291a0c549", "best_bid":"0.59", "best_ask":"0.6"}], "timestamp":"1784449239245", "event_type":"price_change"}
{"market":"0xab772601f501b265bfe8982eb61d5347ef9945de314bfdf4ac0189c288ffb0b3", "price_changes":[{"asset_id":"12935926064588426924078449947177910958215776269411501731627440228801766632772", "price":"0.35", "size":"117.8", "side":"BUY", "hash":"5111ff725682df57927b07fdf75d5418067bd62f", "best_bid":"0.4", "best_ask":"0.41"}, {"asset_id":"17924629579804316786455515989238352689210911545477836576430679697715946894553", "price":"0.65", "size":"117.8", "side":"SELL", "hash":"6c7344dd2f7dbe1501bf2e9bcc01a82d9e10f63c", "best_bid":"0.59", "best_ask":"0.6"}], "timestamp":"1784449239247", "event_type":"price_change"}
{"market":"0xab772601f501b265bfe8982eb61d5347ef9945de314bfdf4ac0189c288ffb0b3", "price_changes":[{"asset_id":"17924629579804316786455515989238352689210911545477836576430679697715946894553", "price":"0.01", "size":"12969.5", "side":"BUY", "hash":"00131c6232c246d173c2fc28e5b0b9a33f1172d1", "best_bid":"0.59", "best_ask":"0.6"}, {"asset_id":"12935926064588426924078449947177910958215776269411501731627440228801766632772", "price":"0.99", "size":"12969.5", "side":"SELL", "hash":"3e2622a35e3334430fd76e897c9e8eb5904e795b", "best_bid":"0.4", "best_ask":"0.41"}], "timestamp":"1784449239252", "event_type":"price_change"}
{"market":"0xab772601f501b265bfe8982eb61d5347ef9945de314bfdf4ac0189c288ffb0b3", "price_changes":[{"asset_id":"12935926064588426924078449947177910958215776269411501731627440228801766632772", "price":"0.34", "size":"150.76", "side":"BUY", "hash":"2bce935d961a520d326723ae7b84c4a823dd10a0", "best_bid":"0.4", "best_ask":"0.41"}, {"asset_id":"17924629579804316786455515989238352689210911545477836576430679697715946894553", "price":"0.66", "size":"150.76", "side":"SELL", "hash":"74ffb037a9306d447a11e13e8f325cb49be24c23", "best_bid":"0.59", "best_ask":"0.6"}], "timestamp":"1784449239253", "event_type":"price_change"}
{"market":"0xab772601f501b265bfe8982eb61d5347ef9945de314bfdf4ac0189c288ffb0b3", "price_changes":[{"asset_id":"12935926064588426924078449947177910958215776269411501731627440228801766632772", "price":"0.01", "size":"14894.14", "side":"BUY", "hash":"6ef9633c65ea91bc445a3488865996b0c47982bf", "best_bid":"0.4", "best_ask":"0.41"}, {"asset_id":"17924629579804316786455515989238352689210911545477836576430679697715946894553", "price":"0.99", "size":"14894.14", "side":"SELL", "hash":"e1b4619c2ad637b45eb081e6aa9ec99b59483dfe", "best_bid":"0.59", "best_ask":"0.6"}], "timestamp":"1784449239257", "event_type":"price_change"}
{"market":"0xab772601f501b265bfe8982eb61d5347ef9945de314bfdf4ac0189c288ffb0b3", "price_changes":[{"asset_id":"12935926064588426924078449947177910958215776269411501731627440228801766632772", "price":"0.39", "size":"193.88", "side":"BUY", "hash":"140161d94db84c260e510741ce33f9a64b0f36b4", "best_bid":"0.4", "best_ask":"0.41"}, {"asset_id":"17924629579804316786455515989238352689210911545477836576430679697715946894553", "price":"0.61", "size":"193.88", "side":"SELL", "hash":"e902e65aa267c0111fb707dff7d1a6c00d48983d", "best_bid":"0.59", "best_ask":"0.6"}], "timestamp":"1784449239258", "event_type":"price_change"}
{"market":"0xab772601f501b265bfe8982eb61d5347ef9945de314bfdf4ac0189c288ffb0b3", "price_changes":[{"asset_id":"17924629579804316786455515989238352689210911545477836576430679697715946894553", "price":"0.01", "size":"13069.5", "side":"BUY", "hash":"fdc20b381aa19a8157c0e954c70f16e8821535fe", "best_bid":"0.59", "best_ask":"0.6"}, {"asset_id":"12935926064588426924078449947177910958215776269411501731627440228801766632772", "price":"0.99", "size":"13069.5", "side":"SELL", "hash":"5ec4a4785b705b2d6581d53237180d39bde21662", "best_bid":"0.4", "best_ask":"0.41"}], "timestamp":"1784449239259", "event_type":"price_change"}
{"market":"0xab772601f501b265bfe8982eb61d5347ef9945de314bfdf4ac0189c288ffb0b3", "price_changes":[{"asset_id":"12935926064588426924078449947177910958215776269411501731627440228801766632772", "price":"0.39", "size":"168.88", "side":"BUY", "hash":"00b68f0fb7653727718d7345b05ce325c7820ff2", "best_bid":"0.4", "best_ask":"0.41"}, {"asset_id":"17924629579804316786455515989238352689210911545477836576430679697715946894553", "price":"0.61", "size":"168.88", "side":"SELL", "hash":"a8a737b4f7b2ff36ef9bdd31f2c2939e8a31683b", "best_bid":"0.59", "best_ask":"0.6"}], "timestamp":"1784449239260", "event_type":"price_change"}
{"market":"0xab772601f501b265bfe8982eb61d5347ef9945de314bfdf4ac0189c288ffb0b3", "price_changes":[{"asset_id":"12935926064588426924078449947177910958215776269411501731627440228801766632772", "price":"0.34", "size":"125.76", "side":"BUY", "hash":"377de221fb2287a78399ff749176483b2ba38c91", "best_bid":"0.4", "best_ask":"0.41"}, {"asset_id":"17924629579804316786455515989238352689210911545477836576430679697715946894553", "price":"0.66", "size":"125.76", "side":"SELL", "hash":"dd91ac234af38e953aec91f4b21a9652eac2926a", "best_bid":"0.59", "best_ask":"0.6"}], "timestamp":"1784449239262", "event_type":"price_change"}
{"market":"0xab772601f501b265bfe8982eb61d5347ef9945de314bfdf4ac0189c288ffb0b3", "price_changes":[{"asset_id":"17924629579804316786455515989238352689210911545477836576430679697715946894553", "price":"0.01", "size":"13074.51", "side":"BUY", "hash":"8662a5c8019858fe7ceee102f4f086f4e1e18a87", "best_bid":"0.59", "best_ask":"0.6"}, {"asset_id":"12935926064588426924078449947177910958215776269411501731627440228801766632772", "price":"0.99", "size":"13074.51", "side":"SELL", "hash":"28f2a7709b42feb8ca2627582f6885ecd76f597f", "best_bid":"0.4", "best_ask":"0.41"}], "timestamp":"1784449239264", "event_type":"price_change"}
{"market":"0xab772601f501b265bfe8982eb61d5347ef9945de314bfdf4ac0189c288ffb0b3", "price_changes":[{"asset_id":"17924629579804316786455515989238352689210911545477836576430679697715946894553", "price":"0.03", "size":"2255.95", "side":"BUY", "hash":"1879c60b25088c088e302fb3582d50d1461f6523", "best_bid":"0.59", "best_ask":"0.6"}, {"asset_id":"12935926064588426924078449947177910958215776269411501731627440228801766632772", "price":"0.97", "size":"2255.95", "side":"SELL", "hash":"df21f94bc787d42f22ebd97f65deb3a3f6cdbec8", "best_bid":"0.4", "best_ask":"0.41"}], "timestamp":"1784449239280", "event_type":"price_change"}
{"market":"0xab772601f501b265bfe8982eb61d5347ef9945de314bfdf4ac0189c288ffb0b3", "price_changes":[{"asset_id":"12935926064588426924078449947177910958215776269411501731627440228801766632772", "price":"0.14", "size":"188.4", "side":"BUY", "hash":"959ccd0d29616f460d67f0d269cc1ee49c8548f2", "best_bid":"0.4", "best_ask":"0.41"}, {"asset_id":"17924629579804316786455515989238352689210911545477836576430679697715946894553", "price":"0.86", "size":"188.4", "side":"SELL", "hash":"1186a656f9797cb5e728ba6ad8cbf0f72f23043d", "best_bid":"0.59", "best_ask":"0.6"}], "timestamp":"1784449239281", "event_type":"price_change"}
{"market":"0xab772601f501b265bfe8982eb61d5347ef9945de314bfdf4ac0189c288ffb0b3", "price_changes":[{"asset_id":"17924629579804316786455515989238352689210911545477836576430679697715946894553", "price":"0.58", "size":"126.82", "side":"BUY", "hash":"381f005b1a8d13e70c01e09da0b8dd7ea7ff8eba", "best_bid":"0.59", "best_ask":"0.6"}, {"asset_id":"12935926064588426924078449947177910958215776269411501731627440228801766632772", "price":"0.42", "size":"126.82", "side":"SELL", "hash":"bdbf2e11375b2dce3207531e9450b149a28743ec", "best_bid":"0.4", "best_ask":"0.41"}], "timestamp":"1784449239282", "event_type":"price_change"}
{"market":"0xab772601f501b265bfe8982eb61d5347ef9945de314bfdf4ac0189c288ffb0b3", "price_changes":[{"asset_id":"12935926064588426924078449947177910958215776269411501731627440228801766632772", "price":"0.39", "size":"193.88", "side":"BUY", "hash":"4e3cb874a35e62ca9171a9e4c353d2147f8b480b", "best_bid":"0.4", "best_ask":"0.41"}, {"asset_id":"17924629579804316786455515989238352689210911545477836576430679697715946894553", "price":"0.61", "size":"193.88", "side":"SELL", "hash":"ada987799b6cda89340837d044017b29fdbbb5e7", "best_bid":"0.59", "best_ask":"0.6"}], "timestamp":"1784449239287", "event_type":"price_change"}
{"market":"0xab772601f501b265bfe8982eb61d5347ef9945de314bfdf4ac0189c288ffb0b3", "price_changes":[{"asset_id":"17924629579804316786455515989238352689210911545477836576430679697715946894553", "price":"0.01", "size":"13069.5", "side":"BUY", "hash":"6bfe1a354e0a48d1514f72b97ac26cc99058391a", "best_bid":"0.59", "best_ask":"0.6"}, {"asset_id":"12935926064588426924078449947177910958215776269411501731627440228801766632772", "price":"0.99", "size":"13069.5", "side":"SELL", "hash":"f63941f680234565bb453840e20f4ff1cec053d7", "best_bid":"0.4", "best_ask":"0.41"}], "timestamp":"1784449239288", "event_type":"price_change"}
{"market":"0xab772601f501b265bfe8982eb61d5347ef9945de314bfdf4ac0189c288ffb0b3", "price_changes":[{"asset_id":"17924629579804316786455515989238352689210911545477836576430679697715946894553", "price":"0.01", "size":"12969.5", "side":"BUY", "hash":"ef9ae72b3132bdf7ef1fb812e0e6de0d381328ff", "best_bid":"0.59", "best_ask":"0.6"}, {"asset_id":"12935926064588426924078449947177910958215776269411501731627440228801766632772", "price":"0.99", "size":"12969.5", "side":"SELL", "hash":"d41bd5571960d9a84e2575edf1e17763cac380d6", "best_bid":"0.4", "best_ask":"0.41"}], "timestamp":"1784449239291", "event_type":"price_change"}
{"market":"0xab772601f501b265bfe8982eb61d5347ef9945de314bfdf4ac0189c288ffb0b3", "price_changes":[{"asset_id":"17924629579804316786455515989238352689210911545477836576430679697715946894553", "price":"0.01", "size":"12964.5", "side":"BUY", "hash":"784aaa91491ba53fa90085750353016bfb170f2d", "best_bid":"0.59", "best_ask":"0.6"}, {"asset_id":"12935926064588426924078449947177910958215776269411501731627440228801766632772", "price":"0.99", "size":"12964.5", "side":"SELL", "hash":"24715889e1ccaa4f38574aea5d1644a3efcc3ef1", "best_bid":"0.4", "best_ask":"0.41"}], "timestamp":"1784449239292", "event_type":"price_change"}
{"market":"0xab772601f501b265bfe8982eb61d5347ef9945de314bfdf4ac0189c288ffb0b3", "price_changes":[{"asset_id":"12935926064588426924078449947177910958215776269411501731627440228801766632772", "price":"0.17", "size":"189.01", "side":"BUY", "hash":"e1dc49a2cc0c2779074ba98073714ca9aa31af02", "best_bid":"0.4", "best_ask":"0.41"}, {"asset_id":"17924629579804316786455515989238352689210911545477836576430679697715946894553", "price":"0.83", "size":"189.01", "side":"SELL", "hash":"d14971541038c9c6ecce7e3e52f3c3462c0dfc49", "best_bid":"0.59", "best_ask":"0.6"}], "timestamp":"1784449239294", "event_type":"price_change"}
{"market":"0xab772601f501b265bfe8982eb61d5347ef9945de314bfdf4ac0189c288ffb0b3", "price_changes":[{"asset_id":"12935926064588426924078449947177910958215776269411501731627440228801766632772", "price":"0.17", "size":"160.85", "side":"BUY", "hash":"6249c15f76d098be3bfebdc6585c02c90d35c3c3", "best_bid":"0.4", "best_ask":"0.41"}, {"asset_id":"17924629579804316786455515989238352689210911545477836576430679697715946894553", "price":"0.83", "size":"160.85", "side":"SELL", "hash":"cd0d51b3092ce7ade00fa4038a63ca223562e1d8", "best_bid":"0.59", "best_ask":"0.6"}], "timestamp":"1784449239294", "event_type":"price_change"}
{"market":"0xab772601f501b265bfe8982eb61d5347ef9945de314bfdf4ac0189c288ffb0b3", "price_changes":[{"asset_id":"12935926064588426924078449947177910958215776269411501731627440228801766632772", "price":"0.17", "size":"132.69", "side":"BUY", "hash":"9b460e0b83b124d2263c6746d7dc88911f00f24d", "best_bid":"0.4", "best_ask":"0.41"}, {"asset_id":"17924629579804316786455515989238352689210911545477836576430679697715946894553", "price":"0.83", "size":"132.69", "side":"SELL", "hash":"5a0f5c9225a6173cde127e3a66c15cfcdb73ac87", "best_bid":"0.59", "best_ask":"0.6"}], "timestamp":"1784449239295", "event_type":"price_change"}
{"market":"0xab772601f501b265bfe8982eb61d5347ef9945de314bfdf4ac0189c288ffb0b3", "price_changes":[{"asset_id":"17924629579804316786455515989238352689210911545477836576430679697715946894553", "price":"0.59", "size":"136.47", "side":"BUY", "hash":"44a39895e8bd61cbe27536c5ae4b96a6ddf9fbb4", "best_bid":"0.59", "best_ask":"0.6"}, {"asset_id":"12935926064588426924078449947177910958215776269411501731627440228801766632772", "price":"0.41", "size":"136.47", "side":"SELL", "hash":"e03af6da5ddc434fd77ebe1069ee444a061a0fa5", "best_bid":"0.4", "best_ask":"0.41"}], "timestamp":"1784449239296", "event_type":"price_change"}
{"market":"0xab772601f501b265bfe8982eb61d5347ef9945de314bfdf4ac0189c288ffb0b3", "price_changes":[{"asset_id":"17924629579804316786455515989238352689210911545477836576430679697715946894553", "price":"0.01", "size":"12970.5", "side":"BUY", "hash":"3fcb7df7f5e669aae73bbb7216b99639e11556f4", "best_bid":"0.59", "best_ask":"0.6"}, {"asset_id":"12935926064588426924078449947177910958215776269411501731627440228801766632772", "price":"0.99", "size":"12970.5", "side":"SELL", "hash":"e2a3096ab9c2cfbb120654e1f7b838e59dc07f63", "best_bid":"0.4", "best_ask":"0.41"}], "timestamp":"1784449239300", "event_type":"price_change"}
{"market":"0xab772601f501b265bfe8982eb61d5347ef9945de314bfdf4ac0189c288ffb0b3", "price_changes":[{"asset_id":"12935926064588426924078449947177910958215776269411501731627440228801766632772", "price":"0.34", "size":"150.76", "side":"BUY", "hash":"27e67cc44d9dac5c01a6cc76549efa44c209183b", "best_bid":"0.4", "best_ask":"0.41"}, {"asset_id":"17924629579804316786455515989238352689210911545477836576430679697715946894553", "price":"0.66", "size":"150.76", "side":"SELL", "hash":"f8623cc625b16233589e8fd6ce457a962b676716", "best_bid":"0.59", "best_ask":"0.6"}], "timestamp":"1784449239306", "event_type":"price_change"}
{"market":"0xab772601f501b265bfe8982eb61d5347ef9945de314bfdf4ac0189c288ffb0b3", "price_changes":[{"asset_id":"17924629579804316786455515989238352689210911545477836576430679697715946894553", "price":"0.32", "size":"175.64", "side":"BUY", "hash":"9da8ce9a44460ff5f160a990ab7b112fc8e5f6fe", "best_bid":"0.59", "best_ask":"0.6"}, {"asset_id":"12935926064588426924078449947177910958215776269411501731627440228801766632772", "price":"0.68", "size":"175.64", "side":"SELL", "hash":"f97fac2268d5b54984bb940fde1976c10b1fffad", "best_bid":"0.4", "best_ask":"0.41"}], "timestamp":"1784449239307", "event_type":"price_change"}
{"market":"0xab772601f501b265bfe8982eb61d5347ef9945de314bfdf4ac0189c288ffb0b3", "price_changes":[{"asset_id":"17924629579804316786455515989238352689210911545477836576430679697715946894553", "price":"0.59", "size":"141.47", "side":"BUY", "hash":"9e8a443a1b7d0d4616fcf2bb462ed9661f8fc9f6", "best_bid":"0.59", "best_ask":"0.6"}, {"asset_id":"12935926064588426924078449947177910958215776269411501731627440228801766632772", "price":"0.41", "size":"141.47", "side":"SELL", "hash":"d9bf73277216246d3ec6ca2e82c98317082bf9a7", "best_bid":"0.4", "best_ask":"0.41"}], "timestamp":"1784449239317", "event_type":"price_change"}
{"market":"0xab772601f501b265bfe8982eb61d5347ef9945de314bfdf4ac0189c288ffb0b3", "price_changes":[{"asset_id":"12935926064588426924078449947177910958215776269411501731627440228801766632772", "price":"0.38", "size":"108.88", "side":"BUY", "hash":"7d182ad07a5d584d1ca753dce4203cc07624d9aa", "best_bid":"0.4", "best_ask":"0.41"}, {"asset_id":"17924629579804316786455515989238352689210911545477836576430679697715946894553", "price":"0.62", "size":"108.88", "side":"SELL", "hash":"e6e455b0b79f73f52b09d7545ffc1bf37db9082a", "best_bid":"0.59", "best_ask":"0.6"}], "timestamp":"1784449239320", "event_type":"price_change"}
{"market":"0xab772601f501b265bfe8982eb61d5347ef9945de314bfdf4ac0189c288ffb0b3", "price_changes":[{"asset_id":"12935926064588426924078449947177910958215776269411501731627440228801766632772", "price":"0.4", "size":"106.06", "side":"BUY", "hash":"18311f22b0a458b7959cd4db384cb31e6a141775", "best_bid":"0.4", "best_ask":"0.41"}, {"asset_id":"17924629579804316786455515989238352689210911545477836576430679697715946894553", "price":"0.6", "size":"106.06", "side":"SELL", "hash":"8dbbcef40690d8a35fc7109bb0241c43423491f5", "best_bid":"0.59", "best_ask":"0.6"}], "timestamp":"1784449239321", "event_type":"price_change"}
{"market":"0xab772601f501b265bfe8982eb61d5347ef9945de314bfdf4ac0189c288ffb0b3", "price_changes":[{"asset_id":"17924629579804316786455515989238352689210911545477836576430679697715946894553", "price":"0.01", "size":"12965.5", "side":"BUY", "hash":"ffed3647524507ef3425eb7463c7731e8a30915c", "best_bid":"0.59", "best_ask":"0.6"}, {"asset_id":"12935926064588426924078449947177910958215776269411501731627440228801766632772", "price":"0.99", "size":"12965.5", "side":"SELL", "hash":"1fff599b270bbe5bb300d31de22f9f337a2f2af1", "best_bid":"0.4", "best_ask":"0.41"}], "timestamp":"1784449239323", "event_type":"price_change"}
{"market":"0xab772601f501b265bfe8982eb61d5347ef9945de314bfdf4ac0189c288ffb0b3", "price_changes":[{"asset_id":"17924629579804316786455515989238352689210911545477836576430679697715946894553", "price":"0.59", "size":"276.56", "side":"BUY", "hash":"bcdd9847b76d2392f0d6e95d09dc14428317dc26", "best_bid":"0.59", "best_ask":"0.6"}, {"asset_id":"12935926064588426924078449947177910958215776269411501731627440228801766632772", "price":"0.41", "size":"276.56", "side":"SELL", "hash":"80b8e3eb35bf08341c1fd86052e2cca68c625c0b", "best_bid":"0.4", "best_ask":"0.41"}], "timestamp":"1784449239324", "event_type":"price_change"}
{"market":"0xab772601f501b265bfe8982eb61d5347ef9945de314bfdf4ac0189c288ffb0b3", "price_changes":[{"asset_id":"12935926064588426924078449947177910958215776269411501731627440228801766632772", "price":"0.35", "size":"122.81", "side":"BUY", "hash":"97af7880d05d658bc156fda6e0390c0341b86f4b", "best_bid":"0.4", "best_ask":"0.41"}, {"asset_id":"17924629579804316786455515989238352689210911545477836576430679697715946894553", "price":"0.65", "size":"122.81", "side":"SELL", "hash":"05646291943284dc049770fffbba321147efc502", "best_bid":"0.59", "best_ask":"0.6"}], "timestamp":"1784449239324", "event_type":"price_change"}
{"market":"0xab772601f501b265bfe8982eb61d5347ef9945de314bfdf4ac0189c288ffb0b3", "price_changes":[{"asset_id":"12935926064588426924078449947177910958215776269411501731627440228801766632772", "price":"0.18", "size":"188.86", "side":"BUY", "hash":"fd7e3ceff0c2db2bcea7e35c7cda7598e39f0de1", "best_bid":"0.4", "best_ask":"0.41"}, {"asset_id":"17924629579804316786455515989238352689210911545477836576430679697715946894553", "price":"0.82", "size":"188.86", "side":"SELL", "hash":"ac64e3c7725f5b15d41dec4f4e7a12bc3b5f7a4a", "best_bid":"0.59", "best_ask":"0.6"}], "timestamp":"1784449239327", "event_type":"price_change"}
{"market":"0xab772601f501b265bfe8982eb61d5347ef9945de314bfdf4ac0189c288ffb0b3", "price_changes":[{"asset_id":"12935926064588426924078449947177910958215776269411501731627440228801766632772", "price":"0.39", "size":"168.88", "side":"BUY", "hash":"baa5b1b3248eb9d666dc59bbd09630113c08f1d6", "best_bid":"0.4", "best_ask":"0.41"}, {"asset_id":"17924629579804316786455515989238352689210911545477836576430679697715946894553", "price":"0.61", "size":"168.88", "side":"SELL", "hash":"b3baf61dc8af6bf185302a6bf0ff23dd0d0d36c4", "best_bid":"0.59", "best_ask":"0.6"}], "timestamp":"1784449239329", "event_type":"price_change"}
{"market":"0xab772601f501b265bfe8982eb61d5347ef9945de314bfdf4ac0189c288ffb0b3", "price_changes":[{"asset_id":"12935926064588426924078449947177910958215776269411501731627440228801766632772", "price":"0.35", "size":"147.81", "side":"BUY", "hash":"cb4a8a3e0507efa2386850b25fe34c486a671a98", "best_bid":"0.4", "best_ask":"0.41"}, {"asset_id":"17924629579804316786455515989238352689210911545477836576430679697715946894553", "price":"0.65", "size":"147.81", "side":"SELL", "hash":"b3da0bbd8bafd3b5f5fa1808ce48897ff64867c8", "best_bid":"0.59", "best_ask":"0.6"}], "timestamp":"1784449239332", "event_type":"price_change"}
{"market":"0xab772601f501b265bfe8982eb61d5347ef9945de314bfdf4ac0189c288ffb0b3", "price_changes":[{"asset_id":"12935926064588426924078449947177910958215776269411501731627440228801766632772", "price":"0.35", "size":"122.81", "side":"BUY", "hash":"0f2b39ef977c963ee85fd0b16af90ae6e545ea3e", "best_bid":"0.4", "best_ask":"0.41"}, {"asset_id":"17924629579804316786455515989238352689210911545477836576430679697715946894553", "price":"0.65", "size":"122.81", "side":"SELL", "hash":"eddae03a2b7c0669184be84713ffa5cc0130b6aa", "best_bid":"0.59", "best_ask":"0.6"}], "timestamp":"1784449239333", "event_type":"price_change"}
{"market":"0xab772601f501b265bfe8982eb61d5347ef9945de314bfdf4ac0189c288ffb0b3", "price_changes":[{"asset_id":"12935926064588426924078449947177910958215776269411501731627440228801766632772", "price":"0.34", "size":"125.76", "side":"BUY", "hash":"c6b1894aba09d03118c710b7448cc3a4589fba82", "best_bid":"0.4", "best_ask":"0.41"}, {"asset_id":"17924629579804316786455515989238352689210911545477836576430679697715946894553", "price":"0.66", "size":"125.76", "side":"SELL", "hash":"88689ca6ebd78bfb23c0587c099d1185c0f2bc3e", "best_bid":"0.59", "best_ask":"0.6"}], "timestamp":"1784449239333", "event_type":"price_change"}
{"market":"0xab772601f501b265bfe8982eb61d5347ef9945de314bfdf4ac0189c288ffb0b3", "price_changes":[{"asset_id":"12935926064588426924078449947177910958215776269411501731627440228801766632772", "price":"0.4", "size":"131.06", "side":"BUY", "hash":"0b499ce857fe69da64f2f36a6dccc84ba7fd2073", "best_bid":"0.4", "best_ask":"0.41"}, {"asset_id":"17924629579804316786455515989238352689210911545477836576430679697715946894553", "price":"0.6", "size":"131.06", "side":"SELL", "hash":"5003a5b40482bc319bc3341ae0a8e2e23b22f4d3", "best_bid":"0.59", "best_ask":"0.6"}], "timestamp":"1784449239333", "event_type":"price_change"}
{"market":"0xab772601f501b265bfe8982eb61d5347ef9945de314bfdf4ac0189c288ffb0b3", "price_changes":[{"asset_id":"17924629579804316786455515989238352689210911545477836576430679697715946894553", "price":"0.03", "size":"2250.95", "side":"BUY", "hash":"9e596ae76526371681d94ecf5b1aad0046871f49", "best_bid":"0.59", "best_ask":"0.6"}, {"asset_id":"12935926064588426924078449947177910958215776269411501731627440228801766632772", "price":"0.97", "size":"2250.95", "side":"SELL", "hash":"551e35edc9742bf76b42e497edb9885f55e035e7", "best_bid":"0.4", "best_ask":"0.41"}], "timestamp":"1784449239334", "event_type":"price_change"}
{"market":"0xab772601f501b265bfe8982eb61d5347ef9945de314bfdf4ac0189c288ffb0b3", "price_changes":[{"asset_id":"17924629579804316786455515989238352689210911545477836576430679697715946894553", "price":"0.01", "size":"13065.5", "side":"BUY", "hash":"524efe61bca26349a86e5ca06027f57d4035283d", "best_bid":"0.59", "best_ask":"0.6"}, {"asset_id":"12935926064588426924078449947177910958215776269411501731627440228801766632772", "price":"0.99", "size":"13065.5", "side":"SELL", "hash":"f0c209f4affd683862258fb62d1d19d342d6c69b", "best_bid":"0.4", "best_ask":"0.41"}], "timestamp":"1784449239336", "event_type":"price_change"}
{"market":"0xab772601f501b265bfe8982eb61d5347ef9945de314bfdf4ac0189c288ffb0b3", "price_changes":[{"asset_id":"12935926064588426924078449947177910958215776269411501731627440228801766632772", "price":"0.4", "size":"106.06", "side":"BUY", "hash":"444f4380a4f1cb4603d288b6ccae7584fc16c2f3", "best_bid":"0.4", "best_ask":"0.41"}, {"asset_id":"17924629579804316786455515989238352689210911545477836576430679697715946894553", "price":"0.6", "size":"106.06", "side":"SELL", "hash":"1bcc39524efc96857509f5ab60cb592f1c4c118e", "best_bid":"0.59", "best_ask":"0.6"}], "timestamp":"1784449239337", "event_type":"price_change"}
{"market":"0xab772601f501b265bfe8982eb61d5347ef9945de314bfdf4ac0189c288ffb0b3", "price_changes":[{"asset_id":"17924629579804316786455515989238352689210911545477836576430679697715946894553", "price":"0.01", "size":"13059.5", "side":"BUY", "hash":"47f8d6527c8bdfb600a8d51ddca6da3feeb7ce46", "best_bid":"0.59", "best_ask":"0.6"}, {"asset_id":"12935926064588426924078449947177910958215776269411501731627440228801766632772", "price":"0.99", "size":"13059.5", "side":"SELL", "hash":"f661733dd64497cfb2cf1bffe9c186cf54bd9157", "best_bid":"0.4", "best_ask":"0.41"}], "timestamp":"1784449239338", "event_type":"price_change"}
