[{"market":"0xab772601f501b265bfe8982eb61d5347ef9945de314bfdf4ac0189c288ffb0b3","asset_id":"12935926064588426924078449947177910958215776269411501731627440228801766632772","timestamp":"1784449237208","hash":"8e1479dc9676c70eb8ed19197d4f640c57aa308c","bids":[{"price":"0.01","size":"14884.14"},{"price":"0.02","size":"3964.52"},{"price":"0.03","size":"2179.29"},{"price":"0.04","size":"1215.1"},{"price":"0.05","size":"1757.19"},{"price":"0.06","size":"1137.02"},{"price":"0.07","size":"968.49"},{"price":"0.08","size":"1234.38"},{"price":"0.09","size":"791.7"},{"price":"0.1","size":"461.2"},{"price":"0.11","size":"1502.1"},{"price":"0.12","size":"1102.45"},{"price":"0.13","size":"139.4"},{"price":"0.14","size":"281.8"},{"price":"0.15","size":"444.04"},{"price":"0.16","size":"147.1"},{"price":"0.17","size":"207.17"},{"price":"0.18","size":"150.7"},{"price":"0.19","size":"103.89"},{"price":"0.2","size":"246.2"},{"price":"0.21","size":"636.8"},{"price":"0.22","size":"135.5"},{"price":"0.23","size":"127.3"},{"price":"0.24","size":"193.92"},{"price":"0.25","size":"137.2"},{"price":"0.26","size":"134.3"},{"price":"0.27","size":"148.5"},{"price":"0.28","size":"146.77"},{"price":"0.29","size":"204.39"},{"price":"0.3","size":"200.41"},{"price":"0.31","size":"554.58"},{"price":"0.32","size":"228.39"},{"price":"0.33","size":"159.65"},{"price":"0.34","size":"410.46"},{"price":"0.35","size":"143.8"},{"price":"0.36","size":"241.77"},{"price":"0.37","size":"251.13"},{"price":"0.38","size":"207.98"}],"asks":[{"price":"0.99","size":"12959.5"},{"price":"0.98","size":"3885.25"},{"price":"0.97","size":"2250.95"},{"price":"0.96","size":"1270.1"},{"price":"0.95","size":"1768.6"},{"price":"0.94","size":"1124.35"},{"price":"0.93","size":"959.2"},{"price":"0.92","size":"1225.88"},{"price":"0.91","size":"796.7"},{"price":"0.9","size":"365.2"},{"price":"0.89","size":"1502.1"},{"price":"0.88","size":"195.05"},{"price":"0.87","size":"147.4"},{"price":"0.86","size":"161.8"},{"price":"0.85","size":"449.04"},{"price":"0.84","size":"127.1"},{"price":"0.83","size":"107.69"},{"price":"0.82","size":"125.7"},{"price":"0.81","size":"98.89"},{"price":"0.8","size":"201.2"},{"price":"0.79","size":"616.8"},{"price":"0.78","size":"982.3"},{"price":"0.77","size":"67.6"},{"price":"0.76","size":"103.73"},{"price":"0.75","size":"78.3"},{"price":"0.74","size":"76.8"},{"price":"0.73","size":"70.3"},{"price":"0.72","size":"79.87"},{"price":"0.71","size":"74.39"},{"price":"0.7","size":"83"},{"price":"0.69","size":"89.7"},{"price":"0.68","size":"160.64"},{"price":"0.67","size":"98.1"},{"price":"0.66","size":"77.8"},{"price":"0.65","size":"69.6"},{"price":"0.64","size":"79.39"},{"price":"0.63","size":"194.2"},{"price":"0.62","size":"85"},{"price":"0.61","size":"95.4"},{"price":"0.6","size":"122.94"},{"price":"0.59","size":"75.5"},{"price":"0.58","size":"86.02"},{"price":"0.57","size":"75.3"},{"price":"0.56","size":"64.2"},{"price":"0.55","size":"204.71"},{"price":"0.54","size":"102.1"},{"price":"0.53","size":"72.1"},{"price":"0.52","size":"83"},{"price":"0.51","size":"91"},{"price":"0.5","size":"85"},{"price":"0.49","size":"115.92"},{"price":"0.48","size":"235.09"},{"price":"0.47","size":"457.38"},{"price":"0.46","size":"123.85"},{"price":"0.45","size":"226.69"},{"price":"0.44","size":"163.99"},{"price":"0.43","size":"133"},{"price":"0.42","size":"176.82"},{"price":"0.41","size":"350.34"},{"price":"0.4","size":"111.7"},{"price":"0.39","size":"54.58"}],"tick_size":"0.01","event_type":"book","last_trade_price":"0.610"},{"market":"0xab772601f501b265bfe8982eb61d5347ef9945de314bfdf4ac0189c288ffb0b3","asset_id":"17924629579804316786455515989238352689210911545477836576430679697715946894553","timestamp":"1784449237208","hash":"a84f1574a741b17502b4662b1ae1593cb78f8ba7","bids":[{"price":"0.01","size":"12959.5"},{"price":"0.02","size":"3885.25"},{"price":"0.03","size":"2250.95"},{"price":"0.04","size":"1270.1"},{"price":"0.05","size":"1768.6"},{"price":"0.06","size":"1124.35"},{"price":"0.07","size":"959.2"},{"price":"0.08","size":"1225.88"},{"price":"0.09","size":"796.7"},{"price":"0.1","size":"365.2"},{"price":"0.11","size":"1502.1"},{"price":"0.12","size":"195.05"},{"price":"0.13","size":"147.4"},{"price":"0.14","size":"161.8"},{"price":"0.15","size":"449.04"},{"price":"0.16","size":"127.1"},{"price":"0.17","size":"107.69"},{"price":"0.18","size":"125.7"},{"price":"0.19","size":"98.89"},{"price":"0.2","size":"201.2"},{"price":"0.21","size":"616.8"},{"price":"0.22","size":"982.3"},{"price":"0.23","size":"67.6"},{"price":"0.24","size":"103.73"},{"price":"0.25","size":"78.3"},{"price":"0.26","size":"76.8"},{"price":"0.27","size":"70.3"},{"price":"0.28","size":"79.87"},{"price":"0.29","size":"74.39"},{"price":"0.3","size":"83"},{"price":"0.31","size":"89.7"},{"price":"0.32","size":"160.64"},{"price":"0.33","size":"98.1"},{"price":"0.34","size":"77.8"},{"price":"0.35","size":"69.6"},{"price":"0.36","size":"79.39"},{"price":"0.37","size":"194.2"},{"price":"0.38","size":"85"},{"price":"0.39","size":"95.4"},{"price":"0.4","size":"122.94"},{"price":"0.41","size":"75.5"},{"price":"0.42","size":"86.02"},{"price":"0.43","size":"75.3"},{"price":"0.44","size":"64.2"},{"price":"0.45","size":"204.71"},{"price":"0.46","size":"102.1"},{"price":"0.47","size":"72.1"},{"price":"0.48","size":"83"},{"price":"0.49","size":"91"},{"price":"0.5","size":"85"},{"price":"0.51","size":"115.92"},{"price":"0.52","size":"235.09"},{"price":"0.53","size":"457.38"},{"price":"0.54","size":"123.85"},{"price":"0.55","size":"226.69"},{"price":"0.56","size":"163.99"},{"price":"0.57","size":"133"},{"price":"0.58","size":"176.82"},{"price":"0.59","size":"350.34"},{"price":"0.6","size":"111.7"},{"price":"0.61","size":"54.58"}],"asks":[{"price":"0.99","size":"14884.14"},{"price":"0.98","size":"3964.52"},{"price":"0.97","size":"2179.29"},{"price":"0.96","size":"1215.1"},{"price":"0.95","size":"1757.19"},{"price":"0.94","size":"1137.02"},{"price":"0.93","size":"968.49"},{"price":"0.92","size":"1234.38"},{"price":"0.91","size":"791.7"},{"price":"0.9","size":"461.2"},{"price":"0.89","size":"1502.1"},{"price":"0.88","size":"1102.45"},{"price":"0.87","size":"139.4"},{"price":"0.86","size":"281.8"},{"price":"0.85","size":"444.04"},{"price":"0.84","size":"147.1"},{"price":"0.83","size":"207.17"},{"price":"0.82","size":"150.7"},{"price":"0.81","size":"103.89"},{"price":"0.8","size":"246.2"},{"price":"0.79","size":"636.8"},{"price":"0.78","size":"135.5"},{"price":"0.77","size":"127.3"},{"price":"0.76","size":"193.92"},{"price":"0.75","size":"137.2"},{"price":"0.74","size":"134.3"},{"price":"0.73","size":"148.5"},{"price":"0.72","size":"146.77"},{"price":"0.71","size":"204.39"},{"price":"0.7","size":"200.41"},{"price":"0.69","size":"554.58"},{"price":"0.68","size":"228.39"},{"price":"0.67","size":"159.65"},{"price":"0.66","size":"410.46"},{"price":"0.65","size":"143.8"},{"price":"0.64","size":"241.77"},{"price":"0.63","size":"251.13"},{"price":"0.62","size":"207.98"}],"tick_size":"0.01","event_type":"book","last_trade_price":"0.610"}]

{"market":"0xab772601f501b265bfe8982eb61d5347ef9945de314bfdf4ac0189c288ffb0b3", "price_changes":[{"asset_id":"17924629579804316786455515989238352689210911545477836576430679697715946894553", "price":"0.61", "size":"54.58", "side":"BUY", "hash":"a84f1574a741b17502b4662b1ae1593cb78f8ba7", "best_bid":"0.61", "best_ask":"0.62"}, {"asset_id":"12935926064588426924078449947177910958215776269411501731627440228801766632772", "price":"0.39", "size":"54.58", "side":"SELL", "hash":"8e1479dc9676c70eb8ed19197d4f640c57aa308c", "best_bid":"0.38", "best_ask":"0.39"}], "timestamp":"1784449237208", "event_type":"price_change"}
{"market":"0xab772601f501b265bfe8982eb61d5347ef9945de314bfdf4ac0189c288ffb0b3", "asset_id":"12935926064588426924078449947177910958215776269411501731627440228801766632772", "bids":[{"price":"0.01", "size":"14884.14"}, {"price":"0.02", "size":"3964.52"}, {"price":"0.03", "size":"2179.29"}, {"price":"0.04", "size":"1215.1"}, {"price":"0.05", "size":"1757.19"}, {"price":"0.06", "size":"1137.02"}, {"price":"0.07", "size":"968.49"}, {"price":"0.08", "size":"1234.38"}, {"price":"0.09", "size":"791.7"}, {"price":"0.1", "size":"461.2"}, {"price":"0.11", "size":"1502.1"}, {"price":"0.12", "size":"1102.45"}, {"price":"0.13", "size":"139.4"}, {"price":"0.14", "size":"281.8"}, {"price":"0.15", "size":"444.04"}, {"price":"0.16", "size":"147.1"}, {"price":"0.17", "size":"207.17"}, {"price":"0.18", "size":"150.7"}, {"price":"0.19", "size":"103.89"}, {"price":"0.2", "size":"246.2"}, {"price":"0.21", "size":"636.8"}, {"price":"0.22", "size":"135.5"}, {"price":"0.23", "size":"127.3"}, {"price":"0.24", "size":"193.92"}, {"price":"0.25", "size":"137.2"}, {"price":"0.26", "size":"134.3"}, {"price":"0.27", "size":"148.5"}, {"price":"0.28", "size":"146.77"}, {"price":"0.29", "size":"204.39"}, {"price":"0.3", "size":"200.41"}, {"price":"0.31", "size":"554.58"}, {"price":"0.32", "size":"228.39"}, {"price":"0.33", "size":"159.65"}, {"price":"0.34", "size":"410.46"}, {"price":"0.35", "size":"143.8"}, {"price":"0.36", "size":"241.77"}, {"price":"0.37", "size":"251.13"}, {"price":"0.38", "size":"207.98"}], "asks":[{"price":"0.99", "size":"12959.5"}, {"price":"0.98", "size":"3885.25"}, {"price":"0.97", "size":"2250.95"}, {"price":"0.96", "size":"1270.1"}, {"price":"0.95", "size":"1768.6"}, {"price":"0.94", "size":"1124.35"}, {"price":"0.93", "size":"959.2"}, {"price":"0.92", "size":"1225.88"}, {"price":"0.91", "size":"796.7"}, {"price":"0.9", "size":"365.2"}, {"price":"0.89", "size":"1502.1"}, {"price":"0.88", "size":"195.05"}, {"price":"0.87", "size":"147.4"}, {"price":"0.86", "size":"161.8"}, {"price":"0.85", "size":"449.04"}, {"price":"0.84", "size":"127.1"}, {"price":"0.83", "size":"107.69"}, {"price":"0.82", "size":"125.7"}, {"price":"0.81", "size":"98.89"}, {"price":"0.8", "size":"201.2"}, {"price":"0.79", "size":"616.8"}, {"price":"0.78", "size":"982.3"}, {"price":"0.77", "size":"67.6"}, {"price":"0.76", "size":"103.73"}, {"price":"0.75", "size":"78.3"}, {"price":"0.74", "size":"76.8"}, {"price":"0.73", "size":"70.3"}, {"price":"0.72", "size":"79.87"}, {"price":"0.71", "size":"74.39"}, {"price":"0.7", "size":"83"}, {"price":"0.69", "size":"89.7"}, {"price":"0.68", "size":"160.64"}, {"price":"0.67", "size":"98.1"}, {"price":"0.66", "size":"77.8"}, {"price":"0.65", "size":"69.6"}, {"price":"0.64", "size":"79.39"}, {"price":"0.63", "size":"194.2"}, {"price":"0.62", "size":"85"}, {"price":"0.61", "size":"95.4"}, {"price":"0.6", "size":"122.94"}, {"price":"0.59", "size":"75.5"}, {"price":"0.58", "size":"86.02"}, {"price":"0.57", "size":"75.3"}, {"price":"0.56", "size":"64.2"}, {"price":"0.55", "size":"204.71"}, {"price":"0.54", "size":"102.1"}, {"price":"0.53", "size":"72.1"}, {"price":"0.52", "size":"83"}, {"price":"0.51", "size":"91"}, {"price":"0.5", "size":"85"}, {"price":"0.49", "size":"115.92"}, {"price":"0.48", "size":"235.09"}, {"price":"0.47", "size":"457.38"}, {"price":"0.46", "size":"123.85"}, {"price":"0.45", "size":"226.69"}, {"price":"0.44", "size":"163.99"}, {"price":"0.43", "size":"133"}, {"price":"0.42", "size":"176.82"}, {"price":"0.41", "size":"350.34"}, {"price":"0.4", "size":"111.7"}, {"price":"0.39", "size":"54.58"}], "hash":"8e1479dc9676c70eb8ed19197d4f640c57aa308c", "timestamp":"1784449237208", "event_type":"book"}
{"market":"0xab772601f501b265bfe8982eb61d5347ef9945de314bfdf4ac0189c288ffb0b3", "asset_id":"17924629579804316786455515989238352689210911545477836576430679697715946894553", "bids":[{"price":"0.01", "size":"12959.5"}, {"price":"0.02", "size":"3885.25"}, {"price":"0.03", "size":"2250.95"}, {"price":"0.04", "size":"1270.1"}, {"price":"0.05", "size":"1768.6"}, {"price":"0.06", "size":"1124.35"}, {"price":"0.07", "size":"959.2"}, {"price":"0.08", "size":"1225.88"}, {"price":"0.09", "size":"796.7"}, {"price":"0.1", "size":"365.2"}, {"price":"0.11", "size":"1502.1"}, {"price":"0.12", "size":"195.05"}, {"price":"0.13", "size":"147.4"}, {"price":"0.14", "size":"161.8"}, {"price":"0.15", "size":"449.04"}, {"price":"0.16", "size":"127.1"}, {"price":"0.17", "size":"107.69"}, {"price":"0.18", "size":"125.7"}, {"price":"0.19", "size":"98.89"}, {"price":"0.2", "size":"201.2"}, {"price":"0.21", "size":"616.8"}, {"price":"0.22", "size":"982.3"}, {"price":"0.23", "size":"67.6"}, {"price":"0.24", "size":"103.73"}, {"price":"0.25", "size":"78.3"}, {"price":"0.26", "size":"76.8"}, {"price":"0.27", "size":"70.3"}, {"price":"0.28", "size":"79.87"}, {"price":"0.29", "size":"74.39"}, {"price":"0.3", "size":"83"}, {"price":"0.31", "size":"89.7"}, {"price":"0.32", "size":"160.64"}, {"price":"0.33", "size":"98.1"}, {"price":"0.34", "size":"77.8"}, {"price":"0.35", "size":"69.6"}, {"price":"0.36", "size":"79.39"}, {"price":"0.37", "size":"194.2"}, {"price":"0.38", "size":"85"}, {"price":"0.39", "size":"95.4"}, {"price":"0.4", "size":"122.94"}, {"price":"0.41", "size":"75.5"}, {"price":"0.42", "size":"86.02"}, {"price":"0.43", "size":"75.3"}, {"price":"0.44", "size":"64.2"}, {"price":"0.45", "size":"204.71"}, {"price":"0.46", "size":"102.1"}, {"price":"0.47", "size":"72.1"}, {"price":"0.48", "size":"83"}, {"price":"0.49", "size":"91"}, {"price":"0.5", "size":"85"}, {"price":"0.51", "size":"115.92"}, {"price":"0.52", "size":"235.09"}, {"price":"0.53", "size":"457.38"}, {"price":"0.54", "size":"123.85"}, {"price":"0.55", "size":"226.69"}, {"price":"0.56", "size":"163.99"}, {"price":"0.57", "size":"133"}, {"price":"0.58", "size":"176.82"}, {"price":"0.59", "size":"350.34"}, {"price":"0.6", "size":"111.7"}, {"price":"0.61", "size":"54.58"}], "asks":[{"price":"0.99", "size":"14884.14"}, {"price":"0.98", "size":"3964.52"}, {"price":"0.97", "size":"2179.29"}, {"price":"0.96", "size":"1215.1"}, {"price":"0.95", "size":"1757.19"}, {"price":"0.94", "size":"1137.02"}, {"price":"0.93", "size":"968.49"}, {"price":"0.92", "size":"1234.38"}, {"price":"0.91", "size":"791.7"}, {"price":"0.9", "size":"461.2"}, {"price":"0.89", "size":"1502.1"}, {"price":"0.88", "size":"1102.45"}, {"price":"0.87", "size":"139.4"}, {"price":"0.86", "size":"281.8"}, {"price":"0.85", "size":"444.04"}, {"price":"0.84", "size":"147.1"}, {"price":"0.83", "size":"207.17"}, {"price":"0.82", "size":"150.7"}, {"price":"0.81", "size":"103.89"}, {"price":"0.8", "size":"246.2"}, {"price":"0.79", "size":"636.8"}, {"price":"0.78", "size":"135.5"}, {"price":"0.77", "size":"127.3"}, {"price":"0.76", "size":"193.92"}, {"price":"0.75", "size":"137.2"}, {"price":"0.74", "size":"134.3"}, {"price":"0.73", "size":"148.5"}, {"price":"0.72", "size":"146.77"}, {"price":"0.71", "size":"204.39"}, {"price":"0.7", "size":"200.41"}, {"price":"0.69", "size":"554.58"}, {"price":"0.68", "size":"228.39"}, {"price":"0.67", "size":"159.65"}, {"price":"0.66", "size":"410.46"}, {"price":"0.65", "size":"143.8"}, {"price":"0.64", "size":"241.77"}, {"price":"0.63", "size":"251.13"}, {"price":"0.62", "size":"207.98"}], "hash":"a84f1574a741b17502b4662b1ae1593cb78f8ba7", "timestamp":"1784449237208", "event_type":"book"}
{"market":"0xab772601f501b265bfe8982eb61d5347ef9945de314bfdf4ac0189c288ffb0b3", "price_changes":[{"asset_id":"12935926064588426924078449947177910958215776269411501731627440228801766632772", "price":"0.38", "size":"162.98", "side":"BUY", "hash":"603255b6125119f96209e59322fd770780d7e104", "best_bid":"0.38", "best_ask":"0.39"}, {"asset_id":"17924629579804316786455515989238352689210911545477836576430679697715946894553", "price":"0.62", "size":"162.98", "side":"SELL", "hash":"9389a404ebc7a8073a0d354f33b7c5c88b1605ec", "best_bid":"0.61", "best_ask":"0.62"}], "timestamp":"1784449237220", "event_type":"price_change"}
{"market":"0xab772601f501b265bfe8982eb61d5347ef9945de314bfdf4ac0189c288ffb0b3", "price_changes":[{"asset_id":"17924629579804316786455515989238352689210911545477836576430679697715946894553", "price":"0.01", "size":"13059.5", "side":"BUY", "hash":"4018dcc7ba053931c53c637bac59f4c6c5a8a031", "best_bid":"0.61", "best_ask":"0.62"}, {"asset_id":"12935926064588426924078449947177910958215776269411501731627440228801766632772", "price":"0.99", "size":"13059.5", "side":"SELL", "hash":"3e06fc25dd03f59e1c902e531cb1d70ef50eb4b0", "best_bid":"0.38", "best_ask":"0.39"}], "timestamp":"1784449237221", "event_type":"price_change"}
{"market":"0xab772601f501b265bfe8982eb61d5347ef9945de314bfdf4ac0189c288ffb0b3", "price_changes":[{"asset_id":"17924629579804316786455515989238352689210911545477836576430679697715946894553", "price":"0.51", "size":"90", "side":"BUY", "hash":"138e4bbd7fa2d8caa4b2623ea7674befdb2805fd", "best_bid":"0.61", "best_ask":"0.62"}, {"asset_id":"12935926064588426924078449947177910958215776269411501731627440228801766632772", "price":"0.49", "size":"90", "side":"SELL", "hash":"26196abd41c8723eeca10c3a48b45469f82c1fd9", "best_bid":"0.38", "best_ask":"0.39"}], "timestamp":"1784449237221", "event_type":"price_change"}
{"market":"0xab772601f501b265bfe8982eb61d5347ef9945de314bfdf4ac0189c288ffb0b3", "price_changes":[{"asset_id":"17924629579804316786455515989238352689210911545477836576430679697715946894553", "price":"0.01", "size":"13054.5", "side":"BUY", "hash":"649e877508126296c8a12d41b1111267cfa27dd6", "best_bid":"0.61", "best_ask":"0.62"}, {"asset_id":"12935926064588426924078449947177910958215776269411501731627440228801766632772", "price":"0.99", "size":"13054.5", "side":"SELL", "hash":"27645ad4cc09cda610fb632ec9c7bd4ebe72fe03", "best_bid":"0.38", "best_ask":"0.39"}], "timestamp":"1784449237221", "event_type":"price_change"}
{"market":"0xab772601f501b265bfe8982eb61d5347ef9945de314bfdf4ac0189c288ffb0b3", "price_changes":[{"asset_id":"17924629579804316786455515989238352689210911545477836576430679697715946894553", "price":"0.5", "size":"101", "side":"BUY", "hash":"8ff6dc697ebb983c323c84cfe5cb09143e54a8c0", "best_bid":"0.61", "best_ask":"0.62"}, {"asset_id":"12935926064588426924078449947177910958215776269411501731627440228801766632772", "price":"0.5", "size":"101", "side":"SELL", "hash":"08b19a818ab6ab7797d02766c8bebcb6591b79e2", "best_bid":"0.38", "best_ask":"0.39"}], "timestamp":"1784449237222", "event_type":"price_change"}
PONG
{"market":"0xab772601f501b265bfe8982eb61d5347ef9945de314bfdf4ac0189c288ffb0b3", "price_changes":[{"asset_id":"12935926064588426924078449947177910958215776269411501731627440228801766632772", "price":"0.38", "size":"154.4", "side":"BUY", "hash":"4c39885256360ec3fe4d941ac9d75f6ab7e013eb", "best_bid":"0.38", "best_ask":"0.39"}, {"asset_id":"17924629579804316786455515989238352689210911545477836576430679697715946894553", "price":"0.62", "size":"154.4", "side":"SELL", "hash":"d0b183f40618ce654a5407967fd7dbdb5b45cad4", "best_bid":"0.61", "best_ask":"0.62"}], "timestamp":"1784449237224", "event_type":"price_change"}
{"market":"0xab772601f501b265bfe8982eb61d5347ef9945de314bfdf4ac0189c288ffb0b3", "price_changes":[{"asset_id":"12935926064588426924078449947177910958215776269411501731627440228801766632772", "price":"0.01", "size":"14889.14", "side":"BUY", "hash":"654e93e686f614d49d5c45c29ed4ce02082e03bf", "best_bid":"0.38", "best_ask":"0.39"}, {"asset_id":"17924629579804316786455515989238352689210911545477836576430679697715946894553", "price":"0.99", "size":"14889.14", "side":"SELL", "hash":"4fd791cc602fd1ee6d1d3a064771c07c0a447b99", "best_bid":"0.61", "best_ask":"0.62"}], "timestamp":"1784449237224", "event_type":"price_change"}
{"market":"0xab772601f501b265bfe8982eb61d5347ef9945de314bfdf4ac0189c288ffb0b3", "price_changes":[{"asset_id":"17924629579804316786455515989238352689210911545477836576430679697715946894553", "price":"0.49", "size":"81", "side":"BUY", "hash":"85e1202abf63b5868fb4449d7bb48350930db884", "best_bid":"0.61", "best_ask":"0.62"}, {"asset_id":"12935926064588426924078449947177910958215776269411501731627440228801766632772", "price":"0.51", "size":"81", "side":"SELL", "hash":"718aee2c77eb530652ce25387e3b8e786d2410a4", "best_bid":"0.38", "best_ask":"0.39"}], "timestamp":"1784449237225", "event_type":"price_change"}
{"market":"0xab772601f501b265bfe8982eb61d5347ef9945de314bfdf4ac0189c288ffb0b3", "price_changes":[{"asset_id":"17924629579804316786455515989238352689210911545477836576430679697715946894553", "price":"0.01", "size":"13060.5", "side":"BUY", "hash":"6963058c9ccd57e98474c2e2ab3528505630d5c6", "best_bid":"0.61", "best_ask":"0.62"}, {"asset_id":"12935926064588426924078449947177910958215776269411501731627440228801766632772", "price":"0.99", "size":"13060.5", "side":"SELL", "hash":"2ea56d62f7cfbb41f08322ec21b24cd04b2d1b1a", "best_bid":"0.38", "best_ask":"0.39"}], "timestamp":"1784449237226", "event_type":"price_change"}
{"market":"0xab772601f501b265bfe8982eb61d5347ef9945de314bfdf4ac0189c288ffb0b3", "price_changes":[{"asset_id":"17924629579804316786455515989238352689210911545477836576430679697715946894553", "price":"0.61", "size":"59.58", "side":"BUY", "hash":"e123dc92074d3d7dd7743afda9bd8078794ba8fc", "best_bid":"0.61", "best_ask":"0.62"}, {"asset_id":"12935926064588426924078449947177910958215776269411501731627440228801766632772", "price":"0.39", "size":"59.58", "side":"SELL", "hash":"ce75221142e58dad17521654641ed1685776e993", "best_bid":"0.38", "best_ask":"0.39"}], "timestamp":"1784449237227", "event_type":"price_change"}
{"market":"0xab772601f501b265bfe8982eb61d5347ef9945de314bfdf4ac0189c288ffb0b3", "price_changes":[{"asset_id":"17924629579804316786455515989238352689210911545477836576430679697715946894553", "price":"0.14", "size":"183.4", "side":"BUY", "hash":"d5212fa610a54f1c5c9b553b76b2bb5b09e7e2ab", "best_bid":"0.61", "best_ask":"0.62"}, {"asset_id":"12935926064588426924078449947177910958215776269411501731627440228801766632772", "price":"0.86", "size":"183.4", "side":"SELL", "hash":"3d8e29acc11cc579d70f56b2e6568f75e261ee2d", "best_bid":"0.38", "best_ask":"0.39"}], "timestamp":"1784449237227", "event_type":"price_change"}
{"market":"0xab772601f501b265bfe8982eb61d5347ef9945de314bfdf4ac0189c288ffb0b3", "price_changes":[{"asset_id":"12935926064588426924078449947177910958215776269411501731627440228801766632772", "price":"0.37", "size":"231.13", "side":"BUY", "hash":"1a08b37b5c40d1f47bd6b8011057058cda1a8684", "best_bid":"0.38", "best_ask":"0.39"}, {"asset_id":"17924629579804316786455515989238352689210911545477836576430679697715946894553", "price":"0.63", "size":"231.13", "side":"SELL", "hash":"85d245ed2e82e0192d621f3c652f607e93163a73", "best_bid":"0.61", "best_ask":"0.62"}], "timestamp":"1784449237228", "event_type":"price_change"}
{"market":"0xab772601f501b265bfe8982eb61d5347ef9945de314bfdf4ac0189c288ffb0b3", "price_changes":[{"asset_id":"12935926064588426924078449947177910958215776269411501731627440228801766632772", "price":"0.36", "size":"221.77", "side":"BUY", "hash":"67f58add9550b9808049a3ff00588e6533eb4007", "best_bid":"0.38", "best_ask":"0.39"}, {"asset_id":"17924629579804316786455515989238352689210911545477836576430679697715946894553", "price":"0.64", "size":"221.77", "side":"SELL", "hash":"3d1df034e5ecdfe00dd83c5a12c3b0850d76f938", "best_bid":"0.61", "best_ask":"0.62"}], "timestamp":"1784449237228", "event_type":"price_change"}
{"market":"0xab772601f501b265bfe8982eb61d5347ef9945de314bfdf4ac0189c288ffb0b3", "price_changes":[{"asset_id":"12935926064588426924078449947177910958215776269411501731627440228801766632772", "price":"0.38", "size":"134.4", "side":"BUY", "hash":"f4329da496795a2dc617fd598436a703f5277880", "best_bid":"0.38", "best_ask":"0.39"}, {"asset_id":"17924629579804316786455515989238352689210911545477836576430679697715946894553", "price":"0.62", "size":"134.4", "side":"SELL", "hash":"1bae1d3706ed96a19e449faf54803c07d8e8a21d", "best_bid":"0.61", "best_ask":"0.62"}], "timestamp":"1784449237228", "event_type":"price_change"}
{"market":"0xab772601f501b265bfe8982eb61d5347ef9945de314bfdf4ac0189c288ffb0b3", "price_changes":[{"asset_id":"17924629579804316786455515989238352689210911545477836576430679697715946894553", "price":"0.58", "size":"156.82", "side":"BUY", "hash":"4234e6a09f71f80d5a81179054cfad31749ebb0b", "best_bid":"0.61", "best_ask":"0.62"}, {"asset_id":"12935926064588426924078449947177910958215776269411501731627440228801766632772", "price":"0.42", "size":"156.82", "side":"SELL", "hash":"f6e65dd1689ea3bd0239db384f943c523d1183f9", "best_bid":"0.38", "best_ask":"0.39"}], "timestamp":"1784449237228", "event_type":"price_change"}
{"market":"0xab772601f501b265bfe8982eb61d5347ef9945de314bfdf4ac0189c288ffb0b3", "price_changes":[{"asset_id":"12935926064588426924078449947177910958215776269411501731627440228801766632772", "price":"0.38", "size":"109.4", "side":"BUY", "hash":"96e58129f1ccd609fc371e2849b742dbbd65e311", "best_bid":"0.38", "best_ask":"0.39"}, {"asset_id":"17924629579804316786455515989238352689210911545477836576430679697715946894553", "price":"0.62", "size":"109.4", "side":"SELL", "hash":"93e11dace5488283e30f999c9a1460b40a74e0d0", "best_bid":"0.61", "best_ask":"0.62"}], "timestamp":"1784449237228", "event_type":"price_change"}
{"market":"0xab772601f501b265bfe8982eb61d5347ef9945de314bfdf4ac0189c288ffb0b3", "price_changes":[{"asset_id":"12935926064588426924078449947177910958215776269411501731627440228801766632772", "price":"0.29", "size":"216.99", "side":"BUY", "hash":"6e16d30d2f33f75de20ffdd04fdfd2b9ae61d535", "best_bid":"0.38", "best_ask":"0.39"}, {"asset_id":"17924629579804316786455515989238352689210911545477836576430679697715946894553", "price":"0.71", "size":"216.99", "side":"SELL", "hash":"02fc8412b77229322c7c9fc3e3249211df4b4e41", "best_bid":"0.61", "best_ask":"0.62"}], "timestamp":"1784449237229", "event_type":"price_change"}
{"market":"0xab772601f501b265bfe8982eb61d5347ef9945de314bfdf4ac0189c288ffb0b3", "price_changes":[{"asset_id":"17924629579804316786455515989238352689210911545477836576430679697715946894553", "price":"0.01", "size":"13065.5", "side":"BUY", "hash":"54e931086a4df6b228c0c3ba977d1bf357549189", "best_bid":"0.61", "best_ask":"0.62"}, {"asset_id":"12935926064588426924078449947177910958215776269411501731627440228801766632772", "price":"0.99", "size":"13065.5", "side":"SELL", "hash":"0a1a5bea03fe189dc1c20154c804f8beb990e347", "best_bid":"0.38", "best_ask":"0.39"}], "timestamp":"1784449237229", "event_type":"price_change"}
{"market":"0xab772601f501b265bfe8982eb61d5347ef9945de314bfdf4ac0189c288ffb0b3", "price_changes":[{"asset_id":"12935926064588426924078449947177910958215776269411501731627440228801766632772", "price":"0.38", "size":"104.4", "side":"BUY", "hash":"fc34929fa5629a2d4e7b2e686a329532f191eeba", "best_bid":"0.38", "best_ask":"0.39"}, {"asset_id":"17924629579804316786455515989238352689210911545477836576430679697715946894553", "price":"0.62", "size":"104.4", "side":"SELL", "hash":"d6d57290a2af6d6e1b93076fc71842847b3c6031", "best_bid":"0.61", "best_ask":"0.62"}], "timestamp":"1784449237230", "event_type":"price_change"}
{"market":"0xab772601f501b265bfe8982eb61d5347ef9945de314bfdf4ac0189c288ffb0b3", "price_changes":[{"asset_id":"12935926064588426924078449947177910958215776269411501731627440228801766632772", "price":"0.39", "size":"64.58", "side":"SELL", "hash":"5c8c5393499c66a3a13b2e81d7ece543eda099ff", "best_bid":"0.38", "best_ask":"0.39"}, {"asset_id":"17924629579804316786455515989238352689210911545477836576430679697715946894553", "price":"0.61", "size":"64.58", "side":"BUY", "hash":"a66a03ba0275e0f16a164dd3a01ddb2067bd1f0b", "best_bid":"0.61", "best_ask":"0.62"}], "timestamp":"1784449237230", "event_type":"price_change"}
{"market":"0xab772601f501b265bfe8982eb61d5347ef9945de314bfdf4ac0189c288ffb0b3", "price_changes":[{"asset_id":"17924629579804316786455515989238352689210911545477836576430679697715946894553", "price":"0.61", "size":"69.58", "side":"BUY", "hash":"7fd42d098277fac5d063da2ef97bbea127417262", "best_bid":"0.61", "best_ask":"0.62"}, {"asset_id":"12935926064588426924078449947177910958215776269411501731627440228801766632772", "price":"0.39", "size":"69.58", "side":"SELL", "hash":"a1238fd25b67de2511a297b428c22d3977db44c0", "best_bid":"0.38", "best_ask":"0.39"}], "timestamp":"1784449237231", "event_type":"price_change"}
{"market":"0xab772601f501b265bfe8982eb61d5347ef9945de314bfdf4ac0189c288ffb0b3", "price_changes":[{"asset_id":"12935926064588426924078449947177910958215776269411501731627440228801766632772", "price":"0.01", "size":"14894.14", "side":"BUY", "hash":"b6f86934c7f0eca3aa05e6c1b55d537fe0957695", "best_bid":"0.38", "best_ask":"0.39"}, {"asset_id":"17924629579804316786455515989238352689210911545477836576430679697715946894553", "price":"0.99", "size":"14894.14", "side":"SELL", "hash":"67e2b5df8f31da76cd3bb8619baf3640af119215", "best_bid":"0.61", "best_ask":"0.62"}], "timestamp":"1784449237231", "event_type":"price_change"}
{"market":"0xab772601f501b265bfe8982eb61d5347ef9945de314bfdf4ac0189c288ffb0b3", "price_changes":[{"asset_id":"17924629579804316786455515989238352689210911545477836576430679697715946894553", "price":"0.4", "size":"97.94", "side":"BUY", "hash":"090596d546875ade6683fc37e47fbe89d5595369", "best_bid":"0.61", "best_ask":"0.62"}, {"asset_id":"12935926064588426924078449947177910958215776269411501731627440228801766632772", "price":"0.6", "size":"97.94", "side":"SELL", "hash":"96de2c6bc7da90d186c2917c473968c77c56854d", "best_bid":"0.38", "best_ask":"0.39"}], "timestamp":"1784449237232", "event_type":"price_change"}
{"market":"0xab772601f501b265bfe8982eb61d5347ef9945de314bfdf4ac0189c288ffb0b3", "price_changes":[{"asset_id":"17924629579804316786455515989238352689210911545477836576430679697715946894553", "price":"0.41", "size":"100.5", "side":"BUY", "hash":"b58c3459af8deb2e713ef3ae565aae01e22cf86a", "best_bid":"0.61", "best_ask":"0.62"}, {"asset_id":"12935926064588426924078449947177910958215776269411501731627440228801766632772", "price":"0.59", "size":"100.5", "side":"SELL", "hash":"e43b7beeb9095b51e937d3d4780dbbf355cf9823", "best_bid":"0.38", "best_ask":"0.39"}], "timestamp":"1784449237233", "event_type":"price_change"}
{"market":"0xab772601f501b265bfe8982eb61d5347ef9945de314bfdf4ac0189c288ffb0b3", "price_changes":[{"asset_id":"17924629579804316786455515989238352689210911545477836576430679697715946894553", "price":"0.01", "size":"13070.5", "side":"BUY", "hash":"e647a83b7009191de9fe5910ccd6a855a3d2deb6", "best_bid":"0.61", "best_ask":"0.62"}, {"asset_id":"12935926064588426924078449947177910958215776269411501731627440228801766632772", "price":"0.99", "size":"13070.5", "side":"SELL", "hash":"33f4d45fa9a6a42b6fd25d916c9285e7bdbf6518", "best_bid":"0.38", "best_ask":"0.39"}], "timestamp":"1784449237233", "event_type":"price_change"}
{"market":"0xab772601f501b265bfe8982eb61d5347ef9945de314bfdf4ac0189c288ffb0b3", "price_changes":[{"asset_id":"12935926064588426924078449947177910958215776269411501731627440228801766632772", "price":"0.37", "size":"221.13", "side":"BUY", "hash":"f043013a2b9e951ed43eff0067aa9c4e542e35e5", "best_bid":"0.38", "best_ask":"0.39"}, {"asset_id":"17924629579804316786455515989238352689210911545477836576430679697715946894553", "price":"0.63", "size":"221.13", "side":"SELL", "hash":"86c9d4bb43ba77af8410d9bf4467debc58b8afe7", "best_bid":"0.61", "best_ask":"0.62"}], "timestamp":"1784449237233", "event_type":"price_change"}
{"market":"0xab772601f501b265bfe8982eb61d5347ef9945de314bfdf4ac0189c288ffb0b3", "price_changes":[{"asset_id":"12935926064588426924078449947177910958215776269411501731627440228801766632772", "price":"0.19", "size":"128.89", "side":"BUY", "hash":"3f115a00012e41e36b611bf9d06e1e2f11cff80a", "best_bid":"0.38", "best_ask":"0.39"}, {"asset_id":"17924629579804316786455515989238352689210911545477836576430679697715946894553", "price":"0.81", "size":"128.89", "side":"SELL", "hash":"4fbf3fab5ecbedd655e44f7fbfffc8eff9a65505", "best_bid":"0.61", "best_ask":"0.62"}], "timestamp":"1784449237234", "event_type":"price_change"}
{"market":"0xab772601f501b265bfe8982eb61d5347ef9945de314bfdf4ac0189c288ffb0b3", "price_changes":[{"asset_id":"17924629579804316786455515989238352689210911545477836576430679697715946894553", "price":"0.01", "size":"13075.5", "side":"BUY", "hash":"0f1a7c832f3abdbc12ade0526036f45f8d84654e", "best_bid":"0.61", "best_ask":"0.62"}, {"asset_id":"12935926064588426924078449947177910958215776269411501731627440228801766632772", "price":"0.99", "size":"13075.5", "side":"SELL", "hash":"ad3f30089c2ed1c0689b1a7da858a3eed9e91acd", "best_bid":"0.38", "best_ask":"0.39"}], "timestamp":"1784449237234", "event_type":"price_change"}
{"market":"0xab772601f501b265bfe8982eb61d5347ef9945de314bfdf4ac0189c288ffb0b3", "price_changes":[{"asset_id":"12935926064588426924078449947177910958215776269411501731627440228801766632772", "price":"0.01", "size":"14899.14", "side":"BUY", "hash":"ed036c8161f0618c98c08d7bd03fc4f2a9c48722", "best_bid":"0.38", "best_ask":"0.39"}, {"asset_id":"17924629579804316786455515989238352689210911545477836576430679697715946894553", "price":"0.99", "size":"14899.14", "side":"SELL", "hash":"088b3ab9f963e1389460750085a9e687dbe1e7bd", "best_bid":"0.61", "best_ask":"0.62"}], "timestamp":"1784449237235", "event_type":"price_change"}
{"market":"0xab772601f501b265bfe8982eb61d5347ef9945de314bfdf4ac0189c288ffb0b3", "price_changes":[{"asset_id":"12935926064588426924078449947177910958215776269411501731627440228801766632772", "price":"0.37", "size":"246.13", "side":"BUY", "hash":"a0bb97e24195e6fa4745e6cea0c868503de9068a", "best_bid":"0.38", "best_ask":"0.39"}, {"asset_id":"17924629579804316786455515989238352689210911545477836576430679697715946894553", "price":"0.63", "size":"246.13", "side":"SELL", "hash":"46c90291cc5356c89802cc5b05593bfb6272c6e4", "best_bid":"0.61", "best_ask":"0.62"}], "timestamp":"1784449237236", "event_type":"price_change"}
{"market":"0xab772601f501b265bfe8982eb61d5347ef9945de314bfdf4ac0189c288ffb0b3", "price_changes":[{"asset_id":"17924629579804316786455515989238352689210911545477836576430679697715946894553", "price":"0.01", "size":"13080.5", "side":"BUY", "hash":"869c1fcd536689b251121ad922f438234dda5082", "best_bid":"0.61", "best_ask":"0.62"}, {"asset_id":"12935926064588426924078449947177910958215776269411501731627440228801766632772", "price":"0.99", "size":"13080.5", "side":"SELL", "hash":"d15c3d2ae173224fe00b9dbb9eb7de77fc6e70d1", "best_bid":"0.38", "best_ask":"0.39"}], "timestamp":"1784449237237", "event_type":"price_change"}
{"market":"0xab772601f501b265bfe8982eb61d5347ef9945de314bfdf4ac0189c288ffb0b3", "price_changes":[{"asset_id":"17924629579804316786455515989238352689210911545477836576430679697715946894553", "price":"0.01", "size":"13085.5", "side":"BUY", "hash":"879925e07fbfd2ee5273343e1fe532edc1d06e68", "best_bid":"0.61", "best_ask":"0.62"}, {"asset_id":"12935926064588426924078449947177910958215776269411501731627440228801766632772", "price":"0.99", "size":"13085.5", "side":"SELL", "hash":"7f250cbb229333fdc2fd98c137a4dd0e0b0b695f", "best_bid":"0.38", "best_ask":"0.39"}], "timestamp":"1784449237237", "event_type":"price_change"}
{"market":"0xab772601f501b265bfe8982eb61d5347ef9945de314bfdf4ac0189c288ffb0b3", "price_changes":[{"asset_id":"17924629579804316786455515989238352689210911545477836576430679697715946894553", "price":"0.01", "size":"13080.5", "side":"BUY", "hash":"bcb598e4a3325e917ceb016d83f12da1d02fe42c", "best_bid":"0.61", "best_ask":"0.62"}, {"asset_id":"12935926064588426924078449947177910958215776269411501731627440228801766632772", "price":"0.99", "size":"13080.5", "side":"SELL", "hash":"7fe046855cbcebe871d5d7d935ae6a328be4e832", "best_bid":"0.38", "best_ask":"0.39"}], "timestamp":"1784449237238", "event_type":"price_change"}
{"market":"0xab772601f501b265bfe8982eb61d5347ef9945de314bfdf4ac0189c288ffb0b3", "price_changes":[{"asset_id":"12935926064588426924078449947177910958215776269411501731627440228801766632772", "price":"0.37", "size":"221.13", "side":"BUY", "hash":"5d3ca0864e3739b67e5ce172a478d6c3ef651bed", "best_bid":"0.38", "best_ask":"0.39"}, {"asset_id":"17924629579804316786455515989238352689210911545477836576430679697715946894553", "price":"0.63", "size":"221.13", "side":"SELL", "hash":"7438469bc94f4745fff91ab140c71b980ee1eee0", "best_bid":"0.61", "best_ask":"0.62"}], "timestamp":"1784449237241", "event_type":"price_change"}
{"market":"0xab772601f501b265bfe8982eb61d5347ef9945de314bfdf4ac0189c288ffb0b3", "price_changes":[{"asset_id":"17924629579804316786455515989238352689210911545477836576430679697715946894553", "price":"0.41", "size":"75.5", "side":"BUY", "hash":"5e4a3370cdecf90fcefc56a950bf8e95b8317682", "best_bid":"0.61", "best_ask":"0.62"}, {"asset_id":"12935926064588426924078449947177910958215776269411501731627440228801766632772", "price":"0.59", "size":"75.5", "side":"SELL", "hash":"6b5c94a125aad2a566dbc8e7adbbabd78203308c", "best_bid":"0.38", "best_ask":"0.39"}], "timestamp":"1784449237242", "event_type":"price_change"}
{"market":"0xab772601f501b265bfe8982eb61d5347ef9945de314bfdf4ac0189c288ffb0b3", "price_changes":[{"asset_id":"17924629579804316786455515989238352689210911545477836576430679697715946894553", "price":"0.01", "size":"13075.5", "side":"BUY", "hash":"8385c881ae517bf6aa9a126cd9dc3cf43ffce80e", "best_bid":"0.61", "best_ask":"0.62"}, {"asset_id":"12935926064588426924078449947177910958215776269411501731627440228801766632772", "price":"0.99", "size":"13075.5", "side":"SELL", "hash":"8fa5f83646ab105fb159fdd21b882df4f57b065e", "best_bid":"0.38", "best_ask":"0.39"}], "timestamp":"1784449237243", "event_type":"price_change"}
{"market":"0xab772601f501b265bfe8982eb61d5347ef9945de314bfdf4ac0189c288ffb0b3", "price_changes":[{"asset_id":"17924629579804316786455515989238352689210911545477836576430679697715946894553", "price":"0.57", "size":"138", "side":"BUY", "hash":"0f14fc80ca75dc3011d0f602fd5afedbf939350f", "best_bid":"0.61", "best_ask":"0.62"}, {"asset_id":"12935926064588426924078449947177910958215776269411501731627440228801766632772", "price":"0.43", "size":"138", "side":"SELL", "hash":"7973a55c4cc861e9bbfa4c2f4bd9125bf27bb76e", "best_bid":"0.38", "best_ask":"0.39"}], "timestamp":"1784449237245", "event_type":"price_change"}
{"market":"0xab772601f501b265bfe8982eb61d5347ef9945de314bfdf4ac0189c288ffb0b3", "price_changes":[{"asset_id":"17924629579804316786455515989238352689210911545477836576430679697715946894553", "price":"0.58", "size":"161.82", "side":"BUY", "hash":"4ae1162d870589b23e578b987da26820d3e4c6e9", "best_bid":"0.61", "best_ask":"0.62"}, {"asset_id":"12935926064588426924078449947177910958215776269411501731627440228801766632772", "price":"0.42", "size":"161.82", "side":"SELL", "hash":"d14c3b654c77d2ead554c615212831f67c327ada", "best_bid":"0.38", "best_ask":"0.39"}], "timestamp":"1784449237246", "event_type":"price_change"}
{"market":"0xab772601f501b265bfe8982eb61d5347ef9945de314bfdf4ac0189c288ffb0b3", "price_changes":[{"asset_id":"17924629579804316786455515989238352689210911545477836576430679697715946894553", "price":"0.01", "size":"13080.5", "side":"BUY", "hash":"5d2a552dff9704bfd81269a83c736ed1f222375a", "best_bid":"0.61", "best_ask":"0.62"}, {"asset_id":"12935926064588426924078449947177910958215776269411501731627440228801766632772", "price":"0.99", "size":"13080.5", "side":"SELL", "hash":"70fab7c06c72723b33482f5c5201dd585aefa6a6", "best_bid":"0.38", "best_ask":"0.39"}], "timestamp":"1784449237247", "event_type":"price_change"}
{"market":"0xab772601f501b265bfe8982eb61d5347ef9945de314bfdf4ac0189c288ffb0b3", "price_changes":[{"asset_id":"12935926064588426924078449947177910958215776269411501731627440228801766632772", "price":"0.37", "size":"216.13", "side":"BUY", "hash":"3965d196361280964befdee55cb16b7ba49e2081", "best_bid":"0.38", "best_ask":"0.39"}, {"asset_id":"17924629579804316786455515989238352689210911545477836576430679697715946894553", "price":"0.63", "size":"216.13", "side":"SELL", "hash":"f12ddce56214edf25d5a3168454e7bcf42f03540", "best_bid":"0.61", "best_ask":"0.62"}], "timestamp":"1784449237249", "event_type":"price_change"}
{"market":"0xab772601f501b265bfe8982eb61d5347ef9945de314bfdf4ac0189c288ffb0b3", "price_changes":[{"asset_id":"17924629579804316786455515989238352689210911545477836576430679697715946894553", "price":"0.01", "size":"13075.5", "side":"BUY", "hash":"43a27ab5eefe84565f97e11405ca4fd9114579b4", "best_bid":"0.61", "best_ask":"0.62"}, {"asset_id":"12935926064588426924078449947177910958215776269411501731627440228801766632772", "price":"0.99", "size":"13075.5", "side":"SELL", "hash":"14d88f0e8f5b30221ae3a5ff931713c751b705be", "best_bid":"0.38", "best_ask":"0.39"}], "timestamp":"1784449237249", "event_type":"price_change"}
{"market":"0xab772601f501b265bfe8982eb61d5347ef9945de314bfdf4ac0189c288ffb0b3", "price_changes":[{"asset_id":"17924629579804316786455515989238352689210911545477836576430679697715946894553", "price":"0.01", "size":"13080.5", "side":"BUY", "hash":"b7cd159e63ad89a33e34f0b677436ea1232aaefe", "best_bid":"0.61", "best_ask":"0.62"}, {"asset_id":"12935926064588426924078449947177910958215776269411501731627440228801766632772", "price":"0.99", "size":"13080.5", "side":"SELL", "hash":"0a7b8242d24bc59436d2c840e6f38a8ecc230771", "best_bid":"0.38", "best_ask":"0.39"}], "timestamp":"1784449237250", "event_type":"price_change"}
{"market":"0xab772601f501b265bfe8982eb61d5347ef9945de314bfdf4ac0189c288ffb0b3", "price_changes":[{"asset_id":"17924629579804316786455515989238352689210911545477836576430679697715946894553", "price":"0.01", "size":"13075.5", "side":"BUY", "hash":"5bb8635c4a1ed845388c1b4a8718e7d0530b526b", "best_bid":"0.61", "best_ask":"0.62"}, {"asset_id":"12935926064588426924078449947177910958215776269411501731627440228801766632772", "price":"0.99", "size":"13075.5", "side":"SELL", "hash":"70d236e9d60f7b77207e96beba24014010fcdfdc", "best_bid":"0.38", "best_ask":"0.39"}], "timestamp":"1784449237252", "event_type":"price_change"}
{"market":"0xab772601f501b265bfe8982eb61d5347ef9945de314bfdf4ac0189c288ffb0b3", "price_changes":[{"asset_id":"12935926064588426924078449947177910958215776269411501731627440228801766632772", "price":"0.19", "size":"103.89", "side":"BUY", "hash":"4ab089b2af7d695aeb00130d6659322835661119", "best_bid":"0.38", "best_ask":"0.39"}, {"asset_id":"17924629579804316786455515989238352689210911545477836576430679697715946894553", "price":"0.81", "size":"103.89", "side":"SELL", "hash":"78125c35e516d1d3c5e2190808e955aacd24a773", "best_bid":"0.61", "best_ask":"0.62"}], "timestamp":"1784449237252", "event_type":"price_change"}
{"market":"0xab772601f501b265bfe8982eb61d5347ef9945de314bfdf4ac0189c288ffb0b3", "price_changes":[{"asset_id":"17924629579804316786455515989238352689210911545477836576430679697715946894553", "price":"0.01", "size":"13070.5", "side":"BUY", "hash":"87afdaad0312133da8ee292b5be31dee38e79aba", "best_bid":"0.61", "best_ask":"0.62"}, {"asset_id":"12935926064588426924078449947177910958215776269411501731627440228801766632772", "price":"0.99", "size":"13070.5", "side":"SELL", "hash":"3d12c07d83670caaaa9822d691dad01613f4aaec", "best_bid":"0.38", "best_ask":"0.39"}], "timestamp":"1784449237255", "event_type":"price_change"}
{"market":"0xab772601f501b265bfe8982eb61d5347ef9945de314bfdf4ac0189c288ffb0b3", "price_changes":[{"asset_id":"17924629579804316786455515989238352689210911545477836576430679697715946894553", "price":"0.01", "size":"13170.5", "side":"BUY", "hash":"7d6813d616644ec51b5880dba7a33a9d53b89c8b", "best_bid":"0.61", "best_ask":"0.62"}, {"asset_id":"12935926064588426924078449947177910958215776269411501731627440228801766632772", "price":"0.99", "size":"13170.5", "side":"SELL", "hash":"1a57fd7f8d378170d8671c3700d9b201ef657bc2", "best_bid":"0.38", "best_ask":"0.39"}], "timestamp":"1784449237255", "event_type":"price_change"}
{"market":"0xab772601f501b265bfe8982eb61d5347ef9945de314bfdf4ac0189c288ffb0b3", "price_changes":[{"asset_id":"12935926064588426924078449947177910958215776269411501731627440228801766632772", "price":"0.38", "size":"129.4", "side":"BUY", "hash":"8ba39b096a8d68415f35b3c8892d3d97138ab14e", "best_bid":"0.38", "best_ask":"0.39"}, {"asset_id":"17924629579804316786455515989238352689210911545477836576430679697715946894553", "price":"0.62", "size":"129.4", "side":"SELL", "hash":"72ebe18c517a9a49b0c1209c3105725eef1437e0", "best_bid":"0.61", "best_ask":"0.62"}], "timestamp":"1784449237256", "event_type":"price_change"}
{"market":"0xab772601f501b265bfe8982eb61d5347ef9945de314bfdf4ac0189c288ffb0b3", "price_changes":[{"asset_id":"17924629579804316786455515989238352689210911545477836576430679697715946894553", "price":"0.01", "size":"13175.5", "side":"BUY", "hash":"52316ed8603bafac254fe747f37ecafa0c10aa69", "best_bid":"0.61", "best_ask":"0.62"}, {"asset_id":"12935926064588426924078449947177910958215776269411501731627440228801766632772", "price":"0.99", "size":"13175.5", "side":"SELL", "hash":"3b5ba60a57d486ad0d76b32e70796458c66188b5", "best_bid":"0.38", "best_ask":"0.39"}], "timestamp":"1784449237257", "event_type":"price_change"}
{"market":"0xab772601f501b265bfe8982eb61d5347ef9945de314bfdf4ac0189c288ffb0b3", "price_changes":[{"asset_id":"12935926064588426924078449947177910958215776269411501731627440228801766632772", "price":"0.38", "size":"104.4", "side":"BUY", "hash":"d308c5748eefeed1f11112f94a260892baf6c70b", "best_bid":"0.38", "best_ask":"0.39"}, {"asset_id":"17924629579804316786455515989238352689210911545477836576430679697715946894553", "price":"0.62", "size":"104.4", "side":"SELL", "hash":"daa58c36a2aa559443786c25074eff93283e9874", "best_bid":"0.61", "best_ask":"0.62"}], "timestamp":"1784449237257", "event_type":"price_change"}
{"market":"0xab772601f501b265bfe8982eb61d5347ef9945de314bfdf4ac0189c288ffb0b3", "price_changes":[{"asset_id":"12935926064588426924078449947177910958215776269411501731627440228801766632772", "price":"0.01", "size":"14894.14", "side":"BUY", "hash":"bb6a06c3b706e2e91a3ae9c6212db57ad5a0921a", "best_bid":"0.38", "best_ask":"0.39"}, {"asset_id":"17924629579804316786455515989238352689210911545477836576430679697715946894553", "price":"0.99", "size":"14894.14", "side":"SELL", "hash":"5b0aeb35a20dbe7387fe8231894aa7bbf0726bfb", "best_bid":"0.61", "best_ask":"0.62"}], "timestamp":"1784449237258", "event_type":"price_change"}
{"market":"0xab772601f501b265bfe8982eb61d5347ef9945de314bfdf4ac0189c288ffb0b3", "price_changes":[{"asset_id":"12935926064588426924078449947177910958215776269411501731627440228801766632772", "price":"0.38", "size":"119.4", "side":"BUY", "hash":"cb8a2faec70fc194258914d2215e88e4a77c5ca9", "best_bid":"0.38", "best_ask":"0.39"}, {"asset_id":"17924629579804316786455515989238352689210911545477836576430679697715946894553", "price":"0.62", "size":"119.4", "side":"SELL", "hash":"faa29c32ea8c0d50a7d78645f4f1fb6a615e1a0f", "best_bid":"0.61", "best_ask":"0.62"}], "timestamp":"1784449237259", "event_type":"price_change"}
{"market":"0xab772601f501b265bfe8982eb61d5347ef9945de314bfdf4ac0189c288ffb0b3", "price_changes":[{"asset_id":"17924629579804316786455515989238352689210911545477836576430679697715946894553", "price":"0.61", "size":"95.5", "side":"BUY", "hash":"aeafcc19e66880300e22e6fdba1c9da7f4ffb173", "best_bid":"0.61", "best_ask":"0.62"}, {"asset_id":"12935926064588426924078449947177910958215776269411501731627440228801766632772", "price":"0.39", "size":"95.5", "side":"SELL", "hash":"754a5a4ba683a352e7332cc948067e5e81de875e", "best_bid":"0.38", "best_ask":"0.39"}], "timestamp":"1784449237259", "event_type":"price_change"}
{"market":"0xab772601f501b265bfe8982eb61d5347ef9945de314bfdf4ac0189c288ffb0b3", "price_changes":[{"asset_id":"17924629579804316786455515989238352689210911545477836576430679697715946894553", "price":"0.01", "size":"13180.51", "side":"BUY", "hash":"0ce0b377141ba23a91ef3e436753b57b3f2ed57e", "best_bid":"0.61", "best_ask":"0.62"}, {"asset_id":"12935926064588426924078449947177910958215776269411501731627440228801766632772", "price":"0.99", "size":"13180.51", "side":"SELL", "hash":"b80363fcae33b56086d6a6d35c2f62f24fbdeda6", "best_bid":"0.38", "best_ask":"0.39"}], "timestamp":"1784449237261", "event_type":"price_change"}
{"market":"0xab772601f501b265bfe8982eb61d5347ef9945de314bfdf4ac0189c288ffb0b3", "price_changes":[{"asset_id":"12935926064588426924078449947177910958215776269411501731627440228801766632772", "price":"0.31", "size":"560.01", "side":"BUY", "hash":"9168748269e87282ae1f070c293f0985ab0aeb9e", "best_bid":"0.38", "best_ask":"0.39"}, {"asset_id":"17924629579804316786455515989238352689210911545477836576430679697715946894553", "price":"0.69", "size":"560.01", "side":"SELL", "hash":"95fdef9c3702b59524cdb6450ec14d02f17a390f", "best_bid":"0.61", "best_ask":"0.62"}], "timestamp":"1784449237263", "event_type":"price_change"}
{"market":"0xab772601f501b265bfe8982eb61d5347ef9945de314bfdf4ac0189c288ffb0b3", "price_changes":[{"asset_id":"17924629579804316786455515989238352689210911545477836576430679697715946894553", "price":"0.01", "size":"13080.51", "side":"BUY", "hash":"75e9bbd5ef8c57d6d78f142c398774f2439ae566", "best_bid":"0.61", "best_ask":"0.62"}, {"asset_id":"12935926064588426924078449947177910958215776269411501731627440228801766632772", "price":"0.99", "size":"13080.51", "side":"SELL", "hash":"4b05bc450cdb30e51ee3924082d99aa055b27ac0", "best_bid":"0.38", "best_ask":"0.39"}], "timestamp":"1784449237264", "event_type":"price_change"}
{"market":"0xab772601f501b265bfe8982eb61d5347ef9945de314bfdf4ac0189c288ffb0b3", "price_changes":[{"asset_id":"12935926064588426924078449947177910958215776269411501731627440228801766632772", "price":"0.35", "size":"126.2", "side":"BUY", "hash":"fa0e3cd0513bb4d9b5e78959f90fa2490ef25049", "best_bid":"0.38", "best_ask":"0.39"}, {"asset_id":"17924629579804316786455515989238352689210911545477836576430679697715946894553", "price":"0.65", "size":"126.2", "side":"SELL", "hash":"3a154fb63b8c35883c7c5be3ee97a018d029bc79", "best_bid":"0.61", "best_ask":"0.62"}], "timestamp":"1784449237266", "event_type":"price_change"}
{"market":"0xab772601f501b265bfe8982eb61d5347ef9945de314bfdf4ac0189c288ffb0b3", "price_changes":[{"asset_id":"17924629579804316786455515989238352689210911545477836576430679697715946894553", "price":"0.61", "size":"103.58", "side":"BUY", "hash":"d1b108d0564338b31570e337ab347fde0ca6681a", "best_bid":"0.61", "best_ask":"0.62"}, {"asset_id":"12935926064588426924078449947177910958215776269411501731627440228801766632772", "price":"0.39", "size":"103.58", "side":"SELL", "hash":"b67e67d2b92ac44acbba2f30db2c575b01d519f8", "best_bid":"0.38", "best_ask":"0.39"}], "timestamp":"1784449237267", "event_type":"price_change"}
{"market":"0xab772601f501b265bfe8982eb61d5347ef9945de314bfdf4ac0189c288ffb0b3", "price_changes":[{"asset_id":"17924629579804316786455515989238352689210911545477836576430679697715946894553", "price":"0.54", "size":"148.85", "side":"BUY", "hash":"94eae88209ae71d99419f76186e9f232b2ee3156", "best_bid":"0.61", "best_ask":"0.62"}, {"asset_id":"12935926064588426924078449947177910958215776269411501731627440228801766632772", "price":"0.46", "size":"148.85", "side":"SELL", "hash":"3ba63dd6abe9cf950f5d37ed8956b7f8a9622de6", "best_bid":"0.38", "best_ask":"0.39"}], "timestamp":"1784449237268", "event_type":"price_change"}
{"market":"0xab772601f501b265bfe8982eb61d5347ef9945de314bfdf4ac0189c288ffb0b3", "price_changes":[{"asset_id":"17924629579804316786455515989238352689210911545477836576430679697715946894553", "price":"0.41", "size":"100.5", "side":"BUY", "hash":"f4ff2bfffe09ebf9f192c9a371fdc3456628f1af", "best_bid":"0.61", "best_ask":"0.62"}, {"asset_id":"12935926064588426924078449947177910958215776269411501731627440228801766632772", "price":"0.59", "size":"100.5", "side":"SELL", "hash":"652371f954b38e55de2a6bb11ca4b42398531f02", "best_bid":"0.38", "best_ask":"0.39"}], "timestamp":"1784449237271", "event_type":"price_change"}
{"market":"0xab772601f501b265bfe8982eb61d5347ef9945de314bfdf4ac0189c288ffb0b3", "price_changes":[{"asset_id":"12935926064588426924078449947177910958215776269411501731627440228801766632772", "price":"0.32", "size":"234.69", "side":"BUY", "hash":"8fcc0b93c3b18acd0b3eb2f0969a82b0568aac5e", "best_bid":"0.38", "best_ask":"0.39"}, {"asset_id":"17924629579804316786455515989238352689210911545477836576430679697715946894553", "price":"0.68", "size":"234.69", "side":"SELL", "hash":"4b3a0726299780096eb96c80137293849da726ee", "best_bid":"0.61", "best_ask":"0.62"}], "timestamp":"1784449237273", "event_type":"price_change"}
{"market":"0xab772601f501b265bfe8982eb61d5347ef9945de314bfdf4ac0189c288ffb0b3", "price_changes":[{"asset_id":"17924629579804316786455515989238352689210911545477836576430679697715946894553", "price":"0.61", "size":"334.32", "side":"BUY", "hash":"e44ffedba1e46f300a2a8781a673940252e54ef1", "best_bid":"0.61", "best_ask":"0.62"}, {"asset_id":"12935926064588426924078449947177910958215776269411501731627440228801766632772", "price":"0.39", "size":"334.32", "side":"SELL", "hash":"9ef2ba0abe148726917663a6f31b785cf49d7574", "best_bid":"0.38", "best_ask":"0.39"}], "timestamp":"1784449237275", "event_type":"price_change"}
{"market":"0xab772601f501b265bfe8982eb61d5347ef9945de314bfdf4ac0189c288ffb0b3", "price_changes":[{"asset_id":"12935926064588426924078449947177910958215776269411501731627440228801766632772", "price":"0.34", "size":"106.76", "side":"BUY", "hash":"31c84aa232f0948e5e15db6b0ca200a739282261", "best_bid":"0.38", "best_ask":"0.39"}, {"asset_id":"17924629579804316786455515989238352689210911545477836576430679697715946894553", "price":"0.66", "size":"106.76", "side":"SELL", "hash":"7a3fb77b12a52ad3e45331f6786ebde805f16ef4", "best_bid":"0.61", "best_ask":"0.62"}], "timestamp":"1784449237275", "event_type":"price_change"}
{"market":"0xab772601f501b265bfe8982eb61d5347ef9945de314bfdf4ac0189c288ffb0b3", "price_changes":[{"asset_id":"12935926064588426924078449947177910958215776269411501731627440228801766632772", "price":"0.38", "size":"104.4", "side":"BUY", "hash":"0ee6d5303d9472101599482c6e80cc58c36716e5", "best_bid":"0.38", "best_ask":"0.39"}, {"asset_id":"17924629579804316786455515989238352689210911545477836576430679697715946894553", "price":"0.62", "size":"104.4", "side":"SELL", "hash":"921c91d10987bb9c3654d1790f3fe6749b36db7f", "best_bid":"0.61", "best_ask":"0.62"}], "timestamp":"1784449237278", "event_type":"price_change"}
{"market":"0xab772601f501b265bfe8982eb61d5347ef9945de314bfdf4ac0189c288ffb0b3", "price_changes":[{"asset_id":"12935926064588426924078449947177910958215776269411501731627440228801766632772", "price":"0.34", "size":"111.76", "side":"BUY", "hash":"193963627098dbb6e4c6890d0976e8f4d7f5d578", "best_bid":"0.38", "best_ask":"0.39"}, {"asset_id":"17924629579804316786455515989238352689210911545477836576430679697715946894553", "price":"0.66", "size":"111.76", "side":"SELL", "hash":"11b9765073373a4458be85d7077e9fc7cac45038", "best_bid":"0.61", "best_ask":"0.62"}], "timestamp":"1784449237278", "event_type":"price_change"}
{"market":"0xab772601f501b265bfe8982eb61d5347ef9945de314bfdf4ac0189c288ffb0b3", "price_changes":[{"asset_id":"12935926064588426924078449947177910958215776269411501731627440228801766632772", "price":"0.38", "size":"99.4", "side":"BUY", "hash":"60f2fbef6fdea5b9cbb9fe66f3d3d0b3d3d232e3", "best_bid":"0.38", "best_ask":"0.39"}, {"asset_id":"17924629579804316786455515989238352689210911545477836576430679697715946894553", "price":"0.62", "size":"99.4", "side":"SELL", "hash":"8876768c68115ac6cc64f726eff10482cfdca82c", "best_bid":"0.61", "best_ask":"0.62"}], "timestamp":"1784449237278", "event_type":"price_change"}
{"market":"0xab772601f501b265bfe8982eb61d5347ef9945de314bfdf4ac0189c288ffb0b3", "price_changes":[{"asset_id":"12935926064588426924078449947177910958215776269411501731627440228801766632772", "price":"0.33", "size":"164.65", "side":"BUY", "hash":"7ab21e15ba9e48967a6a08b055c4ab399de589c0", "best_bid":"0.38", "best_ask":"0.39"}, {"asset_id":"17924629579804316786455515989238352689210911545477836576430679697715946894553", "price":"0.67", "size":"164.65", "side":"SELL", "hash":"b7fdfa4cf23eabdbc6dd26807906925aa1798957", "best_bid":"0.61", "best_ask":"0.62"}], "timestamp":"1784449237279", "event_type":"price_change"}
{"market":"0xab772601f501b265bfe8982eb61d5347ef9945de314bfdf4ac0189c288ffb0b3", "price_changes":[{"asset_id":"12935926064588426924078449947177910958215776269411501731627440228801766632772", "price":"0.37", "size":"241.13", "side":"BUY", "hash":"6c2e910d9a840f9d48cc479649544241b5cadd05", "best_bid":"0.38", "best_ask":"0.39"}, {"asset_id":"17924629579804316786455515989238352689210911545477836576430679697715946894553", "price":"0.63", "size":"241.13", "side":"SELL", "hash":"00b2219414fb8e2a98318dfc6990ce150514199d", "best_bid":"0.61", "best_ask":"0.62"}], "timestamp":"1784449237279", "event_type":"price_change"}
{"market":"0xab772601f501b265bfe8982eb61d5347ef9945de314bfdf4ac0189c288ffb0b3", "price_changes":[{"asset_id":"12935926064588426924078449947177910958215776269411501731627440228801766632772", "price":"0.32", "size":"239.69", "side":"BUY", "hash":"6db4eb7f3cec3d093a455a97652a4458805dcd91", "best_bid":"0.38", "best_ask":"0.39"}, {"asset_id":"17924629579804316786455515989238352689210911545477836576430679697715946894553", "price":"0.68", "size":"239.69", "side":"SELL", "hash":"3df9753475f1412b8662f0e6767f4bb2de22ec99", "best_bid":"0.61", "best_ask":"0.62"}], "timestamp":"1784449237280", "event_type":"price_change"}
{"market":"0xab772601f501b265bfe8982eb61d5347ef9945de314bfdf4ac0189c288ffb0b3", "price_changes":[{"asset_id":"12935926064588426924078449947177910958215776269411501731627440228801766632772", "price":"0.37", "size":"216.13", "side":"BUY", "hash":"4ac32d458943e723ed3f421fc11048db0dba81a6", "best_bid":"0.38", "best_ask":"0.39"}, {"asset_id":"17924629579804316786455515989238352689210911545477836576430679697715946894553", "price":"0.63", "size":"216.13", "side":"SELL", "hash":"483ffb9dc791620b983eab62f16a056cbf77b4a0", "best_bid":"0.61", "best_ask":"0.62"}], "timestamp":"1784449237281", "event_type":"price_change"}
{"market":"0xab772601f501b265bfe8982eb61d5347ef9945de314bfdf4ac0189c288ffb0b3", "price_changes":[{"asset_id":"12935926064588426924078449947177910958215776269411501731627440228801766632772", "price":"0.3", "size":"205.64", "side":"BUY", "hash":"1be1b783cc888339a30bea8f068f42affd935c78", "best_bid":"0.38", "best_ask":"0.39"}, {"asset_id":"17924629579804316786455515989238352689210911545477836576430679697715946894553", "price":"0.7", "size":"205.64", "side":"SELL", "hash":"ed568b159cb7e0da66f6ea4f9e329d4076424b65", "best_bid":"0.61", "best_ask":"0.62"}], "timestamp":"1784449237282", "event_type":"price_change"}
{"market":"0xab772601f501b265bfe8982eb61d5347ef9945de314bfdf4ac0189c288ffb0b3", "price_changes":[{"asset_id":"17924629579804316786455515989238352689210911545477836576430679697715946894553", "price":"0.31", "size":"64.7", "side":"BUY", "hash":"94676a585e9a0892b8c827c71edbb29d3195f88b", "best_bid":"0.61", "best_ask":"0.62"}, {"asset_id":"12935926064588426924078449947177910958215776269411501731627440228801766632772", "price":"0.69", "size":"64.7", "side":"SELL", "hash":"c5196d3d6ac1b56684ccd688f970ce19a4524e9b", "best_bid":"0.38", "best_ask":"0.39"}], "timestamp":"1784449237282", "event_type":"price_change"}
{"market":"0xab772601f501b265bfe8982eb61d5347ef9945de314bfdf4ac0189c288ffb0b3", "price_changes":[{"asset_id":"12935926064588426924078449947177910958215776269411501731627440228801766632772", "price":"0.35", "size":"101.2", "side":"BUY", "hash":"9cde4c8c109e3a375c5f8392064d468b71d7d9e6", "best_bid":"0.38", "best_ask":"0.39"}, {"asset_id":"17924629579804316786455515989238352689210911545477836576430679697715946894553", "price":"0.65", "size":"101.2", "side":"SELL", "hash":"4638b4f2f020271897c0d3a7dcf41399e1daad07", "best_bid":"0.61", "best_ask":"0.62"}], "timestamp":"1784449237283", "event_type":"price_change"}
{"market":"0xab772601f501b265bfe8982eb61d5347ef9945de314bfdf4ac0189c288ffb0b3", "price_changes":[{"asset_id":"17924629579804316786455515989238352689210911545477836576430679697715946894553", "price":"0.6", "size":"136.7", "side":"BUY", "hash":"5771a1d6aea7386600213022c3eda7e965dd33cb", "best_bid":"0.61", "best_ask":"0.62"}, {"asset_id":"12935926064588426924078449947177910958215776269411501731627440228801766632772", "price":"0.4", "size":"136.7", "side":"SELL", "hash":"fc3cebc51b22af8c4c927a7e90cdc61909b19317", "best_bid":"0.38", "best_ask":"0.39"}], "timestamp":"1784449237283", "event_type":"price_change"}
{"market":"0xab772601f501b265bfe8982eb61d5347ef9945de314bfdf4ac0189c288ffb0b3", "price_changes":[{"asset_id":"12935926064588426924078449947177910958215776269411501731627440228801766632772", "price":"0.33", "size":"139.65", "side":"BUY", "hash":"88a567b565e9744be383a6b0c5b4349988a52307", "best_bid":"0.38", "best_ask":"0.39"}, {"asset_id":"17924629579804316786455515989238352689210911545477836576430679697715946894553", "price":"0.67", "size":"139.65", "side":"SELL", "hash":"918974eb2775312140c0c1b69b5c1eed581379b0", "best_bid":"0.61", "best_ask":"0.62"}], "timestamp":"1784449237285", "event_type":"price_change"}
{"market":"0xab772601f501b265bfe8982eb61d5347ef9945de314bfdf4ac0189c288ffb0b3", "price_changes":[{"asset_id":"17924629579804316786455515989238352689210911545477836576430679697715946894553", "price":"0.43", "size":"100.3", "side":"BUY", "hash":"6ca0873a5e46c578857cd0ce5aa07c87cd20f0d9", "best_bid":"0.61", "best_ask":"0.62"}, {"asset_id":"12935926064588426924078449947177910958215776269411501731627440228801766632772", "price":"0.57", "size":"100.3", "side":"SELL", "hash":"2fa7ca2042302815251617a20e08d62c8a5f4449", "best_bid":"0.38", "best_ask":"0.39"}], "timestamp":"1784449237286", "event_type":"price_change"}
{"market":"0xab772601f501b265bfe8982eb61d5347ef9945de314bfdf4ac0189c288ffb0b3", "price_changes":[{"asset_id":"12935926064588426924078449947177910958215776269411501731627440228801766632772", "price":"0.19", "size":"128.89", "side":"BUY", "hash":"065c0feb41abd195c037166795b5c43482659b12", "best_bid":"0.38", "best_ask":"0.39"}, {"asset_id":"17924629579804316786455515989238352689210911545477836576430679697715946894553", "price":"0.81", "size":"128.89", "side":"SELL", "hash":"2f72586aa6a3f684857d8b3bfd06724cdad23a5f", "best_bid":"0.61", "best_ask":"0.62"}], "timestamp":"1784449237286", "event_type":"price_change"}
{"market":"0xab772601f501b265bfe8982eb61d5347ef9945de314bfdf4ac0189c288ffb0b3", "price_changes":[{"asset_id":"17924629579804316786455515989238352689210911545477836576430679697715946894553", "price":"0.41", "size":"75.5", "side":"BUY", "hash":"3e46613683d97e405b2ba3c7489f0dad51d3fd2c", "best_bid":"0.61", "best_ask":"0.62"}, {"asset_id":"12935926064588426924078449947177910958215776269411501731627440228801766632772", "price":"0.59", "size":"75.5", "side":"SELL", "hash":"c23a1ae55a1eb114d8bb723584f3610b4c12f423", "best_bid":"0.38", "best_ask":"0.39"}], "timestamp":"1784449237287", "event_type":"price_change"}
{"market":"0xab772601f501b265bfe8982eb61d5347ef9945de314bfdf4ac0189c288ffb0b3", "price_changes":[{"asset_id":"17924629579804316786455515989238352689210911545477836576430679697715946894553", "price":"0.6", "size":"111.7", "side":"BUY", "hash":"13de47ef5ccfc3c31120ed9a27ac7955072e2c8b", "best_bid":"0.61", "best_ask":"0.62"}, {"asset_id":"12935926064588426924078449947177910958215776269411501731627440228801766632772", "price":"0.4", "size":"111.7", "side":"SELL", "hash":"a777ffb86443551e745c14df35c5c4a95ca46ae6", "best_bid":"0.38", "best_ask":"0.39"}], "timestamp":"1784449237287", "event_type":"price_change"}
{"market":"0xab772601f501b265bfe8982eb61d5347ef9945de314bfdf4ac0189c288ffb0b3", "price_changes":[{"asset_id":"17924629579804316786455515989238352689210911545477836576430679697715946894553", "price":"0.43", "size":"75.3", "side":"BUY", "hash":"bc87255328a563d9c0a84580e7ce6640c12e03e4", "best_bid":"0.61", "best_ask":"0.62"}, {"asset_id":"12935926064588426924078449947177910958215776269411501731627440228801766632772", "price":"0.57", "size":"75.3", "side":"SELL", "hash":"ed8559edb304d8ee695255e400c23a462501812a", "best_bid":"0.38", "best_ask":"0.39"}], "timestamp":"1784449237289", "event_type":"price_change"}
{"market":"0xab772601f501b265bfe8982eb61d5347ef9945de314bfdf4ac0189c288ffb0b3", "price_changes":[{"asset_id":"17924629579804316786455515989238352689210911545477836576430679697715946894553", "price":"0.57", "size":"163", "side":"BUY", "hash":"00d243aab6066111789e02a5247c072d4dc2b68a", "best_bid":"0.61", "best_ask":"0.62"}, {"asset_id":"12935926064588426924078449947177910958215776269411501731627440228801766632772", "price":"0.43", "size":"163", "side":"SELL", "hash":"e84e6150984d0dd367e04d0353f9f159299c25d6", "best_bid":"0.38", "best_ask":"0.39"}], "timestamp":"1784449237291", "event_type":"price_change"}
{"market":"0xab772601f501b265bfe8982eb61d5347ef9945de314bfdf4ac0189c288ffb0b3", "price_changes":[{"asset_id":"17924629579804316786455515989238352689210911545477836576430679697715946894553", "price":"0.57", "size":"138", "side":"BUY", "hash":"5854e968219938ea3c281ddb06d0faac0d166c3f", "best_bid":"0.61", "best_ask":"0.62"}, {"asset_id":"12935926064588426924078449947177910958215776269411501731627440228801766632772", "price":"0.43", "size":"138", "side":"SELL", "hash":"18fc7985e4eeb5d0e73fb4ad6d803d11e09672d1", "best_bid":"0.38", "best_ask":"0.39"}], "timestamp":"1784449237292", "event_type":"price_change"}
{"market":"0xab772601f501b265bfe8982eb61d5347ef9945de314bfdf4ac0189c288ffb0b3", "price_changes":[{"asset_id":"12935926064588426924078449947177910958215776269411501731627440228801766632772", "price":"0.32", "size":"264.69", "side":"BUY", "hash":"368facafcd3372c438bfed316dd705a4dbee9e75", "best_bid":"0.38", "best_ask":"0.39"}, {"asset_id":"17924629579804316786455515989238352689210911545477836576430679697715946894553", "price":"0.68", "size":"264.69", "side":"SELL", "hash":"b048010d80f7b4f8cb4ac46a569fae617c6ef409", "best_bid":"0.61", "best_ask":"0.62"}], "timestamp":"1784449237292", "event_type":"price_change"}
{"market":"0xab772601f501b265bfe8982eb61d5347ef9945de314bfdf4ac0189c288ffb0b3", "price_changes":[{"asset_id":"17924629579804316786455515989238352689210911545477836576430679697715946894553", "price":"0.01", "size":"12980.51", "side":"BUY", "hash":"9305302e135b5c64017391e3286e4b41d8d7b4ce", "best_bid":"0.61", "best_ask":"0.62"}, {"asset_id":"12935926064588426924078449947177910958215776269411501731627440228801766632772", "price":"0.99", "size":"12980.51", "side":"SELL", "hash":"929d7e65effcd543e738bb74291fe10877926f6a", "best_bid":"0.38", "best_ask":"0.39"}], "timestamp":"1784449237293", "event_type":"price_change"}
{"market":"0xab772601f501b265bfe8982eb61d5347ef9945de314bfdf4ac0189c288ffb0b3", "price_changes":[{"asset_id":"17924629579804316786455515989238352689210911545477836576430679697715946894553", "price":"0.01", "size":"12975.5", "side":"BUY", "hash":"4dd11e19ac2667e7a880eb060dea331dcb4d5b34", "best_bid":"0.61", "best_ask":"0.62"}, {"asset_id":"12935926064588426924078449947177910958215776269411501731627440228801766632772", "price":"0.99", "size":"12975.5", "side":"SELL", "hash":"693572d22100ff76f477e730c88db86ba328eedf", "best_bid":"0.38", "best_ask":"0.39"}], "timestamp":"1784449237293", "event_type":"price_change"}
{"market":"0xab772601f501b265bfe8982eb61d5347ef9945de314bfdf4ac0189c288ffb0b3", "price_changes":[{"asset_id":"12935926064588426924078449947177910958215776269411501731627440228801766632772", "price":"0.32", "size":"239.69", "side":"BUY", "hash":"203cba737e71d9b65d16dc2f64860a1ad00c0a10", "best_bid":"0.38", "best_ask":"0.39"}, {"asset_id":"17924629579804316786455515989238352689210911545477836576430679697715946894553", "price":"0.68", "size":"239.69", "side":"SELL", "hash":"20d4e5133d9f1aa55ec4330e3c2d3836e559106c", "best_bid":"0.61", "best_ask":"0.62"}], "timestamp":"1784449237294", "event_type":"price_change"}
{"market":"0xab772601f501b265bfe8982eb61d5347ef9945de314bfdf4ac0189c288ffb0b3", "price_changes":[{"asset_id":"12935926064588426924078449947177910958215776269411501731627440228801766632772", "price":"0.37", "size":"126.13", "side":"BUY", "hash":"151f3a6bc5bbe136699df60e6de80a28c92526ea", "best_bid":"0.38", "best_ask":"0.39"}, {"asset_id":"17924629579804316786455515989238352689210911545477836576430679697715946894553", "price":"0.63", "size":"126.13", "side":"SELL", "hash":"5b0e3456b17686f06fa429befc13b96b3fe17474", "best_bid":"0.61", "best_ask":"0.62"}], "timestamp":"1784449237295", "event_type":"price_change"}
{"market":"0xab772601f501b265bfe8982eb61d5347ef9945de314bfdf4ac0189c288ffb0b3", "price_changes":[{"asset_id":"12935926064588426924078449947177910958215776269411501731627440228801766632772", "price":"0.38", "size":"112.4", "side":"BUY", "hash":"41af61353d0d2f99c1600777576efc249eafc1cb", "best_bid":"0.38", "best_ask":"0.39"}, {"asset_id":"17924629579804316786455515989238352689210911545477836576430679697715946894553", "price":"0.62", "size":"112.4", "side":"SELL", "hash":"6772e9d6eee087066f063d9badb21169a86ec8f0", "best_bid":"0.61", "best_ask":"0.62"}], "timestamp":"1784449237295", "event_type":"price_change"}
{"market":"0xab772601f501b265bfe8982eb61d5347ef9945de314bfdf4ac0189c288ffb0b3", "price_changes":[{"asset_id":"17924629579804316786455515989238352689210911545477836576430679697715946894553", "price":"0.01", "size":"12970.5", "side":"BUY", "hash":"c03f2af434b0511b6122ae64458ddccd29711e9f", "best_bid":"0.61", "best_ask":"0.62"}, {"asset_id":"12935926064588426924078449947177910958215776269411501731627440228801766632772", "price":"0.99", "size":"12970.5", "side":"SELL", "hash":"bc418ab35d7637783c9a067d4f88ef163f338dc0", "best_bid":"0.38", "best_ask":"0.39"}], "timestamp":"1784449237296", "event_type":"price_change"}
{"market":"0xab772601f501b265bfe8982eb61d5347ef9945de314bfdf4ac0189c288ffb0b3", "price_changes":[{"asset_id":"12935926064588426924078449947177910958215776269411501731627440228801766632772", "price":"0.23", "size":"102.3", "side":"BUY", "hash":"09fd97f9c2a2c618217e2c1504fb824d84dd696a", "best_bid":"0.38", "best_ask":"0.39"}, {"asset_id":"17924629579804316786455515989238352689210911545477836576430679697715946894553", "price":"0.77", "size":"102.3", "side":"SELL", "hash":"60628324a1264cc3e616bf0aac57f872c1be09f4", "best_bid":"0.61", "best_ask":"0.62"}], "timestamp":"1784449237297", "event_type":"price_change"}
{"market":"0xab772601f501b265bfe8982eb61d5347ef9945de314bfdf4ac0189c288ffb0b3", "price_changes":[{"asset_id":"17924629579804316786455515989238352689210911545477836576430679697715946894553", "price":"0.02", "size":"3890.25", "side":"BUY", "hash":"00ae4f1f94f16c5a5ad384156a2c56f23d0d944d", "best_bid":"0.61", "best_ask":"0.62"}, {"asset_id":"12935926064588426924078449947177910958215776269411501731627440228801766632772", "price":"0.98", "size":"3890.25", "side":"SELL", "hash":"0769ca23834d1249d41c6af29afe96234664c94d", "best_bid":"0.38", "best_ask":"0.39"}], "timestamp":"1784449237300", "event_type":"price_change"}
{"market":"0xab772601f501b265bfe8982eb61d5347ef9945de314bfdf4ac0189c288ffb0b3", "price_changes":[{"asset_id":"12935926064588426924078449947177910958215776269411501731627440228801766632772", "price":"0.38", "size":"83.18", "side":"BUY", "hash":"3ce1f1d0fb4a3160f0bb4418706ee252d1efb806", "best_bid":"0.38", "best_ask":"0.39"}, {"asset_id":"17924629579804316786455515989238352689210911545477836576430679697715946894553", "price":"0.62", "size":"83.18", "side":"SELL", "hash":"3f884616c4e763fc7acd427cc4f217933764b412", "best_bid":"0.61", "best_ask":"0.62"}], "timestamp":"1784449237300", "event_type":"price_change"}
{"market":"0xab772601f501b265bfe8982eb61d5347ef9945de314bfdf4ac0189c288ffb0b3", "price_changes":[{"asset_id":"17924629579804316786455515989238352689210911545477836576430679697715946894553", "price":"0.52", "size":"205", "side":"BUY", "hash":"abe930f0c4276e2722597ee780f9764dbe29b34b", "best_bid":"0.61", "best_ask":"0.62"}, {"asset_id":"12935926064588426924078449947177910958215776269411501731627440228801766632772", "price":"0.48", "size":"205", "side":"SELL", "hash":"b15481fe6a32cd468ae0e9c57575871de4233d8d", "best_bid":"0.38", "best_ask":"0.39"}], "timestamp":"1784449237302", "event_type":"price_change"}
{"market":"0xab772601f501b265bfe8982eb61d5347ef9945de314bfdf4ac0189c288ffb0b3", "price_changes":[{"asset_id":"12935926064588426924078449947177910958215776269411501731627440228801766632772", "price":"0.22", "size":"160.5", "side":"BUY", "hash":"97dd8972f597bddf61677d03444bc430f2d6ebfb", "best_bid":"0.38", "best_ask":"0.39"}, {"asset_id":"17924629579804316786455515989238352689210911545477836576430679697715946894553", "price":"0.78", "size":"160.5", "side":"SELL", "hash":"8a8f1aa8f2f9eaca1c52452bca293220e58a6a62", "best_bid":"0.61", "best_ask":"0.62"}], "timestamp":"1784449237302", "event_type":"price_change"}
{"market":"0xab772601f501b265bfe8982eb61d5347ef9945de314bfdf4ac0189c288ffb0b3", "price_changes":[{"asset_id":"12935926064588426924078449947177910958215776269411501731627440228801766632772", "price":"0.38", "size":"68.18", "side":"BUY", "hash":"e84640541bd4b79427a26f5fa3e04391e1e3f168", "best_bid":"0.38", "best_ask":"0.39"}, {"asset_id":"17924629579804316786455515989238352689210911545477836576430679697715946894553", "price":"0.62", "size":"68.18", "side":"SELL", "hash":"30f044598841a8b37d6ce386b4ed77768f49889b", "best_bid":"0.61", "best_ask":"0.62"}], "timestamp":"1784449237303", "event_type":"price_change"}
{"market":"0xab772601f501b265bfe8982eb61d5347ef9945de314bfdf4ac0189c288ffb0b3", "price_changes":[{"asset_id":"12935926064588426924078449947177910958215776269411501731627440228801766632772", "price":"0.22", "size":"135.5", "side":"BUY", "hash":"fc5b56b2c7f9c5dcf169d23cf886542fea8a9a2c", "best_bid":"0.38", "best_ask":"0.39"}, {"asset_id":"17924629579804316786455515989238352689210911545477836576430679697715946894553", "price":"0.78", "size":"135.5", "side":"SELL", "hash":"c775a6a6010c7b916e4f5dde5844e5c585421260", "best_bid":"0.61", "best_ask":"0.62"}], "timestamp":"1784449237303", "event_type":"price_change"}
{"market":"0xab772601f501b265bfe8982eb61d5347ef9945de314bfdf4ac0189c288ffb0b3", "price_changes":[{"asset_id":"17924629579804316786455515989238352689210911545477836576430679697715946894553", "price":"0.61", "size":"344.32", "side":"BUY", "hash":"606a1a14131dcb8f7765cf6df3b29171578f800b", "best_bid":"0.61", "best_ask":"0.62"}, {"asset_id":"12935926064588426924078449947177910958215776269411501731627440228801766632772", "price":"0.39", "size":"344.32", "side":"SELL", "hash":"180b2a6b8647e7c80f92f52901be93d8ab424f17", "best_bid":"0.38", "best_ask":"0.39"}], "timestamp":"1784449237305", "event_type":"price_change"}
{"market":"0xab772601f501b265bfe8982eb61d5347ef9945de314bfdf4ac0189c288ffb0b3", "price_changes":[{"asset_id":"17924629579804316786455515989238352689210911545477836576430679697715946894553", "price":"0.61", "size":"352.63", "side":"BUY", "hash":"97e4aa179a43e0f5966139b7dd2bcefc7f3f2177", "best_bid":"0.61", "best_ask":"0.62"}, {"asset_id":"12935926064588426924078449947177910958215776269411501731627440228801766632772", "price":"0.39", "size":"352.63", "side":"SELL", "hash":"89abe0fb90cf8deafcfcde7b7df1f91e4be98a67", "best_bid":"0.38", "best_ask":"0.39"}], "timestamp":"1784449237307", "event_type":"price_change"}
{"market":"0xab772601f501b265bfe8982eb61d5347ef9945de314bfdf4ac0189c288ffb0b3", "price_changes":[{"asset_id":"12935926064588426924078449947177910958215776269411501731627440228801766632772", "price":"0.38", "size":"52.05", "side":"BUY", "hash":"0fb26f514adb0bac56e595954a1a9ed3e3b26816", "best_bid":"0.38", "best_ask":"0.39"}, {"asset_id":"17924629579804316786455515989238352689210911545477836576430679697715946894553", "price":"0.62", "size":"52.05", "side":"SELL", "hash":"daf7a13842fc49185f8ad40e6c984013b9c11d10", "best_bid":"0.61", "best_ask":"0.62"}], "timestamp":"1784449237309", "event_type":"price_change"}
{"market":"0xab772601f501b265bfe8982eb61d5347ef9945de314bfdf4ac0189c288ffb0b3", "asset_id":"12935926064588426924078449947177910958215776269411501731627440228801766632772", "bids":[{"price":"0.01", "size":"14894.14"}, {"price":"0.02", "size":"3964.52"}, {"price":"0.03", "size":"2179.29"}, {"price":"0.04", "size":"1215.1"}, {"price":"0.05", "size":"1757.19"}, {"price":"0.06", "size":"1137.02"}, {"price":"0.07", "size":"968.49"}, {"price":"0.08", "size":"1234.38"}, {"price":"0.09", "size":"791.7"}, {"price":"0.1", "size":"461.2"}, {"price":"0.11", "size":"1502.1"}, {"price":"0.12", "size":"1102.45"}, {"price":"0.13", "size":"139.4"}, {"price":"0.14", "size":"281.8"}, {"price":"0.15", "size":"444.04"}, {"price":"0.16", "size":"147.1"}, {"price":"0.17", "size":"207.17"}, {"price":"0.18", "size":"150.7"}, {"price":"0.19", "size":"128.89"}, {"price":"0.2", "size":"246.2"}, {"price":"0.21", "size":"636.8"}, {"price":"0.22", "size":"135.5"}, {"price":"0.23", "size":"102.3"}, {"price":"0.24", "size":"193.92"}, {"price":"0.25", "size":"137.2"}, {"price":"0.26", "size":"134.3"}, {"price":"0.27", "size":"148.5"}, {"price":"0.28", "size":"146.77"}, {"price":"0.29", "size":"216.99"}, {"price":"0.3", "size":"205.64"}, {"price":"0.31", "size":"560.01"}, {"price":"0.32", "size":"239.69"}, {"price":"0.33", "size":"139.65"}, {"price":"0.34", "size":"111.76"}, {"price":"0.35", "size":"101.2"}, {"price":"0.36", "size":"221.77"}, {"price":"0.37", "size":"126.13"}, {"price":"0.38", "size":"52.05"}], "asks":[{"price":"0.99", "size":"12970.5"}, {"price":"0.98", "size":"3890.25"}, {"price":"0.97", "size":"2250.95"}, {"price":"0.96", "size":"1270.1"}, {"price":"0.95", "size":"1768.6"}, {"price":"0.94", "size":"1124.35"}, {"price":"0.93", "size":"959.2"}, {"price":"0.92", "size":"1225.88"}, {"price":"0.91", "size":"796.7"}, {"price":"0.9", "size":"365.2"}, {"price":"0.89", "size":"1502.1"}, {"price":"0.88", "size":"195.05"}, {"price":"0.87", "size":"147.4"}, {"price":"0.86", "size":"183.4"}, {"price":"0.85", "size":"449.04"}, {"price":"0.84", "size":"127.1"}, {"price":"0.83", "size":"107.69"}, {"price":"0.82", "size":"125.7"}, {"price":"0.81", "size":"98.89"}, {"price":"0.8", "size":"201.2"}, {"price":"0.79", "size":"616.8"}, {"price":"0.78", "size":"982.3"}, {"price":"0.77", "size":"67.6"}, {"price":"0.76", "size":"103.73"}, {"price":"0.75", "size":"78.3"}, {"price":"0.74", "size":"76.8"}, {"price":"0.73", "size":"70.3"}, {"price":"0.72", "size":"79.87"}, {"price":"0.71", "size":"74.39"}, {"price":"0.7", "size":"83"}, {"price":"0.69", "size":"64.7"}, {"price":"0.68", "size":"160.64"}, {"price":"0.67", "size":"98.1"}, {"price":"0.66", "size":"77.8"}, {"price":"0.65", "size":"69.6"}, {"price":"0.64", "size":"79.39"}, {"price":"0.63", "size":"194.2"}, {"price":"0.62", "size":"85"}, {"price":"0.61", "size":"95.4"}, {"price":"0.6", "size":"97.94"}, {"price":"0.59", "size":"75.5"}, {"price":"0.58", "size":"86.02"}, {"price":"0.57", "size":"75.3"}, {"price":"0.56", "size":"64.2"}, {"price":"0.55", "size":"204.71"}, {"price":"0.54", "size":"102.1"}, {"price":"0.53", "size":"72.1"}, {"price":"0.52", "size":"83"}, {"price":"0.51", "size":"81"}, {"price":"0.5", "size":"101"}, {"price":"0.49", "size":"90"}, {"price":"0.48", "size":"205"}, {"price":"0.47", "size":"457.38"}, {"price":"0.46", "size":"148.85"}, {"price":"0.45", "size":"226.69"}, {"price":"0.44", "size":"163.99"}, {"price":"0.43", "size":"138"}, {"price":"0.42", "size":"161.82"}, {"price":"0.41", "size":"350.34"}, {"price":"0.4", "size":"111.7"}, {"price":"0.39", "size":"352.63"}], "hash":"0fb26f514adb0bac56e595954a1a9ed3e3b26816", "timestamp":"1784449237309", "event_type":"book"}
{"market":"0xab772601f501b265bfe8982eb61d5347ef9945de314bfdf4ac0189c288ffb0b3", "asset_id":"17924629579804316786455515989238352689210911545477836576430679697715946894553", "bids":[{"price":"0.01", "size":"12970.5"}, {"price":"0.02", "size":"3890.25"}, {"price":"0.03", "size":"2250.95"}, {"price":"0.04", "size":"1270.1"}, {"price":"0.05", "size":"1768.6"}, {"price":"0.06", "size":"1124.35"}, {"price":"0.07", "size":"959.2"}, {"price":"0.08", "size":"1225.88"}, {"price":"0.09", "size":"796.7"}, {"price":"0.1", "size":"365.2"}, {"price":"0.11", "size":"1502.1"}, {"price":"0.12", "size":"195.05"}, {"price":"0.13", "size":"147.4"}, {"price":"0.14", "size":"183.4"}, {"price":"0.15", "size":"449.04"}, {"price":"0.16", "size":"127.1"}, {"price":"0.17", "size":"107.69"}, {"price":"0.18", "size":"125.7"}, {"price":"0.19", "size":"98.89"}, {"price":"0.2", "size":"201.2"}, {"price":"0.21", "size":"616.8"}, {"price":"0.22", "size":"982.3"}, {"price":"0.23", "size":"67.6"}, {"price":"0.24", "size":"103.73"}, {"price":"0.25", "size":"78.3"}, {"price":"0.26", "size":"76.8"}, {"price":"0.27", "size":"70.3"}, {"price":"0.28", "size":"79.87"}, {"price":"0.29", "size":"74.39"}, {"price":"0.3", "size":"83"}, {"price":"0.31", "size":"64.7"}, {"price":"0.32", "size":"160.64"}, {"price":"0.33", "size":"98.1"}, {"price":"0.34", "size":"77.8"}, {"price":"0.35", "size":"69.6"}, {"price":"0.36", "size":"79.39"}, {"price":"0.37", "size":"194.2"}, {"price":"0.38", "size":"85"}, {"price":"0.39", "size":"95.4"}, {"price":"0.4", "size":"97.94"}, {"price":"0.41", "size":"75.5"}, {"price":"0.42", "size":"86.02"}, {"price":"0.43", "size":"75.3"}, {"price":"0.44", "size":"64.2"}, {"price":"0.45", "size":"204.71"}, {"price":"0.46", "size":"102.1"}, {"price":"0.47", "size":"72.1"}, {"price":"0.48", "size":"83"}, {"price":"0.49", "size":"81"}, {"price":"0.5", "size":"101"}, {"price":"0.51", "size":"90"}, {"price":"0.52", "size":"205"}, {"price":"0.53", "size":"457.38"}, {"price":"0.54", "size":"148.85"}, {"price":"0.55", "size":"226.69"}, {"price":"0.56", "size":"163.99"}, {"price":"0.57", "size":"138"}, {"price":"0.58", "size":"161.82"}, {"price":"0.59", "size":"350.34"}, {"price":"0.6", "size":"111.7"}, {"price":"0.61", "size":"352.63"}], "asks":[{"price":"0.99", "size":"14894.14"}, {"price":"0.98", "size":"3964.52"}, {"price":"0.97", "size":"2179.29"}, {"price":"0.96", "size":"1215.1"}, {"price":"0.95", "size":"1757.19"}, {"price":"0.94", "size":"1137.02"}, {"price":"0.93", "size":"968.49"}, {"price":"0.92", "size":"1234.38"}, {"price":"0.91", "size":"791.7"}, {"price":"0.9", "size":"461.2"}, {"price":"0.89", "size":"1502.1"}, {"price":"0.88", "size":"1102.45"}, {"price":"0.87", "size":"139.4"}, {"price":"0.86", "size":"281.8"}, {"price":"0.85", "size":"444.04"}, {"price":"0.84", "size":"147.1"}, {"price":"0.83", "size":"207.17"}, {"price":"0.82", "size":"150.7"}, {"price":"0.81", "size":"128.89"}, {"price":"0.8", "size":"246.2"}, {"price":"0.79", "size":"636.8"}, {"price":"0.78", "size":"135.5"}, {"price":"0.77", "size":"102.3"}, {"price":"0.76", "size":"193.92"}, {"price":"0.75", "size":"137.2"}, {"price":"0.74", "size":"134.3"}, {"price":"0.73", "size":"148.5"}, {"price":"0.72", "size":"146.77"}, {"price":"0.71", "size":"216.99"}, {"price":"0.7", "size":"205.64"}, {"price":"0.69", "size":"560.01"}, {"price":"0.68", "size":"239.69"}, {"price":"0.67", "size":"139.65"}, {"price":"0.66", "size":"111.76"}, {"price":"0.65", "size":"101.2"}, {"price":"0.64", "size":"221.77"}, {"price":"0.63", "size":"126.13"}, {"price":"0.62", "size":"52.05"}], "hash":"daf7a13842fc49185f8ad40e6c984013b9c11d10", "timestamp":"1784449237309", "event_type":"book"}
{"market":"0xab772601f501b265bfe8982eb61d5347ef9945de314bfdf4ac0189c288ffb0b3", "price_changes":[{"asset_id":"12935926064588426924078449947177910958215776269411501731627440228801766632772", "price":"0.37", "size":"141.13", "side":"BUY", "hash":"62a6495d38fe16dea46c87365ebe418b3ceac0ee", "best_bid":"0.38", "best_ask":"0.39"}, {"asset_id":"17924629579804316786455515989238352689210911545477836576430679697715946894553", "price":"0.63", "size":"141.13", "side":"SELL", "hash":"0787bc89d02f0e0c7db5ab4bcfab72fe2c645f26", "best_bid":"0.61", "best_ask":"0.62"}], "timestamp":"1784449237312", "event_type":"price_change"}
{"market":"0xab772601f501b265bfe8982eb61d5347ef9945de314bfdf4ac0189c288ffb0b3", "price_changes":[{"asset_id":"12935926064588426924078449947177910958215776269411501731627440228801766632772", "price":"0.29", "size":"222.52", "side":"BUY", "hash":"02bbd5e56932b54a71ff983eda76ad4c7a1e3713", "best_bid":"0.38", "best_ask":"0.39"}, {"asset_id":"17924629579804316786455515989238352689210911545477836576430679697715946894553", "price":"0.71", "size":"222.52", "side":"SELL", "hash":"bcd6c515cdc692250df7270bea9d99af8795a8ce", "best_bid":"0.61", "best_ask":"0.62"}], "timestamp":"1784449237313", "event_type":"price_change"}
{"market":"0xab772601f501b265bfe8982eb61d5347ef9945de314bfdf4ac0189c288ffb0b3", "price_changes":[{"asset_id":"17924629579804316786455515989238352689210911545477836576430679697715946894553", "price":"0.43", "size":"100.3", "side":"BUY", "hash":"d3bdaa83e6e390901e59d5c3b6b489a50e15cead", "best_bid":"0.61", "best_ask":"0.62"}, {"asset_id":"12935926064588426924078449947177910958215776269411501731627440228801766632772", "price":"0.57", "size":"100.3", "side":"SELL", "hash":"0eb78b197ee9d3d9a9e629edca1e7ad41daf9d81", "best_bid":"0.38", "best_ask":"0.39"}], "timestamp":"1784449237315", "event_type":"price_change"}
{"market":"0xab772601f501b265bfe8982eb61d5347ef9945de314bfdf4ac0189c288ffb0b3", "price_changes":[{"asset_id":"17924629579804316786455515989238352689210911545477836576430679697715946894553", "price":"0.53", "size":"426.02", "side":"BUY", "hash":"fc964fdde7e4b968d77c5de109615648ff77b025", "best_bid":"0.61", "best_ask":"0.62"}, {"asset_id":"12935926064588426924078449947177910958215776269411501731627440228801766632772", "price":"0.47", "size":"426.02", "side":"SELL", "hash":"ce5604340f9050fa3c769e0d73781e3efd19ab0f", "best_bid":"0.38", "best_ask":"0.39"}], "timestamp":"1784449237315", "event_type":"price_change"}
{"market":"0xab772601f501b265bfe8982eb61d5347ef9945de314bfdf4ac0189c288ffb0b3", "price_changes":[{"asset_id":"12935926064588426924078449947177910958215776269411501731627440228801766632772", "price":"0.33", "size":"134.65", "side":"BUY", "hash":"58ab114ca8a9a422401e95f54e0beb01c037b37f", "best_bid":"0.38", "best_ask":"0.39"}, {"asset_id":"17924629579804316786455515989238352689210911545477836576430679697715946894553", "price":"0.67", "size":"134.65", "side":"SELL", "hash":"410ef01ab07bb753450c0beadba4ec884242102d", "best_bid":"0.61", "best_ask":"0.62"}], "timestamp":"1784449237316", "event_type":"price_change"}
{"market":"0xab772601f501b265bfe8982eb61d5347ef9945de314bfdf4ac0189c288ffb0b3", "price_changes":[{"asset_id":"12935926064588426924078449947177910958215776269411501731627440228801766632772", "price":"0.34", "size":"106.76", "side":"BUY", "hash":"58ab114ca8a9a422401e95f54e0beb01c037b37f", "best_bid":"0.38", "best_ask":"0.39"}, {"asset_id":"17924629579804316786455515989238352689210911545477836576430679697715946894553", "price":"0.66", "size":"106.76", "side":"SELL", "hash":"410ef01ab07bb753450c0beadba4ec884242102d", "best_bid":"0.61", "best_ask":"0.62"}], "timestamp":"1784449237316", "event_type":"price_change"}
{"market":"0xab772601f501b265bfe8982eb61d5347ef9945de314bfdf4ac0189c288ffb0b3", "price_changes":[{"asset_id":"12935926064588426924078449947177910958215776269411501731627440228801766632772", "price":"0.32", "size":"234.69", "side":"BUY", "hash":"58ab114ca8a9a422401e95f54e0beb01c037b37f", "best_bid":"0.38", "best_ask":"0.39"}, {"asset_id":"17924629579804316786455515989238352689210911545477836576430679697715946894553", "price":"0.68", "size":"234.69", "side":"SELL", "hash":"410ef01ab07bb753450c0beadba4ec884242102d", "best_bid":"0.61", "best_ask":"0.62"}], "timestamp":"1784449237316", "event_type":"price_change"}
{"market":"0xab772601f501b265bfe8982eb61d5347ef9945de314bfdf4ac0189c288ffb0b3", "price_changes":[{"asset_id":"17924629579804316786455515989238352689210911545477836576430679697715946894553", "price":"0.58", "size":"156.82", "side":"BUY", "hash":"e7700489179d8b877d2720cb95c6b43d5fd87f39", "best_bid":"0.61", "best_ask":"0.62"}, {"asset_id":"12935926064588426924078449947177910958215776269411501731627440228801766632772", "price":"0.42", "size":"156.82", "side":"SELL", "hash":"b606f26c1f25eadc04b9aab53b275e65268ff08e", "best_bid":"0.38", "best_ask":"0.39"}], "timestamp":"1784449237316", "event_type":"price_change"}
{"market":"0xab772601f501b265bfe8982eb61d5347ef9945de314bfdf4ac0189c288ffb0b3", "price_changes":[{"asset_id":"17924629579804316786455515989238352689210911545477836576430679697715946894553", "price":"0.57", "size":"133", "side":"BUY", "hash":"e7700489179d8b877d2720cb95c6b43d5fd87f39", "best_bid":"0.61", "best_ask":"0.62"}, {"asset_id":"12935926064588426924078449947177910958215776269411501731627440228801766632772", "price":"0.43", "size":"133", "side":"SELL", "hash":"b606f26c1f25eadc04b9aab53b275e65268ff08e", "best_bid":"0.38", "best_ask":"0.39"}], "timestamp":"1784449237316", "event_type":"price_change"}
{"market":"0xab772601f501b265bfe8982eb61d5347ef9945de314bfdf4ac0189c288ffb0b3", "price_changes":[{"asset_id":"12935926064588426924078449947177910958215776269411501731627440228801766632772", "price":"0.37", "size":"111.91", "side":"BUY", "hash":"1a8b6ff17d6f190bd834f240c302319880f6fdd1", "best_bid":"0.38", "best_ask":"0.39"}, {"asset_id":"17924629579804316786455515989238352689210911545477836576430679697715946894553", "price":"0.63", "size":"111.91", "side":"SELL", "hash":"9d81ddc0cbbcd68e761945d3c398bcbeb10c72c2", "best_bid":"0.61", "best_ask":"0.62"}], "timestamp":"1784449237316", "event_type":"price_change"}
{"market":"0xab772601f501b265bfe8982eb61d5347ef9945de314bfdf4ac0189c288ffb0b3", "price_changes":[{"asset_id":"17924629579804316786455515989238352689210911545477836576430679697715946894553", "price":"0.59", "size":"330.34", "side":"BUY", "hash":"441876fef3b24b542efa69d30504e8335096a9f9", "best_bid":"0.61", "best_ask":"0.62"}, {"asset_id":"12935926064588426924078449947177910958215776269411501731627440228801766632772", "price":"0.41", "size":"330.34", "side":"SELL", "hash":"871271b5450352a943e9d65c49ba51860d12309c", "best_bid":"0.38", "best_ask":"0.39"}], "timestamp":"1784449237317", "event_type":"price_change"}
{"market":"0xab772601f501b265bfe8982eb61d5347ef9945de314bfdf4ac0189c288ffb0b3", "price_changes":[{"asset_id":"17924629579804316786455515989238352689210911545477836576430679697715946894553", "price":"0.6", "size":"136.7", "side":"BUY", "hash":"817be72d2f91ff94221ae25dd5901bc0f6424746", "best_bid":"0.61", "best_ask":"0.62"}, {"asset_id":"12935926064588426924078449947177910958215776269411501731627440228801766632772", "price":"0.4", "size":"136.7", "side":"SELL", "hash":"7c83ac40149e15da9491e19ad76f5f0036c37db3", "best_bid":"0.38", "best_ask":"0.39"}], "timestamp":"1784449237319", "event_type":"price_change"}
{"market":"0xab772601f501b265bfe8982eb61d5347ef9945de314bfdf4ac0189c288ffb0b3", "price_changes":[{"asset_id":"12935926064588426924078449947177910958215776269411501731627440228801766632772", "price":"0.35", "size":"106.2", "side":"BUY", "hash":"caf6115d64519ce62e1e3fd031b0580a98eda5db", "best_bid":"0.38", "best_ask":"0.39"}, {"asset_id":"17924629579804316786455515989238352689210911545477836576430679697715946894553", "price":"0.65", "size":"106.2", "side":"SELL", "hash":"680bdc0332d1458dce9472d2df6f2837a7127dd7", "best_bid":"0.61", "best_ask":"0.62"}], "timestamp":"1784449237320", "event_type":"price_change"}
{"market":"0xab772601f501b265bfe8982eb61d5347ef9945de314bfdf4ac0189c288ffb0b3", "price_changes":[{"asset_id":"12935926064588426924078449947177910958215776269411501731627440228801766632772", "price":"0.36", "size":"226.77", "side":"BUY", "hash":"38c4549916e5ad1c1977e1ef4e97dad86fbff1f6", "best_bid":"0.38", "best_ask":"0.39"}, {"asset_id":"17924629579804316786455515989238352689210911545477836576430679697715946894553", "price":"0.64", "size":"226.77", "side":"SELL", "hash":"d1328ed4e304f59bc9dd1a22644bdc7a419369d3", "best_bid":"0.61", "best_ask":"0.62"}], "timestamp":"1784449237320", "event_type":"price_change"}
{"market":"0xab772601f501b265bfe8982eb61d5347ef9945de314bfdf4ac0189c288ffb0b3", "price_changes":[{"asset_id":"17924629579804316786455515989238352689210911545477836576430679697715946894553", "price":"0.61", "size":"357.63", "side":"BUY", "hash":"b2edfc9f93ca25af5cd5d7b418e9d4b80898dcea", "best_bid":"0.61", "best_ask":"0.62"}, {"asset_id":"12935926064588426924078449947177910958215776269411501731627440228801766632772", "price":"0.39", "size":"357.63", "side":"SELL", "hash":"1d5ccf6628b03f304394f55a167989390f5b2d00", "best_bid":"0.38", "best_ask":"0.39"}], "timestamp":"1784449237321", "event_type":"price_change"}
{"market":"0xab772601f501b265bfe8982eb61d5347ef9945de314bfdf4ac0189c288ffb0b3", "price_changes":[{"asset_id":"17924629579804316786455515989238352689210911545477836576430679697715946894553", "price":"0.57", "size":"158", "side":"BUY", "hash":"c24f01003db8b661a0e3aa1f6e933f15b22422ab", "best_bid":"0.61", "best_ask":"0.62"}, {"asset_id":"12935926064588426924078449947177910958215776269411501731627440228801766632772", "price":"0.43", "size":"158", "side":"SELL", "hash":"511120041621d3f031033b395fef0e7821fd7823", "best_bid":"0.38", "best_ask":"0.39"}], "timestamp":"1784449237322", "event_type":"price_change"}
{"market":"0xab772601f501b265bfe8982eb61d5347ef9945de314bfdf4ac0189c288ffb0b3", "price_changes":[{"asset_id":"12935926064588426924078449947177910958215776269411501731627440228801766632772", "price":"0.28", "size":"151.88", "side":"BUY", "hash":"b3fb1a8956f55a3600e9b093759936cf55a7d84b", "best_bid":"0.38", "best_ask":"0.39"}, {"asset_id":"17924629579804316786455515989238352689210911545477836576430679697715946894553", "price":"0.72", "size":"151.88", "side":"SELL", "hash":"63fd031c031ef83a9cc68c5b2bad08135f4302c3", "best_bid":"0.61", "best_ask":"0.62"}], "timestamp":"1784449237324", "event_type":"price_change"}
{"market":"0xab772601f501b265bfe8982eb61d5347ef9945de314bfdf4ac0189c288ffb0b3", "price_changes":[{"asset_id":"12935926064588426924078449947177910958215776269411501731627440228801766632772", "price":"0.25", "size":"162.2", "side":"BUY", "hash":"381fa6f076157bafea93dac3d3c71e14329c99cc", "best_bid":"0.38", "best_ask":"0.39"}, {"asset_id":"17924629579804316786455515989238352689210911545477836576430679697715946894553", "price":"0.75", "size":"162.2", "side":"SELL", "hash":"e70b79470882ad9a56bc03f8267576762159ba29", "best_bid":"0.61", "best_ask":"0.62"}], "timestamp":"1784449237325", "event_type":"price_change"}
{"market":"0xab772601f501b265bfe8982eb61d5347ef9945de314bfdf4ac0189c288ffb0b3", "price_changes":[{"asset_id":"12935926064588426924078449947177910958215776269411501731627440228801766632772", "price":"0.32", "size":"259.69", "side":"BUY", "hash":"1679ae602d3fa06c0c4fa40b6c26b38b20612048", "best_bid":"0.38", "best_ask":"0.39"}, {"asset_id":"17924629579804316786455515989238352689210911545477836576430679697715946894553", "price":"0.68", "size":"259.69", "side":"SELL", "hash":"6b6f008f3621e09ed115fda1f9738867f4793233", "best_bid":"0.61", "best_ask":"0.62"}], "timestamp":"1784449237328", "event_type":"price_change"}
{"market":"0xab772601f501b265bfe8982eb61d5347ef9945de314bfdf4ac0189c288ffb0b3", "price_changes":[{"asset_id":"12935926064588426924078449947177910958215776269411501731627440228801766632772", "price":"0.23", "size":"127.3", "side":"BUY", "hash":"32eaae9e3ad9ab9ff36ed3abb149816b519cbe3e", "best_bid":"0.38", "best_ask":"0.39"}, {"asset_id":"17924629579804316786455515989238352689210911545477836576430679697715946894553", "price":"0.77", "size":"127.3", "side":"SELL", "hash":"23f95b63b69362b7ed3d1d46ac5f9a0155b10521", "best_bid":"0.61", "best_ask":"0.62"}], "timestamp":"1784449237328", "event_type":"price_change"}
{"market":"0xab772601f501b265bfe8982eb61d5347ef9945de314bfdf4ac0189c288ffb0b3", "price_changes":[{"asset_id":"12935926064588426924078449947177910958215776269411501731627440228801766632772", "price":"0.01", "size":"14889.14", "side":"BUY", "hash":"36ac809fee79c0479bd522580784e26b735a0a0a", "best_bid":"0.38", "best_ask":"0.39"}, {"asset_id":"17924629579804316786455515989238352689210911545477836576430679697715946894553", "price":"0.99", "size":"14889.14", "side":"SELL", "hash":"d58af1e6f8d0491365a5939bf0172d64b643ffb6", "best_bid":"0.61", "best_ask":"0.62"}], "timestamp":"1784449237330", "event_type":"price_change"}
{"market":"0xab772601f501b265bfe8982eb61d5347ef9945de314bfdf4ac0189c288ffb0b3", "price_changes":[{"asset_id":"12935926064588426924078449947177910958215776269411501731627440228801766632772", "price":"0.38", "size":"47.05", "side":"BUY", "hash":"1a3109978bf4240ddab3ab2ab99ab804eabf72b5", "best_bid":"0.38", "best_ask":"0.39"}, {"asset_id":"17924629579804316786455515989238352689210911545477836576430679697715946894553", "price":"0.62", "size":"47.05", "side":"SELL", "hash":"635f4a09d950f07ad3fa3866ce0b27accb26c5fc", "best_bid":"0.61", "best_ask":"0.62"}], "timestamp":"1784449237331", "event_type":"price_change"}
{"market":"0xab772601f501b265bfe8982eb61d5347ef9945de314bfdf4ac0189c288ffb0b3", "price_changes":[{"asset_id":"17924629579804316786455515989238352689210911545477836576430679697715946894553", "price":"0.61", "size":"369.63", "side":"BUY", "hash":"721a97ffe1a6a6d73bddba894d6c61bab2a45bdd", "best_bid":"0.61", "best_ask":"0.62"}, {"asset_id":"12935926064588426924078449947177910958215776269411501731627440228801766632772", "price":"0.39", "size":"369.63", "side":"SELL", "hash":"dece13ffdda6260c67a3d80d39ec2bb4f5cf9ed9", "best_bid":"0.38", "best_ask":"0.39"}], "timestamp":"1784449237334", "event_type":"price_change"}
{"market":"0xab772601f501b265bfe8982eb61d5347ef9945de314bfdf4ac0189c288ffb0b3", "price_changes":[{"asset_id":"12935926064588426924078449947177910958215776269411501731627440228801766632772", "price":"0.51", "size":"91", "side":"SELL", "hash":"f91216cdab5c3881d893b161c0914d83c08cd1ca", "best_bid":"0.38", "best_ask":"0.39"}, {"asset_id":"17924629579804316786455515989238352689210911545477836576430679697715946894553", "price":"0.49", "size":"91", "side":"BUY", "hash":"0acae0477a8e79a7ee67ecafd82ce742e0b9cbee", "best_bid":"0.61", "best_ask":"0.62"}], "timestamp":"1784449237335", "event_type":"price_change"}
{"market":"0xab772601f501b265bfe8982eb61d5347ef9945de314bfdf4ac0189c288ffb0b3", "price_changes":[{"asset_id":"17924629579804316786455515989238352689210911545477836576430679697715946894553", "price":"0.01", "size":"12964.5", "side":"BUY", "hash":"516e78a1ebf68ed1b18bdd2b151e703c7e963249", "best_bid":"0.61", "best_ask":"0.62"}, {"asset_id":"12935926064588426924078449947177910958215776269411501731627440228801766632772", "price":"0.99", "size":"12964.5", "side":"SELL", "hash":"f2d64bd51eb171cc36a09840b271a01d89df9070", "best_bid":"0.38", "best_ask":"0.39"}], "timestamp":"1784449237337", "event_type":"price_change"}
{"market":"0xab772601f501b265bfe8982eb61d5347ef9945de314bfdf4ac0189c288ffb0b3", "price_changes":[{"asset_id":"17924629579804316786455515989238352689210911545477836576430679697715946894553", "price":"0.01", "size":"13064.5", "side":"BUY", "hash":"baf343948479afa4c3511dffe2c784098d00b32f", "best_bid":"0.61", "best_ask":"0.62"}, {"asset_id":"12935926064588426924078449947177910958215776269411501731627440228801766632772", "price":"0.99", "size":"13064.5", "side":"SELL", "hash":"51174f711b6e9615242dde2a6cb710f0ae8d3d3d", "best_bid":"0.38", "best_ask":"0.39"}], "timestamp":"1784449237337", "event_type":"price_change"}
{"market":"0xab772601f501b265bfe8982eb61d5347ef9945de314bfdf4ac0189c288ffb0b3", "price_changes":[{"asset_id":"12935926064588426924078449947177910958215776269411501731627440228801766632772", "price":"0.32", "size":"254.69", "side":"BUY", "hash":"faeafd2e22042b757478732c07a0a1c8b53e3221", "best_bid":"0.38", "best_ask":"0.39"}, {"asset_id":"17924629579804316786455515989238352689210911545477836576430679697715946894553", "price":"0.68", "size":"254.69", "side":"SELL", "hash":"54ba9b586b2cde0def64eba420cc74acbd0b0d57", "best_bid":"0.61", "best_ask":"0.62"}], "timestamp":"1784449237339", "event_type":"price_change"}
{"market":"0xab772601f501b265bfe8982eb61d5347ef9945de314bfdf4ac0189c288ffb0b3", "price_changes":[{"asset_id":"12935926064588426924078449947177910958215776269411501731627440228801766632772", "price":"0.37", "size":"105.91", "side":"BUY", "hash":"34ac0128d86be0c95d8e82b1a47c338ec75b32d2", "best_bid":"0.38", "best_ask":"0.39"}, {"asset_id":"17924629579804316786455515989238352689210911545477836576430679697715946894553", "price":"0.63", "size":"105.91", "side":"SELL", "hash":"cd8fb1d004cf350194bff367b2629e3ab8aee636", "best_bid":"0.61", "best_ask":"0.62"}], "timestamp":"1784449237340", "event_type":"price_change"}
{"market":"0xab772601f501b265bfe8982eb61d5347ef9945de314bfdf4ac0189c288ffb0b3", "price_changes":[{"asset_id":"12935926064588426924078449947177910958215776269411501731627440228801766632772", "price":"0.05", "size":"1742.19", "side":"BUY", "hash":"3f8a732c8779f9683ec0c7e2b2bd8088d5982c49", "best_bid":"0.38", "best_ask":"0.39"}, {"asset_id":"17924629579804316786455515989238352689210911545477836576430679697715946894553", "price":"0.95", "size":"1742.19", "side":"SELL", "hash":"bff5be690bd1c88aabb3ced0a3238f944c0be098", "best_bid":"0.61", "best_ask":"0.62"}], "timestamp":"1784449237341", "event_type":"price_change"}
{"market":"0xab772601f501b265bfe8982eb61d5347ef9945de314bfdf4ac0189c288ffb0b3", "price_changes":[{"asset_id":"12935926064588426924078449947177910958215776269411501731627440228801766632772", "price":"0.07", "size":"953.49", "side":"BUY", "hash":"a53da61b90a9c6720022f385f20d991d6d585c7c", "best_bid":"0.38", "best_ask":"0.39"}, {"asset_id":"17924629579804316786455515989238352689210911545477836576430679697715946894553", "price":"0.93", "size":"953.49", "side":"SELL", "hash":"ebb5d71595542b9101d9412c47802dbe51c73fbf", "best_bid":"0.61", "best_ask":"0.62"}], "timestamp":"1784449237341", "event_type":"price_change"}
{"market":"0xab772601f501b265bfe8982eb61d5347ef9945de314bfdf4ac0189c288ffb0b3", "price_changes":[{"asset_id":"12935926064588426924078449947177910958215776269411501731627440228801766632772", "price":"0.06", "size":"1122.02", "side":"BUY", "hash":"a8c247d55f0bb9b6b99dbbe54c2a26f531f7561f", "best_bid":"0.38", "best_ask":"0.39"}, {"asset_id":"17924629579804316786455515989238352689210911545477836576430679697715946894553", "price":"0.94", "size":"1122.02", "side":"SELL", "hash":"10cd9b957ad045da429b395972a52542eed6d8f3", "best_bid":"0.61", "best_ask":"0.62"}], "timestamp":"1784449237342", "event_type":"price_change"}
{"market":"0xab772601f501b265bfe8982eb61d5347ef9945de314bfdf4ac0189c288ffb0b3", "price_changes":[{"asset_id":"17924629579804316786455515989238352689210911545477836576430679697715946894553", "price":"0.58", "size":"151.82", "side":"BUY", "hash":"646891d57ef94fb43d4569897ac0d4e5a351908e", "best_bid":"0.61", "best_ask":"0.62"}, {"asset_id":"12935926064588426924078449947177910958215776269411501731627440228801766632772", "price":"0.42", "size":"151.82", "side":"SELL", "hash":"2595eb2697581e12765e0bae255e16800e7292ea", "best_bid":"0.38", "best_ask":"0.39"}], "timestamp":"1784449237346", "event_type":"price_change"}
{"market":"0xab772601f501b265bfe8982eb61d5347ef9945de314bfdf4ac0189c288ffb0b3", "price_changes":[{"asset_id":"12935926064588426924078449947177910958215776269411501731627440228801766632772", "price":"0.27", "size":"153.61", "side":"BUY", "hash":"13d9f089645368195beab0b592a183b81ec616b8", "best_bid":"0.38", "best_ask":"0.39"}, {"asset_id":"17924629579804316786455515989238352689210911545477836576430679697715946894553", "price":"0.73", "size":"153.61", "side":"SELL", "hash":"35fdc5a9b8209938c9b46ea162a6ddaf21fc68b1", "best_bid":"0.61", "best_ask":"0.62"}], "timestamp":"1784449237346", "event_type":"price_change"}
{"market":"0xab772601f501b265bfe8982eb61d5347ef9945de314bfdf4ac0189c288ffb0b3", "price_changes":[{"asset_id":"17924629579804316786455515989238352689210911545477836576430679697715946894553", "price":"0.02", "size":"3885.25", "side":"BUY", "hash":"69646d3d5ec279bbeb30ed3a8c3a880caa2f28df", "best_bid":"0.61", "best_ask":"0.62"}, {"asset_id":"12935926064588426924078449947177910958215776269411501731627440228801766632772", "price":"0.98", "size":"3885.25", "side":"SELL", "hash":"6fca083a7c591b3e75b7b15b7a2c60fa1c961030", "best_bid":"0.38", "best_ask":"0.39"}], "timestamp":"1784449237352", "event_type":"price_change"}
{"market":"0xab772601f501b265bfe8982eb61d5347ef9945de314bfdf4ac0189c288ffb0b3", "price_changes":[{"asset_id":"17924629579804316786455515989238352689210911545477836576430679697715946894553", "price":"0.61", "size":"374.63", "side":"BUY", "hash":"dfa4cadcf56506dc7ea801a4610f6376c114932f", "best_bid":"0.61", "best_ask":"0.62"}, {"asset_id":"12935926064588426924078449947177910958215776269411501731627440228801766632772", "price":"0.39", "size":"374.63", "side":"SELL", "hash":"81b32b595ae775dd2281c8e51768d131044696ce", "best_bid":"0.38", "best_ask":"0.39"}], "timestamp":"1784449237355", "event_type":"price_change"}
{"market":"0xab772601f501b265bfe8982eb61d5347ef9945de314bfdf4ac0189c288ffb0b3", "asset_id":"17924629579804316786455515989238352689210911545477836576430679697715946894553", "price":"0.62", "size":"16.129031", "fee_rate_bps":"0", "side":"BUY", "timestamp":"1784449237352", "event_type":"last_trade_price", "transaction_hash":"0x4023c6f1df542c4cbbf58fb6b0ca9937a98be42a4bd2ca0c3b8b0be79aed5a9b"}
{"market":"0xab772601f501b265bfe8982eb61d5347ef9945de314bfdf4ac0189c288ffb0b3", "price_changes":[{"asset_id":"17924629579804316786455515989238352689210911545477836576430679697715946894553", "price":"0.01", "size":"13059.5", "side":"BUY", "hash":"014720159dcef3a2c3ac23791d1fa9b208518be6", "best_bid":"0.61", "best_ask":"0.62"}, {"asset_id":"12935926064588426924078449947177910958215776269411501731627440228801766632772", "price":"0.99", "size":"13059.5", "side":"SELL", "hash":"087f68f04ad23b72ae1675276e277429be20e8e7", "best_bid":"0.38", "best_ask":"0.39"}], "timestamp":"1784449237363", "event_type":"price_change"}
{"market":"0xab772601f501b265bfe8982eb61d5347ef9945de314bfdf4ac0189c288ffb0b3", "price_changes":[{"asset_id":"12935926064588426924078449947177910958215776269411501731627440228801766632772", "price":"0.36", "size":"216.77", "side":"BUY", "hash":"1ceb722657e6a153ac77af67881ef9c5798ff216", "best_bid":"0.38", "best_ask":"0.39"}, {"asset_id":"17924629579804316786455515989238352689210911545477836576430679697715946894553", "price":"0.64", "size":"216.77", "side":"SELL", "hash":"d51134b93d45c6fe7f63921027ee44545f4ffb14", "best_bid":"0.61", "best_ask":"0.62"}], "timestamp":"1784449237371", "event_type":"price_change"}
{"market":"0xab772601f501b265bfe8982eb61d5347ef9945de314bfdf4ac0189c288ffb0b3", "price_changes":[{"asset_id":"17924629579804316786455515989238352689210911545477836576430679697715946894553", "price":"0.01", "size":"12959.5", "side":"BUY", "hash":"aa047da76d816dc3c5685d5206d204fa787edd0e", "best_bid":"0.61", "best_ask":"0.62"}, {"asset_id":"12935926064588426924078449947177910958215776269411501731627440228801766632772", "price":"0.99", "size":"12959.5", "side":"SELL", "hash":"f7818c51aea14eb862f8e256f31f58fe205f20d0", "best_bid":"0.38", "best_ask":"0.39"}], "timestamp":"1784449237376", "event_type":"price_change"}
{"market":"0xab772601f501b265bfe8982eb61d5347ef9945de314bfdf4ac0189c288ffb0b3", "asset_id":"12935926064588426924078449947177910958215776269411501731627440228801766632772", "price":"0.39", "size":"12.820511", "fee_rate_bps":"0", "side":"BUY", "timestamp":"1784449237382", "event_type":"last_trade_price", "transaction_hash":"0x0da43b2578d74058b181832e48b7a1b9d40c89dcdb7d5d8fc2d9a586206f226d"}
{"market":"0xab772601f501b265bfe8982eb61d5347ef9945de314bfdf4ac0189c288ffb0b3", "price_changes":[{"asset_id":"12935926064588426924078449947177910958215776269411501731627440228801766632772", "price":"0.01", "size":"14884.14", "side":"BUY", "hash":"b6f9074f7546802dc97f5afc9ff3886256926760", "best_bid":"0.38", "best_ask":"0.39"}, {"asset_id":"17924629579804316786455515989238352689210911545477836576430679697715946894553", "price":"0.99", "size":"14884.14", "side":"SELL", "hash":"b7e3b9544f48a5c0995611526f580a83314cb281", "best_bid":"0.61", "best_ask":"0.62"}], "timestamp":"1784449237395", "event_type":"price_change"}
{"market":"0xab772601f501b265bfe8982eb61d5347ef9945de314bfdf4ac0189c288ffb0b3", "price_changes":[{"asset_id":"17924629579804316786455515989238352689210911545477836576430679697715946894553", "price":"0.01", "size":"12965.5", "side":"BUY", "hash":"1053d1c4b4cc6fde0726f8a81118a64f1a37854f", "best_bid":"0.61", "best_ask":"0.62"}, {"asset_id":"12935926064588426924078449947177910958215776269411501731627440228801766632772", "price":"0.99", "size":"12965.5", "side":"SELL", "hash":"d58787dceef5dafc931993b62ed72a3337832903", "best_bid":"0.38", "best_ask":"0.39"}], "timestamp":"1784449237399", "event_type":"price_change"}
{"market":"0xab772601f501b265bfe8982eb61d5347ef9945de314bfdf4ac0189c288ffb0b3", "price_changes":[{"asset_id":"17924629579804316786455515989238352689210911545477836576430679697715946894553", "price":"0.01", "size":"12970.5", "side":"BUY", "hash":"ebf6f2eb51698954d4b0385454ac018d45bb5593", "best_bid":"0.61", "best_ask":"0.62"}, {"asset_id":"12935926064588426924078449947177910958215776269411501731627440228801766632772", "price":"0.99", "size":"12970.5", "side":"SELL", "hash":"88daaf917d61204aba3929a879f83e99bee12ecc", "best_bid":"0.38", "best_ask":"0.39"}], "timestamp":"1784449237400", "event_type":"price_change"}
{"market":"0xab772601f501b265bfe8982eb61d5347ef9945de314bfdf4ac0189c288ffb0b3", "price_changes":[{"asset_id":"12935926064588426924078449947177910958215776269411501731627440228801766632772", "price":"0.24", "size":"152.22", "side":"BUY", "hash":"05cf113467fe809142e22b78d028143f0b351109", "best_bid":"0.38", "best_ask":"0.39"}, {"asset_id":"17924629579804316786455515989238352689210911545477836576430679697715946894553", "price":"0.76", "size":"152.22", "side":"SELL", "hash":"30d9d973485dd1bb2c22a5e881df0dff79527815", "best_bid":"0.61", "best_ask":"0.62"}], "timestamp":"1784449237406", "event_type":"price_change"}
{"market":"0xab772601f501b265bfe8982eb61d5347ef9945de314bfdf4ac0189c288ffb0b3", "price_changes":[{"asset_id":"17924629579804316786455515989238352689210911545477836576430679697715946894553", "price":"0.01", "size":"13070.5", "side":"BUY", "hash":"abec6260ab659325d2f5952ca8988c7cdd6bdadf", "best_bid":"0.61", "best_ask":"0.62"}, {"asset_id":"12935926064588426924078449947177910958215776269411501731627440228801766632772", "price":"0.99", "size":"13070.5", "side":"SELL", "hash":"f189e25d66fc151ba7206e82d2be4850ec7142b1", "best_bid":"0.38", "best_ask":"0.39"}], "timestamp":"1784449237410", "event_type":"price_change"}
{"market":"0xab772601f501b265bfe8982eb61d5347ef9945de314bfdf4ac0189c288ffb0b3", "price_changes":[{"asset_id":"17924629579804316786455515989238352689210911545477836576430679697715946894553", "price":"0.5", "size":"91", "side":"BUY", "hash":"051d3d147b05bc94995d2192bb04de42dab75cd4", "best_bid":"0.61", "best_ask":"0.62"}, {"asset_id":"12935926064588426924078449947177910958215776269411501731627440228801766632772", "price":"0.5", "size":"91", "side":"SELL", "hash":"19cb364e0233ef53be2497c4151c87c7d5aba52c", "best_bid":"0.38", "best_ask":"0.39"}], "timestamp":"1784449237411", "event_type":"price_change"}
{"market":"0xab772601f501b265bfe8982eb61d5347ef9945de314bfdf4ac0189c288ffb0b3", "price_changes":[{"asset_id":"12935926064588426924078449947177910958215776269411501731627440228801766632772", "price":"0.3", "size":"218.04", "side":"BUY", "hash":"5ca641869223fedb45a0267f61ce0823c754be5a", "best_bid":"0.38", "best_ask":"0.39"}, {"asset_id":"17924629579804316786455515989238352689210911545477836576430679697715946894553", "price":"0.7", "size":"218.04", "side":"SELL", "hash":"aec033dd3f4ddece74103eb449ea12b61025a809", "best_bid":"0.61", "best_ask":"0.62"}], "timestamp":"1784449237414", "event_type":"price_change"}
{"market":"0xab772601f501b265bfe8982eb61d5347ef9945de314bfdf4ac0189c288ffb0b3", "price_changes":[{"asset_id":"17924629579804316786455515989238352689210911545477836576430679697715946894553", "price":"0.01", "size":"13170.5", "side":"BUY", "hash":"556edc919996a19e556dcdc426a548db9928eb46", "best_bid":"0.61", "best_ask":"0.62"}, {"asset_id":"12935926064588426924078449947177910958215776269411501731627440228801766632772", "price":"0.99", "size":"13170.5", "side":"SELL", "hash":"45ce2fe269868665a1d3c34754e5ac735b2716b9", "best_bid":"0.38", "best_ask":"0.39"}], "timestamp":"1784449237417", "event_type":"price_change"}
{"market":"0xab772601f501b265bfe8982eb61d5347ef9945de314bfdf4ac0189c288ffb0b3", "price_changes":[{"asset_id":"12935926064588426924078449947177910958215776269411501731627440228801766632772", "price":"0.01", "size":"14879.14", "side":"BUY", "hash":"8ca9aba04bbe2bed4c2ae2d2e268f11a063953f6", "best_bid":"0.38", "best_ask":"0.39"}, {"asset_id":"17924629579804316786455515989238352689210911545477836576430679697715946894553", "price":"0.99", "size":"14879.14", "side":"SELL", "hash":"1c5753ab88441b657334f48fc1fa9a15bfe3bfc3", "best_bid":"0.61", "best_ask":"0.62"}], "timestamp":"1784449237419", "event_type":"price_change"}
{"market":"0xab772601f501b265bfe8982eb61d5347ef9945de314bfdf4ac0189c288ffb0b3", "price_changes":[{"asset_id":"12935926064588426924078449947177910958215776269411501731627440228801766632772", "price":"0.01", "size":"14874.14", "side":"BUY", "hash":"23af2e07d67897e60a152ce994e8cddd8649f6fc", "best_bid":"0.38", "best_ask":"0.39"}, {"asset_id":"17924629579804316786455515989238352689210911545477836576430679697715946894553", "price":"0.99", "size":"14874.14", "side":"SELL", "hash":"58ece94527a2f54ffc4920225a4c5eaf7be02ac4", "best_bid":"0.61", "best_ask":"0.62"}], "timestamp":"1784449237419", "event_type":"price_change"}
{"market":"0xab772601f501b265bfe8982eb61d5347ef9945de314bfdf4ac0189c288ffb0b3", "price_changes":[{"asset_id":"12935926064588426924078449947177910958215776269411501731627440228801766632772", "price":"0.01", "size":"14869.14", "side":"BUY", "hash":"0c23bdd0628692fbcb1fad88cd759b9b1dd2656b", "best_bid":"0.38", "best_ask":"0.39"}, {"asset_id":"17924629579804316786455515989238352689210911545477836576430679697715946894553", "price":"0.99", "size":"14869.14", "side":"SELL", "hash":"d188089d2c9cda5441b7f1b46c223ee662f0107a", "best_bid":"0.61", "best_ask":"0.62"}], "timestamp":"1784449237420", "event_type":"price_change"}
{"market":"0xab772601f501b265bfe8982eb61d5347ef9945de314bfdf4ac0189c288ffb0b3", "price_changes":[{"asset_id":"12935926064588426924078449947177910958215776269411501731627440228801766632772", "price":"0.32", "size":"244.69", "side":"BUY", "hash":"97ef9a3f7f2b4756ca6319f8c2ae92811b78aa39", "best_bid":"0.38", "best_ask":"0.39"}, {"asset_id":"17924629579804316786455515989238352689210911545477836576430679697715946894553", "price":"0.68", "size":"244.69", "side":"SELL", "hash":"f02fa07822e7653c9ba34d519f97f4164ace27f9", "best_bid":"0.61", "best_ask":"0.62"}], "timestamp":"1784449237421", "event_type":"price_change"}
{"market":"0xab772601f501b265bfe8982eb61d5347ef9945de314bfdf4ac0189c288ffb0b3", "price_changes":[{"asset_id":"17924629579804316786455515989238352689210911545477836576430679697715946894553", "price":"0.01", "size":"13165.5", "side":"BUY", "hash":"c9c6820e02a48403bf091742563f0b45633f5758", "best_bid":"0.61", "best_ask":"0.62"}, {"asset_id":"12935926064588426924078449947177910958215776269411501731627440228801766632772", "price":"0.99", "size":"13165.5", "side":"SELL", "hash":"7531dbf264d5589cce3b9664a397620bd3b7fcd1", "best_bid":"0.38", "best_ask":"0.39"}], "timestamp":"1784449237427", "event_type":"price_change"}
{"market":"0xab772601f501b265bfe8982eb61d5347ef9945de314bfdf4ac0189c288ffb0b3", "price_changes":[{"asset_id":"12935926064588426924078449947177910958215776269411501731627440228801766632772", "price":"0.01", "size":"14874.14", "side":"BUY", "hash":"5e7865188b0f4bf6b4b5132107d0f730f8fadb93", "best_bid":"0.38", "best_ask":"0.39"}, {"asset_id":"17924629579804316786455515989238352689210911545477836576430679697715946894553", "price":"0.99", "size":"14874.14", "side":"SELL", "hash":"5eb46d68612ddfb9ae0f96b334a446760a7a8812", "best_bid":"0.61", "best_ask":"0.62"}], "timestamp":"1784449237428", "event_type":"price_change"}
{"market":"0xab772601f501b265bfe8982eb61d5347ef9945de314bfdf4ac0189c288ffb0b3", "price_changes":[{"asset_id":"12935926064588426924078449947177910958215776269411501731627440228801766632772", "price":"0.01", "size":"14879.14", "side":"BUY", "hash":"017fed437eadf1d66823fdb0604555db3a360398", "best_bid":"0.38", "best_ask":"0.39"}, {"asset_id":"17924629579804316786455515989238352689210911545477836576430679697715946894553", "price":"0.99", "size":"14879.14", "side":"SELL", "hash":"3ba89a866a6b2bd3c97a740aadcec28c03405cfb", "best_bid":"0.61", "best_ask":"0.62"}], "timestamp":"1784449237430", "event_type":"price_change"}
{"market":"0xab772601f501b265bfe8982eb61d5347ef9945de314bfdf4ac0189c288ffb0b3", "price_changes":[{"asset_id":"17924629579804316786455515989238352689210911545477836576430679697715946894553", "price":"0.01", "size":"13065.5", "side":"BUY", "hash":"664dae5e8c704388829aa857beff0d4ce184d31f", "best_bid":"0.61", "best_ask":"0.62"}, {"asset_id":"12935926064588426924078449947177910958215776269411501731627440228801766632772", "price":"0.99", "size":"13065.5", "side":"SELL", "hash":"315629738243742bfc8175b336aa36c95ee649a1", "best_bid":"0.38", "best_ask":"0.39"}], "timestamp":"1784449237430", "event_type":"price_change"}
{"market":"0xab772601f501b265bfe8982eb61d5347ef9945de314bfdf4ac0189c288ffb0b3", "price_changes":[{"asset_id":"12935926064588426924078449947177910958215776269411501731627440228801766632772", "price":"0.01", "size":"14884.14", "side":"BUY", "hash":"f9f379648955bfbec29f54feb3bd094f6f806449", "best_bid":"0.38", "best_ask":"0.39"}, {"asset_id":"17924629579804316786455515989238352689210911545477836576430679697715946894553", "price":"0.99", "size":"14884.14", "side":"SELL", "hash":"d0dac148f6474e5877817f9f59f15326a4b786f9", "best_bid":"0.61", "best_ask":"0.62"}], "timestamp":"1784449237430", "event_type":"price_change"}
{"market":"0xab772601f501b265bfe8982eb61d5347ef9945de314bfdf4ac0189c288ffb0b3", "price_changes":[{"asset_id":"17924629579804316786455515989238352689210911545477836576430679697715946894553", "price":"0.02", "size":"3890.25", "side":"BUY", "hash":"1fbaa4453e967d0e9374e266220ee369fef7a8ab", "best_bid":"0.61", "best_ask":"0.62"}, {"asset_id":"12935926064588426924078449947177910958215776269411501731627440228801766632772", "price":"0.98", "size":"3890.25", "side":"SELL", "hash":"c7fab8b69e446e244860c69c7ca33418525e992e", "best_bid":"0.38", "best_ask":"0.39"}], "timestamp":"1784449237431", "event_type":"price_change"}
{"market":"0xab772601f501b265bfe8982eb61d5347ef9945de314bfdf4ac0189c288ffb0b3", "price_changes":[{"asset_id":"17924629579804316786455515989238352689210911545477836576430679697715946894553", "price":"0.01", "size":"13059.5", "side":"BUY", "hash":"7469fbc138005b399c65c56c1940190e599d3201", "best_bid":"0.61", "best_ask":"0.62"}, {"asset_id":"12935926064588426924078449947177910958215776269411501731627440228801766632772", "price":"0.99", "size":"13059.5", "side":"SELL", "hash":"8ae64ac68f4563a36cbd7fbf4c4f99410a62d359", "best_bid":"0.38", "best_ask":"0.39"}], "timestamp":"1784449237432", "event_type":"price_change"}
{"market":"0xab772601f501b265bfe8982eb61d5347ef9945de314bfdf4ac0189c288ffb0b3", "price_changes":[{"asset_id":"12935926064588426924078449947177910958215776269411501731627440228801766632772", "price":"0.27", "size":"148.5", "side":"BUY", "hash":"4ac013243577c383e157b64ce8729488dafbf9fa", "best_bid":"0.38", "best_ask":"0.39"}, {"asset_id":"17924629579804316786455515989238352689210911545477836576430679697715946894553", "price":"0.73", "size":"148.5", "side":"SELL", "hash":"d81812f7f7a803785537789cdf63c087eff90ef4", "best_bid":"0.61", "best_ask":"0.62"}], "timestamp":"1784449237435", "event_type":"price_change"}
{"market":"0xab772601f501b265bfe8982eb61d5347ef9945de314bfdf4ac0189c288ffb0b3", "price_changes":[{"asset_id":"12935926064588426924078449947177910958215776269411501731627440228801766632772", "price":"0.36", "size":"211.77", "side":"BUY", "hash":"d49b703557e055d8df55bc017f69bf707d7c6ea4", "best_bid":"0.38", "best_ask":"0.39"}, {"asset_id":"17924629579804316786455515989238352689210911545477836576430679697715946894553", "price":"0.64", "size":"211.77", "side":"SELL", "hash":"5a160e6a62aae81bd6a478f8714bd42621ccb57b", "best_bid":"0.61", "best_ask":"0.62"}], "timestamp":"1784449237448", "event_type":"price_change"}
{"market":"0xab772601f501b265bfe8982eb61d5347ef9945de314bfdf4ac0189c288ffb0b3", "price_changes":[{"asset_id":"17924629579804316786455515989238352689210911545477836576430679697715946894553", "price":"0.01", "size":"12959.5", "side":"BUY", "hash":"1b1e974cd14809698196df55b484270671eefe09", "best_bid":"0.61", "best_ask":"0.62"}, {"asset_id":"12935926064588426924078449947177910958215776269411501731627440228801766632772", "price":"0.99", "size":"12959.5", "side":"SELL", "hash":"df1cd014ba51a6a15d75847bbcf3d642ce294537", "best_bid":"0.38", "best_ask":"0.39"}], "timestamp":"1784449237449", "event_type":"price_change"}
{"market":"0xab772601f501b265bfe8982eb61d5347ef9945de314bfdf4ac0189c288ffb0b3", "price_changes":[{"asset_id":"17924629579804316786455515989238352689210911545477836576430679697715946894553", "price":"0.59", "size":"335.34", "side":"BUY", "hash":"f6183513d6530915f8f687cd88fa9807700992bb", "best_bid":"0.61", "best_ask":"0.62"}, {"asset_id":"12935926064588426924078449947177910958215776269411501731627440228801766632772", "price":"0.41", "size":"335.34", "side":"SELL", "hash":"3d1d22efd1b0d03306e6d608707c3b948ef8d9b9", "best_bid":"0.38", "best_ask":"0.39"}], "timestamp":"1784449237451", "event_type":"price_change"}
{"market":"0xab772601f501b265bfe8982eb61d5347ef9945de314bfdf4ac0189c288ffb0b3", "price_changes":[{"asset_id":"17924629579804316786455515989238352689210911545477836576430679697715946894553", "price":"0.01", "size":"12964.51", "side":"BUY", "hash":"bd46be2770bd260707f78adb8d9e36f880a6a51c", "best_bid":"0.61", "best_ask":"0.62"}, {"asset_id":"12935926064588426924078449947177910958215776269411501731627440228801766632772", "price":"0.99", "size":"12964.51", "side":"SELL", "hash":"9c21803965f64ee58f4eea7a227fdd220334ad19", "best_bid":"0.38", "best_ask":"0.39"}], "timestamp":"1784449237459", "event_type":"price_change"}
{"market":"0xab772601f501b265bfe8982eb61d5347ef9945de314bfdf4ac0189c288ffb0b3", "price_changes":[{"asset_id":"17924629579804316786455515989238352689210911545477836576430679697715946894553", "price":"0.01", "size":"12959.51", "side":"BUY", "hash":"ae4aa4f1e3e294c6f0de29fba62e8532fb6dd2e7", "best_bid":"0.61", "best_ask":"0.62"}, {"asset_id":"12935926064588426924078449947177910958215776269411501731627440228801766632772", "price":"0.99", "size":"12959.51", "side":"SELL", "hash":"d96a03d800a97cee620df1bb122e4920c54c0a11", "best_bid":"0.38", "best_ask":"0.39"}], "timestamp":"1784449237463", "event_type":"price_change"}
{"market":"0xab772601f501b265bfe8982eb61d5347ef9945de314bfdf4ac0189c288ffb0b3", "price_changes":[{"asset_id":"17924629579804316786455515989238352689210911545477836576430679697715946894553", "price":"0.39", "size":"69.8", "side":"BUY", "hash":"0fd4c5121ce64832dbf91b711ffb43e87c5f8b0a", "best_bid":"0.61", "best_ask":"0.62"}, {"asset_id":"12935926064588426924078449947177910958215776269411501731627440228801766632772", "price":"0.61", "size":"69.8", "side":"SELL", "hash":"039759b81e5355f3b014d30cb7bf4ce69cede1ff", "best_bid":"0.38", "best_ask":"0.39"}], "timestamp":"1784449237466", "event_type":"price_change"}
{"market":"0xab772601f501b265bfe8982eb61d5347ef9945de314bfdf4ac0189c288ffb0b3", "price_changes":[{"asset_id":"12935926064588426924078449947177910958215776269411501731627440228801766632772", "price":"0.34", "size":"88.96", "side":"BUY", "hash":"e24fcb6b62a53c693eff0b8c633ca36018a38331", "best_bid":"0.38", "best_ask":"0.39"}, {"asset_id":"17924629579804316786455515989238352689210911545477836576430679697715946894553", "price":"0.66", "size":"88.96", "side":"SELL", "hash":"6b1b2ee7a6915165ae2c1af42b3f1f6b56c0be4e", "best_bid":"0.61", "best_ask":"0.62"}], "timestamp":"1784449237474", "event_type":"price_change"}
{"market":"0xab772601f501b265bfe8982eb61d5347ef9945de314bfdf4ac0189c288ffb0b3", "price_changes":[{"asset_id":"12935926064588426924078449947177910958215776269411501731627440228801766632772", "price":"0.24", "size":"162.22", "side":"BUY", "hash":"c1d684df9d9490e9fed9245aa857e04dca675fa0", "best_bid":"0.38", "best_ask":"0.39"}, {"asset_id":"17924629579804316786455515989238352689210911545477836576430679697715946894553", "price":"0.76", "size":"162.22", "side":"SELL", "hash":"b9bad3bafc5881e0ec365654ce55d2a368deb66c", "best_bid":"0.61", "best_ask":"0.62"}], "timestamp":"1784449237476", "event_type":"price_change"}
{"market":"0xab772601f501b265bfe8982eb61d5347ef9945de314bfdf4ac0189c288ffb0b3", "price_changes":[{"asset_id":"17924629579804316786455515989238352689210911545477836576430679697715946894553", "price":"0.61", "size":"370.55", "side":"BUY", "hash":"0703f63f9f0cc90f15fdc1d1d19dbdb0a5e955d7", "best_bid":"0.61", "best_ask":"0.62"}, {"asset_id":"12935926064588426924078449947177910958215776269411501731627440228801766632772", "price":"0.39", "size":"370.55", "side":"SELL", "hash":"2fa6c09b0618aed38b604022978b72a4121d09ec", "best_bid":"0.38", "best_ask":"0.39"}], "timestamp":"1784449237482", "event_type":"price_change"}
{"market":"0xab772601f501b265bfe8982eb61d5347ef9945de314bfdf4ac0189c288ffb0b3", "price_changes":[{"asset_id":"12935926064588426924078449947177910958215776269411501731627440228801766632772", "price":"0.3", "size":"213.04", "side":"BUY", "hash":"17147483d8f468e9e5f5ff4f99b51404ea5d9959", "best_bid":"0.38", "best_ask":"0.39"}, {"asset_id":"17924629579804316786455515989238352689210911545477836576430679697715946894553", "price":"0.7", "size":"213.04", "side":"SELL", "hash":"1fb27a5ffd81a682d411a0e409806c35488d09c6", "best_bid":"0.61", "best_ask":"0.62"}], "timestamp":"1784449237484", "event_type":"price_change"}
{"market":"0xab772601f501b265bfe8982eb61d5347ef9945de314bfdf4ac0189c288ffb0b3", "price_changes":[{"asset_id":"17924629579804316786455515989238352689210911545477836576430679697715946894553", "price":"0.02", "size":"3885.25", "side":"BUY", "hash":"4d5e738c14b3ab85934c13e01d60a9cb6abd106a", "best_bid":"0.61", "best_ask":"0.62"}, {"asset_id":"12935926064588426924078449947177910958215776269411501731627440228801766632772", "price":"0.98", "size":"3885.25", "side":"SELL", "hash":"45513bd624936fe76d005414edfce7f98ed477cf", "best_bid":"0.38", "best_ask":"0.39"}], "timestamp":"1784449237485", "event_type":"price_change"}
{"market":"0xab772601f501b265bfe8982eb61d5347ef9945de314bfdf4ac0189c288ffb0b3", "price_changes":[{"asset_id":"17924629579804316786455515989238352689210911545477836576430679697715946894553", "price":"0.01", "size":"12954.5", "side":"BUY", "hash":"97f7774741a38d2e3a34de5b87bb5fdb03c6d579", "best_bid":"0.61", "best_ask":"0.62"}, {"asset_id":"12935926064588426924078449947177910958215776269411501731627440228801766632772", "price":"0.99", "size":"12954.5", "side":"SELL", "hash":"c2f29f148aa8c3aeb26c09d6f9af860fbdbbecdc", "best_bid":"0.38", "best_ask":"0.39"}], "timestamp":"1784449237486", "event_type":"price_change"}
{"market":"0xab772601f501b265bfe8982eb61d5347ef9945de314bfdf4ac0189c288ffb0b3", "price_changes":[{"asset_id":"17924629579804316786455515989238352689210911545477836576430679697715946894553", "price":"0.51", "size":"106", "side":"BUY", "hash":"4c49f5575e5bd397bf17e5a14388cc4afd35184b", "best_bid":"0.61", "best_ask":"0.62"}, {"asset_id":"12935926064588426924078449947177910958215776269411501731627440228801766632772", "price":"0.49", "size":"106", "side":"SELL", "hash":"66886b3d21d1e70f64e42c41da1c7a9596a41f99", "best_bid":"0.38", "best_ask":"0.39"}], "timestamp":"1784449237489", "event_type":"price_change"}
{"market":"0xab772601f501b265bfe8982eb61d5347ef9945de314bfdf4ac0189c288ffb0b3", "price_changes":[{"asset_id":"17924629579804316786455515989238352689210911545477836576430679697715946894553", "price":"0.01", "size":"13054.5", "side":"BUY", "hash":"b99b04aec92ea3e959d5bcef549d61b2b35a83e2", "best_bid":"0.61", "best_ask":"0.62"}, {"asset_id":"12935926064588426924078449947177910958215776269411501731627440228801766632772", "price":"0.99", "size":"13054.5", "side":"SELL", "hash":"e243bf3999308f132b73d10699718ea167294ec3", "best_bid":"0.38", "best_ask":"0.39"}], "timestamp":"1784449237497", "event_type":"price_change"}
{"market":"0xab772601f501b265bfe8982eb61d5347ef9945de314bfdf4ac0189c288ffb0b3", "price_changes":[{"asset_id":"17924629579804316786455515989238352689210911545477836576430679697715946894553", "price":"0.01", "size":"13060.5", "side":"BUY", "hash":"40662320d7ebdd492c0423806f14022c7a2e25a3", "best_bid":"0.61", "best_ask":"0.62"}, {"asset_id":"12935926064588426924078449947177910958215776269411501731627440228801766632772", "price":"0.99", "size":"13060.5", "side":"SELL", "hash":"0c285a75bb8833c67e0a2212a69feff48ac058c1", "best_bid":"0.38", "best_ask":"0.39"}], "timestamp":"1784449237500", "event_type":"price_change"}
{"market":"0xab772601f501b265bfe8982eb61d5347ef9945de314bfdf4ac0189c288ffb0b3", "price_changes":[{"asset_id":"17924629579804316786455515989238352689210911545477836576430679697715946894553", "price":"0.59", "size":"340.34", "side":"BUY", "hash":"afba07b5e8ec57c753e0b95ef5e78bb766fc83ba", "best_bid":"0.61", "best_ask":"0.62"}, {"asset_id":"12935926064588426924078449947177910958215776269411501731627440228801766632772", "price":"0.41", "size":"340.34", "side":"SELL", "hash":"f0330492a446062ca61cce51a0c66c894c8d17e0", "best_bid":"0.38", "best_ask":"0.39"}], "timestamp":"1784449237513", "event_type":"price_change"}
{"market":"0xab772601f501b265bfe8982eb61d5347ef9945de314bfdf4ac0189c288ffb0b3", "price_changes":[{"asset_id":"17924629579804316786455515989238352689210911545477836576430679697715946894553", "price":"0.01", "size":"13054.5", "side":"BUY", "hash":"85ba6f2d42801ba44c031390c3b892eeb4f8f124", "best_bid":"0.61", "best_ask":"0.62"}, {"asset_id":"12935926064588426924078449947177910958215776269411501731627440228801766632772", "price":"0.99", "size":"13054.5", "side":"SELL", "hash":"64597604f49ed9e500be2d7dadf26e5c4276541f", "best_bid":"0.38", "best_ask":"0.39"}], "timestamp":"1784449237529", "event_type":"price_change"}
{"market":"0xab772601f501b265bfe8982eb61d5347ef9945de314bfdf4ac0189c288ffb0b3", "price_changes":[{"asset_id":"17924629579804316786455515989238352689210911545477836576430679697715946894553", "price":"0.01", "size":"12954.5", "side":"BUY", "hash":"16fdc732698bda847de7c824409d4df31a4245a9", "best_bid":"0.61", "best_ask":"0.62"}, {"asset_id":"12935926064588426924078449947177910958215776269411501731627440228801766632772", "price":"0.99", "size":"12954.5", "side":"SELL", "hash":"312ca748c64f295617d59ed9067b696e1f92473b", "best_bid":"0.38", "best_ask":"0.39"}], "timestamp":"1784449237529", "event_type":"price_change"}
{"market":"0xab772601f501b265bfe8982eb61d5347ef9945de314bfdf4ac0189c288ffb0b3", "price_changes":[{"asset_id":"12935926064588426924078449947177910958215776269411501731627440228801766632772", "price":"0.1", "size":"561.2", "side":"BUY", "hash":"c8cb94b8f53a91b6c546b98c325cb73984798062", "best_bid":"0.38", "best_ask":"0.39"}, {"asset_id":"17924629579804316786455515989238352689210911545477836576430679697715946894553", "price":"0.9", "size":"561.2", "side":"SELL", "hash":"2c81441469b76440fb9bb07fc9d346820c739593", "best_bid":"0.61", "best_ask":"0.62"}], "timestamp":"1784449237537", "event_type":"price_change"}
{"market":"0xab772601f501b265bfe8982eb61d5347ef9945de314bfdf4ac0189c288ffb0b3", "price_changes":[{"asset_id":"17924629579804316786455515989238352689210911545477836576430679697715946894553", "price":"0.01", "size":"12959.5", "side":"BUY", "hash":"234f9aa8a7e8fe23490d23dd2008fab8799c4bcc", "best_bid":"0.61", "best_ask":"0.62"}, {"asset_id":"12935926064588426924078449947177910958215776269411501731627440228801766632772", "price":"0.99", "size":"12959.5", "side":"SELL", "hash":"544114b6e759887987697b51e2267dc45ab99828", "best_bid":"0.38", "best_ask":"0.39"}], "timestamp":"1784449237539", "event_type":"price_change"}
{"market":"0xab772601f501b265bfe8982eb61d5347ef9945de314bfdf4ac0189c288ffb0b3", "price_changes":[{"asset_id":"17924629579804316786455515989238352689210911545477836576430679697715946894553", "price":"0.59", "size":"335.34", "side":"BUY", "hash":"e308c2e77531ffcfa210b742401d1c9b543a8f27", "best_bid":"0.61", "best_ask":"0.62"}, {"asset_id":"12935926064588426924078449947177910958215776269411501731627440228801766632772", "price":"0.41", "size":"335.34", "side":"SELL", "hash":"baa3b7804872fab55aae00ed68d006d487366159", "best_bid":"0.38", "best_ask":"0.39"}], "timestamp":"1784449237548", "event_type":"price_change"}
{"market":"0xab772601f501b265bfe8982eb61d5347ef9945de314bfdf4ac0189c288ffb0b3", "price_changes":[{"asset_id":"17924629579804316786455515989238352689210911545477836576430679697715946894553", "price":"0.57", "size":"169", "side":"BUY", "hash":"146d793b7523e2823bd93870f7d7d76d1d3cb3f5", "best_bid":"0.61", "best_ask":"0.62"}, {"asset_id":"12935926064588426924078449947177910958215776269411501731627440228801766632772", "price":"0.43", "size":"169", "side":"SELL", "hash":"dbc46f4b492bd80106ce4964bab30cb89d3f4a6d", "best_bid":"0.38", "best_ask":"0.39"}], "timestamp":"1784449237550", "event_type":"price_change"}
{"market":"0xab772601f501b265bfe8982eb61d5347ef9945de314bfdf4ac0189c288ffb0b3", "price_changes":[{"asset_id":"12935926064588426924078449947177910958215776269411501731627440228801766632772", "price":"0.34", "size":"94.96", "side":"BUY", "hash":"ee80ce630696dc56a0e6b3724388d574f63912ff", "best_bid":"0.38", "best_ask":"0.39"}, {"asset_id":"17924629579804316786455515989238352689210911545477836576430679697715946894553", "price":"0.66", "size":"94.96", "side":"SELL", "hash":"0e0e00a8a17b526c93067b52d371aec8e4965bfc", "best_bid":"0.61", "best_ask":"0.62"}], "timestamp":"1784449237550", "event_type":"price_change"}
{"market":"0xab772601f501b265bfe8982eb61d5347ef9945de314bfdf4ac0189c288ffb0b3", "price_changes":[{"asset_id":"17924629579804316786455515989238352689210911545477836576430679697715946894553", "price":"0.03", "size":"2255.95", "side":"BUY", "hash":"38fd166ba32d8026b6505b2c39dcd998abe1f012", "best_bid":"0.61", "best_ask":"0.62"}, {"asset_id":"12935926064588426924078449947177910958215776269411501731627440228801766632772", "price":"0.97", "size":"2255.95", "side":"SELL", "hash":"2112e4d0e2b5a4f648bb9484e9ad17caca434cac", "best_bid":"0.38", "best_ask":"0.39"}], "timestamp":"1784449237564", "event_type":"price_change"}
{"market":"0xab772601f501b265bfe8982eb61d5347ef9945de314bfdf4ac0189c288ffb0b3", "price_changes":[{"asset_id":"17924629579804316786455515989238352689210911545477836576430679697715946894553", "price":"0.01", "size":"12954.5", "side":"BUY", "hash":"3578e6831fd9edf5f7bdecaf7b6fa4d0e649be4c", "best_bid":"0.61", "best_ask":"0.62"}, {"asset_id":"12935926064588426924078449947177910958215776269411501731627440228801766632772", "price":"0.99", "size":"12954.5", "side":"SELL", "hash":"fa2f8be09dff538e2cabd8c411f924fed17f1717", "best_bid":"0.38", "best_ask":"0.39"}], "timestamp":"1784449237565", "event_type":"price_change"}
{"market":"0xab772601f501b265bfe8982eb61d5347ef9945de314bfdf4ac0189c288ffb0b3", "price_changes":[{"asset_id":"12935926064588426924078449947177910958215776269411501731627440228801766632772", "price":"0.01", "size":"14889.14", "side":"BUY", "hash":"674b218f9e44fe411586b515ef6c965c8e50afe7", "best_bid":"0.38", "best_ask":"0.39"}, {"asset_id":"17924629579804316786455515989238352689210911545477836576430679697715946894553", "price":"0.99", "size":"14889.14", "side":"SELL", "hash":"a9e3b1a5d05d24d47cdf181249784c1c4b33682a", "best_bid":"0.61", "best_ask":"0.62"}], "timestamp":"1784449237573", "event_type":"price_change"}
{"market":"0xab772601f501b265bfe8982eb61d5347ef9945de314bfdf4ac0189c288ffb0b3", "price_changes":[{"asset_id":"17924629579804316786455515989238352689210911545477836576430679697715946894553", "price":"0.01", "size":"12959.5", "side":"BUY", "hash":"01307d47ad546068a02ed19a8e9108b98c4d58c4", "best_bid":"0.61", "best_ask":"0.62"}, {"asset_id":"12935926064588426924078449947177910958215776269411501731627440228801766632772", "price":"0.99", "size":"12959.5", "side":"SELL", "hash":"3615c42e62b511321246dc219b1c00e217145c7d", "best_bid":"0.38", "best_ask":"0.39"}], "timestamp":"1784449237573", "event_type":"price_change"}
{"market":"0xab772601f501b265bfe8982eb61d5347ef9945de314bfdf4ac0189c288ffb0b3", "price_changes":[{"asset_id":"17924629579804316786455515989238352689210911545477836576430679697715946894553", "price":"0.01", "size":"12964.5", "side":"BUY", "hash":"6e15b71dfbf96eeebacfc7176cd799dbdd73dd78", "best_bid":"0.61", "best_ask":"0.62"}, {"asset_id":"12935926064588426924078449947177910958215776269411501731627440228801766632772", "price":"0.99", "size":"12964.5", "side":"SELL", "hash":"1ee59cbf443f4292e3cfeb8aabfc6cc764c287ae", "best_bid":"0.38", "best_ask":"0.39"}], "timestamp":"1784449237574", "event_type":"price_change"}
{"market":"0xab772601f501b265bfe8982eb61d5347ef9945de314bfdf4ac0189c288ffb0b3", "price_changes":[{"asset_id":"12935926064588426924078449947177910958215776269411501731627440228801766632772", "price":"0.38", "size":"37.05", "side":"BUY", "hash":"6df969c40fd331607bc678e7beb12dacbe89a76f", "best_bid":"0.38", "best_ask":"0.39"}, {"asset_id":"17924629579804316786455515989238352689210911545477836576430679697715946894553", "price":"0.62", "size":"37.05", "side":"SELL", "hash":"1c4ca6d0e7a61296eda7412c528d8415aef06546", "best_bid":"0.61", "best_ask":"0.62"}], "timestamp":"1784449237574", "event_type":"price_change"}
{"market":"0xab772601f501b265bfe8982eb61d5347ef9945de314bfdf4ac0189c288ffb0b3", "price_changes":[{"asset_id":"17924629579804316786455515989238352689210911545477836576430679697715946894553", "price":"0.01", "size":"12969.5", "side":"BUY", "hash":"e2a9af184ce90f3a29d9e80b5fa534b93ee883f9", "best_bid":"0.61", "best_ask":"0.62"}, {"asset_id":"12935926064588426924078449947177910958215776269411501731627440228801766632772", "price":"0.99", "size":"12969.5", "side":"SELL", "hash":"93006887a74f973d8aad1a846ab33b9171d087c2", "best_bid":"0.38", "best_ask":"0.39"}], "timestamp":"1784449237575", "event_type":"price_change"}
{"market":"0xab772601f501b265bfe8982eb61d5347ef9945de314bfdf4ac0189c288ffb0b3", "price_changes":[{"asset_id":"12935926064588426924078449947177910958215776269411501731627440228801766632772", "price":"0.01", "size":"14894.14", "side":"BUY", "hash":"a8c3d7e78f3dcda63e68f38a20490c3c79ba9610", "best_bid":"0.38", "best_ask":"0.39"}, {"asset_id":"17924629579804316786455515989238352689210911545477836576430679697715946894553", "price":"0.99", "size":"14894.14", "side":"SELL", "hash":"1dfb1b033670d914213ba17d272b9caf6669cb87", "best_bid":"0.61", "best_ask":"0.62"}], "timestamp":"1784449237575", "event_type":"price_change"}
{"market":"0xab772601f501b265bfe8982eb61d5347ef9945de314bfdf4ac0189c288ffb0b3", "price_changes":[{"asset_id":"12935926064588426924078449947177910958215776269411501731627440228801766632772", "price":"0.01", "size":"14899.14", "side":"BUY", "hash":"1e9b0b21ce928f345065d46b1e305273c6502290", "best_bid":"0.38", "best_ask":"0.39"}, {"asset_id":"17924629579804316786455515989238352689210911545477836576430679697715946894553", "price":"0.99", "size":"14899.14", "side":"SELL", "hash":"48f3a3ee5295657846a0406ef7951f57fef9981c", "best_bid":"0.61", "best_ask":"0.62"}], "timestamp":"1784449237576", "event_type":"price_change"}
{"market":"0xab772601f501b265bfe8982eb61d5347ef9945de314bfdf4ac0189c288ffb0b3", "price_changes":[{"asset_id":"17924629579804316786455515989238352689210911545477836576430679697715946894553", "price":"0.01", "size":"13069.5", "side":"BUY", "hash":"db55b80624da9127d8f43916f2ce2790f366e8f1", "best_bid":"0.61", "best_ask":"0.62"}, {"asset_id":"12935926064588426924078449947177910958215776269411501731627440228801766632772", "price":"0.99", "size":"13069.5", "side":"SELL", "hash":"2eacb33346d1d2f89d051a1983ef3153d9186935", "best_bid":"0.38", "best_ask":"0.39"}], "timestamp":"1784449237576", "event_type":"price_change"}
{"market":"0xab772601f501b265bfe8982eb61d5347ef9945de314bfdf4ac0189c288ffb0b3", "price_changes":[{"asset_id":"12935926064588426924078449947177910958215776269411501731627440228801766632772", "price":"0.38", "size":"35.05", "side":"BUY", "hash":"a49c090b467d9ade6d1648052c0266844b1784a5", "best_bid":"0.38", "best_ask":"0.39"}, {"asset_id":"17924629579804316786455515989238352689210911545477836576430679697715946894553", "price":"0.62", "size":"35.05", "side":"SELL", "hash":"ad7e53280e40841151fe4ac2e1286e557517f85d", "best_bid":"0.61", "best_ask":"0.62"}], "timestamp":"1784449237589", "event_type":"price_change"}
{"market":"0xab772601f501b265bfe8982eb61d5347ef9945de314bfdf4ac0189c288ffb0b3", "asset_id":"12935926064588426924078449947177910958215776269411501731627440228801766632772", "bids":[{"price":"0.01", "size":"14899.14"}, {"price":"0.02", "size":"3964.52"}, {"price":"0.03", "size":"2179.29"}, {"price":"0.04", "size":"1215.1"}, {"price":"0.05", "size":"1742.19"}, {"price":"0.06", "size":"1122.02"}, {"price":"0.07", "size":"953.49"}, {"price":"0.08", "size":"1234.38"}, {"price":"0.09", "size":"791.7"}, {"price":"0.1", "size":"561.2"}, {"price":"0.11", "size":"1502.1"}, {"price":"0.12", "size":"1102.45"}, {"price":"0.13", "size":"139.4"}, {"price":"0.14", "size":"281.8"}, {"price":"0.15", "size":"444.04"}, {"price":"0.16", "size":"147.1"}, {"price":"0.17", "size":"207.17"}, {"price":"0.18", "size":"150.7"}, {"price":"0.19", "size":"128.89"}, {"price":"0.2", "size":"246.2"}, {"price":"0.21", "size":"636.8"}, {"price":"0.22", "size":"135.5"}, {"price":"0.23", "size":"127.3"}, {"price":"0.24", "size":"162.22"}, {"price":"0.25", "size":"162.2"}, {"price":"0.26", "size":"134.3"}, {"price":"0.27", "size":"148.5"}, {"price":"0.28", "size":"151.88"}, {"price":"0.29", "size":"222.52"}, {"price":"0.3", "size":"213.04"}, {"price":"0.31", "size":"560.01"}, {"price":"0.32", "size":"244.69"}, {"price":"0.33", "size":"134.65"}, {"price":"0.34", "size":"94.96"}, {"price":"0.35", "size":"106.2"}, {"price":"0.36", "size":"211.77"}, {"price":"0.37", "size":"105.91"}, {"price":"0.38", "size":"35.05"}], "asks":[{"price":"0.99", "size":"13069.5"}, {"price":"0.98", "size":"3885.25"}, {"price":"0.97", "size":"2255.95"}, {"price":"0.96", "size":"1270.1"}, {"price":"0.95", "size":"1768.6"}, {"price":"0.94", "size":"1124.35"}, {"price":"0.93", "size":"959.2"}, {"price":"0.92", "size":"1225.88"}, {"price":"0.91", "size":"796.7"}, {"price":"0.9", "size":"365.2"}, {"price":"0.89", "size":"1502.1"}, {"price":"0.88", "size":"195.05"}, {"price":"0.87", "size":"147.4"}, {"price":"0.86", "size":"183.4"}, {"price":"0.85", "size":"449.04"}, {"price":"0.84", "size":"127.1"}, {"price":"0.83", "size":"107.69"}, {"price":"0.82", "size":"125.7"}, {"price":"0.81", "size":"98.89"}, {"price":"0.8", "size":"201.2"}, {"price":"0.79", "size":"616.8"}, {"price":"0.78", "size":"982.3"}, {"price":"0.77", "size":"67.6"}, {"price":"0.76", "size":"103.73"}, {"price":"0.75", "size":"78.3"}, {"price":"0.74", "size":"76.8"}, {"price":"0.73", "size":"70.3"}, {"price":"0.72", "size":"79.87"}, {"price":"0.71", "size":"74.39"}, {"price":"0.7", "size":"83"}, {"price":"0.69", "size":"64.7"}, {"price":"0.68", "size":"160.64"}, {"price":"0.67", "size":"98.1"}, {"price":"0.66", "size":"77.8"}, {"price":"0.65", "size":"69.6"}, {"price":"0.64", "size":"79.39"}, {"price":"0.63", "size":"194.2"}, {"price":"0.62", "size":"85"}, {"price":"0.61", "size":"69.8"}, {"price":"0.6", "size":"97.94"}, {"price":"0.59", "size":"75.5"}, {"price":"0.58", "size":"86.02"}, {"price":"0.57", "size":"100.3"}, {"price":"0.56", "size":"64.2"}, {"price":"0.55", "size":"204.71"}, {"price":"0.54", "size":"102.1"}, {"price":"0.53", "size":"72.1"}, {"price":"0.52", "size":"83"}, {"price":"0.51", "size":"91"}, {"price":"0.5", "size":"91"}, {"price":"0.49", "size":"106"}, {"price":"0.48", "size":"205"}, {"price":"0.47", "size":"426.02"}, {"price":"0.46", "size":"148.85"}, {"price":"0.45", "size":"226.69"}, {"price":"0.44", "size":"163.99"}, {"price":"0.43", "size":"169"}, {"price":"0.42", "size":"151.82"}, {"price":"0.41", "size":"335.34"}, {"price":"0.4", "size":"136.7"}, {"price":"0.39", "size":"370.55"}], "hash":"a49c090b467d9ade6d1648052c0266844b1784a5", "timestamp":"1784449237589", "event_type":"book"}
{"market":"0xab772601f501b265bfe8982eb61d5347ef9945de314bfdf4ac0189c288ffb0b3", "asset_id":"17924629579804316786455515989238352689210911545477836576430679697715946894553", "bids":[{"price":"0.01", "size":"13069.5"}, {"price":"0.02", "size":"3885.25"}, {"price":"0.03", "size":"2255.95"}, {"price":"0.04", "size":"1270.1"}, {"price":"0.05", "size":"1768.6"}, {"price":"0.06", "size":"1124.35"}, {"price":"0.07", "size":"959.2"}, {"price":"0.08", "size":"1225.88"}, {"price":"0.09", "size":"796.7"}, {"price":"0.1", "size":"365.2"}, {"price":"0.11", "size":"1502.1"}, {"price":"0.12", "size":"195.05"}, {"price":"0.13", "size":"147.4"}, {"price":"0.14", "size":"183.4"}, {"price":"0.15", "size":"449.04"}, {"price":"0.16", "size":"127.1"}, {"price":"0.17", "size":"107.69"}, {"price":"0.18", "size":"125.7"}, {"price":"0.19", "size":"98.89"}, {"price":"0.2", "size":"201.2"}, {"price":"0.21", "size":"616.8"}, {"price":"0.22", "size":"982.3"}, {"price":"0.23", "size":"67.6"}, {"price":"0.24", "size":"103.73"}, {"price":"0.25", "size":"78.3"}, {"price":"0.26", "size":"76.8"}, {"price":"0.27", "size":"70.3"}, {"price":"0.28", "size":"79.87"}, {"price":"0.29", "size":"74.39"}, {"price":"0.3", "size":"83"}, {"price":"0.31", "size":"64.7"}, {"price":"0.32", "size":"160.64"}, {"price":"0.33", "size":"98.1"}, {"price":"0.34", "size":"77.8"}, {"price":"0.35", "size":"69.6"}, {"price":"0.36", "size":"79.39"}, {"price":"0.37", "size":"194.2"}, {"price":"0.38", "size":"85"}, {"price":"0.39", "size":"69.8"}, {"price":"0.4", "size":"97.94"}, {"price":"0.41", "size":"75.5"}, {"price":"0.42", "size":"86.02"}, {"price":"0.43", "size":"100.3"}, {"price":"0.44", "size":"64.2"}, {"price":"0.45", "size":"204.71"}, {"price":"0.46", "size":"102.1"}, {"price":"0.47", "size":"72.1"}, {"price":"0.48", "size":"83"}, {"price":"0.49", "size":"91"}, {"price":"0.5", "size":"91"}, {"price":"0.51", "size":"106"}, {"price":"0.52", "size":"205"}, {"price":"0.53", "size":"426.02"}, {"price":"0.54", "size":"148.85"}, {"price":"0.55", "size":"226.69"}, {"price":"0.56", "size":"163.99"}, {"price":"0.57", "size":"169"}, {"price":"0.58", "size":"151.82"}, {"price":"0.59", "size":"335.34"}, {"price":"0.6", "size":"136.7"}, {"price":"0.61", "size":"370.55"}], "asks":[{"price":"0.99", "size":"14899.14"}, {"price":"0.98", "size":"3964.52"}, {"price":"0.97", "size":"2179.29"}, {"price":"0.96", "size":"1215.1"}, {"price":"0.95", "size":"1742.19"}, {"price":"0.94", "size":"1122.02"}, {"price":"0.93", "size":"953.49"}, {"price":"0.92", "size":"1234.38"}, {"price":"0.91", "size":"791.7"}, {"price":"0.9", "size":"561.2"}, {"price":"0.89", "size":"1502.1"}, {"price":"0.88", "size":"1102.45"}, {"price":"0.87", "size":"139.4"}, {"price":"0.86", "size":"281.8"}, {"price":"0.85", "size":"444.04"}, {"price":"0.84", "size":"147.1"}, {"price":"0.83", "size":"207.17"}, {"price":"0.82", "size":"150.7"}, {"price":"0.81", "size":"128.89"}, {"price":"0.8", "size":"246.2"}, {"price":"0.79", "size":"636.8"}, {"price":"0.78", "size":"135.5"}, {"price":"0.77", "size":"127.3"}, {"price":"0.76", "size":"162.22"}, {"price":"0.75", "size":"162.2"}, {"price":"0.74", "size":"134.3"}, {"price":"0.73", "size":"148.5"}, {"price":"0.72", "size":"151.88"}, {"price":"0.71", "size":"222.52"}, {"price":"0.7", "size":"213.04"}, {"price":"0.69", "size":"560.01"}, {"price":"0.68", "size":"244.69"}, {"price":"0.67", "size":"134.65"}, {"price":"0.66", "size":"94.96"}, {"price":"0.65", "size":"106.2"}, {"price":"0.64", "size":"211.77"}, {"price":"0.63", "size":"105.91"}, {"price":"0.62", "size":"35.05"}], "hash":"ad7e53280e40841151fe4ac2e1286e557517f85d", "timestamp":"1784449237589", "event_type":"book"}
{"market":"0xab772601f501b265bfe8982eb61d5347ef9945de314bfdf4ac0189c288ffb0b3", "price_changes":[{"asset_id":"12935926064588426924078449947177910958215776269411501731627440228801766632772", "price":"0.5", "size":"101", "side":"SELL", "hash":"66788a04d3a832ad2fd3b2a1f1fe6714fff495e1", "best_bid":"0.38", "best_ask":"0.39"}, {"asset_id":"17924629579804316786455515989238352689210911545477836576430679697715946894553", "price":"0.5", "size":"101", "side":"BUY", "hash":"ce291087711f16d998091172c47ae72b4d90bda9", "best_bid":"0.61", "best_ask":"0.62"}], "timestamp":"1784449237598", "event_type":"price_change"}
{"market":"0xab772601f501b265bfe8982eb61d5347ef9945de314bfdf4ac0189c288ffb0b3", "price_changes":[{"asset_id":"17924629579804316786455515989238352689210911545477836576430679697715946894553", "price":"0.01", "size":"13075.5", "side":"BUY", "hash":"99092569cef65f1ca458c096e3c95ca9d8cab8d1", "best_bid":"0.61", "best_ask":"0.62"}, {"asset_id":"12935926064588426924078449947177910958215776269411501731627440228801766632772", "price":"0.99", "size":"13075.5", "side":"SELL", "hash":"a9ae21b4cedd37e063e0e642879c46008541486f", "best_bid":"0.38", "best_ask":"0.39"}], "timestamp":"1784449237602", "event_type":"price_change"}
{"market":"0xab772601f501b265bfe8982eb61d5347ef9945de314bfdf4ac0189c288ffb0b3", "price_changes":[{"asset_id":"17924629579804316786455515989238352689210911545477836576430679697715946894553", "price":"0.01", "size":"13070.5", "side":"BUY", "hash":"882051680eba8012232384367c922b5adaa14939", "best_bid":"0.61", "best_ask":"0.62"}, {"asset_id":"12935926064588426924078449947177910958215776269411501731627440228801766632772", "price":"0.99", "size":"13070.5", "side":"SELL", "hash":"6c17fe9b4bc4b1ee50e2d2b2c7129416bc50cb70", "best_bid":"0.38", "best_ask":"0.39"}], "timestamp":"1784449237604", "event_type":"price_change"}
{"market":"0xab772601f501b265bfe8982eb61d5347ef9945de314bfdf4ac0189c288ffb0b3", "price_changes":[{"asset_id":"17924629579804316786455515989238352689210911545477836576430679697715946894553", "price":"0.01", "size":"13065.5", "side":"BUY", "hash":"6d914cbffc5f3632da73190a5d8228c5e423eab8", "best_bid":"0.61", "best_ask":"0.62"}, {"asset_id":"12935926064588426924078449947177910958215776269411501731627440228801766632772", "price":"0.99", "size":"13065.5", "side":"SELL", "hash":"8cb2433dae28f688dbd9a3739f1a6c32c5322334", "best_bid":"0.38", "best_ask":"0.39"}], "timestamp":"1784449237615", "event_type":"price_change"}
{"market":"0xab772601f501b265bfe8982eb61d5347ef9945de314bfdf4ac0189c288ffb0b3", "price_changes":[{"asset_id":"17924629579804316786455515989238352689210911545477836576430679697715946894553", "price":"0.01", "size":"13070.5", "side":"BUY", "hash":"9f3d08b6e01d952535ff544db37b433b8827984d", "best_bid":"0.61", "best_ask":"0.62"}, {"asset_id":"12935926064588426924078449947177910958215776269411501731627440228801766632772", "price":"0.99", "size":"13070.5", "side":"SELL", "hash":"7d25c168cec7f3fd309d357812d2a667119115a3", "best_bid":"0.38", "best_ask":"0.39"}], "timestamp":"1784449237619", "event_type":"price_change"}
{"market":"0xab772601f501b265bfe8982eb61d5347ef9945de314bfdf4ac0189c288ffb0b3", "price_changes":[{"asset_id":"17924629579804316786455515989238352689210911545477836576430679697715946894553", "price":"0.03", "size":"2250.95", "side":"BUY", "hash":"082ad25ee07b30c83ec2ad3d5eef7cc1312b8d03", "best_bid":"0.61", "best_ask":"0.62"}, {"asset_id":"12935926064588426924078449947177910958215776269411501731627440228801766632772", "price":"0.97", "size":"2250.95", "side":"SELL", "hash":"aa2c2076e38d4b766807b54c725e4d671022bd3a", "best_bid":"0.38", "best_ask":"0.39"}], "timestamp":"1784449237620", "event_type":"price_change"}
{"market":"0xab772601f501b265bfe8982eb61d5347ef9945de314bfdf4ac0189c288ffb0b3", "price_changes":[{"asset_id":"17924629579804316786455515989238352689210911545477836576430679697715946894553", "price":"0.01", "size":"13065.5", "side":"BUY", "hash":"7b7ea4cec1ab17818f0fc93510195f8abbeebefc", "best_bid":"0.61", "best_ask":"0.62"}, {"asset_id":"12935926064588426924078449947177910958215776269411501731627440228801766632772", "price":"0.99", "size":"13065.5", "side":"SELL", "hash":"64261f973ede6e38fce2a9dbfd5825aa590003aa", "best_bid":"0.38", "best_ask":"0.39"}], "timestamp":"1784449237621", "event_type":"price_change"}
{"market":"0xab772601f501b265bfe8982eb61d5347ef9945de314bfdf4ac0189c288ffb0b3", "price_changes":[{"asset_id":"17924629579804316786455515989238352689210911545477836576430679697715946894553", "price":"0.01", "size":"12965.5", "side":"BUY", "hash":"e1b80eecf4a8a24126caf93f86f9cd6cff8e836e", "best_bid":"0.61", "best_ask":"0.62"}, {"asset_id":"12935926064588426924078449947177910958215776269411501731627440228801766632772", "price":"0.99", "size":"12965.5", "side":"SELL", "hash":"87a3241331c7e2d258e57d424562548d1dfc065b", "best_bid":"0.38", "best_ask":"0.39"}], "timestamp":"1784449237621", "event_type":"price_change"}
{"market":"0xab772601f501b265bfe8982eb61d5347ef9945de314bfdf4ac0189c288ffb0b3", "price_changes":[{"asset_id":"17924629579804316786455515989238352689210911545477836576430679697715946894553", "price":"0.01", "size":"12970.5", "side":"BUY", "hash":"168e5ad6cd56d9272088f2e17ee9a9c727fdb7d5", "best_bid":"0.61", "best_ask":"0.62"}, {"asset_id":"12935926064588426924078449947177910958215776269411501731627440228801766632772", "price":"0.99", "size":"12970.5", "side":"SELL", "hash":"5e1b172c64d66802ab763ee8314780ad80f5a873", "best_bid":"0.38", "best_ask":"0.39"}], "timestamp":"1784449237623", "event_type":"price_change"}
{"market":"0xab772601f501b265bfe8982eb61d5347ef9945de314bfdf4ac0189c288ffb0b3", "price_changes":[{"asset_id":"17924629579804316786455515989238352689210911545477836576430679697715946894553", "price":"0.01", "size":"12975.5", "side":"BUY", "hash":"1a1c1ca6d7fee441f8c3b78819979e06131793e0", "best_bid":"0.61", "best_ask":"0.62"}, {"asset_id":"12935926064588426924078449947177910958215776269411501731627440228801766632772", "price":"0.99", "size":"12975.5", "side":"SELL", "hash":"09010c293a944122acd4a9ca4db24297502189ef", "best_bid":"0.38", "best_ask":"0.39"}], "timestamp":"1784449237623", "event_type":"price_change"}
{"market":"0xab772601f501b265bfe8982eb61d5347ef9945de314bfdf4ac0189c288ffb0b3", "price_changes":[{"asset_id":"17924629579804316786455515989238352689210911545477836576430679697715946894553", "price":"0.01", "size":"12970.5", "side":"BUY", "hash":"23f6863b71169f242968f2e488b1e726febc4f3d", "best_bid":"0.61", "best_ask":"0.62"}, {"asset_id":"12935926064588426924078449947177910958215776269411501731627440228801766632772", "price":"0.99", "size":"12970.5", "side":"SELL", "hash":"229f5ea5ebc9ab15f8d907a33c8e4596b405ab70", "best_bid":"0.38", "best_ask":"0.39"}], "timestamp":"1784449237624", "event_type":"price_change"}
{"market":"0xab772601f501b265bfe8982eb61d5347ef9945de314bfdf4ac0189c288ffb0b3", "price_changes":[{"asset_id":"17924629579804316786455515989238352689210911545477836576430679697715946894553", "price":"0.01", "size":"12975.5", "side":"BUY", "hash":"11cece3266f9cfe3481973ab44d2cd21333112c2", "best_bid":"0.61", "best_ask":"0.62"}, {"asset_id":"12935926064588426924078449947177910958215776269411501731627440228801766632772", "price":"0.99", "size":"12975.5", "side":"SELL", "hash":"f5ae31f9a8a8e6e6cd5d1bf4da561254dee79efc", "best_bid":"0.38", "best_ask":"0.39"}], "timestamp":"1784449237627", "event_type":"price_change"}
{"market":"0xab772601f501b265bfe8982eb61d5347ef9945de314bfdf4ac0189c288ffb0b3", "price_changes":[{"asset_id":"12935926064588426924078449947177910958215776269411501731627440228801766632772", "price":"0.49", "size":"406", "side":"SELL", "hash":"23efddab5b63a3109dab7ed6e0690b995e7edc50", "best_bid":"0.38", "best_ask":"0.39"}, {"asset_id":"17924629579804316786455515989238352689210911545477836576430679697715946894553", "price":"0.51", "size":"406", "side":"BUY", "hash":"2ab6a3343ef8cca65f19efbcd13cdd20a350c6b9", "best_bid":"0.61", "best_ask":"0.62"}], "timestamp":"1784449237630", "event_type":"price_change"}
{"market":"0xab772601f501b265bfe8982eb61d5347ef9945de314bfdf4ac0189c288ffb0b3", "price_changes":[{"asset_id":"12935926064588426924078449947177910958215776269411501731627440228801766632772", "price":"0.31", "size":"550.01", "side":"BUY", "hash":"0efb46dbe67c06d30cc2aa82f45fd84a8805280b", "best_bid":"0.38", "best_ask":"0.39"}, {"asset_id":"17924629579804316786455515989238352689210911545477836576430679697715946894553", "price":"0.69", "size":"550.01", "side":"SELL", "hash":"95da7c06ad25b06caed4af43f9b686d7265d8a45", "best_bid":"0.61", "best_ask":"0.62"}], "timestamp":"1784449237632", "event_type":"price_change"}
{"market":"0xab772601f501b265bfe8982eb61d5347ef9945de314bfdf4ac0189c288ffb0b3", "price_changes":[{"asset_id":"17924629579804316786455515989238352689210911545477836576430679697715946894553", "price":"0.61", "size":"384.43", "side":"BUY", "hash":"3997ce73f36e644daff69e0f89023773ea689bf5", "best_bid":"0.61", "best_ask":"0.62"}, {"asset_id":"12935926064588426924078449947177910958215776269411501731627440228801766632772", "price":"0.39", "size":"384.43", "side":"SELL", "hash":"c1690812de00b289b1a437792759d66b15cffa91", "best_bid":"0.38", "best_ask":"0.39"}], "timestamp":"1784449237632", "event_type":"price_change"}
{"market":"0xab772601f501b265bfe8982eb61d5347ef9945de314bfdf4ac0189c288ffb0b3", "price_changes":[{"asset_id":"17924629579804316786455515989238352689210911545477836576430679697715946894553", "price":"0.01", "size":"12970.5", "side":"BUY", "hash":"6bbc952dba16dac4dd255a8cc716d64a9090fe36", "best_bid":"0.61", "best_ask":"0.62"}, {"asset_id":"12935926064588426924078449947177910958215776269411501731627440228801766632772", "price":"0.99", "size":"12970.5", "side":"SELL", "hash":"00ffda24cfa0259d269a8108ce83543f0c1d9e8f", "best_bid":"0.38", "best_ask":"0.39"}], "timestamp":"1784449237634", "event_type":"price_change"}
{"market":"0xab772601f501b265bfe8982eb61d5347ef9945de314bfdf4ac0189c288ffb0b3", "price_changes":[{"asset_id":"12935926064588426924078449947177910958215776269411501731627440228801766632772", "price":"0.3", "size":"203.04", "side":"BUY", "hash":"0d81e26414723be6ad2f61d995657dad2866335a", "best_bid":"0.38", "best_ask":"0.39"}, {"asset_id":"17924629579804316786455515989238352689210911545477836576430679697715946894553", "price":"0.7", "size":"203.04", "side":"SELL", "hash":"dbde8c5236d5e1796b2fa87916d5a11e017d065f", "best_bid":"0.61", "best_ask":"0.62"}], "timestamp":"1784449237634", "event_type":"price_change"}
{"market":"0xab772601f501b265bfe8982eb61d5347ef9945de314bfdf4ac0189c288ffb0b3", "price_changes":[{"asset_id":"17924629579804316786455515989238352689210911545477836576430679697715946894553", "price":"0.52", "size":"195", "side":"BUY", "hash":"7fdf19ddac2e662e15067ca580d9cd2a3b0f7429", "best_bid":"0.61", "best_ask":"0.62"}, {"asset_id":"12935926064588426924078449947177910958215776269411501731627440228801766632772", "price":"0.48", "size":"195", "side":"SELL", "hash":"6bcc6142d895de8f196c7afb7647a261e9397da7", "best_bid":"0.38", "best_ask":"0.39"}], "timestamp":"1784449237635", "event_type":"price_change"}
{"market":"0xab772601f501b265bfe8982eb61d5347ef9945de314bfdf4ac0189c288ffb0b3", "price_changes":[{"asset_id":"17924629579804316786455515989238352689210911545477836576430679697715946894553", "price":"0.01", "size":"12964.5", "side":"BUY", "hash":"a89cd2f098f72000e0434a842dcd3a27d5b1da65", "best_bid":"0.61", "best_ask":"0.62"}, {"asset_id":"12935926064588426924078449947177910958215776269411501731627440228801766632772", "price":"0.99", "size":"12964.5", "side":"SELL", "hash":"d0c2577325fea4f810bda1284b341127568fec62", "best_bid":"0.38", "best_ask":"0.39"}], "timestamp":"1784449237636", "event_type":"price_change"}
{"market":"0xab772601f501b265bfe8982eb61d5347ef9945de314bfdf4ac0189c288ffb0b3", "price_changes":[{"asset_id":"17924629579804316786455515989238352689210911545477836576430679697715946894553", "price":"0.61", "size":"369.43", "side":"BUY", "hash":"ec28d96821b259f86283231f667323f730f253a7", "best_bid":"0.61", "best_ask":"0.62"}, {"asset_id":"12935926064588426924078449947177910958215776269411501731627440228801766632772", "price":"0.39", "size":"369.43", "side":"SELL", "hash":"ee290080a4c67bcd0f480d4cd60408081ff9d328", "best_bid":"0.38", "best_ask":"0.39"}], "timestamp":"1784449237641", "event_type":"price_change"}
{"market":"0xab772601f501b265bfe8982eb61d5347ef9945de314bfdf4ac0189c288ffb0b3", "price_changes":[{"asset_id":"12935926064588426924078449947177910958215776269411501731627440228801766632772", "price":"0.34", "size":"79.96", "side":"BUY", "hash":"b82e538af431213edb42516b3448971c58d6b776", "best_bid":"0.38", "best_ask":"0.39"}, {"asset_id":"17924629579804316786455515989238352689210911545477836576430679697715946894553", "price":"0.66", "size":"79.96", "side":"SELL", "hash":"c3805dbaace5506a8a3b1f122644122546836699", "best_bid":"0.61", "best_ask":"0.62"}], "timestamp":"1784449237642", "event_type":"price_change"}
{"market":"0xab772601f501b265bfe8982eb61d5347ef9945de314bfdf4ac0189c288ffb0b3", "price_changes":[{"asset_id":"17924629579804316786455515989238352689210911545477836576430679697715946894553", "price":"0.59", "size":"320.34", "side":"BUY", "hash":"3fefbdd02bc711eb172b503ef6a6feae3b8dfa08", "best_bid":"0.61", "best_ask":"0.62"}, {"asset_id":"12935926064588426924078449947177910958215776269411501731627440228801766632772", "price":"0.41", "size":"320.34", "side":"SELL", "hash":"4335149cd2c419526cc80c178d2be0a6cad5a156", "best_bid":"0.38", "best_ask":"0.39"}], "timestamp":"1784449237642", "event_type":"price_change"}
{"market":"0xab772601f501b265bfe8982eb61d5347ef9945de314bfdf4ac0189c288ffb0b3", "price_changes":[{"asset_id":"17924629579804316786455515989238352689210911545477836576430679697715946894553", "price":"0.6", "size":"121.7", "side":"BUY", "hash":"3fefbdd02bc711eb172b503ef6a6feae3b8dfa08", "best_bid":"0.61", "best_ask":"0.62"}, {"asset_id":"12935926064588426924078449947177910958215776269411501731627440228801766632772", "price":"0.4", "size":"121.7", "side":"SELL", "hash":"4335149cd2c419526cc80c178d2be0a6cad5a156", "best_bid":"0.38", "best_ask":"0.39"}], "timestamp":"1784449237642", "event_type":"price_change"}
{"market":"0xab772601f501b265bfe8982eb61d5347ef9945de314bfdf4ac0189c288ffb0b3", "price_changes":[{"asset_id":"17924629579804316786455515989238352689210911545477836576430679697715946894553", "price":"0.6", "size":"131.7", "side":"BUY", "hash":"7492e563969d9f548d588d3edbcd6cd95a8204ca", "best_bid":"0.61", "best_ask":"0.62"}, {"asset_id":"12935926064588426924078449947177910958215776269411501731627440228801766632772", "price":"0.4", "size":"131.7", "side":"SELL", "hash":"e38f450ed7a10737b4b579607f7e83f142f3b278", "best_bid":"0.38", "best_ask":"0.39"}], "timestamp":"1784449237643", "event_type":"price_change"}
{"market":"0xab772601f501b265bfe8982eb61d5347ef9945de314bfdf4ac0189c288ffb0b3", "price_changes":[{"asset_id":"12935926064588426924078449947177910958215776269411501731627440228801766632772", "price":"0.23", "size":"137.3", "side":"BUY", "hash":"bbe5632e5f09b8928a9afde556ffaa5cbd54204c", "best_bid":"0.38", "best_ask":"0.39"}, {"asset_id":"17924629579804316786455515989238352689210911545477836576430679697715946894553", "price":"0.77", "size":"137.3", "side":"SELL", "hash":"48e1522aa84f1e5dc376e82cde614f65a6d82e5c", "best_bid":"0.61", "best_ask":"0.62"}], "timestamp":"1784449237644", "event_type":"price_change"}
{"market":"0xab772601f501b265bfe8982eb61d5347ef9945de314bfdf4ac0189c288ffb0b3", "price_changes":[{"asset_id":"17924629579804316786455515989238352689210911545477836576430679697715946894553", "price":"0.59", "size":"340.34", "side":"BUY", "hash":"8cae2caf656579fdbab7dd43c917d8a1b782d44e", "best_bid":"0.61", "best_ask":"0.62"}, {"asset_id":"12935926064588426924078449947177910958215776269411501731627440228801766632772", "price":"0.41", "size":"340.34", "side":"SELL", "hash":"ee79223f2a18176389fd354f184ee01ca23c049d", "best_bid":"0.38", "best_ask":"0.39"}], "timestamp":"1784449237644", "event_type":"price_change"}
{"market":"0xab772601f501b265bfe8982eb61d5347ef9945de314bfdf4ac0189c288ffb0b3", "price_changes":[{"asset_id":"12935926064588426924078449947177910958215776269411501731627440228801766632772", "price":"0.22", "size":"145.5", "side":"BUY", "hash":"0fe609bf9c60e7325c6280af37746e1f769f4cd9", "best_bid":"0.38", "best_ask":"0.39"}, {"asset_id":"17924629579804316786455515989238352689210911545477836576430679697715946894553", "price":"0.78", "size":"145.5", "side":"SELL", "hash":"0484b844af3c23e0d8ecfaf1da85e32bdf9d38f6", "best_bid":"0.61", "best_ask":"0.62"}], "timestamp":"1784449237645", "event_type":"price_change"}
{"market":"0xab772601f501b265bfe8982eb61d5347ef9945de314bfdf4ac0189c288ffb0b3", "price_changes":[{"asset_id":"17924629579804316786455515989238352689210911545477836576430679697715946894553", "price":"0.22", "size":"997.5", "side":"BUY", "hash":"4f55d14e77d316be7e09b3aef0c944d08e0e8b35", "best_bid":"0.61", "best_ask":"0.62"}, {"asset_id":"12935926064588426924078449947177910958215776269411501731627440228801766632772", "price":"0.78", "size":"997.5", "side":"SELL", "hash":"f0cd388f277221c00bd873643293f0d1373e0416", "best_bid":"0.38", "best_ask":"0.39"}], "timestamp":"1784449237646", "event_type":"price_change"}
{"market":"0xab772601f501b265bfe8982eb61d5347ef9945de314bfdf4ac0189c288ffb0b3", "price_changes":[{"asset_id":"17924629579804316786455515989238352689210911545477836576430679697715946894553", "price":"0.01", "size":"12959.5", "side":"BUY", "hash":"3f2d230a9ca42a9a9932ed3d834bfa38aabbce72", "best_bid":"0.61", "best_ask":"0.62"}, {"asset_id":"12935926064588426924078449947177910958215776269411501731627440228801766632772", "price":"0.99", "size":"12959.5", "side":"SELL", "hash":"6744962965492c0cf87cc4b59f15b164a20c018f", "best_bid":"0.38", "best_ask":"0.39"}], "timestamp":"1784449237647", "event_type":"price_change"}
{"market":"0xab772601f501b265bfe8982eb61d5347ef9945de314bfdf4ac0189c288ffb0b3", "price_changes":[{"asset_id":"12935926064588426924078449947177910958215776269411501731627440228801766632772", "price":"0.35", "size":"101.2", "side":"BUY", "hash":"2d7a7442c31b8dcf783a889428a2d4466177cbf3", "best_bid":"0.38", "best_ask":"0.39"}, {"asset_id":"17924629579804316786455515989238352689210911545477836576430679697715946894553", "price":"0.65", "size":"101.2", "side":"SELL", "hash":"cdbee9723ed830321892e565255f3142f54b8708", "best_bid":"0.61", "best_ask":"0.62"}], "timestamp":"1784449237652", "event_type":"price_change"}
{"market":"0xab772601f501b265bfe8982eb61d5347ef9945de314bfdf4ac0189c288ffb0b3", "price_changes":[{"asset_id":"17924629579804316786455515989238352689210911545477836576430679697715946894553", "price":"0.01", "size":"13059.5", "side":"BUY", "hash":"4f8734d7ef65d68e8431343e79ded91679afa7ef", "best_bid":"0.61", "best_ask":"0.62"}, {"asset_id":"12935926064588426924078449947177910958215776269411501731627440228801766632772", "price":"0.99", "size":"13059.5", "side":"SELL", "hash":"1c812e139e674a12fd8eef83a50b68c36e5b55d9", "best_bid":"0.38", "best_ask":"0.39"}], "timestamp":"1784449237656", "event_type":"price_change"}
{"market":"0xab772601f501b265bfe8982eb61d5347ef9945de314bfdf4ac0189c288ffb0b3", "price_changes":[{"asset_id":"17924629579804316786455515989238352689210911545477836576430679697715946894553", "price":"0.41", "size":"100.5", "side":"BUY", "hash":"71e2ce5dd2f4e495dae44a17efef3d9894cc4132", "best_bid":"0.61", "best_ask":"0.62"}, {"asset_id":"12935926064588426924078449947177910958215776269411501731627440228801766632772", "price":"0.59", "size":"100.5", "side":"SELL", "hash":"e43ee601e77a96211187aef2e72b9e79fdd5c937", "best_bid":"0.38", "best_ask":"0.39"}], "timestamp":"1784449237656", "event_type":"price_change"}
{"market":"0xab772601f501b265bfe8982eb61d5347ef9945de314bfdf4ac0189c288ffb0b3", "price_changes":[{"asset_id":"17924629579804316786455515989238352689210911545477836576430679697715946894553", "price":"0.59", "size":"345.34", "side":"BUY", "hash":"a638c2f9d1214e85dfbd8e22973b0127df50b760", "best_bid":"0.61", "best_ask":"0.62"}, {"asset_id":"12935926064588426924078449947177910958215776269411501731627440228801766632772", "price":"0.41", "size":"345.34", "side":"SELL", "hash":"dca3cf0ddd42c2df70d51cbbd16c5c3fec714f50", "best_bid":"0.38", "best_ask":"0.39"}], "timestamp":"1784449237657", "event_type":"price_change"}
{"market":"0xab772601f501b265bfe8982eb61d5347ef9945de314bfdf4ac0189c288ffb0b3", "asset_id":"17924629579804316786455515989238352689210911545477836576430679697715946894553", "price":"0.62", "size":"2", "fee_rate_bps":"0", "side":"BUY", "timestamp":"1784449237652", "event_type":"last_trade_price", "transaction_hash":"0xc5a3ea99f1218b561c8821cef8d72135344dba8c29170b59ac217cf4bbeba84f"}
{"market":"0xab772601f501b265bfe8982eb61d5347ef9945de314bfdf4ac0189c288ffb0b3", "price_changes":[{"asset_id":"17924629579804316786455515989238352689210911545477836576430679697715946894553", "price":"0.01", "size":"13064.51", "side":"BUY", "hash":"64f4450f134b59ef5c80c95309d422b5634c7694", "best_bid":"0.61", "best_ask":"0.62"}, {"asset_id":"12935926064588426924078449947177910958215776269411501731627440228801766632772", "price":"0.99", "size":"13064.51", "side":"SELL", "hash":"ab4abc14c9c0fb33facdf65994c4dd336e8c2fad", "best_bid":"0.38", "best_ask":"0.39"}], "timestamp":"1784449237661", "event_type":"price_change"}
{"market":"0xab772601f501b265bfe8982eb61d5347ef9945de314bfdf4ac0189c288ffb0b3", "price_changes":[{"asset_id":"17924629579804316786455515989238352689210911545477836576430679697715946894553", "price":"0.59", "size":"360.34", "side":"BUY", "hash":"94e1d1c1528177e3996864fc07be4987a095e8ca", "best_bid":"0.61", "best_ask":"0.62"}, {"asset_id":"12935926064588426924078449947177910958215776269411501731627440228801766632772", "price":"0.41", "size":"360.34", "side":"SELL", "hash":"e711fefe1ae7a6cd14ac05fabb11d6dd0eb5093e", "best_bid":"0.38", "best_ask":"0.39"}], "timestamp":"1784449237666", "event_type":"price_change"}
{"market":"0xab772601f501b265bfe8982eb61d5347ef9945de314bfdf4ac0189c288ffb0b3", "price_changes":[{"asset_id":"17924629579804316786455515989238352689210911545477836576430679697715946894553", "price":"0.6", "size":"146.7", "side":"BUY", "hash":"21fffdad014aa620ca196247fd031e8d5097ee99", "best_bid":"0.61", "best_ask":"0.62"}, {"asset_id":"12935926064588426924078449947177910958215776269411501731627440228801766632772", "price":"0.4", "size":"146.7", "side":"SELL", "hash":"aa2b8406afb94fee41cc84e408bb7c200137394c", "best_bid":"0.38", "best_ask":"0.39"}], "timestamp":"1784449237667", "event_type":"price_change"}
{"market":"0xab772601f501b265bfe8982eb61d5347ef9945de314bfdf4ac0189c288ffb0b3", "price_changes":[{"asset_id":"12935926064588426924078449947177910958215776269411501731627440228801766632772", "price":"0.01", "size":"14894.14", "side":"BUY", "hash":"c161fc4e023013cc65050f09804e02686118028a", "best_bid":"0.38", "best_ask":"0.39"}, {"asset_id":"17924629579804316786455515989238352689210911545477836576430679697715946894553", "price":"0.99", "size":"14894.14", "side":"SELL", "hash":"611f0d6e58bed626d5f22c892048c5da745146c9", "best_bid":"0.61", "best_ask":"0.62"}], "timestamp":"1784449237668", "event_type":"price_change"}
{"market":"0xab772601f501b265bfe8982eb61d5347ef9945de314bfdf4ac0189c288ffb0b3", "price_changes":[{"asset_id":"12935926064588426924078449947177910958215776269411501731627440228801766632772", "price":"0.34", "size":"94.96", "side":"BUY", "hash":"e77e36606a91c1cbb0c1e4013b497196dff52711", "best_bid":"0.38", "best_ask":"0.39"}, {"asset_id":"17924629579804316786455515989238352689210911545477836576430679697715946894553", "price":"0.66", "size":"94.96", "side":"SELL", "hash":"c207ca9926bdb8474f023bec241fb5b255758d89", "best_bid":"0.61", "best_ask":"0.62"}], "timestamp":"1784449237668", "event_type":"price_change"}
{"market":"0xab772601f501b265bfe8982eb61d5347ef9945de314bfdf4ac0189c288ffb0b3", "price_changes":[{"asset_id":"17924629579804316786455515989238352689210911545477836576430679697715946894553", "price":"0.61", "size":"384.43", "side":"BUY", "hash":"4a31bcc8391b276ddf06b67aa46e44c6d7784996", "best_bid":"0.61", "best_ask":"0.62"}, {"asset_id":"12935926064588426924078449947177910958215776269411501731627440228801766632772", "price":"0.39", "size":"384.43", "side":"SELL", "hash":"d93276011b700369f4b1015305e903b47c772dc2", "best_bid":"0.38", "best_ask":"0.39"}], "timestamp":"1784449237669", "event_type":"price_change"}
{"market":"0xab772601f501b265bfe8982eb61d5347ef9945de314bfdf4ac0189c288ffb0b3", "price_changes":[{"asset_id":"17924629579804316786455515989238352689210911545477836576430679697715946894553", "price":"0.01", "size":"12964.51", "side":"BUY", "hash":"5b9d4de91629260b190c864c635e1151817f229c", "best_bid":"0.61", "best_ask":"0.62"}, {"asset_id":"12935926064588426924078449947177910958215776269411501731627440228801766632772", "price":"0.99", "size":"12964.51", "side":"SELL", "hash":"b49600f276d63e1be82ff2d88fbc23b1a5e76704", "best_bid":"0.38", "best_ask":"0.39"}], "timestamp":"1784449237690", "event_type":"price_change"}
{"market":"0xab772601f501b265bfe8982eb61d5347ef9945de314bfdf4ac0189c288ffb0b3", "price_changes":[{"asset_id":"12935926064588426924078449947177910958215776269411501731627440228801766632772", "price":"0.3", "size":"228.04", "side":"BUY", "hash":"74f55aad342394729e0b2b8f5d3c8de36ea84d43", "best_bid":"0.38", "best_ask":"0.39"}, {"asset_id":"17924629579804316786455515989238352689210911545477836576430679697715946894553", "price":"0.7", "size":"228.04", "side":"SELL", "hash":"f8bfd61ca878436be903734a470d3670f1e77e7c", "best_bid":"0.61", "best_ask":"0.62"}], "timestamp":"1784449237691", "event_type":"price_change"}
{"market":"0xab772601f501b265bfe8982eb61d5347ef9945de314bfdf4ac0189c288ffb0b3", "price_changes":[{"asset_id":"17924629579804316786455515989238352689210911545477836576430679697715946894553", "price":"0.01", "size":"12959.5", "side":"BUY", "hash":"5d732cd76ef6a15d3a8e77a0e0151247237d80a0", "best_bid":"0.61", "best_ask":"0.62"}, {"asset_id":"12935926064588426924078449947177910958215776269411501731627440228801766632772", "price":"0.99", "size":"12959.5", "side":"SELL", "hash":"b216efcbfc1f6fab1c0d5cfe0459bc7687166a11", "best_bid":"0.38", "best_ask":"0.39"}], "timestamp":"1784449237692", "event_type":"price_change"}
{"market":"0xab772601f501b265bfe8982eb61d5347ef9945de314bfdf4ac0189c288ffb0b3", "price_changes":[{"asset_id":"12935926064588426924078449947177910958215776269411501731627440228801766632772", "price":"0.01", "size":"14889.14", "side":"BUY", "hash":"b10066873a613f7f916570536d8a7a63a8c9f3ac", "best_bid":"0.38", "best_ask":"0.39"}, {"asset_id":"17924629579804316786455515989238352689210911545477836576430679697715946894553", "price":"0.99", "size":"14889.14", "side":"SELL", "hash":"48f54d84aded19451c9c66991bc196634edc39fa", "best_bid":"0.61", "best_ask":"0.62"}], "timestamp":"1784449237700", "event_type":"price_change"}
{"market":"0xab772601f501b265bfe8982eb61d5347ef9945de314bfdf4ac0189c288ffb0b3", "price_changes":[{"asset_id":"12935926064588426924078449947177910958215776269411501731627440228801766632772", "price":"0.3", "size":"203.04", "side":"BUY", "hash":"7029f1d343b83705239674a0c313e2ac80d704db", "best_bid":"0.38", "best_ask":"0.39"}, {"asset_id":"17924629579804316786455515989238352689210911545477836576430679697715946894553", "price":"0.7", "size":"203.04", "side":"SELL", "hash":"ca5b7296ac2cf43d6a0bc7afa8acd35d8021cc4b", "best_bid":"0.61", "best_ask":"0.62"}], "timestamp":"1784449237703", "event_type":"price_change"}
{"market":"0xab772601f501b265bfe8982eb61d5347ef9945de314bfdf4ac0189c288ffb0b3", "price_changes":[{"asset_id":"17924629579804316786455515989238352689210911545477836576430679697715946894553", "price":"0.01", "size":"12965.5", "side":"BUY", "hash":"81758d2054c2a3d7969180aeeff2430e195ba0ff", "best_bid":"0.61", "best_ask":"0.62"}, {"asset_id":"12935926064588426924078449947177910958215776269411501731627440228801766632772", "price":"0.99", "size":"12965.5", "side":"SELL", "hash":"945c3fe8d456eb1bd15b9b54e67cde5b250c530f", "best_bid":"0.38", "best_ask":"0.39"}], "timestamp":"1784449237708", "event_type":"price_change"}
{"market":"0xab772601f501b265bfe8982eb61d5347ef9945de314bfdf4ac0189c288ffb0b3", "price_changes":[{"asset_id":"17924629579804316786455515989238352689210911545477836576430679697715946894553", "price":"0.04", "size":"1275.1", "side":"BUY", "hash":"67b74a70039e22a5765647bdfe6e17a2dd223cb8", "best_bid":"0.61", "best_ask":"0.62"}, {"asset_id":"12935926064588426924078449947177910958215776269411501731627440228801766632772", "price":"0.96", "size":"1275.1", "side":"SELL", "hash":"48047d8100984a6a3b09a160c4889903786ade2c", "best_bid":"0.38", "best_ask":"0.39"}], "timestamp":"1784449237714", "event_type":"price_change"}
{"market":"0xab772601f501b265bfe8982eb61d5347ef9945de314bfdf4ac0189c288ffb0b3", "price_changes":[{"asset_id":"17924629579804316786455515989238352689210911545477836576430679697715946894553", "price":"0.15", "size":"469.43", "side":"BUY", "hash":"2e795bec2b50f721424d190c5a43fcc3f94ab113", "best_bid":"0.61", "best_ask":"0.62"}, {"asset_id":"12935926064588426924078449947177910958215776269411501731627440228801766632772", "price":"0.85", "size":"469.43", "side":"SELL", "hash":"9b669b73ea795c422585b8750b1e448274abf66d", "best_bid":"0.38", "best_ask":"0.39"}], "timestamp":"1784449237715", "event_type":"price_change"}
{"market":"0xab772601f501b265bfe8982eb61d5347ef9945de314bfdf4ac0189c288ffb0b3", "price_changes":[{"asset_id":"17924629579804316786455515989238352689210911545477836576430679697715946894553", "price":"0.01", "size":"12970.5", "side":"BUY", "hash":"0d94ef4b9aeaaef447bf6524b16c0d9ceba42e35", "best_bid":"0.61", "best_ask":"0.62"}, {"asset_id":"12935926064588426924078449947177910958215776269411501731627440228801766632772", "price":"0.99", "size":"12970.5", "side":"SELL", "hash":"8adb450cb9407155766da6abd72de02596856d1e", "best_bid":"0.38", "best_ask":"0.39"}], "timestamp":"1784449237720", "event_type":"price_change"}
{"market":"0xab772601f501b265bfe8982eb61d5347ef9945de314bfdf4ac0189c288ffb0b3", "price_changes":[{"asset_id":"17924629579804316786455515989238352689210911545477836576430679697715946894553", "price":"0.01", "size":"12964.5", "side":"BUY", "hash":"62bd0b7f7c2111125d52cfdfced8f53fc585d636", "best_bid":"0.61", "best_ask":"0.62"}, {"asset_id":"12935926064588426924078449947177910958215776269411501731627440228801766632772", "price":"0.99", "size":"12964.5", "side":"SELL", "hash":"54292611af594970d438073f0ba60444dd054ad9", "best_bid":"0.38", "best_ask":"0.39"}], "timestamp":"1784449237729", "event_type":"price_change"}
{"market":"0xab772601f501b265bfe8982eb61d5347ef9945de314bfdf4ac0189c288ffb0b3", "price_changes":[{"asset_id":"17924629579804316786455515989238352689210911545477836576430679697715946894553", "price":"0.01", "size":"12959.5", "side":"BUY", "hash":"b7ab10ad3e3cd0ac5f0a76bae1708d56bd8827c7", "best_bid":"0.61", "best_ask":"0.62"}, {"asset_id":"12935926064588426924078449947177910958215776269411501731627440228801766632772", "price":"0.99", "size":"12959.5", "side":"SELL", "hash":"e4a59350633cfa26cd38835b4a67c0de3d6bcd7b", "best_bid":"0.38", "best_ask":"0.39"}], "timestamp":"1784449237732", "event_type":"price_change"}
{"market":"0xab772601f501b265bfe8982eb61d5347ef9945de314bfdf4ac0189c288ffb0b3", "price_changes":[{"asset_id":"12935926064588426924078449947177910958215776269411501731627440228801766632772", "price":"0.3", "size":"228.04", "side":"BUY", "hash":"22642118804aeac19fc247aa9fcd5c90395f8d39", "best_bid":"0.38", "best_ask":"0.39"}, {"asset_id":"17924629579804316786455515989238352689210911545477836576430679697715946894553", "price":"0.7", "size":"228.04", "side":"SELL", "hash":"2ae2d852332eeedd9b4f691c752b687cc242364a", "best_bid":"0.61", "best_ask":"0.62"}], "timestamp":"1784449237735", "event_type":"price_change"}
{"market":"0xab772601f501b265bfe8982eb61d5347ef9945de314bfdf4ac0189c288ffb0b3", "price_changes":[{"asset_id":"12935926064588426924078449947177910958215776269411501731627440228801766632772", "price":"0.3", "size":"203.04", "side":"BUY", "hash":"e02620be8de7f638492d725dba1e7d20aa23e2b7", "best_bid":"0.38", "best_ask":"0.39"}, {"asset_id":"17924629579804316786455515989238352689210911545477836576430679697715946894553", "price":"0.7", "size":"203.04", "side":"SELL", "hash":"3060c32a8323cbd45f4bf744bb4f54a57f69c6a7", "best_bid":"0.61", "best_ask":"0.62"}], "timestamp":"1784449237736", "event_type":"price_change"}
{"market":"0xab772601f501b265bfe8982eb61d5347ef9945de314bfdf4ac0189c288ffb0b3", "price_changes":[{"asset_id":"17924629579804316786455515989238352689210911545477836576430679697715946894553", "price":"0.01", "size":"13059.5", "side":"BUY", "hash":"2eac295e6914a3e80501d88336939abc1ae69b8b", "best_bid":"0.61", "best_ask":"0.62"}, {"asset_id":"12935926064588426924078449947177910958215776269411501731627440228801766632772", "price":"0.99", "size":"13059.5", "side":"SELL", "hash":"1ec87773bae670dd1630604fc48e1630487e7a36", "best_bid":"0.38", "best_ask":"0.39"}], "timestamp":"1784449237737", "event_type":"price_change"}
{"market":"0xab772601f501b265bfe8982eb61d5347ef9945de314bfdf4ac0189c288ffb0b3", "price_changes":[{"asset_id":"17924629579804316786455515989238352689210911545477836576430679697715946894553", "price":"0.01", "size":"13054.5", "side":"BUY", "hash":"60a8ea18175c6a1bf74aa6f0b626605336bfcb4f", "best_bid":"0.61", "best_ask":"0.62"}, {"asset_id":"12935926064588426924078449947177910958215776269411501731627440228801766632772", "price":"0.99", "size":"13054.5", "side":"SELL", "hash":"14f770d36882243a4098fd7b73c81a29cdcee181", "best_bid":"0.38", "best_ask":"0.39"}], "timestamp":"1784449237739", "event_type":"price_change"}
{"market":"0xab772601f501b265bfe8982eb61d5347ef9945de314bfdf4ac0189c288ffb0b3", "price_changes":[{"asset_id":"12935926064588426924078449947177910958215776269411501731627440228801766632772", "price":"0.35", "size":"106.2", "side":"BUY", "hash":"dec6e5f282d5bafc9bc413aa9d23537fc33511ab", "best_bid":"0.38", "best_ask":"0.39"}, {"asset_id":"17924629579804316786455515989238352689210911545477836576430679697715946894553", "price":"0.65", "size":"106.2", "side":"SELL", "hash":"63a1b09cbdffd6075c85575e43700dfd49a275e0", "best_bid":"0.61", "best_ask":"0.62"}], "timestamp":"1784449237753", "event_type":"price_change"}
{"market":"0xab772601f501b265bfe8982eb61d5347ef9945de314bfdf4ac0189c288ffb0b3", "price_changes":[{"asset_id":"17924629579804316786455515989238352689210911545477836576430679697715946894553", "price":"0.59", "size":"355.34", "side":"BUY", "hash":"0fbc5d2899fc1f098a644175ed06f7748183e8aa", "best_bid":"0.61", "best_ask":"0.62"}, {"asset_id":"12935926064588426924078449947177910958215776269411501731627440228801766632772", "price":"0.41", "size":"355.34", "side":"SELL", "hash":"c87b3d3dd8efa33b35ec8a2a0665a7145caea2a0", "best_bid":"0.38", "best_ask":"0.39"}], "timestamp":"1784449237755", "event_type":"price_change"}
{"market":"0xab772601f501b265bfe8982eb61d5347ef9945de314bfdf4ac0189c288ffb0b3", "price_changes":[{"asset_id":"12935926064588426924078449947177910958215776269411501731627440228801766632772", "price":"0.39", "size":"381.86", "side":"SELL", "hash":"9240bf66857037f78cd2cf038c4e685de3dedb0e", "best_bid":"0.38", "best_ask":"0.39"}, {"asset_id":"17924629579804316786455515989238352689210911545477836576430679697715946894553", "price":"0.61", "size":"381.86", "side":"BUY", "hash":"e74def4ccba6b341f009bfefe4374b4d47dcc677", "best_bid":"0.61", "best_ask":"0.62"}], "timestamp":"1784449237763", "event_type":"price_change"}
{"market":"0xab772601f501b265bfe8982eb61d5347ef9945de314bfdf4ac0189c288ffb0b3", "asset_id":"12935926064588426924078449947177910958215776269411501731627440228801766632772", "bids":[{"price":"0.01", "size":"14889.14"}, {"price":"0.02", "size":"3964.52"}, {"price":"0.03", "size":"2179.29"}, {"price":"0.04", "size":"1215.1"}, {"price":"0.05", "size":"1742.19"}, {"price":"0.06", "size":"1122.02"}, {"price":"0.07", "size":"953.49"}, {"price":"0.08", "size":"1234.38"}, {"price":"0.09", "size":"791.7"}, {"price":"0.1", "size":"561.2"}, {"price":"0.11", "size":"1502.1"}, {"price":"0.12", "size":"1102.45"}, {"price":"0.13", "size":"139.4"}, {"price":"0.14", "size":"281.8"}, {"price":"0.15", "size":"444.04"}, {"price":"0.16", "size":"147.1"}, {"price":"0.17", "size":"207.17"}, {"price":"0.18", "size":"150.7"}, {"price":"0.19", "size":"128.89"}, {"price":"0.2", "size":"246.2"}, {"price":"0.21", "size":"636.8"}, {"price":"0.22", "size":"145.5"}, {"price":"0.23", "size":"137.3"}, {"price":"0.24", "size":"162.22"}, {"price":"0.25", "size":"162.2"}, {"price":"0.26", "size":"134.3"}, {"price":"0.27", "size":"148.5"}, {"price":"0.28", "size":"151.88"}, {"price":"0.29", "size":"222.52"}, {"price":"0.3", "size":"203.04"}, {"price":"0.31", "size":"550.01"}, {"price":"0.32", "size":"244.69"}, {"price":"0.33", "size":"134.65"}, {"price":"0.34", "size":"94.96"}, {"price":"0.35", "size":"106.2"}, {"price":"0.36", "size":"211.77"}, {"price":"0.37", "size":"105.91"}, {"price":"0.38", "size":"35.05"}], "asks":[{"price":"0.99", "size":"13054.5"}, {"price":"0.98", "size":"3885.25"}, {"price":"0.97", "size":"2250.95"}, {"price":"0.96", "size":"1275.1"}, {"price":"0.95", "size":"1768.6"}, {"price":"0.94", "size":"1124.35"}, {"price":"0.93", "size":"959.2"}, {"price":"0.92", "size":"1225.88"}, {"price":"0.91", "size":"796.7"}, {"price":"0.9", "size":"365.2"}, {"price":"0.89", "size":"1502.1"}, {"price":"0.88", "size":"195.05"}, {"price":"0.87", "size":"147.4"}, {"price":"0.86", "size":"183.4"}, {"price":"0.85", "size":"469.43"}, {"price":"0.84", "size":"127.1"}, {"price":"0.83", "size":"107.69"}, {"price":"0.82", "size":"125.7"}, {"price":"0.81", "size":"98.89"}, {"price":"0.8", "size":"201.2"}, {"price":"0.79", "size":"616.8"}, {"price":"0.78", "size":"997.5"}, {"price":"0.77", "size":"67.6"}, {"price":"0.76", "size":"103.73"}, {"price":"0.75", "size":"78.3"}, {"price":"0.74", "size":"76.8"}, {"price":"0.73", "size":"70.3"}, {"price":"0.72", "size":"79.87"}, {"price":"0.71", "size":"74.39"}, {"price":"0.7", "size":"83"}, {"price":"0.69", "size":"64.7"}, {"price":"0.68", "size":"160.64"}, {"price":"0.67", "size":"98.1"}, {"price":"0.66", "size":"77.8"}, {"price":"0.65", "size":"69.6"}, {"price":"0.64", "size":"79.39"}, {"price":"0.63", "size":"194.2"}, {"price":"0.62", "size":"85"}, {"price":"0.61", "size":"69.8"}, {"price":"0.6", "size":"97.94"}, {"price":"0.59", "size":"100.5"}, {"price":"0.58", "size":"86.02"}, {"price":"0.57", "size":"100.3"}, {"price":"0.56", "size":"64.2"}, {"price":"0.55", "size":"204.71"}, {"price":"0.54", "size":"102.1"}, {"price":"0.53", "size":"72.1"}, {"price":"0.52", "size":"83"}, {"price":"0.51", "size":"91"}, {"price":"0.5", "size":"101"}, {"price":"0.49", "size":"406"}, {"price":"0.48", "size":"195"}, {"price":"0.47", "size":"426.02"}, {"price":"0.46", "size":"148.85"}, {"price":"0.45", "size":"226.69"}, {"price":"0.44", "size":"163.99"}, {"price":"0.43", "size":"169"}, {"price":"0.42", "size":"151.82"}, {"price":"0.41", "size":"355.34"}, {"price":"0.4", "size":"146.7"}, {"price":"0.39", "size":"381.86"}], "hash":"9240bf66857037f78cd2cf038c4e685de3dedb0e", "timestamp":"1784449237763", "event_type":"book"}
{"market":"0xab772601f501b265bfe8982eb61d5347ef9945de314bfdf4ac0189c288ffb0b3", "asset_id":"17924629579804316786455515989238352689210911545477836576430679697715946894553", "bids":[{"price":"0.01", "size":"13054.5"}, {"price":"0.02", "size":"3885.25"}, {"price":"0.03", "size":"2250.95"}, {"price":"0.04", "size":"1275.1"}, {"price":"0.05", "size":"1768.6"}, {"price":"0.06", "size":"1124.35"}, {"price":"0.07", "size":"959.2"}, {"price":"0.08", "size":"1225.88"}, {"price":"0.09", "size":"796.7"}, {"price":"0.1", "size":"365.2"}, {"price":"0.11", "size":"1502.1"}, {"price":"0.12", "size":"195.05"}, {"price":"0.13", "size":"147.4"}, {"price":"0.14", "size":"183.4"}, {"price":"0.15", "size":"469.43"}, {"price":"0.16", "size":"127.1"}, {"price":"0.17", "size":"107.69"}, {"price":"0.18", "size":"125.7"}, {"price":"0.19", "size":"98.89"}, {"price":"0.2", "size":"201.2"}, {"price":"0.21", "size":"616.8"}, {"price":"0.22", "size":"997.5"}, {"price":"0.23", "size":"67.6"}, {"price":"0.24", "size":"103.73"}, {"price":"0.25", "size":"78.3"}, {"price":"0.26", "size":"76.8"}, {"price":"0.27", "size":"70.3"}, {"price":"0.28", "size":"79.87"}, {"price":"0.29", "size":"74.39"}, {"price":"0.3", "size":"83"}, {"price":"0.31", "size":"64.7"}, {"price":"0.32", "size":"160.64"}, {"price":"0.33", "size":"98.1"}, {"price":"0.34", "size":"77.8"}, {"price":"0.35", "size":"69.6"}, {"price":"0.36", "size":"79.39"}, {"price":"0.37", "size":"194.2"}, {"price":"0.38", "size":"85"}, {"price":"0.39", "size":"69.8"}, {"price":"0.4", "size":"97.94"}, {"price":"0.41", "size":"100.5"}, {"price":"0.42", "size":"86.02"}, {"price":"0.43", "size":"100.3"}, {"price":"0.44", "size":"64.2"}, {"price":"0.45", "size":"204.71"}, {"price":"0.46", "size":"102.1"}, {"price":"0.47", "size":"72.1"}, {"price":"0.48", "size":"83"}, {"price":"0.49", "size":"91"}, {"price":"0.5", "size":"101"}, {"price":"0.51", "size":"406"}, {"price":"0.52", "size":"195"}, {"price":"0.53", "size":"426.02"}, {"price":"0.54", "size":"148.85"}, {"price":"0.55", "size":"226.69"}, {"price":"0.56", "size":"163.99"}, {"price":"0.57", "size":"169"}, {"price":"0.58", "size":"151.82"}, {"price":"0.59", "size":"355.34"}, {"price":"0.6", "size":"146.7"}, {"price":"0.61", "size":"381.86"}], "asks":[{"price":"0.99", "size":"14889.14"}, {"price":"0.98", "size":"3964.52"}, {"price":"0.97", "size":"2179.29"}, {"price":"0.96", "size":"1215.1"}, {"price":"0.95", "size":"1742.19"}, {"price":"0.94", "size":"1122.02"}, {"price":"0.93", "size":"953.49"}, {"price":"0.92", "size":"1234.38"}, {"price":"0.91", "size":"791.7"}, {"price":"0.9", "size":"561.2"}, {"price":"0.89", "size":"1502.1"}, {"price":"0.88", "size":"1102.45"}, {"price":"0.87", "size":"139.4"}, {"price":"0.86", "size":"281.8"}, {"price":"0.85", "size":"444.04"}, {"price":"0.84", "size":"147.1"}, {"price":"0.83", "size":"207.17"}, {"price":"0.82", "size":"150.7"}, {"price":"0.81", "size":"128.89"}, {"price":"0.8", "size":"246.2"}, {"price":"0.79", "size":"636.8"}, {"price":"0.78", "size":"145.5"}, {"price":"0.77", "size":"137.3"}, {"price":"0.76", "size":"162.22"}, {"price":"0.75", "size":"162.2"}, {"price":"0.74", "size":"134.3"}, {"price":"0.73", "size":"148.5"}, {"price":"0.72", "size":"151.88"}, {"price":"0.71", "size":"222.52"}, {"price":"0.7", "size":"203.04"}, {"price":"0.69", "size":"550.01"}, {"price":"0.68", "size":"244.69"}, {"price":"0.67", "size":"134.65"}, {"price":"0.66", "size":"94.96"}, {"price":"0.65", "size":"106.2"}, {"price":"0.64", "size":"211.77"}, {"price":"0.63", "size":"105.91"}, {"price":"0.62", "size":"35.05"}], "hash":"e74def4ccba6b341f009bfefe4374b4d47dcc677", "timestamp":"1784449237763", "event_type":"book"}
{"market":"0xab772601f501b265bfe8982eb61d5347ef9945de314bfdf4ac0189c288ffb0b3", "price_changes":[{"asset_id":"12935926064588426924078449947177910958215776269411501731627440228801766632772", "price":"0.01", "size":"14884.14", "side":"BUY", "hash":"5b356ae8c0060f3cfa98a29549508d92abb822c7", "best_bid":"0.38", "best_ask":"0.39"}, {"asset_id":"17924629579804316786455515989238352689210911545477836576430679697715946894553", "price":"0.99", "size":"14884.14", "side":"SELL", "hash":"5439436ed5ca0a5ef2b077e133f4bbecf9ca0b75", "best_bid":"0.61", "best_ask":"0.62"}], "timestamp":"1784449237766", "event_type":"price_change"}
{"market":"0xab772601f501b265bfe8982eb61d5347ef9945de314bfdf4ac0189c288ffb0b3", "price_changes":[{"asset_id":"17924629579804316786455515989238352689210911545477836576430679697715946894553", "price":"0.01", "size":"12954.5", "side":"BUY", "hash":"735df9bb6a6b5e5371546f113221cef1fb9296f1", "best_bid":"0.61", "best_ask":"0.62"}, {"asset_id":"12935926064588426924078449947177910958215776269411501731627440228801766632772", "price":"0.99", "size":"12954.5", "side":"SELL", "hash":"adfbe241e538a276df1fc7bc6d1d8b3ddbf483c9", "best_bid":"0.38", "best_ask":"0.39"}], "timestamp":"1784449237766", "event_type":"price_change"}
{"market":"0xab772601f501b265bfe8982eb61d5347ef9945de314bfdf4ac0189c288ffb0b3", "price_changes":[{"asset_id":"17924629579804316786455515989238352689210911545477836576430679697715946894553", "price":"0.59", "size":"255.34", "side":"BUY", "hash":"c41a2b1171f3204b08f11eb0f2197fb590af780c", "best_bid":"0.61", "best_ask":"0.62"}, {"asset_id":"12935926064588426924078449947177910958215776269411501731627440228801766632772", "price":"0.41", "size":"255.34", "side":"SELL", "hash":"322465dbee301a57454eed875f86e52f9c19da88", "best_bid":"0.38", "best_ask":"0.39"}], "timestamp":"1784449237767", "event_type":"price_change"}
{"market":"0xab772601f501b265bfe8982eb61d5347ef9945de314bfdf4ac0189c288ffb0b3", "price_changes":[{"asset_id":"17924629579804316786455515989238352689210911545477836576430679697715946894553", "price":"0.04", "size":"1270.1", "side":"BUY", "hash":"c54f533186c9e5641643e80d13813f519c3f47e1", "best_bid":"0.61", "best_ask":"0.62"}, {"asset_id":"12935926064588426924078449947177910958215776269411501731627440228801766632772", "price":"0.96", "size":"1270.1", "side":"SELL", "hash":"8844eb5d85021b2ec0eb94481b0a25633723e6f8", "best_bid":"0.38", "best_ask":"0.39"}], "timestamp":"1784449237767", "event_type":"price_change"}
{"market":"0xab772601f501b265bfe8982eb61d5347ef9945de314bfdf4ac0189c288ffb0b3", "price_changes":[{"asset_id":"12935926064588426924078449947177910958215776269411501731627440228801766632772", "price":"0.3", "size":"228.04", "side":"BUY", "hash":"303919efd859ecc7057e2dd33a006cb9c871674b", "best_bid":"0.38", "best_ask":"0.39"}, {"asset_id":"17924629579804316786455515989238352689210911545477836576430679697715946894553", "price":"0.7", "size":"228.04", "side":"SELL", "hash":"4eeaa84a07801e883df02b38dcfe5ccfc63c0731", "best_bid":"0.61", "best_ask":"0.62"}], "timestamp":"1784449237771", "event_type":"price_change"}
{"market":"0xab772601f501b265bfe8982eb61d5347ef9945de314bfdf4ac0189c288ffb0b3", "price_changes":[{"asset_id":"12935926064588426924078449947177910958215776269411501731627440228801766632772", "price":"0.3", "size":"203.04", "side":"BUY", "hash":"32214e698a37a6131d5c088523afab45ec76bcc0", "best_bid":"0.38", "best_ask":"0.39"}, {"asset_id":"17924629579804316786455515989238352689210911545477836576430679697715946894553", "price":"0.7", "size":"203.04", "side":"SELL", "hash":"1ae15237e04b41d62931f15e479f7297435db9dd", "best_bid":"0.61", "best_ask":"0.62"}], "timestamp":"1784449237773", "event_type":"price_change"}
{"market":"0xab772601f501b265bfe8982eb61d5347ef9945de314bfdf4ac0189c288ffb0b3", "price_changes":[{"asset_id":"17924629579804316786455515989238352689210911545477836576430679697715946894553", "price":"0.51", "size":"396", "side":"BUY", "hash":"826b9f117b4bedf3e7ffa0a9bda8b6850c822a9b", "best_bid":"0.61", "best_ask":"0.62"}, {"asset_id":"12935926064588426924078449947177910958215776269411501731627440228801766632772", "price":"0.49", "size":"396", "side":"SELL", "hash":"8c619956900049106f3735ab6ace0671bf2254c4", "best_bid":"0.38", "best_ask":"0.39"}], "timestamp":"1784449237784", "event_type":"price_change"}
{"market":"0xab772601f501b265bfe8982eb61d5347ef9945de314bfdf4ac0189c288ffb0b3", "price_changes":[{"asset_id":"17924629579804316786455515989238352689210911545477836576430679697715946894553", "price":"0.61", "size":"374.16", "side":"BUY", "hash":"949fef1934fdc1ec20b083960a8605ba198b14dc", "best_bid":"0.61", "best_ask":"0.62"}, {"asset_id":"12935926064588426924078449947177910958215776269411501731627440228801766632772", "price":"0.39", "size":"374.16", "side":"SELL", "hash":"ffcd68a9004511a6b60761a48a136b9ef216272a", "best_bid":"0.38", "best_ask":"0.39"}], "timestamp":"1784449237786", "event_type":"price_change"}
{"market":"0xab772601f501b265bfe8982eb61d5347ef9945de314bfdf4ac0189c288ffb0b3", "price_changes":[{"asset_id":"12935926064588426924078449947177910958215776269411501731627440228801766632772", "price":"0.39", "size":"374.16", "side":"SELL", "hash":"ffcd68a9004511a6b60761a48a136b9ef216272a", "best_bid":"0.38", "best_ask":"0.39"}, {"asset_id":"17924629579804316786455515989238352689210911545477836576430679697715946894553", "price":"0.61", "size":"374.16", "side":"BUY", "hash":"949fef1934fdc1ec20b083960a8605ba198b14dc", "best_bid":"0.61", "best_ask":"0.62"}], "timestamp":"1784449237786", "event_type":"price_change"}
