{"market":"0x982eae4503214e5d7992668e93f48f42e4707b92e23bb45f8d52d321f643cbe3", "asset_id":"74913635031537477155015393896000154190746945075332596665612975928350948042868", "bids":[{"price":"0.01", "size":"16179.14"}, {"price":"0.02", "size":"3289.11"}, {"price":"0.03", "size":"2085.95"}, {"price":"0.04", "size":"1462.1"}, {"price":"0.05", "size":"1953.67"}, {"price":"0.06", "size":"1677.35"}, {"price":"0.07", "size":"1155.2"}, {"price":"0.08", "size":"1325.88"}, {"price":"0.09", "size":"1027.7"}, {"price":"0.1", "size":"528.2"}, {"price":"0.11", "size":"454.1"}, {"price":"0.12", "size":"203.05"}, {"price":"0.13", "size":"179.4"}, {"price":"0.14", "size":"159.4"}, {"price":"0.15", "size":"149.23"}, {"price":"0.16", "size":"150.4"}, {"price":"0.17", "size":"105.08"}, {"price":"0.18", "size":"127.3"}, {"price":"0.19", "size":"99.78"}, {"price":"0.2", "size":"181.4"}, {"price":"0.21", "size":"111.5"}, {"price":"0.22", "size":"125.7"}, {"price":"0.23", "size":"92"}, {"price":"0.24", "size":"111.5"}, {"price":"0.25", "size":"823.6"}, {"price":"0.26", "size":"148.03"}, {"price":"0.27", "size":"86.7"}, {"price":"0.28", "size":"100.6"}, {"price":"0.29", "size":"84.59"}, {"price":"0.3", "size":"107.8"}, {"price":"0.31", "size":"79.1"}, {"price":"0.32", "size":"107.19"}, {"price":"0.33", "size":"76.7"}, {"price":"0.34", "size":"89"}, {"price":"0.35", "size":"84.4"}, {"price":"0.36", "size":"86.99"}, {"price":"0.37", "size":"73.6"}, {"price":"0.38", "size":"85"}, {"price":"0.39", "size":"71.6"}, {"price":"0.4", "size":"88.3"}, {"price":"0.41", "size":"69.9"}, {"price":"0.42", "size":"142.27"}, {"price":"0.43", "size":"109.8"}, {"price":"0.44", "size":"91.08"}, {"price":"0.45", "size":"104.31"}, {"price":"0.46", "size":"80.1"}, {"price":"0.47", "size":"94.9"}, {"price":"0.48", "size":"88.8"}, {"price":"0.49", "size":"99.36"}, {"price":"0.5", "size":"102.8"}, {"price":"0.51", "size":"100.8"}, {"price":"0.52", "size":"95.8"}, {"price":"0.53", "size":"104.9"}, {"price":"0.54", "size":"92.1"}, {"price":"0.55", "size":"485.2"}, {"price":"0.56", "size":"95.4"}, {"price":"0.57", "size":"85.5"}, {"price":"0.58", "size":"101.12"}, {"price":"0.59", "size":"94.9"}, {"price":"0.6", "size":"203.58"}, {"price":"0.61", "size":"105.6"}, {"price":"0.62", "size":"130"}, {"price":"0.63", "size":"150.6"}, {"price":"0.64", "size":"482.99"}, {"price":"0.65", "size":"107.4"}, {"price":"0.66", "size":"143.24"}, {"price":"0.67", "size":"312.58"}, {"price":"0.68", "size":"93.19"}, {"price":"0.69", "size":"104.1"}, {"price":"0.7", "size":"113.04"}, {"price":"0.71", "size":"84"}, {"price":"0.72", "size":"283"}, {"price":"0.73", "size":"179.41"}, {"price":"0.74", "size":"146.85"}, {"price":"0.75", "size":"172.84"}, {"price":"0.76", "size":"160.24"}, {"price":"0.77", "size":"189.66"}, {"price":"0.78", "size":"228.41"}, {"price":"0.79", "size":"88.19"}, {"price":"0.8", "size":"58.58"}], "asks":[{"price":"0.99", "size":"17934.98"}, {"price":"0.98", "size":"3156.06"}, {"price":"0.97", "size":"3788.29"}, {"price":"0.96", "size":"1529.1"}, {"price":"0.95", "size":"1803.6"}, {"price":"0.94", "size":"1208.35"}, {"price":"0.93", "size":"1367.2"}, {"price":"0.92", "size":"1409.68"}, {"price":"0.91", "size":"942.82"}, {"price":"0.9", "size":"518.32"}, {"price":"0.89", "size":"503.73"}, {"price":"0.88", "size":"241.17"}, {"price":"0.87", "size":"397.4"}, {"price":"0.86", "size":"169.14"}, {"price":"0.85", "size":"155.71"}, {"price":"0.84", "size":"104.17"}, {"price":"0.83", "size":"39.31"}], "hash":"ce55971509f65f809c39342309ced2eac35e91cb", "timestamp":"1784449597275", "event_type":"book"}
{"market":"0x982eae4503214e5d7992668e93f48f42e4707b92e23bb45f8d52d321f643cbe3", "asset_id":"37613674580450069178400687025689415665506452565086963049482350052080099056186", "bids":[{"price":"0.01", "size":"17934.98"}, {"price":"0.02", "size":"3156.06"}, {"price":"0.03", "size":"3788.29"}, {"price":"0.04", "size":"1529.1"}, {"price":"0.05", "size":"1803.6"}, {"price":"0.06", "size":"1208.35"}, {"price":"0.07", "size":"1367.2"}, {"price":"0.08", "size":"1409.68"}, {"price":"0.09", "size":"942.82"}, {"price":"0.1", "size":"518.32"}, {"price":"0.11", "size":"503.73"}, {"price":"0.12", "size":"241.17"}, {"price":"0.13", "size":"397.4"}, {"price":"0.14", "size":"169.14"}, {"price":"0.15", "size":"155.71"}, {"price":"0.16", "size":"104.17"}, {"price":"0.17", "size":"39.31"}], "asks":[{"price":"0.99", "size":"16179.14"}, {"price":"0.98", "size":"3289.11"}, {"price":"0.97", "size":"2085.95"}, {"price":"0.96", "size":"1462.1"}, {"price":"0.95", "size":"1953.67"}, {"price":"0.94", "size":"1677.35"}, {"price":"0.93", "size":"1155.2"}, {"price":"0.92", "size":"1325.88"}, {"price":"0.91", "size":"1027.7"}, {"price":"0.9", "size":"528.2"}, {"price":"0.89", "size":"454.1"}, {"price":"0.88", "size":"203.05"}, {"price":"0.87", "size":"179.4"}, {"price":"0.86", "size":"159.4"}, {"price":"0.85", "size":"149.23"}, {"price":"0.84", "size":"150.4"}, {"price":"0.83", "size":"105.08"}, {"price":"0.82", "size":"127.3"}, {"price":"0.81", "size":"99.78"}, {"price":"0.8", "size":"181.4"}, {"price":"0.79", "size":"111.5"}, {"price":"0.78", "size":"125.7"}, {"price":"0.77", "size":"92"}, {"price":"0.76", "size":"111.5"}, {"price":"0.75", "size":"823.6"}, {"price":"0.74", "size":"148.03"}, {"price":"0.73", "size":"86.7"}, {"price":"0.72", "size":"100.6"}, {"price":"0.71", "size":"84.59"}, {"price":"0.7", "size":"107.8"}, {"price":"0.69", "size":"79.1"}, {"price":"0.68", "size":"107.19"}, {"price":"0.67", "size":"76.7"}, {"price":"0.66", "size":"89"}, {"price":"0.65", "size":"84.4"}, {"price":"0.64", "size":"86.99"}, {"price":"0.63", "size":"73.6"}, {"price":"0.62", "size":"85"}, {"price":"0.61", "size":"71.6"}, {"price":"0.6", "size":"88.3"}, {"price":"0.59", "size":"69.9"}, {"price":"0.58", "size":"142.27"}, {"price":"0.57", "size":"109.8"}, {"price":"0.56", "size":"91.08"}, {"price":"0.55", "size":"104.31"}, {"price":"0.54", "size":"80.1"}, {"price":"0.53", "size":"94.9"}, {"price":"0.52", "size":"88.8"}, {"price":"0.51", "size":"99.36"}, {"price":"0.5", "size":"102.8"}, {"price":"0.49", "size":"100.8"}, {"price":"0.48", "size":"95.8"}, {"price":"0.47", "size":"104.9"}, {"price":"0.46", "size":"92.1"}, {"price":"0.45", "size":"485.2"}, {"price":"0.44", "size":"95.4"}, {"price":"0.43", "size":"85.5"}, {"price":"0.42", "size":"101.12"}, {"price":"0.41", "size":"94.9"}, {"price":"0.4", "size":"203.58"}, {"price":"0.39", "size":"105.6"}, {"price":"0.38", "size":"130"}, {"price":"0.37", "size":"150.6"}, {"price":"0.36", "size":"482.99"}, {"price":"0.35", "size":"107.4"}, {"price":"0.34", "size":"143.24"}, {"price":"0.33", "size":"312.58"}, {"price":"0.32", "size":"93.19"}, {"price":"0.31", "size":"104.1"}, {"price":"0.3", "size":"113.04"}, {"price":"0.29", "size":"84"}, {"price":"0.28", "size":"283"}, {"price":"0.27", "size":"179.41"}, {"price":"0.26", "size":"146.85"}, {"price":"0.25", "size":"172.84"}, {"price":"0.24", "size":"160.24"}, {"price":"0.23", "size":"189.66"}, {"price":"0.22", "size":"228.41"}, {"price":"0.21", "size":"88.19"}, {"price":"0.2", "size":"58.58"}], "hash":"e7b0affdb4f4faeb39ff2f3c53c60502d03206ac", "timestamp":"1784449597275", "event_type":"book"}
{"market":"0x982eae4503214e5d7992668e93f48f42e4707b92e23bb45f8d52d321f643cbe3", "price_changes":[{"asset_id":"74913635031537477155015393896000154190746945075332596665612975928350948042868", "price":"0.02", "size":"3294.11", "side":"BUY", "hash":"e64cae4134095240ebdbb1b5b6e46e162d0f1d50", "best_bid":"0.8", "best_ask":"0.83"}, {"asset_id":"37613674580450069178400687025689415665506452565086963049482350052080099056186", "price":"0.98", "size":"3294.11", "side":"SELL", "hash":"e86e960a0707c9200e266e677b853e2e38b59b22", "best_bid":"0.17", "best_ask":"0.2"}], "timestamp":"1784449597284", "event_type":"price_change"}
{"market":"0x982eae4503214e5d7992668e93f48f42e4707b92e23bb45f8d52d321f643cbe3", "price_changes":[{"asset_id":"37613674580450069178400687025689415665506452565086963049482350052080099056186", "price":"0.17", "size":"31.31", "side":"BUY", "hash":"bb70878be1426dc58034d809680901c8e5d47ec3", "best_bid":"0.17", "best_ask":"0.2"}, {"asset_id":"74913635031537477155015393896000154190746945075332596665612975928350948042868", "price":"0.83", "size":"31.31", "side":"SELL", "hash":"c9a67105c2825cd7c7e59fade7899c827e9cf79b", "best_bid":"0.8", "best_ask":"0.83"}], "timestamp":"1784449597285", "event_type":"price_change"}
{"market":"0x982eae4503214e5d7992668e93f48f42e4707b92e23bb45f8d52d321f643cbe3", "price_changes":[{"asset_id":"37613674580450069178400687025689415665506452565086963049482350052080099056186", "price":"0.08", "size":"1414.68", "side":"BUY", "hash":"f879fca4d424c3c6751a77dc5609e88e80758063", "best_bid":"0.17", "best_ask":"0.2"}, {"asset_id":"74913635031537477155015393896000154190746945075332596665612975928350948042868", "price":"0.92", "size":"1414.68", "side":"SELL", "hash":"3202ea6fee91210b462f111c0e5f4db68b3fce3c", "best_bid":"0.8", "best_ask":"0.83"}], "timestamp":"1784449597285", "event_type":"price_change"}
{"market":"0x982eae4503214e5d7992668e93f48f42e4707b92e23bb45f8d52d321f643cbe3", "price_changes":[{"asset_id":"74913635031537477155015393896000154190746945075332596665612975928350948042868", "price":"0.01", "size":"16174.14", "side":"BUY", "hash":"688e540a894d572282527b693cdec86bfa936113", "best_bid":"0.8", "best_ask":"0.83"}, {"asset_id":"37613674580450069178400687025689415665506452565086963049482350052080099056186", "price":"0.99", "size":"16174.14", "side":"SELL", "hash":"d1a99fef5fa4e1640403768c7306993494b817be", "best_bid":"0.17", "best_ask":"0.2"}], "timestamp":"1784449597289", "event_type":"price_change"}
{"market":"0x982eae4503214e5d7992668e93f48f42e4707b92e23bb45f8d52d321f643cbe3", "price_changes":[{"asset_id":"37613674580450069178400687025689415665506452565086963049482350052080099056186", "price":"0.19", "size":"13.33", "side":"BUY", "hash":"2e191aa608d2cbbc1414c5f5996822203d758580", "best_bid":"0.19", "best_ask":"0.2"}, {"asset_id":"74913635031537477155015393896000154190746945075332596665612975928350948042868", "price":"0.81", "size":"13.33", "side":"SELL", "hash":"88cade47506eb9c0e04f2e20e1bacca6a3d072bf", "best_bid":"0.8", "best_ask":"0.81"}], "timestamp":"1784449597291", "event_type":"price_change"}
{"market":"0x982eae4503214e5d7992668e93f48f42e4707b92e23bb45f8d52d321f643cbe3", "price_changes":[{"asset_id":"37613674580450069178400687025689415665506452565086963049482350052080099056186", "price":"0.18", "size":"13.33", "side":"BUY", "hash":"f362337b53af5f96d7fad194b2acfe91dfab62c4", "best_bid":"0.19", "best_ask":"0.2"}, {"asset_id":"74913635031537477155015393896000154190746945075332596665612975928350948042868", "price":"0.82", "size":"13.33", "side":"SELL", "hash":"d47937da56c443e0d1eab728c62d3c2c8be35f37", "best_bid":"0.8", "best_ask":"0.81"}], "timestamp":"1784449597291", "event_type":"price_change"}
{"market":"0x982eae4503214e5d7992668e93f48f42e4707b92e23bb45f8d52d321f643cbe3", "price_changes":[{"asset_id":"37613674580450069178400687025689415665506452565086963049482350052080099056186", "price":"0.17", "size":"16.31", "side":"BUY", "hash":"1f7b8484c7736da0980256ce71aa8001937f7ced", "best_bid":"0.19", "best_ask":"0.2"}, {"asset_id":"74913635031537477155015393896000154190746945075332596665612975928350948042868", "price":"0.83", "size":"16.31", "side":"SELL", "hash":"2edbceeef5c379d7566e273fcba8abc3eba51e50", "best_bid":"0.8", "best_ask":"0.81"}], "timestamp":"1784449597292", "event_type":"price_change"}
{"market":"0x982eae4503214e5d7992668e93f48f42e4707b92e23bb45f8d52d321f643cbe3", "price_changes":[{"asset_id":"74913635031537477155015393896000154190746945075332596665612975928350948042868", "price":"0.72", "size":"268", "side":"BUY", "hash":"14078354fba561e668ec9b231f0f4f3883314e90", "best_bid":"0.8", "best_ask":"0.81"}, {"asset_id":"37613674580450069178400687025689415665506452565086963049482350052080099056186", "price":"0.28", "size":"268", "side":"SELL", "hash":"47896168e71a8739c68805fac5270c397a6a2e79", "best_bid":"0.19", "best_ask":"0.2"}], "timestamp":"1784449597294", "event_type":"price_change"}
{"market":"0x982eae4503214e5d7992668e93f48f42e4707b92e23bb45f8d52d321f643cbe3", "price_changes":[{"asset_id":"74913635031537477155015393896000154190746945075332596665612975928350948042868", "price":"0.01", "size":"16169.13", "side":"BUY", "hash":"fd4b3ebc0bbb3d27ab88143a6bdfa089d16f8943", "best_bid":"0.8", "best_ask":"0.81"}, {"asset_id":"37613674580450069178400687025689415665506452565086963049482350052080099056186", "price":"0.99", "size":"16169.13", "side":"SELL", "hash":"b301de980141d83210ffb56668699271a2da6194", "best_bid":"0.19", "best_ask":"0.2"}], "timestamp":"1784449597294", "event_type":"price_change"}
{"market":"0x982eae4503214e5d7992668e93f48f42e4707b92e23bb45f8d52d321f643cbe3", "price_changes":[{"asset_id":"74913635031537477155015393896000154190746945075332596665612975928350948042868", "price":"0.76", "size":"135.24", "side":"BUY", "hash":"5f5c0e149d92ba4de83875c91005ba95e497bc8a", "best_bid":"0.8", "best_ask":"0.81"}, {"asset_id":"37613674580450069178400687025689415665506452565086963049482350052080099056186", "price":"0.24", "size":"135.24", "side":"SELL", "hash":"dd124dc321af0b0ad2043fa44981a2ca2894a0e4", "best_bid":"0.19", "best_ask":"0.2"}], "timestamp":"1784449597297", "event_type":"price_change"}
{"market":"0x982eae4503214e5d7992668e93f48f42e4707b92e23bb45f8d52d321f643cbe3", "price_changes":[{"asset_id":"74913635031537477155015393896000154190746945075332596665612975928350948042868", "price":"0.8", "size":"73.58", "side":"BUY", "hash":"8b02533742454396647180367d68875ee7e5ba11", "best_bid":"0.8", "best_ask":"0.81"}, {"asset_id":"37613674580450069178400687025689415665506452565086963049482350052080099056186", "price":"0.2", "size":"73.58", "side":"SELL", "hash":"acc1ea26e784652ef02f79255f06acff0267dc81", "best_bid":"0.19", "best_ask":"0.2"}], "timestamp":"1784449597299", "event_type":"price_change"}
{"market":"0x982eae4503214e5d7992668e93f48f42e4707b92e23bb45f8d52d321f643cbe3", "price_changes":[{"asset_id":"74913635031537477155015393896000154190746945075332596665612975928350948042868", "price":"0.8", "size":"68.58", "side":"BUY", "hash":"301d508e5d0cd48ff9f857f85d4441b1da5d801a", "best_bid":"0.8", "best_ask":"0.81"}, {"asset_id":"37613674580450069178400687025689415665506452565086963049482350052080099056186", "price":"0.2", "size":"68.58", "side":"SELL", "hash":"5c497d07a5f842f15d31422b5582909cbf6f1eaa", "best_bid":"0.19", "best_ask":"0.2"}], "timestamp":"1784449597304", "event_type":"price_change"}
{"market":"0x982eae4503214e5d7992668e93f48f42e4707b92e23bb45f8d52d321f643cbe3", "price_changes":[{"asset_id":"37613674580450069178400687025689415665506452565086963049482350052080099056186", "price":"0.12", "size":"216.17", "side":"BUY", "hash":"baaeee8b11e38346054e05984b35d53bd2fd3339", "best_bid":"0.19", "best_ask":"0.2"}, {"asset_id":"74913635031537477155015393896000154190746945075332596665612975928350948042868", "price":"0.88", "size":"216.17", "side":"SELL", "hash":"567f2ebdbf222a487417101959b5fbb0db38e3ba", "best_bid":"0.8", "best_ask":"0.81"}], "timestamp":"1784449597304", "event_type":"price_change"}
{"market":"0x982eae4503214e5d7992668e93f48f42e4707b92e23bb45f8d52d321f643cbe3", "price_changes":[{"asset_id":"37613674580450069178400687025689415665506452565086963049482350052080099056186", "price":"0.09", "size":"937.7", "side":"BUY", "hash":"dfe312baa33c39957d2f87741bef63f845cb8347", "best_bid":"0.19", "best_ask":"0.2"}, {"asset_id":"74913635031537477155015393896000154190746945075332596665612975928350948042868", "price":"0.91", "size":"937.7", "side":"SELL", "hash":"57143b90137a28e39e81dd0c282e4a00280f7540", "best_bid":"0.8", "best_ask":"0.81"}], "timestamp":"1784449597304", "event_type":"price_change"}
{"market":"0x982eae4503214e5d7992668e93f48f42e4707b92e23bb45f8d52d321f643cbe3", "price_changes":[{"asset_id":"74913635031537477155015393896000154190746945075332596665612975928350948042868", "price":"0.72", "size":"274.42", "side":"BUY", "hash":"2144a8bda50e3d5dc522ba9f1d32b98c41b709e9", "best_bid":"0.8", "best_ask":"0.81"}, {"asset_id":"37613674580450069178400687025689415665506452565086963049482350052080099056186", "price":"0.28", "size":"274.42", "side":"SELL", "hash":"d062a3a490c469318a4f5f79463b94ae66cf7110", "best_bid":"0.19", "best_ask":"0.2"}], "timestamp":"1784449597305", "event_type":"price_change"}
{"market":"0x982eae4503214e5d7992668e93f48f42e4707b92e23bb45f8d52d321f643cbe3", "price_changes":[{"asset_id":"74913635031537477155015393896000154190746945075332596665612975928350948042868", "price":"0.01", "size":"16669.13", "side":"BUY", "hash":"2e46048c3e486e64cb3dcbdf114d7c14ef68d4f6", "best_bid":"0.8", "best_ask":"0.81"}, {"asset_id":"37613674580450069178400687025689415665506452565086963049482350052080099056186", "price":"0.99", "size":"16669.13", "side":"SELL", "hash":"5c997c752b5c36a670da527d8c810233564ef767", "best_bid":"0.19", "best_ask":"0.2"}], "timestamp":"1784449597307", "event_type":"price_change"}
{"market":"0x982eae4503214e5d7992668e93f48f42e4707b92e23bb45f8d52d321f643cbe3", "price_changes":[{"asset_id":"74913635031537477155015393896000154190746945075332596665612975928350948042868", "price":"0.8", "size":"53.58", "side":"BUY", "hash":"0c48627a4f228b048b073f4a79fa31de7624e730", "best_bid":"0.8", "best_ask":"0.81"}, {"asset_id":"37613674580450069178400687025689415665506452565086963049482350052080099056186", "price":"0.2", "size":"53.58", "side":"SELL", "hash":"dd5c687b56bb224d0e57772aae93a73d776f9ec9", "best_bid":"0.19", "best_ask":"0.2"}], "timestamp":"1784449597308", "event_type":"price_change"}
{"market":"0x982eae4503214e5d7992668e93f48f42e4707b92e23bb45f8d52d321f643cbe3", "price_changes":[{"asset_id":"74913635031537477155015393896000154190746945075332596665612975928350948042868", "price":"0.78", "size":"213.41", "side":"BUY", "hash":"d10ef1aac13f0a76e6cbc1ebcd8b4558d2890d16", "best_bid":"0.8", "best_ask":"0.81"}, {"asset_id":"37613674580450069178400687025689415665506452565086963049482350052080099056186", "price":"0.22", "size":"213.41", "side":"SELL", "hash":"e3e2af47ae78f5dc82b254f0ce312876ff68d735", "best_bid":"0.19", "best_ask":"0.2"}], "timestamp":"1784449597308", "event_type":"price_change"}
{"market":"0x982eae4503214e5d7992668e93f48f42e4707b92e23bb45f8d52d321f643cbe3", "price_changes":[{"asset_id":"74913635031537477155015393896000154190746945075332596665612975928350948042868", "price":"0.79", "size":"73.19", "side":"BUY", "hash":"d10ef1aac13f0a76e6cbc1ebcd8b4558d2890d16", "best_bid":"0.8", "best_ask":"0.81"}, {"asset_id":"37613674580450069178400687025689415665506452565086963049482350052080099056186", "price":"0.21", "size":"73.19", "side":"SELL", "hash":"e3e2af47ae78f5dc82b254f0ce312876ff68d735", "best_bid":"0.19", "best_ask":"0.2"}], "timestamp":"1784449597308", "event_type":"price_change"}
{"market":"0x982eae4503214e5d7992668e93f48f42e4707b92e23bb45f8d52d321f643cbe3", "price_changes":[{"asset_id":"37613674580450069178400687025689415665506452565086963049482350052080099056186", "price":"0.08", "size":"1409.68", "side":"BUY", "hash":"1ae98976627662cd6d197fd163ebd4525b85bad9", "best_bid":"0.19", "best_ask":"0.2"}, {"asset_id":"74913635031537477155015393896000154190746945075332596665612975928350948042868", "price":"0.92", "size":"1409.68", "side":"SELL", "hash":"6d265f6f5ab39f8dd4524e804f05ce66722ae1fd", "best_bid":"0.8", "best_ask":"0.81"}], "timestamp":"1784449597312", "event_type":"price_change"}
{"market":"0x982eae4503214e5d7992668e93f48f42e4707b92e23bb45f8d52d321f643cbe3", "price_changes":[{"asset_id":"74913635031537477155015393896000154190746945075332596665612975928350948042868", "price":"0.01", "size":"16769.13", "side":"BUY", "hash":"91c26f37506fd52f375b823d0d7572772dd3d6f9", "best_bid":"0.8", "best_ask":"0.81"}, {"asset_id":"37613674580450069178400687025689415665506452565086963049482350052080099056186", "price":"0.99", "size":"16769.13", "side":"SELL", "hash":"f009c260b62de54ef656f0f33d4f594b449c42bf", "best_bid":"0.19", "best_ask":"0.2"}], "timestamp":"1784449597313", "event_type":"price_change"}
{"market":"0x982eae4503214e5d7992668e93f48f42e4707b92e23bb45f8d52d321f643cbe3", "price_changes":[{"asset_id":"74913635031537477155015393896000154190746945075332596665612975928350948042868", "price":"0.54", "size":"85.1", "side":"BUY", "hash":"69d39a62771f9e513ec2263689f500fe04e4dddf", "best_bid":"0.8", "best_ask":"0.81"}, {"asset_id":"37613674580450069178400687025689415665506452565086963049482350052080099056186", "price":"0.46", "size":"85.1", "side":"SELL", "hash":"ab982bb447b2b8a73829a298bb1b100caeb2ef98", "best_bid":"0.19", "best_ask":"0.2"}], "timestamp":"1784449597313", "event_type":"price_change"}
{"market":"0x982eae4503214e5d7992668e93f48f42e4707b92e23bb45f8d52d321f643cbe3", "price_changes":[{"asset_id":"74913635031537477155015393896000154190746945075332596665612975928350948042868", "price":"0.8", "size":"46.51", "side":"BUY", "hash":"b672b68cc056408d4a340a5b7f266da530b4eec0", "best_bid":"0.8", "best_ask":"0.81"}, {"asset_id":"37613674580450069178400687025689415665506452565086963049482350052080099056186", "price":"0.2", "size":"46.51", "side":"SELL", "hash":"ce3fba6bb78d1ddcf8160318b82c25b5c184f9a9", "best_bid":"0.19", "best_ask":"0.2"}], "timestamp":"1784449597314", "event_type":"price_change"}
{"market":"0x982eae4503214e5d7992668e93f48f42e4707b92e23bb45f8d52d321f643cbe3", "price_changes":[{"asset_id":"74913635031537477155015393896000154190746945075332596665612975928350948042868", "price":"0.79", "size":"78.56", "side":"BUY", "hash":"3ed5c7cf8bdc026a2f5a353a80379fd7a861c617", "best_bid":"0.8", "best_ask":"0.81"}, {"asset_id":"37613674580450069178400687025689415665506452565086963049482350052080099056186", "price":"0.21", "size":"78.56", "side":"SELL", "hash":"9ca09e84313258b1e9d49daaee1ddd6fb2d1c5ad", "best_bid":"0.19", "best_ask":"0.2"}], "timestamp":"1784449597316", "event_type":"price_change"}
{"market":"0x982eae4503214e5d7992668e93f48f42e4707b92e23bb45f8d52d321f643cbe3", "price_changes":[{"asset_id":"74913635031537477155015393896000154190746945075332596665612975928350948042868", "price":"0.8", "size":"53.52", "side":"BUY", "hash":"49325b2d5d00db2fe5e302e4ab3c55ffa3321caf", "best_bid":"0.8", "best_ask":"0.81"}, {"asset_id":"37613674580450069178400687025689415665506452565086963049482350052080099056186", "price":"0.2", "size":"53.52", "side":"SELL", "hash":"465d80c7f14bf8fc5a04b2f2982ce75066e092d0", "best_bid":"0.19", "best_ask":"0.2"}], "timestamp":"1784449597316", "event_type":"price_change"}
{"market":"0x982eae4503214e5d7992668e93f48f42e4707b92e23bb45f8d52d321f643cbe3", "price_changes":[{"asset_id":"74913635031537477155015393896000154190746945075332596665612975928350948042868", "price":"0.71", "size":"108.98", "side":"BUY", "hash":"fda0d70cb7a108eeb578253daf1550d308f5889d", "best_bid":"0.8", "best_ask":"0.81"}, {"asset_id":"37613674580450069178400687025689415665506452565086963049482350052080099056186", "price":"0.29", "size":"108.98", "side":"SELL", "hash":"d331b926433aa9ccdd7de8a6c44ae76c75ef6e62", "best_bid":"0.19", "best_ask":"0.2"}], "timestamp":"1784449597317", "event_type":"price_change"}
{"market":"0x982eae4503214e5d7992668e93f48f42e4707b92e23bb45f8d52d321f643cbe3", "price_changes":[{"asset_id":"37613674580450069178400687025689415665506452565086963049482350052080099056186", "price":"0.14", "size":"144.14", "side":"BUY", "hash":"dfbc73dcc1e387c19c7370ab0bed928243bd4b2a", "best_bid":"0.19", "best_ask":"0.2"}, {"asset_id":"74913635031537477155015393896000154190746945075332596665612975928350948042868", "price":"0.86", "size":"144.14", "side":"SELL", "hash":"4f2bc53fdc987838409dc4d50029ba148a2f169c", "best_bid":"0.8", "best_ask":"0.81"}], "timestamp":"1784449597321", "event_type":"price_change"}
{"market":"0x982eae4503214e5d7992668e93f48f42e4707b92e23bb45f8d52d321f643cbe3", "price_changes":[{"asset_id":"37613674580450069178400687025689415665506452565086963049482350052080099056186", "price":"0.16", "size":"109.17", "side":"BUY", "hash":"4d741d563b9ec193b095f36f555b17096f8d3e10", "best_bid":"0.19", "best_ask":"0.2"}, {"asset_id":"74913635031537477155015393896000154190746945075332596665612975928350948042868", "price":"0.84", "size":"109.17", "side":"SELL", "hash":"bb61124f68b2aec5a5113117cb19c68115b2503e", "best_bid":"0.8", "best_ask":"0.81"}], "timestamp":"1784449597322", "event_type":"price_change"}
{"market":"0x982eae4503214e5d7992668e93f48f42e4707b92e23bb45f8d52d321f643cbe3", "price_changes":[{"asset_id":"74913635031537477155015393896000154190746945075332596665612975928350948042868", "price":"0.72", "size":"309.89", "side":"BUY", "hash":"1f4a5553f9d8d93f0f7eb88accec95c685bb6ba4", "best_bid":"0.8", "best_ask":"0.81"}, {"asset_id":"37613674580450069178400687025689415665506452565086963049482350052080099056186", "price":"0.28", "size":"309.89", "side":"SELL", "hash":"01bd4f0365d174f85a7f4a80ed407b07ed2e7f6b", "best_bid":"0.19", "best_ask":"0.2"}], "timestamp":"1784449597323", "event_type":"price_change"}
{"market":"0x982eae4503214e5d7992668e93f48f42e4707b92e23bb45f8d52d321f643cbe3", "price_changes":[{"asset_id":"37613674580450069178400687025689415665506452565086963049482350052080099056186", "price":"0.11", "size":"485.73", "side":"BUY", "hash":"0cf6b310a804215f84660f3aba8d93baf28671a0", "best_bid":"0.19", "best_ask":"0.2"}, {"asset_id":"74913635031537477155015393896000154190746945075332596665612975928350948042868", "price":"0.89", "size":"485.73", "side":"SELL", "hash":"63eaa068642074bbff23d9fbd190b3cd10255339", "best_bid":"0.8", "best_ask":"0.81"}], "timestamp":"1784449597324", "event_type":"price_change"}
{"market":"0x982eae4503214e5d7992668e93f48f42e4707b92e23bb45f8d52d321f643cbe3", "price_changes":[{"asset_id":"37613674580450069178400687025689415665506452565086963049482350052080099056186", "price":"0.13", "size":"389.4", "side":"BUY", "hash":"0cf6b310a804215f84660f3aba8d93baf28671a0", "best_bid":"0.19", "best_ask":"0.2"}, {"asset_id":"74913635031537477155015393896000154190746945075332596665612975928350948042868", "price":"0.87", "size":"389.4", "side":"SELL", "hash":"63eaa068642074bbff23d9fbd190b3cd10255339", "best_bid":"0.8", "best_ask":"0.81"}], "timestamp":"1784449597324", "event_type":"price_change"}
{"market":"0x982eae4503214e5d7992668e93f48f42e4707b92e23bb45f8d52d321f643cbe3", "price_changes":[{"asset_id":"37613674580450069178400687025689415665506452565086963049482350052080099056186", "price":"0.12", "size":"204.17", "side":"BUY", "hash":"0cf6b310a804215f84660f3aba8d93baf28671a0", "best_bid":"0.19", "best_ask":"0.2"}, {"asset_id":"74913635031537477155015393896000154190746945075332596665612975928350948042868", "price":"0.88", "size":"204.17", "side":"SELL", "hash":"63eaa068642074bbff23d9fbd190b3cd10255339", "best_bid":"0.8", "best_ask":"0.81"}], "timestamp":"1784449597324", "event_type":"price_change"}
{"market":"0x982eae4503214e5d7992668e93f48f42e4707b92e23bb45f8d52d321f643cbe3", "price_changes":[{"asset_id":"37613674580450069178400687025689415665506452565086963049482350052080099056186", "price":"0.14", "size":"139.14", "side":"BUY", "hash":"0cf6b310a804215f84660f3aba8d93baf28671a0", "best_bid":"0.19", "best_ask":"0.2"}, {"asset_id":"74913635031537477155015393896000154190746945075332596665612975928350948042868", "price":"0.86", "size":"139.14", "side":"SELL", "hash":"63eaa068642074bbff23d9fbd190b3cd10255339", "best_bid":"0.8", "best_ask":"0.81"}], "timestamp":"1784449597324", "event_type":"price_change"}
{"market":"0x982eae4503214e5d7992668e93f48f42e4707b92e23bb45f8d52d321f643cbe3", "price_changes":[{"asset_id":"37613674580450069178400687025689415665506452565086963049482350052080099056186", "price":"0.17", "size":"31.31", "side":"BUY", "hash":"82cc47990cf0cea80a90bc11bdf64600830ee44f", "best_bid":"0.19", "best_ask":"0.2"}, {"asset_id":"74913635031537477155015393896000154190746945075332596665612975928350948042868", "price":"0.83", "size":"31.31", "side":"SELL", "hash":"5be1e9288012310c993395c5202282911ce9101e", "best_bid":"0.8", "best_ask":"0.81"}], "timestamp":"1784449597324", "event_type":"price_change"}
{"market":"0x982eae4503214e5d7992668e93f48f42e4707b92e23bb45f8d52d321f643cbe3", "price_changes":[{"asset_id":"37613674580450069178400687025689415665506452565086963049482350052080099056186", "price":"0.18", "size":"19.66", "side":"BUY", "hash":"f7561763a4150b6b13d9570eb1c826e67d0e4956", "best_bid":"0.19", "best_ask":"0.2"}, {"asset_id":"74913635031537477155015393896000154190746945075332596665612975928350948042868", "price":"0.82", "size":"19.66", "side":"SELL", "hash":"f7e95c48f2e6915a51b2d230cececee6c7c396de", "best_bid":"0.8", "best_ask":"0.81"}], "timestamp":"1784449597325", "event_type":"price_change"}
{"market":"0x982eae4503214e5d7992668e93f48f42e4707b92e23bb45f8d52d321f643cbe3", "price_changes":[{"asset_id":"37613674580450069178400687025689415665506452565086963049482350052080099056186", "price":"0.18", "size":"6.33", "side":"BUY", "hash":"e15de9ce8d706d347ca3ca14a32213e109a9c96e", "best_bid":"0.19", "best_ask":"0.2"}, {"asset_id":"74913635031537477155015393896000154190746945075332596665612975928350948042868", "price":"0.82", "size":"6.33", "side":"SELL", "hash":"a0da50ed611142735988a01cebafbd843e4eb391", "best_bid":"0.8", "best_ask":"0.81"}], "timestamp":"1784449597325", "event_type":"price_change"}
{"market":"0x982eae4503214e5d7992668e93f48f42e4707b92e23bb45f8d52d321f643cbe3", "price_changes":[{"asset_id":"74913635031537477155015393896000154190746945075332596665612975928350948042868", "price":"0.8", "size":"71.36", "side":"BUY", "hash":"37b84bda2e91d7372be47021de1e60d714f08a7b", "best_bid":"0.8", "best_ask":"0.81"}, {"asset_id":"37613674580450069178400687025689415665506452565086963049482350052080099056186", "price":"0.2", "size":"71.36", "side":"SELL", "hash":"91a1b6784a5248c18ea40754a34405474192c7f4", "best_bid":"0.19", "best_ask":"0.2"}], "timestamp":"1784449597326", "event_type":"price_change"}
{"market":"0x982eae4503214e5d7992668e93f48f42e4707b92e23bb45f8d52d321f643cbe3", "price_changes":[{"asset_id":"37613674580450069178400687025689415665506452565086963049482350052080099056186", "price":"0.15", "size":"163.71", "side":"BUY", "hash":"30f632657eed41e369eb38c4cae06ced5c96e37f", "best_bid":"0.19", "best_ask":"0.2"}, {"asset_id":"74913635031537477155015393896000154190746945075332596665612975928350948042868", "price":"0.85", "size":"163.71", "side":"SELL", "hash":"c18a79f796325fb83c050df21903c33b422284ad", "best_bid":"0.8", "best_ask":"0.81"}], "timestamp":"1784449597327", "event_type":"price_change"}
{"market":"0x982eae4503214e5d7992668e93f48f42e4707b92e23bb45f8d52d321f643cbe3", "price_changes":[{"asset_id":"74913635031537477155015393896000154190746945075332596665612975928350948042868", "price":"0.8", "size":"80.74", "side":"BUY", "hash":"990f74476dde26b576048e7551402613558f0fd0", "best_bid":"0.8", "best_ask":"0.81"}, {"asset_id":"37613674580450069178400687025689415665506452565086963049482350052080099056186", "price":"0.2", "size":"80.74", "side":"SELL", "hash":"badd78d00f47211e1e09a3165ba517adce48cc97", "best_bid":"0.19", "best_ask":"0.2"}], "timestamp":"1784449597327", "event_type":"price_change"}
{"market":"0x982eae4503214e5d7992668e93f48f42e4707b92e23bb45f8d52d321f643cbe3", "price_changes":[{"asset_id":"37613674580450069178400687025689415665506452565086963049482350052080099056186", "price":"0.15", "size":"188.71", "side":"BUY", "hash":"0e84ad55120b5359bcc7bb22c1efd61762465385", "best_bid":"0.19", "best_ask":"0.2"}, {"asset_id":"74913635031537477155015393896000154190746945075332596665612975928350948042868", "price":"0.85", "size":"188.71", "side":"SELL", "hash":"204b06b5a9daaa2b390fc3e5771d366f2f48deb1", "best_bid":"0.8", "best_ask":"0.81"}], "timestamp":"1784449597328", "event_type":"price_change"}
{"market":"0x982eae4503214e5d7992668e93f48f42e4707b92e23bb45f8d52d321f643cbe3", "price_changes":[{"asset_id":"74913635031537477155015393896000154190746945075332596665612975928350948042868", "price":"0.01", "size":"16269.13", "side":"BUY", "hash":"54839b3ee1b86a97d943845e4b86800d51b9f676", "best_bid":"0.8", "best_ask":"0.81"}, {"asset_id":"37613674580450069178400687025689415665506452565086963049482350052080099056186", "price":"0.99", "size":"16269.13", "side":"SELL", "hash":"23ea3abe43261355aba641dbead95cc79422268c", "best_bid":"0.19", "best_ask":"0.2"}], "timestamp":"1784449597329", "event_type":"price_change"}
{"market":"0x982eae4503214e5d7992668e93f48f42e4707b92e23bb45f8d52d321f643cbe3", "price_changes":[{"asset_id":"37613674580450069178400687025689415665506452565086963049482350052080099056186", "price":"0.14", "size":"151.14", "side":"BUY", "hash":"3379f986b1db08ccb79379bdf9f786b548acc648", "best_bid":"0.19", "best_ask":"0.2"}, {"asset_id":"74913635031537477155015393896000154190746945075332596665612975928350948042868", "price":"0.86", "size":"151.14", "side":"SELL", "hash":"8f825bacf8bad3612ea3968f01ab3ce80e09317f", "best_bid":"0.8", "best_ask":"0.81"}], "timestamp":"1784449597329", "event_type":"price_change"}
{"market":"0x982eae4503214e5d7992668e93f48f42e4707b92e23bb45f8d52d321f643cbe3", "price_changes":[{"asset_id":"74913635031537477155015393896000154190746945075332596665612975928350948042868", "price":"0.02", "size":"3289.11", "side":"BUY", "hash":"13f30bd2b7ea91862ad5ded1a23818f9652ab44c", "best_bid":"0.8", "best_ask":"0.81"}, {"asset_id":"37613674580450069178400687025689415665506452565086963049482350052080099056186", "price":"0.98", "size":"3289.11", "side":"SELL", "hash":"ce99c9abb68354f7f8c2863af696e32621d2fb96", "best_bid":"0.19", "best_ask":"0.2"}], "timestamp":"1784449597329", "event_type":"price_change"}
{"market":"0x982eae4503214e5d7992668e93f48f42e4707b92e23bb45f8d52d321f643cbe3", "price_changes":[{"asset_id":"37613674580450069178400687025689415665506452565086963049482350052080099056186", "price":"0.13", "size":"407.4", "side":"BUY", "hash":"d2a274c22286179311eef58c742eaeb5150d6e33", "best_bid":"0.19", "best_ask":"0.2"}, {"asset_id":"74913635031537477155015393896000154190746945075332596665612975928350948042868", "price":"0.87", "size":"407.4", "side":"SELL", "hash":"db7208a1afae68e9aa2a078d977f437f60f424cb", "best_bid":"0.8", "best_ask":"0.81"}], "timestamp":"1784449597330", "event_type":"price_change"}
{"market":"0x982eae4503214e5d7992668e93f48f42e4707b92e23bb45f8d52d321f643cbe3", "price_changes":[{"asset_id":"74913635031537477155015393896000154190746945075332596665612975928350948042868", "price":"0.71", "size":"123.98", "side":"BUY", "hash":"b5f7d1753d592d6cf4982e99745e42fd685ada15", "best_bid":"0.8", "best_ask":"0.81"}, {"asset_id":"37613674580450069178400687025689415665506452565086963049482350052080099056186", "price":"0.29", "size":"123.98", "side":"SELL", "hash":"66f26f9913a43eab433fa01b0ae7a1f25a4893e0", "best_bid":"0.19", "best_ask":"0.2"}], "timestamp":"1784449597336", "event_type":"price_change"}
{"market":"0x982eae4503214e5d7992668e93f48f42e4707b92e23bb45f8d52d321f643cbe3", "price_changes":[{"asset_id":"74913635031537477155015393896000154190746945075332596665612975928350948042868", "price":"0.7", "size":"128.04", "side":"BUY", "hash":"05df11c5808e2ab03ca6f9262c88001b580ee971", "best_bid":"0.8", "best_ask":"0.81"}, {"asset_id":"37613674580450069178400687025689415665506452565086963049482350052080099056186", "price":"0.3", "size":"128.04", "side":"SELL", "hash":"325664cd3063e985ee2d8ab5ab473150952fab6c", "best_bid":"0.19", "best_ask":"0.2"}], "timestamp":"1784449597336", "event_type":"price_change"}
{"market":"0x982eae4503214e5d7992668e93f48f42e4707b92e23bb45f8d52d321f643cbe3", "price_changes":[{"asset_id":"74913635031537477155015393896000154190746945075332596665612975928350948042868", "price":"0.72", "size":"324.89", "side":"BUY", "hash":"3922738fb0c3a944cddd76f7a17282bbcd0ba193", "best_bid":"0.8", "best_ask":"0.81"}, {"asset_id":"37613674580450069178400687025689415665506452565086963049482350052080099056186", "price":"0.28", "size":"324.89", "side":"SELL", "hash":"f2eb45a492f64986641744d6214669c705beda59", "best_bid":"0.19", "best_ask":"0.2"}], "timestamp":"1784449597337", "event_type":"price_change"}
{"market":"0x982eae4503214e5d7992668e93f48f42e4707b92e23bb45f8d52d321f643cbe3", "price_changes":[{"asset_id":"37613674580450069178400687025689415665506452565086963049482350052080099056186", "price":"0.12", "size":"209.17", "side":"BUY", "hash":"a0f61ffe664ab3b86d255116eed74857159fb01e", "best_bid":"0.19", "best_ask":"0.2"}, {"asset_id":"74913635031537477155015393896000154190746945075332596665612975928350948042868", "price":"0.88", "size":"209.17", "side":"SELL", "hash":"dd97ec4a894ea2bc1bf78f44b43672a1522d5395", "best_bid":"0.8", "best_ask":"0.81"}], "timestamp":"1784449597337", "event_type":"price_change"}
{"market":"0x982eae4503214e5d7992668e93f48f42e4707b92e23bb45f8d52d321f643cbe3", "price_changes":[{"asset_id":"37613674580450069178400687025689415665506452565086963049482350052080099056186", "price":"0.34", "size":"153.24", "side":"SELL", "hash":"de1e8c241cedf75558a7ab075edeb80c7e94d0b9", "best_bid":"0.19", "best_ask":"0.2"}, {"asset_id":"74913635031537477155015393896000154190746945075332596665612975928350948042868", "price":"0.66", "size":"153.24", "side":"BUY", "hash":"6e767b3a8f12732420609181280cbda1efad12c9", "best_bid":"0.8", "best_ask":"0.81"}], "timestamp":"1784449597338", "event_type":"price_change"}
{"market":"0x982eae4503214e5d7992668e93f48f42e4707b92e23bb45f8d52d321f643cbe3", "price_changes":[{"asset_id":"37613674580450069178400687025689415665506452565086963049482350052080099056186", "price":"0.41", "size":"84.9", "side":"SELL", "hash":"e130c106268eac50732beac6aab06874e11778a9", "best_bid":"0.19", "best_ask":"0.2"}, {"asset_id":"74913635031537477155015393896000154190746945075332596665612975928350948042868", "price":"0.59", "size":"84.9", "side":"BUY", "hash":"52e61df688b7c6d7fbccab341055e95925c36159", "best_bid":"0.8", "best_ask":"0.81"}], "timestamp":"1784449597338", "event_type":"price_change"}
{"market":"0x982eae4503214e5d7992668e93f48f42e4707b92e23bb45f8d52d321f643cbe3", "price_changes":[{"asset_id":"74913635031537477155015393896000154190746945075332596665612975928350948042868", "price":"0.8", "size":"96.74", "side":"BUY", "hash":"e93c96fdb66ed195b7f764ff59e2f9c9c725de1c", "best_bid":"0.8", "best_ask":"0.81"}, {"asset_id":"37613674580450069178400687025689415665506452565086963049482350052080099056186", "price":"0.2", "size":"96.74", "side":"SELL", "hash":"ab0bcd8398be6c44a34598fc3bd6cf3d257e029e", "best_bid":"0.19", "best_ask":"0.2"}], "timestamp":"1784449597342", "event_type":"price_change"}
{"market":"0x982eae4503214e5d7992668e93f48f42e4707b92e23bb45f8d52d321f643cbe3", "price_changes":[{"asset_id":"37613674580450069178400687025689415665506452565086963049482350052080099056186", "price":"0.15", "size":"163.71", "side":"BUY", "hash":"5b93613a95ef07b6c1827eba02dac153f7737ef6", "best_bid":"0.19", "best_ask":"0.2"}, {"asset_id":"74913635031537477155015393896000154190746945075332596665612975928350948042868", "price":"0.85", "size":"163.71", "side":"SELL", "hash":"a33f24f1e4cecea1c3a58630adb879239df38878", "best_bid":"0.8", "best_ask":"0.81"}], "timestamp":"1784449597344", "event_type":"price_change"}
{"market":"0x982eae4503214e5d7992668e93f48f42e4707b92e23bb45f8d52d321f643cbe3", "price_changes":[{"asset_id":"74913635031537477155015393896000154190746945075332596665612975928350948042868", "price":"0.01", "size":"16274.13", "side":"BUY", "hash":"e3c401f4d86abab0c1d332355c4affaebe8d3b8f", "best_bid":"0.8", "best_ask":"0.81"}, {"asset_id":"37613674580450069178400687025689415665506452565086963049482350052080099056186", "price":"0.99", "size":"16274.13", "side":"SELL", "hash":"f68315487578b8d2d7df05b9c04ffc612a659c99", "best_bid":"0.19", "best_ask":"0.2"}], "timestamp":"1784449597345", "event_type":"price_change"}
{"market":"0x982eae4503214e5d7992668e93f48f42e4707b92e23bb45f8d52d321f643cbe3", "price_changes":[{"asset_id":"37613674580450069178400687025689415665506452565086963049482350052080099056186", "price":"0.15", "size":"183.71", "side":"BUY", "hash":"5332c646c693e12de7319fc047139e73691147d3", "best_bid":"0.19", "best_ask":"0.2"}, {"asset_id":"74913635031537477155015393896000154190746945075332596665612975928350948042868", "price":"0.85", "size":"183.71", "side":"SELL", "hash":"5e5d5ab435377017e420d422e710c8f6a222dd93", "best_bid":"0.8", "best_ask":"0.81"}], "timestamp":"1784449597346", "event_type":"price_change"}
{"market":"0x982eae4503214e5d7992668e93f48f42e4707b92e23bb45f8d52d321f643cbe3", "price_changes":[{"asset_id":"74913635031537477155015393896000154190746945075332596665612975928350948042868", "price":"0.01", "size":"16174.13", "side":"BUY", "hash":"bf11239f036cd1fbbbfe4dc00eb5f383702e381a", "best_bid":"0.8", "best_ask":"0.81"}, {"asset_id":"37613674580450069178400687025689415665506452565086963049482350052080099056186", "price":"0.99", "size":"16174.13", "side":"SELL", "hash":"57f2c2808183076a214d6b765d0e9a63495b7687", "best_bid":"0.19", "best_ask":"0.2"}], "timestamp":"1784449597348", "event_type":"price_change"}
{"market":"0x982eae4503214e5d7992668e93f48f42e4707b92e23bb45f8d52d321f643cbe3", "price_changes":[{"asset_id":"37613674580450069178400687025689415665506452565086963049482350052080099056186", "price":"0.14", "size":"176.14", "side":"BUY", "hash":"cd9c7a515091df37be754f07bc3e12b0991f4e3d", "best_bid":"0.19", "best_ask":"0.2"}, {"asset_id":"74913635031537477155015393896000154190746945075332596665612975928350948042868", "price":"0.86", "size":"176.14", "side":"SELL", "hash":"d36a3af4f72ba85fd726ab7976245677bbb05f85", "best_bid":"0.8", "best_ask":"0.81"}], "timestamp":"1784449597351", "event_type":"price_change"}
{"market":"0x982eae4503214e5d7992668e93f48f42e4707b92e23bb45f8d52d321f643cbe3", "price_changes":[{"asset_id":"74913635031537477155015393896000154190746945075332596665612975928350948042868", "price":"0.7", "size":"103.04", "side":"BUY", "hash":"1d3d88a0eff44dfa0df61db5544fc6095993fc73", "best_bid":"0.8", "best_ask":"0.81"}, {"asset_id":"37613674580450069178400687025689415665506452565086963049482350052080099056186", "price":"0.3", "size":"103.04", "side":"SELL", "hash":"1ab57e989a02c4e213de3a04ba497c0ef020582e", "best_bid":"0.19", "best_ask":"0.2"}], "timestamp":"1784449597356", "event_type":"price_change"}
