{"market":"0xab772601f501b265bfe8982eb61d5347ef9945de314bfdf4ac0189c288ffb0b3", "asset_id":"12935926064588426924078449947177910958215776269411501731627440228801766632772", "bids":[{"price":"0.01", "size":"14884.14"}, {"price":"0.02", "size":"3964.52"}, {"price":"0.03", "size":"2179.29"}, {"price":"0.04", "size":"1215.1"}, {"price":"0.05", "size":"1742.19"}, {"price":"0.06", "size":"1122.02"}, {"price":"0.07", "size":"953.49"}, {"price":"0.08", "size":"1234.38"}, {"price":"0.09", "size":"791.7"}, {"price":"0.1", "size":"561.2"}, {"price":"0.11", "size":"1502.1"}, {"price":"0.12", "size":"1102.45"}, {"price":"0.13", "size":"139.4"}, {"price":"0.14", "size":"281.8"}, {"price":"0.15", "size":"444.04"}, {"price":"0.16", "size":"147.1"}, {"price":"0.17", "size":"207.17"}, {"price":"0.18", "size":"150.7"}, {"price":"0.19", "size":"128.89"}, {"price":"0.2", "size":"246.2"}, {"price":"0.21", "size":"636.8"}, {"price":"0.22", "size":"145.5"}, {"price":"0.23", "size":"137.3"}, {"price":"0.24", "size":"162.22"}, {"price":"0.25", "size":"162.2"}, {"price":"0.26", "size":"134.3"}, {"price":"0.27", "size":"148.5"}, {"price":"0.28", "size":"151.88"}, {"price":"0.29", "size":"222.52"}, {"price":"0.3", "size":"203.04"}, {"price":"0.31", "size":"550.01"}, {"price":"0.32", "size":"244.69"}, {"price":"0.33", "size":"134.65"}, {"price":"0.34", "size":"94.96"}, {"price":"0.35", "size":"106.2"}, {"price":"0.36", "size":"211.77"}, {"price":"0.37", "size":"105.91"}, {"price":"0.38", "size":"35.05"}], "asks":[{"price":"0.99", "size":"12954.5"}, {"price":"0.98", "size":"3885.25"}, {"price":"0.97", "size":"2250.95"}, {"price":"0.96", "size":"1270.1"}, {"price":"0.95", "size":"1768.6"}, {"price":"0.94", "size":"1124.35"}, {"price":"0.93", "size":"959.2"}, {"price":"0.92", "size":"1225.88"}, {"price":"0.91", "size":"796.7"}, {"price":"0.9", "size":"365.2"}, {"price":"0.89", "size":"1502.1"}, {"price":"0.88", "size":"195.05"}, {"price":"0.87", "size":"147.4"}, {"price":"0.86", "size":"183.4"}, {"price":"0.85", "size":"469.43"}, {"price":"0.84", "size":"127.1"}, {"price":"0.83", "size":"107.69"}, {"price":"0.82", "size":"125.7"}, {"price":"0.81", "size":"98.89"}, {"price":"0.8", "size":"201.2"}, {"price":"0.79", "size":"616.8"}, {"price":"0.78", "size":"997.5"}, {"price":"0.77", "size":"67.6"}, {"price":"0.76", "size":"103.73"}, {"price":"0.75", "size":"78.3"}, {"price":"0.74", "size":"76.8"}, {"price":"0.73", "size":"70.3"}, {"price":"0.72", "size":"79.87"}, {"price":"0.71", "size":"74.39"}, {"price":"0.7", "size":"83"}, {"price":"0.69", "size":"64.7"}, {"price":"0.68", "size":"160.64"}, {"price":"0.67", "size":"98.1"}, {"price":"0.66", "size":"77.8"}, {"price":"0.65", "size":"69.6"}, {"price":"0.64", "size":"79.39"}, {"price":"0.63", "size":"194.2"}, {"price":"0.62", "size":"85"}, {"price":"0.61", "size":"69.8"}, {"price":"0.6", "size":"97.94"}, {"price":"0.59", "size":"100.5"}, {"price":"0.58", "size":"86.02"}, {"price":"0.57", "size":"100.3"}, {"price":"0.56", "size":"64.2"}, {"price":"0.55", "size":"204.71"}, {"price":"0.54", "size":"102.1"}, {"price":"0.53", "size":"72.1"}, {"price":"0.52", "size":"83"}, {"price":"0.51", "size":"91"}, {"price":"0.5", "size":"101"}, {"price":"0.49", "size":"396"}, {"price":"0.48", "size":"195"}, {"price":"0.47", "size":"426.02"}, {"price":"0.46", "size":"148.85"}, {"price":"0.45", "size":"226.69"}, {"price":"0.44", "size":"163.99"}, {"price":"0.43", "size":"169"}, {"price":"0.42", "size":"151.82"}, {"price":"0.41", "size":"255.34"}, {"price":"0.4", "size":"146.7"}, {"price":"0.39", "size":"374.16"}], "hash":"ffcd68a9004511a6b60761a48a136b9ef216272a", "timestamp":"1784449237786", "event_type":"book"}
{"market":"0xab772601f501b265bfe8982eb61d5347ef9945de314bfdf4ac0189c288ffb0b3", "asset_id":"17924629579804316786455515989238352689210911545477836576430679697715946894553", "bids":[{"price":"0.01", "size":"12954.5"}, {"price":"0.02", "size":"3885.25"}, {"price":"0.03", "size":"2250.95"}, {"price":"0.04", "size":"1270.1"}, {"price":"0.05", "size":"1768.6"}, {"price":"0.06", "size":"1124.35"}, {"price":"0.07", "size":"959.2"}, {"price":"0.08", "size":"1225.88"}, {"price":"0.09", "size":"796.7"}, {"price":"0.1", "size":"365.2"}, {"price":"0.11", "size":"1502.1"}, {"price":"0.12", "size":"195.05"}, {"price":"0.13", "size":"147.4"}, {"price":"0.14", "size":"183.4"}, {"price":"0.15", "size":"469.43"}, {"price":"0.16", "size":"127.1"}, {"price":"0.17", "size":"107.69"}, {"price":"0.18", "size":"125.7"}, {"price":"0.19", "size":"98.89"}, {"price":"0.2", "size":"201.2"}, {"price":"0.21", "size":"616.8"}, {"price":"0.22", "size":"997.5"}, {"price":"0.23", "size":"67.6"}, {"price":"0.24", "size":"103.73"}, {"price":"0.25", "size":"78.3"}, {"price":"0.26", "size":"76.8"}, {"price":"0.27", "size":"70.3"}, {"price":"0.28", "size":"79.87"}, {"price":"0.29", "size":"74.39"}, {"price":"0.3", "size":"83"}, {"price":"0.31", "size":"64.7"}, {"price":"0.32", "size":"160.64"}, {"price":"0.33", "size":"98.1"}, {"price":"0.34", "size":"77.8"}, {"price":"0.35", "size":"69.6"}, {"price":"0.36", "size":"79.39"}, {"price":"0.37", "size":"194.2"}, {"price":"0.38", "size":"85"}, {"price":"0.39", "size":"69.8"}, {"price":"0.4", "size":"97.94"}, {"price":"0.41", "size":"100.5"}, {"price":"0.42", "size":"86.02"}, {"price":"0.43", "size":"100.3"}, {"price":"0.44", "size":"64.2"}, {"price":"0.45", "size":"204.71"}, {"price":"0.46", "size":"102.1"}, {"price":"0.47", "size":"72.1"}, {"price":"0.48", "size":"83"}, {"price":"0.49", "size":"91"}, {"price":"0.5", "size":"101"}, {"price":"0.51", "size":"396"}, {"price":"0.52", "size":"195"}, {"price":"0.53", "size":"426.02"}, {"price":"0.54", "size":"148.85"}, {"price":"0.55", "size":"226.69"}, {"price":"0.56", "size":"163.99"}, {"price":"0.57", "size":"169"}, {"price":"0.58", "size":"151.82"}, {"price":"0.59", "size":"255.34"}, {"price":"0.6", "size":"146.7"}, {"price":"0.61", "size":"374.16"}], "asks":[{"price":"0.99", "size":"14884.14"}, {"price":"0.98", "size":"3964.52"}, {"price":"0.97", "size":"2179.29"}, {"price":"0.96", "size":"1215.1"}, {"price":"0.95", "size":"1742.19"}, {"price":"0.94", "size":"1122.02"}, {"price":"0.93", "size":"953.49"}, {"price":"0.92", "size":"1234.38"}, {"price":"0.91", "size":"791.7"}, {"price":"0.9", "size":"561.2"}, {"price":"0.89", "size":"1502.1"}, {"price":"0.88", "size":"1102.45"}, {"price":"0.87", "size":"139.4"}, {"price":"0.86", "size":"281.8"}, {"price":"0.85", "size":"444.04"}, {"price":"0.84", "size":"147.1"}, {"price":"0.83", "size":"207.17"}, {"price":"0.82", "size":"150.7"}, {"price":"0.81", "size":"128.89"}, {"price":"0.8", "size":"246.2"}, {"price":"0.79", "size":"636.8"}, {"price":"0.78", "size":"145.5"}, {"price":"0.77", "size":"137.3"}, {"price":"0.76", "size":"162.22"}, {"price":"0.75", "size":"162.2"}, {"price":"0.74", "size":"134.3"}, {"price":"0.73", "size":"148.5"}, {"price":"0.72", "size":"151.88"}, {"price":"0.71", "size":"222.52"}, {"price":"0.7", "size":"203.04"}, {"price":"0.69", "size":"550.01"}, {"price":"0.68", "size":"244.69"}, {"price":"0.67", "size":"134.65"}, {"price":"0.66", "size":"94.96"}, {"price":"0.65", "size":"106.2"}, {"price":"0.64", "size":"211.77"}, {"price":"0.63", "size":"105.91"}, {"price":"0.62", "size":"35.05"}], "hash":"949fef1934fdc1ec20b083960a8605ba198b14dc", "timestamp":"1784449237786", "event_type":"book"}
{"market":"0xab772601f501b265bfe8982eb61d5347ef9945de314bfdf4ac0189c288ffb0b3", "price_changes":[{"asset_id":"17924629579804316786455515989238352689210911545477836576430679697715946894553", "price":"0.49", "size":"81", "side":"BUY", "hash":"a51db04cf05b56723db51f1a5529fd2bf92e3b64", "best_bid":"0.61", "best_ask":"0.62"}, {"asset_id":"12935926064588426924078449947177910958215776269411501731627440228801766632772", "price":"0.51", "size":"81", "side":"SELL", "hash":"e4994ae0e084e1ed00ae6336c9ddccaa51f3dec1", "best_bid":"0.38", "best_ask":"0.39"}], "timestamp":"1784449237790", "event_type":"price_change"}
{"market":"0xab772601f501b265bfe8982eb61d5347ef9945de314bfdf4ac0189c288ffb0b3", "price_changes":[{"asset_id":"12935926064588426924078449947177910958215776269411501731627440228801766632772", "price":"0.34", "size":"82.96", "side":"BUY", "hash":"14109ba08e600816b0b56d713f4831023c7a7525", "best_bid":"0.38", "best_ask":"0.39"}, {"asset_id":"17924629579804316786455515989238352689210911545477836576430679697715946894553", "price":"0.66", "size":"82.96", "side":"SELL", "hash":"e11fb89aa56186e18f31ad55258996becac682a0", "best_bid":"0.61", "best_ask":"0.62"}], "timestamp":"1784449237790", "event_type":"price_change"}
{"market":"0xab772601f501b265bfe8982eb61d5347ef9945de314bfdf4ac0189c288ffb0b3", "price_changes":[{"asset_id":"17924629579804316786455515989238352689210911545477836576430679697715946894553", "price":"0.48", "size":"71", "side":"BUY", "hash":"7740bd853580902c91455e89abaab8cd33ee4bd1", "best_bid":"0.61", "best_ask":"0.62"}, {"asset_id":"12935926064588426924078449947177910958215776269411501731627440228801766632772", "price":"0.52", "size":"71", "side":"SELL", "hash":"442fe6dc1cee6e5095e694c0aa9de5e58a8e8bbf", "best_bid":"0.38", "best_ask":"0.39"}], "timestamp":"1784449237792", "event_type":"price_change"}
{"market":"0xab772601f501b265bfe8982eb61d5347ef9945de314bfdf4ac0189c288ffb0b3", "price_changes":[{"asset_id":"17924629579804316786455515989238352689210911545477836576430679697715946894553", "price":"0.61", "size":"369.16", "side":"BUY", "hash":"fad9bdcb7f6f20a85daaf1d4f0e0cb88753c5a2c", "best_bid":"0.61", "best_ask":"0.62"}, {"asset_id":"12935926064588426924078449947177910958215776269411501731627440228801766632772", "price":"0.39", "size":"369.16", "side":"SELL", "hash":"c9fae22c2afc18e4296df623d1523fd217863fc6", "best_bid":"0.38", "best_ask":"0.39"}], "timestamp":"1784449237794", "event_type":"price_change"}
{"market":"0xab772601f501b265bfe8982eb61d5347ef9945de314bfdf4ac0189c288ffb0b3", "price_changes":[{"asset_id":"17924629579804316786455515989238352689210911545477836576430679697715946894553", "price":"0.53", "size":"436.02", "side":"BUY", "hash":"be10e2d5b45f3cd7cefa881a7c27445d4e27d308", "best_bid":"0.61", "best_ask":"0.62"}, {"asset_id":"12935926064588426924078449947177910958215776269411501731627440228801766632772", "price":"0.47", "size":"436.02", "side":"SELL", "hash":"d39c960767237d91309590334fee69b94f7f982e", "best_bid":"0.38", "best_ask":"0.39"}], "timestamp":"1784449237803", "event_type":"price_change"}
{"market":"0xab772601f501b265bfe8982eb61d5347ef9945de314bfdf4ac0189c288ffb0b3", "price_changes":[{"asset_id":"17924629579804316786455515989238352689210911545477836576430679697715946894553", "price":"0.01", "size":"12960.5", "side":"BUY", "hash":"97ff1ca49711220efe4f6063e5f852a364e3576d", "best_bid":"0.61", "best_ask":"0.62"}, {"asset_id":"12935926064588426924078449947177910958215776269411501731627440228801766632772", "price":"0.99", "size":"12960.5", "side":"SELL", "hash":"8a17b0a215bba26ce5b24e8624fe202933b7b696", "best_bid":"0.38", "best_ask":"0.39"}], "timestamp":"1784449237804", "event_type":"price_change"}
{"market":"0xab772601f501b265bfe8982eb61d5347ef9945de314bfdf4ac0189c288ffb0b3", "price_changes":[{"asset_id":"17924629579804316786455515989238352689210911545477836576430679697715946894553", "price":"0.51", "size":"406", "side":"BUY", "hash":"5d83ddd2937c623fc8be6f212596a45c24bc0cd8", "best_bid":"0.61", "best_ask":"0.62"}, {"asset_id":"12935926064588426924078449947177910958215776269411501731627440228801766632772", "price":"0.49", "size":"406", "side":"SELL", "hash":"1bc7aaae1dc45edbc208f3f29b324262a8f52bc1", "best_bid":"0.38", "best_ask":"0.39"}], "timestamp":"1784449237810", "event_type":"price_change"}
{"market":"0xab772601f501b265bfe8982eb61d5347ef9945de314bfdf4ac0189c288ffb0b3", "price_changes":[{"asset_id":"17924629579804316786455515989238352689210911545477836576430679697715946894553", "price":"0.5", "size":"113", "side":"BUY", "hash":"556e2ab62f4d76a905d7908fd0663baff13f7138", "best_bid":"0.61", "best_ask":"0.62"}, {"asset_id":"12935926064588426924078449947177910958215776269411501731627440228801766632772", "price":"0.5", "size":"113", "side":"SELL", "hash":"1a6e947806ac236059a05ee81d9eba983ce099bc", "best_bid":"0.38", "best_ask":"0.39"}], "timestamp":"1784449237815", "event_type":"price_change"}
{"market":"0xab772601f501b265bfe8982eb61d5347ef9945de314bfdf4ac0189c288ffb0b3", "price_changes":[{"asset_id":"12935926064588426924078449947177910958215776269411501731627440228801766632772", "price":"0.32", "size":"256.69", "side":"BUY", "hash":"a7cd9e0d1b27ad452ed03be17ec58b3ed72a1b8d", "best_bid":"0.38", "best_ask":"0.39"}, {"asset_id":"17924629579804316786455515989238352689210911545477836576430679697715946894553", "price":"0.68", "size":"256.69", "side":"SELL", "hash":"ef465aea046805d80a908f05ddf8fcd7156c2b6d", "best_bid":"0.61", "best_ask":"0.62"}], "timestamp":"1784449237818", "event_type":"price_change"}
{"market":"0xab772601f501b265bfe8982eb61d5347ef9945de314bfdf4ac0189c288ffb0b3", "price_changes":[{"asset_id":"12935926064588426924078449947177910958215776269411501731627440228801766632772", "price":"0.01", "size":"14889.14", "side":"BUY", "hash":"80c5fdb63fcbdc44f46d62d06785eb00e4a3a486", "best_bid":"0.38", "best_ask":"0.39"}, {"asset_id":"17924629579804316786455515989238352689210911545477836576430679697715946894553", "price":"0.99", "size":"14889.14", "side":"SELL", "hash":"f9d5c9090b9f070daa37ab21e611a2f3001e93cb", "best_bid":"0.61", "best_ask":"0.62"}], "timestamp":"1784449237818", "event_type":"price_change"}
{"market":"0xab772601f501b265bfe8982eb61d5347ef9945de314bfdf4ac0189c288ffb0b3", "price_changes":[{"asset_id":"12935926064588426924078449947177910958215776269411501731627440228801766632772", "price":"0.3", "size":"228.04", "side":"BUY", "hash":"30e5a2030b7a84d8501ab05511c71fd71225ef40", "best_bid":"0.38", "best_ask":"0.39"}, {"asset_id":"17924629579804316786455515989238352689210911545477836576430679697715946894553", "price":"0.7", "size":"228.04", "side":"SELL", "hash":"15ef30288568d73821b7697b1fb74adbc87debe2", "best_bid":"0.61", "best_ask":"0.62"}], "timestamp":"1784449237819", "event_type":"price_change"}
{"market":"0xab772601f501b265bfe8982eb61d5347ef9945de314bfdf4ac0189c288ffb0b3", "price_changes":[{"asset_id":"12935926064588426924078449947177910958215776269411501731627440228801766632772", "price":"0.01", "size":"14884.14", "side":"BUY", "hash":"9ea37c3bf6266d5cfa1dbed9904c22d5bca77a74", "best_bid":"0.38", "best_ask":"0.39"}, {"asset_id":"17924629579804316786455515989238352689210911545477836576430679697715946894553", "price":"0.99", "size":"14884.14", "side":"SELL", "hash":"aea95e27b05cd66ba338d52eba816925eb65d602", "best_bid":"0.61", "best_ask":"0.62"}], "timestamp":"1784449237823", "event_type":"price_change"}
{"market":"0xab772601f501b265bfe8982eb61d5347ef9945de314bfdf4ac0189c288ffb0b3", "price_changes":[{"asset_id":"17924629579804316786455515989238352689210911545477836576430679697715946894553", "price":"0.01", "size":"13060.5", "side":"BUY", "hash":"0d5c2e58a506ecb77c601ba39af8a8daf5e99ba1", "best_bid":"0.61", "best_ask":"0.62"}, {"asset_id":"12935926064588426924078449947177910958215776269411501731627440228801766632772", "price":"0.99", "size":"13060.5", "side":"SELL", "hash":"2162e9f27b09b1f29bda946d774a012b18885dfb", "best_bid":"0.38", "best_ask":"0.39"}], "timestamp":"1784449237825", "event_type":"price_change"}
{"market":"0xab772601f501b265bfe8982eb61d5347ef9945de314bfdf4ac0189c288ffb0b3", "price_changes":[{"asset_id":"12935926064588426924078449947177910958215776269411501731627440228801766632772", "price":"0.01", "size":"14879.14", "side":"BUY", "hash":"a38470747af03f6878c59ada2d144fdfa72e9628", "best_bid":"0.38", "best_ask":"0.39"}, {"asset_id":"17924629579804316786455515989238352689210911545477836576430679697715946894553", "price":"0.99", "size":"14879.14", "side":"SELL", "hash":"72c9b39eda6a094eca2bb1545c76ae0aaed1871c", "best_bid":"0.61", "best_ask":"0.62"}], "timestamp":"1784449237825", "event_type":"price_change"}
{"market":"0xab772601f501b265bfe8982eb61d5347ef9945de314bfdf4ac0189c288ffb0b3", "price_changes":[{"asset_id":"12935926064588426924078449947177910958215776269411501731627440228801766632772", "price":"0.01", "size":"14874.14", "side":"BUY", "hash":"62978cb0f8233855f43e1721a4051dc99305c6a9", "best_bid":"0.38", "best_ask":"0.39"}, {"asset_id":"17924629579804316786455515989238352689210911545477836576430679697715946894553", "price":"0.99", "size":"14874.14", "side":"SELL", "hash":"ea98acb0e291b3c6f96a965c39cded714f295f45", "best_bid":"0.61", "best_ask":"0.62"}], "timestamp":"1784449237826", "event_type":"price_change"}
{"market":"0xab772601f501b265bfe8982eb61d5347ef9945de314bfdf4ac0189c288ffb0b3", "price_changes":[{"asset_id":"12935926064588426924078449947177910958215776269411501731627440228801766632772", "price":"0.01", "size":"14879.14", "side":"BUY", "hash":"f7481976d581740e808bb00ba6fc32075ab0120a", "best_bid":"0.38", "best_ask":"0.39"}, {"asset_id":"17924629579804316786455515989238352689210911545477836576430679697715946894553", "price":"0.99", "size":"14879.14", "side":"SELL", "hash":"14d3742b340c596d0fe4b0254a4b4769fd966dd3", "best_bid":"0.61", "best_ask":"0.62"}], "timestamp":"1784449237830", "event_type":"price_change"}
{"market":"0xab772601f501b265bfe8982eb61d5347ef9945de314bfdf4ac0189c288ffb0b3", "price_changes":[{"asset_id":"17924629579804316786455515989238352689210911545477836576430679697715946894553", "price":"0.01", "size":"13054.5", "side":"BUY", "hash":"1367a71a9502707e36c766cb8a85609f107f6840", "best_bid":"0.61", "best_ask":"0.62"}, {"asset_id":"12935926064588426924078449947177910958215776269411501731627440228801766632772", "price":"0.99", "size":"13054.5", "side":"SELL", "hash":"978f6d6f157f5d813564086f8be42b269e0bc17b", "best_bid":"0.38", "best_ask":"0.39"}], "timestamp":"1784449237833", "event_type":"price_change"}
{"market":"0xab772601f501b265bfe8982eb61d5347ef9945de314bfdf4ac0189c288ffb0b3", "price_changes":[{"asset_id":"12935926064588426924078449947177910958215776269411501731627440228801766632772", "price":"0.01", "size":"14884.14", "side":"BUY", "hash":"d69e0eac985435d1f02ed6dcf4dad3ec3d11d6e2", "best_bid":"0.38", "best_ask":"0.39"}, {"asset_id":"17924629579804316786455515989238352689210911545477836576430679697715946894553", "price":"0.99", "size":"14884.14", "side":"SELL", "hash":"cbdd0bdd32a083ac0eb306dfcbe3cc41b359df5c", "best_bid":"0.61", "best_ask":"0.62"}], "timestamp":"1784449237835", "event_type":"price_change"}
{"market":"0xab772601f501b265bfe8982eb61d5347ef9945de314bfdf4ac0189c288ffb0b3", "price_changes":[{"asset_id":"17924629579804316786455515989238352689210911545477836576430679697715946894553", "price":"0.59", "size":"260.34", "side":"BUY", "hash":"aeac6cb12856a85c708f31b107151e4ca327ee8d", "best_bid":"0.61", "best_ask":"0.62"}, {"asset_id":"12935926064588426924078449947177910958215776269411501731627440228801766632772", "price":"0.41", "size":"260.34", "side":"SELL", "hash":"666221e44971ce6c0165e7d6c5930e4d0ca82bef", "best_bid":"0.38", "best_ask":"0.39"}], "timestamp":"1784449237847", "event_type":"price_change"}
{"market":"0xab772601f501b265bfe8982eb61d5347ef9945de314bfdf4ac0189c288ffb0b3", "price_changes":[{"asset_id":"12935926064588426924078449947177910958215776269411501731627440228801766632772", "price":"0.35", "size":"101.2", "side":"BUY", "hash":"50c20388ace17e1c62cf573c96429e680de6791c", "best_bid":"0.38", "best_ask":"0.39"}, {"asset_id":"17924629579804316786455515989238352689210911545477836576430679697715946894553", "price":"0.65", "size":"101.2", "side":"SELL", "hash":"a5bef403a86f077923b025c2a66ec9c33012eaf3", "best_bid":"0.61", "best_ask":"0.62"}], "timestamp":"1784449237847", "event_type":"price_change"}
{"market":"0xab772601f501b265bfe8982eb61d5347ef9945de314bfdf4ac0189c288ffb0b3", "price_changes":[{"asset_id":"17924629579804316786455515989238352689210911545477836576430679697715946894553", "price":"0.04", "size":"1275.1", "side":"BUY", "hash":"dca42811b2472d7e0f38a93e0f4967ffaa509400", "best_bid":"0.61", "best_ask":"0.62"}, {"asset_id":"12935926064588426924078449947177910958215776269411501731627440228801766632772", "price":"0.96", "size":"1275.1", "side":"SELL", "hash":"055faf0bf987f496960bbc89eb62ff0b5f3d05b0", "best_bid":"0.38", "best_ask":"0.39"}], "timestamp":"1784449237850", "event_type":"price_change"}
{"market":"0xab772601f501b265bfe8982eb61d5347ef9945de314bfdf4ac0189c288ffb0b3", "price_changes":[{"asset_id":"17924629579804316786455515989238352689210911545477836576430679697715946894553", "price":"0.01", "size":"12954.5", "side":"BUY", "hash":"46afa31a46518238984d7bea47f1a097f3871b43", "best_bid":"0.61", "best_ask":"0.62"}, {"asset_id":"12935926064588426924078449947177910958215776269411501731627440228801766632772", "price":"0.99", "size":"12954.5", "side":"SELL", "hash":"0ad2f5cb78061b612080a0f8b7256907bd2933bb", "best_bid":"0.38", "best_ask":"0.39"}], "timestamp":"1784449237855", "event_type":"price_change"}
{"market":"0xab772601f501b265bfe8982eb61d5347ef9945de314bfdf4ac0189c288ffb0b3", "price_changes":[{"asset_id":"17924629579804316786455515989238352689210911545477836576430679697715946894553", "price":"0.01", "size":"12959.51", "side":"BUY", "hash":"c7ed8d3491ec614585a771e173c3ee1aae8b2d96", "best_bid":"0.61", "best_ask":"0.62"}, {"asset_id":"12935926064588426924078449947177910958215776269411501731627440228801766632772", "price":"0.99", "size":"12959.51", "side":"SELL", "hash":"49503391e2b98c0f6c525134fed003c33fa65041", "best_bid":"0.38", "best_ask":"0.39"}], "timestamp":"1784449237860", "event_type":"price_change"}
{"market":"0xab772601f501b265bfe8982eb61d5347ef9945de314bfdf4ac0189c288ffb0b3", "asset_id":"12935926064588426924078449947177910958215776269411501731627440228801766632772", "price":"0.39", "size":"2.564101", "fee_rate_bps":"0", "side":"BUY", "timestamp":"1784449237875", "event_type":"last_trade_price", "transaction_hash":"0xb912b03ebe9e0f0a1907bfeeb6ed4cadb4ed96a5b68bcb223ad06ed657549fad"}
{"market":"0xab772601f501b265bfe8982eb61d5347ef9945de314bfdf4ac0189c288ffb0b3", "price_changes":[{"asset_id":"17924629579804316786455515989238352689210911545477836576430679697715946894553", "price":"0.23", "size":"82.3", "side":"BUY", "hash":"1e87d190487335abda4357caa66b2765b8b0e124", "best_bid":"0.61", "best_ask":"0.62"}, {"asset_id":"12935926064588426924078449947177910958215776269411501731627440228801766632772", "price":"0.77", "size":"82.3", "side":"SELL", "hash":"897a83baec7a98a55a85475f42da48a961bd02f5", "best_bid":"0.38", "best_ask":"0.39"}], "timestamp":"1784449237880", "event_type":"price_change"}
{"market":"0xab772601f501b265bfe8982eb61d5347ef9945de314bfdf4ac0189c288ffb0b3", "price_changes":[{"asset_id":"17924629579804316786455515989238352689210911545477836576430679697715946894553", "price":"0.01", "size":"12954.5", "side":"BUY", "hash":"84c188e497656e1f16caa595ae22f4b583b0dbf0", "best_bid":"0.61", "best_ask":"0.62"}, {"asset_id":"12935926064588426924078449947177910958215776269411501731627440228801766632772", "price":"0.99", "size":"12954.5", "side":"SELL", "hash":"d799c9912904a70de0414439d8f44d5f3c26ef0b", "best_bid":"0.38", "best_ask":"0.39"}], "timestamp":"1784449237888", "event_type":"price_change"}
{"market":"0xab772601f501b265bfe8982eb61d5347ef9945de314bfdf4ac0189c288ffb0b3", "price_changes":[{"asset_id":"12935926064588426924078449947177910958215776269411501731627440228801766632772", "price":"0.01", "size":"14889.14", "side":"BUY", "hash":"cfcee6a23c02b9ba69c29ca3bd220c7dc25069dc", "best_bid":"0.38", "best_ask":"0.39"}, {"asset_id":"17924629579804316786455515989238352689210911545477836576430679697715946894553", "price":"0.99", "size":"14889.14", "side":"SELL", "hash":"f6df990261b68326629580e01bf4f8b1d38b73f4", "best_bid":"0.61", "best_ask":"0.62"}], "timestamp":"1784449237888", "event_type":"price_change"}
{"market":"0xab772601f501b265bfe8982eb61d5347ef9945de314bfdf4ac0189c288ffb0b3", "price_changes":[{"asset_id":"12935926064588426924078449947177910958215776269411501731627440228801766632772", "price":"0.01", "size":"14894.14", "side":"BUY", "hash":"0ca6832deb0eeca38d85b989170b857b6741f9d6", "best_bid":"0.38", "best_ask":"0.39"}, {"asset_id":"17924629579804316786455515989238352689210911545477836576430679697715946894553", "price":"0.99", "size":"14894.14", "side":"SELL", "hash":"01e7a2ff20b9fb45ee7618cbde9c2345881d379b", "best_bid":"0.61", "best_ask":"0.62"}], "timestamp":"1784449237889", "event_type":"price_change"}
{"market":"0xab772601f501b265bfe8982eb61d5347ef9945de314bfdf4ac0189c288ffb0b3", "price_changes":[{"asset_id":"12935926064588426924078449947177910958215776269411501731627440228801766632772", "price":"0.01", "size":"14899.14", "side":"BUY", "hash":"717d28a7511892548c6995138cbaaffbaf2927c2", "best_bid":"0.38", "best_ask":"0.39"}, {"asset_id":"17924629579804316786455515989238352689210911545477836576430679697715946894553", "price":"0.99", "size":"14899.14", "side":"SELL", "hash":"78acf4fe3d31086b08fc954db34513d93b163b67", "best_bid":"0.61", "best_ask":"0.62"}], "timestamp":"1784449237890", "event_type":"price_change"}
{"market":"0xab772601f501b265bfe8982eb61d5347ef9945de314bfdf4ac0189c288ffb0b3", "price_changes":[{"asset_id":"17924629579804316786455515989238352689210911545477836576430679697715946894553", "price":"0.01", "size":"12959.5", "side":"BUY", "hash":"86222ffae681b617461843e51c46c4563610c008", "best_bid":"0.61", "best_ask":"0.62"}, {"asset_id":"12935926064588426924078449947177910958215776269411501731627440228801766632772", "price":"0.99", "size":"12959.5", "side":"SELL", "hash":"b18caecfc69822888b068043129d580715dd90d5", "best_bid":"0.38", "best_ask":"0.39"}], "timestamp":"1784449237890", "event_type":"price_change"}
{"market":"0xab772601f501b265bfe8982eb61d5347ef9945de314bfdf4ac0189c288ffb0b3", "price_changes":[{"asset_id":"17924629579804316786455515989238352689210911545477836576430679697715946894553", "price":"0.01", "size":"12964.5", "side":"BUY", "hash":"b58bc53c319764ee533a38cbe4956afeab602f82", "best_bid":"0.61", "best_ask":"0.62"}, {"asset_id":"12935926064588426924078449947177910958215776269411501731627440228801766632772", "price":"0.99", "size":"12964.5", "side":"SELL", "hash":"952367aea68914ff0a47bcd45c294b306783cf83", "best_bid":"0.38", "best_ask":"0.39"}], "timestamp":"1784449237891", "event_type":"price_change"}
{"market":"0xab772601f501b265bfe8982eb61d5347ef9945de314bfdf4ac0189c288ffb0b3", "price_changes":[{"asset_id":"17924629579804316786455515989238352689210911545477836576430679697715946894553", "price":"0.01", "size":"12969.5", "side":"BUY", "hash":"f53855dadee3b010c8063f156f206dfdc4a693c1", "best_bid":"0.61", "best_ask":"0.62"}, {"asset_id":"12935926064588426924078449947177910958215776269411501731627440228801766632772", "price":"0.99", "size":"12969.5", "side":"SELL", "hash":"6d3dde2100a2db40b4cbac267d0b52c59c8a0331", "best_bid":"0.38", "best_ask":"0.39"}], "timestamp":"1784449237892", "event_type":"price_change"}
{"market":"0xab772601f501b265bfe8982eb61d5347ef9945de314bfdf4ac0189c288ffb0b3", "price_changes":[{"asset_id":"17924629579804316786455515989238352689210911545477836576430679697715946894553", "price":"0.01", "size":"13069.5", "side":"BUY", "hash":"a344d4b8e03a5ac3e989c66b2814d4ebf2958abd", "best_bid":"0.61", "best_ask":"0.62"}, {"asset_id":"12935926064588426924078449947177910958215776269411501731627440228801766632772", "price":"0.99", "size":"13069.5", "side":"SELL", "hash":"c22c439cf3ca39fc04e2ff241412c9edb32b5069", "best_bid":"0.38", "best_ask":"0.39"}], "timestamp":"1784449237896", "event_type":"price_change"}
{"market":"0xab772601f501b265bfe8982eb61d5347ef9945de314bfdf4ac0189c288ffb0b3", "price_changes":[{"asset_id":"17924629579804316786455515989238352689210911545477836576430679697715946894553", "price":"0.01", "size":"13075.5", "side":"BUY", "hash":"9ecfa0eae14e136e4a7c624f17f32a1b8e9dbd84", "best_bid":"0.61", "best_ask":"0.62"}, {"asset_id":"12935926064588426924078449947177910958215776269411501731627440228801766632772", "price":"0.99", "size":"13075.5", "side":"SELL", "hash":"b95e20b78ef94efbd87e53ba10c421fd16fb2aab", "best_bid":"0.38", "best_ask":"0.39"}], "timestamp":"1784449237901", "event_type":"price_change"}
{"market":"0xab772601f501b265bfe8982eb61d5347ef9945de314bfdf4ac0189c288ffb0b3", "price_changes":[{"asset_id":"17924629579804316786455515989238352689210911545477836576430679697715946894553", "price":"0.04", "size":"1270.1", "side":"BUY", "hash":"e3e91a26c30df076a7eddfad5313071b7a11eca8", "best_bid":"0.61", "best_ask":"0.62"}, {"asset_id":"12935926064588426924078449947177910958215776269411501731627440228801766632772", "price":"0.96", "size":"1270.1", "side":"SELL", "hash":"38eaacd002e34c4500388485a05773e6359618c6", "best_bid":"0.38", "best_ask":"0.39"}], "timestamp":"1784449237904", "event_type":"price_change"}
{"market":"0xab772601f501b265bfe8982eb61d5347ef9945de314bfdf4ac0189c288ffb0b3", "price_changes":[{"asset_id":"17924629579804316786455515989238352689210911545477836576430679697715946894553", "price":"0.61", "size":"374.66", "side":"BUY", "hash":"48fac79c9b98c6e5d0f7d2aa9f4ab577937ba9e9", "best_bid":"0.61", "best_ask":"0.62"}, {"asset_id":"12935926064588426924078449947177910958215776269411501731627440228801766632772", "price":"0.39", "size":"374.66", "side":"SELL", "hash":"4f657f50b2f16abfd443c00954f3eebdbb3fa994", "best_bid":"0.38", "best_ask":"0.39"}], "timestamp":"1784449237905", "event_type":"price_change"}
{"market":"0xab772601f501b265bfe8982eb61d5347ef9945de314bfdf4ac0189c288ffb0b3", "price_changes":[{"asset_id":"12935926064588426924078449947177910958215776269411501731627440228801766632772", "price":"0.01", "size":"14894.14", "side":"BUY", "hash":"a656b37339969fcae08e5ea06f9f14a931ee86b8", "best_bid":"0.38", "best_ask":"0.39"}, {"asset_id":"17924629579804316786455515989238352689210911545477836576430679697715946894553", "price":"0.99", "size":"14894.14", "side":"SELL", "hash":"5c6541a4816d191971e7f6685c622eb07cc394ac", "best_bid":"0.61", "best_ask":"0.62"}], "timestamp":"1784449237925", "event_type":"price_change"}
{"market":"0xab772601f501b265bfe8982eb61d5347ef9945de314bfdf4ac0189c288ffb0b3", "price_changes":[{"asset_id":"17924629579804316786455515989238352689210911545477836576430679697715946894553", "price":"0.61", "size":"386.66", "side":"BUY", "hash":"dbf2a85408200237a3bd37770bad2e7a04844c5c", "best_bid":"0.61", "best_ask":"0.62"}, {"asset_id":"12935926064588426924078449947177910958215776269411501731627440228801766632772", "price":"0.39", "size":"386.66", "side":"SELL", "hash":"48fc34d3bf91ffe336709ba529f9a01eb396b13f", "best_bid":"0.38", "best_ask":"0.39"}], "timestamp":"1784449237935", "event_type":"price_change"}
{"market":"0xab772601f501b265bfe8982eb61d5347ef9945de314bfdf4ac0189c288ffb0b3", "price_changes":[{"asset_id":"17924629579804316786455515989238352689210911545477836576430679697715946894553", "price":"0.01", "size":"13069.5", "side":"BUY", "hash":"4db33a12d43f27b643439a8dbe649c36d11ef577", "best_bid":"0.61", "best_ask":"0.62"}, {"asset_id":"12935926064588426924078449947177910958215776269411501731627440228801766632772", "price":"0.99", "size":"13069.5", "side":"SELL", "hash":"c1e7cdbe4050ab420ec8a6f77ad6a07e1ec12176", "best_bid":"0.38", "best_ask":"0.39"}], "timestamp":"1784449237935", "event_type":"price_change"}
{"market":"0xab772601f501b265bfe8982eb61d5347ef9945de314bfdf4ac0189c288ffb0b3", "price_changes":[{"asset_id":"17924629579804316786455515989238352689210911545477836576430679697715946894553", "price":"0.01", "size":"12969.5", "side":"BUY", "hash":"9c240a03fabf8327f856b2b5909fb763d691473d", "best_bid":"0.61", "best_ask":"0.62"}, {"asset_id":"12935926064588426924078449947177910958215776269411501731627440228801766632772", "price":"0.99", "size":"12969.5", "side":"SELL", "hash":"68031a9cea2811c0df32bc979fe6d3f3ab441c68", "best_bid":"0.38", "best_ask":"0.39"}], "timestamp":"1784449237939", "event_type":"price_change"}
{"market":"0xab772601f501b265bfe8982eb61d5347ef9945de314bfdf4ac0189c288ffb0b3", "price_changes":[{"asset_id":"17924629579804316786455515989238352689210911545477836576430679697715946894553", "price":"0.56", "size":"263.99", "side":"BUY", "hash":"a72d274e88e20905be78ea024f4dca20b735445b", "best_bid":"0.61", "best_ask":"0.62"}, {"asset_id":"12935926064588426924078449947177910958215776269411501731627440228801766632772", "price":"0.44", "size":"263.99", "side":"SELL", "hash":"a785d42d6e9b8ae02993573aad8e2deed0dfecb5", "best_bid":"0.38", "best_ask":"0.39"}], "timestamp":"1784449237946", "event_type":"price_change"}
{"market":"0xab772601f501b265bfe8982eb61d5347ef9945de314bfdf4ac0189c288ffb0b3", "price_changes":[{"asset_id":"12935926064588426924078449947177910958215776269411501731627440228801766632772", "price":"0.35", "size":"106.2", "side":"BUY", "hash":"067a849e0948b428845875535d751deb1aa2a368", "best_bid":"0.38", "best_ask":"0.39"}, {"asset_id":"17924629579804316786455515989238352689210911545477836576430679697715946894553", "price":"0.65", "size":"106.2", "side":"SELL", "hash":"1d6074784a3ec9b524e409302821733e91361513", "best_bid":"0.61", "best_ask":"0.62"}], "timestamp":"1784449237952", "event_type":"price_change"}
{"market":"0xab772601f501b265bfe8982eb61d5347ef9945de314bfdf4ac0189c288ffb0b3", "price_changes":[{"asset_id":"12935926064588426924078449947177910958215776269411501731627440228801766632772", "price":"0.01", "size":"14889.14", "side":"BUY", "hash":"5889c5bfb9d12ae76dbd92744d8d66b56e3f8af5", "best_bid":"0.38", "best_ask":"0.39"}, {"asset_id":"17924629579804316786455515989238352689210911545477836576430679697715946894553", "price":"0.99", "size":"14889.14", "side":"SELL", "hash":"2f79e98ca68face2f9dd014dd909d1bc62bc4c12", "best_bid":"0.61", "best_ask":"0.62"}], "timestamp":"1784449237960", "event_type":"price_change"}
{"market":"0xab772601f501b265bfe8982eb61d5347ef9945de314bfdf4ac0189c288ffb0b3", "price_changes":[{"asset_id":"12935926064588426924078449947177910958215776269411501731627440228801766632772", "price":"0.78", "size":"992.5", "side":"SELL", "hash":"2838b4bedd80d4595376dae8b9da8e374fa5106d", "best_bid":"0.38", "best_ask":"0.39"}, {"asset_id":"17924629579804316786455515989238352689210911545477836576430679697715946894553", "price":"0.22", "size":"992.5", "side":"BUY", "hash":"3265d604b2122458eb7c8b7ec107a365d4804e64", "best_bid":"0.61", "best_ask":"0.62"}], "timestamp":"1784449237972", "event_type":"price_change"}
{"market":"0xab772601f501b265bfe8982eb61d5347ef9945de314bfdf4ac0189c288ffb0b3", "price_changes":[{"asset_id":"17924629579804316786455515989238352689210911545477836576430679697715946894553", "price":"0.01", "size":"13069.5", "side":"BUY", "hash":"31b31d2a44626882005a90b0d6895daf7b69cfe0", "best_bid":"0.61", "best_ask":"0.62"}, {"asset_id":"12935926064588426924078449947177910958215776269411501731627440228801766632772", "price":"0.99", "size":"13069.5", "side":"SELL", "hash":"ecbffd02992915ad35107c4630fefb6cb02f20bd", "best_bid":"0.38", "best_ask":"0.39"}], "timestamp":"1784449237974", "event_type":"price_change"}
{"market":"0xab772601f501b265bfe8982eb61d5347ef9945de314bfdf4ac0189c288ffb0b3", "price_changes":[{"asset_id":"12935926064588426924078449947177910958215776269411501731627440228801766632772", "price":"0.28", "size":"146.77", "side":"BUY", "hash":"bcb1195148632c7a951ade747e005998af06a6db", "best_bid":"0.38", "best_ask":"0.39"}, {"asset_id":"17924629579804316786455515989238352689210911545477836576430679697715946894553", "price":"0.72", "size":"146.77", "side":"SELL", "hash":"a5db612602867bf18fbc3427a06490eeab5026f7", "best_bid":"0.61", "best_ask":"0.62"}], "timestamp":"1784449237975", "event_type":"price_change"}
{"market":"0xab772601f501b265bfe8982eb61d5347ef9945de314bfdf4ac0189c288ffb0b3", "price_changes":[{"asset_id":"17924629579804316786455515989238352689210911545477836576430679697715946894553", "price":"0.03", "size":"2255.95", "side":"BUY", "hash":"0ecb4fd3603e9661ce5ec08ff8ce4c8da7e48a70", "best_bid":"0.61", "best_ask":"0.62"}, {"asset_id":"12935926064588426924078449947177910958215776269411501731627440228801766632772", "price":"0.97", "size":"2255.95", "side":"SELL", "hash":"6af5ac861894efa8e7609b4fad5689818330ad29", "best_bid":"0.38", "best_ask":"0.39"}], "timestamp":"1784449237986", "event_type":"price_change"}
{"market":"0xab772601f501b265bfe8982eb61d5347ef9945de314bfdf4ac0189c288ffb0b3", "price_changes":[{"asset_id":"17924629579804316786455515989238352689210911545477836576430679697715946894553", "price":"0.01", "size":"13064.5", "side":"BUY", "hash":"63784c1a3b75b4adc85e413f5dbde25db94e70c2", "best_bid":"0.61", "best_ask":"0.62"}, {"asset_id":"12935926064588426924078449947177910958215776269411501731627440228801766632772", "price":"0.99", "size":"13064.5", "side":"SELL", "hash":"45001a0b53c4295e484a2ab4890af8af13feacf1", "best_bid":"0.38", "best_ask":"0.39"}], "timestamp":"1784449237994", "event_type":"price_change"}
{"market":"0xab772601f501b265bfe8982eb61d5347ef9945de314bfdf4ac0189c288ffb0b3", "price_changes":[{"asset_id":"12935926064588426924078449947177910958215776269411501731627440228801766632772", "price":"0.01", "size":"14884.14", "side":"BUY", "hash":"b558f974a03e2315240427423fba844f4fe9fefb", "best_bid":"0.38", "best_ask":"0.39"}, {"asset_id":"17924629579804316786455515989238352689210911545477836576430679697715946894553", "price":"0.99", "size":"14884.14", "side":"SELL", "hash":"7ed923f203884ca085654cdd11d1c773e19f5169", "best_bid":"0.61", "best_ask":"0.62"}], "timestamp":"1784449237998", "event_type":"price_change"}
{"market":"0xab772601f501b265bfe8982eb61d5347ef9945de314bfdf4ac0189c288ffb0b3", "price_changes":[{"asset_id":"17924629579804316786455515989238352689210911545477836576430679697715946894553", "price":"0.01", "size":"13054.5", "side":"BUY", "hash":"6b69a0dae040b2970488b70d6e036e4e42e5cc7f", "best_bid":"0.61", "best_ask":"0.62"}, {"asset_id":"12935926064588426924078449947177910958215776269411501731627440228801766632772", "price":"0.99", "size":"13054.5", "side":"SELL", "hash":"a08347f9b7e762167a288839e941a1893c172b7c", "best_bid":"0.38", "best_ask":"0.39"}], "timestamp":"1784449237998", "event_type":"price_change"}
{"market":"0xab772601f501b265bfe8982eb61d5347ef9945de314bfdf4ac0189c288ffb0b3", "price_changes":[{"asset_id":"17924629579804316786455515989238352689210911545477836576430679697715946894553", "price":"0.01", "size":"13060.5", "side":"BUY", "hash":"5b0e0700d2b50051e7a7373d9b2f47fc0dfeefea", "best_bid":"0.61", "best_ask":"0.62"}, {"asset_id":"12935926064588426924078449947177910958215776269411501731627440228801766632772", "price":"0.99", "size":"13060.5", "side":"SELL", "hash":"49054f49c397435f83534f5c84c82ecba6fa90b4", "best_bid":"0.38", "best_ask":"0.39"}], "timestamp":"1784449238010", "event_type":"price_change"}
{"market":"0xab772601f501b265bfe8982eb61d5347ef9945de314bfdf4ac0189c288ffb0b3", "price_changes":[{"asset_id":"17924629579804316786455515989238352689210911545477836576430679697715946894553", "price":"0.01", "size":"13055.5", "side":"BUY", "hash":"8d31e4b19584dc626883de996132a8f45bb42e3d", "best_bid":"0.61", "best_ask":"0.62"}, {"asset_id":"12935926064588426924078449947177910958215776269411501731627440228801766632772", "price":"0.99", "size":"13055.5", "side":"SELL", "hash":"96502d4127a5eca593b7f8f5214f5d78d3e099ec", "best_bid":"0.38", "best_ask":"0.39"}], "timestamp":"1784449238014", "event_type":"price_change"}
{"market":"0xab772601f501b265bfe8982eb61d5347ef9945de314bfdf4ac0189c288ffb0b3", "price_changes":[{"asset_id":"17924629579804316786455515989238352689210911545477836576430679697715946894553", "price":"0.01", "size":"12955.5", "side":"BUY", "hash":"0c1141bd41eac44cbd806bb8a6a31a2e820785f4", "best_bid":"0.61", "best_ask":"0.62"}, {"asset_id":"12935926064588426924078449947177910958215776269411501731627440228801766632772", "price":"0.99", "size":"12955.5", "side":"SELL", "hash":"0d66f7d6e39a004c81dfbc6e931e0a4d5aaccbe8", "best_bid":"0.38", "best_ask":"0.39"}], "timestamp":"1784449238018", "event_type":"price_change"}
{"market":"0xab772601f501b265bfe8982eb61d5347ef9945de314bfdf4ac0189c288ffb0b3", "price_changes":[{"asset_id":"17924629579804316786455515989238352689210911545477836576430679697715946894553", "price":"0.01", "size":"12950.5", "side":"BUY", "hash":"74c9096a0361f0bfde45b6124dff6d61a8a68333", "best_bid":"0.61", "best_ask":"0.62"}, {"asset_id":"12935926064588426924078449947177910958215776269411501731627440228801766632772", "price":"0.99", "size":"12950.5", "side":"SELL", "hash":"c070b0d4a778b692e4d5bcdd530fe1a9990472f6", "best_bid":"0.38", "best_ask":"0.39"}], "timestamp":"1784449238019", "event_type":"price_change"}
{"market":"0xab772601f501b265bfe8982eb61d5347ef9945de314bfdf4ac0189c288ffb0b3", "price_changes":[{"asset_id":"12935926064588426924078449947177910958215776269411501731627440228801766632772", "price":"0.01", "size":"14889.14", "side":"BUY", "hash":"401fb87b4567aff8709f1426869d93fc8b683b02", "best_bid":"0.38", "best_ask":"0.39"}, {"asset_id":"17924629579804316786455515989238352689210911545477836576430679697715946894553", "price":"0.99", "size":"14889.14", "side":"SELL", "hash":"2ee42571aaddc9c7ea3ea4d9c593aadb71fe9d00", "best_bid":"0.61", "best_ask":"0.62"}], "timestamp":"1784449238019", "event_type":"price_change"}
{"market":"0xab772601f501b265bfe8982eb61d5347ef9945de314bfdf4ac0189c288ffb0b3", "price_changes":[{"asset_id":"17924629579804316786455515989238352689210911545477836576430679697715946894553", "price":"0.01", "size":"12945.5", "side":"BUY", "hash":"0dd6154689f34cc8f1c1c9b56bc04bdce47cce72", "best_bid":"0.61", "best_ask":"0.62"}, {"asset_id":"12935926064588426924078449947177910958215776269411501731627440228801766632772", "price":"0.99", "size":"12945.5", "side":"SELL", "hash":"a5b4d1d874a215758406bed11a7684bd800df352", "best_bid":"0.38", "best_ask":"0.39"}], "timestamp":"1784449238022", "event_type":"price_change"}
{"market":"0xab772601f501b265bfe8982eb61d5347ef9945de314bfdf4ac0189c288ffb0b3", "price_changes":[{"asset_id":"12935926064588426924078449947177910958215776269411501731627440228801766632772", "price":"0.01", "size":"14894.14", "side":"BUY", "hash":"b681d3b109c33faa5e4ca98aff1778bb8a201c3f", "best_bid":"0.38", "best_ask":"0.39"}, {"asset_id":"17924629579804316786455515989238352689210911545477836576430679697715946894553", "price":"0.99", "size":"14894.14", "side":"SELL", "hash":"a5632805c53f90b937102e210bcbaf93fc26648d", "best_bid":"0.61", "best_ask":"0.62"}], "timestamp":"1784449238024", "event_type":"price_change"}
{"market":"0xab772601f501b265bfe8982eb61d5347ef9945de314bfdf4ac0189c288ffb0b3", "price_changes":[{"asset_id":"17924629579804316786455515989238352689210911545477836576430679697715946894553", "price":"0.01", "size":"12950.5", "side":"BUY", "hash":"1658ce3c1c1dadd3a86cb86850d981048cb01c75", "best_bid":"0.61", "best_ask":"0.62"}, {"asset_id":"12935926064588426924078449947177910958215776269411501731627440228801766632772", "price":"0.99", "size":"12950.5", "side":"SELL", "hash":"2c77a86b270ef25aa1d8a0e8c64a522b5c298a72", "best_bid":"0.38", "best_ask":"0.39"}], "timestamp":"1784449238030", "event_type":"price_change"}
{"market":"0xab772601f501b265bfe8982eb61d5347ef9945de314bfdf4ac0189c288ffb0b3", "price_changes":[{"asset_id":"17924629579804316786455515989238352689210911545477836576430679697715946894553", "price":"0.01", "size":"12955.5", "side":"BUY", "hash":"b0f29cafc28a02801a16bf04217345de83fdd7bb", "best_bid":"0.61", "best_ask":"0.62"}, {"asset_id":"12935926064588426924078449947177910958215776269411501731627440228801766632772", "price":"0.99", "size":"12955.5", "side":"SELL", "hash":"d21f83052a060f8adc5399d14c42ff8ac75382f0", "best_bid":"0.38", "best_ask":"0.39"}], "timestamp":"1784449238031", "event_type":"price_change"}
{"market":"0xab772601f501b265bfe8982eb61d5347ef9945de314bfdf4ac0189c288ffb0b3", "asset_id":"12935926064588426924078449947177910958215776269411501731627440228801766632772", "price":"0.39", "size":"7.692306", "fee_rate_bps":"0", "side":"BUY", "timestamp":"1784449237942", "event_type":"last_trade_price", "transaction_hash":"0x3f99cce786c5a1ed194f45878aff13b9b35f24a1af6f2650fb27cb531a989886"}
{"market":"0xab772601f501b265bfe8982eb61d5347ef9945de314bfdf4ac0189c288ffb0b3", "price_changes":[{"asset_id":"17924629579804316786455515989238352689210911545477836576430679697715946894553", "price":"0.01", "size":"12960.5", "side":"BUY", "hash":"fafcf66f8e9aa5605d32a6361ca668f640c11c58", "best_bid":"0.61", "best_ask":"0.62"}, {"asset_id":"12935926064588426924078449947177910958215776269411501731627440228801766632772", "price":"0.99", "size":"12960.5", "side":"SELL", "hash":"e575175a1590b0eda7cc7ca760a81c9c2a234dd5", "best_bid":"0.38", "best_ask":"0.39"}], "timestamp":"1784449238032", "event_type":"price_change"}
{"market":"0xab772601f501b265bfe8982eb61d5347ef9945de314bfdf4ac0189c288ffb0b3", "price_changes":[{"asset_id":"17924629579804316786455515989238352689210911545477836576430679697715946894553", "price":"0.01", "size":"12965.5", "side":"BUY", "hash":"9204ad6c5784c9c11257a61d41317271e8dff19c", "best_bid":"0.61", "best_ask":"0.62"}, {"asset_id":"12935926064588426924078449947177910958215776269411501731627440228801766632772", "price":"0.99", "size":"12965.5", "side":"SELL", "hash":"c3a8f1e883738b7f5126e304aff95b74dc7cc484", "best_bid":"0.38", "best_ask":"0.39"}], "timestamp":"1784449238033", "event_type":"price_change"}
{"market":"0xab772601f501b265bfe8982eb61d5347ef9945de314bfdf4ac0189c288ffb0b3", "price_changes":[{"asset_id":"17924629579804316786455515989238352689210911545477836576430679697715946894553", "price":"0.03", "size":"2250.95", "side":"BUY", "hash":"0dc0b3340f9451542e0a7bd3174d7beae826b334", "best_bid":"0.61", "best_ask":"0.62"}, {"asset_id":"12935926064588426924078449947177910958215776269411501731627440228801766632772", "price":"0.97", "size":"2250.95", "side":"SELL", "hash":"34e1b75439a81f6dc54da4875fe21590934a8a16", "best_bid":"0.38", "best_ask":"0.39"}], "timestamp":"1784449238035", "event_type":"price_change"}
{"market":"0xab772601f501b265bfe8982eb61d5347ef9945de314bfdf4ac0189c288ffb0b3", "price_changes":[{"asset_id":"12935926064588426924078449947177910958215776269411501731627440228801766632772", "price":"0.01", "size":"14889.14", "side":"BUY", "hash":"8cf73d752ffee8c7b5a230c70e15c3fc6db6bab8", "best_bid":"0.38", "best_ask":"0.39"}, {"asset_id":"17924629579804316786455515989238352689210911545477836576430679697715946894553", "price":"0.99", "size":"14889.14", "side":"SELL", "hash":"2b85dcece5e68553ee3f7c63b40b23bf943a24bb", "best_bid":"0.61", "best_ask":"0.62"}], "timestamp":"1784449238040", "event_type":"price_change"}
{"market":"0xab772601f501b265bfe8982eb61d5347ef9945de314bfdf4ac0189c288ffb0b3", "price_changes":[{"asset_id":"12935926064588426924078449947177910958215776269411501731627440228801766632772", "price":"0.01", "size":"14884.14", "side":"BUY", "hash":"f868314aa786b3f36b89b1eb62520b10e227bd88", "best_bid":"0.38", "best_ask":"0.39"}, {"asset_id":"17924629579804316786455515989238352689210911545477836576430679697715946894553", "price":"0.99", "size":"14884.14", "side":"SELL", "hash":"d52548283a5e318fa644f2857635a411b1ea9ef8", "best_bid":"0.61", "best_ask":"0.62"}], "timestamp":"1784449238048", "event_type":"price_change"}
{"market":"0xab772601f501b265bfe8982eb61d5347ef9945de314bfdf4ac0189c288ffb0b3", "price_changes":[{"asset_id":"12935926064588426924078449947177910958215776269411501731627440228801766632772", "price":"0.35", "size":"101.2", "side":"BUY", "hash":"bf080bb260a37e5ef5056129daa2a8455d083b70", "best_bid":"0.38", "best_ask":"0.39"}, {"asset_id":"17924629579804316786455515989238352689210911545477836576430679697715946894553", "price":"0.65", "size":"101.2", "side":"SELL", "hash":"ee87c27ebfebdbe1c45f422d0bb0a360fc74cf98", "best_bid":"0.61", "best_ask":"0.62"}], "timestamp":"1784449238053", "event_type":"price_change"}
{"market":"0xab772601f501b265bfe8982eb61d5347ef9945de314bfdf4ac0189c288ffb0b3", "price_changes":[{"asset_id":"17924629579804316786455515989238352689210911545477836576430679697715946894553", "price":"0.61", "size":"381.16", "side":"BUY", "hash":"f98f378f683967cfe35ca7a1deb80b4c0259c0bc", "best_bid":"0.61", "best_ask":"0.62"}, {"asset_id":"12935926064588426924078449947177910958215776269411501731627440228801766632772", "price":"0.39", "size":"381.16", "side":"SELL", "hash":"2954ac7a0118e056303b54e614ed2fbb732752d1", "best_bid":"0.38", "best_ask":"0.39"}], "timestamp":"1784449238053", "event_type":"price_change"}
{"market":"0xab772601f501b265bfe8982eb61d5347ef9945de314bfdf4ac0189c288ffb0b3", "price_changes":[{"asset_id":"17924629579804316786455515989238352689210911545477836576430679697715946894553", "price":"0.01", "size":"12960.5", "side":"BUY", "hash":"dbbee5674ca80ebb6267af682f159a723cd97b8d", "best_bid":"0.61", "best_ask":"0.62"}, {"asset_id":"12935926064588426924078449947177910958215776269411501731627440228801766632772", "price":"0.99", "size":"12960.5", "side":"SELL", "hash":"dca476a5ff833381801dbf5f6e8230376bfdcf7d", "best_bid":"0.38", "best_ask":"0.39"}], "timestamp":"1784449238056", "event_type":"price_change"}
{"market":"0xab772601f501b265bfe8982eb61d5347ef9945de314bfdf4ac0189c288ffb0b3", "price_changes":[{"asset_id":"17924629579804316786455515989238352689210911545477836576430679697715946894553", "price":"0.01", "size":"13060.5", "side":"BUY", "hash":"c9dafc0e73fb547f53f90f8a39e77ab27b4d574a", "best_bid":"0.61", "best_ask":"0.62"}, {"asset_id":"12935926064588426924078449947177910958215776269411501731627440228801766632772", "price":"0.99", "size":"13060.5", "side":"SELL", "hash":"70044076529df6b447e9145519df96201b78b181", "best_bid":"0.38", "best_ask":"0.39"}], "timestamp":"1784449238060", "event_type":"price_change"}
{"market":"0xab772601f501b265bfe8982eb61d5347ef9945de314bfdf4ac0189c288ffb0b3", "price_changes":[{"asset_id":"17924629579804316786455515989238352689210911545477836576430679697715946894553", "price":"0.01", "size":"13065.51", "side":"BUY", "hash":"b2b6e40d19e6b71ef2e016f2d5a0bf31d33fb3f1", "best_bid":"0.61", "best_ask":"0.62"}, {"asset_id":"12935926064588426924078449947177910958215776269411501731627440228801766632772", "price":"0.99", "size":"13065.51", "side":"SELL", "hash":"e4b2c1cb8a14523fdc49c3989bab39c1d29eb12a", "best_bid":"0.38", "best_ask":"0.39"}], "timestamp":"1784449238061", "event_type":"price_change"}
{"market":"0xab772601f501b265bfe8982eb61d5347ef9945de314bfdf4ac0189c288ffb0b3", "price_changes":[{"asset_id":"17924629579804316786455515989238352689210911545477836576430679697715946894553", "price":"0.01", "size":"13060.5", "side":"BUY", "hash":"99e57f06637adb1dcce91d6f30ab0b9148b75c0c", "best_bid":"0.61", "best_ask":"0.62"}, {"asset_id":"12935926064588426924078449947177910958215776269411501731627440228801766632772", "price":"0.99", "size":"13060.5", "side":"SELL", "hash":"52dc6ec88a85c3184ba3465c405e663288d724b0", "best_bid":"0.38", "best_ask":"0.39"}], "timestamp":"1784449238065", "event_type":"price_change"}
{"market":"0xab772601f501b265bfe8982eb61d5347ef9945de314bfdf4ac0189c288ffb0b3", "price_changes":[{"asset_id":"17924629579804316786455515989238352689210911545477836576430679697715946894553", "price":"0.01", "size":"12960.5", "side":"BUY", "hash":"5f25ee525fe5878164b6468a830d179dc1f9f598", "best_bid":"0.61", "best_ask":"0.62"}, {"asset_id":"12935926064588426924078449947177910958215776269411501731627440228801766632772", "price":"0.99", "size":"12960.5", "side":"SELL", "hash":"e5cb2274918d4532b8a532404e40d3f1ae5c5144", "best_bid":"0.38", "best_ask":"0.39"}], "timestamp":"1784449238097", "event_type":"price_change"}
{"market":"0xab772601f501b265bfe8982eb61d5347ef9945de314bfdf4ac0189c288ffb0b3", "price_changes":[{"asset_id":"12935926064588426924078449947177910958215776269411501731627440228801766632772", "price":"0.34", "size":"100.76", "side":"BUY", "hash":"c08aa3c3b883657a8998e188759a3e59b3744b00", "best_bid":"0.38", "best_ask":"0.39"}, {"asset_id":"17924629579804316786455515989238352689210911545477836576430679697715946894553", "price":"0.66", "size":"100.76", "side":"SELL", "hash":"17d65d32d84700bda26f7cbf351c6ba2b17a88ca", "best_bid":"0.61", "best_ask":"0.62"}], "timestamp":"1784449238106", "event_type":"price_change"}
{"market":"0xab772601f501b265bfe8982eb61d5347ef9945de314bfdf4ac0189c288ffb0b3", "price_changes":[{"asset_id":"17924629579804316786455515989238352689210911545477836576430679697715946894553", "price":"0.24", "size":"118.03", "side":"BUY", "hash":"19231c106abee734383fa69ceed9cfba31829180", "best_bid":"0.61", "best_ask":"0.62"}, {"asset_id":"12935926064588426924078449947177910958215776269411501731627440228801766632772", "price":"0.76", "size":"118.03", "side":"SELL", "hash":"45df2e8b08e02a4ae28fcf7b76da5d47b0392035", "best_bid":"0.38", "best_ask":"0.39"}], "timestamp":"1784449238107", "event_type":"price_change"}
{"market":"0xab772601f501b265bfe8982eb61d5347ef9945de314bfdf4ac0189c288ffb0b3", "price_changes":[{"asset_id":"17924629579804316786455515989238352689210911545477836576430679697715946894553", "price":"0.01", "size":"12954.5", "side":"BUY", "hash":"f7988689ad22b7b1b208052f22975903ceeefe60", "best_bid":"0.61", "best_ask":"0.62"}, {"asset_id":"12935926064588426924078449947177910958215776269411501731627440228801766632772", "price":"0.99", "size":"12954.5", "side":"SELL", "hash":"248c5d618927bab7127bb6c178a8c8666f736d02", "best_bid":"0.38", "best_ask":"0.39"}], "timestamp":"1784449238134", "event_type":"price_change"}
{"market":"0xab772601f501b265bfe8982eb61d5347ef9945de314bfdf4ac0189c288ffb0b3", "price_changes":[{"asset_id":"17924629579804316786455515989238352689210911545477836576430679697715946894553", "price":"0.01", "size":"13054.5", "side":"BUY", "hash":"6322ff3207676ee8de6f0509356da95dfc3ee9fd", "best_bid":"0.61", "best_ask":"0.62"}, {"asset_id":"12935926064588426924078449947177910958215776269411501731627440228801766632772", "price":"0.99", "size":"13054.5", "side":"SELL", "hash":"747c5dc9bcee396922846c7ee93df922bede6bd1", "best_bid":"0.38", "best_ask":"0.39"}], "timestamp":"1784449238135", "event_type":"price_change"}
{"market":"0xab772601f501b265bfe8982eb61d5347ef9945de314bfdf4ac0189c288ffb0b3", "price_changes":[{"asset_id":"12935926064588426924078449947177910958215776269411501731627440228801766632772", "price":"0.39", "size":"355.51", "side":"SELL", "hash":"2b2d36a829e1a4cde231d35257d57b8ffd65fa92", "best_bid":"0.38", "best_ask":"0.39"}, {"asset_id":"17924629579804316786455515989238352689210911545477836576430679697715946894553", "price":"0.61", "size":"355.51", "side":"BUY", "hash":"db08d031c22d2137019688c35c70c13ad67667bf", "best_bid":"0.61", "best_ask":"0.62"}], "timestamp":"1784449238140", "event_type":"price_change"}
{"market":"0xab772601f501b265bfe8982eb61d5347ef9945de314bfdf4ac0189c288ffb0b3", "price_changes":[{"asset_id":"17924629579804316786455515989238352689210911545477836576430679697715946894553", "price":"0.61", "size":"355.51", "side":"BUY", "hash":"db08d031c22d2137019688c35c70c13ad67667bf", "best_bid":"0.61", "best_ask":"0.62"}, {"asset_id":"12935926064588426924078449947177910958215776269411501731627440228801766632772", "price":"0.39", "size":"355.51", "side":"SELL", "hash":"2b2d36a829e1a4cde231d35257d57b8ffd65fa92", "best_bid":"0.38", "best_ask":"0.39"}], "timestamp":"1784449238140", "event_type":"price_change"}
{"market":"0xab772601f501b265bfe8982eb61d5347ef9945de314bfdf4ac0189c288ffb0b3", "asset_id":"12935926064588426924078449947177910958215776269411501731627440228801766632772", "bids":[{"price":"0.01", "size":"14884.14"}, {"price":"0.02", "size":"3964.52"}, {"price":"0.03", "size":"2179.29"}, {"price":"0.04", "size":"1215.1"}, {"price":"0.05", "size":"1742.19"}, {"price":"0.06", "size":"1122.02"}, {"price":"0.07", "size":"953.49"}, {"price":"0.08", "size":"1234.38"}, {"price":"0.09", "size":"791.7"}, {"price":"0.1", "size":"561.2"}, {"price":"0.11", "size":"1502.1"}, {"price":"0.12", "size":"1102.45"}, {"price":"0.13", "size":"139.4"}, {"price":"0.14", "size":"281.8"}, {"price":"0.15", "size":"444.04"}, {"price":"0.16", "size":"147.1"}, {"price":"0.17", "size":"207.17"}, {"price":"0.18", "size":"150.7"}, {"price":"0.19", "size":"128.89"}, {"price":"0.2", "size":"246.2"}, {"price":"0.21", "size":"636.8"}, {"price":"0.22", "size":"145.5"}, {"price":"0.23", "size":"137.3"}, {"price":"0.24", "size":"162.22"}, {"price":"0.25", "size":"162.2"}, {"price":"0.26", "size":"134.3"}, {"price":"0.27", "size":"148.5"}, {"price":"0.28", "size":"146.77"}, {"price":"0.29", "size":"222.52"}, {"price":"0.3", "size":"228.04"}, {"price":"0.31", "size":"550.01"}, {"price":"0.32", "size":"256.69"}, {"price":"0.33", "size":"134.65"}, {"price":"0.34", "size":"100.76"}, {"price":"0.35", "size":"101.2"}, {"price":"0.36", "size":"211.77"}, {"price":"0.37", "size":"105.91"}, {"price":"0.38", "size":"35.05"}], "asks":[{"price":"0.99", "size":"13054.5"}, {"price":"0.98", "size":"3885.25"}, {"price":"0.97", "size":"2250.95"}, {"price":"0.96", "size":"1270.1"}, {"price":"0.95", "size":"1768.6"}, {"price":"0.94", "size":"1124.35"}, {"price":"0.93", "size":"959.2"}, {"price":"0.92", "size":"1225.88"}, {"price":"0.91", "size":"796.7"}, {"price":"0.9", "size":"365.2"}, {"price":"0.89", "size":"1502.1"}, {"price":"0.88", "size":"195.05"}, {"price":"0.87", "size":"147.4"}, {"price":"0.86", "size":"183.4"}, {"price":"0.85", "size":"469.43"}, {"price":"0.84", "size":"127.1"}, {"price":"0.83", "size":"107.69"}, {"price":"0.82", "size":"125.7"}, {"price":"0.81", "size":"98.89"}, {"price":"0.8", "size":"201.2"}, {"price":"0.79", "size":"616.8"}, {"price":"0.78", "size":"992.5"}, {"price":"0.77", "size":"82.3"}, {"price":"0.76", "size":"118.03"}, {"price":"0.75", "size":"78.3"}, {"price":"0.74", "size":"76.8"}, {"price":"0.73", "size":"70.3"}, {"price":"0.72", "size":"79.87"}, {"price":"0.71", "size":"74.39"}, {"price":"0.7", "size":"83"}, {"price":"0.69", "size":"64.7"}, {"price":"0.68", "size":"160.64"}, {"price":"0.67", "size":"98.1"}, {"price":"0.66", "size":"77.8"}, {"price":"0.65", "size":"69.6"}, {"price":"0.64", "size":"79.39"}, {"price":"0.63", "size":"194.2"}, {"price":"0.62", "size":"85"}, {"price":"0.61", "size":"69.8"}, {"price":"0.6", "size":"97.94"}, {"price":"0.59", "size":"100.5"}, {"price":"0.58", "size":"86.02"}, {"price":"0.57", "size":"100.3"}, {"price":"0.56", "size":"64.2"}, {"price":"0.55", "size":"204.71"}, {"price":"0.54", "size":"102.1"}, {"price":"0.53", "size":"72.1"}, {"price":"0.52", "size":"71"}, {"price":"0.51", "size":"81"}, {"price":"0.5", "size":"113"}, {"price":"0.49", "size":"406"}, {"price":"0.48", "size":"195"}, {"price":"0.47", "size":"436.02"}, {"price":"0.46", "size":"148.85"}, {"price":"0.45", "size":"226.69"}, {"price":"0.44", "size":"263.99"}, {"price":"0.43", "size":"169"}, {"price":"0.42", "size":"151.82"}, {"price":"0.41", "size":"260.34"}, {"price":"0.4", "size":"146.7"}, {"price":"0.39", "size":"355.51"}], "hash":"2b2d36a829e1a4cde231d35257d57b8ffd65fa92", "timestamp":"1784449238140", "event_type":"book"}
{"market":"0xab772601f501b265bfe8982eb61d5347ef9945de314bfdf4ac0189c288ffb0b3", "asset_id":"17924629579804316786455515989238352689210911545477836576430679697715946894553", "bids":[{"price":"0.01", "size":"13054.5"}, {"price":"0.02", "size":"3885.25"}, {"price":"0.03", "size":"2250.95"}, {"price":"0.04", "size":"1270.1"}, {"price":"0.05", "size":"1768.6"}, {"price":"0.06", "size":"1124.35"}, {"price":"0.07", "size":"959.2"}, {"price":"0.08", "size":"1225.88"}, {"price":"0.09", "size":"796.7"}, {"price":"0.1", "size":"365.2"}, {"price":"0.11", "size":"1502.1"}, {"price":"0.12", "size":"195.05"}, {"price":"0.13", "size":"147.4"}, {"price":"0.14", "size":"183.4"}, {"price":"0.15", "size":"469.43"}, {"price":"0.16", "size":"127.1"}, {"price":"0.17", "size":"107.69"}, {"price":"0.18", "size":"125.7"}, {"price":"0.19", "size":"98.89"}, {"price":"0.2", "size":"201.2"}, {"price":"0.21", "size":"616.8"}, {"price":"0.22", "size":"992.5"}, {"price":"0.23", "size":"82.3"}, {"price":"0.24", "size":"118.03"}, {"price":"0.25", "size":"78.3"}, {"price":"0.26", "size":"76.8"}, {"price":"0.27", "size":"70.3"}, {"price":"0.28", "size":"79.87"}, {"price":"0.29", "size":"74.39"}, {"price":"0.3", "size":"83"}, {"price":"0.31", "size":"64.7"}, {"price":"0.32", "size":"160.64"}, {"price":"0.33", "size":"98.1"}, {"price":"0.34", "size":"77.8"}, {"price":"0.35", "size":"69.6"}, {"price":"0.36", "size":"79.39"}, {"price":"0.37", "size":"194.2"}, {"price":"0.38", "size":"85"}, {"price":"0.39", "size":"69.8"}, {"price":"0.4", "size":"97.94"}, {"price":"0.41", "size":"100.5"}, {"price":"0.42", "size":"86.02"}, {"price":"0.43", "size":"100.3"}, {"price":"0.44", "size":"64.2"}, {"price":"0.45", "size":"204.71"}, {"price":"0.46", "size":"102.1"}, {"price":"0.47", "size":"72.1"}, {"price":"0.48", "size":"71"}, {"price":"0.49", "size":"81"}, {"price":"0.5", "size":"113"}, {"price":"0.51", "size":"406"}, {"price":"0.52", "size":"195"}, {"price":"0.53", "size":"436.02"}, {"price":"0.54", "size":"148.85"}, {"price":"0.55", "size":"226.69"}, {"price":"0.56", "size":"263.99"}, {"price":"0.57", "size":"169"}, {"price":"0.58", "size":"151.82"}, {"price":"0.59", "size":"260.34"}, {"price":"0.6", "size":"146.7"}, {"price":"0.61", "size":"355.51"}], "asks":[{"price":"0.99", "size":"14884.14"}, {"price":"0.98", "size":"3964.52"}, {"price":"0.97", "size":"2179.29"}, {"price":"0.96", "size":"1215.1"}, {"price":"0.95", "size":"1742.19"}, {"price":"0.94", "size":"1122.02"}, {"price":"0.93", "size":"953.49"}, {"price":"0.92", "size":"1234.38"}, {"price":"0.91", "size":"791.7"}, {"price":"0.9", "size":"561.2"}, {"price":"0.89", "size":"1502.1"}, {"price":"0.88", "size":"1102.45"}, {"price":"0.87", "size":"139.4"}, {"price":"0.86", "size":"281.8"}, {"price":"0.85", "size":"444.04"}, {"price":"0.84", "size":"147.1"}, {"price":"0.83", "size":"207.17"}, {"price":"0.82", "size":"150.7"}, {"price":"0.81", "size":"128.89"}, {"price":"0.8", "size":"246.2"}, {"price":"0.79", "size":"636.8"}, {"price":"0.78", "size":"145.5"}, {"price":"0.77", "size":"137.3"}, {"price":"0.76", "size":"162.22"}, {"price":"0.75", "size":"162.2"}, {"price":"0.74", "size":"134.3"}, {"price":"0.73", "size":"148.5"}, {"price":"0.72", "size":"146.77"}, {"price":"0.71", "size":"222.52"}, {"price":"0.7", "size":"228.04"}, {"price":"0.69", "size":"550.01"}, {"price":"0.68", "size":"256.69"}, {"price":"0.67", "size":"134.65"}, {"price":"0.66", "size":"100.76"}, {"price":"0.65", "size":"101.2"}, {"price":"0.64", "size":"211.77"}, {"price":"0.63", "size":"105.91"}, {"price":"0.62", "size":"35.05"}], "hash":"db08d031c22d2137019688c35c70c13ad67667bf", "timestamp":"1784449238140", "event_type":"book"}
{"market":"0xab772601f501b265bfe8982eb61d5347ef9945de314bfdf4ac0189c288ffb0b3", "price_changes":[{"asset_id":"12935926064588426924078449947177910958215776269411501731627440228801766632772", "price":"0.35", "size":"106.2", "side":"BUY", "hash":"8804af0afba6857a4f9ed29de6a3aa64c2201665", "best_bid":"0.38", "best_ask":"0.39"}, {"asset_id":"17924629579804316786455515989238352689210911545477836576430679697715946894553", "price":"0.65", "size":"106.2", "side":"SELL", "hash":"3681bf8e0453099808a4a8309b88b05b7d6507c5", "best_bid":"0.61", "best_ask":"0.62"}], "timestamp":"1784449238152", "event_type":"price_change"}
{"market":"0xab772601f501b265bfe8982eb61d5347ef9945de314bfdf4ac0189c288ffb0b3", "price_changes":[{"asset_id":"12935926064588426924078449947177910958215776269411501731627440228801766632772", "price":"0.8", "size":"206.2", "side":"SELL", "hash":"54a83d4c2f3c29c2f0fba00b4eeca9de299e4d30", "best_bid":"0.38", "best_ask":"0.39"}, {"asset_id":"17924629579804316786455515989238352689210911545477836576430679697715946894553", "price":"0.2", "size":"206.2", "side":"BUY", "hash":"41596880a2fa76b8fa915104331754ceb70c6ad9", "best_bid":"0.61", "best_ask":"0.62"}], "timestamp":"1784449238158", "event_type":"price_change"}
{"market":"0xab772601f501b265bfe8982eb61d5347ef9945de314bfdf4ac0189c288ffb0b3", "price_changes":[{"asset_id":"17924629579804316786455515989238352689210911545477836576430679697715946894553", "price":"0.02", "size":"3890.25", "side":"BUY", "hash":"e10004b46f5fbf39da89075bb4ab0f1f586a7ef3", "best_bid":"0.61", "best_ask":"0.62"}, {"asset_id":"12935926064588426924078449947177910958215776269411501731627440228801766632772", "price":"0.98", "size":"3890.25", "side":"SELL", "hash":"d5738ddcbb43da9606a8e12f10a639116368d48c", "best_bid":"0.38", "best_ask":"0.39"}], "timestamp":"1784449238159", "event_type":"price_change"}
{"market":"0xab772601f501b265bfe8982eb61d5347ef9945de314bfdf4ac0189c288ffb0b3", "price_changes":[{"asset_id":"12935926064588426924078449947177910958215776269411501731627440228801766632772", "price":"0.34", "size":"82.96", "side":"BUY", "hash":"b6d31af89fce96062810ea0bddbbaa97749a414d", "best_bid":"0.38", "best_ask":"0.39"}, {"asset_id":"17924629579804316786455515989238352689210911545477836576430679697715946894553", "price":"0.66", "size":"82.96", "side":"SELL", "hash":"143a78e681d9eee29fe0864487c2144357dd715e", "best_bid":"0.61", "best_ask":"0.62"}], "timestamp":"1784449238164", "event_type":"price_change"}
{"market":"0xab772601f501b265bfe8982eb61d5347ef9945de314bfdf4ac0189c288ffb0b3", "price_changes":[{"asset_id":"17924629579804316786455515989238352689210911545477836576430679697715946894553", "price":"0.01", "size":"12954.5", "side":"BUY", "hash":"b02f326e5ebbf41d0bb56384548d48547289dde8", "best_bid":"0.61", "best_ask":"0.62"}, {"asset_id":"12935926064588426924078449947177910958215776269411501731627440228801766632772", "price":"0.99", "size":"12954.5", "side":"SELL", "hash":"4938285d829239ec191f6bf5963b567f655b1f70", "best_bid":"0.38", "best_ask":"0.39"}], "timestamp":"1784449238165", "event_type":"price_change"}
{"market":"0xab772601f501b265bfe8982eb61d5347ef9945de314bfdf4ac0189c288ffb0b3", "price_changes":[{"asset_id":"17924629579804316786455515989238352689210911545477836576430679697715946894553", "price":"0.61", "size":"364.9", "side":"BUY", "hash":"d5b679cb1f843e6edce9f6720e42978b6c3433c5", "best_bid":"0.61", "best_ask":"0.62"}, {"asset_id":"12935926064588426924078449947177910958215776269411501731627440228801766632772", "price":"0.39", "size":"364.9", "side":"SELL", "hash":"fe8ae9e6e3f908669916907a5e5ce1c9201bb30a", "best_bid":"0.38", "best_ask":"0.39"}], "timestamp":"1784449238166", "event_type":"price_change"}
{"market":"0xab772601f501b265bfe8982eb61d5347ef9945de314bfdf4ac0189c288ffb0b3", "price_changes":[{"asset_id":"17924629579804316786455515989238352689210911545477836576430679697715946894553", "price":"0.61", "size":"354.9", "side":"BUY", "hash":"fd27c7aeb4d75dac5c6ad216fd9ebe261bab0987", "best_bid":"0.61", "best_ask":"0.62"}, {"asset_id":"12935926064588426924078449947177910958215776269411501731627440228801766632772", "price":"0.39", "size":"354.9", "side":"SELL", "hash":"f89e9684928c91d4f4440847edf73b481e595701", "best_bid":"0.38", "best_ask":"0.39"}], "timestamp":"1784449238196", "event_type":"price_change"}
{"market":"0xab772601f501b265bfe8982eb61d5347ef9945de314bfdf4ac0189c288ffb0b3", "price_changes":[{"asset_id":"17924629579804316786455515989238352689210911545477836576430679697715946894553", "price":"0.01", "size":"12960.5", "side":"BUY", "hash":"2abe03653d956cb91f7471e395b024c9b312d8e1", "best_bid":"0.61", "best_ask":"0.62"}, {"asset_id":"12935926064588426924078449947177910958215776269411501731627440228801766632772", "price":"0.99", "size":"12960.5", "side":"SELL", "hash":"b5e474ae5b5c95ce9ccac710c780cd958231c01a", "best_bid":"0.38", "best_ask":"0.39"}], "timestamp":"1784449238204", "event_type":"price_change"}
{"market":"0xab772601f501b265bfe8982eb61d5347ef9945de314bfdf4ac0189c288ffb0b3", "price_changes":[{"asset_id":"12935926064588426924078449947177910958215776269411501731627440228801766632772", "price":"0.37", "size":"125.91", "side":"BUY", "hash":"aa809afb92f1aa38874249ee2f1a1f641705e364", "best_bid":"0.38", "best_ask":"0.39"}, {"asset_id":"17924629579804316786455515989238352689210911545477836576430679697715946894553", "price":"0.63", "size":"125.91", "side":"SELL", "hash":"5f9ee63a15f785e7918ea31b823af45662eb8073", "best_bid":"0.61", "best_ask":"0.62"}], "timestamp":"1784449238205", "event_type":"price_change"}
{"market":"0xab772601f501b265bfe8982eb61d5347ef9945de314bfdf4ac0189c288ffb0b3", "price_changes":[{"asset_id":"12935926064588426924078449947177910958215776269411501731627440228801766632772", "price":"0.36", "size":"231.77", "side":"BUY", "hash":"57e0c354a8818af7cce792137785fcccc67bfbcb", "best_bid":"0.38", "best_ask":"0.39"}, {"asset_id":"17924629579804316786455515989238352689210911545477836576430679697715946894553", "price":"0.64", "size":"231.77", "side":"SELL", "hash":"f844c45dbd947b04181b87a8eb01a74fe84e1e33", "best_bid":"0.61", "best_ask":"0.62"}], "timestamp":"1784449238205", "event_type":"price_change"}
{"market":"0xab772601f501b265bfe8982eb61d5347ef9945de314bfdf4ac0189c288ffb0b3", "price_changes":[{"asset_id":"12935926064588426924078449947177910958215776269411501731627440228801766632772", "price":"0.38", "size":"55.05", "side":"BUY", "hash":"7d935924a5e9648802c664b45055133ea0fe9f28", "best_bid":"0.38", "best_ask":"0.39"}, {"asset_id":"17924629579804316786455515989238352689210911545477836576430679697715946894553", "price":"0.62", "size":"55.05", "side":"SELL", "hash":"3df32e95e82d5ddb3ba3c50b1f6942b158655b2f", "best_bid":"0.61", "best_ask":"0.62"}], "timestamp":"1784449238209", "event_type":"price_change"}
{"market":"0xab772601f501b265bfe8982eb61d5347ef9945de314bfdf4ac0189c288ffb0b3", "price_changes":[{"asset_id":"12935926064588426924078449947177910958215776269411501731627440228801766632772", "price":"0.01", "size":"14879.14", "side":"BUY", "hash":"9600a8d9fdc51b14c34de329d3f390b486aff7a9", "best_bid":"0.38", "best_ask":"0.39"}, {"asset_id":"17924629579804316786455515989238352689210911545477836576430679697715946894553", "price":"0.99", "size":"14879.14", "side":"SELL", "hash":"47592c4e7cc2d449626a6c21621f619861794472", "best_bid":"0.61", "best_ask":"0.62"}], "timestamp":"1784449238212", "event_type":"price_change"}
{"market":"0xab772601f501b265bfe8982eb61d5347ef9945de314bfdf4ac0189c288ffb0b3", "price_changes":[{"asset_id":"12935926064588426924078449947177910958215776269411501731627440228801766632772", "price":"0.22", "size":"125.5", "side":"BUY", "hash":"8de3a0645a8a5cd8a3be2049df7d515d77d10447", "best_bid":"0.38", "best_ask":"0.39"}, {"asset_id":"17924629579804316786455515989238352689210911545477836576430679697715946894553", "price":"0.78", "size":"125.5", "side":"SELL", "hash":"3f998187e989551f8d1581153bb3f5d8523f388c", "best_bid":"0.61", "best_ask":"0.62"}], "timestamp":"1784449238213", "event_type":"price_change"}
{"market":"0xab772601f501b265bfe8982eb61d5347ef9945de314bfdf4ac0189c288ffb0b3", "price_changes":[{"asset_id":"17924629579804316786455515989238352689210911545477836576430679697715946894553", "price":"0.01", "size":"13060.5", "side":"BUY", "hash":"aa8a0539aa724010bf65436424eb4bf8fe09ad09", "best_bid":"0.61", "best_ask":"0.62"}, {"asset_id":"12935926064588426924078449947177910958215776269411501731627440228801766632772", "price":"0.99", "size":"13060.5", "side":"SELL", "hash":"c01414c69aacab8ab96a0ec8263c9b8c27c41956", "best_bid":"0.38", "best_ask":"0.39"}], "timestamp":"1784449238216", "event_type":"price_change"}
{"market":"0xab772601f501b265bfe8982eb61d5347ef9945de314bfdf4ac0189c288ffb0b3", "price_changes":[{"asset_id":"12935926064588426924078449947177910958215776269411501731627440228801766632772", "price":"0.01", "size":"14874.14", "side":"BUY", "hash":"f086e01127ea2485a3de27929aebfb1bca48074d", "best_bid":"0.38", "best_ask":"0.39"}, {"asset_id":"17924629579804316786455515989238352689210911545477836576430679697715946894553", "price":"0.99", "size":"14874.14", "side":"SELL", "hash":"f1a4fb8a2f88f894d45aa735ece2c000d74f12dd", "best_bid":"0.61", "best_ask":"0.62"}], "timestamp":"1784449238219", "event_type":"price_change"}
{"market":"0xab772601f501b265bfe8982eb61d5347ef9945de314bfdf4ac0189c288ffb0b3", "price_changes":[{"asset_id":"12935926064588426924078449947177910958215776269411501731627440228801766632772", "price":"0.38", "size":"65.05", "side":"BUY", "hash":"83c96ce3c0f44b691e91c20a5d1d9459d83a6299", "best_bid":"0.38", "best_ask":"0.39"}, {"asset_id":"17924629579804316786455515989238352689210911545477836576430679697715946894553", "price":"0.62", "size":"65.05", "side":"SELL", "hash":"608e820c2c2aab31d593c3219a0313b4cb2b3437", "best_bid":"0.61", "best_ask":"0.62"}], "timestamp":"1784449238220", "event_type":"price_change"}
{"market":"0xab772601f501b265bfe8982eb61d5347ef9945de314bfdf4ac0189c288ffb0b3", "price_changes":[{"asset_id":"12935926064588426924078449947177910958215776269411501731627440228801766632772", "price":"0.01", "size":"14869.14", "side":"BUY", "hash":"ea90bfb19e5f24359ef7826b01877ae4ca4b8385", "best_bid":"0.38", "best_ask":"0.39"}, {"asset_id":"17924629579804316786455515989238352689210911545477836576430679697715946894553", "price":"0.99", "size":"14869.14", "side":"SELL", "hash":"f44d93fb8f992089cd1f9243b64f497ff6b4d00e", "best_bid":"0.61", "best_ask":"0.62"}], "timestamp":"1784449238222", "event_type":"price_change"}
{"market":"0xab772601f501b265bfe8982eb61d5347ef9945de314bfdf4ac0189c288ffb0b3", "price_changes":[{"asset_id":"17924629579804316786455515989238352689210911545477836576430679697715946894553", "price":"0.02", "size":"3885.25", "side":"BUY", "hash":"b3a1504d1f3a535631d54e3bcf3602b1397c1cf7", "best_bid":"0.61", "best_ask":"0.62"}, {"asset_id":"12935926064588426924078449947177910958215776269411501731627440228801766632772", "price":"0.98", "size":"3885.25", "side":"SELL", "hash":"1d395a6b6341001053d2d92e8f19a9178e9e80e0", "best_bid":"0.38", "best_ask":"0.39"}], "timestamp":"1784449238223", "event_type":"price_change"}
{"market":"0xab772601f501b265bfe8982eb61d5347ef9945de314bfdf4ac0189c288ffb0b3", "price_changes":[{"asset_id":"12935926064588426924078449947177910958215776269411501731627440228801766632772", "price":"0.01", "size":"14874.14", "side":"BUY", "hash":"1da4d253989faba76a743058c34ec6062ecd5602", "best_bid":"0.38", "best_ask":"0.39"}, {"asset_id":"17924629579804316786455515989238352689210911545477836576430679697715946894553", "price":"0.99", "size":"14874.14", "side":"SELL", "hash":"87bfb76ce16d0a44d0dbfc24e8cbf392a1bbc59d", "best_bid":"0.61", "best_ask":"0.62"}], "timestamp":"1784449238224", "event_type":"price_change"}
{"market":"0xab772601f501b265bfe8982eb61d5347ef9945de314bfdf4ac0189c288ffb0b3", "price_changes":[{"asset_id":"17924629579804316786455515989238352689210911545477836576430679697715946894553", "price":"0.01", "size":"13065.5", "side":"BUY", "hash":"fadc821b29ecefc10a4c8d183b3eb515a6e68fcd", "best_bid":"0.61", "best_ask":"0.62"}, {"asset_id":"12935926064588426924078449947177910958215776269411501731627440228801766632772", "price":"0.99", "size":"13065.5", "side":"SELL", "hash":"1a215719d057c5ad1bc913b1aba424e5e1563657", "best_bid":"0.38", "best_ask":"0.39"}], "timestamp":"1784449238225", "event_type":"price_change"}
{"market":"0xab772601f501b265bfe8982eb61d5347ef9945de314bfdf4ac0189c288ffb0b3", "price_changes":[{"asset_id":"12935926064588426924078449947177910958215776269411501731627440228801766632772", "price":"0.01", "size":"14879.14", "side":"BUY", "hash":"cb0d2dccadb152b8511d6a270e09fbc20bbe0a76", "best_bid":"0.38", "best_ask":"0.39"}, {"asset_id":"17924629579804316786455515989238352689210911545477836576430679697715946894553", "price":"0.99", "size":"14879.14", "side":"SELL", "hash":"763f6657cb3cd3eaba9ada642df1b819c0db43d5", "best_bid":"0.61", "best_ask":"0.62"}], "timestamp":"1784449238227", "event_type":"price_change"}
{"market":"0xab772601f501b265bfe8982eb61d5347ef9945de314bfdf4ac0189c288ffb0b3", "price_changes":[{"asset_id":"12935926064588426924078449947177910958215776269411501731627440228801766632772", "price":"0.01", "size":"14884.14", "side":"BUY", "hash":"4f22a03cc391ada6894796cf37ff85941647f22a", "best_bid":"0.38", "best_ask":"0.39"}, {"asset_id":"17924629579804316786455515989238352689210911545477836576430679697715946894553", "price":"0.99", "size":"14884.14", "side":"SELL", "hash":"b21dc37de973d4f4cc1c5c559fd0029c8aaf8b0d", "best_bid":"0.61", "best_ask":"0.62"}], "timestamp":"1784449238228", "event_type":"price_change"}
{"market":"0xab772601f501b265bfe8982eb61d5347ef9945de314bfdf4ac0189c288ffb0b3", "price_changes":[{"asset_id":"12935926064588426924078449947177910958215776269411501731627440228801766632772", "price":"0.12", "size":"1127.05", "side":"BUY", "hash":"4827205ef142af6d0b56e6c7639e15d9e7a22ef9", "best_bid":"0.38", "best_ask":"0.39"}, {"asset_id":"17924629579804316786455515989238352689210911545477836576430679697715946894553", "price":"0.88", "size":"1127.05", "side":"SELL", "hash":"0ef36e36822df394e4a478eb9a0da25cd96eb0b3", "best_bid":"0.61", "best_ask":"0.62"}], "timestamp":"1784449238229", "event_type":"price_change"}
{"market":"0xab772601f501b265bfe8982eb61d5347ef9945de314bfdf4ac0189c288ffb0b3", "price_changes":[{"asset_id":"17924629579804316786455515989238352689210911545477836576430679697715946894553", "price":"0.01", "size":"13059.5", "side":"BUY", "hash":"4c7a9dae4874c238c24347d0ab4570c5fd91db0f", "best_bid":"0.61", "best_ask":"0.62"}, {"asset_id":"12935926064588426924078449947177910958215776269411501731627440228801766632772", "price":"0.99", "size":"13059.5", "side":"SELL", "hash":"f87c9de2d18b05092ca956d81725b7082964ca25", "best_bid":"0.38", "best_ask":"0.39"}], "timestamp":"1784449238231", "event_type":"price_change"}
{"market":"0xab772601f501b265bfe8982eb61d5347ef9945de314bfdf4ac0189c288ffb0b3", "price_changes":[{"asset_id":"12935926064588426924078449947177910958215776269411501731627440228801766632772", "price":"0.38", "size":"70.05", "side":"BUY", "hash":"75810bf695a79bc645b49fb6e87e798eacce4ef4", "best_bid":"0.38", "best_ask":"0.39"}, {"asset_id":"17924629579804316786455515989238352689210911545477836576430679697715946894553", "price":"0.62", "size":"70.05", "side":"SELL", "hash":"52cd56ab67034e82f9a3d032367bf10a51188770", "best_bid":"0.61", "best_ask":"0.62"}], "timestamp":"1784449238232", "event_type":"price_change"}
{"market":"0xab772601f501b265bfe8982eb61d5347ef9945de314bfdf4ac0189c288ffb0b3", "price_changes":[{"asset_id":"12935926064588426924078449947177910958215776269411501731627440228801766632772", "price":"0.01", "size":"14889.14", "side":"BUY", "hash":"f5248663e3da7ce46c45bafd2c106b89c103d4f5", "best_bid":"0.38", "best_ask":"0.39"}, {"asset_id":"17924629579804316786455515989238352689210911545477836576430679697715946894553", "price":"0.99", "size":"14889.14", "side":"SELL", "hash":"1de0fd91bc25e800a34c6b1b8e022f8cb0cdf89a", "best_bid":"0.61", "best_ask":"0.62"}], "timestamp":"1784449238234", "event_type":"price_change"}
{"market":"0xab772601f501b265bfe8982eb61d5347ef9945de314bfdf4ac0189c288ffb0b3", "price_changes":[{"asset_id":"12935926064588426924078449947177910958215776269411501731627440228801766632772", "price":"0.01", "size":"14894.14", "side":"BUY", "hash":"8a29038476f7a9c24853f1eb673c2dbf923dd9d8", "best_bid":"0.38", "best_ask":"0.39"}, {"asset_id":"17924629579804316786455515989238352689210911545477836576430679697715946894553", "price":"0.99", "size":"14894.14", "side":"SELL", "hash":"12c465cf4b8409ffa55f8075d6819f3d44da0d14", "best_bid":"0.61", "best_ask":"0.62"}], "timestamp":"1784449238234", "event_type":"price_change"}
{"market":"0xab772601f501b265bfe8982eb61d5347ef9945de314bfdf4ac0189c288ffb0b3", "price_changes":[{"asset_id":"17924629579804316786455515989238352689210911545477836576430679697715946894553", "price":"0.01", "size":"13064.5", "side":"BUY", "hash":"5101589babc9cb2b4a69cc37b98d5d9ce4313d9a", "best_bid":"0.61", "best_ask":"0.62"}, {"asset_id":"12935926064588426924078449947177910958215776269411501731627440228801766632772", "price":"0.99", "size":"13064.5", "side":"SELL", "hash":"cf5fe3bfb7ba4ec951ae6dacee2ee32e4f67fe1a", "best_bid":"0.38", "best_ask":"0.39"}], "timestamp":"1784449238235", "event_type":"price_change"}
{"market":"0xab772601f501b265bfe8982eb61d5347ef9945de314bfdf4ac0189c288ffb0b3", "price_changes":[{"asset_id":"12935926064588426924078449947177910958215776269411501731627440228801766632772", "price":"0.01", "size":"14899.14", "side":"BUY", "hash":"757afc79ee47ea1ada5fecd62b18976b1dc096f7", "best_bid":"0.38", "best_ask":"0.39"}, {"asset_id":"17924629579804316786455515989238352689210911545477836576430679697715946894553", "price":"0.99", "size":"14899.14", "side":"SELL", "hash":"ef00694235bb0ead6b0065a36525c73899db6769", "best_bid":"0.61", "best_ask":"0.62"}], "timestamp":"1784449238236", "event_type":"price_change"}
{"market":"0xab772601f501b265bfe8982eb61d5347ef9945de314bfdf4ac0189c288ffb0b3", "price_changes":[{"asset_id":"17924629579804316786455515989238352689210911545477836576430679697715946894553", "price":"0.01", "size":"13069.5", "side":"BUY", "hash":"4e0f5e851ca0d55ada6db976ce0963a1be43240d", "best_bid":"0.61", "best_ask":"0.62"}, {"asset_id":"12935926064588426924078449947177910958215776269411501731627440228801766632772", "price":"0.99", "size":"13069.5", "side":"SELL", "hash":"49fdcf345be11ca5cf9fcbe87d29aea93913ef08", "best_bid":"0.38", "best_ask":"0.39"}], "timestamp":"1784449238237", "event_type":"price_change"}
{"market":"0xab772601f501b265bfe8982eb61d5347ef9945de314bfdf4ac0189c288ffb0b3", "price_changes":[{"asset_id":"17924629579804316786455515989238352689210911545477836576430679697715946894553", "price":"0.01", "size":"13074.5", "side":"BUY", "hash":"b37f8c3406d05a67248e949d8d1d026547e35492", "best_bid":"0.61", "best_ask":"0.62"}, {"asset_id":"12935926064588426924078449947177910958215776269411501731627440228801766632772", "price":"0.99", "size":"13074.5", "side":"SELL", "hash":"41446e9daddcddf6c111162a774a43cd5d582032", "best_bid":"0.38", "best_ask":"0.39"}], "timestamp":"1784449238237", "event_type":"price_change"}
{"market":"0xab772601f501b265bfe8982eb61d5347ef9945de314bfdf4ac0189c288ffb0b3", "price_changes":[{"asset_id":"17924629579804316786455515989238352689210911545477836576430679697715946894553", "price":"0.01", "size":"13069.5", "side":"BUY", "hash":"d4750461fd7772a8119b7e05e1c944907604347e", "best_bid":"0.61", "best_ask":"0.62"}, {"asset_id":"12935926064588426924078449947177910958215776269411501731627440228801766632772", "price":"0.99", "size":"13069.5", "side":"SELL", "hash":"0c51be4a4c26a63e50de7f2ec0a76f0d40a0dbd3", "best_bid":"0.38", "best_ask":"0.39"}], "timestamp":"1784449238245", "event_type":"price_change"}
{"market":"0xab772601f501b265bfe8982eb61d5347ef9945de314bfdf4ac0189c288ffb0b3", "price_changes":[{"asset_id":"12935926064588426924078449947177910958215776269411501731627440228801766632772", "price":"0.35", "size":"101.2", "side":"BUY", "hash":"84d3ee9e71a32df487a06dafa784a32fd2db2986", "best_bid":"0.38", "best_ask":"0.39"}, {"asset_id":"17924629579804316786455515989238352689210911545477836576430679697715946894553", "price":"0.65", "size":"101.2", "side":"SELL", "hash":"70904599d5c977c0c45d4a49d4afceee0953fb14", "best_bid":"0.61", "best_ask":"0.62"}], "timestamp":"1784449238250", "event_type":"price_change"}
{"market":"0xab772601f501b265bfe8982eb61d5347ef9945de314bfdf4ac0189c288ffb0b3", "price_changes":[{"asset_id":"17924629579804316786455515989238352689210911545477836576430679697715946894553", "price":"0.01", "size":"13169.5", "side":"BUY", "hash":"cb03ceaab08446a856411d2bf5283677a0e325c1", "best_bid":"0.61", "best_ask":"0.62"}, {"asset_id":"12935926064588426924078449947177910958215776269411501731627440228801766632772", "price":"0.99", "size":"13169.5", "side":"SELL", "hash":"961d1cc379996a959763a7e6d826423259b7dbbe", "best_bid":"0.38", "best_ask":"0.39"}], "timestamp":"1784449238251", "event_type":"price_change"}
{"market":"0xab772601f501b265bfe8982eb61d5347ef9945de314bfdf4ac0189c288ffb0b3", "asset_id":"12935926064588426924078449947177910958215776269411501731627440228801766632772", "price":"0.39", "size":"25.641024", "fee_rate_bps":"0", "side":"BUY", "timestamp":"1784449238256", "event_type":"last_trade_price", "transaction_hash":"0xf14a0455a88996c670570217450df7a54f23489ab67d78c281266860862467dd"}
{"market":"0xab772601f501b265bfe8982eb61d5347ef9945de314bfdf4ac0189c288ffb0b3", "price_changes":[{"asset_id":"17924629579804316786455515989238352689210911545477836576430679697715946894553", "price":"0.01", "size":"13069.5", "side":"BUY", "hash":"2a22e34f05dc8ceaeccfc62f0fe84b6322d181fb", "best_bid":"0.61", "best_ask":"0.62"}, {"asset_id":"12935926064588426924078449947177910958215776269411501731627440228801766632772", "price":"0.99", "size":"13069.5", "side":"SELL", "hash":"f367c46a6e913984d48342fe68493dca5c954545", "best_bid":"0.38", "best_ask":"0.39"}], "timestamp":"1784449238260", "event_type":"price_change"}
{"market":"0xab772601f501b265bfe8982eb61d5347ef9945de314bfdf4ac0189c288ffb0b3", "price_changes":[{"asset_id":"17924629579804316786455515989238352689210911545477836576430679697715946894553", "price":"0.01", "size":"13074.51", "side":"BUY", "hash":"e32cc5aa0c7c7a415eaa5e1391b2d43302d373c5", "best_bid":"0.61", "best_ask":"0.62"}, {"asset_id":"12935926064588426924078449947177910958215776269411501731627440228801766632772", "price":"0.99", "size":"13074.51", "side":"SELL", "hash":"f4e35dfefbcd581542be81526d1908e523b3d475", "best_bid":"0.38", "best_ask":"0.39"}], "timestamp":"1784449238263", "event_type":"price_change"}
{"market":"0xab772601f501b265bfe8982eb61d5347ef9945de314bfdf4ac0189c288ffb0b3", "price_changes":[{"asset_id":"12935926064588426924078449947177910958215776269411501731627440228801766632772", "price":"0.23", "size":"112.3", "side":"BUY", "hash":"bb2aac3c86797347e851d7eb26898b1b369fc99b", "best_bid":"0.38", "best_ask":"0.39"}, {"asset_id":"17924629579804316786455515989238352689210911545477836576430679697715946894553", "price":"0.77", "size":"112.3", "side":"SELL", "hash":"613c26d18e19589063807afecc37dcf313948e1b", "best_bid":"0.61", "best_ask":"0.62"}], "timestamp":"1784449238265", "event_type":"price_change"}
{"market":"0xab772601f501b265bfe8982eb61d5347ef9945de314bfdf4ac0189c288ffb0b3", "price_changes":[{"asset_id":"17924629579804316786455515989238352689210911545477836576430679697715946894553", "price":"0.57", "size":"144", "side":"BUY", "hash":"0046cc2fea3ee40e0b7144c36f49f9a695ac2c67", "best_bid":"0.61", "best_ask":"0.62"}, {"asset_id":"12935926064588426924078449947177910958215776269411501731627440228801766632772", "price":"0.43", "size":"144", "side":"SELL", "hash":"6c29121392c48129dce420aae6b4598bdb037f06", "best_bid":"0.38", "best_ask":"0.39"}], "timestamp":"1784449238265", "event_type":"price_change"}
{"market":"0xab772601f501b265bfe8982eb61d5347ef9945de314bfdf4ac0189c288ffb0b3", "price_changes":[{"asset_id":"12935926064588426924078449947177910958215776269411501731627440228801766632772", "price":"0.19", "size":"103.89", "side":"BUY", "hash":"25be1653eafbfa42dc8dea60a64962b82345de7a", "best_bid":"0.38", "best_ask":"0.39"}, {"asset_id":"17924629579804316786455515989238352689210911545477836576430679697715946894553", "price":"0.81", "size":"103.89", "side":"SELL", "hash":"7cf2935744496b891080cf84c5a50b373c762dd9", "best_bid":"0.61", "best_ask":"0.62"}], "timestamp":"1784449238267", "event_type":"price_change"}
{"market":"0xab772601f501b265bfe8982eb61d5347ef9945de314bfdf4ac0189c288ffb0b3", "price_changes":[{"asset_id":"17924629579804316786455515989238352689210911545477836576430679697715946894553", "price":"0.43", "size":"75.3", "side":"BUY", "hash":"3655a48f0fb685c3d5bb3bf5b0b2803c66587c03", "best_bid":"0.61", "best_ask":"0.62"}, {"asset_id":"12935926064588426924078449947177910958215776269411501731627440228801766632772", "price":"0.57", "size":"75.3", "side":"SELL", "hash":"1cb74e3a3a0e9f0ff735f2e3cdb67fc03f1ebf70", "best_bid":"0.38", "best_ask":"0.39"}], "timestamp":"1784449238268", "event_type":"price_change"}
{"market":"0xab772601f501b265bfe8982eb61d5347ef9945de314bfdf4ac0189c288ffb0b3", "price_changes":[{"asset_id":"17924629579804316786455515989238352689210911545477836576430679697715946894553", "price":"0.6", "size":"121.7", "side":"BUY", "hash":"ede9f45c87ecce19152d84f3a2bb8ef1e96688ae", "best_bid":"0.61", "best_ask":"0.62"}, {"asset_id":"12935926064588426924078449947177910958215776269411501731627440228801766632772", "price":"0.4", "size":"121.7", "side":"SELL", "hash":"ce85e5be9c23d287fc52565527b7e6a26043207a", "best_bid":"0.38", "best_ask":"0.39"}], "timestamp":"1784449238268", "event_type":"price_change"}
{"market":"0xab772601f501b265bfe8982eb61d5347ef9945de314bfdf4ac0189c288ffb0b3", "price_changes":[{"asset_id":"12935926064588426924078449947177910958215776269411501731627440228801766632772", "price":"0.32", "size":"231.69", "side":"BUY", "hash":"dd8020dcd275ef875d32ea3aa010c8abc9c09e6f", "best_bid":"0.38", "best_ask":"0.39"}, {"asset_id":"17924629579804316786455515989238352689210911545477836576430679697715946894553", "price":"0.68", "size":"231.69", "side":"SELL", "hash":"1aab78cfe7937c7f918815402a5fe77db7b637c8", "best_bid":"0.61", "best_ask":"0.62"}], "timestamp":"1784449238268", "event_type":"price_change"}
{"market":"0xab772601f501b265bfe8982eb61d5347ef9945de314bfdf4ac0189c288ffb0b3", "price_changes":[{"asset_id":"12935926064588426924078449947177910958215776269411501731627440228801766632772", "price":"0.01", "size":"14894.14", "side":"BUY", "hash":"b82190bbe07b277e61e4a1ce0bdc02fec34c2c18", "best_bid":"0.38", "best_ask":"0.39"}, {"asset_id":"17924629579804316786455515989238352689210911545477836576430679697715946894553", "price":"0.99", "size":"14894.14", "side":"SELL", "hash":"a19bb20352c57110347ce758e4ea883e09fae3a6", "best_bid":"0.61", "best_ask":"0.62"}], "timestamp":"1784449238268", "event_type":"price_change"}
{"market":"0xab772601f501b265bfe8982eb61d5347ef9945de314bfdf4ac0189c288ffb0b3", "price_changes":[{"asset_id":"12935926064588426924078449947177910958215776269411501731627440228801766632772", "price":"0.29", "size":"216.99", "side":"BUY", "hash":"060c62732b65cf5c936850bf782a4a271ad87bcb", "best_bid":"0.38", "best_ask":"0.39"}, {"asset_id":"17924629579804316786455515989238352689210911545477836576430679697715946894553", "price":"0.71", "size":"216.99", "side":"SELL", "hash":"e70f0782e3a40b5c7980ce486d43d8413757dfd8", "best_bid":"0.61", "best_ask":"0.62"}], "timestamp":"1784449238269", "event_type":"price_change"}
{"market":"0xab772601f501b265bfe8982eb61d5347ef9945de314bfdf4ac0189c288ffb0b3", "price_changes":[{"asset_id":"12935926064588426924078449947177910958215776269411501731627440228801766632772", "price":"0.25", "size":"137.2", "side":"BUY", "hash":"c45e7bd93d96da539949ee3fe74775d01369c606", "best_bid":"0.38", "best_ask":"0.39"}, {"asset_id":"17924629579804316786455515989238352689210911545477836576430679697715946894553", "price":"0.75", "size":"137.2", "side":"SELL", "hash":"c7e2bf3f9c8bb2c867fad027cb93677ac43c24fe", "best_bid":"0.61", "best_ask":"0.62"}], "timestamp":"1784449238269", "event_type":"price_change"}
{"market":"0xab772601f501b265bfe8982eb61d5347ef9945de314bfdf4ac0189c288ffb0b3", "price_changes":[{"asset_id":"17924629579804316786455515989238352689210911545477836576430679697715946894553", "price":"0.31", "size":"89.7", "side":"BUY", "hash":"acd4be0c0a479a3f465cf8ebc500f691ad846361", "best_bid":"0.61", "best_ask":"0.62"}, {"asset_id":"12935926064588426924078449947177910958215776269411501731627440228801766632772", "price":"0.69", "size":"89.7", "side":"SELL", "hash":"43f9774becd5c1cf5cd9048d590831c025b88b6b", "best_bid":"0.38", "best_ask":"0.39"}], "timestamp":"1784449238269", "event_type":"price_change"}
{"market":"0xab772601f501b265bfe8982eb61d5347ef9945de314bfdf4ac0189c288ffb0b3", "price_changes":[{"asset_id":"17924629579804316786455515989238352689210911545477836576430679697715946894553", "price":"0.52", "size":"220.91", "side":"BUY", "hash":"98d9d50e9b6f7f6acea2f2b2658a9a3d07663152", "best_bid":"0.61", "best_ask":"0.62"}, {"asset_id":"12935926064588426924078449947177910958215776269411501731627440228801766632772", "price":"0.48", "size":"220.91", "side":"SELL", "hash":"8d3af34a493812aa232711f63afb4f2ea98b220b", "best_bid":"0.38", "best_ask":"0.39"}], "timestamp":"1784449238270", "event_type":"price_change"}
{"market":"0xab772601f501b265bfe8982eb61d5347ef9945de314bfdf4ac0189c288ffb0b3", "price_changes":[{"asset_id":"17924629579804316786455515989238352689210911545477836576430679697715946894553", "price":"0.61", "size":"328.98", "side":"BUY", "hash":"c61de1d872403e95e38054fbdf94332cff629c27", "best_bid":"0.61", "best_ask":"0.62"}, {"asset_id":"12935926064588426924078449947177910958215776269411501731627440228801766632772", "price":"0.39", "size":"328.98", "side":"SELL", "hash":"f87231894cb0f3940d8bf075b0d6cc0389700515", "best_bid":"0.38", "best_ask":"0.39"}], "timestamp":"1784449238270", "event_type":"price_change"}
{"market":"0xab772601f501b265bfe8982eb61d5347ef9945de314bfdf4ac0189c288ffb0b3", "price_changes":[{"asset_id":"17924629579804316786455515989238352689210911545477836576430679697715946894553", "price":"0.54", "size":"123.85", "side":"BUY", "hash":"2cc76dcb8802ba35c3e0edd0f0ed7aa17e72f4dd", "best_bid":"0.61", "best_ask":"0.62"}, {"asset_id":"12935926064588426924078449947177910958215776269411501731627440228801766632772", "price":"0.46", "size":"123.85", "side":"SELL", "hash":"6f91b06a997c2cfff0f0ebd61b37ada245986a1d", "best_bid":"0.38", "best_ask":"0.39"}], "timestamp":"1784449238271", "event_type":"price_change"}
{"market":"0xab772601f501b265bfe8982eb61d5347ef9945de314bfdf4ac0189c288ffb0b3", "price_changes":[{"asset_id":"12935926064588426924078449947177910958215776269411501731627440228801766632772", "price":"0.34", "size":"107.96", "side":"BUY", "hash":"13e18d34c6c99759bfe791046629f893ae09dbd5", "best_bid":"0.38", "best_ask":"0.39"}, {"asset_id":"17924629579804316786455515989238352689210911545477836576430679697715946894553", "price":"0.66", "size":"107.96", "side":"SELL", "hash":"2d0c48f0fbecfa3cd9678bebbb3972646a91310e", "best_bid":"0.61", "best_ask":"0.62"}], "timestamp":"1784449238271", "event_type":"price_change"}
{"market":"0xab772601f501b265bfe8982eb61d5347ef9945de314bfdf4ac0189c288ffb0b3", "price_changes":[{"asset_id":"12935926064588426924078449947177910958215776269411501731627440228801766632772", "price":"0.37", "size":"150.91", "side":"BUY", "hash":"f1d2d85285d3f6c5b39d660737d03dad4192d759", "best_bid":"0.38", "best_ask":"0.39"}, {"asset_id":"17924629579804316786455515989238352689210911545477836576430679697715946894553", "price":"0.63", "size":"150.91", "side":"SELL", "hash":"d91e77b70f905c11afbcedc15ecad2603457c471", "best_bid":"0.61", "best_ask":"0.62"}], "timestamp":"1784449238273", "event_type":"price_change"}
{"market":"0xab772601f501b265bfe8982eb61d5347ef9945de314bfdf4ac0189c288ffb0b3", "price_changes":[{"asset_id":"17924629579804316786455515989238352689210911545477836576430679697715946894553", "price":"0.41", "size":"75.5", "side":"BUY", "hash":"229c9681915a0445e3b07152c3117faa356f483f", "best_bid":"0.61", "best_ask":"0.62"}, {"asset_id":"12935926064588426924078449947177910958215776269411501731627440228801766632772", "price":"0.59", "size":"75.5", "side":"SELL", "hash":"17ebaa9e4e782e75f9790a741bcadcc3df9d45be", "best_bid":"0.38", "best_ask":"0.39"}], "timestamp":"1784449238274", "event_type":"price_change"}
{"market":"0xab772601f501b265bfe8982eb61d5347ef9945de314bfdf4ac0189c288ffb0b3", "price_changes":[{"asset_id":"12935926064588426924078449947177910958215776269411501731627440228801766632772", "price":"0.3", "size":"203.04", "side":"BUY", "hash":"1bd031342ce2b8b89f49a732b7349b2bfd3325c3", "best_bid":"0.38", "best_ask":"0.39"}, {"asset_id":"17924629579804316786455515989238352689210911545477836576430679697715946894553", "price":"0.7", "size":"203.04", "side":"SELL", "hash":"098c150dbf5f8056c3a36c6a15ce9f55ec5c79b2", "best_bid":"0.61", "best_ask":"0.62"}], "timestamp":"1784449238274", "event_type":"price_change"}
{"market":"0xab772601f501b265bfe8982eb61d5347ef9945de314bfdf4ac0189c288ffb0b3", "price_changes":[{"asset_id":"17924629579804316786455515989238352689210911545477836576430679697715946894553", "price":"0.01", "size":"12974.51", "side":"BUY", "hash":"4aeea65fc9f9f8d12ccc0439ae6f7448473aa806", "best_bid":"0.61", "best_ask":"0.62"}, {"asset_id":"12935926064588426924078449947177910958215776269411501731627440228801766632772", "price":"0.99", "size":"12974.51", "side":"SELL", "hash":"038e10ba0eb5a6082707f86b1817fd003b915494", "best_bid":"0.38", "best_ask":"0.39"}], "timestamp":"1784449238275", "event_type":"price_change"}
{"market":"0xab772601f501b265bfe8982eb61d5347ef9945de314bfdf4ac0189c288ffb0b3", "price_changes":[{"asset_id":"12935926064588426924078449947177910958215776269411501731627440228801766632772", "price":"0.38", "size":"110.93", "side":"BUY", "hash":"9bb0052087117fe974e65cb9a9a3a6839599b879", "best_bid":"0.38", "best_ask":"0.39"}, {"asset_id":"17924629579804316786455515989238352689210911545477836576430679697715946894553", "price":"0.62", "size":"110.93", "side":"SELL", "hash":"22dd3681a387690ef8ef60d707f3d83b876722e0", "best_bid":"0.61", "best_ask":"0.62"}], "timestamp":"1784449238275", "event_type":"price_change"}
{"market":"0xab772601f501b265bfe8982eb61d5347ef9945de314bfdf4ac0189c288ffb0b3", "price_changes":[{"asset_id":"17924629579804316786455515989238352689210911545477836576430679697715946894553", "price":"0.53", "size":"467.7", "side":"BUY", "hash":"400a919b399b18494eabe89bb0435f1e7cd1002f", "best_bid":"0.61", "best_ask":"0.62"}, {"asset_id":"12935926064588426924078449947177910958215776269411501731627440228801766632772", "price":"0.47", "size":"467.7", "side":"SELL", "hash":"03ad533b37becb695e27a0aa55ea0d8c44dd1ded", "best_bid":"0.38", "best_ask":"0.39"}], "timestamp":"1784449238276", "event_type":"price_change"}
{"market":"0xab772601f501b265bfe8982eb61d5347ef9945de314bfdf4ac0189c288ffb0b3", "price_changes":[{"asset_id":"17924629579804316786455515989238352689210911545477836576430679697715946894553", "price":"0.52", "size":"245.91", "side":"BUY", "hash":"19b8fcafdbc10aadf9b0e221c19298056d8f4e8a", "best_bid":"0.61", "best_ask":"0.62"}, {"asset_id":"12935926064588426924078449947177910958215776269411501731627440228801766632772", "price":"0.48", "size":"245.91", "side":"SELL", "hash":"1b36b799db7b81c78e6eced4ee2e78c74a95a82a", "best_bid":"0.38", "best_ask":"0.39"}], "timestamp":"1784449238277", "event_type":"price_change"}
{"market":"0xab772601f501b265bfe8982eb61d5347ef9945de314bfdf4ac0189c288ffb0b3", "price_changes":[{"asset_id":"17924629579804316786455515989238352689210911545477836576430679697715946894553", "price":"0.51", "size":"431.92", "side":"BUY", "hash":"80843dddb6c58600fa8b5aa57879920969f072c0", "best_bid":"0.61", "best_ask":"0.62"}, {"asset_id":"12935926064588426924078449947177910958215776269411501731627440228801766632772", "price":"0.49", "size":"431.92", "side":"SELL", "hash":"4a984a64d883b1e1096dc5c045191c0cdde422b3", "best_bid":"0.38", "best_ask":"0.39"}], "timestamp":"1784449238288", "event_type":"price_change"}
{"market":"0xab772601f501b265bfe8982eb61d5347ef9945de314bfdf4ac0189c288ffb0b3", "price_changes":[{"asset_id":"17924629579804316786455515989238352689210911545477836576430679697715946894553", "price":"0.01", "size":"12969.5", "side":"BUY", "hash":"87326d5446633c37bb740af62866feda98d11569", "best_bid":"0.61", "best_ask":"0.62"}, {"asset_id":"12935926064588426924078449947177910958215776269411501731627440228801766632772", "price":"0.99", "size":"12969.5", "side":"SELL", "hash":"455b8858214d8d7334b9d3b785103c61dccd363d", "best_bid":"0.38", "best_ask":"0.39"}], "timestamp":"1784449238292", "event_type":"price_change"}
{"market":"0xab772601f501b265bfe8982eb61d5347ef9945de314bfdf4ac0189c288ffb0b3", "price_changes":[{"asset_id":"17924629579804316786455515989238352689210911545477836576430679697715946894553", "price":"0.01", "size":"12975.5", "side":"BUY", "hash":"94488bae017152dfa4315ea0a1539e2113958723", "best_bid":"0.61", "best_ask":"0.62"}, {"asset_id":"12935926064588426924078449947177910958215776269411501731627440228801766632772", "price":"0.99", "size":"12975.5", "side":"SELL", "hash":"9c1c4c602b46ed48d0308a3ab85d4bc2ee66e343", "best_bid":"0.38", "best_ask":"0.39"}], "timestamp":"1784449238298", "event_type":"price_change"}
{"market":"0xab772601f501b265bfe8982eb61d5347ef9945de314bfdf4ac0189c288ffb0b3", "price_changes":[{"asset_id":"17924629579804316786455515989238352689210911545477836576430679697715946894553", "price":"0.01", "size":"12970.5", "side":"BUY", "hash":"fb110f7365e4fabeeca66d5e70b6f556baa049a2", "best_bid":"0.61", "best_ask":"0.62"}, {"asset_id":"12935926064588426924078449947177910958215776269411501731627440228801766632772", "price":"0.99", "size":"12970.5", "side":"SELL", "hash":"15c3fcfe736a5945ed0cddb608426973d52b0440", "best_bid":"0.38", "best_ask":"0.39"}], "timestamp":"1784449238299", "event_type":"price_change"}
{"market":"0xab772601f501b265bfe8982eb61d5347ef9945de314bfdf4ac0189c288ffb0b3", "price_changes":[{"asset_id":"17924629579804316786455515989238352689210911545477836576430679697715946894553", "price":"0.01", "size":"13070.5", "side":"BUY", "hash":"9e470c3f9c657c693b8bb0b6ad1515db92e90b44", "best_bid":"0.61", "best_ask":"0.62"}, {"asset_id":"12935926064588426924078449947177910958215776269411501731627440228801766632772", "price":"0.99", "size":"13070.5", "side":"SELL", "hash":"94e5e7c7590cf54f4af18f7093cc0f355c2c9d52", "best_bid":"0.38", "best_ask":"0.39"}], "timestamp":"1784449238299", "event_type":"price_change"}
{"market":"0xab772601f501b265bfe8982eb61d5347ef9945de314bfdf4ac0189c288ffb0b3", "price_changes":[{"asset_id":"17924629579804316786455515989238352689210911545477836576430679697715946894553", "price":"0.61", "size":"320.9", "side":"BUY", "hash":"8a756c4a83b98cffd9f0a7b8f65b6700f77c8461", "best_bid":"0.61", "best_ask":"0.62"}, {"asset_id":"12935926064588426924078449947177910958215776269411501731627440228801766632772", "price":"0.39", "size":"320.9", "side":"SELL", "hash":"780cd5c541e7a6476e578fd797683f00e41b7680", "best_bid":"0.38", "best_ask":"0.39"}], "timestamp":"1784449238300", "event_type":"price_change"}
{"market":"0xab772601f501b265bfe8982eb61d5347ef9945de314bfdf4ac0189c288ffb0b3", "price_changes":[{"asset_id":"12935926064588426924078449947177910958215776269411501731627440228801766632772", "price":"0.39", "size":"316.32", "side":"SELL", "hash":"0d896dfdd5f478ff83833d917a1688b0c87302ce", "best_bid":"0.38", "best_ask":"0.39"}, {"asset_id":"17924629579804316786455515989238352689210911545477836576430679697715946894553", "price":"0.61", "size":"316.32", "side":"BUY", "hash":"09a4389fa147da62366248455ea97971e63eff5b", "best_bid":"0.61", "best_ask":"0.62"}], "timestamp":"1784449238301", "event_type":"price_change"}
{"market":"0xab772601f501b265bfe8982eb61d5347ef9945de314bfdf4ac0189c288ffb0b3", "price_changes":[{"asset_id":"17924629579804316786455515989238352689210911545477836576430679697715946894553", "price":"0.61", "size":"308.01", "side":"BUY", "hash":"9361bfbd6ba875f45646880ad63d7f8f146fe492", "best_bid":"0.61", "best_ask":"0.62"}, {"asset_id":"12935926064588426924078449947177910958215776269411501731627440228801766632772", "price":"0.39", "size":"308.01", "side":"SELL", "hash":"df2174ef921af10602ea50ecdd11387c0ca062c9", "best_bid":"0.38", "best_ask":"0.39"}], "timestamp":"1784449238302", "event_type":"price_change"}
{"market":"0xab772601f501b265bfe8982eb61d5347ef9945de314bfdf4ac0189c288ffb0b3", "price_changes":[{"asset_id":"12935926064588426924078449947177910958215776269411501731627440228801766632772", "price":"0.38", "size":"115.93", "side":"BUY", "hash":"93ddd95a09d94872287cdb0cd03a1def9ee97a4a", "best_bid":"0.38", "best_ask":"0.39"}, {"asset_id":"17924629579804316786455515989238352689210911545477836576430679697715946894553", "price":"0.62", "size":"115.93", "side":"SELL", "hash":"3be8ea38d4dbc2e71b24a38a33a97532548458ac", "best_bid":"0.61", "best_ask":"0.62"}], "timestamp":"1784449238302", "event_type":"price_change"}
{"market":"0xab772601f501b265bfe8982eb61d5347ef9945de314bfdf4ac0189c288ffb0b3", "price_changes":[{"asset_id":"12935926064588426924078449947177910958215776269411501731627440228801766632772", "price":"0.34", "size":"125.76", "side":"BUY", "hash":"fa19eff390c14e7a7ff3983abc66ac708292c287", "best_bid":"0.38", "best_ask":"0.39"}, {"asset_id":"17924629579804316786455515989238352689210911545477836576430679697715946894553", "price":"0.66", "size":"125.76", "side":"SELL", "hash":"9cac150afd40189fa180673f088a2ccc9ec8ca35", "best_bid":"0.61", "best_ask":"0.62"}], "timestamp":"1784449238303", "event_type":"price_change"}
{"market":"0xab772601f501b265bfe8982eb61d5347ef9945de314bfdf4ac0189c288ffb0b3", "price_changes":[{"asset_id":"17924629579804316786455515989238352689210911545477836576430679697715946894553", "price":"0.03", "size":"2255.95", "side":"BUY", "hash":"bdfd29af6c87d2dfac2df9a164c905f0cfc3ec47", "best_bid":"0.61", "best_ask":"0.62"}, {"asset_id":"12935926064588426924078449947177910958215776269411501731627440228801766632772", "price":"0.97", "size":"2255.95", "side":"SELL", "hash":"13d19507066708abdc1ce1d32987df1e6fe5b1db", "best_bid":"0.38", "best_ask":"0.39"}], "timestamp":"1784449238304", "event_type":"price_change"}
{"market":"0xab772601f501b265bfe8982eb61d5347ef9945de314bfdf4ac0189c288ffb0b3", "price_changes":[{"asset_id":"17924629579804316786455515989238352689210911545477836576430679697715946894553", "price":"0.58", "size":"171.82", "side":"BUY", "hash":"04964ff7cf6de5e98f4ca0e27246fa3e8a93dff1", "best_bid":"0.61", "best_ask":"0.62"}, {"asset_id":"12935926064588426924078449947177910958215776269411501731627440228801766632772", "price":"0.42", "size":"171.82", "side":"SELL", "hash":"24313839c5448756e71ae452aab9865f090b1e06", "best_bid":"0.38", "best_ask":"0.39"}], "timestamp":"1784449238304", "event_type":"price_change"}
{"market":"0xab772601f501b265bfe8982eb61d5347ef9945de314bfdf4ac0189c288ffb0b3", "price_changes":[{"asset_id":"17924629579804316786455515989238352689210911545477836576430679697715946894553", "price":"0.61", "size":"294.13", "side":"BUY", "hash":"f45066a855f6f54922f8a2fac24e9e416cbe5385", "best_bid":"0.61", "best_ask":"0.62"}, {"asset_id":"12935926064588426924078449947177910958215776269411501731627440228801766632772", "price":"0.39", "size":"294.13", "side":"SELL", "hash":"e0fc8a453bf95c6cee7c60d4ed35f020a760056f", "best_bid":"0.38", "best_ask":"0.39"}], "timestamp":"1784449238304", "event_type":"price_change"}
{"market":"0xab772601f501b265bfe8982eb61d5347ef9945de314bfdf4ac0189c288ffb0b3", "price_changes":[{"asset_id":"17924629579804316786455515989238352689210911545477836576430679697715946894553", "price":"0.61", "size":"289.13", "side":"BUY", "hash":"27b4dfd4a41a505f0f2e59bac2a462c7a1f796e8", "best_bid":"0.61", "best_ask":"0.62"}, {"asset_id":"12935926064588426924078449947177910958215776269411501731627440228801766632772", "price":"0.39", "size":"289.13", "side":"SELL", "hash":"2add2305d7a4691666af60b8d2105e03552d83ff", "best_bid":"0.38", "best_ask":"0.39"}], "timestamp":"1784449238305", "event_type":"price_change"}
{"market":"0xab772601f501b265bfe8982eb61d5347ef9945de314bfdf4ac0189c288ffb0b3", "price_changes":[{"asset_id":"17924629579804316786455515989238352689210911545477836576430679697715946894553", "price":"0.51", "size":"415.92", "side":"BUY", "hash":"0a94c24f823132407b56f2729c13129697e19f6b", "best_bid":"0.61", "best_ask":"0.62"}, {"asset_id":"12935926064588426924078449947177910958215776269411501731627440228801766632772", "price":"0.49", "size":"415.92", "side":"SELL", "hash":"ab80bb646360a24146c597d84fb31cb81c66d7c1", "best_bid":"0.38", "best_ask":"0.39"}], "timestamp":"1784449238311", "event_type":"price_change"}
{"market":"0xab772601f501b265bfe8982eb61d5347ef9945de314bfdf4ac0189c288ffb0b3", "price_changes":[{"asset_id":"17924629579804316786455515989238352689210911545477836576430679697715946894553", "price":"0.61", "size":"279.74", "side":"BUY", "hash":"f74f6795d804a40f8f9d4efe918ae5854d93be15", "best_bid":"0.61", "best_ask":"0.62"}, {"asset_id":"12935926064588426924078449947177910958215776269411501731627440228801766632772", "price":"0.39", "size":"279.74", "side":"SELL", "hash":"1ff50265b2f190d1a40f21709464ebe11ce6ac3f", "best_bid":"0.38", "best_ask":"0.39"}], "timestamp":"1784449238313", "event_type":"price_change"}
{"market":"0xab772601f501b265bfe8982eb61d5347ef9945de314bfdf4ac0189c288ffb0b3", "price_changes":[{"asset_id":"12935926064588426924078449947177910958215776269411501731627440228801766632772", "price":"0.38", "size":"368.28", "side":"BUY", "hash":"8c00f6d9215b8e69943fb2babd86902cd50ca271", "best_bid":"0.38", "best_ask":"0.39"}, {"asset_id":"17924629579804316786455515989238352689210911545477836576430679697715946894553", "price":"0.62", "size":"368.28", "side":"SELL", "hash":"baeaa12de8df733314d5236f4554d5571987560b", "best_bid":"0.61", "best_ask":"0.62"}], "timestamp":"1784449238320", "event_type":"price_change"}
{"market":"0xab772601f501b265bfe8982eb61d5347ef9945de314bfdf4ac0189c288ffb0b3", "price_changes":[{"asset_id":"17924629579804316786455515989238352689210911545477836576430679697715946894553", "price":"0.61", "size":"267.74", "side":"BUY", "hash":"2cc6e844fcf8fb93fdaf6ebbcb16835b11749a01", "best_bid":"0.61", "best_ask":"0.62"}, {"asset_id":"12935926064588426924078449947177910958215776269411501731627440228801766632772", "price":"0.39", "size":"267.74", "side":"SELL", "hash":"5ea9a9e3854d3198f81348a3881022a3914123f6", "best_bid":"0.38", "best_ask":"0.39"}], "timestamp":"1784449238322", "event_type":"price_change"}
{"market":"0xab772601f501b265bfe8982eb61d5347ef9945de314bfdf4ac0189c288ffb0b3", "price_changes":[{"asset_id":"17924629579804316786455515989238352689210911545477836576430679697715946894553", "price":"0.61", "size":"37", "side":"BUY", "hash":"fe9c608b7256286cf771cf868a8ebf5a1dae09ea", "best_bid":"0.61", "best_ask":"0.62"}, {"asset_id":"12935926064588426924078449947177910958215776269411501731627440228801766632772", "price":"0.39", "size":"37", "side":"SELL", "hash":"5c01c9dd2e61eb389f1e9a998078852c8e283897", "best_bid":"0.38", "best_ask":"0.39"}], "timestamp":"1784449238322", "event_type":"price_change"}
{"market":"0xab772601f501b265bfe8982eb61d5347ef9945de314bfdf4ac0189c288ffb0b3", "price_changes":[{"asset_id":"17924629579804316786455515989238352689210911545477836576430679697715946894553", "price":"0.5", "size":"97", "side":"BUY", "hash":"4e1756a0d2ae54d255ebbabb55d3012c35019577", "best_bid":"0.61", "best_ask":"0.62"}, {"asset_id":"12935926064588426924078449947177910958215776269411501731627440228801766632772", "price":"0.5", "size":"97", "side":"SELL", "hash":"fbde968ce8eb525ddc03d2978d04f652c0625066", "best_bid":"0.38", "best_ask":"0.39"}], "timestamp":"1784449238328", "event_type":"price_change"}
{"market":"0xab772601f501b265bfe8982eb61d5347ef9945de314bfdf4ac0189c288ffb0b3", "price_changes":[{"asset_id":"17924629579804316786455515989238352689210911545477836576430679697715946894553", "price":"0.01", "size":"13064.5", "side":"BUY", "hash":"47f08cc4fac29c41143f7ae1b0d25cecd34f5566", "best_bid":"0.61", "best_ask":"0.62"}, {"asset_id":"12935926064588426924078449947177910958215776269411501731627440228801766632772", "price":"0.99", "size":"13064.5", "side":"SELL", "hash":"a18c2611a3f316c0be9bce9cc54780a4b46c0080", "best_bid":"0.38", "best_ask":"0.39"}], "timestamp":"1784449238331", "event_type":"price_change"}
{"market":"0xab772601f501b265bfe8982eb61d5347ef9945de314bfdf4ac0189c288ffb0b3", "price_changes":[{"asset_id":"17924629579804316786455515989238352689210911545477836576430679697715946894553", "price":"0.01", "size":"12964.5", "side":"BUY", "hash":"56644130fa49b51a54b1fd541c350ef25f4b9f17", "best_bid":"0.61", "best_ask":"0.62"}, {"asset_id":"12935926064588426924078449947177910958215776269411501731627440228801766632772", "price":"0.99", "size":"12964.5", "side":"SELL", "hash":"cede9c2c3bb006b606d5779959da3af48e745597", "best_bid":"0.38", "best_ask":"0.39"}], "timestamp":"1784449238333", "event_type":"price_change"}
{"market":"0xab772601f501b265bfe8982eb61d5347ef9945de314bfdf4ac0189c288ffb0b3", "price_changes":[{"asset_id":"12935926064588426924078449947177910958215776269411501731627440228801766632772", "price":"0.38", "size":"375.99", "side":"BUY", "hash":"7b27261f410a4e4e2ba3e03c4f9337a784e5e75f", "best_bid":"0.38", "best_ask":"0.39"}, {"asset_id":"17924629579804316786455515989238352689210911545477836576430679697715946894553", "price":"0.62", "size":"375.99", "side":"SELL", "hash":"0546562b8519fbc80af6b0b55f4a640e9b6e2936", "best_bid":"0.61", "best_ask":"0.62"}], "timestamp":"1784449238333", "event_type":"price_change"}
{"market":"0xab772601f501b265bfe8982eb61d5347ef9945de314bfdf4ac0189c288ffb0b3", "price_changes":[{"asset_id":"12935926064588426924078449947177910958215776269411501731627440228801766632772", "price":"0.01", "size":"14889.14", "side":"BUY", "hash":"02d629a564b8ed576373a5c73b1b03946bdd506d", "best_bid":"0.38", "best_ask":"0.39"}, {"asset_id":"17924629579804316786455515989238352689210911545477836576430679697715946894553", "price":"0.99", "size":"14889.14", "side":"SELL", "hash":"da76bc74a7d5480d9c5c73b80c3ea0df5a0b4048", "best_bid":"0.61", "best_ask":"0.62"}], "timestamp":"1784449238339", "event_type":"price_change"}
{"market":"0xab772601f501b265bfe8982eb61d5347ef9945de314bfdf4ac0189c288ffb0b3", "price_changes":[{"asset_id":"17924629579804316786455515989238352689210911545477836576430679697715946894553", "price":"0.25", "size":"92.2", "side":"BUY", "hash":"a7cc92faa7667607cb3ef25377ab59f123b455f2", "best_bid":"0.61", "best_ask":"0.62"}, {"asset_id":"12935926064588426924078449947177910958215776269411501731627440228801766632772", "price":"0.75", "size":"92.2", "side":"SELL", "hash":"7849e2ec24084f030ff3c03d6cdc86302643ee40", "best_bid":"0.38", "best_ask":"0.39"}], "timestamp":"1784449238340", "event_type":"price_change"}
{"market":"0xab772601f501b265bfe8982eb61d5347ef9945de314bfdf4ac0189c288ffb0b3", "price_changes":[{"asset_id":"17924629579804316786455515989238352689210911545477836576430679697715946894553", "price":"0.59", "size":"255.34", "side":"BUY", "hash":"e06386feca1a2e8be6a2f917a695f590daf9d12e", "best_bid":"0.61", "best_ask":"0.62"}, {"asset_id":"12935926064588426924078449947177910958215776269411501731627440228801766632772", "price":"0.41", "size":"255.34", "side":"SELL", "hash":"17d2254a59400c45e3b4244619e56ad627d7aadf", "best_bid":"0.38", "best_ask":"0.39"}], "timestamp":"1784449238340", "event_type":"price_change"}
{"market":"0xab772601f501b265bfe8982eb61d5347ef9945de314bfdf4ac0189c288ffb0b3", "price_changes":[{"asset_id":"17924629579804316786455515989238352689210911545477836576430679697715946894553", "price":"0.59", "size":"250.34", "side":"BUY", "hash":"0f637d2a48a88a080e8cb68c17bf1cb65e985cdd", "best_bid":"0.61", "best_ask":"0.62"}, {"asset_id":"12935926064588426924078449947177910958215776269411501731627440228801766632772", "price":"0.41", "size":"250.34", "side":"SELL", "hash":"c4b254e2928eb3ea0087588f51fe40d2a3d7c435", "best_bid":"0.38", "best_ask":"0.39"}], "timestamp":"1784449238340", "event_type":"price_change"}
{"market":"0xab772601f501b265bfe8982eb61d5347ef9945de314bfdf4ac0189c288ffb0b3", "price_changes":[{"asset_id":"12935926064588426924078449947177910958215776269411501731627440228801766632772", "price":"0.31", "size":"555.01", "side":"BUY", "hash":"0ad16124227b96362ff4606379dbfb7f441704be", "best_bid":"0.38", "best_ask":"0.39"}, {"asset_id":"17924629579804316786455515989238352689210911545477836576430679697715946894553", "price":"0.69", "size":"555.01", "side":"SELL", "hash":"af7b1fe0b67bd3924a7714963747c95b917edd68", "best_bid":"0.61", "best_ask":"0.62"}], "timestamp":"1784449238341", "event_type":"price_change"}
{"market":"0xab772601f501b265bfe8982eb61d5347ef9945de314bfdf4ac0189c288ffb0b3", "price_changes":[{"asset_id":"12935926064588426924078449947177910958215776269411501731627440228801766632772", "price":"0.36", "size":"226.77", "side":"BUY", "hash":"2bfdee515c0197049299d9c4e25c7f781d9be54f", "best_bid":"0.38", "best_ask":"0.39"}, {"asset_id":"17924629579804316786455515989238352689210911545477836576430679697715946894553", "price":"0.64", "size":"226.77", "side":"SELL", "hash":"1ac56f60dd263861b479de46210e93647024cdd7", "best_bid":"0.61", "best_ask":"0.62"}], "timestamp":"1784449238343", "event_type":"price_change"}
{"market":"0xab772601f501b265bfe8982eb61d5347ef9945de314bfdf4ac0189c288ffb0b3", "price_changes":[{"asset_id":"12935926064588426924078449947177910958215776269411501731627440228801766632772", "price":"0.3", "size":"197.81", "side":"BUY", "hash":"f251d91ad1aa49f0448066f046ed86ab36b13eec", "best_bid":"0.38", "best_ask":"0.39"}, {"asset_id":"17924629579804316786455515989238352689210911545477836576430679697715946894553", "price":"0.7", "size":"197.81", "side":"SELL", "hash":"1006fa757aea58aa0e043b34883e21feb99e38ef", "best_bid":"0.61", "best_ask":"0.62"}], "timestamp":"1784449238344", "event_type":"price_change"}
{"market":"0xab772601f501b265bfe8982eb61d5347ef9945de314bfdf4ac0189c288ffb0b3", "price_changes":[{"asset_id":"12935926064588426924078449947177910958215776269411501731627440228801766632772", "price":"0.22", "size":"145.5", "side":"BUY", "hash":"cfc538abf48623a4bbd05ff40c2512a316063bcb", "best_bid":"0.38", "best_ask":"0.39"}, {"asset_id":"17924629579804316786455515989238352689210911545477836576430679697715946894553", "price":"0.78", "size":"145.5", "side":"SELL", "hash":"52771a800927c33135800239ef8a24766477d019", "best_bid":"0.61", "best_ask":"0.62"}], "timestamp":"1784449238345", "event_type":"price_change"}
{"market":"0xab772601f501b265bfe8982eb61d5347ef9945de314bfdf4ac0189c288ffb0b3", "price_changes":[{"asset_id":"12935926064588426924078449947177910958215776269411501731627440228801766632772", "price":"0.38", "size":"384.01", "side":"BUY", "hash":"78faf7d9c6e181909565e6f5f67715303b503df9", "best_bid":"0.38", "best_ask":"0.39"}, {"asset_id":"17924629579804316786455515989238352689210911545477836576430679697715946894553", "price":"0.62", "size":"384.01", "side":"SELL", "hash":"41f943d856d49ccef508587eee1d538f9ef9c14d", "best_bid":"0.61", "best_ask":"0.62"}], "timestamp":"1784449238346", "event_type":"price_change"}
{"market":"0xab772601f501b265bfe8982eb61d5347ef9945de314bfdf4ac0189c288ffb0b3", "price_changes":[{"asset_id":"17924629579804316786455515989238352689210911545477836576430679697715946894553", "price":"0.52", "size":"220.91", "side":"BUY", "hash":"71130c56a655cb09bb6e66ed750181b133b97b99", "best_bid":"0.61", "best_ask":"0.62"}, {"asset_id":"12935926064588426924078449947177910958215776269411501731627440228801766632772", "price":"0.48", "size":"220.91", "side":"SELL", "hash":"a524968aac2227678bf25457fad768ae7697c97b", "best_bid":"0.38", "best_ask":"0.39"}], "timestamp":"1784449238346", "event_type":"price_change"}
{"market":"0xab772601f501b265bfe8982eb61d5347ef9945de314bfdf4ac0189c288ffb0b3", "price_changes":[{"asset_id":"12935926064588426924078449947177910958215776269411501731627440228801766632772", "price":"0.37", "size":"155.91", "side":"BUY", "hash":"fc8e70a98f2c38640b99ba0c319712405d9e6ab7", "best_bid":"0.38", "best_ask":"0.39"}, {"asset_id":"17924629579804316786455515989238352689210911545477836576430679697715946894553", "price":"0.63", "size":"155.91", "side":"SELL", "hash":"5565b201462ffdb4948b26f385dd538cecdd0507", "best_bid":"0.61", "best_ask":"0.62"}], "timestamp":"1784449238347", "event_type":"price_change"}
{"market":"0xab772601f501b265bfe8982eb61d5347ef9945de314bfdf4ac0189c288ffb0b3", "price_changes":[{"asset_id":"17924629579804316786455515989238352689210911545477836576430679697715946894553", "price":"0.5", "size":"125.8", "side":"BUY", "hash":"5ec839f1450c02826d09ecdb32a1fe91251be749", "best_bid":"0.61", "best_ask":"0.62"}, {"asset_id":"12935926064588426924078449947177910958215776269411501731627440228801766632772", "price":"0.5", "size":"125.8", "side":"SELL", "hash":"896cf3f2e89d856cf8f6141a2684025918b9efa8", "best_bid":"0.38", "best_ask":"0.39"}], "timestamp":"1784449238347", "event_type":"price_change"}
{"market":"0xab772601f501b265bfe8982eb61d5347ef9945de314bfdf4ac0189c288ffb0b3", "price_changes":[{"asset_id":"17924629579804316786455515989238352689210911545477836576430679697715946894553", "price":"0.6", "size":"76.7", "side":"BUY", "hash":"4ad314fecd1fed4e3fc28774270d7c95f1f303f9", "best_bid":"0.61", "best_ask":"0.62"}, {"asset_id":"12935926064588426924078449947177910958215776269411501731627440228801766632772", "price":"0.4", "size":"76.7", "side":"SELL", "hash":"1bf190bd40df3b7bb26fdd918bbdb2fc52dc1a44", "best_bid":"0.38", "best_ask":"0.39"}], "timestamp":"1784449238348", "event_type":"price_change"}
{"market":"0xab772601f501b265bfe8982eb61d5347ef9945de314bfdf4ac0189c288ffb0b3", "price_changes":[{"asset_id":"12935926064588426924078449947177910958215776269411501731627440228801766632772", "price":"0.37", "size":"160.97", "side":"BUY", "hash":"2a27a1561a73d46ee395124e6ec51e9fcd5962e8", "best_bid":"0.38", "best_ask":"0.39"}, {"asset_id":"17924629579804316786455515989238352689210911545477836576430679697715946894553", "price":"0.63", "size":"160.97", "side":"SELL", "hash":"6f304f98cc625332124114911f6dfbd7240b983f", "best_bid":"0.61", "best_ask":"0.62"}], "timestamp":"1784449238348", "event_type":"price_change"}
{"market":"0xab772601f501b265bfe8982eb61d5347ef9945de314bfdf4ac0189c288ffb0b3", "price_changes":[{"asset_id":"17924629579804316786455515989238352689210911545477836576430679697715946894553", "price":"0.59", "size":"245.34", "side":"BUY", "hash":"1a59abf148b9b9f2ab42b207d6e59d219b2f8a29", "best_bid":"0.61", "best_ask":"0.62"}, {"asset_id":"12935926064588426924078449947177910958215776269411501731627440228801766632772", "price":"0.41", "size":"245.34", "side":"SELL", "hash":"b37d049fef149c4b4435303ffee7cff764d4a01a", "best_bid":"0.38", "best_ask":"0.39"}], "timestamp":"1784449238352", "event_type":"price_change"}
{"market":"0xab772601f501b265bfe8982eb61d5347ef9945de314bfdf4ac0189c288ffb0b3", "price_changes":[{"asset_id":"12935926064588426924078449947177910958215776269411501731627440228801766632772", "price":"0.35", "size":"106.2", "side":"BUY", "hash":"7acbbbbd81f1dedd86674acf9f1490446bacdec5", "best_bid":"0.38", "best_ask":"0.39"}, {"asset_id":"17924629579804316786455515989238352689210911545477836576430679697715946894553", "price":"0.65", "size":"106.2", "side":"SELL", "hash":"17a5d703b82bd532ac53c2214178147a2a3d4e77", "best_bid":"0.61", "best_ask":"0.62"}], "timestamp":"1784449238354", "event_type":"price_change"}
{"market":"0xab772601f501b265bfe8982eb61d5347ef9945de314bfdf4ac0189c288ffb0b3", "price_changes":[{"asset_id":"17924629579804316786455515989238352689210911545477836576430679697715946894553", "price":"0.59", "size":"240.34", "side":"BUY", "hash":"d2364e7d4b7268e9b367a3b6379515083a04c7fc", "best_bid":"0.61", "best_ask":"0.62"}, {"asset_id":"12935926064588426924078449947177910958215776269411501731627440228801766632772", "price":"0.41", "size":"240.34", "side":"SELL", "hash":"efa071e0426a0d26f476d59cd5edd6f52acc4379", "best_bid":"0.38", "best_ask":"0.39"}], "timestamp":"1784449238355", "event_type":"price_change"}
{"market":"0xab772601f501b265bfe8982eb61d5347ef9945de314bfdf4ac0189c288ffb0b3", "price_changes":[{"asset_id":"17924629579804316786455515989238352689210911545477836576430679697715946894553", "price":"0.03", "size":"2250.95", "side":"BUY", "hash":"a4b0b2eeb6faa49842414a5907d55e43ca0f8447", "best_bid":"0.61", "best_ask":"0.62"}, {"asset_id":"12935926064588426924078449947177910958215776269411501731627440228801766632772", "price":"0.97", "size":"2250.95", "side":"SELL", "hash":"4c460d0a5fb7a344373ea021d3ae24649433111e", "best_bid":"0.38", "best_ask":"0.39"}], "timestamp":"1784449238357", "event_type":"price_change"}
{"market":"0xab772601f501b265bfe8982eb61d5347ef9945de314bfdf4ac0189c288ffb0b3", "price_changes":[{"asset_id":"12935926064588426924078449947177910958215776269411501731627440228801766632772", "price":"0.36", "size":"206.77", "side":"BUY", "hash":"3f1745959e1e279f717bd923fcd648885b39c6b3", "best_bid":"0.38", "best_ask":"0.39"}, {"asset_id":"17924629579804316786455515989238352689210911545477836576430679697715946894553", "price":"0.64", "size":"206.77", "side":"SELL", "hash":"1ac36973b3287e303c328a305daf2dbf36516d5e", "best_bid":"0.61", "best_ask":"0.62"}], "timestamp":"1784449238362", "event_type":"price_change"}
{"market":"0xab772601f501b265bfe8982eb61d5347ef9945de314bfdf4ac0189c288ffb0b3", "price_changes":[{"asset_id":"17924629579804316786455515989238352689210911545477836576430679697715946894553", "price":"0.59", "size":"220.34", "side":"BUY", "hash":"fe1840e653243cf7fe48993bf3088e400b9d52dc", "best_bid":"0.61", "best_ask":"0.62"}, {"asset_id":"12935926064588426924078449947177910958215776269411501731627440228801766632772", "price":"0.41", "size":"220.34", "side":"SELL", "hash":"7d3d792e72a59bb879029afd2827a47e05de445e", "best_bid":"0.38", "best_ask":"0.39"}], "timestamp":"1784449238366", "event_type":"price_change"}
{"market":"0xab772601f501b265bfe8982eb61d5347ef9945de314bfdf4ac0189c288ffb0b3", "price_changes":[{"asset_id":"17924629579804316786455515989238352689210911545477836576430679697715946894553", "price":"0.58", "size":"151.82", "side":"BUY", "hash":"4dd242966e1a338557e00b73efaf389309a54102", "best_bid":"0.61", "best_ask":"0.62"}, {"asset_id":"12935926064588426924078449947177910958215776269411501731627440228801766632772", "price":"0.42", "size":"151.82", "side":"SELL", "hash":"700ff447929631173690c19a51065adefd240dcb", "best_bid":"0.38", "best_ask":"0.39"}], "timestamp":"1784449238368", "event_type":"price_change"}
{"market":"0xab772601f501b265bfe8982eb61d5347ef9945de314bfdf4ac0189c288ffb0b3", "price_changes":[{"asset_id":"17924629579804316786455515989238352689210911545477836576430679697715946894553", "price":"0.6", "size":"56.7", "side":"BUY", "hash":"00d8f44292a8a07f642c541d35541add26e77dee", "best_bid":"0.61", "best_ask":"0.62"}, {"asset_id":"12935926064588426924078449947177910958215776269411501731627440228801766632772", "price":"0.4", "size":"56.7", "side":"SELL", "hash":"6749bff663629c27105080551c3fad5dfc9e0690", "best_bid":"0.38", "best_ask":"0.39"}], "timestamp":"1784449238368", "event_type":"price_change"}
{"market":"0xab772601f501b265bfe8982eb61d5347ef9945de314bfdf4ac0189c288ffb0b3", "price_changes":[{"asset_id":"12935926064588426924078449947177910958215776269411501731627440228801766632772", "price":"0.01", "size":"14884.14", "side":"BUY", "hash":"5628649d041f495b09f3752c604786ae4e520b0f", "best_bid":"0.38", "best_ask":"0.39"}, {"asset_id":"17924629579804316786455515989238352689210911545477836576430679697715946894553", "price":"0.99", "size":"14884.14", "side":"SELL", "hash":"81efe434841a51a465df37907089becd986f7291", "best_bid":"0.61", "best_ask":"0.62"}], "timestamp":"1784449238371", "event_type":"price_change"}
{"market":"0xab772601f501b265bfe8982eb61d5347ef9945de314bfdf4ac0189c288ffb0b3", "price_changes":[{"asset_id":"17924629579804316786455515989238352689210911545477836576430679697715946894553", "price":"0.61", "size":"32", "side":"BUY", "hash":"4503a7a3e35d79d9b6842d197c918e6b7cfd3df7", "best_bid":"0.61", "best_ask":"0.62"}, {"asset_id":"12935926064588426924078449947177910958215776269411501731627440228801766632772", "price":"0.39", "size":"32", "side":"SELL", "hash":"6389810de8a0519fb8b5020bb003bd4c2eef8996", "best_bid":"0.38", "best_ask":"0.39"}], "timestamp":"1784449238371", "event_type":"price_change"}
{"market":"0xab772601f501b265bfe8982eb61d5347ef9945de314bfdf4ac0189c288ffb0b3", "price_changes":[{"asset_id":"17924629579804316786455515989238352689210911545477836576430679697715946894553", "price":"0.52", "size":"245.91", "side":"BUY", "hash":"a27e0a4c62dad93e52c431dd661719433e3d59cf", "best_bid":"0.61", "best_ask":"0.62"}, {"asset_id":"12935926064588426924078449947177910958215776269411501731627440228801766632772", "price":"0.48", "size":"245.91", "side":"SELL", "hash":"634f8b380b29744d1b40ff05c33a2dcb9ff62d33", "best_bid":"0.38", "best_ask":"0.39"}], "timestamp":"1784449238372", "event_type":"price_change"}
{"market":"0xab772601f501b265bfe8982eb61d5347ef9945de314bfdf4ac0189c288ffb0b3", "price_changes":[{"asset_id":"17924629579804316786455515989238352689210911545477836576430679697715946894553", "price":"0.6", "size":"61.7", "side":"BUY", "hash":"618ceec822c24dd4d8583c1683b7ba6cb59e2a30", "best_bid":"0.61", "best_ask":"0.62"}, {"asset_id":"12935926064588426924078449947177910958215776269411501731627440228801766632772", "price":"0.4", "size":"61.7", "side":"SELL", "hash":"74fc4fc396d810e51c25d820cec1e8bc038ce6e0", "best_bid":"0.38", "best_ask":"0.39"}], "timestamp":"1784449238374", "event_type":"price_change"}
{"market":"0xab772601f501b265bfe8982eb61d5347ef9945de314bfdf4ac0189c288ffb0b3", "price_changes":[{"asset_id":"17924629579804316786455515989238352689210911545477836576430679697715946894553", "price":"0.59", "size":"225.34", "side":"BUY", "hash":"95a7488ae7ac84beff1daaaec04ab7fb2d282353", "best_bid":"0.61", "best_ask":"0.62"}, {"asset_id":"12935926064588426924078449947177910958215776269411501731627440228801766632772", "price":"0.41", "size":"225.34", "side":"SELL", "hash":"904b2597138da84904bd1747ec64cc9545462fae", "best_bid":"0.38", "best_ask":"0.39"}], "timestamp":"1784449238374", "event_type":"price_change"}
{"market":"0xab772601f501b265bfe8982eb61d5347ef9945de314bfdf4ac0189c288ffb0b3", "price_changes":[{"asset_id":"17924629579804316786455515989238352689210911545477836576430679697715946894553", "price":"0.58", "size":"156.82", "side":"BUY", "hash":"883252614fb2c320c9df38b534bd95e511ac8921", "best_bid":"0.61", "best_ask":"0.62"}, {"asset_id":"12935926064588426924078449947177910958215776269411501731627440228801766632772", "price":"0.42", "size":"156.82", "side":"SELL", "hash":"10156fa45c379cf19428ce2f5c1a4d3a605857f6", "best_bid":"0.38", "best_ask":"0.39"}], "timestamp":"1784449238375", "event_type":"price_change"}
{"market":"0xab772601f501b265bfe8982eb61d5347ef9945de314bfdf4ac0189c288ffb0b3", "price_changes":[{"asset_id":"12935926064588426924078449947177910958215776269411501731627440228801766632772", "price":"0.31", "size":"550.01", "side":"BUY", "hash":"d524b2bbd9f675c5043a1a33329dd8eecb9e5a04", "best_bid":"0.38", "best_ask":"0.39"}, {"asset_id":"17924629579804316786455515989238352689210911545477836576430679697715946894553", "price":"0.69", "size":"550.01", "side":"SELL", "hash":"caa0ea2dfae80bffab2c64e9e92085fd3b2e416b", "best_bid":"0.61", "best_ask":"0.62"}], "timestamp":"1784449238375", "event_type":"price_change"}
{"market":"0xab772601f501b265bfe8982eb61d5347ef9945de314bfdf4ac0189c288ffb0b3", "price_changes":[{"asset_id":"17924629579804316786455515989238352689210911545477836576430679697715946894553", "price":"0.61", "size":"27", "side":"BUY", "hash":"652b5a90f295a080faad458a8440f48c56f98d93", "best_bid":"0.61", "best_ask":"0.62"}, {"asset_id":"12935926064588426924078449947177910958215776269411501731627440228801766632772", "price":"0.39", "size":"27", "side":"SELL", "hash":"f1dca8015b5567081f9aebbf4facad1060b565a4", "best_bid":"0.38", "best_ask":"0.39"}], "timestamp":"1784449238380", "event_type":"price_change"}
{"market":"0xab772601f501b265bfe8982eb61d5347ef9945de314bfdf4ac0189c288ffb0b3", "price_changes":[{"asset_id":"17924629579804316786455515989238352689210911545477836576430679697715946894553", "price":"0.01", "size":"13064.5", "side":"BUY", "hash":"e1c4d813affa644732612cb3f2f6e84fc317f014", "best_bid":"0.61", "best_ask":"0.62"}, {"asset_id":"12935926064588426924078449947177910958215776269411501731627440228801766632772", "price":"0.99", "size":"13064.5", "side":"SELL", "hash":"34d478052116070277417c3ba5db949ebed285c3", "best_bid":"0.38", "best_ask":"0.39"}], "timestamp":"1784449238381", "event_type":"price_change"}
{"market":"0xab772601f501b265bfe8982eb61d5347ef9945de314bfdf4ac0189c288ffb0b3", "price_changes":[{"asset_id":"17924629579804316786455515989238352689210911545477836576430679697715946894553", "price":"0.01", "size":"13059.5", "side":"BUY", "hash":"3db57c558ac9592b93ab675507f7a983ba4ba5fd", "best_bid":"0.61", "best_ask":"0.62"}, {"asset_id":"12935926064588426924078449947177910958215776269411501731627440228801766632772", "price":"0.99", "size":"13059.5", "side":"SELL", "hash":"5139b9306b036fb1ba132e525f50c5c12f0ab23f", "best_bid":"0.38", "best_ask":"0.39"}], "timestamp":"1784449238404", "event_type":"price_change"}
{"market":"0xab772601f501b265bfe8982eb61d5347ef9945de314bfdf4ac0189c288ffb0b3", "price_changes":[{"asset_id":"17924629579804316786455515989238352689210911545477836576430679697715946894553", "price":"0.01", "size":"13065.5", "side":"BUY", "hash":"615a6178f6b0854abcf2d6989fd1a4a162f6a951", "best_bid":"0.61", "best_ask":"0.62"}, {"asset_id":"12935926064588426924078449947177910958215776269411501731627440228801766632772", "price":"0.99", "size":"13065.5", "side":"SELL", "hash":"317bad4d1bab87f1d3aa9f819146e1ef7cbe276a", "best_bid":"0.38", "best_ask":"0.39"}], "timestamp":"1784449238405", "event_type":"price_change"}
{"market":"0xab772601f501b265bfe8982eb61d5347ef9945de314bfdf4ac0189c288ffb0b3", "price_changes":[{"asset_id":"17924629579804316786455515989238352689210911545477836576430679697715946894553", "price":"0.59", "size":"210.34", "side":"BUY", "hash":"ea4ceee38996b63ea96c286a953902f9d99b844d", "best_bid":"0.61", "best_ask":"0.62"}, {"asset_id":"12935926064588426924078449947177910958215776269411501731627440228801766632772", "price":"0.41", "size":"210.34", "side":"SELL", "hash":"53d5435838cd6dbbd6efcb46316ad200bbe6969e", "best_bid":"0.38", "best_ask":"0.39"}], "timestamp":"1784449238411", "event_type":"price_change"}
{"market":"0xab772601f501b265bfe8982eb61d5347ef9945de314bfdf4ac0189c288ffb0b3", "price_changes":[{"asset_id":"17924629579804316786455515989238352689210911545477836576430679697715946894553", "price":"0.6", "size":"46.7", "side":"BUY", "hash":"ea4ceee38996b63ea96c286a953902f9d99b844d", "best_bid":"0.61", "best_ask":"0.62"}, {"asset_id":"12935926064588426924078449947177910958215776269411501731627440228801766632772", "price":"0.4", "size":"46.7", "side":"SELL", "hash":"53d5435838cd6dbbd6efcb46316ad200bbe6969e", "best_bid":"0.38", "best_ask":"0.39"}], "timestamp":"1784449238411", "event_type":"price_change"}
{"market":"0xab772601f501b265bfe8982eb61d5347ef9945de314bfdf4ac0189c288ffb0b3", "price_changes":[{"asset_id":"17924629579804316786455515989238352689210911545477836576430679697715946894553", "price":"0.61", "size":"12", "side":"BUY", "hash":"1d19357ebf8bd16717db7d836ffee687c9950d1c", "best_bid":"0.61", "best_ask":"0.62"}, {"asset_id":"12935926064588426924078449947177910958215776269411501731627440228801766632772", "price":"0.39", "size":"12", "side":"SELL", "hash":"c1f583679269973c40d4560c5dd265601ee46452", "best_bid":"0.38", "best_ask":"0.39"}], "timestamp":"1784449238411", "event_type":"price_change"}
{"market":"0xab772601f501b265bfe8982eb61d5347ef9945de314bfdf4ac0189c288ffb0b3", "price_changes":[{"asset_id":"12935926064588426924078449947177910958215776269411501731627440228801766632772", "price":"0.12", "size":"1112.05", "side":"BUY", "hash":"1fc2041632ae889750759b08562a02fa520b703e", "best_bid":"0.38", "best_ask":"0.39"}, {"asset_id":"17924629579804316786455515989238352689210911545477836576430679697715946894553", "price":"0.88", "size":"1112.05", "side":"SELL", "hash":"620c8afd36ed2535f2e8b0de9940cb79aef06eca", "best_bid":"0.61", "best_ask":"0.62"}], "timestamp":"1784449238413", "event_type":"price_change"}
{"market":"0xab772601f501b265bfe8982eb61d5347ef9945de314bfdf4ac0189c288ffb0b3", "price_changes":[{"asset_id":"17924629579804316786455515989238352689210911545477836576430679697715946894553", "price":"0.01", "size":"12965.5", "side":"BUY", "hash":"f0fbd49b573a252b2325dcd6193081fd2ba662ba", "best_bid":"0.61", "best_ask":"0.62"}, {"asset_id":"12935926064588426924078449947177910958215776269411501731627440228801766632772", "price":"0.99", "size":"12965.5", "side":"SELL", "hash":"21ce6f0ea7d948adef9e281fccb25c492329c1f1", "best_bid":"0.38", "best_ask":"0.39"}], "timestamp":"1784449238413", "event_type":"price_change"}
{"market":"0xab772601f501b265bfe8982eb61d5347ef9945de314bfdf4ac0189c288ffb0b3", "price_changes":[{"asset_id":"17924629579804316786455515989238352689210911545477836576430679697715946894553", "price":"0.01", "size":"12960.5", "side":"BUY", "hash":"cac3be36e461df92655f5f3a3910418aacd3d709", "best_bid":"0.61", "best_ask":"0.62"}, {"asset_id":"12935926064588426924078449947177910958215776269411501731627440228801766632772", "price":"0.99", "size":"12960.5", "side":"SELL", "hash":"97fbaae429c91a775a4e9d2449e2e003fc2cc1a3", "best_bid":"0.38", "best_ask":"0.39"}], "timestamp":"1784449238420", "event_type":"price_change"}
{"market":"0xab772601f501b265bfe8982eb61d5347ef9945de314bfdf4ac0189c288ffb0b3", "price_changes":[{"asset_id":"17924629579804316786455515989238352689210911545477836576430679697715946894553", "price":"0.01", "size":"12955.5", "side":"BUY", "hash":"9d32960bd29ae4e7ea8ea396c8dae75ce16be5e1", "best_bid":"0.61", "best_ask":"0.62"}, {"asset_id":"12935926064588426924078449947177910958215776269411501731627440228801766632772", "price":"0.99", "size":"12955.5", "side":"SELL", "hash":"02999eb3dfd62333950dee25eb80101648d9a2dd", "best_bid":"0.38", "best_ask":"0.39"}], "timestamp":"1784449238426", "event_type":"price_change"}
{"market":"0xab772601f501b265bfe8982eb61d5347ef9945de314bfdf4ac0189c288ffb0b3", "price_changes":[{"asset_id":"17924629579804316786455515989238352689210911545477836576430679697715946894553", "price":"0.01", "size":"12960.5", "side":"BUY", "hash":"23af1732ed7b47480042f107b495d0eb261da0db", "best_bid":"0.61", "best_ask":"0.62"}, {"asset_id":"12935926064588426924078449947177910958215776269411501731627440228801766632772", "price":"0.99", "size":"12960.5", "side":"SELL", "hash":"b762e6a196cb813c28a02b8a5fc8c3deff15958c", "best_bid":"0.38", "best_ask":"0.39"}], "timestamp":"1784449238426", "event_type":"price_change"}
{"market":"0xab772601f501b265bfe8982eb61d5347ef9945de314bfdf4ac0189c288ffb0b3", "price_changes":[{"asset_id":"12935926064588426924078449947177910958215776269411501731627440228801766632772", "price":"0.22", "size":"135.5", "side":"BUY", "hash":"9a39b104461ae7045b6c96481f507437e531919c", "best_bid":"0.38", "best_ask":"0.39"}, {"asset_id":"17924629579804316786455515989238352689210911545477836576430679697715946894553", "price":"0.78", "size":"135.5", "side":"SELL", "hash":"4ba12030fbd4b692dc8ccdbc5f9decee29ef2206", "best_bid":"0.61", "best_ask":"0.62"}], "timestamp":"1784449238427", "event_type":"price_change"}
{"market":"0xab772601f501b265bfe8982eb61d5347ef9945de314bfdf4ac0189c288ffb0b3", "price_changes":[{"asset_id":"17924629579804316786455515989238352689210911545477836576430679697715946894553", "price":"0.01", "size":"12965.5", "side":"BUY", "hash":"5370a3209510276655ef75660ac58d44ebdde51d", "best_bid":"0.61", "best_ask":"0.62"}, {"asset_id":"12935926064588426924078449947177910958215776269411501731627440228801766632772", "price":"0.99", "size":"12965.5", "side":"SELL", "hash":"2feabfaf52a63f99ada6dd45da908293dbac9b85", "best_bid":"0.38", "best_ask":"0.39"}], "timestamp":"1784449238427", "event_type":"price_change"}
{"market":"0xab772601f501b265bfe8982eb61d5347ef9945de314bfdf4ac0189c288ffb0b3", "price_changes":[{"asset_id":"17924629579804316786455515989238352689210911545477836576430679697715946894553", "price":"0.6", "size":"36.7", "side":"BUY", "hash":"9ea90e0c6582a25a98372969c8656f8f953e5e41", "best_bid":"0.61", "best_ask":"0.62"}, {"asset_id":"12935926064588426924078449947177910958215776269411501731627440228801766632772", "price":"0.4", "size":"36.7", "side":"SELL", "hash":"8b76f8075ff043cda9461f718a4753ce602032ed", "best_bid":"0.38", "best_ask":"0.39"}], "timestamp":"1784449238428", "event_type":"price_change"}
{"market":"0xab772601f501b265bfe8982eb61d5347ef9945de314bfdf4ac0189c288ffb0b3", "price_changes":[{"asset_id":"17924629579804316786455515989238352689210911545477836576430679697715946894553", "price":"0.01", "size":"12960.5", "side":"BUY", "hash":"7add93e6b78021a08f6886dc68ab2787a0d17e49", "best_bid":"0.61", "best_ask":"0.62"}, {"asset_id":"12935926064588426924078449947177910958215776269411501731627440228801766632772", "price":"0.99", "size":"12960.5", "side":"SELL", "hash":"6ac1a894ef3c7164c9b79275fe5cd602c588e925", "best_bid":"0.38", "best_ask":"0.39"}], "timestamp":"1784449238430", "event_type":"price_change"}
{"market":"0xab772601f501b265bfe8982eb61d5347ef9945de314bfdf4ac0189c288ffb0b3", "price_changes":[{"asset_id":"12935926064588426924078449947177910958215776269411501731627440228801766632772", "price":"0.35", "size":"121.2", "side":"BUY", "hash":"bdf68150d9be466b8cb624588acd9390b9783a85", "best_bid":"0.38", "best_ask":"0.39"}, {"asset_id":"17924629579804316786455515989238352689210911545477836576430679697715946894553", "price":"0.65", "size":"121.2", "side":"SELL", "hash":"59efef3b9c0d7fb851dfc6a924d95da7c57207ec", "best_bid":"0.61", "best_ask":"0.62"}], "timestamp":"1784449238432", "event_type":"price_change"}
{"market":"0xab772601f501b265bfe8982eb61d5347ef9945de314bfdf4ac0189c288ffb0b3", "price_changes":[{"asset_id":"17924629579804316786455515989238352689210911545477836576430679697715946894553", "price":"0.01", "size":"12954.5", "side":"BUY", "hash":"ee910fdc19afc8e135f3dacdb12d4fdbacf46462", "best_bid":"0.61", "best_ask":"0.62"}, {"asset_id":"12935926064588426924078449947177910958215776269411501731627440228801766632772", "price":"0.99", "size":"12954.5", "side":"SELL", "hash":"8210649de1e3a3493c103890e853686375541f6f", "best_bid":"0.38", "best_ask":"0.39"}], "timestamp":"1784449238434", "event_type":"price_change"}
{"market":"0xab772601f501b265bfe8982eb61d5347ef9945de314bfdf4ac0189c288ffb0b3", "price_changes":[{"asset_id":"17924629579804316786455515989238352689210911545477836576430679697715946894553", "price":"0.52", "size":"220.91", "side":"BUY", "hash":"53bd1110289383e136b1a27488ad86cf95566754", "best_bid":"0.61", "best_ask":"0.62"}, {"asset_id":"12935926064588426924078449947177910958215776269411501731627440228801766632772", "price":"0.48", "size":"220.91", "side":"SELL", "hash":"a88efe0e7ee911595bcf5e5c9bd9b6a31e0565c6", "best_bid":"0.38", "best_ask":"0.39"}], "timestamp":"1784449238434", "event_type":"price_change"}
{"market":"0xab772601f501b265bfe8982eb61d5347ef9945de314bfdf4ac0189c288ffb0b3", "price_changes":[{"asset_id":"17924629579804316786455515989238352689210911545477836576430679697715946894553", "price":"0.02", "size":"3890.25", "side":"BUY", "hash":"0e296ff4747d1f3fadeb4ef184d7383200ba53ba", "best_bid":"0.61", "best_ask":"0.62"}, {"asset_id":"12935926064588426924078449947177910958215776269411501731627440228801766632772", "price":"0.98", "size":"3890.25", "side":"SELL", "hash":"a6601ec24c0310e0d1aa99e043df0db62a92637a", "best_bid":"0.38", "best_ask":"0.39"}], "timestamp":"1784449238435", "event_type":"price_change"}
{"market":"0xab772601f501b265bfe8982eb61d5347ef9945de314bfdf4ac0189c288ffb0b3", "price_changes":[{"asset_id":"17924629579804316786455515989238352689210911545477836576430679697715946894553", "price":"0.01", "size":"12959.5", "side":"BUY", "hash":"e59d0eadb1d9087ad21f7845ad891d7c0605b625", "best_bid":"0.61", "best_ask":"0.62"}, {"asset_id":"12935926064588426924078449947177910958215776269411501731627440228801766632772", "price":"0.99", "size":"12959.5", "side":"SELL", "hash":"8142f3e55ada1a8c5c478a9eb19719a4c42feeb9", "best_bid":"0.38", "best_ask":"0.39"}], "timestamp":"1784449238435", "event_type":"price_change"}
{"market":"0xab772601f501b265bfe8982eb61d5347ef9945de314bfdf4ac0189c288ffb0b3", "price_changes":[{"asset_id":"12935926064588426924078449947177910958215776269411501731627440228801766632772", "price":"0.3", "size":"207.81", "side":"BUY", "hash":"17090e98c230f655bb82fc92c0a46cbce32e20a5", "best_bid":"0.38", "best_ask":"0.39"}, {"asset_id":"17924629579804316786455515989238352689210911545477836576430679697715946894553", "price":"0.7", "size":"207.81", "side":"SELL", "hash":"7e68ab559fa6e526fd3ebbc19d40e04094238e4d", "best_bid":"0.61", "best_ask":"0.62"}], "timestamp":"1784449238436", "event_type":"price_change"}
{"market":"0xab772601f501b265bfe8982eb61d5347ef9945de314bfdf4ac0189c288ffb0b3", "price_changes":[{"asset_id":"17924629579804316786455515989238352689210911545477836576430679697715946894553", "price":"0.34", "size":"92.8", "side":"BUY", "hash":"8e67a8d3035637e154dfb559eede4486433a6c52", "best_bid":"0.61", "best_ask":"0.62"}, {"asset_id":"12935926064588426924078449947177910958215776269411501731627440228801766632772", "price":"0.66", "size":"92.8", "side":"SELL", "hash":"408d4145441727f894ff89f1cb610a58942b46b0", "best_bid":"0.38", "best_ask":"0.39"}], "timestamp":"1784449238436", "event_type":"price_change"}
{"market":"0xab772601f501b265bfe8982eb61d5347ef9945de314bfdf4ac0189c288ffb0b3", "price_changes":[{"asset_id":"17924629579804316786455515989238352689210911545477836576430679697715946894553", "price":"0.52", "size":"230.91", "side":"BUY", "hash":"6dea7841e36006e38c2805d8c466e13be6e1fcbb", "best_bid":"0.61", "best_ask":"0.62"}, {"asset_id":"12935926064588426924078449947177910958215776269411501731627440228801766632772", "price":"0.48", "size":"230.91", "side":"SELL", "hash":"951a0a77c422ee279454833daf670412aba7bafe", "best_bid":"0.38", "best_ask":"0.39"}], "timestamp":"1784449238437", "event_type":"price_change"}
{"market":"0xab772601f501b265bfe8982eb61d5347ef9945de314bfdf4ac0189c288ffb0b3", "price_changes":[{"asset_id":"17924629579804316786455515989238352689210911545477836576430679697715946894553", "price":"0.35", "size":"84.6", "side":"BUY", "hash":"f499c70f57439eff2b66f1481e5765ef5ed9ec17", "best_bid":"0.61", "best_ask":"0.62"}, {"asset_id":"12935926064588426924078449947177910958215776269411501731627440228801766632772", "price":"0.65", "size":"84.6", "side":"SELL", "hash":"87745f7b8493096dc597e1d11b5aae755617c4e8", "best_bid":"0.38", "best_ask":"0.39"}], "timestamp":"1784449238438", "event_type":"price_change"}
{"market":"0xab772601f501b265bfe8982eb61d5347ef9945de314bfdf4ac0189c288ffb0b3", "price_changes":[{"asset_id":"17924629579804316786455515989238352689210911545477836576430679697715946894553", "price":"0.33", "size":"113.1", "side":"BUY", "hash":"8686bedb39be1c63dac7c05387d2ba20a538f1a1", "best_bid":"0.61", "best_ask":"0.62"}, {"asset_id":"12935926064588426924078449947177910958215776269411501731627440228801766632772", "price":"0.67", "size":"113.1", "side":"SELL", "hash":"27c7bb9ce17b235e192d60c0a80996ed134c50c7", "best_bid":"0.38", "best_ask":"0.39"}], "timestamp":"1784449238439", "event_type":"price_change"}
{"market":"0xab772601f501b265bfe8982eb61d5347ef9945de314bfdf4ac0189c288ffb0b3", "price_changes":[{"asset_id":"17924629579804316786455515989238352689210911545477836576430679697715946894553", "price":"0.01", "size":"12964.5", "side":"BUY", "hash":"926ad71725f226f4c5244b6393269dae7cc0823b", "best_bid":"0.61", "best_ask":"0.62"}, {"asset_id":"12935926064588426924078449947177910958215776269411501731627440228801766632772", "price":"0.99", "size":"12964.5", "side":"SELL", "hash":"18fba26dd92a7b6fbde2b0ac175f2b683f8ba350", "best_bid":"0.38", "best_ask":"0.39"}], "timestamp":"1784449238440", "event_type":"price_change"}
{"market":"0xab772601f501b265bfe8982eb61d5347ef9945de314bfdf4ac0189c288ffb0b3", "price_changes":[{"asset_id":"17924629579804316786455515989238352689210911545477836576430679697715946894553", "price":"0.01", "size":"12959.5", "side":"BUY", "hash":"56bd314498edd6974fbb13c48f3b90a2a90181eb", "best_bid":"0.61", "best_ask":"0.62"}, {"asset_id":"12935926064588426924078449947177910958215776269411501731627440228801766632772", "price":"0.99", "size":"12959.5", "side":"SELL", "hash":"7cb5f15971275ec3e91d01919b4cbf93cc456e21", "best_bid":"0.38", "best_ask":"0.39"}], "timestamp":"1784449238444", "event_type":"price_change"}
{"market":"0xab772601f501b265bfe8982eb61d5347ef9945de314bfdf4ac0189c288ffb0b3", "price_changes":[{"asset_id":"12935926064588426924078449947177910958215776269411501731627440228801766632772", "price":"0.38", "size":"394.01", "side":"BUY", "hash":"cb75e9fb331f53df6b878df4b2974149831799e0", "best_bid":"0.38", "best_ask":"0.39"}, {"asset_id":"17924629579804316786455515989238352689210911545477836576430679697715946894553", "price":"0.62", "size":"394.01", "side":"SELL", "hash":"25eddfac81138bc01515413dae98edba303f8053", "best_bid":"0.61", "best_ask":"0.62"}], "timestamp":"1784449238451", "event_type":"price_change"}
{"market":"0xab772601f501b265bfe8982eb61d5347ef9945de314bfdf4ac0189c288ffb0b3", "price_changes":[{"asset_id":"17924629579804316786455515989238352689210911545477836576430679697715946894553", "price":"0.58", "size":"151.82", "side":"BUY", "hash":"66401786282406ed4f21d4ad2cddc138b4f3ff47", "best_bid":"0.61", "best_ask":"0.62"}, {"asset_id":"12935926064588426924078449947177910958215776269411501731627440228801766632772", "price":"0.42", "size":"151.82", "side":"SELL", "hash":"a6e7f0b7605db35c7f1a8860de0645dd81703b3c", "best_bid":"0.38", "best_ask":"0.39"}], "timestamp":"1784449238452", "event_type":"price_change"}
{"market":"0xab772601f501b265bfe8982eb61d5347ef9945de314bfdf4ac0189c288ffb0b3", "price_changes":[{"asset_id":"17924629579804316786455515989238352689210911545477836576430679697715946894553", "price":"0.58", "size":"156.82", "side":"BUY", "hash":"087bca7a25df617a8daef1e742f858b98aba7edd", "best_bid":"0.61", "best_ask":"0.62"}, {"asset_id":"12935926064588426924078449947177910958215776269411501731627440228801766632772", "price":"0.42", "size":"156.82", "side":"SELL", "hash":"7b2b2c5e37bf59f3504bda5cc701c5db66d674a9", "best_bid":"0.38", "best_ask":"0.39"}], "timestamp":"1784449238453", "event_type":"price_change"}
{"market":"0xab772601f501b265bfe8982eb61d5347ef9945de314bfdf4ac0189c288ffb0b3", "price_changes":[{"asset_id":"17924629579804316786455515989238352689210911545477836576430679697715946894553", "price":"0.01", "size":"12954.5", "side":"BUY", "hash":"cf7e480163c860b8950fd0089ab7552c04f45f8c", "best_bid":"0.61", "best_ask":"0.62"}, {"asset_id":"12935926064588426924078449947177910958215776269411501731627440228801766632772", "price":"0.99", "size":"12954.5", "side":"SELL", "hash":"8fbc2de316ffd835c100a47b68c3a744f42114e3", "best_bid":"0.38", "best_ask":"0.39"}], "timestamp":"1784449238454", "event_type":"price_change"}
{"market":"0xab772601f501b265bfe8982eb61d5347ef9945de314bfdf4ac0189c288ffb0b3", "price_changes":[{"asset_id":"17924629579804316786455515989238352689210911545477836576430679697715946894553", "price":"0.57", "size":"139", "side":"BUY", "hash":"d0040d275f01863c6919455058c9415fda50e9b6", "best_bid":"0.61", "best_ask":"0.62"}, {"asset_id":"12935926064588426924078449947177910958215776269411501731627440228801766632772", "price":"0.43", "size":"139", "side":"SELL", "hash":"bac5af655c7696da3adde1150937b60cd59b3978", "best_bid":"0.38", "best_ask":"0.39"}], "timestamp":"1784449238454", "event_type":"price_change"}
{"market":"0xab772601f501b265bfe8982eb61d5347ef9945de314bfdf4ac0189c288ffb0b3", "price_changes":[{"asset_id":"12935926064588426924078449947177910958215776269411501731627440228801766632772", "price":"0.32", "size":"236.69", "side":"BUY", "hash":"a1d155163fe90ac6c105a9ac7b5c5fd5569e4a53", "best_bid":"0.38", "best_ask":"0.39"}, {"asset_id":"17924629579804316786455515989238352689210911545477836576430679697715946894553", "price":"0.68", "size":"236.69", "side":"SELL", "hash":"6a3fd6a9dbca908283c518b0b6213a58c09841f0", "best_bid":"0.61", "best_ask":"0.62"}], "timestamp":"1784449238457", "event_type":"price_change"}
{"market":"0xab772601f501b265bfe8982eb61d5347ef9945de314bfdf4ac0189c288ffb0b3", "price_changes":[{"asset_id":"12935926064588426924078449947177910958215776269411501731627440228801766632772", "price":"0.36", "size":"211.77", "side":"BUY", "hash":"a2d572ee43dcc843be373762d4bd0d13686e7976", "best_bid":"0.38", "best_ask":"0.39"}, {"asset_id":"17924629579804316786455515989238352689210911545477836576430679697715946894553", "price":"0.64", "size":"211.77", "side":"SELL", "hash":"32260994888c65d61bd7ebf4434bc0b522becf98", "best_bid":"0.61", "best_ask":"0.62"}], "timestamp":"1784449238459", "event_type":"price_change"}
{"market":"0xab772601f501b265bfe8982eb61d5347ef9945de314bfdf4ac0189c288ffb0b3", "price_changes":[{"asset_id":"17924629579804316786455515989238352689210911545477836576430679697715946894553", "price":"0.01", "size":"13054.5", "side":"BUY", "hash":"a65a0580ae4276639f5313496b0b45b7e09a11b3", "best_bid":"0.61", "best_ask":"0.62"}, {"asset_id":"12935926064588426924078449947177910958215776269411501731627440228801766632772", "price":"0.99", "size":"13054.5", "side":"SELL", "hash":"aa5079c3c25f1a7d8865d00ada2107162fed5102", "best_bid":"0.38", "best_ask":"0.39"}], "timestamp":"1784449238460", "event_type":"price_change"}
{"market":"0xab772601f501b265bfe8982eb61d5347ef9945de314bfdf4ac0189c288ffb0b3", "price_changes":[{"asset_id":"17924629579804316786455515989238352689210911545477836576430679697715946894553", "price":"0.01", "size":"13059.51", "side":"BUY", "hash":"5cfac1ddc582a3c3cd229e34863162f8b0d423e4", "best_bid":"0.61", "best_ask":"0.62"}, {"asset_id":"12935926064588426924078449947177910958215776269411501731627440228801766632772", "price":"0.99", "size":"13059.51", "side":"SELL", "hash":"1f209d5ea05b3bfcb0a6bf67e2ef910db8a360d1", "best_bid":"0.38", "best_ask":"0.39"}], "timestamp":"1784449238462", "event_type":"price_change"}
{"market":"0xab772601f501b265bfe8982eb61d5347ef9945de314bfdf4ac0189c288ffb0b3", "price_changes":[{"asset_id":"17924629579804316786455515989238352689210911545477836576430679697715946894553", "price":"0.52", "size":"255.91", "side":"BUY", "hash":"11967066276d94156a6adbda1fa737c487615c30", "best_bid":"0.61", "best_ask":"0.62"}, {"asset_id":"12935926064588426924078449947177910958215776269411501731627440228801766632772", "price":"0.48", "size":"255.91", "side":"SELL", "hash":"5217b94d62a4fb6ffb1f1678b76c81fd418a48fe", "best_bid":"0.38", "best_ask":"0.39"}], "timestamp":"1784449238462", "event_type":"price_change"}
{"market":"0xab772601f501b265bfe8982eb61d5347ef9945de314bfdf4ac0189c288ffb0b3", "price_changes":[{"asset_id":"12935926064588426924078449947177910958215776269411501731627440228801766632772", "price":"0.37", "size":"165.97", "side":"BUY", "hash":"df6d36de004ef9352a416cc011c72587dc9ffd1b", "best_bid":"0.38", "best_ask":"0.39"}, {"asset_id":"17924629579804316786455515989238352689210911545477836576430679697715946894553", "price":"0.63", "size":"165.97", "side":"SELL", "hash":"a1962a143b1e569c48f8434bb8fae927b26079d3", "best_bid":"0.61", "best_ask":"0.62"}], "timestamp":"1784449238463", "event_type":"price_change"}
{"market":"0xab772601f501b265bfe8982eb61d5347ef9945de314bfdf4ac0189c288ffb0b3", "price_changes":[{"asset_id":"12935926064588426924078449947177910958215776269411501731627440228801766632772", "price":"0.51", "size":"71", "side":"SELL", "hash":"63643a0ec50336f43087465d62a4f836ca7aa374", "best_bid":"0.38", "best_ask":"0.39"}, {"asset_id":"17924629579804316786455515989238352689210911545477836576430679697715946894553", "price":"0.49", "size":"71", "side":"BUY", "hash":"8a722bcd1671988bfb5ca6ea2db010d4a109bcf0", "best_bid":"0.61", "best_ask":"0.62"}], "timestamp":"1784449238474", "event_type":"price_change"}
{"market":"0xab772601f501b265bfe8982eb61d5347ef9945de314bfdf4ac0189c288ffb0b3", "price_changes":[{"asset_id":"12935926064588426924078449947177910958215776269411501731627440228801766632772", "price":"0.05", "size":"1752.19", "side":"BUY", "hash":"d74fe2e71f4f6add823f8f0a26cd3acac40fb1ad", "best_bid":"0.38", "best_ask":"0.39"}, {"asset_id":"17924629579804316786455515989238352689210911545477836576430679697715946894553", "price":"0.95", "size":"1752.19", "side":"SELL", "hash":"9256338760d44a5d5fd12074ef59fbd2459dcf10", "best_bid":"0.61", "best_ask":"0.62"}], "timestamp":"1784449238485", "event_type":"price_change"}
{"market":"0xab772601f501b265bfe8982eb61d5347ef9945de314bfdf4ac0189c288ffb0b3", "price_changes":[{"asset_id":"17924629579804316786455515989238352689210911545477836576430679697715946894553", "price":"0.02", "size":"3885.25", "side":"BUY", "hash":"7b9bd03e9593b189da21b85d13dd7946256e1b51", "best_bid":"0.61", "best_ask":"0.62"}, {"asset_id":"12935926064588426924078449947177910958215776269411501731627440228801766632772", "price":"0.98", "size":"3885.25", "side":"SELL", "hash":"3f417938ac407da30b650fe9fe680f68b8884f67", "best_bid":"0.38", "best_ask":"0.39"}], "timestamp":"1784449238487", "event_type":"price_change"}
{"market":"0xab772601f501b265bfe8982eb61d5347ef9945de314bfdf4ac0189c288ffb0b3", "price_changes":[{"asset_id":"17924629579804316786455515989238352689210911545477836576430679697715946894553", "price":"0.01", "size":"13054.5", "side":"BUY", "hash":"c69a83d0bd90db8a1434b62f842689c4a75eba2e", "best_bid":"0.61", "best_ask":"0.62"}, {"asset_id":"12935926064588426924078449947177910958215776269411501731627440228801766632772", "price":"0.99", "size":"13054.5", "side":"SELL", "hash":"b790d0112e9392a1668726badd84e7d9d93a534f", "best_bid":"0.38", "best_ask":"0.39"}], "timestamp":"1784449238489", "event_type":"price_change"}
{"market":"0xab772601f501b265bfe8982eb61d5347ef9945de314bfdf4ac0189c288ffb0b3", "price_changes":[{"asset_id":"17924629579804316786455515989238352689210911545477836576430679697715946894553", "price":"0.01", "size":"12954.5", "side":"BUY", "hash":"4bdcfbfe0051ec6782928cd3499438f976a5fc58", "best_bid":"0.61", "best_ask":"0.62"}, {"asset_id":"12935926064588426924078449947177910958215776269411501731627440228801766632772", "price":"0.99", "size":"12954.5", "side":"SELL", "hash":"07b21e39125881545dbc11780ff4be9f093939c9", "best_bid":"0.38", "best_ask":"0.39"}], "timestamp":"1784449238489", "event_type":"price_change"}
{"market":"0xab772601f501b265bfe8982eb61d5347ef9945de314bfdf4ac0189c288ffb0b3", "price_changes":[{"asset_id":"12935926064588426924078449947177910958215776269411501731627440228801766632772", "price":"0.35", "size":"138.8", "side":"BUY", "hash":"489cf2d822716dcb70ca028118ff468273aa57a1", "best_bid":"0.38", "best_ask":"0.39"}, {"asset_id":"17924629579804316786455515989238352689210911545477836576430679697715946894553", "price":"0.65", "size":"138.8", "side":"SELL", "hash":"6f459ef65306d91f80816efa3380060f8333f5e9", "best_bid":"0.61", "best_ask":"0.62"}], "timestamp":"1784449238500", "event_type":"price_change"}
{"market":"0xab772601f501b265bfe8982eb61d5347ef9945de314bfdf4ac0189c288ffb0b3", "price_changes":[{"asset_id":"17924629579804316786455515989238352689210911545477836576430679697715946894553", "price":"0.01", "size":"12960.5", "side":"BUY", "hash":"8752ef30480c0cb25135df4a604971784d7dcaa2", "best_bid":"0.61", "best_ask":"0.62"}, {"asset_id":"12935926064588426924078449947177910958215776269411501731627440228801766632772", "price":"0.99", "size":"12960.5", "side":"SELL", "hash":"6bf27ca68c78cbb8db5ff4743a3ddf5cdeb28c8d", "best_bid":"0.38", "best_ask":"0.39"}], "timestamp":"1784449238507", "event_type":"price_change"}
{"market":"0xab772601f501b265bfe8982eb61d5347ef9945de314bfdf4ac0189c288ffb0b3", "price_changes":[{"asset_id":"17924629579804316786455515989238352689210911545477836576430679697715946894553", "price":"0.01", "size":"12954.5", "side":"BUY", "hash":"f0b8953337b7ed640d5fa6c41e17ee17384b63f9", "best_bid":"0.61", "best_ask":"0.62"}, {"asset_id":"12935926064588426924078449947177910958215776269411501731627440228801766632772", "price":"0.99", "size":"12954.5", "side":"SELL", "hash":"71a34466779673a1f06f94ed8a7e54b85d405e87", "best_bid":"0.38", "best_ask":"0.39"}], "timestamp":"1784449238531", "event_type":"price_change"}
{"market":"0xab772601f501b265bfe8982eb61d5347ef9945de314bfdf4ac0189c288ffb0b3", "price_changes":[{"asset_id":"17924629579804316786455515989238352689210911545477836576430679697715946894553", "price":"0.01", "size":"13054.5", "side":"BUY", "hash":"e24d79c83a45b5328877d3020955e5f17fd4d057", "best_bid":"0.61", "best_ask":"0.62"}, {"asset_id":"12935926064588426924078449947177910958215776269411501731627440228801766632772", "price":"0.99", "size":"13054.5", "side":"SELL", "hash":"52f610cc30da99e54353af06e6a012fefcc47baa", "best_bid":"0.38", "best_ask":"0.39"}], "timestamp":"1784449238536", "event_type":"price_change"}
{"market":"0xab772601f501b265bfe8982eb61d5347ef9945de314bfdf4ac0189c288ffb0b3", "price_changes":[{"asset_id":"17924629579804316786455515989238352689210911545477836576430679697715946894553", "price":"0.26", "size":"90.3", "side":"BUY", "hash":"1d02b0b5d689e0d958a7a4460747acd09fe2097e", "best_bid":"0.61", "best_ask":"0.62"}, {"asset_id":"12935926064588426924078449947177910958215776269411501731627440228801766632772", "price":"0.74", "size":"90.3", "side":"SELL", "hash":"8f775deab9cbdf60944273159ce3374a0e378abe", "best_bid":"0.38", "best_ask":"0.39"}], "timestamp":"1784449238537", "event_type":"price_change"}
{"market":"0xab772601f501b265bfe8982eb61d5347ef9945de314bfdf4ac0189c288ffb0b3", "price_changes":[{"asset_id":"17924629579804316786455515989238352689210911545477836576430679697715946894553", "price":"0.59", "size":"155.04", "side":"BUY", "hash":"8b7d2b3bac69b201d218328e7f200e149aabcec5", "best_bid":"0.59", "best_ask":"0.62"}, {"asset_id":"12935926064588426924078449947177910958215776269411501731627440228801766632772", "price":"0.41", "size":"155.04", "side":"SELL", "hash":"405cbad6e24f68b43c5aba39620c0765df6ecbc3", "best_bid":"0.38", "best_ask":"0.41"}], "timestamp":"1784449238547", "event_type":"price_change"}
{"market":"0xab772601f501b265bfe8982eb61d5347ef9945de314bfdf4ac0189c288ffb0b3", "price_changes":[{"asset_id":"17924629579804316786455515989238352689210911545477836576430679697715946894553", "price":"0.61", "size":"0", "side":"BUY", "hash":"8b7d2b3bac69b201d218328e7f200e149aabcec5", "best_bid":"0.59", "best_ask":"0.62"}, {"asset_id":"12935926064588426924078449947177910958215776269411501731627440228801766632772", "price":"0.39", "size":"0", "side":"SELL", "hash":"405cbad6e24f68b43c5aba39620c0765df6ecbc3", "best_bid":"0.38", "best_ask":"0.41"}], "timestamp":"1784449238547", "event_type":"price_change"}
{"market":"0xab772601f501b265bfe8982eb61d5347ef9945de314bfdf4ac0189c288ffb0b3", "price_changes":[{"asset_id":"17924629579804316786455515989238352689210911545477836576430679697715946894553", "price":"0.6", "size":"0", "side":"BUY", "hash":"8b7d2b3bac69b201d218328e7f200e149aabcec5", "best_bid":"0.59", "best_ask":"0.62"}, {"asset_id":"12935926064588426924078449947177910958215776269411501731627440228801766632772", "price":"0.4", "size":"0", "side":"SELL", "hash":"405cbad6e24f68b43c5aba39620c0765df6ecbc3", "best_bid":"0.38", "best_ask":"0.41"}], "timestamp":"1784449238547", "event_type":"price_change"}
