{"market":"0x982eae4503214e5d7992668e93f48f42e4707b92e23bb45f8d52d321f643cbe3", "asset_id":"74913635031537477155015393896000154190746945075332596665612975928350948042868", "bids":[{"price":"0.01", "size":"16184.13"}, {"price":"0.02", "size":"3289.11"}, {"price":"0.03", "size":"2090.95"}, {"price":"0.04", "size":"1462.1"}, {"price":"0.05", "size":"1953.67"}, {"price":"0.06", "size":"1677.35"}, {"price":"0.07", "size":"1155.2"}, {"price":"0.08", "size":"1325.88"}, {"price":"0.09", "size":"1027.7"}, {"price":"0.1", "size":"528.2"}, {"price":"0.11", "size":"454.1"}, {"price":"0.12", "size":"203.05"}, {"price":"0.13", "size":"179.4"}, {"price":"0.14", "size":"159.4"}, {"price":"0.15", "size":"149.23"}, {"price":"0.16", "size":"150.4"}, {"price":"0.17", "size":"105.08"}, {"price":"0.18", "size":"127.3"}, {"price":"0.19", "size":"99.78"}, {"price":"0.2", "size":"181.4"}, {"price":"0.21", "size":"111.5"}, {"price":"0.22", "size":"125.7"}, {"price":"0.23", "size":"92"}, {"price":"0.24", "size":"111.5"}, {"price":"0.25", "size":"823.6"}, {"price":"0.26", "size":"128.8"}, {"price":"0.27", "size":"86.7"}, {"price":"0.28", "size":"106.67"}, {"price":"0.29", "size":"84.59"}, {"price":"0.3", "size":"107.8"}, {"price":"0.31", "size":"79.1"}, {"price":"0.32", "size":"107.19"}, {"price":"0.33", "size":"76.7"}, {"price":"0.34", "size":"89"}, {"price":"0.35", "size":"84.4"}, {"price":"0.36", "size":"86.99"}, {"price":"0.37", "size":"73.6"}, {"price":"0.38", "size":"85"}, {"price":"0.39", "size":"71.6"}, {"price":"0.4", "size":"88.3"}, {"price":"0.41", "size":"69.9"}, {"price":"0.42", "size":"142.27"}, {"price":"0.43", "size":"86.5"}, {"price":"0.44", "size":"91.08"}, {"price":"0.45", "size":"104.31"}, {"price":"0.46", "size":"80.1"}, {"price":"0.47", "size":"94.9"}, {"price":"0.48", "size":"88.8"}, {"price":"0.49", "size":"99.36"}, {"price":"0.5", "size":"102.8"}, {"price":"0.51", "size":"100.8"}, {"price":"0.52", "size":"100.8"}, {"price":"0.53", "size":"99.9"}, {"price":"0.54", "size":"92.1"}, {"price":"0.55", "size":"485.2"}, {"price":"0.56", "size":"95.4"}, {"price":"0.57", "size":"85.5"}, {"price":"0.58", "size":"111.12"}, {"price":"0.59", "size":"94.9"}, {"price":"0.6", "size":"193.58"}, {"price":"0.61", "size":"105.6"}, {"price":"0.62", "size":"125"}, {"price":"0.63", "size":"150.6"}, {"price":"0.64", "size":"482.99"}, {"price":"0.65", "size":"107.4"}, {"price":"0.66", "size":"133.24"}, {"price":"0.67", "size":"302.58"}, {"price":"0.68", "size":"93.19"}, {"price":"0.69", "size":"85.7"}, {"price":"0.7", "size":"82.04"}, {"price":"0.71", "size":"99"}, {"price":"0.72", "size":"313.22"}, {"price":"0.73", "size":"159.41"}, {"price":"0.74", "size":"151.85"}, {"price":"0.75", "size":"162.84"}, {"price":"0.76", "size":"170.24"}, {"price":"0.77", "size":"189.66"}, {"price":"0.78", "size":"213.41"}, {"price":"0.79", "size":"118.19"}, {"price":"0.8", "size":"158.28"}, {"price":"0.81", "size":"392.9"}], "asks":[{"price":"0.99", "size":"17919.98"}, {"price":"0.98", "size":"3156.06"}, {"price":"0.97", "size":"3788.29"}, {"price":"0.96", "size":"1529.1"}, {"price":"0.95", "size":"1723.6"}, {"price":"0.94", "size":"1201.35"}, {"price":"0.93", "size":"1167.2"}, {"price":"0.92", "size":"1404.88"}, {"price":"0.91", "size":"942.82"}, {"price":"0.9", "size":"518.32"}, {"price":"0.89", "size":"490.73"}, {"price":"0.88", "size":"207.17"}, {"price":"0.87", "size":"426.4"}, {"price":"0.86", "size":"184.34"}, {"price":"0.85", "size":"127.71"}, {"price":"0.84", "size":"91.17"}, {"price":"0.83", "size":"16.31"}, {"price":"0.82", "size":"7.03"}], "hash":"7abd6ff2eaa80bf01f7cad1538159a7df2685592", "timestamp":"1784449596344", "event_type":"book"}
{"market":"0x982eae4503214e5d7992668e93f48f42e4707b92e23bb45f8d52d321f643cbe3", "asset_id":"37613674580450069178400687025689415665506452565086963049482350052080099056186", "bids":[{"price":"0.01", "size":"17919.98"}, {"price":"0.02", "size":"3156.06"}, {"price":"0.03", "size":"3788.29"}, {"price":"0.04", "size":"1529.1"}, {"price":"0.05", "size":"1723.6"}, {"price":"0.06", "size":"1201.35"}, {"price":"0.07", "size":"1167.2"}, {"price":"0.08", "size":"1404.88"}, {"price":"0.09", "size":"942.82"}, {"price":"0.1", "size":"518.32"}, {"price":"0.11", "size":"490.73"}, {"price":"0.12", "size":"207.17"}, {"price":"0.13", "size":"426.4"}, {"price":"0.14", "size":"184.34"}, {"price":"0.15", "size":"127.71"}, {"price":"0.16", "size":"91.17"}, {"price":"0.17", "size":"16.31"}, {"price":"0.18", "size":"7.03"}], "asks":[{"price":"0.99", "size":"16184.13"}, {"price":"0.98", "size":"3289.11"}, {"price":"0.97", "size":"2090.95"}, {"price":"0.96", "size":"1462.1"}, {"price":"0.95", "size":"1953.67"}, {"price":"0.94", "size":"1677.35"}, {"price":"0.93", "size":"1155.2"}, {"price":"0.92", "size":"1325.88"}, {"price":"0.91", "size":"1027.7"}, {"price":"0.9", "size":"528.2"}, {"price":"0.89", "size":"454.1"}, {"price":"0.88", "size":"203.05"}, {"price":"0.87", "size":"179.4"}, {"price":"0.86", "size":"159.4"}, {"price":"0.85", "size":"149.23"}, {"price":"0.84", "size":"150.4"}, {"price":"0.83", "size":"105.08"}, {"price":"0.82", "size":"127.3"}, {"price":"0.81", "size":"99.78"}, {"price":"0.8", "size":"181.4"}, {"price":"0.79", "size":"111.5"}, {"price":"0.78", "size":"125.7"}, {"price":"0.77", "size":"92"}, {"price":"0.76", "size":"111.5"}, {"price":"0.75", "size":"823.6"}, {"price":"0.74", "size":"128.8"}, {"price":"0.73", "size":"86.7"}, {"price":"0.72", "size":"106.67"}, {"price":"0.71", "size":"84.59"}, {"price":"0.7", "size":"107.8"}, {"price":"0.69", "size":"79.1"}, {"price":"0.68", "size":"107.19"}, {"price":"0.67", "size":"76.7"}, {"price":"0.66", "size":"89"}, {"price":"0.65", "size":"84.4"}, {"price":"0.64", "size":"86.99"}, {"price":"0.63", "size":"73.6"}, {"price":"0.62", "size":"85"}, {"price":"0.61", "size":"71.6"}, {"price":"0.6", "size":"88.3"}, {"price":"0.59", "size":"69.9"}, {"price":"0.58", "size":"142.27"}, {"price":"0.57", "size":"86.5"}, {"price":"0.56", "size":"91.08"}, {"price":"0.55", "size":"104.31"}, {"price":"0.54", "size":"80.1"}, {"price":"0.53", "size":"94.9"}, {"price":"0.52", "size":"88.8"}, {"price":"0.51", "size":"99.36"}, {"price":"0.5", "size":"102.8"}, {"price":"0.49", "size":"100.8"}, {"price":"0.48", "size":"100.8"}, {"price":"0.47", "size":"99.9"}, {"price":"0.46", "size":"92.1"}, {"price":"0.45", "size":"485.2"}, {"price":"0.44", "size":"95.4"}, {"price":"0.43", "size":"85.5"}, {"price":"0.42", "size":"111.12"}, {"price":"0.41", "size":"94.9"}, {"price":"0.4", "size":"193.58"}, {"price":"0.39", "size":"105.6"}, {"price":"0.38", "size":"125"}, {"price":"0.37", "size":"150.6"}, {"price":"0.36", "size":"482.99"}, {"price":"0.35", "size":"107.4"}, {"price":"0.34", "size":"133.24"}, {"price":"0.33", "size":"302.58"}, {"price":"0.32", "size":"93.19"}, {"price":"0.31", "size":"85.7"}, {"price":"0.3", "size":"82.04"}, {"price":"0.29", "size":"99"}, {"price":"0.28", "size":"313.22"}, {"price":"0.27", "size":"159.41"}, {"price":"0.26", "size":"151.85"}, {"price":"0.25", "size":"162.84"}, {"price":"0.24", "size":"170.24"}, {"price":"0.23", "size":"189.66"}, {"price":"0.22", "size":"213.41"}, {"price":"0.21", "size":"118.19"}, {"price":"0.2", "size":"158.28"}, {"price":"0.19", "size":"392.9"}], "hash":"1716570ecebba959cdeef59f7992116cc6891f01", "timestamp":"1784449596344", "event_type":"book"}
{"market":"0x982eae4503214e5d7992668e93f48f42e4707b92e23bb45f8d52d321f643cbe3", "price_changes":[{"asset_id":"74913635031537477155015393896000154190746945075332596665612975928350948042868", "price":"0.79", "size":"98.19", "side":"BUY", "hash":"232faf5e9147daae3c871e388d6714472cf253ce", "best_bid":"0.81", "best_ask":"0.82"}, {"asset_id":"37613674580450069178400687025689415665506452565086963049482350052080099056186", "price":"0.21", "size":"98.19", "side":"SELL", "hash":"7ca906718c0e09f26df574272a5cea88521cdf67", "best_bid":"0.18", "best_ask":"0.19"}], "timestamp":"1784449596347", "event_type":"price_change"}
{"market":"0x982eae4503214e5d7992668e93f48f42e4707b92e23bb45f8d52d321f643cbe3", "price_changes":[{"asset_id":"74913635031537477155015393896000154190746945075332596665612975928350948042868", "price":"0.01", "size":"16284.13", "side":"BUY", "hash":"1832744fc209aa9dc612cf070eece243bf0b8930", "best_bid":"0.81", "best_ask":"0.82"}, {"asset_id":"37613674580450069178400687025689415665506452565086963049482350052080099056186", "price":"0.99", "size":"16284.13", "side":"SELL", "hash":"516c309a7c94d6de5e6616b4b5de005d920d51e1", "best_bid":"0.18", "best_ask":"0.19"}], "timestamp":"1784449596350", "event_type":"price_change"}
{"market":"0x982eae4503214e5d7992668e93f48f42e4707b92e23bb45f8d52d321f643cbe3", "price_changes":[{"asset_id":"74913635031537477155015393896000154190746945075332596665612975928350948042868", "price":"0.03", "size":"2085.95", "side":"BUY", "hash":"8244fe5316887787392574eae7a419d0db21f065", "best_bid":"0.81", "best_ask":"0.82"}, {"asset_id":"37613674580450069178400687025689415665506452565086963049482350052080099056186", "price":"0.97", "size":"2085.95", "side":"SELL", "hash":"f3d78baac8244df97337ce7b72ed05a293042941", "best_bid":"0.18", "best_ask":"0.19"}], "timestamp":"1784449596355", "event_type":"price_change"}
{"market":"0x982eae4503214e5d7992668e93f48f42e4707b92e23bb45f8d52d321f643cbe3", "price_changes":[{"asset_id":"74913635031537477155015393896000154190746945075332596665612975928350948042868", "price":"0.01", "size":"16289.13", "side":"BUY", "hash":"0c2daf13a495b01f00cffb59e15e3b667fd9839d", "best_bid":"0.81", "best_ask":"0.82"}, {"asset_id":"37613674580450069178400687025689415665506452565086963049482350052080099056186", "price":"0.99", "size":"16289.13", "side":"SELL", "hash":"979d619523a1daded07bea9f0b7f71fffb936bf6", "best_bid":"0.18", "best_ask":"0.19"}], "timestamp":"1784449596360", "event_type":"price_change"}
{"market":"0x982eae4503214e5d7992668e93f48f42e4707b92e23bb45f8d52d321f643cbe3", "price_changes":[{"asset_id":"74913635031537477155015393896000154190746945075332596665612975928350948042868", "price":"0.68", "size":"118.19", "side":"BUY", "hash":"5ce64dd87399176bd807a0162142223e735274ac", "best_bid":"0.81", "best_ask":"0.82"}, {"asset_id":"37613674580450069178400687025689415665506452565086963049482350052080099056186", "price":"0.32", "size":"118.19", "side":"SELL", "hash":"12b0684b6b70678a12dc98a3cec974458206a04a", "best_bid":"0.18", "best_ask":"0.19"}], "timestamp":"1784449596372", "event_type":"price_change"}
{"market":"0x982eae4503214e5d7992668e93f48f42e4707b92e23bb45f8d52d321f643cbe3", "price_changes":[{"asset_id":"74913635031537477155015393896000154190746945075332596665612975928350948042868", "price":"0.01", "size":"16284.13", "side":"BUY", "hash":"39ee9cb7347dc07b93d7584f4f632db7f2d3451e", "best_bid":"0.81", "best_ask":"0.82"}, {"asset_id":"37613674580450069178400687025689415665506452565086963049482350052080099056186", "price":"0.99", "size":"16284.13", "side":"SELL", "hash":"1f4cc26c02238e3c97b68be03ff3757b55781f68", "best_bid":"0.18", "best_ask":"0.19"}], "timestamp":"1784449596382", "event_type":"price_change"}
{"market":"0x982eae4503214e5d7992668e93f48f42e4707b92e23bb45f8d52d321f643cbe3", "price_changes":[{"asset_id":"74913635031537477155015393896000154190746945075332596665612975928350948042868", "price":"0.01", "size":"16184.13", "side":"BUY", "hash":"856351506ac8ac8e5c3b2b8ab5be2404b7283917", "best_bid":"0.81", "best_ask":"0.82"}, {"asset_id":"37613674580450069178400687025689415665506452565086963049482350052080099056186", "price":"0.99", "size":"16184.13", "side":"SELL", "hash":"393d05873a816164a71bd82439f63057f88d0047", "best_bid":"0.18", "best_ask":"0.19"}], "timestamp":"1784449596387", "event_type":"price_change"}
{"market":"0x982eae4503214e5d7992668e93f48f42e4707b92e23bb45f8d52d321f643cbe3", "price_changes":[{"asset_id":"74913635031537477155015393896000154190746945075332596665612975928350948042868", "price":"0.68", "size":"93.19", "side":"BUY", "hash":"6e3d9ab477fcb8e30a4809e19746bf69f12eacb7", "best_bid":"0.81", "best_ask":"0.82"}, {"asset_id":"37613674580450069178400687025689415665506452565086963049482350052080099056186", "price":"0.32", "size":"93.19", "side":"SELL", "hash":"238fa29f453204ff82016099b6bf9c3a47aa0039", "best_bid":"0.18", "best_ask":"0.19"}], "timestamp":"1784449596391", "event_type":"price_change"}
{"market":"0x982eae4503214e5d7992668e93f48f42e4707b92e23bb45f8d52d321f643cbe3", "price_changes":[{"asset_id":"74913635031537477155015393896000154190746945075332596665612975928350948042868", "price":"0.69", "size":"110.7", "side":"BUY", "hash":"bfe5dfdc8ee589337d60747e4a1c0ab778a9093b", "best_bid":"0.81", "best_ask":"0.82"}, {"asset_id":"37613674580450069178400687025689415665506452565086963049482350052080099056186", "price":"0.31", "size":"110.7", "side":"SELL", "hash":"01be40634a7b998d046da115fc0f663fe707fabb", "best_bid":"0.18", "best_ask":"0.19"}], "timestamp":"1784449596401", "event_type":"price_change"}
{"market":"0x982eae4503214e5d7992668e93f48f42e4707b92e23bb45f8d52d321f643cbe3", "price_changes":[{"asset_id":"74913635031537477155015393896000154190746945075332596665612975928350948042868", "price":"0.01", "size":"16684.13", "side":"BUY", "hash":"bde2a0f876949c2c44c72162ad63dd7f207e3ccc", "best_bid":"0.81", "best_ask":"0.82"}, {"asset_id":"37613674580450069178400687025689415665506452565086963049482350052080099056186", "price":"0.99", "size":"16684.13", "side":"SELL", "hash":"1c003f695839950eb7ab86789b6f4db19ff0173a", "best_bid":"0.18", "best_ask":"0.19"}], "timestamp":"1784449596404", "event_type":"price_change"}
{"market":"0x982eae4503214e5d7992668e93f48f42e4707b92e23bb45f8d52d321f643cbe3", "price_changes":[{"asset_id":"74913635031537477155015393896000154190746945075332596665612975928350948042868", "price":"0.69", "size":"85.7", "side":"BUY", "hash":"6b410a5c85bd0d36bf5256e01194a4f8157d7e84", "best_bid":"0.81", "best_ask":"0.82"}, {"asset_id":"37613674580450069178400687025689415665506452565086963049482350052080099056186", "price":"0.31", "size":"85.7", "side":"SELL", "hash":"31140c960076019feb0cc7da30a205b751c82a38", "best_bid":"0.18", "best_ask":"0.19"}], "timestamp":"1784449596413", "event_type":"price_change"}
{"market":"0x982eae4503214e5d7992668e93f48f42e4707b92e23bb45f8d52d321f643cbe3", "price_changes":[{"asset_id":"74913635031537477155015393896000154190746945075332596665612975928350948042868", "price":"0.68", "size":"118.19", "side":"BUY", "hash":"7b59980086ffc9e2b5af1d514b7e5c96090473cd", "best_bid":"0.81", "best_ask":"0.82"}, {"asset_id":"37613674580450069178400687025689415665506452565086963049482350052080099056186", "price":"0.32", "size":"118.19", "side":"SELL", "hash":"d43e57d8132adf17baf1558282e47742d028145b", "best_bid":"0.18", "best_ask":"0.19"}], "timestamp":"1784449596416", "event_type":"price_change"}
{"market":"0x982eae4503214e5d7992668e93f48f42e4707b92e23bb45f8d52d321f643cbe3", "price_changes":[{"asset_id":"74913635031537477155015393896000154190746945075332596665612975928350948042868", "price":"0.01", "size":"16679.13", "side":"BUY", "hash":"61cb18e2fa585bdf32acd2dca2d0d38384dcdd91", "best_bid":"0.81", "best_ask":"0.82"}, {"asset_id":"37613674580450069178400687025689415665506452565086963049482350052080099056186", "price":"0.99", "size":"16679.13", "side":"SELL", "hash":"a66b46c4e3df8437f872b66447d4fb8d2a03c4da", "best_bid":"0.18", "best_ask":"0.19"}], "timestamp":"1784449596419", "event_type":"price_change"}
{"market":"0x982eae4503214e5d7992668e93f48f42e4707b92e23bb45f8d52d321f643cbe3", "price_changes":[{"asset_id":"37613674580450069178400687025689415665506452565086963049482350052080099056186", "price":"0.07", "size":"1367.2", "side":"BUY", "hash":"1f69e047bd6d84ee855d7a3d83a62cdb2342cd3c", "best_bid":"0.18", "best_ask":"0.19"}, {"asset_id":"74913635031537477155015393896000154190746945075332596665612975928350948042868", "price":"0.93", "size":"1367.2", "side":"SELL", "hash":"2f6c5e08fc90bc2d434c7472ff8e1706601ca039", "best_bid":"0.81", "best_ask":"0.82"}], "timestamp":"1784449596423", "event_type":"price_change"}
{"market":"0x982eae4503214e5d7992668e93f48f42e4707b92e23bb45f8d52d321f643cbe3", "price_changes":[{"asset_id":"74913635031537477155015393896000154190746945075332596665612975928350948042868", "price":"0.01", "size":"16779.13", "side":"BUY", "hash":"f7b2d918f3b7b09ca1dc981b2edc7082cb8cff53", "best_bid":"0.81", "best_ask":"0.82"}, {"asset_id":"37613674580450069178400687025689415665506452565086963049482350052080099056186", "price":"0.99", "size":"16779.13", "side":"SELL", "hash":"fc63cedca3529a9724dd3ab50b1e67e599ca9b58", "best_bid":"0.18", "best_ask":"0.19"}], "timestamp":"1784449596425", "event_type":"price_change"}
{"market":"0x982eae4503214e5d7992668e93f48f42e4707b92e23bb45f8d52d321f643cbe3", "price_changes":[{"asset_id":"74913635031537477155015393896000154190746945075332596665612975928350948042868", "price":"0.01", "size":"16784.13", "side":"BUY", "hash":"791d298fe2f78e7c573a3d5e1a7860fbc59c0cbb", "best_bid":"0.81", "best_ask":"0.82"}, {"asset_id":"37613674580450069178400687025689415665506452565086963049482350052080099056186", "price":"0.99", "size":"16784.13", "side":"SELL", "hash":"be39e08d1e6777deaa29d95db2ea85dabc3d1355", "best_bid":"0.18", "best_ask":"0.19"}], "timestamp":"1784449596425", "event_type":"price_change"}
{"market":"0x982eae4503214e5d7992668e93f48f42e4707b92e23bb45f8d52d321f643cbe3", "price_changes":[{"asset_id":"74913635031537477155015393896000154190746945075332596665612975928350948042868", "price":"0.01", "size":"16884.13", "side":"BUY", "hash":"99942574d1083b2825116cbd3a05f9a2958a09b1", "best_bid":"0.81", "best_ask":"0.82"}, {"asset_id":"37613674580450069178400687025689415665506452565086963049482350052080099056186", "price":"0.99", "size":"16884.13", "side":"SELL", "hash":"ebb7c545b6b19c1f6d2b6da56e17e47d8a59bec0", "best_bid":"0.18", "best_ask":"0.19"}], "timestamp":"1784449596426", "event_type":"price_change"}
{"market":"0x982eae4503214e5d7992668e93f48f42e4707b92e23bb45f8d52d321f643cbe3", "price_changes":[{"asset_id":"74913635031537477155015393896000154190746945075332596665612975928350948042868", "price":"0.01", "size":"16889.13", "side":"BUY", "hash":"5971cabc144ec1a9951ef715e1fe5f8fdc9e6890", "best_bid":"0.81", "best_ask":"0.82"}, {"asset_id":"37613674580450069178400687025689415665506452565086963049482350052080099056186", "price":"0.99", "size":"16889.13", "side":"SELL", "hash":"65b7e424dd9bfb9655b03e9d40fe1ef4e52b16b8", "best_bid":"0.18", "best_ask":"0.19"}], "timestamp":"1784449596427", "event_type":"price_change"}
{"market":"0x982eae4503214e5d7992668e93f48f42e4707b92e23bb45f8d52d321f643cbe3", "price_changes":[{"asset_id":"37613674580450069178400687025689415665506452565086963049482350052080099056186", "price":"0.01", "size":"17924.98", "side":"BUY", "hash":"2a2f89eb9b885dd5c51d44681b04ba17499fc9b1", "best_bid":"0.18", "best_ask":"0.19"}, {"asset_id":"74913635031537477155015393896000154190746945075332596665612975928350948042868", "price":"0.99", "size":"17924.98", "side":"SELL", "hash":"d779738343fc7b9846315a83c2ed6ce7780e5d97", "best_bid":"0.81", "best_ask":"0.82"}], "timestamp":"1784449596428", "event_type":"price_change"}
{"market":"0x982eae4503214e5d7992668e93f48f42e4707b92e23bb45f8d52d321f643cbe3", "price_changes":[{"asset_id":"74913635031537477155015393896000154190746945075332596665612975928350948042868", "price":"0.01", "size":"16884.13", "side":"BUY", "hash":"10cca7d3f34f5ed2970e8dd0a093412ad7203c13", "best_bid":"0.81", "best_ask":"0.82"}, {"asset_id":"37613674580450069178400687025689415665506452565086963049482350052080099056186", "price":"0.99", "size":"16884.13", "side":"SELL", "hash":"09e213e0423d76f34303f676b518388dd09598cd", "best_bid":"0.18", "best_ask":"0.19"}], "timestamp":"1784449596428", "event_type":"price_change"}
{"market":"0x982eae4503214e5d7992668e93f48f42e4707b92e23bb45f8d52d321f643cbe3", "price_changes":[{"asset_id":"74913635031537477155015393896000154190746945075332596665612975928350948042868", "price":"0.01", "size":"16984.13", "side":"BUY", "hash":"1e868fa7c7328d33735a8193437e3fe775477ad6", "best_bid":"0.81", "best_ask":"0.82"}, {"asset_id":"37613674580450069178400687025689415665506452565086963049482350052080099056186", "price":"0.99", "size":"16984.13", "side":"SELL", "hash":"85b7c54195791b01f5c8e1a49862107a16dc47d3", "best_bid":"0.18", "best_ask":"0.19"}], "timestamp":"1784449596428", "event_type":"price_change"}
{"market":"0x982eae4503214e5d7992668e93f48f42e4707b92e23bb45f8d52d321f643cbe3", "price_changes":[{"asset_id":"37613674580450069178400687025689415665506452565086963049482350052080099056186", "price":"0.01", "size":"17929.98", "side":"BUY", "hash":"f20ba3bae0da033951e510bf6bfd4a38a398d43e", "best_bid":"0.18", "best_ask":"0.19"}, {"asset_id":"74913635031537477155015393896000154190746945075332596665612975928350948042868", "price":"0.99", "size":"17929.98", "side":"SELL", "hash":"9de936f3b23e59e633ac52919a59ea9844390f04", "best_bid":"0.81", "best_ask":"0.82"}], "timestamp":"1784449596429", "event_type":"price_change"}
{"market":"0x982eae4503214e5d7992668e93f48f42e4707b92e23bb45f8d52d321f643cbe3", "price_changes":[{"asset_id":"74913635031537477155015393896000154190746945075332596665612975928350948042868", "price":"0.01", "size":"16979.13", "side":"BUY", "hash":"729ddc80dc2d2762d68e57f2fa47c7bd092131a1", "best_bid":"0.81", "best_ask":"0.82"}, {"asset_id":"37613674580450069178400687025689415665506452565086963049482350052080099056186", "price":"0.99", "size":"16979.13", "side":"SELL", "hash":"dc88b93695b486ef2bba35f3474c4f2fab29dbb6", "best_bid":"0.18", "best_ask":"0.19"}], "timestamp":"1784449596429", "event_type":"price_change"}
{"market":"0x982eae4503214e5d7992668e93f48f42e4707b92e23bb45f8d52d321f643cbe3", "price_changes":[{"asset_id":"74913635031537477155015393896000154190746945075332596665612975928350948042868", "price":"0.01", "size":"16984.13", "side":"BUY", "hash":"c8274497f6248bca66427fed32d4d35a015a3e28", "best_bid":"0.81", "best_ask":"0.82"}, {"asset_id":"37613674580450069178400687025689415665506452565086963049482350052080099056186", "price":"0.99", "size":"16984.13", "side":"SELL", "hash":"3bd92e57bf93646dd35ae96d62bfe5bd460501de", "best_bid":"0.18", "best_ask":"0.19"}], "timestamp":"1784449596430", "event_type":"price_change"}
{"market":"0x982eae4503214e5d7992668e93f48f42e4707b92e23bb45f8d52d321f643cbe3", "price_changes":[{"asset_id":"74913635031537477155015393896000154190746945075332596665612975928350948042868", "price":"0.01", "size":"16989.13", "side":"BUY", "hash":"efce2dd8c0b37cf964688745ac70f79cf0547acc", "best_bid":"0.81", "best_ask":"0.82"}, {"asset_id":"37613674580450069178400687025689415665506452565086963049482350052080099056186", "price":"0.99", "size":"16989.13", "side":"SELL", "hash":"2b8115934ae402bd3e886d1fc898c56bd9bb7da0", "best_bid":"0.18", "best_ask":"0.19"}], "timestamp":"1784449596431", "event_type":"price_change"}
{"market":"0x982eae4503214e5d7992668e93f48f42e4707b92e23bb45f8d52d321f643cbe3", "price_changes":[{"asset_id":"37613674580450069178400687025689415665506452565086963049482350052080099056186", "price":"0.01", "size":"17934.98", "side":"BUY", "hash":"d0e8184d80cddcd4ad517210637f17f7016a3759", "best_bid":"0.18", "best_ask":"0.19"}, {"asset_id":"74913635031537477155015393896000154190746945075332596665612975928350948042868", "price":"0.99", "size":"17934.98", "side":"SELL", "hash":"ec8541ea84bef38949dbbf2ff1cd9b407a68a29d", "best_bid":"0.81", "best_ask":"0.82"}], "timestamp":"1784449596431", "event_type":"price_change"}
{"market":"0x982eae4503214e5d7992668e93f48f42e4707b92e23bb45f8d52d321f643cbe3", "price_changes":[{"asset_id":"74913635031537477155015393896000154190746945075332596665612975928350948042868", "price":"0.01", "size":"16489.13", "side":"BUY", "hash":"1d3cc36699cf55066da6ac6d2845cf1a41432f77", "best_bid":"0.81", "best_ask":"0.82"}, {"asset_id":"37613674580450069178400687025689415665506452565086963049482350052080099056186", "price":"0.99", "size":"16489.13", "side":"SELL", "hash":"29c044094305330a3eb63193b64f77092af0b677", "best_bid":"0.18", "best_ask":"0.19"}], "timestamp":"1784449596432", "event_type":"price_change"}
{"market":"0x982eae4503214e5d7992668e93f48f42e4707b92e23bb45f8d52d321f643cbe3", "price_changes":[{"asset_id":"74913635031537477155015393896000154190746945075332596665612975928350948042868", "price":"0.01", "size":"16589.13", "side":"BUY", "hash":"3903f9790b6b46df80ec0c5347c4c24d6844a3a7", "best_bid":"0.81", "best_ask":"0.82"}, {"asset_id":"37613674580450069178400687025689415665506452565086963049482350052080099056186", "price":"0.99", "size":"16589.13", "side":"SELL", "hash":"487553c459ce1a10547476129cc1e24492d98a11", "best_bid":"0.18", "best_ask":"0.19"}], "timestamp":"1784449596432", "event_type":"price_change"}
{"market":"0x982eae4503214e5d7992668e93f48f42e4707b92e23bb45f8d52d321f643cbe3", "price_changes":[{"asset_id":"74913635031537477155015393896000154190746945075332596665612975928350948042868", "price":"0.01", "size":"16574.13", "side":"BUY", "hash":"a8a580daae02c4f16af811bae12e0039df1758ab", "best_bid":"0.81", "best_ask":"0.82"}, {"asset_id":"37613674580450069178400687025689415665506452565086963049482350052080099056186", "price":"0.99", "size":"16574.13", "side":"SELL", "hash":"7c87874d00b57d90accc0766d3315ff7d775aa46", "best_bid":"0.18", "best_ask":"0.19"}], "timestamp":"1784449596434", "event_type":"price_change"}
{"market":"0x982eae4503214e5d7992668e93f48f42e4707b92e23bb45f8d52d321f643cbe3", "price_changes":[{"asset_id":"74913635031537477155015393896000154190746945075332596665612975928350948042868", "price":"0.92", "size":"1414.68", "side":"SELL", "hash":"a82dc523b5ce2c665b1e9ba97238367967d45549", "best_bid":"0.81", "best_ask":"0.82"}, {"asset_id":"37613674580450069178400687025689415665506452565086963049482350052080099056186", "price":"0.08", "size":"1414.68", "side":"BUY", "hash":"94bf6509b68f9f5abc2935b3ac3fe85d11e0a229", "best_bid":"0.18", "best_ask":"0.19"}], "timestamp":"1784449596437", "event_type":"price_change"}
{"market":"0x982eae4503214e5d7992668e93f48f42e4707b92e23bb45f8d52d321f643cbe3", "price_changes":[{"asset_id":"74913635031537477155015393896000154190746945075332596665612975928350948042868", "price":"0.01", "size":"16579.13", "side":"BUY", "hash":"e1f48f5520456c1793ac33e8b6a4f252990cfebd", "best_bid":"0.81", "best_ask":"0.82"}, {"asset_id":"37613674580450069178400687025689415665506452565086963049482350052080099056186", "price":"0.99", "size":"16579.13", "side":"SELL", "hash":"9cfff0973f7a26ef88903f35dd160381b50e6831", "best_bid":"0.18", "best_ask":"0.19"}], "timestamp":"1784449596439", "event_type":"price_change"}
{"market":"0x982eae4503214e5d7992668e93f48f42e4707b92e23bb45f8d52d321f643cbe3", "price_changes":[{"asset_id":"74913635031537477155015393896000154190746945075332596665612975928350948042868", "price":"0.01", "size":"16479.13", "side":"BUY", "hash":"15f4166a162ab498a0b3c34ee7a6f41b85bd56e5", "best_bid":"0.81", "best_ask":"0.82"}, {"asset_id":"37613674580450069178400687025689415665506452565086963049482350052080099056186", "price":"0.99", "size":"16479.13", "side":"SELL", "hash":"18ad8a8e4c28df3642c893606a883cc12fbc9f59", "best_bid":"0.18", "best_ask":"0.19"}], "timestamp":"1784449596445", "event_type":"price_change"}
{"market":"0x982eae4503214e5d7992668e93f48f42e4707b92e23bb45f8d52d321f643cbe3", "price_changes":[{"asset_id":"74913635031537477155015393896000154190746945075332596665612975928350948042868", "price":"0.01", "size":"16379.13", "side":"BUY", "hash":"a11c39dc6d39d5baa1c887cd3a49087708277926", "best_bid":"0.81", "best_ask":"0.82"}, {"asset_id":"37613674580450069178400687025689415665506452565086963049482350052080099056186", "price":"0.99", "size":"16379.13", "side":"SELL", "hash":"95ea496d50dcf8c07725d69333988cd29bab10c9", "best_bid":"0.18", "best_ask":"0.19"}], "timestamp":"1784449596449", "event_type":"price_change"}
{"market":"0x982eae4503214e5d7992668e93f48f42e4707b92e23bb45f8d52d321f643cbe3", "asset_id":"74913635031537477155015393896000154190746945075332596665612975928350948042868", "price":"0.82", "size":"6.61", "fee_rate_bps":"0", "side":"BUY", "timestamp":"1784449596452", "event_type":"last_trade_price", "transaction_hash":"0xc35bbd0b05c38820efd429f058212233bb5e65af1f3a07049a1e1a0444f0c74a"}
{"market":"0x982eae4503214e5d7992668e93f48f42e4707b92e23bb45f8d52d321f643cbe3", "price_changes":[{"asset_id":"74913635031537477155015393896000154190746945075332596665612975928350948042868", "price":"0.01", "size":"16279.13", "side":"BUY", "hash":"64e698226e7cbdfcbe42b0c6dacef058f10bfe97", "best_bid":"0.81", "best_ask":"0.82"}, {"asset_id":"37613674580450069178400687025689415665506452565086963049482350052080099056186", "price":"0.99", "size":"16279.13", "side":"SELL", "hash":"9d2772669e33e05f5b70fde3428e90a02fe2eabc", "best_bid":"0.18", "best_ask":"0.19"}], "timestamp":"1784449596454", "event_type":"price_change"}
{"market":"0x982eae4503214e5d7992668e93f48f42e4707b92e23bb45f8d52d321f643cbe3", "price_changes":[{"asset_id":"74913635031537477155015393896000154190746945075332596665612975928350948042868", "price":"0.01", "size":"16274.13", "side":"BUY", "hash":"0a17ab248d45ba1d081ecbba89eb67d80b7d0214", "best_bid":"0.81", "best_ask":"0.82"}, {"asset_id":"37613674580450069178400687025689415665506452565086963049482350052080099056186", "price":"0.99", "size":"16274.13", "side":"SELL", "hash":"03e2f9efa3db92972ee264d5d46ab711629a6c4e", "best_bid":"0.18", "best_ask":"0.19"}], "timestamp":"1784449596455", "event_type":"price_change"}
{"market":"0x982eae4503214e5d7992668e93f48f42e4707b92e23bb45f8d52d321f643cbe3", "price_changes":[{"asset_id":"74913635031537477155015393896000154190746945075332596665612975928350948042868", "price":"0.75", "size":"182.84", "side":"BUY", "hash":"9592f969b53a9789eeea6505bd4f8b1cf16fb451", "best_bid":"0.81", "best_ask":"0.82"}, {"asset_id":"37613674580450069178400687025689415665506452565086963049482350052080099056186", "price":"0.25", "size":"182.84", "side":"SELL", "hash":"1472013b7b5f697d65a44ef36fd86a7bceca17f4", "best_bid":"0.18", "best_ask":"0.19"}], "timestamp":"1784449596459", "event_type":"price_change"}
{"market":"0x982eae4503214e5d7992668e93f48f42e4707b92e23bb45f8d52d321f643cbe3", "price_changes":[{"asset_id":"74913635031537477155015393896000154190746945075332596665612975928350948042868", "price":"0.68", "size":"93.19", "side":"BUY", "hash":"f8b426efa5f716c886ec408ce5d1f6d76ce4fe5a", "best_bid":"0.81", "best_ask":"0.82"}, {"asset_id":"37613674580450069178400687025689415665506452565086963049482350052080099056186", "price":"0.32", "size":"93.19", "side":"SELL", "hash":"a20e2bfb5a292685a9379001d078c92f46aded71", "best_bid":"0.18", "best_ask":"0.19"}], "timestamp":"1784449596459", "event_type":"price_change"}
{"market":"0x982eae4503214e5d7992668e93f48f42e4707b92e23bb45f8d52d321f643cbe3", "price_changes":[{"asset_id":"74913635031537477155015393896000154190746945075332596665612975928350948042868", "price":"0.01", "size":"16279.14", "side":"BUY", "hash":"d62b6682baecb91db2e64c2985cfad68f4317803", "best_bid":"0.81", "best_ask":"0.82"}, {"asset_id":"37613674580450069178400687025689415665506452565086963049482350052080099056186", "price":"0.99", "size":"16279.14", "side":"SELL", "hash":"c09539abf7f88ca00cba86c05aef2fa062ea3016", "best_bid":"0.18", "best_ask":"0.19"}], "timestamp":"1784449596461", "event_type":"price_change"}
{"market":"0x982eae4503214e5d7992668e93f48f42e4707b92e23bb45f8d52d321f643cbe3", "price_changes":[{"asset_id":"74913635031537477155015393896000154190746945075332596665612975928350948042868", "price":"0.69", "size":"110.7", "side":"BUY", "hash":"83bf2ca681fe3ff16891c97fd136542416c79733", "best_bid":"0.81", "best_ask":"0.82"}, {"asset_id":"37613674580450069178400687025689415665506452565086963049482350052080099056186", "price":"0.31", "size":"110.7", "side":"SELL", "hash":"e0a87738865a2d4b90cb4b8a6197aaf181c3f429", "best_bid":"0.18", "best_ask":"0.19"}], "timestamp":"1784449596462", "event_type":"price_change"}
{"market":"0x982eae4503214e5d7992668e93f48f42e4707b92e23bb45f8d52d321f643cbe3", "price_changes":[{"asset_id":"37613674580450069178400687025689415665506452565086963049482350052080099056186", "price":"0.15", "size":"136.71", "side":"BUY", "hash":"4efacfb8be36e256f46144fa8efd131b7998c42d", "best_bid":"0.18", "best_ask":"0.19"}, {"asset_id":"74913635031537477155015393896000154190746945075332596665612975928350948042868", "price":"0.85", "size":"136.71", "side":"SELL", "hash":"31f92b9cf5ea59e8fee0fd52f4ef90c8a3d7d352", "best_bid":"0.81", "best_ask":"0.82"}], "timestamp":"1784449596463", "event_type":"price_change"}
{"market":"0x982eae4503214e5d7992668e93f48f42e4707b92e23bb45f8d52d321f643cbe3", "price_changes":[{"asset_id":"74913635031537477155015393896000154190746945075332596665612975928350948042868", "price":"0.01", "size":"16179.14", "side":"BUY", "hash":"69f60130513070db852a2a48a72a238f365a9ee9", "best_bid":"0.81", "best_ask":"0.82"}, {"asset_id":"37613674580450069178400687025689415665506452565086963049482350052080099056186", "price":"0.99", "size":"16179.14", "side":"SELL", "hash":"3d7f0a63c8e4e473ee8b6a05db915bf8dd2fb20e", "best_bid":"0.18", "best_ask":"0.19"}], "timestamp":"1784449596467", "event_type":"price_change"}
{"market":"0x982eae4503214e5d7992668e93f48f42e4707b92e23bb45f8d52d321f643cbe3", "price_changes":[{"asset_id":"74913635031537477155015393896000154190746945075332596665612975928350948042868", "price":"0.69", "size":"85.7", "side":"BUY", "hash":"b1ebf90537e9f7444e7e54fa98fe00f481d37c77", "best_bid":"0.81", "best_ask":"0.82"}, {"asset_id":"37613674580450069178400687025689415665506452565086963049482350052080099056186", "price":"0.31", "size":"85.7", "side":"SELL", "hash":"8e63aa34b40674f74dfc791bc1587af7b5115851", "best_bid":"0.18", "best_ask":"0.19"}], "timestamp":"1784449596484", "event_type":"price_change"}
{"market":"0x982eae4503214e5d7992668e93f48f42e4707b92e23bb45f8d52d321f643cbe3", "price_changes":[{"asset_id":"74913635031537477155015393896000154190746945075332596665612975928350948042868", "price":"0.68", "size":"118.19", "side":"BUY", "hash":"9403781ac5db242378e7d55c41719749e82be27c", "best_bid":"0.81", "best_ask":"0.82"}, {"asset_id":"37613674580450069178400687025689415665506452565086963049482350052080099056186", "price":"0.32", "size":"118.19", "side":"SELL", "hash":"7e6530e692c90f825352956b783cd9fcd6cf998f", "best_bid":"0.18", "best_ask":"0.19"}], "timestamp":"1784449596485", "event_type":"price_change"}
{"market":"0x982eae4503214e5d7992668e93f48f42e4707b92e23bb45f8d52d321f643cbe3", "price_changes":[{"asset_id":"74913635031537477155015393896000154190746945075332596665612975928350948042868", "price":"0.01", "size":"16174.14", "side":"BUY", "hash":"8522660b67d42aebac2273f21ec3c40fbf65862a", "best_bid":"0.81", "best_ask":"0.82"}, {"asset_id":"37613674580450069178400687025689415665506452565086963049482350052080099056186", "price":"0.99", "size":"16174.14", "side":"SELL", "hash":"c8f493331d7264e5889b9013226e5cafb8de3912", "best_bid":"0.18", "best_ask":"0.19"}], "timestamp":"1784449596489", "event_type":"price_change"}
{"market":"0x982eae4503214e5d7992668e93f48f42e4707b92e23bb45f8d52d321f643cbe3", "price_changes":[{"asset_id":"74913635031537477155015393896000154190746945075332596665612975928350948042868", "price":"0.01", "size":"16169.13", "side":"BUY", "hash":"d57ab07fbd604a4af9642a21b2b0a8133c3ad368", "best_bid":"0.81", "best_ask":"0.82"}, {"asset_id":"37613674580450069178400687025689415665506452565086963049482350052080099056186", "price":"0.99", "size":"16169.13", "side":"SELL", "hash":"c16a7b5582768f14d43178444fc6bb892d142122", "best_bid":"0.18", "best_ask":"0.19"}], "timestamp":"1784449596489", "event_type":"price_change"}
{"market":"0x982eae4503214e5d7992668e93f48f42e4707b92e23bb45f8d52d321f643cbe3", "price_changes":[{"asset_id":"74913635031537477155015393896000154190746945075332596665612975928350948042868", "price":"0.01", "size":"16669.13", "side":"BUY", "hash":"a8ef5bce281c095fd6a59ee5467daa18179a9778", "best_bid":"0.81", "best_ask":"0.82"}, {"asset_id":"37613674580450069178400687025689415665506452565086963049482350052080099056186", "price":"0.99", "size":"16669.13", "side":"SELL", "hash":"150c4c3c9d6212a167eb610f6d2273ffea5310ad", "best_bid":"0.18", "best_ask":"0.19"}], "timestamp":"1784449596500", "event_type":"price_change"}
{"market":"0x982eae4503214e5d7992668e93f48f42e4707b92e23bb45f8d52d321f643cbe3", "price_changes":[{"asset_id":"74913635031537477155015393896000154190746945075332596665612975928350948042868", "price":"0.81", "size":"391.02", "side":"BUY", "hash":"63cd1fedb1ef9e7e236327250b574b5f91d55ffa", "best_bid":"0.81", "best_ask":"0.82"}, {"asset_id":"37613674580450069178400687025689415665506452565086963049482350052080099056186", "price":"0.19", "size":"391.02", "side":"SELL", "hash":"94ee3d6dd63a657f92234e597e64a100a2e1f276", "best_bid":"0.18", "best_ask":"0.19"}], "timestamp":"1784449596508", "event_type":"price_change"}
{"market":"0x982eae4503214e5d7992668e93f48f42e4707b92e23bb45f8d52d321f643cbe3", "asset_id":"74913635031537477155015393896000154190746945075332596665612975928350948042868", "bids":[{"price":"0.01", "size":"16669.13"}, {"price":"0.02", "size":"3289.11"}, {"price":"0.03", "size":"2085.95"}, {"price":"0.04", "size":"1462.1"}, {"price":"0.05", "size":"1953.67"}, {"price":"0.06", "size":"1677.35"}, {"price":"0.07", "size":"1155.2"}, {"price":"0.08", "size":"1325.88"}, {"price":"0.09", "size":"1027.7"}, {"price":"0.1", "size":"528.2"}, {"price":"0.11", "size":"454.1"}, {"price":"0.12", "size":"203.05"}, {"price":"0.13", "size":"179.4"}, {"price":"0.14", "size":"159.4"}, {"price":"0.15", "size":"149.23"}, {"price":"0.16", "size":"150.4"}, {"price":"0.17", "size":"105.08"}, {"price":"0.18", "size":"127.3"}, {"price":"0.19", "size":"99.78"}, {"price":"0.2", "size":"181.4"}, {"price":"0.21", "size":"111.5"}, {"price":"0.22", "size":"125.7"}, {"price":"0.23", "size":"92"}, {"price":"0.24", "size":"111.5"}, {"price":"0.25", "size":"823.6"}, {"price":"0.26", "size":"128.8"}, {"price":"0.27", "size":"86.7"}, {"price":"0.28", "size":"106.67"}, {"price":"0.29", "size":"84.59"}, {"price":"0.3", "size":"107.8"}, {"price":"0.31", "size":"79.1"}, {"price":"0.32", "size":"107.19"}, {"price":"0.33", "size":"76.7"}, {"price":"0.34", "size":"89"}, {"price":"0.35", "size":"84.4"}, {"price":"0.36", "size":"86.99"}, {"price":"0.37", "size":"73.6"}, {"price":"0.38", "size":"85"}, {"price":"0.39", "size":"71.6"}, {"price":"0.4", "size":"88.3"}, {"price":"0.41", "size":"69.9"}, {"price":"0.42", "size":"142.27"}, {"price":"0.43", "size":"86.5"}, {"price":"0.44", "size":"91.08"}, {"price":"0.45", "size":"104.31"}, {"price":"0.46", "size":"80.1"}, {"price":"0.47", "size":"94.9"}, {"price":"0.48", "size":"88.8"}, {"price":"0.49", "size":"99.36"}, {"price":"0.5", "size":"102.8"}, {"price":"0.51", "size":"100.8"}, {"price":"0.52", "size":"100.8"}, {"price":"0.53", "size":"99.9"}, {"price":"0.54", "size":"92.1"}, {"price":"0.55", "size":"485.2"}, {"price":"0.56", "size":"95.4"}, {"price":"0.57", "size":"85.5"}, {"price":"0.58", "size":"111.12"}, {"price":"0.59", "size":"94.9"}, {"price":"0.6", "size":"193.58"}, {"price":"0.61", "size":"105.6"}, {"price":"0.62", "size":"125"}, {"price":"0.63", "size":"150.6"}, {"price":"0.64", "size":"482.99"}, {"price":"0.65", "size":"107.4"}, {"price":"0.66", "size":"133.24"}, {"price":"0.67", "size":"302.58"}, {"price":"0.68", "size":"118.19"}, {"price":"0.69", "size":"85.7"}, {"price":"0.7", "size":"82.04"}, {"price":"0.71", "size":"99"}, {"price":"0.72", "size":"313.22"}, {"price":"0.73", "size":"159.41"}, {"price":"0.74", "size":"151.85"}, {"price":"0.75", "size":"182.84"}, {"price":"0.76", "size":"170.24"}, {"price":"0.77", "size":"189.66"}, {"price":"0.78", "size":"213.41"}, {"price":"0.79", "size":"98.19"}, {"price":"0.8", "size":"158.28"}, {"price":"0.81", "size":"391.02"}], "asks":[{"price":"0.99", "size":"17934.98"}, {"price":"0.98", "size":"3156.06"}, {"price":"0.97", "size":"3788.29"}, {"price":"0.96", "size":"1529.1"}, {"price":"0.95", "size":"1723.6"}, {"price":"0.94", "size":"1201.35"}, {"price":"0.93", "size":"1367.2"}, {"price":"0.92", "size":"1414.68"}, {"price":"0.91", "size":"942.82"}, {"price":"0.9", "size":"518.32"}, {"price":"0.89", "size":"490.73"}, {"price":"0.88", "size":"207.17"}, {"price":"0.87", "size":"426.4"}, {"price":"0.86", "size":"184.34"}, {"price":"0.85", "size":"136.71"}, {"price":"0.84", "size":"91.17"}, {"price":"0.83", "size":"16.31"}, {"price":"0.82", "size":"7.03"}], "hash":"63cd1fedb1ef9e7e236327250b574b5f91d55ffa", "timestamp":"1784449596508", "event_type":"book"}
{"market":"0x982eae4503214e5d7992668e93f48f42e4707b92e23bb45f8d52d321f643cbe3", "asset_id":"37613674580450069178400687025689415665506452565086963049482350052080099056186", "bids":[{"price":"0.01", "size":"17934.98"}, {"price":"0.02", "size":"3156.06"}, {"price":"0.03", "size":"3788.29"}, {"price":"0.04", "size":"1529.1"}, {"price":"0.05", "size":"1723.6"}, {"price":"0.06", "size":"1201.35"}, {"price":"0.07", "size":"1367.2"}, {"price":"0.08", "size":"1414.68"}, {"price":"0.09", "size":"942.82"}, {"price":"0.1", "size":"518.32"}, {"price":"0.11", "size":"490.73"}, {"price":"0.12", "size":"207.17"}, {"price":"0.13", "size":"426.4"}, {"price":"0.14", "size":"184.34"}, {"price":"0.15", "size":"136.71"}, {"price":"0.16", "size":"91.17"}, {"price":"0.17", "size":"16.31"}, {"price":"0.18", "size":"7.03"}], "asks":[{"price":"0.99", "size":"16669.13"}, {"price":"0.98", "size":"3289.11"}, {"price":"0.97", "size":"2085.95"}, {"price":"0.96", "size":"1462.1"}, {"price":"0.95", "size":"1953.67"}, {"price":"0.94", "size":"1677.35"}, {"price":"0.93", "size":"1155.2"}, {"price":"0.92", "size":"1325.88"}, {"price":"0.91", "size":"1027.7"}, {"price":"0.9", "size":"528.2"}, {"price":"0.89", "size":"454.1"}, {"price":"0.88", "size":"203.05"}, {"price":"0.87", "size":"179.4"}, {"price":"0.86", "size":"159.4"}, {"price":"0.85", "size":"149.23"}, {"price":"0.84", "size":"150.4"}, {"price":"0.83", "size":"105.08"}, {"price":"0.82", "size":"127.3"}, {"price":"0.81", "size":"99.78"}, {"price":"0.8", "size":"181.4"}, {"price":"0.79", "size":"111.5"}, {"price":"0.78", "size":"125.7"}, {"price":"0.77", "size":"92"}, {"price":"0.76", "size":"111.5"}, {"price":"0.75", "size":"823.6"}, {"price":"0.74", "size":"128.8"}, {"price":"0.73", "size":"86.7"}, {"price":"0.72", "size":"106.67"}, {"price":"0.71", "size":"84.59"}, {"price":"0.7", "size":"107.8"}, {"price":"0.69", "size":"79.1"}, {"price":"0.68", "size":"107.19"}, {"price":"0.67", "size":"76.7"}, {"price":"0.66", "size":"89"}, {"price":"0.65", "size":"84.4"}, {"price":"0.64", "size":"86.99"}, {"price":"0.63", "size":"73.6"}, {"price":"0.62", "size":"85"}, {"price":"0.61", "size":"71.6"}, {"price":"0.6", "size":"88.3"}, {"price":"0.59", "size":"69.9"}, {"price":"0.58", "size":"142.27"}, {"price":"0.57", "size":"86.5"}, {"price":"0.56", "size":"91.08"}, {"price":"0.55", "size":"104.31"}, {"price":"0.54", "size":"80.1"}, {"price":"0.53", "size":"94.9"}, {"price":"0.52", "size":"88.8"}, {"price":"0.51", "size":"99.36"}, {"price":"0.5", "size":"102.8"}, {"price":"0.49", "size":"100.8"}, {"price":"0.48", "size":"100.8"}, {"price":"0.47", "size":"99.9"}, {"price":"0.46", "size":"92.1"}, {"price":"0.45", "size":"485.2"}, {"price":"0.44", "size":"95.4"}, {"price":"0.43", "size":"85.5"}, {"price":"0.42", "size":"111.12"}, {"price":"0.41", "size":"94.9"}, {"price":"0.4", "size":"193.58"}, {"price":"0.39", "size":"105.6"}, {"price":"0.38", "size":"125"}, {"price":"0.37", "size":"150.6"}, {"price":"0.36", "size":"482.99"}, {"price":"0.35", "size":"107.4"}, {"price":"0.34", "size":"133.24"}, {"price":"0.33", "size":"302.58"}, {"price":"0.32", "size":"118.19"}, {"price":"0.31", "size":"85.7"}, {"price":"0.3", "size":"82.04"}, {"price":"0.29", "size":"99"}, {"price":"0.28", "size":"313.22"}, {"price":"0.27", "size":"159.41"}, {"price":"0.26", "size":"151.85"}, {"price":"0.25", "size":"182.84"}, {"price":"0.24", "size":"170.24"}, {"price":"0.23", "size":"189.66"}, {"price":"0.22", "size":"213.41"}, {"price":"0.21", "size":"98.19"}, {"price":"0.2", "size":"158.28"}, {"price":"0.19", "size":"391.02"}], "hash":"94ee3d6dd63a657f92234e597e64a100a2e1f276", "timestamp":"1784449596508", "event_type":"book"}
{"market":"0x982eae4503214e5d7992668e93f48f42e4707b92e23bb45f8d52d321f643cbe3", "price_changes":[{"asset_id":"74913635031537477155015393896000154190746945075332596665612975928350948042868", "price":"0.01", "size":"16769.13", "side":"BUY", "hash":"0588f3181d81549c68a51c91e2411b32870e1ba2", "best_bid":"0.81", "best_ask":"0.82"}, {"asset_id":"37613674580450069178400687025689415665506452565086963049482350052080099056186", "price":"0.99", "size":"16769.13", "side":"SELL", "hash":"bd04b95998f969fbaa47797f22d21677e38ce382", "best_bid":"0.18", "best_ask":"0.19"}], "timestamp":"1784449596512", "event_type":"price_change"}
{"market":"0x982eae4503214e5d7992668e93f48f42e4707b92e23bb45f8d52d321f643cbe3", "price_changes":[{"asset_id":"74913635031537477155015393896000154190746945075332596665612975928350948042868", "price":"0.01", "size":"16269.13", "side":"BUY", "hash":"53865dca20ee76ecccd2392475e1304e5a51e209", "best_bid":"0.81", "best_ask":"0.82"}, {"asset_id":"37613674580450069178400687025689415665506452565086963049482350052080099056186", "price":"0.99", "size":"16269.13", "side":"SELL", "hash":"069bd3c38f64628273ddb49c76c3d4566a72aa6f", "best_bid":"0.18", "best_ask":"0.19"}], "timestamp":"1784449596528", "event_type":"price_change"}
{"market":"0x982eae4503214e5d7992668e93f48f42e4707b92e23bb45f8d52d321f643cbe3", "price_changes":[{"asset_id":"74913635031537477155015393896000154190746945075332596665612975928350948042868", "price":"0.28", "size":"100.6", "side":"BUY", "hash":"5cbb8a8c117412923d21d733c3eb6f63e8028d47", "best_bid":"0.81", "best_ask":"0.82"}, {"asset_id":"37613674580450069178400687025689415665506452565086963049482350052080099056186", "price":"0.72", "size":"100.6", "side":"SELL", "hash":"afc2bbcc9b4684e9f62fb0bcfc55074ebece6aee", "best_bid":"0.18", "best_ask":"0.19"}], "timestamp":"1784449596532", "event_type":"price_change"}
{"market":"0x982eae4503214e5d7992668e93f48f42e4707b92e23bb45f8d52d321f643cbe3", "price_changes":[{"asset_id":"74913635031537477155015393896000154190746945075332596665612975928350948042868", "price":"0.01", "size":"16169.13", "side":"BUY", "hash":"612c70a6b6ef74b1f8ce9769feef2bbc5dee2620", "best_bid":"0.81", "best_ask":"0.82"}, {"asset_id":"37613674580450069178400687025689415665506452565086963049482350052080099056186", "price":"0.99", "size":"16169.13", "side":"SELL", "hash":"29a68f03568bac1399e7cffacaa043e9c9fd29af", "best_bid":"0.18", "best_ask":"0.19"}], "timestamp":"1784449596546", "event_type":"price_change"}
{"market":"0x982eae4503214e5d7992668e93f48f42e4707b92e23bb45f8d52d321f643cbe3", "asset_id":"74913635031537477155015393896000154190746945075332596665612975928350948042868", "price":"0.81", "size":"1.88", "fee_rate_bps":"0", "side":"SELL", "timestamp":"1784449596557", "event_type":"last_trade_price", "transaction_hash":"0x61efc8afd97814bbcdc13313918cb6456b3321710350a98415fcdb9ae80bd01f"}
{"market":"0x982eae4503214e5d7992668e93f48f42e4707b92e23bb45f8d52d321f643cbe3", "price_changes":[{"asset_id":"74913635031537477155015393896000154190746945075332596665612975928350948042868", "price":"0.26", "size":"148.03", "side":"BUY", "hash":"963202e2af03520744e342d61b67fb22b7f0ad61", "best_bid":"0.81", "best_ask":"0.82"}, {"asset_id":"37613674580450069178400687025689415665506452565086963049482350052080099056186", "price":"0.74", "size":"148.03", "side":"SELL", "hash":"293ac34aee2efd5550112cce56bfaa467df60a62", "best_bid":"0.18", "best_ask":"0.19"}], "timestamp":"1784449596561", "event_type":"price_change"}
{"market":"0x982eae4503214e5d7992668e93f48f42e4707b92e23bb45f8d52d321f643cbe3", "price_changes":[{"asset_id":"37613674580450069178400687025689415665506452565086963049482350052080099056186", "price":"0.4", "size":"203.58", "side":"SELL", "hash":"1026267388b8741868903c707a4ee2d00c6af1df", "best_bid":"0.18", "best_ask":"0.19"}, {"asset_id":"74913635031537477155015393896000154190746945075332596665612975928350948042868", "price":"0.6", "size":"203.58", "side":"BUY", "hash":"aafb6095a7ec866b1251761ea2747eb33d7d006d", "best_bid":"0.81", "best_ask":"0.82"}], "timestamp":"1784449596571", "event_type":"price_change"}
{"market":"0x982eae4503214e5d7992668e93f48f42e4707b92e23bb45f8d52d321f643cbe3", "price_changes":[{"asset_id":"74913635031537477155015393896000154190746945075332596665612975928350948042868", "price":"0.75", "size":"172.84", "side":"BUY", "hash":"45915847579b6583f25c2355e3b7c85a9acec434", "best_bid":"0.81", "best_ask":"0.82"}, {"asset_id":"37613674580450069178400687025689415665506452565086963049482350052080099056186", "price":"0.25", "size":"172.84", "side":"SELL", "hash":"8b6e4c9bbc02c74e5638103702968189688c64cc", "best_bid":"0.18", "best_ask":"0.19"}], "timestamp":"1784449596571", "event_type":"price_change"}
{"market":"0x982eae4503214e5d7992668e93f48f42e4707b92e23bb45f8d52d321f643cbe3", "price_changes":[{"asset_id":"74913635031537477155015393896000154190746945075332596665612975928350948042868", "price":"0.04", "size":"1467.1", "side":"BUY", "hash":"45aee922151dddc45c20e7132db6fe55671a2304", "best_bid":"0.81", "best_ask":"0.82"}, {"asset_id":"37613674580450069178400687025689415665506452565086963049482350052080099056186", "price":"0.96", "size":"1467.1", "side":"SELL", "hash":"c269c0dc64226704fdbf08776928f9b5bcabc47d", "best_bid":"0.18", "best_ask":"0.19"}], "timestamp":"1784449596572", "event_type":"price_change"}
{"market":"0x982eae4503214e5d7992668e93f48f42e4707b92e23bb45f8d52d321f643cbe3", "price_changes":[{"asset_id":"74913635031537477155015393896000154190746945075332596665612975928350948042868", "price":"0.01", "size":"16269.13", "side":"BUY", "hash":"1cc1167f2699cd62d9994c4cf9547f88df0e4e25", "best_bid":"0.81", "best_ask":"0.82"}, {"asset_id":"37613674580450069178400687025689415665506452565086963049482350052080099056186", "price":"0.99", "size":"16269.13", "side":"SELL", "hash":"3d1290fb1d9ac9c934bf69beea8e2f1e932c28cf", "best_bid":"0.18", "best_ask":"0.19"}], "timestamp":"1784449596589", "event_type":"price_change"}
{"market":"0x982eae4503214e5d7992668e93f48f42e4707b92e23bb45f8d52d321f643cbe3", "price_changes":[{"asset_id":"74913635031537477155015393896000154190746945075332596665612975928350948042868", "price":"0.67", "size":"312.58", "side":"BUY", "hash":"74270312de8dc688e5e5b3e02a43f044e2d24bb8", "best_bid":"0.81", "best_ask":"0.82"}, {"asset_id":"37613674580450069178400687025689415665506452565086963049482350052080099056186", "price":"0.33", "size":"312.58", "side":"SELL", "hash":"47a53888797ad27899dbc9657fc33b663285ba19", "best_bid":"0.18", "best_ask":"0.19"}], "timestamp":"1784449596596", "event_type":"price_change"}
{"market":"0x982eae4503214e5d7992668e93f48f42e4707b92e23bb45f8d52d321f643cbe3", "price_changes":[{"asset_id":"74913635031537477155015393896000154190746945075332596665612975928350948042868", "price":"0.01", "size":"16769.13", "side":"BUY", "hash":"34c184f42c2c8aa10fae53234208877fd984832f", "best_bid":"0.81", "best_ask":"0.82"}, {"asset_id":"37613674580450069178400687025689415665506452565086963049482350052080099056186", "price":"0.99", "size":"16769.13", "side":"SELL", "hash":"fcae9e851aee3e08319210339b5339a2e6a5fe95", "best_bid":"0.18", "best_ask":"0.19"}], "timestamp":"1784449596605", "event_type":"price_change"}
{"market":"0x982eae4503214e5d7992668e93f48f42e4707b92e23bb45f8d52d321f643cbe3", "price_changes":[{"asset_id":"37613674580450069178400687025689415665506452565086963049482350052080099056186", "price":"0.01", "size":"17929.98", "side":"BUY", "hash":"1de942597190f5a615d2599b5098d55347d2a99d", "best_bid":"0.18", "best_ask":"0.19"}, {"asset_id":"74913635031537477155015393896000154190746945075332596665612975928350948042868", "price":"0.99", "size":"17929.98", "side":"SELL", "hash":"d457edfd78f67ce28668ef54ca30449f4cea20b1", "best_bid":"0.81", "best_ask":"0.82"}], "timestamp":"1784449596612", "event_type":"price_change"}
{"market":"0x982eae4503214e5d7992668e93f48f42e4707b92e23bb45f8d52d321f643cbe3", "price_changes":[{"asset_id":"37613674580450069178400687025689415665506452565086963049482350052080099056186", "price":"0.01", "size":"17924.98", "side":"BUY", "hash":"46b4ddac675aef34db1c3bdfe2cc84451523a9b9", "best_bid":"0.18", "best_ask":"0.19"}, {"asset_id":"74913635031537477155015393896000154190746945075332596665612975928350948042868", "price":"0.99", "size":"17924.98", "side":"SELL", "hash":"10b581601f27686140d169173beeb556444d3ff1", "best_bid":"0.81", "best_ask":"0.82"}], "timestamp":"1784449596615", "event_type":"price_change"}
{"market":"0x982eae4503214e5d7992668e93f48f42e4707b92e23bb45f8d52d321f643cbe3", "price_changes":[{"asset_id":"74913635031537477155015393896000154190746945075332596665612975928350948042868", "price":"0.01", "size":"16774.13", "side":"BUY", "hash":"b32bbefcac5d24174493899e0aa46745b8b61ebf", "best_bid":"0.81", "best_ask":"0.82"}, {"asset_id":"37613674580450069178400687025689415665506452565086963049482350052080099056186", "price":"0.99", "size":"16774.13", "side":"SELL", "hash":"fffa95dea68ae8698c522953db3fb0970d5da06c", "best_bid":"0.18", "best_ask":"0.19"}], "timestamp":"1784449596618", "event_type":"price_change"}
{"market":"0x982eae4503214e5d7992668e93f48f42e4707b92e23bb45f8d52d321f643cbe3", "price_changes":[{"asset_id":"37613674580450069178400687025689415665506452565086963049482350052080099056186", "price":"0.01", "size":"17919.98", "side":"BUY", "hash":"c2c75c69fd96f4b0a73d6e8e098cc206f42e03f0", "best_bid":"0.18", "best_ask":"0.19"}, {"asset_id":"74913635031537477155015393896000154190746945075332596665612975928350948042868", "price":"0.99", "size":"17919.98", "side":"SELL", "hash":"17f3261a1c3766b82b2bfe845147848c06750030", "best_bid":"0.81", "best_ask":"0.82"}], "timestamp":"1784449596622", "event_type":"price_change"}
{"market":"0x982eae4503214e5d7992668e93f48f42e4707b92e23bb45f8d52d321f643cbe3", "price_changes":[{"asset_id":"74913635031537477155015393896000154190746945075332596665612975928350948042868", "price":"0.04", "size":"1462.1", "side":"BUY", "hash":"b17fca9908f1374e66f4849061da0098e941f1a7", "best_bid":"0.81", "best_ask":"0.82"}, {"asset_id":"37613674580450069178400687025689415665506452565086963049482350052080099056186", "price":"0.96", "size":"1462.1", "side":"SELL", "hash":"d511b9dd5f2fe7cc98758db34dfa0969d6f14a92", "best_bid":"0.18", "best_ask":"0.19"}], "timestamp":"1784449596623", "event_type":"price_change"}
{"market":"0x982eae4503214e5d7992668e93f48f42e4707b92e23bb45f8d52d321f643cbe3", "price_changes":[{"asset_id":"74913635031537477155015393896000154190746945075332596665612975928350948042868", "price":"0.01", "size":"16779.13", "side":"BUY", "hash":"c9f8e957555338db4072e575aea17751f920d8b3", "best_bid":"0.81", "best_ask":"0.82"}, {"asset_id":"37613674580450069178400687025689415665506452565086963049482350052080099056186", "price":"0.99", "size":"16779.13", "side":"SELL", "hash":"b3f419c65c602a235279f440d44698b79ed75b2a", "best_bid":"0.18", "best_ask":"0.19"}], "timestamp":"1784449596625", "event_type":"price_change"}
{"market":"0x982eae4503214e5d7992668e93f48f42e4707b92e23bb45f8d52d321f643cbe3", "price_changes":[{"asset_id":"74913635031537477155015393896000154190746945075332596665612975928350948042868", "price":"0.01", "size":"16784.13", "side":"BUY", "hash":"bf7c74b7672ad2dcf212d963c7ebf3f34613a4fa", "best_bid":"0.81", "best_ask":"0.82"}, {"asset_id":"37613674580450069178400687025689415665506452565086963049482350052080099056186", "price":"0.99", "size":"16784.13", "side":"SELL", "hash":"64b9eea4990b6ad11ba3c5ccd1ab3e510d5b3a74", "best_bid":"0.18", "best_ask":"0.19"}], "timestamp":"1784449596626", "event_type":"price_change"}
{"market":"0x982eae4503214e5d7992668e93f48f42e4707b92e23bb45f8d52d321f643cbe3", "price_changes":[{"asset_id":"74913635031537477155015393896000154190746945075332596665612975928350948042868", "price":"0.01", "size":"16789.13", "side":"BUY", "hash":"4dc3ace8903b0e8f682b16b11ceab9f1541101ac", "best_bid":"0.81", "best_ask":"0.82"}, {"asset_id":"37613674580450069178400687025689415665506452565086963049482350052080099056186", "price":"0.99", "size":"16789.13", "side":"SELL", "hash":"ae60a6d949920d81ef0ebe9e0a22ede93239bdc1", "best_bid":"0.18", "best_ask":"0.19"}], "timestamp":"1784449596627", "event_type":"price_change"}
{"market":"0x982eae4503214e5d7992668e93f48f42e4707b92e23bb45f8d52d321f643cbe3", "price_changes":[{"asset_id":"74913635031537477155015393896000154190746945075332596665612975928350948042868", "price":"0.01", "size":"16794.13", "side":"BUY", "hash":"cf457bca8191231a674bf963993b2f6eb9fe8a70", "best_bid":"0.81", "best_ask":"0.82"}, {"asset_id":"37613674580450069178400687025689415665506452565086963049482350052080099056186", "price":"0.99", "size":"16794.13", "side":"SELL", "hash":"c5d4121c5405687076976e8c24fffd7b2a4de050", "best_bid":"0.18", "best_ask":"0.19"}], "timestamp":"1784449596628", "event_type":"price_change"}
{"market":"0x982eae4503214e5d7992668e93f48f42e4707b92e23bb45f8d52d321f643cbe3", "price_changes":[{"asset_id":"74913635031537477155015393896000154190746945075332596665612975928350948042868", "price":"0.01", "size":"16799.13", "side":"BUY", "hash":"434c4a34876d06144e2f3b89dbf107cd6df3af43", "best_bid":"0.81", "best_ask":"0.82"}, {"asset_id":"37613674580450069178400687025689415665506452565086963049482350052080099056186", "price":"0.99", "size":"16799.13", "side":"SELL", "hash":"5fa38f4f6a68ce046ae1d707ea6cf7d1957ea0ef", "best_bid":"0.18", "best_ask":"0.19"}], "timestamp":"1784449596628", "event_type":"price_change"}
{"market":"0x982eae4503214e5d7992668e93f48f42e4707b92e23bb45f8d52d321f643cbe3", "price_changes":[{"asset_id":"74913635031537477155015393896000154190746945075332596665612975928350948042868", "price":"0.01", "size":"16299.13", "side":"BUY", "hash":"bb451a31cd26df155b7b6d6124f5ecc245d811dc", "best_bid":"0.81", "best_ask":"0.82"}, {"asset_id":"37613674580450069178400687025689415665506452565086963049482350052080099056186", "price":"0.99", "size":"16299.13", "side":"SELL", "hash":"247e6bc968ae06d8a87602b6bd6a1e99caaf8a5d", "best_bid":"0.18", "best_ask":"0.19"}], "timestamp":"1784449596633", "event_type":"price_change"}
{"market":"0x982eae4503214e5d7992668e93f48f42e4707b92e23bb45f8d52d321f643cbe3", "price_changes":[{"asset_id":"74913635031537477155015393896000154190746945075332596665612975928350948042868", "price":"0.01", "size":"16199.13", "side":"BUY", "hash":"a9387692e00e7ba89fffa1379836e0184125ac5a", "best_bid":"0.81", "best_ask":"0.82"}, {"asset_id":"37613674580450069178400687025689415665506452565086963049482350052080099056186", "price":"0.99", "size":"16199.13", "side":"SELL", "hash":"1ec57bbd36a2db9ce03968dd7d564c7a278ae0f9", "best_bid":"0.18", "best_ask":"0.19"}], "timestamp":"1784449596638", "event_type":"price_change"}
{"market":"0x982eae4503214e5d7992668e93f48f42e4707b92e23bb45f8d52d321f643cbe3", "price_changes":[{"asset_id":"74913635031537477155015393896000154190746945075332596665612975928350948042868", "price":"0.74", "size":"171.85", "side":"BUY", "hash":"00a0c06fcaef37b908b018d781a237c0aed41002", "best_bid":"0.81", "best_ask":"0.82"}, {"asset_id":"37613674580450069178400687025689415665506452565086963049482350052080099056186", "price":"0.26", "size":"171.85", "side":"SELL", "hash":"6f4ecd6432ad2976f982542063e90ff4ea191ecd", "best_bid":"0.18", "best_ask":"0.19"}], "timestamp":"1784449596643", "event_type":"price_change"}
{"market":"0x982eae4503214e5d7992668e93f48f42e4707b92e23bb45f8d52d321f643cbe3", "price_changes":[{"asset_id":"74913635031537477155015393896000154190746945075332596665612975928350948042868", "price":"0.01", "size":"16194.13", "side":"BUY", "hash":"5b81fef740c031b13f239fe14b01db53d6a01b91", "best_bid":"0.81", "best_ask":"0.82"}, {"asset_id":"37613674580450069178400687025689415665506452565086963049482350052080099056186", "price":"0.99", "size":"16194.13", "side":"SELL", "hash":"3d2099f3ea0d671348505f985cffdb2e89d4eb9a", "best_bid":"0.18", "best_ask":"0.19"}], "timestamp":"1784449596657", "event_type":"price_change"}
{"market":"0x982eae4503214e5d7992668e93f48f42e4707b92e23bb45f8d52d321f643cbe3", "price_changes":[{"asset_id":"74913635031537477155015393896000154190746945075332596665612975928350948042868", "price":"0.01", "size":"16199.14", "side":"BUY", "hash":"b9250feb9bae237a9d6337fd582a5ec8e88da089", "best_bid":"0.81", "best_ask":"0.82"}, {"asset_id":"37613674580450069178400687025689415665506452565086963049482350052080099056186", "price":"0.99", "size":"16199.14", "side":"SELL", "hash":"7b498313523a287d49cb411802423c6ec35c0907", "best_bid":"0.18", "best_ask":"0.19"}], "timestamp":"1784449596661", "event_type":"price_change"}
{"market":"0x982eae4503214e5d7992668e93f48f42e4707b92e23bb45f8d52d321f643cbe3", "price_changes":[{"asset_id":"74913635031537477155015393896000154190746945075332596665612975928350948042868", "price":"0.74", "size":"146.85", "side":"BUY", "hash":"e79acabe71528fd4aaf042ccac203a018c3aa440", "best_bid":"0.81", "best_ask":"0.82"}, {"asset_id":"37613674580450069178400687025689415665506452565086963049482350052080099056186", "price":"0.26", "size":"146.85", "side":"SELL", "hash":"87a18cdc2e9eaccf899e08e6f9bf0a4b132e6c45", "best_bid":"0.18", "best_ask":"0.19"}], "timestamp":"1784449596665", "event_type":"price_change"}
{"market":"0x982eae4503214e5d7992668e93f48f42e4707b92e23bb45f8d52d321f643cbe3", "price_changes":[{"asset_id":"37613674580450069178400687025689415665506452565086963049482350052080099056186", "price":"0.12", "size":"222.17", "side":"BUY", "hash":"2ba8ddacfcdbff198f8b9006be945ab64e2e646e", "best_bid":"0.18", "best_ask":"0.19"}, {"asset_id":"74913635031537477155015393896000154190746945075332596665612975928350948042868", "price":"0.88", "size":"222.17", "side":"SELL", "hash":"76c68555519d24012dedd67dd59a34289d1a44b8", "best_bid":"0.81", "best_ask":"0.82"}], "timestamp":"1784449596669", "event_type":"price_change"}
{"market":"0x982eae4503214e5d7992668e93f48f42e4707b92e23bb45f8d52d321f643cbe3", "price_changes":[{"asset_id":"74913635031537477155015393896000154190746945075332596665612975928350948042868", "price":"0.01", "size":"16299.14", "side":"BUY", "hash":"e4d959ca745884b9a1c1fb564975ff1df095abe1", "best_bid":"0.81", "best_ask":"0.82"}, {"asset_id":"37613674580450069178400687025689415665506452565086963049482350052080099056186", "price":"0.99", "size":"16299.14", "side":"SELL", "hash":"e05552781508499f7d2914d6e02b162196a75582", "best_bid":"0.18", "best_ask":"0.19"}], "timestamp":"1784449596669", "event_type":"price_change"}
{"market":"0x982eae4503214e5d7992668e93f48f42e4707b92e23bb45f8d52d321f643cbe3", "price_changes":[{"asset_id":"37613674580450069178400687025689415665506452565086963049482350052080099056186", "price":"0.14", "size":"199.34", "side":"BUY", "hash":"a2a0f27296338cdcdef3cee35bfde12f194297c0", "best_bid":"0.18", "best_ask":"0.19"}, {"asset_id":"74913635031537477155015393896000154190746945075332596665612975928350948042868", "price":"0.86", "size":"199.34", "side":"SELL", "hash":"2a3648490420a5c5d53109fcba9c812dd281f472", "best_bid":"0.81", "best_ask":"0.82"}], "timestamp":"1784449596670", "event_type":"price_change"}
{"market":"0x982eae4503214e5d7992668e93f48f42e4707b92e23bb45f8d52d321f643cbe3", "price_changes":[{"asset_id":"37613674580450069178400687025689415665506452565086963049482350052080099056186", "price":"0.15", "size":"151.71", "side":"BUY", "hash":"bfad3a7935807bcbda54b4a77d973f043009cd6e", "best_bid":"0.18", "best_ask":"0.19"}, {"asset_id":"74913635031537477155015393896000154190746945075332596665612975928350948042868", "price":"0.85", "size":"151.71", "side":"SELL", "hash":"cdbb477cff566a69acfd19f6ecfc2ebe4c6d20af", "best_bid":"0.81", "best_ask":"0.82"}], "timestamp":"1784449596670", "event_type":"price_change"}
{"market":"0x982eae4503214e5d7992668e93f48f42e4707b92e23bb45f8d52d321f643cbe3", "price_changes":[{"asset_id":"37613674580450069178400687025689415665506452565086963049482350052080099056186", "price":"0.13", "size":"441.4", "side":"BUY", "hash":"0238a18e4f9c9b1559966587466039adb2413ad9", "best_bid":"0.18", "best_ask":"0.19"}, {"asset_id":"74913635031537477155015393896000154190746945075332596665612975928350948042868", "price":"0.87", "size":"441.4", "side":"SELL", "hash":"534b66d7b82e1a7bf2bbbc0c9d48a4528103761f", "best_bid":"0.81", "best_ask":"0.82"}], "timestamp":"1784449596671", "event_type":"price_change"}
{"market":"0x982eae4503214e5d7992668e93f48f42e4707b92e23bb45f8d52d321f643cbe3", "price_changes":[{"asset_id":"74913635031537477155015393896000154190746945075332596665612975928350948042868", "price":"0.01", "size":"16294.14", "side":"BUY", "hash":"fb215b3088575b35bca5356c3bcf6cf3d2373d1e", "best_bid":"0.81", "best_ask":"0.82"}, {"asset_id":"37613674580450069178400687025689415665506452565086963049482350052080099056186", "price":"0.99", "size":"16294.14", "side":"SELL", "hash":"a07e08f22eb6db8e1ee91774b8463036cf31f764", "best_bid":"0.18", "best_ask":"0.19"}], "timestamp":"1784449596687", "event_type":"price_change"}
{"market":"0x982eae4503214e5d7992668e93f48f42e4707b92e23bb45f8d52d321f643cbe3", "price_changes":[{"asset_id":"74913635031537477155015393896000154190746945075332596665612975928350948042868", "price":"0.01", "size":"16289.13", "side":"BUY", "hash":"3994fe53775c4514bee11331cc3e620e5c54a77d", "best_bid":"0.81", "best_ask":"0.82"}, {"asset_id":"37613674580450069178400687025689415665506452565086963049482350052080099056186", "price":"0.99", "size":"16289.13", "side":"SELL", "hash":"f99820f62c02c5b5b66d6aca20ab9a7f4b29e64f", "best_bid":"0.18", "best_ask":"0.19"}], "timestamp":"1784449596690", "event_type":"price_change"}
{"market":"0x982eae4503214e5d7992668e93f48f42e4707b92e23bb45f8d52d321f643cbe3", "price_changes":[{"asset_id":"74913635031537477155015393896000154190746945075332596665612975928350948042868", "price":"0.01", "size":"16789.13", "side":"BUY", "hash":"ba67d512496fc45a6ceac105709ce899f6b58b0d", "best_bid":"0.81", "best_ask":"0.82"}, {"asset_id":"37613674580450069178400687025689415665506452565086963049482350052080099056186", "price":"0.99", "size":"16789.13", "side":"SELL", "hash":"2da98363a9f21b5d0111532ced86421cf28657f9", "best_bid":"0.18", "best_ask":"0.19"}], "timestamp":"1784449596704", "event_type":"price_change"}
{"market":"0x982eae4503214e5d7992668e93f48f42e4707b92e23bb45f8d52d321f643cbe3", "price_changes":[{"asset_id":"74913635031537477155015393896000154190746945075332596665612975928350948042868", "price":"0.01", "size":"16689.13", "side":"BUY", "hash":"4eda3cf5f174518b6a17c7ea7a4ef2c907cb4a7b", "best_bid":"0.81", "best_ask":"0.82"}, {"asset_id":"37613674580450069178400687025689415665506452565086963049482350052080099056186", "price":"0.99", "size":"16689.13", "side":"SELL", "hash":"cd22d5cf16635ba763c49a1f414f64c54d335dd1", "best_bid":"0.18", "best_ask":"0.19"}], "timestamp":"1784449596707", "event_type":"price_change"}
{"market":"0x982eae4503214e5d7992668e93f48f42e4707b92e23bb45f8d52d321f643cbe3", "price_changes":[{"asset_id":"37613674580450069178400687025689415665506452565086963049482350052080099056186", "price":"0.18", "size":"5.81", "side":"BUY", "hash":"7d5c5382ae69969f573efbbcb3df9bbd18c36128", "best_bid":"0.18", "best_ask":"0.19"}, {"asset_id":"74913635031537477155015393896000154190746945075332596665612975928350948042868", "price":"0.82", "size":"5.81", "side":"SELL", "hash":"eddbaf47d06f14a7a09a91f435fbdd1f98bba416", "best_bid":"0.81", "best_ask":"0.82"}], "timestamp":"1784449596710", "event_type":"price_change"}
{"market":"0x982eae4503214e5d7992668e93f48f42e4707b92e23bb45f8d52d321f643cbe3", "asset_id":"74913635031537477155015393896000154190746945075332596665612975928350948042868", "bids":[{"price":"0.01", "size":"16689.13"}, {"price":"0.02", "size":"3289.11"}, {"price":"0.03", "size":"2085.95"}, {"price":"0.04", "size":"1462.1"}, {"price":"0.05", "size":"1953.67"}, {"price":"0.06", "size":"1677.35"}, {"price":"0.07", "size":"1155.2"}, {"price":"0.08", "size":"1325.88"}, {"price":"0.09", "size":"1027.7"}, {"price":"0.1", "size":"528.2"}, {"price":"0.11", "size":"454.1"}, {"price":"0.12", "size":"203.05"}, {"price":"0.13", "size":"179.4"}, {"price":"0.14", "size":"159.4"}, {"price":"0.15", "size":"149.23"}, {"price":"0.16", "size":"150.4"}, {"price":"0.17", "size":"105.08"}, {"price":"0.18", "size":"127.3"}, {"price":"0.19", "size":"99.78"}, {"price":"0.2", "size":"181.4"}, {"price":"0.21", "size":"111.5"}, {"price":"0.22", "size":"125.7"}, {"price":"0.23", "size":"92"}, {"price":"0.24", "size":"111.5"}, {"price":"0.25", "size":"823.6"}, {"price":"0.26", "size":"148.03"}, {"price":"0.27", "size":"86.7"}, {"price":"0.28", "size":"100.6"}, {"price":"0.29", "size":"84.59"}, {"price":"0.3", "size":"107.8"}, {"price":"0.31", "size":"79.1"}, {"price":"0.32", "size":"107.19"}, {"price":"0.33", "size":"76.7"}, {"price":"0.34", "size":"89"}, {"price":"0.35", "size":"84.4"}, {"price":"0.36", "size":"86.99"}, {"price":"0.37", "size":"73.6"}, {"price":"0.38", "size":"85"}, {"price":"0.39", "size":"71.6"}, {"price":"0.4", "size":"88.3"}, {"price":"0.41", "size":"69.9"}, {"price":"0.42", "size":"142.27"}, {"price":"0.43", "size":"86.5"}, {"price":"0.44", "size":"91.08"}, {"price":"0.45", "size":"104.31"}, {"price":"0.46", "size":"80.1"}, {"price":"0.47", "size":"94.9"}, {"price":"0.48", "size":"88.8"}, {"price":"0.49", "size":"99.36"}, {"price":"0.5", "size":"102.8"}, {"price":"0.51", "size":"100.8"}, {"price":"0.52", "size":"100.8"}, {"price":"0.53", "size":"99.9"}, {"price":"0.54", "size":"92.1"}, {"price":"0.55", "size":"485.2"}, {"price":"0.56", "size":"95.4"}, {"price":"0.57", "size":"85.5"}, {"price":"0.58", "size":"111.12"}, {"price":"0.59", "size":"94.9"}, {"price":"0.6", "size":"203.58"}, {"price":"0.61", "size":"105.6"}, {"price":"0.62", "size":"125"}, {"price":"0.63", "size":"150.6"}, {"price":"0.64", "size":"482.99"}, {"price":"0.65", "size":"107.4"}, {"price":"0.66", "size":"133.24"}, {"price":"0.67", "size":"312.58"}, {"price":"0.68", "size":"118.19"}, {"price":"0.69", "size":"85.7"}, {"price":"0.7", "size":"82.04"}, {"price":"0.71", "size":"99"}, {"price":"0.72", "size":"313.22"}, {"price":"0.73", "size":"159.41"}, {"price":"0.74", "size":"146.85"}, {"price":"0.75", "size":"172.84"}, {"price":"0.76", "size":"170.24"}, {"price":"0.77", "size":"189.66"}, {"price":"0.78", "size":"213.41"}, {"price":"0.79", "size":"98.19"}, {"price":"0.8", "size":"158.28"}, {"price":"0.81", "size":"391.02"}], "asks":[{"price":"0.99", "size":"17919.98"}, {"price":"0.98", "size":"3156.06"}, {"price":"0.97", "size":"3788.29"}, {"price":"0.96", "size":"1529.1"}, {"price":"0.95", "size":"1723.6"}, {"price":"0.94", "size":"1201.35"}, {"price":"0.93", "size":"1367.2"}, {"price":"0.92", "size":"1414.68"}, {"price":"0.91", "size":"942.82"}, {"price":"0.9", "size":"518.32"}, {"price":"0.89", "size":"490.73"}, {"price":"0.88", "size":"222.17"}, {"price":"0.87", "size":"441.4"}, {"price":"0.86", "size":"199.34"}, {"price":"0.85", "size":"151.71"}, {"price":"0.84", "size":"91.17"}, {"price":"0.83", "size":"16.31"}, {"price":"0.82", "size":"5.81"}], "hash":"eddbaf47d06f14a7a09a91f435fbdd1f98bba416", "timestamp":"1784449596710", "event_type":"book"}
{"market":"0x982eae4503214e5d7992668e93f48f42e4707b92e23bb45f8d52d321f643cbe3", "asset_id":"37613674580450069178400687025689415665506452565086963049482350052080099056186", "bids":[{"price":"0.01", "size":"17919.98"}, {"price":"0.02", "size":"3156.06"}, {"price":"0.03", "size":"3788.29"}, {"price":"0.04", "size":"1529.1"}, {"price":"0.05", "size":"1723.6"}, {"price":"0.06", "size":"1201.35"}, {"price":"0.07", "size":"1367.2"}, {"price":"0.08", "size":"1414.68"}, {"price":"0.09", "size":"942.82"}, {"price":"0.1", "size":"518.32"}, {"price":"0.11", "size":"490.73"}, {"price":"0.12", "size":"222.17"}, {"price":"0.13", "size":"441.4"}, {"price":"0.14", "size":"199.34"}, {"price":"0.15", "size":"151.71"}, {"price":"0.16", "size":"91.17"}, {"price":"0.17", "size":"16.31"}, {"price":"0.18", "size":"5.81"}], "asks":[{"price":"0.99", "size":"16689.13"}, {"price":"0.98", "size":"3289.11"}, {"price":"0.97", "size":"2085.95"}, {"price":"0.96", "size":"1462.1"}, {"price":"0.95", "size":"1953.67"}, {"price":"0.94", "size":"1677.35"}, {"price":"0.93", "size":"1155.2"}, {"price":"0.92", "size":"1325.88"}, {"price":"0.91", "size":"1027.7"}, {"price":"0.9", "size":"528.2"}, {"price":"0.89", "size":"454.1"}, {"price":"0.88", "size":"203.05"}, {"price":"0.87", "size":"179.4"}, {"price":"0.86", "size":"159.4"}, {"price":"0.85", "size":"149.23"}, {"price":"0.84", "size":"150.4"}, {"price":"0.83", "size":"105.08"}, {"price":"0.82", "size":"127.3"}, {"price":"0.81", "size":"99.78"}, {"price":"0.8", "size":"181.4"}, {"price":"0.79", "size":"111.5"}, {"price":"0.78", "size":"125.7"}, {"price":"0.77", "size":"92"}, {"price":"0.76", "size":"111.5"}, {"price":"0.75", "size":"823.6"}, {"price":"0.74", "size":"148.03"}, {"price":"0.73", "size":"86.7"}, {"price":"0.72", "size":"100.6"}, {"price":"0.71", "size":"84.59"}, {"price":"0.7", "size":"107.8"}, {"price":"0.69", "size":"79.1"}, {"price":"0.68", "size":"107.19"}, {"price":"0.67", "size":"76.7"}, {"price":"0.66", "size":"89"}, {"price":"0.65", "size":"84.4"}, {"price":"0.64", "size":"86.99"}, {"price":"0.63", "size":"73.6"}, {"price":"0.62", "size":"85"}, {"price":"0.61", "size":"71.6"}, {"price":"0.6", "size":"88.3"}, {"price":"0.59", "size":"69.9"}, {"price":"0.58", "size":"142.27"}, {"price":"0.57", "size":"86.5"}, {"price":"0.56", "size":"91.08"}, {"price":"0.55", "size":"104.31"}, {"price":"0.54", "size":"80.1"}, {"price":"0.53", "size":"94.9"}, {"price":"0.52", "size":"88.8"}, {"price":"0.51", "size":"99.36"}, {"price":"0.5", "size":"102.8"}, {"price":"0.49", "size":"100.8"}, {"price":"0.48", "size":"100.8"}, {"price":"0.47", "size":"99.9"}, {"price":"0.46", "size":"92.1"}, {"price":"0.45", "size":"485.2"}, {"price":"0.44", "size":"95.4"}, {"price":"0.43", "size":"85.5"}, {"price":"0.42", "size":"111.12"}, {"price":"0.41", "size":"94.9"}, {"price":"0.4", "size":"203.58"}, {"price":"0.39", "size":"105.6"}, {"price":"0.38", "size":"125"}, {"price":"0.37", "size":"150.6"}, {"price":"0.36", "size":"482.99"}, {"price":"0.35", "size":"107.4"}, {"price":"0.34", "size":"133.24"}, {"price":"0.33", "size":"312.58"}, {"price":"0.32", "size":"118.19"}, {"price":"0.31", "size":"85.7"}, {"price":"0.3", "size":"82.04"}, {"price":"0.29", "size":"99"}, {"price":"0.28", "size":"313.22"}, {"price":"0.27", "size":"159.41"}, {"price":"0.26", "size":"146.85"}, {"price":"0.25", "size":"172.84"}, {"price":"0.24", "size":"170.24"}, {"price":"0.23", "size":"189.66"}, {"price":"0.22", "size":"213.41"}, {"price":"0.21", "size":"98.19"}, {"price":"0.2", "size":"158.28"}, {"price":"0.19", "size":"391.02"}], "hash":"7d5c5382ae69969f573efbbcb3df9bbd18c36128", "timestamp":"1784449596710", "event_type":"book"}
{"market":"0x982eae4503214e5d7992668e93f48f42e4707b92e23bb45f8d52d321f643cbe3", "price_changes":[{"asset_id":"74913635031537477155015393896000154190746945075332596665612975928350948042868", "price":"0.03", "size":"2090.95", "side":"BUY", "hash":"e0cbe67473a6020f7457d0c2509256d62addda36", "best_bid":"0.81", "best_ask":"0.82"}, {"asset_id":"37613674580450069178400687025689415665506452565086963049482350052080099056186", "price":"0.97", "size":"2090.95", "side":"SELL", "hash":"bdff99d1dd72a5939aaceb43f2fa038341b49a1a", "best_bid":"0.18", "best_ask":"0.19"}], "timestamp":"1784449596714", "event_type":"price_change"}
{"market":"0x982eae4503214e5d7992668e93f48f42e4707b92e23bb45f8d52d321f643cbe3", "price_changes":[{"asset_id":"74913635031537477155015393896000154190746945075332596665612975928350948042868", "price":"0.01", "size":"16684.13", "side":"BUY", "hash":"81fa0ff130dbc8b341078090589160713879bc20", "best_bid":"0.81", "best_ask":"0.82"}, {"asset_id":"37613674580450069178400687025689415665506452565086963049482350052080099056186", "price":"0.99", "size":"16684.13", "side":"SELL", "hash":"f6f0b254c137013c90a0b468620d583d8435fd73", "best_bid":"0.18", "best_ask":"0.19"}], "timestamp":"1784449596717", "event_type":"price_change"}
{"market":"0x982eae4503214e5d7992668e93f48f42e4707b92e23bb45f8d52d321f643cbe3", "price_changes":[{"asset_id":"74913635031537477155015393896000154190746945075332596665612975928350948042868", "price":"0.01", "size":"16184.13", "side":"BUY", "hash":"208bef00408be51b7345f9c284711a8569e7f9ec", "best_bid":"0.81", "best_ask":"0.82"}, {"asset_id":"37613674580450069178400687025689415665506452565086963049482350052080099056186", "price":"0.99", "size":"16184.13", "side":"SELL", "hash":"aaddfdb2cd50973631dd35c53b40393ab3084043", "best_bid":"0.18", "best_ask":"0.19"}], "timestamp":"1784449596732", "event_type":"price_change"}
{"market":"0x982eae4503214e5d7992668e93f48f42e4707b92e23bb45f8d52d321f643cbe3", "price_changes":[{"asset_id":"74913635031537477155015393896000154190746945075332596665612975928350948042868", "price":"0.69", "size":"97.9", "side":"BUY", "hash":"72bc06022b2c10735cf8e4500db6b28d0c657a11", "best_bid":"0.81", "best_ask":"0.82"}, {"asset_id":"37613674580450069178400687025689415665506452565086963049482350052080099056186", "price":"0.31", "size":"97.9", "side":"SELL", "hash":"e96194c8dbac586f8152b3ea4e9aefb0f87e89af", "best_bid":"0.18", "best_ask":"0.19"}], "timestamp":"1784449596733", "event_type":"price_change"}
{"market":"0x982eae4503214e5d7992668e93f48f42e4707b92e23bb45f8d52d321f643cbe3", "price_changes":[{"asset_id":"74913635031537477155015393896000154190746945075332596665612975928350948042868", "price":"0.01", "size":"16284.13", "side":"BUY", "hash":"aa522cd7b8c544282de063d5e0eaa2448249e70a", "best_bid":"0.81", "best_ask":"0.82"}, {"asset_id":"37613674580450069178400687025689415665506452565086963049482350052080099056186", "price":"0.99", "size":"16284.13", "side":"SELL", "hash":"e6539d38246ca4aa32fc0f78d36d53fc67769027", "best_bid":"0.18", "best_ask":"0.19"}], "timestamp":"1784449596754", "event_type":"price_change"}
{"market":"0x982eae4503214e5d7992668e93f48f42e4707b92e23bb45f8d52d321f643cbe3", "price_changes":[{"asset_id":"37613674580450069178400687025689415665506452565086963049482350052080099056186", "price":"0.15", "size":"142.71", "side":"BUY", "hash":"d5080147a82b9f326e82b4d387e5cedfab23c808", "best_bid":"0.18", "best_ask":"0.19"}, {"asset_id":"74913635031537477155015393896000154190746945075332596665612975928350948042868", "price":"0.85", "size":"142.71", "side":"SELL", "hash":"492287eeafd01e14add5fe038546a4084793ef67", "best_bid":"0.81", "best_ask":"0.82"}], "timestamp":"1784449596759", "event_type":"price_change"}
{"market":"0x982eae4503214e5d7992668e93f48f42e4707b92e23bb45f8d52d321f643cbe3", "price_changes":[{"asset_id":"74913635031537477155015393896000154190746945075332596665612975928350948042868", "price":"0.73", "size":"154.41", "side":"BUY", "hash":"7a3290ab124764762f0a91a5d8d0faee57613842", "best_bid":"0.81", "best_ask":"0.82"}, {"asset_id":"37613674580450069178400687025689415665506452565086963049482350052080099056186", "price":"0.27", "size":"154.41", "side":"SELL", "hash":"1101f1ad817e4ae8584f357339fd6c65e010aa3c", "best_bid":"0.18", "best_ask":"0.19"}], "timestamp":"1784449596782", "event_type":"price_change"}
{"market":"0x982eae4503214e5d7992668e93f48f42e4707b92e23bb45f8d52d321f643cbe3", "price_changes":[{"asset_id":"74913635031537477155015393896000154190746945075332596665612975928350948042868", "price":"0.03", "size":"2085.95", "side":"BUY", "hash":"6784b34ced60ddb53f70d07f9e78045580f91295", "best_bid":"0.81", "best_ask":"0.82"}, {"asset_id":"37613674580450069178400687025689415665506452565086963049482350052080099056186", "price":"0.97", "size":"2085.95", "side":"SELL", "hash":"e5b4123de0b253d78800b07600b2a2a34da13e7b", "best_bid":"0.18", "best_ask":"0.19"}], "timestamp":"1784449596782", "event_type":"price_change"}
{"market":"0x982eae4503214e5d7992668e93f48f42e4707b92e23bb45f8d52d321f643cbe3", "price_changes":[{"asset_id":"74913635031537477155015393896000154190746945075332596665612975928350948042868", "price":"0.01", "size":"16184.13", "side":"BUY", "hash":"f2c1302b8b38a4c4b292cb3a53c9ca37994ceec7", "best_bid":"0.81", "best_ask":"0.82"}, {"asset_id":"37613674580450069178400687025689415665506452565086963049482350052080099056186", "price":"0.99", "size":"16184.13", "side":"SELL", "hash":"e20e2617ae31510d4afa70d74959afff4eafedca", "best_bid":"0.18", "best_ask":"0.19"}], "timestamp":"1784449596790", "event_type":"price_change"}
{"market":"0x982eae4503214e5d7992668e93f48f42e4707b92e23bb45f8d52d321f643cbe3", "asset_id":"74913635031537477155015393896000154190746945075332596665612975928350948042868", "price":"0.82", "size":"1.219511", "fee_rate_bps":"0", "side":"BUY", "timestamp":"1784449596803", "event_type":"last_trade_price", "transaction_hash":"0xbd4c152c7d3723eb35c73d50285440f5675de811d065b7688876b2742183f4ac"}
{"market":"0x982eae4503214e5d7992668e93f48f42e4707b92e23bb45f8d52d321f643cbe3", "price_changes":[{"asset_id":"37613674580450069178400687025689415665506452565086963049482350052080099056186", "price":"0.27", "size":"159.41", "side":"SELL", "hash":"9ab72d227682bffe09ede71052f91f1caa27044d", "best_bid":"0.18", "best_ask":"0.19"}, {"asset_id":"74913635031537477155015393896000154190746945075332596665612975928350948042868", "price":"0.73", "size":"159.41", "side":"BUY", "hash":"200549bf263355740537223cd4482b6b862546cf", "best_bid":"0.81", "best_ask":"0.82"}], "timestamp":"1784449596807", "event_type":"price_change"}
{"market":"0x982eae4503214e5d7992668e93f48f42e4707b92e23bb45f8d52d321f643cbe3", "price_changes":[{"asset_id":"74913635031537477155015393896000154190746945075332596665612975928350948042868", "price":"0.01", "size":"16684.13", "side":"BUY", "hash":"9b00c723b3a9ea433f44cae945e4f9dda5588a71", "best_bid":"0.81", "best_ask":"0.82"}, {"asset_id":"37613674580450069178400687025689415665506452565086963049482350052080099056186", "price":"0.99", "size":"16684.13", "side":"SELL", "hash":"509151f8fefbf5ffa5baceeae640d8a09ea85241", "best_bid":"0.18", "best_ask":"0.19"}], "timestamp":"1784449596812", "event_type":"price_change"}
{"market":"0x982eae4503214e5d7992668e93f48f42e4707b92e23bb45f8d52d321f643cbe3", "price_changes":[{"asset_id":"74913635031537477155015393896000154190746945075332596665612975928350948042868", "price":"0.66", "size":"143.24", "side":"BUY", "hash":"2e006fa3836556fd0ef5403ff783b9b0379c926c", "best_bid":"0.81", "best_ask":"0.82"}, {"asset_id":"37613674580450069178400687025689415665506452565086963049482350052080099056186", "price":"0.34", "size":"143.24", "side":"SELL", "hash":"401e529d6159ece2e5a29dad77fb8e641909bdea", "best_bid":"0.18", "best_ask":"0.19"}], "timestamp":"1784449596816", "event_type":"price_change"}
{"market":"0x982eae4503214e5d7992668e93f48f42e4707b92e23bb45f8d52d321f643cbe3", "price_changes":[{"asset_id":"74913635031537477155015393896000154190746945075332596665612975928350948042868", "price":"0.01", "size":"16689.13", "side":"BUY", "hash":"a116bd4e255b441d151dd04d66bbd197b30d11be", "best_bid":"0.81", "best_ask":"0.82"}, {"asset_id":"37613674580450069178400687025689415665506452565086963049482350052080099056186", "price":"0.99", "size":"16689.13", "side":"SELL", "hash":"7a92668947d14a7154ac55d02b53492f4ad49191", "best_bid":"0.18", "best_ask":"0.19"}], "timestamp":"1784449596821", "event_type":"price_change"}
{"market":"0x982eae4503214e5d7992668e93f48f42e4707b92e23bb45f8d52d321f643cbe3", "price_changes":[{"asset_id":"74913635031537477155015393896000154190746945075332596665612975928350948042868", "price":"0.01", "size":"16694.13", "side":"BUY", "hash":"3d3451e126b4c7e7ceb4ea69a798bba03bee9c92", "best_bid":"0.81", "best_ask":"0.82"}, {"asset_id":"37613674580450069178400687025689415665506452565086963049482350052080099056186", "price":"0.99", "size":"16694.13", "side":"SELL", "hash":"4ad3346baaee7c9e4e55ad8ae038a57430bc9be3", "best_bid":"0.18", "best_ask":"0.19"}], "timestamp":"1784449596822", "event_type":"price_change"}
{"market":"0x982eae4503214e5d7992668e93f48f42e4707b92e23bb45f8d52d321f643cbe3", "price_changes":[{"asset_id":"74913635031537477155015393896000154190746945075332596665612975928350948042868", "price":"0.01", "size":"16699.13", "side":"BUY", "hash":"95e1ed6d9e2315a870235090554ec3403ad6a09c", "best_bid":"0.81", "best_ask":"0.82"}, {"asset_id":"37613674580450069178400687025689415665506452565086963049482350052080099056186", "price":"0.99", "size":"16699.13", "side":"SELL", "hash":"16a8ee2203f7f2c3264eeb0ad3434c18f3d607ef", "best_bid":"0.18", "best_ask":"0.19"}], "timestamp":"1784449596823", "event_type":"price_change"}
{"market":"0x982eae4503214e5d7992668e93f48f42e4707b92e23bb45f8d52d321f643cbe3", "price_changes":[{"asset_id":"74913635031537477155015393896000154190746945075332596665612975928350948042868", "price":"0.01", "size":"16694.13", "side":"BUY", "hash":"b100fbf182696a64fb5f16fd94169099cba494a6", "best_bid":"0.81", "best_ask":"0.82"}, {"asset_id":"37613674580450069178400687025689415665506452565086963049482350052080099056186", "price":"0.99", "size":"16694.13", "side":"SELL", "hash":"572b3ed06a67a5f05a41c776cc4beed8e52a6623", "best_bid":"0.18", "best_ask":"0.19"}], "timestamp":"1784449596824", "event_type":"price_change"}
{"market":"0x982eae4503214e5d7992668e93f48f42e4707b92e23bb45f8d52d321f643cbe3", "price_changes":[{"asset_id":"74913635031537477155015393896000154190746945075332596665612975928350948042868", "price":"0.01", "size":"16689.13", "side":"BUY", "hash":"103b319c9ba155855014db5c33b8716617d3542d", "best_bid":"0.81", "best_ask":"0.82"}, {"asset_id":"37613674580450069178400687025689415665506452565086963049482350052080099056186", "price":"0.99", "size":"16689.13", "side":"SELL", "hash":"b7c2f5a91a7d2fbe292f149dc4dfa4b78906bf95", "best_bid":"0.18", "best_ask":"0.19"}], "timestamp":"1784449596829", "event_type":"price_change"}
{"market":"0x982eae4503214e5d7992668e93f48f42e4707b92e23bb45f8d52d321f643cbe3", "price_changes":[{"asset_id":"74913635031537477155015393896000154190746945075332596665612975928350948042868", "price":"0.01", "size":"16694.13", "side":"BUY", "hash":"6c48e059553ef91dbe973e44cd998acde874d875", "best_bid":"0.81", "best_ask":"0.82"}, {"asset_id":"37613674580450069178400687025689415665506452565086963049482350052080099056186", "price":"0.99", "size":"16694.13", "side":"SELL", "hash":"98c4ae26d44401f4dacbfd5a96c3292c2b2cc520", "best_bid":"0.18", "best_ask":"0.19"}], "timestamp":"1784449596830", "event_type":"price_change"}
{"market":"0x982eae4503214e5d7992668e93f48f42e4707b92e23bb45f8d52d321f643cbe3", "price_changes":[{"asset_id":"37613674580450069178400687025689415665506452565086963049482350052080099056186", "price":"0.01", "size":"17924.98", "side":"BUY", "hash":"2328a8c880aa03d5e17db85bb3b2198b9b93db1c", "best_bid":"0.18", "best_ask":"0.19"}, {"asset_id":"74913635031537477155015393896000154190746945075332596665612975928350948042868", "price":"0.99", "size":"17924.98", "side":"SELL", "hash":"2dd20e75d3aa388663ff691600b0ad09df0b8093", "best_bid":"0.81", "best_ask":"0.82"}], "timestamp":"1784449596831", "event_type":"price_change"}
{"market":"0x982eae4503214e5d7992668e93f48f42e4707b92e23bb45f8d52d321f643cbe3", "price_changes":[{"asset_id":"74913635031537477155015393896000154190746945075332596665612975928350948042868", "price":"0.01", "size":"16689.13", "side":"BUY", "hash":"f6d1b2c8b443ce11744d7d9f9891146a8baaac9c", "best_bid":"0.81", "best_ask":"0.82"}, {"asset_id":"37613674580450069178400687025689415665506452565086963049482350052080099056186", "price":"0.99", "size":"16689.13", "side":"SELL", "hash":"b771e1082201df4a6f10201eaf9ad4f02acda8aa", "best_bid":"0.18", "best_ask":"0.19"}], "timestamp":"1784449596832", "event_type":"price_change"}
{"market":"0x982eae4503214e5d7992668e93f48f42e4707b92e23bb45f8d52d321f643cbe3", "price_changes":[{"asset_id":"74913635031537477155015393896000154190746945075332596665612975928350948042868", "price":"0.01", "size":"16789.13", "side":"BUY", "hash":"9e1bd356ff8b5ba104c341eb0c77b1d14bd0f2c9", "best_bid":"0.81", "best_ask":"0.82"}, {"asset_id":"37613674580450069178400687025689415665506452565086963049482350052080099056186", "price":"0.99", "size":"16789.13", "side":"SELL", "hash":"0ae732d86d272529f5136504471a6268bd69f4ee", "best_bid":"0.18", "best_ask":"0.19"}], "timestamp":"1784449596833", "event_type":"price_change"}
{"market":"0x982eae4503214e5d7992668e93f48f42e4707b92e23bb45f8d52d321f643cbe3", "price_changes":[{"asset_id":"37613674580450069178400687025689415665506452565086963049482350052080099056186", "price":"0.01", "size":"17929.98", "side":"BUY", "hash":"1d5d80b1995e714fd8c28c2a0036a2784301bdbf", "best_bid":"0.18", "best_ask":"0.19"}, {"asset_id":"74913635031537477155015393896000154190746945075332596665612975928350948042868", "price":"0.99", "size":"17929.98", "side":"SELL", "hash":"419e53b80ff20590df65177982424d2d6e1ae406", "best_bid":"0.81", "best_ask":"0.82"}], "timestamp":"1784449596835", "event_type":"price_change"}
{"market":"0x982eae4503214e5d7992668e93f48f42e4707b92e23bb45f8d52d321f643cbe3", "price_changes":[{"asset_id":"37613674580450069178400687025689415665506452565086963049482350052080099056186", "price":"0.01", "size":"17934.98", "side":"BUY", "hash":"906bfc785306f14eabebda86b2eefcf6562324f7", "best_bid":"0.18", "best_ask":"0.19"}, {"asset_id":"74913635031537477155015393896000154190746945075332596665612975928350948042868", "price":"0.99", "size":"17934.98", "side":"SELL", "hash":"28692615db3b1d6309549d3c2a91c9432d2154d8", "best_bid":"0.81", "best_ask":"0.82"}], "timestamp":"1784449596835", "event_type":"price_change"}
{"market":"0x982eae4503214e5d7992668e93f48f42e4707b92e23bb45f8d52d321f643cbe3", "price_changes":[{"asset_id":"74913635031537477155015393896000154190746945075332596665612975928350948042868", "price":"0.81", "size":"396.79", "side":"BUY", "hash":"9b6acc28709ee6f971dc37c80e006db9e218ec56", "best_bid":"0.81", "best_ask":"0.82"}, {"asset_id":"37613674580450069178400687025689415665506452565086963049482350052080099056186", "price":"0.19", "size":"396.79", "side":"SELL", "hash":"87d1803b06189b548c40688de8262674d7cf7795", "best_bid":"0.18", "best_ask":"0.19"}], "timestamp":"1784449596837", "event_type":"price_change"}
{"market":"0x982eae4503214e5d7992668e93f48f42e4707b92e23bb45f8d52d321f643cbe3", "price_changes":[{"asset_id":"37613674580450069178400687025689415665506452565086963049482350052080099056186", "price":"0.05", "size":"1703.6", "side":"BUY", "hash":"2e74e501d95b18a07ca7c90beaba9f3017925c36", "best_bid":"0.18", "best_ask":"0.19"}, {"asset_id":"74913635031537477155015393896000154190746945075332596665612975928350948042868", "price":"0.95", "size":"1703.6", "side":"SELL", "hash":"e26d6b08dcff9f94830635f7f9f37d49c50a2b04", "best_bid":"0.81", "best_ask":"0.82"}], "timestamp":"1784449596843", "event_type":"price_change"}
{"market":"0x982eae4503214e5d7992668e93f48f42e4707b92e23bb45f8d52d321f643cbe3", "price_changes":[{"asset_id":"74913635031537477155015393896000154190746945075332596665612975928350948042868", "price":"0.73", "size":"179.41", "side":"BUY", "hash":"716f449352f7b1e5e4a636299df4075c02ed706a", "best_bid":"0.81", "best_ask":"0.82"}, {"asset_id":"37613674580450069178400687025689415665506452565086963049482350052080099056186", "price":"0.27", "size":"179.41", "side":"SELL", "hash":"f3714eea7301769579e8308642953f164d58c070", "best_bid":"0.18", "best_ask":"0.19"}], "timestamp":"1784449596844", "event_type":"price_change"}
{"market":"0x982eae4503214e5d7992668e93f48f42e4707b92e23bb45f8d52d321f643cbe3", "price_changes":[{"asset_id":"74913635031537477155015393896000154190746945075332596665612975928350948042868", "price":"0.01", "size":"16784.13", "side":"BUY", "hash":"d129ba466198dfd33c7a791839dd12880bd1602e", "best_bid":"0.81", "best_ask":"0.82"}, {"asset_id":"37613674580450069178400687025689415665506452565086963049482350052080099056186", "price":"0.99", "size":"16784.13", "side":"SELL", "hash":"a68d6cd3a526f27d3f68f888abb4fc86680cc2df", "best_bid":"0.18", "best_ask":"0.19"}], "timestamp":"1784449596847", "event_type":"price_change"}
{"market":"0x982eae4503214e5d7992668e93f48f42e4707b92e23bb45f8d52d321f643cbe3", "price_changes":[{"asset_id":"74913635031537477155015393896000154190746945075332596665612975928350948042868", "price":"0.01", "size":"16779.13", "side":"BUY", "hash":"283c6beaa56581b54640f06ac1373051511a0289", "best_bid":"0.81", "best_ask":"0.82"}, {"asset_id":"37613674580450069178400687025689415665506452565086963049482350052080099056186", "price":"0.99", "size":"16779.13", "side":"SELL", "hash":"fc5827c2310cfb433a891c252cb9d357411a6a1a", "best_bid":"0.18", "best_ask":"0.19"}], "timestamp":"1784449596851", "event_type":"price_change"}
{"market":"0x982eae4503214e5d7992668e93f48f42e4707b92e23bb45f8d52d321f643cbe3", "price_changes":[{"asset_id":"74913635031537477155015393896000154190746945075332596665612975928350948042868", "price":"0.01", "size":"16784.14", "side":"BUY", "hash":"df27d04b94816efca5930f2f7de6c41d73944849", "best_bid":"0.81", "best_ask":"0.82"}, {"asset_id":"37613674580450069178400687025689415665506452565086963049482350052080099056186", "price":"0.99", "size":"16784.14", "side":"SELL", "hash":"8ab0be7479ce1884e83bd0e552a5e558a243ea4f", "best_bid":"0.18", "best_ask":"0.19"}], "timestamp":"1784449596861", "event_type":"price_change"}
{"market":"0x982eae4503214e5d7992668e93f48f42e4707b92e23bb45f8d52d321f643cbe3", "price_changes":[{"asset_id":"37613674580450069178400687025689415665506452565086963049482350052080099056186", "price":"0.15", "size":"151.71", "side":"BUY", "hash":"dc24608f744537e2963351670f0a29cd6e3cf7ee", "best_bid":"0.18", "best_ask":"0.19"}, {"asset_id":"74913635031537477155015393896000154190746945075332596665612975928350948042868", "price":"0.85", "size":"151.71", "side":"SELL", "hash":"4b2a98500e644b22f38d6b7c360638e84ea0a238", "best_bid":"0.81", "best_ask":"0.82"}], "timestamp":"1784449596863", "event_type":"price_change"}
{"market":"0x982eae4503214e5d7992668e93f48f42e4707b92e23bb45f8d52d321f643cbe3", "price_changes":[{"asset_id":"74913635031537477155015393896000154190746945075332596665612975928350948042868", "price":"0.01", "size":"16789.14", "side":"BUY", "hash":"612e10d510f0ed027c9df0a11469af52f3cdfa96", "best_bid":"0.81", "best_ask":"0.82"}, {"asset_id":"37613674580450069178400687025689415665506452565086963049482350052080099056186", "price":"0.99", "size":"16789.14", "side":"SELL", "hash":"6840f08472490af72373e2d0a489a8b8070192a4", "best_bid":"0.18", "best_ask":"0.19"}], "timestamp":"1784449596865", "event_type":"price_change"}
{"market":"0x982eae4503214e5d7992668e93f48f42e4707b92e23bb45f8d52d321f643cbe3", "price_changes":[{"asset_id":"74913635031537477155015393896000154190746945075332596665612975928350948042868", "price":"0.03", "size":"2090.95", "side":"BUY", "hash":"a806801ad17327adb431e1d975dac3fac13ae9f0", "best_bid":"0.81", "best_ask":"0.82"}, {"asset_id":"37613674580450069178400687025689415665506452565086963049482350052080099056186", "price":"0.97", "size":"2090.95", "side":"SELL", "hash":"58d9eaa2921ccb27a470a5ddabdfa89336135385", "best_bid":"0.18", "best_ask":"0.19"}], "timestamp":"1784449596871", "event_type":"price_change"}
{"market":"0x982eae4503214e5d7992668e93f48f42e4707b92e23bb45f8d52d321f643cbe3", "price_changes":[{"asset_id":"74913635031537477155015393896000154190746945075332596665612975928350948042868", "price":"0.01", "size":"16689.14", "side":"BUY", "hash":"7af568d68cb2b7b13443317b26803677b7127f0e", "best_bid":"0.81", "best_ask":"0.82"}, {"asset_id":"37613674580450069178400687025689415665506452565086963049482350052080099056186", "price":"0.99", "size":"16689.14", "side":"SELL", "hash":"017f91414fc9fd9915da99baa972d50c33fb644a", "best_bid":"0.18", "best_ask":"0.19"}], "timestamp":"1784449596873", "event_type":"price_change"}
{"market":"0x982eae4503214e5d7992668e93f48f42e4707b92e23bb45f8d52d321f643cbe3", "price_changes":[{"asset_id":"74913635031537477155015393896000154190746945075332596665612975928350948042868", "price":"0.01", "size":"16684.14", "side":"BUY", "hash":"c9d4d1f49d9cdb1d32810b69947b4c379889678f", "best_bid":"0.81", "best_ask":"0.82"}, {"asset_id":"37613674580450069178400687025689415665506452565086963049482350052080099056186", "price":"0.99", "size":"16684.14", "side":"SELL", "hash":"094a92a1bfe9fd82deb01552008b6b7914de1799", "best_bid":"0.18", "best_ask":"0.19"}], "timestamp":"1784449596877", "event_type":"price_change"}
{"market":"0x982eae4503214e5d7992668e93f48f42e4707b92e23bb45f8d52d321f643cbe3", "price_changes":[{"asset_id":"37613674580450069178400687025689415665506452565086963049482350052080099056186", "price":"0.18", "size":"20.81", "side":"BUY", "hash":"c776bddb6fa8a357cd2db5eced3e382f806ad1a4", "best_bid":"0.18", "best_ask":"0.19"}, {"asset_id":"74913635031537477155015393896000154190746945075332596665612975928350948042868", "price":"0.82", "size":"20.81", "side":"SELL", "hash":"83955dab905a7e8df49ce97536156b9d24475684", "best_bid":"0.81", "best_ask":"0.82"}], "timestamp":"1784449596886", "event_type":"price_change"}
{"market":"0x982eae4503214e5d7992668e93f48f42e4707b92e23bb45f8d52d321f643cbe3", "price_changes":[{"asset_id":"74913635031537477155015393896000154190746945075332596665612975928350948042868", "price":"0.01", "size":"16679.13", "side":"BUY", "hash":"69298de0d858d1a4667eb75d4ee88e0f5f3c1de5", "best_bid":"0.81", "best_ask":"0.82"}, {"asset_id":"37613674580450069178400687025689415665506452565086963049482350052080099056186", "price":"0.99", "size":"16679.13", "side":"SELL", "hash":"d9c6716b0f20144ce8fb421d8e94a56e558a111e", "best_bid":"0.18", "best_ask":"0.19"}], "timestamp":"1784449596886", "event_type":"price_change"}
{"market":"0x982eae4503214e5d7992668e93f48f42e4707b92e23bb45f8d52d321f643cbe3", "price_changes":[{"asset_id":"37613674580450069178400687025689415665506452565086963049482350052080099056186", "price":"0.17", "size":"31.31", "side":"BUY", "hash":"f7d0a9c042c4b697d03fad957fd71c3e422caf37", "best_bid":"0.18", "best_ask":"0.19"}, {"asset_id":"74913635031537477155015393896000154190746945075332596665612975928350948042868", "price":"0.83", "size":"31.31", "side":"SELL", "hash":"89a0c64bacfb40e5a0e086c344b070c3d4bdc579", "best_bid":"0.81", "best_ask":"0.82"}], "timestamp":"1784449596887", "event_type":"price_change"}
{"market":"0x982eae4503214e5d7992668e93f48f42e4707b92e23bb45f8d52d321f643cbe3", "price_changes":[{"asset_id":"37613674580450069178400687025689415665506452565086963049482350052080099056186", "price":"0.16", "size":"106.17", "side":"BUY", "hash":"f7c4ddddce91e1c6e8db152690bddc4f8dfcb6c0", "best_bid":"0.18", "best_ask":"0.19"}, {"asset_id":"74913635031537477155015393896000154190746945075332596665612975928350948042868", "price":"0.84", "size":"106.17", "side":"SELL", "hash":"8da77c55d1265c46d204b0fc7c119fae0a1304f0", "best_bid":"0.81", "best_ask":"0.82"}], "timestamp":"1784449596887", "event_type":"price_change"}
{"market":"0x982eae4503214e5d7992668e93f48f42e4707b92e23bb45f8d52d321f643cbe3", "price_changes":[{"asset_id":"74913635031537477155015393896000154190746945075332596665612975928350948042868", "price":"0.01", "size":"16674.13", "side":"BUY", "hash":"aba7cf6e69c88ce9236347e9e40a4d80e911b4fc", "best_bid":"0.81", "best_ask":"0.82"}, {"asset_id":"37613674580450069178400687025689415665506452565086963049482350052080099056186", "price":"0.99", "size":"16674.13", "side":"SELL", "hash":"7404d5357d4ed72334b19bfe8d91a9a13e97b4d5", "best_bid":"0.18", "best_ask":"0.19"}], "timestamp":"1784449596890", "event_type":"price_change"}
{"market":"0x982eae4503214e5d7992668e93f48f42e4707b92e23bb45f8d52d321f643cbe3", "price_changes":[{"asset_id":"37613674580450069178400687025689415665506452565086963049482350052080099056186", "price":"0.18", "size":"0.81", "side":"BUY", "hash":"f34c1ab65db5ddb7688aa11a2e9b3f5343811c50", "best_bid":"0.18", "best_ask":"0.19"}, {"asset_id":"74913635031537477155015393896000154190746945075332596665612975928350948042868", "price":"0.82", "size":"0.81", "side":"SELL", "hash":"5863539d0d3285e3d300a0c53461111604e1b1cf", "best_bid":"0.81", "best_ask":"0.82"}], "timestamp":"1784449596905", "event_type":"price_change"}
{"market":"0x982eae4503214e5d7992668e93f48f42e4707b92e23bb45f8d52d321f643cbe3", "asset_id":"74913635031537477155015393896000154190746945075332596665612975928350948042868", "bids":[{"price":"0.01", "size":"16674.13"}, {"price":"0.02", "size":"3289.11"}, {"price":"0.03", "size":"2090.95"}, {"price":"0.04", "size":"1462.1"}, {"price":"0.05", "size":"1953.67"}, {"price":"0.06", "size":"1677.35"}, {"price":"0.07", "size":"1155.2"}, {"price":"0.08", "size":"1325.88"}, {"price":"0.09", "size":"1027.7"}, {"price":"0.1", "size":"528.2"}, {"price":"0.11", "size":"454.1"}, {"price":"0.12", "size":"203.05"}, {"price":"0.13", "size":"179.4"}, {"price":"0.14", "size":"159.4"}, {"price":"0.15", "size":"149.23"}, {"price":"0.16", "size":"150.4"}, {"price":"0.17", "size":"105.08"}, {"price":"0.18", "size":"127.3"}, {"price":"0.19", "size":"99.78"}, {"price":"0.2", "size":"181.4"}, {"price":"0.21", "size":"111.5"}, {"price":"0.22", "size":"125.7"}, {"price":"0.23", "size":"92"}, {"price":"0.24", "size":"111.5"}, {"price":"0.25", "size":"823.6"}, {"price":"0.26", "size":"148.03"}, {"price":"0.27", "size":"86.7"}, {"price":"0.28", "size":"100.6"}, {"price":"0.29", "size":"84.59"}, {"price":"0.3", "size":"107.8"}, {"price":"0.31", "size":"79.1"}, {"price":"0.32", "size":"107.19"}, {"price":"0.33", "size":"76.7"}, {"price":"0.34", "size":"89"}, {"price":"0.35", "size":"84.4"}, {"price":"0.36", "size":"86.99"}, {"price":"0.37", "size":"73.6"}, {"price":"0.38", "size":"85"}, {"price":"0.39", "size":"71.6"}, {"price":"0.4", "size":"88.3"}, {"price":"0.41", "size":"69.9"}, {"price":"0.42", "size":"142.27"}, {"price":"0.43", "size":"86.5"}, {"price":"0.44", "size":"91.08"}, {"price":"0.45", "size":"104.31"}, {"price":"0.46", "size":"80.1"}, {"price":"0.47", "size":"94.9"}, {"price":"0.48", "size":"88.8"}, {"price":"0.49", "size":"99.36"}, {"price":"0.5", "size":"102.8"}, {"price":"0.51", "size":"100.8"}, {"price":"0.52", "size":"100.8"}, {"price":"0.53", "size":"99.9"}, {"price":"0.54", "size":"92.1"}, {"price":"0.55", "size":"485.2"}, {"price":"0.56", "size":"95.4"}, {"price":"0.57", "size":"85.5"}, {"price":"0.58", "size":"111.12"}, {"price":"0.59", "size":"94.9"}, {"price":"0.6", "size":"203.58"}, {"price":"0.61", "size":"105.6"}, {"price":"0.62", "size":"125"}, {"price":"0.63", "size":"150.6"}, {"price":"0.64", "size":"482.99"}, {"price":"0.65", "size":"107.4"}, {"price":"0.66", "size":"143.24"}, {"price":"0.67", "size":"312.58"}, {"price":"0.68", "size":"118.19"}, {"price":"0.69", "size":"97.9"}, {"price":"0.7", "size":"82.04"}, {"price":"0.71", "size":"99"}, {"price":"0.72", "size":"313.22"}, {"price":"0.73", "size":"179.41"}, {"price":"0.74", "size":"146.85"}, {"price":"0.75", "size":"172.84"}, {"price":"0.76", "size":"170.24"}, {"price":"0.77", "size":"189.66"}, {"price":"0.78", "size":"213.41"}, {"price":"0.79", "size":"98.19"}, {"price":"0.8", "size":"158.28"}, {"price":"0.81", "size":"396.79"}], "asks":[{"price":"0.99", "size":"17934.98"}, {"price":"0.98", "size":"3156.06"}, {"price":"0.97", "size":"3788.29"}, {"price":"0.96", "size":"1529.1"}, {"price":"0.95", "size":"1703.6"}, {"price":"0.94", "size":"1201.35"}, {"price":"0.93", "size":"1367.2"}, {"price":"0.92", "size":"1414.68"}, {"price":"0.91", "size":"942.82"}, {"price":"0.9", "size":"518.32"}, {"price":"0.89", "size":"490.73"}, {"price":"0.88", "size":"222.17"}, {"price":"0.87", "size":"441.4"}, {"price":"0.86", "size":"199.34"}, {"price":"0.85", "size":"151.71"}, {"price":"0.84", "size":"106.17"}, {"price":"0.83", "size":"31.31"}, {"price":"0.82", "size":"0.81"}], "hash":"5863539d0d3285e3d300a0c53461111604e1b1cf", "timestamp":"1784449596905", "event_type":"book"}
{"market":"0x982eae4503214e5d7992668e93f48f42e4707b92e23bb45f8d52d321f643cbe3", "asset_id":"37613674580450069178400687025689415665506452565086963049482350052080099056186", "bids":[{"price":"0.01", "size":"17934.98"}, {"price":"0.02", "size":"3156.06"}, {"price":"0.03", "size":"3788.29"}, {"price":"0.04", "size":"1529.1"}, {"price":"0.05", "size":"1703.6"}, {"price":"0.06", "size":"1201.35"}, {"price":"0.07", "size":"1367.2"}, {"price":"0.08", "size":"1414.68"}, {"price":"0.09", "size":"942.82"}, {"price":"0.1", "size":"518.32"}, {"price":"0.11", "size":"490.73"}, {"price":"0.12", "size":"222.17"}, {"price":"0.13", "size":"441.4"}, {"price":"0.14", "size":"199.34"}, {"price":"0.15", "size":"151.71"}, {"price":"0.16", "size":"106.17"}, {"price":"0.17", "size":"31.31"}, {"price":"0.18", "size":"0.81"}], "asks":[{"price":"0.99", "size":"16674.13"}, {"price":"0.98", "size":"3289.11"}, {"price":"0.97", "size":"2090.95"}, {"price":"0.96", "size":"1462.1"}, {"price":"0.95", "size":"1953.67"}, {"price":"0.94", "size":"1677.35"}, {"price":"0.93", "size":"1155.2"}, {"price":"0.92", "size":"1325.88"}, {"price":"0.91", "size":"1027.7"}, {"price":"0.9", "size":"528.2"}, {"price":"0.89", "size":"454.1"}, {"price":"0.88", "size":"203.05"}, {"price":"0.87", "size":"179.4"}, {"price":"0.86", "size":"159.4"}, {"price":"0.85", "size":"149.23"}, {"price":"0.84", "size":"150.4"}, {"price":"0.83", "size":"105.08"}, {"price":"0.82", "size":"127.3"}, {"price":"0.81", "size":"99.78"}, {"price":"0.8", "size":"181.4"}, {"price":"0.79", "size":"111.5"}, {"price":"0.78", "size":"125.7"}, {"price":"0.77", "size":"92"}, {"price":"0.76", "size":"111.5"}, {"price":"0.75", "size":"823.6"}, {"price":"0.74", "size":"148.03"}, {"price":"0.73", "size":"86.7"}, {"price":"0.72", "size":"100.6"}, {"price":"0.71", "size":"84.59"}, {"price":"0.7", "size":"107.8"}, {"price":"0.69", "size":"79.1"}, {"price":"0.68", "size":"107.19"}, {"price":"0.67", "size":"76.7"}, {"price":"0.66", "size":"89"}, {"price":"0.65", "size":"84.4"}, {"price":"0.64", "size":"86.99"}, {"price":"0.63", "size":"73.6"}, {"price":"0.62", "size":"85"}, {"price":"0.61", "size":"71.6"}, {"price":"0.6", "size":"88.3"}, {"price":"0.59", "size":"69.9"}, {"price":"0.58", "size":"142.27"}, {"price":"0.57", "size":"86.5"}, {"price":"0.56", "size":"91.08"}, {"price":"0.55", "size":"104.31"}, {"price":"0.54", "size":"80.1"}, {"price":"0.53", "size":"94.9"}, {"price":"0.52", "size":"88.8"}, {"price":"0.51", "size":"99.36"}, {"price":"0.5", "size":"102.8"}, {"price":"0.49", "size":"100.8"}, {"price":"0.48", "size":"100.8"}, {"price":"0.47", "size":"99.9"}, {"price":"0.46", "size":"92.1"}, {"price":"0.45", "size":"485.2"}, {"price":"0.44", "size":"95.4"}, {"price":"0.43", "size":"85.5"}, {"price":"0.42", "size":"111.12"}, {"price":"0.41", "size":"94.9"}, {"price":"0.4", "size":"203.58"}, {"price":"0.39", "size":"105.6"}, {"price":"0.38", "size":"125"}, {"price":"0.37", "size":"150.6"}, {"price":"0.36", "size":"482.99"}, {"price":"0.35", "size":"107.4"}, {"price":"0.34", "size":"143.24"}, {"price":"0.33", "size":"312.58"}, {"price":"0.32", "size":"118.19"}, {"price":"0.31", "size":"97.9"}, {"price":"0.3", "size":"82.04"}, {"price":"0.29", "size":"99"}, {"price":"0.28", "size":"313.22"}, {"price":"0.27", "size":"179.41"}, {"price":"0.26", "size":"146.85"}, {"price":"0.25", "size":"172.84"}, {"price":"0.24", "size":"170.24"}, {"price":"0.23", "size":"189.66"}, {"price":"0.22", "size":"213.41"}, {"price":"0.21", "size":"98.19"}, {"price":"0.2", "size":"158.28"}, {"price":"0.19", "size":"396.79"}], "hash":"f34c1ab65db5ddb7688aa11a2e9b3f5343811c50", "timestamp":"1784449596905", "event_type":"book"}
{"market":"0x982eae4503214e5d7992668e93f48f42e4707b92e23bb45f8d52d321f643cbe3", "price_changes":[{"asset_id":"74913635031537477155015393896000154190746945075332596665612975928350948042868", "price":"0.01", "size":"16669.13", "side":"BUY", "hash":"0a2bfe6ecc15d4cfee0cf2b2abdaeb34a27b44b8", "best_bid":"0.81", "best_ask":"0.82"}, {"asset_id":"37613674580450069178400687025689415665506452565086963049482350052080099056186", "price":"0.99", "size":"16669.13", "side":"SELL", "hash":"18164b4c6270ad0795a85afb53e5515f132544ca", "best_bid":"0.18", "best_ask":"0.19"}], "timestamp":"1784449596908", "event_type":"price_change"}
{"market":"0x982eae4503214e5d7992668e93f48f42e4707b92e23bb45f8d52d321f643cbe3", "price_changes":[{"asset_id":"74913635031537477155015393896000154190746945075332596665612975928350948042868", "price":"0.03", "size":"2085.95", "side":"BUY", "hash":"e23533ea11bd60426f9ec611eba9357b3fbf51e3", "best_bid":"0.81", "best_ask":"0.82"}, {"asset_id":"37613674580450069178400687025689415665506452565086963049482350052080099056186", "price":"0.97", "size":"2085.95", "side":"SELL", "hash":"0632304eaee6e03dffbb74ad97d08da369ad664b", "best_bid":"0.18", "best_ask":"0.19"}], "timestamp":"1784449596914", "event_type":"price_change"}
{"market":"0x982eae4503214e5d7992668e93f48f42e4707b92e23bb45f8d52d321f643cbe3", "price_changes":[{"asset_id":"74913635031537477155015393896000154190746945075332596665612975928350948042868", "price":"0.01", "size":"16769.13", "side":"BUY", "hash":"dfcdbd75f56624cb32919b2cde1ba245652d248f", "best_bid":"0.81", "best_ask":"0.82"}, {"asset_id":"37613674580450069178400687025689415665506452565086963049482350052080099056186", "price":"0.99", "size":"16769.13", "side":"SELL", "hash":"41016f0deeb9596d33985e4c050a74f1f5bcd2b3", "best_bid":"0.18", "best_ask":"0.19"}], "timestamp":"1784449596918", "event_type":"price_change"}
{"market":"0x982eae4503214e5d7992668e93f48f42e4707b92e23bb45f8d52d321f643cbe3", "price_changes":[{"asset_id":"74913635031537477155015393896000154190746945075332596665612975928350948042868", "price":"0.62", "size":"130", "side":"BUY", "hash":"4dc77e5d4068c46e09b36966cbefa1162189ff59", "best_bid":"0.81", "best_ask":"0.82"}, {"asset_id":"37613674580450069178400687025689415665506452565086963049482350052080099056186", "price":"0.38", "size":"130", "side":"SELL", "hash":"221b8a51997de472d778f4af73733264c81e1bd2", "best_bid":"0.18", "best_ask":"0.19"}], "timestamp":"1784449596924", "event_type":"price_change"}
{"market":"0x982eae4503214e5d7992668e93f48f42e4707b92e23bb45f8d52d321f643cbe3", "price_changes":[{"asset_id":"74913635031537477155015393896000154190746945075332596665612975928350948042868", "price":"0.01", "size":"16269.13", "side":"BUY", "hash":"d9a338ce3741f24f6029a1afc5167b4b8a28b2e4", "best_bid":"0.81", "best_ask":"0.82"}, {"asset_id":"37613674580450069178400687025689415665506452565086963049482350052080099056186", "price":"0.99", "size":"16269.13", "side":"SELL", "hash":"9eb9b09b9767ddfa6445c0768f888b8edfbb7208", "best_bid":"0.18", "best_ask":"0.19"}], "timestamp":"1784449596937", "event_type":"price_change"}
{"market":"0x982eae4503214e5d7992668e93f48f42e4707b92e23bb45f8d52d321f643cbe3", "price_changes":[{"asset_id":"37613674580450069178400687025689415665506452565086963049482350052080099056186", "price":"0.06", "size":"1208.35", "side":"BUY", "hash":"5116a520db5519f1b2357594e7e9f878ee81d34d", "best_bid":"0.18", "best_ask":"0.19"}, {"asset_id":"74913635031537477155015393896000154190746945075332596665612975928350948042868", "price":"0.94", "size":"1208.35", "side":"SELL", "hash":"9c96a830692e08dd19eb9f9049625a53d9144c36", "best_bid":"0.81", "best_ask":"0.82"}], "timestamp":"1784449596940", "event_type":"price_change"}
{"market":"0x982eae4503214e5d7992668e93f48f42e4707b92e23bb45f8d52d321f643cbe3", "price_changes":[{"asset_id":"37613674580450069178400687025689415665506452565086963049482350052080099056186", "price":"0.14", "size":"239.34", "side":"BUY", "hash":"742ed124d17f9c4d57326a02a16cbc0c33162627", "best_bid":"0.18", "best_ask":"0.19"}, {"asset_id":"74913635031537477155015393896000154190746945075332596665612975928350948042868", "price":"0.86", "size":"239.34", "side":"SELL", "hash":"f06d2fa18290b3706baa05653279a0406a4d9491", "best_bid":"0.81", "best_ask":"0.82"}], "timestamp":"1784449596941", "event_type":"price_change"}
{"market":"0x982eae4503214e5d7992668e93f48f42e4707b92e23bb45f8d52d321f643cbe3", "price_changes":[{"asset_id":"37613674580450069178400687025689415665506452565086963049482350052080099056186", "price":"0.13", "size":"401.4", "side":"BUY", "hash":"7303e1ebaa219a14df5ec3ca29b22fa7ee3e435b", "best_bid":"0.18", "best_ask":"0.19"}, {"asset_id":"74913635031537477155015393896000154190746945075332596665612975928350948042868", "price":"0.87", "size":"401.4", "side":"SELL", "hash":"8f22560db9e78360ae5ab0b0163f58dcb48fa4de", "best_bid":"0.81", "best_ask":"0.82"}], "timestamp":"1784449596941", "event_type":"price_change"}
{"market":"0x982eae4503214e5d7992668e93f48f42e4707b92e23bb45f8d52d321f643cbe3", "price_changes":[{"asset_id":"37613674580450069178400687025689415665506452565086963049482350052080099056186", "price":"0.08", "size":"1409.68", "side":"BUY", "hash":"b4ae4a2f4fa20ce37b2e09f9b4cd1a939550ba88", "best_bid":"0.18", "best_ask":"0.19"}, {"asset_id":"74913635031537477155015393896000154190746945075332596665612975928350948042868", "price":"0.92", "size":"1409.68", "side":"SELL", "hash":"a3f4c16a232040853521ab5c66efc8711b5f2a1c", "best_bid":"0.81", "best_ask":"0.82"}], "timestamp":"1784449596944", "event_type":"price_change"}
{"market":"0x982eae4503214e5d7992668e93f48f42e4707b92e23bb45f8d52d321f643cbe3", "price_changes":[{"asset_id":"37613674580450069178400687025689415665506452565086963049482350052080099056186", "price":"0.15", "size":"171.71", "side":"BUY", "hash":"d20c4d0fd9855c92127a355af7b65e7d8bbbedc1", "best_bid":"0.18", "best_ask":"0.19"}, {"asset_id":"74913635031537477155015393896000154190746945075332596665612975928350948042868", "price":"0.85", "size":"171.71", "side":"SELL", "hash":"4f00af14b3c1a0f2aff1291b14ea5f51bafbb14a", "best_bid":"0.81", "best_ask":"0.82"}], "timestamp":"1784449596948", "event_type":"price_change"}
{"market":"0x982eae4503214e5d7992668e93f48f42e4707b92e23bb45f8d52d321f643cbe3", "price_changes":[{"asset_id":"74913635031537477155015393896000154190746945075332596665612975928350948042868", "price":"0.01", "size":"16169.13", "side":"BUY", "hash":"356dd7c4254f06ca2205f22e58bd19756efc950d", "best_bid":"0.81", "best_ask":"0.82"}, {"asset_id":"37613674580450069178400687025689415665506452565086963049482350052080099056186", "price":"0.99", "size":"16169.13", "side":"SELL", "hash":"8221ee453673a178e4cf13f54e95bf2465da7762", "best_bid":"0.18", "best_ask":"0.19"}], "timestamp":"1784449596953", "event_type":"price_change"}
{"market":"0x982eae4503214e5d7992668e93f48f42e4707b92e23bb45f8d52d321f643cbe3", "price_changes":[{"asset_id":"37613674580450069178400687025689415665506452565086963049482350052080099056186", "price":"0.16", "size":"119.17", "side":"BUY", "hash":"ef77c3eb0967203801a2c161506ee55b6100d21e", "best_bid":"0.18", "best_ask":"0.19"}, {"asset_id":"74913635031537477155015393896000154190746945075332596665612975928350948042868", "price":"0.84", "size":"119.17", "side":"SELL", "hash":"d7c2d8e93f29ebbdd5e4f26b7f230d8d57f70b63", "best_bid":"0.81", "best_ask":"0.82"}], "timestamp":"1784449596962", "event_type":"price_change"}
{"market":"0x982eae4503214e5d7992668e93f48f42e4707b92e23bb45f8d52d321f643cbe3", "price_changes":[{"asset_id":"74913635031537477155015393896000154190746945075332596665612975928350948042868", "price":"0.72", "size":"319.64", "side":"BUY", "hash":"257c502bb84dd6ae604203ec9c030816536ecd80", "best_bid":"0.81", "best_ask":"0.82"}, {"asset_id":"37613674580450069178400687025689415665506452565086963049482350052080099056186", "price":"0.28", "size":"319.64", "side":"SELL", "hash":"f704bc15c97ed7c20cb7e33ef2ddf626bf659ff4", "best_bid":"0.18", "best_ask":"0.19"}], "timestamp":"1784449596990", "event_type":"price_change"}
{"market":"0x982eae4503214e5d7992668e93f48f42e4707b92e23bb45f8d52d321f643cbe3", "price_changes":[{"asset_id":"74913635031537477155015393896000154190746945075332596665612975928350948042868", "price":"0.52", "size":"95.8", "side":"BUY", "hash":"8be5cca83d5295469a3e365d1e5ae9acf4070015", "best_bid":"0.81", "best_ask":"0.82"}, {"asset_id":"37613674580450069178400687025689415665506452565086963049482350052080099056186", "price":"0.48", "size":"95.8", "side":"SELL", "hash":"c0547a43d1ca87153ae070a4f6c14605708ffedc", "best_bid":"0.18", "best_ask":"0.19"}], "timestamp":"1784449596991", "event_type":"price_change"}
{"market":"0x982eae4503214e5d7992668e93f48f42e4707b92e23bb45f8d52d321f643cbe3", "price_changes":[{"asset_id":"74913635031537477155015393896000154190746945075332596665612975928350948042868", "price":"0.04", "size":"1467.1", "side":"BUY", "hash":"61ff13195b9a87c7bd65ffb96cb54c751330121e", "best_bid":"0.81", "best_ask":"0.82"}, {"asset_id":"37613674580450069178400687025689415665506452565086963049482350052080099056186", "price":"0.96", "size":"1467.1", "side":"SELL", "hash":"61900be4861a6116edeaaf2ad2c72005f02edf32", "best_bid":"0.18", "best_ask":"0.19"}], "timestamp":"1784449596995", "event_type":"price_change"}
{"market":"0x982eae4503214e5d7992668e93f48f42e4707b92e23bb45f8d52d321f643cbe3", "price_changes":[{"asset_id":"74913635031537477155015393896000154190746945075332596665612975928350948042868", "price":"0.01", "size":"16269.13", "side":"BUY", "hash":"548283e943661e98a397ed09c81ea6419daf50b2", "best_bid":"0.81", "best_ask":"0.82"}, {"asset_id":"37613674580450069178400687025689415665506452565086963049482350052080099056186", "price":"0.99", "size":"16269.13", "side":"SELL", "hash":"d0fb2918b7026469bbeb60e169f520d650255401", "best_bid":"0.18", "best_ask":"0.19"}], "timestamp":"1784449596995", "event_type":"price_change"}
{"market":"0x982eae4503214e5d7992668e93f48f42e4707b92e23bb45f8d52d321f643cbe3", "price_changes":[{"asset_id":"74913635031537477155015393896000154190746945075332596665612975928350948042868", "price":"0.81", "size":"391.52", "side":"BUY", "hash":"66df05c5026835ddb4c9e6413a28ff8fe4a644ec", "best_bid":"0.81", "best_ask":"0.82"}, {"asset_id":"37613674580450069178400687025689415665506452565086963049482350052080099056186", "price":"0.19", "size":"391.52", "side":"SELL", "hash":"a3d4930f5a799094f6a918fa358c185d60af6c34", "best_bid":"0.18", "best_ask":"0.19"}], "timestamp":"1784449596999", "event_type":"price_change"}
{"market":"0x982eae4503214e5d7992668e93f48f42e4707b92e23bb45f8d52d321f643cbe3", "asset_id":"74913635031537477155015393896000154190746945075332596665612975928350948042868", "bids":[{"price":"0.01", "size":"16269.13"}, {"price":"0.02", "size":"3289.11"}, {"price":"0.03", "size":"2085.95"}, {"price":"0.04", "size":"1467.1"}, {"price":"0.05", "size":"1953.67"}, {"price":"0.06", "size":"1677.35"}, {"price":"0.07", "size":"1155.2"}, {"price":"0.08", "size":"1325.88"}, {"price":"0.09", "size":"1027.7"}, {"price":"0.1", "size":"528.2"}, {"price":"0.11", "size":"454.1"}, {"price":"0.12", "size":"203.05"}, {"price":"0.13", "size":"179.4"}, {"price":"0.14", "size":"159.4"}, {"price":"0.15", "size":"149.23"}, {"price":"0.16", "size":"150.4"}, {"price":"0.17", "size":"105.08"}, {"price":"0.18", "size":"127.3"}, {"price":"0.19", "size":"99.78"}, {"price":"0.2", "size":"181.4"}, {"price":"0.21", "size":"111.5"}, {"price":"0.22", "size":"125.7"}, {"price":"0.23", "size":"92"}, {"price":"0.24", "size":"111.5"}, {"price":"0.25", "size":"823.6"}, {"price":"0.26", "size":"148.03"}, {"price":"0.27", "size":"86.7"}, {"price":"0.28", "size":"100.6"}, {"price":"0.29", "size":"84.59"}, {"price":"0.3", "size":"107.8"}, {"price":"0.31", "size":"79.1"}, {"price":"0.32", "size":"107.19"}, {"price":"0.33", "size":"76.7"}, {"price":"0.34", "size":"89"}, {"price":"0.35", "size":"84.4"}, {"price":"0.36", "size":"86.99"}, {"price":"0.37", "size":"73.6"}, {"price":"0.38", "size":"85"}, {"price":"0.39", "size":"71.6"}, {"price":"0.4", "size":"88.3"}, {"price":"0.41", "size":"69.9"}, {"price":"0.42", "size":"142.27"}, {"price":"0.43", "size":"86.5"}, {"price":"0.44", "size":"91.08"}, {"price":"0.45", "size":"104.31"}, {"price":"0.46", "size":"80.1"}, {"price":"0.47", "size":"94.9"}, {"price":"0.48", "size":"88.8"}, {"price":"0.49", "size":"99.36"}, {"price":"0.5", "size":"102.8"}, {"price":"0.51", "size":"100.8"}, {"price":"0.52", "size":"95.8"}, {"price":"0.53", "size":"99.9"}, {"price":"0.54", "size":"92.1"}, {"price":"0.55", "size":"485.2"}, {"price":"0.56", "size":"95.4"}, {"price":"0.57", "size":"85.5"}, {"price":"0.58", "size":"111.12"}, {"price":"0.59", "size":"94.9"}, {"price":"0.6", "size":"203.58"}, {"price":"0.61", "size":"105.6"}, {"price":"0.62", "size":"130"}, {"price":"0.63", "size":"150.6"}, {"price":"0.64", "size":"482.99"}, {"price":"0.65", "size":"107.4"}, {"price":"0.66", "size":"143.24"}, {"price":"0.67", "size":"312.58"}, {"price":"0.68", "size":"118.19"}, {"price":"0.69", "size":"97.9"}, {"price":"0.7", "size":"82.04"}, {"price":"0.71", "size":"99"}, {"price":"0.72", "size":"319.64"}, {"price":"0.73", "size":"179.41"}, {"price":"0.74", "size":"146.85"}, {"price":"0.75", "size":"172.84"}, {"price":"0.76", "size":"170.24"}, {"price":"0.77", "size":"189.66"}, {"price":"0.78", "size":"213.41"}, {"price":"0.79", "size":"98.19"}, {"price":"0.8", "size":"158.28"}, {"price":"0.81", "size":"391.52"}], "asks":[{"price":"0.99", "size":"17934.98"}, {"price":"0.98", "size":"3156.06"}, {"price":"0.97", "size":"3788.29"}, {"price":"0.96", "size":"1529.1"}, {"price":"0.95", "size":"1703.6"}, {"price":"0.94", "size":"1208.35"}, {"price":"0.93", "size":"1367.2"}, {"price":"0.92", "size":"1409.68"}, {"price":"0.91", "size":"942.82"}, {"price":"0.9", "size":"518.32"}, {"price":"0.89", "size":"490.73"}, {"price":"0.88", "size":"222.17"}, {"price":"0.87", "size":"401.4"}, {"price":"0.86", "size":"239.34"}, {"price":"0.85", "size":"171.71"}, {"price":"0.84", "size":"119.17"}, {"price":"0.83", "size":"31.31"}, {"price":"0.82", "size":"0.81"}], "hash":"66df05c5026835ddb4c9e6413a28ff8fe4a644ec", "timestamp":"1784449596999", "event_type":"book"}
{"market":"0x982eae4503214e5d7992668e93f48f42e4707b92e23bb45f8d52d321f643cbe3", "asset_id":"37613674580450069178400687025689415665506452565086963049482350052080099056186", "bids":[{"price":"0.01", "size":"17934.98"}, {"price":"0.02", "size":"3156.06"}, {"price":"0.03", "size":"3788.29"}, {"price":"0.04", "size":"1529.1"}, {"price":"0.05", "size":"1703.6"}, {"price":"0.06", "size":"1208.35"}, {"price":"0.07", "size":"1367.2"}, {"price":"0.08", "size":"1409.68"}, {"price":"0.09", "size":"942.82"}, {"price":"0.1", "size":"518.32"}, {"price":"0.11", "size":"490.73"}, {"price":"0.12", "size":"222.17"}, {"price":"0.13", "size":"401.4"}, {"price":"0.14", "size":"239.34"}, {"price":"0.15", "size":"171.71"}, {"price":"0.16", "size":"119.17"}, {"price":"0.17", "size":"31.31"}, {"price":"0.18", "size":"0.81"}], "asks":[{"price":"0.99", "size":"16269.13"}, {"price":"0.98", "size":"3289.11"}, {"price":"0.97", "size":"2085.95"}, {"price":"0.96", "size":"1467.1"}, {"price":"0.95", "size":"1953.67"}, {"price":"0.94", "size":"1677.35"}, {"price":"0.93", "size":"1155.2"}, {"price":"0.92", "size":"1325.88"}, {"price":"0.91", "size":"1027.7"}, {"price":"0.9", "size":"528.2"}, {"price":"0.89", "size":"454.1"}, {"price":"0.88", "size":"203.05"}, {"price":"0.87", "size":"179.4"}, {"price":"0.86", "size":"159.4"}, {"price":"0.85", "size":"149.23"}, {"price":"0.84", "size":"150.4"}, {"price":"0.83", "size":"105.08"}, {"price":"0.82", "size":"127.3"}, {"price":"0.81", "size":"99.78"}, {"price":"0.8", "size":"181.4"}, {"price":"0.79", "size":"111.5"}, {"price":"0.78", "size":"125.7"}, {"price":"0.77", "size":"92"}, {"price":"0.76", "size":"111.5"}, {"price":"0.75", "size":"823.6"}, {"price":"0.74", "size":"148.03"}, {"price":"0.73", "size":"86.7"}, {"price":"0.72", "size":"100.6"}, {"price":"0.71", "size":"84.59"}, {"price":"0.7", "size":"107.8"}, {"price":"0.69", "size":"79.1"}, {"price":"0.68", "size":"107.19"}, {"price":"0.67", "size":"76.7"}, {"price":"0.66", "size":"89"}, {"price":"0.65", "size":"84.4"}, {"price":"0.64", "size":"86.99"}, {"price":"0.63", "size":"73.6"}, {"price":"0.62", "size":"85"}, {"price":"0.61", "size":"71.6"}, {"price":"0.6", "size":"88.3"}, {"price":"0.59", "size":"69.9"}, {"price":"0.58", "size":"142.27"}, {"price":"0.57", "size":"86.5"}, {"price":"0.56", "size":"91.08"}, {"price":"0.55", "size":"104.31"}, {"price":"0.54", "size":"80.1"}, {"price":"0.53", "size":"94.9"}, {"price":"0.52", "size":"88.8"}, {"price":"0.51", "size":"99.36"}, {"price":"0.5", "size":"102.8"}, {"price":"0.49", "size":"100.8"}, {"price":"0.48", "size":"95.8"}, {"price":"0.47", "size":"99.9"}, {"price":"0.46", "size":"92.1"}, {"price":"0.45", "size":"485.2"}, {"price":"0.44", "size":"95.4"}, {"price":"0.43", "size":"85.5"}, {"price":"0.42", "size":"111.12"}, {"price":"0.41", "size":"94.9"}, {"price":"0.4", "size":"203.58"}, {"price":"0.39", "size":"105.6"}, {"price":"0.38", "size":"130"}, {"price":"0.37", "size":"150.6"}, {"price":"0.36", "size":"482.99"}, {"price":"0.35", "size":"107.4"}, {"price":"0.34", "size":"143.24"}, {"price":"0.33", "size":"312.58"}, {"price":"0.32", "size":"118.19"}, {"price":"0.31", "size":"97.9"}, {"price":"0.3", "size":"82.04"}, {"price":"0.29", "size":"99"}, {"price":"0.28", "size":"319.64"}, {"price":"0.27", "size":"179.41"}, {"price":"0.26", "size":"146.85"}, {"price":"0.25", "size":"172.84"}, {"price":"0.24", "size":"170.24"}, {"price":"0.23", "size":"189.66"}, {"price":"0.22", "size":"213.41"}, {"price":"0.21", "size":"98.19"}, {"price":"0.2", "size":"158.28"}, {"price":"0.19", "size":"391.52"}], "hash":"a3d4930f5a799094f6a918fa358c185d60af6c34", "timestamp":"1784449596999", "event_type":"book"}
{"market":"0x982eae4503214e5d7992668e93f48f42e4707b92e23bb45f8d52d321f643cbe3", "price_changes":[{"asset_id":"74913635031537477155015393896000154190746945075332596665612975928350948042868", "price":"0.72", "size":"313.22", "side":"BUY", "hash":"1434409f093e87f2225b3f9075d3322309bf8f03", "best_bid":"0.81", "best_ask":"0.82"}, {"asset_id":"37613674580450069178400687025689415665506452565086963049482350052080099056186", "price":"0.28", "size":"313.22", "side":"SELL", "hash":"22a42493d4aa46f2e2a25c938dd61ae2a1496bfb", "best_bid":"0.18", "best_ask":"0.19"}], "timestamp":"1784449597011", "event_type":"price_change"}
{"market":"0x982eae4503214e5d7992668e93f48f42e4707b92e23bb45f8d52d321f643cbe3", "price_changes":[{"asset_id":"74913635031537477155015393896000154190746945075332596665612975928350948042868", "price":"0.01", "size":"16274.13", "side":"BUY", "hash":"99c84d227f27697b8c26b4ae533d512d32a8d5fb", "best_bid":"0.81", "best_ask":"0.82"}, {"asset_id":"37613674580450069178400687025689415665506452565086963049482350052080099056186", "price":"0.99", "size":"16274.13", "side":"SELL", "hash":"b5304bc90d53b427874d4ec20cc5c745fa0a956c", "best_bid":"0.18", "best_ask":"0.19"}], "timestamp":"1784449597011", "event_type":"price_change"}
{"market":"0x982eae4503214e5d7992668e93f48f42e4707b92e23bb45f8d52d321f643cbe3", "price_changes":[{"asset_id":"74913635031537477155015393896000154190746945075332596665612975928350948042868", "price":"0.01", "size":"16279.13", "side":"BUY", "hash":"2d412e238154843ec419f52bb3e58c3dd811e774", "best_bid":"0.81", "best_ask":"0.82"}, {"asset_id":"37613674580450069178400687025689415665506452565086963049482350052080099056186", "price":"0.99", "size":"16279.13", "side":"SELL", "hash":"154aa87d12673b154d158aebcd3343e9006c800b", "best_bid":"0.18", "best_ask":"0.19"}], "timestamp":"1784449597017", "event_type":"price_change"}
{"market":"0x982eae4503214e5d7992668e93f48f42e4707b92e23bb45f8d52d321f643cbe3", "price_changes":[{"asset_id":"37613674580450069178400687025689415665506452565086963049482350052080099056186", "price":"0.01", "size":"17939.98", "side":"BUY", "hash":"16a4b8a077a8e343bfae3d1f67d87b19b1a566d1", "best_bid":"0.18", "best_ask":"0.19"}, {"asset_id":"74913635031537477155015393896000154190746945075332596665612975928350948042868", "price":"0.99", "size":"17939.98", "side":"SELL", "hash":"a7dd844dd048d380d008f29538187cd23738593a", "best_bid":"0.81", "best_ask":"0.82"}], "timestamp":"1784449597025", "event_type":"price_change"}
{"market":"0x982eae4503214e5d7992668e93f48f42e4707b92e23bb45f8d52d321f643cbe3", "price_changes":[{"asset_id":"74913635031537477155015393896000154190746945075332596665612975928350948042868", "price":"0.01", "size":"16779.13", "side":"BUY", "hash":"6f0504315e719eaf72f78faa6c7be3a0b3781d95", "best_bid":"0.81", "best_ask":"0.82"}, {"asset_id":"37613674580450069178400687025689415665506452565086963049482350052080099056186", "price":"0.99", "size":"16779.13", "side":"SELL", "hash":"c423f8862e8ecaf92b0031baeb3b149397fb700f", "best_bid":"0.18", "best_ask":"0.19"}], "timestamp":"1784449597026", "event_type":"price_change"}
{"market":"0x982eae4503214e5d7992668e93f48f42e4707b92e23bb45f8d52d321f643cbe3", "price_changes":[{"asset_id":"74913635031537477155015393896000154190746945075332596665612975928350948042868", "price":"0.53", "size":"104.9", "side":"BUY", "hash":"732d1b43ec8f93648cd961229c0ac7bbdf73a9b4", "best_bid":"0.81", "best_ask":"0.82"}, {"asset_id":"37613674580450069178400687025689415665506452565086963049482350052080099056186", "price":"0.47", "size":"104.9", "side":"SELL", "hash":"1d9119b3ec668f9a9e69af8997c78920ef9d1ed3", "best_bid":"0.18", "best_ask":"0.19"}], "timestamp":"1784449597027", "event_type":"price_change"}
{"market":"0x982eae4503214e5d7992668e93f48f42e4707b92e23bb45f8d52d321f643cbe3", "price_changes":[{"asset_id":"37613674580450069178400687025689415665506452565086963049482350052080099056186", "price":"0.01", "size":"17934.98", "side":"BUY", "hash":"033accd116d45152e22ccbbd886d56b78c4c7faf", "best_bid":"0.18", "best_ask":"0.19"}, {"asset_id":"74913635031537477155015393896000154190746945075332596665612975928350948042868", "price":"0.99", "size":"17934.98", "side":"SELL", "hash":"543cfd60736be8ac4c6b2dde66892098952b9c7b", "best_bid":"0.81", "best_ask":"0.82"}], "timestamp":"1784449597027", "event_type":"price_change"}
{"market":"0x982eae4503214e5d7992668e93f48f42e4707b92e23bb45f8d52d321f643cbe3", "price_changes":[{"asset_id":"37613674580450069178400687025689415665506452565086963049482350052080099056186", "price":"0.15", "size":"165.71", "side":"BUY", "hash":"1bbda0bb635a09395ec15f4f83da4bd012c86049", "best_bid":"0.18", "best_ask":"0.19"}, {"asset_id":"74913635031537477155015393896000154190746945075332596665612975928350948042868", "price":"0.85", "size":"165.71", "side":"SELL", "hash":"a18ae2c2ae2680b7d09b57a6584e45c990299489", "best_bid":"0.81", "best_ask":"0.82"}], "timestamp":"1784449597027", "event_type":"price_change"}
{"market":"0x982eae4503214e5d7992668e93f48f42e4707b92e23bb45f8d52d321f643cbe3", "price_changes":[{"asset_id":"74913635031537477155015393896000154190746945075332596665612975928350948042868", "price":"0.01", "size":"16784.13", "side":"BUY", "hash":"bd2482436189923ccd7c53f4b506b02eb78ce285", "best_bid":"0.81", "best_ask":"0.82"}, {"asset_id":"37613674580450069178400687025689415665506452565086963049482350052080099056186", "price":"0.99", "size":"16784.13", "side":"SELL", "hash":"6a378697c4e529f1f1fd711ff7c3432bf45dad48", "best_bid":"0.18", "best_ask":"0.19"}], "timestamp":"1784449597028", "event_type":"price_change"}
{"market":"0x982eae4503214e5d7992668e93f48f42e4707b92e23bb45f8d52d321f643cbe3", "price_changes":[{"asset_id":"74913635031537477155015393896000154190746945075332596665612975928350948042868", "price":"0.01", "size":"16789.13", "side":"BUY", "hash":"8a40f486e6cb499fe25fa8c11d46b16c6f31ddf8", "best_bid":"0.81", "best_ask":"0.82"}, {"asset_id":"37613674580450069178400687025689415665506452565086963049482350052080099056186", "price":"0.99", "size":"16789.13", "side":"SELL", "hash":"1d5d434bd4178f7abedb38c6add6e61dcc26e9f7", "best_bid":"0.18", "best_ask":"0.19"}], "timestamp":"1784449597028", "event_type":"price_change"}
{"market":"0x982eae4503214e5d7992668e93f48f42e4707b92e23bb45f8d52d321f643cbe3", "price_changes":[{"asset_id":"74913635031537477155015393896000154190746945075332596665612975928350948042868", "price":"0.69", "size":"91.9", "side":"BUY", "hash":"2ff97792e549191d8a46ba19be61032ad4cd1bf4", "best_bid":"0.81", "best_ask":"0.82"}, {"asset_id":"37613674580450069178400687025689415665506452565086963049482350052080099056186", "price":"0.31", "size":"91.9", "side":"SELL", "hash":"b483b610193660dddb158d96c9b612589a64afb1", "best_bid":"0.18", "best_ask":"0.19"}], "timestamp":"1784449597029", "event_type":"price_change"}
{"market":"0x982eae4503214e5d7992668e93f48f42e4707b92e23bb45f8d52d321f643cbe3", "price_changes":[{"asset_id":"37613674580450069178400687025689415665506452565086963049482350052080099056186", "price":"0.01", "size":"17929.98", "side":"BUY", "hash":"a6d03a8e3718eee9ea97df86999fe7d3ffdd225d", "best_bid":"0.18", "best_ask":"0.19"}, {"asset_id":"74913635031537477155015393896000154190746945075332596665612975928350948042868", "price":"0.99", "size":"17929.98", "side":"SELL", "hash":"55d534d2aa94c5bd88052c19c0751d2ba43ccf70", "best_bid":"0.81", "best_ask":"0.82"}], "timestamp":"1784449597031", "event_type":"price_change"}
{"market":"0x982eae4503214e5d7992668e93f48f42e4707b92e23bb45f8d52d321f643cbe3", "price_changes":[{"asset_id":"37613674580450069178400687025689415665506452565086963049482350052080099056186", "price":"0.01", "size":"17924.98", "side":"BUY", "hash":"e428e9399278c4a12ebbc31da6781c1ccccb7cb6", "best_bid":"0.18", "best_ask":"0.19"}, {"asset_id":"74913635031537477155015393896000154190746945075332596665612975928350948042868", "price":"0.99", "size":"17924.98", "side":"SELL", "hash":"ab5c3044cb2e8821263cafe29b321b3488207bf4", "best_bid":"0.81", "best_ask":"0.82"}], "timestamp":"1784449597031", "event_type":"price_change"}
{"market":"0x982eae4503214e5d7992668e93f48f42e4707b92e23bb45f8d52d321f643cbe3", "price_changes":[{"asset_id":"74913635031537477155015393896000154190746945075332596665612975928350948042868", "price":"0.01", "size":"16794.13", "side":"BUY", "hash":"3cd5a88648bc1c911edb2b372228a3d40d2ca207", "best_bid":"0.81", "best_ask":"0.82"}, {"asset_id":"37613674580450069178400687025689415665506452565086963049482350052080099056186", "price":"0.99", "size":"16794.13", "side":"SELL", "hash":"fe7d4455ba774dd084798a3c25847ece4b56d974", "best_bid":"0.18", "best_ask":"0.19"}], "timestamp":"1784449597032", "event_type":"price_change"}
{"market":"0x982eae4503214e5d7992668e93f48f42e4707b92e23bb45f8d52d321f643cbe3", "price_changes":[{"asset_id":"74913635031537477155015393896000154190746945075332596665612975928350948042868", "price":"0.01", "size":"16694.13", "side":"BUY", "hash":"a2138c403af138cb0cad9e858573147ce3b1e584", "best_bid":"0.81", "best_ask":"0.82"}, {"asset_id":"37613674580450069178400687025689415665506452565086963049482350052080099056186", "price":"0.99", "size":"16694.13", "side":"SELL", "hash":"1bb0268373ef05143e077c3828fb6625ae46fc88", "best_bid":"0.18", "best_ask":"0.19"}], "timestamp":"1784449597033", "event_type":"price_change"}
{"market":"0x982eae4503214e5d7992668e93f48f42e4707b92e23bb45f8d52d321f643cbe3", "price_changes":[{"asset_id":"74913635031537477155015393896000154190746945075332596665612975928350948042868", "price":"0.01", "size":"16699.13", "side":"BUY", "hash":"e54d0b22482fd5dfc99140fa2852ea6da6bb3b42", "best_bid":"0.81", "best_ask":"0.82"}, {"asset_id":"37613674580450069178400687025689415665506452565086963049482350052080099056186", "price":"0.99", "size":"16699.13", "side":"SELL", "hash":"edb1abb29d59cc9bb21cf10a713c560d45a289e3", "best_bid":"0.18", "best_ask":"0.19"}], "timestamp":"1784449597036", "event_type":"price_change"}
{"market":"0x982eae4503214e5d7992668e93f48f42e4707b92e23bb45f8d52d321f643cbe3", "price_changes":[{"asset_id":"37613674580450069178400687025689415665506452565086963049482350052080099056186", "price":"0.14", "size":"245.34", "side":"BUY", "hash":"37b2d98fd843beefc156b0d2f19bd1ba6fa3b766", "best_bid":"0.18", "best_ask":"0.19"}, {"asset_id":"74913635031537477155015393896000154190746945075332596665612975928350948042868", "price":"0.86", "size":"245.34", "side":"SELL", "hash":"e87a3b6383b692795267accf9a0f90fd2e3a6f7a", "best_bid":"0.81", "best_ask":"0.82"}], "timestamp":"1784449597037", "event_type":"price_change"}
{"market":"0x982eae4503214e5d7992668e93f48f42e4707b92e23bb45f8d52d321f643cbe3", "price_changes":[{"asset_id":"37613674580450069178400687025689415665506452565086963049482350052080099056186", "price":"0.01", "size":"17929.98", "side":"BUY", "hash":"4490d5b03d226c7021ba2949f85e172222448758", "best_bid":"0.18", "best_ask":"0.19"}, {"asset_id":"74913635031537477155015393896000154190746945075332596665612975928350948042868", "price":"0.99", "size":"17929.98", "side":"SELL", "hash":"cf94c115a2a0b61b22e2021ecaa052a0aaed8be6", "best_bid":"0.81", "best_ask":"0.82"}], "timestamp":"1784449597039", "event_type":"price_change"}
{"market":"0x982eae4503214e5d7992668e93f48f42e4707b92e23bb45f8d52d321f643cbe3", "price_changes":[{"asset_id":"74913635031537477155015393896000154190746945075332596665612975928350948042868", "price":"0.01", "size":"16694.13", "side":"BUY", "hash":"ffe2519e5c91a3ea652c19023c12a44e19eef90c", "best_bid":"0.81", "best_ask":"0.82"}, {"asset_id":"37613674580450069178400687025689415665506452565086963049482350052080099056186", "price":"0.99", "size":"16694.13", "side":"SELL", "hash":"3adefdd0440e8e4e9741038c0c9c8f59f68c9448", "best_bid":"0.18", "best_ask":"0.19"}], "timestamp":"1784449597041", "event_type":"price_change"}
{"market":"0x982eae4503214e5d7992668e93f48f42e4707b92e23bb45f8d52d321f643cbe3", "price_changes":[{"asset_id":"37613674580450069178400687025689415665506452565086963049482350052080099056186", "price":"0.01", "size":"17924.98", "side":"BUY", "hash":"1bb6986883a75ab0153d498be54023ed9e0cde04", "best_bid":"0.18", "best_ask":"0.19"}, {"asset_id":"74913635031537477155015393896000154190746945075332596665612975928350948042868", "price":"0.99", "size":"17924.98", "side":"SELL", "hash":"0dfd22d5a650c3b0e902322030e2240a67aa77b8", "best_bid":"0.81", "best_ask":"0.82"}], "timestamp":"1784449597050", "event_type":"price_change"}
{"market":"0x982eae4503214e5d7992668e93f48f42e4707b92e23bb45f8d52d321f643cbe3", "price_changes":[{"asset_id":"74913635031537477155015393896000154190746945075332596665612975928350948042868", "price":"0.04", "size":"1462.1", "side":"BUY", "hash":"0e432ae1535b3c0ddbdea29e4d05678f9c74b39b", "best_bid":"0.81", "best_ask":"0.82"}, {"asset_id":"37613674580450069178400687025689415665506452565086963049482350052080099056186", "price":"0.96", "size":"1462.1", "side":"SELL", "hash":"eed9ee95c13fc5187f6889ce50b9443b5e7a6a55", "best_bid":"0.18", "best_ask":"0.19"}], "timestamp":"1784449597059", "event_type":"price_change"}
{"market":"0x982eae4503214e5d7992668e93f48f42e4707b92e23bb45f8d52d321f643cbe3", "price_changes":[{"asset_id":"74913635031537477155015393896000154190746945075332596665612975928350948042868", "price":"0.01", "size":"16699.14", "side":"BUY", "hash":"0f97734be43549bde3a6830e9b5f41417e86ac0f", "best_bid":"0.81", "best_ask":"0.82"}, {"asset_id":"37613674580450069178400687025689415665506452565086963049482350052080099056186", "price":"0.99", "size":"16699.14", "side":"SELL", "hash":"14c66b15e4013091e8c8a225517ec9cf9e0a11f3", "best_bid":"0.18", "best_ask":"0.19"}], "timestamp":"1784449597059", "event_type":"price_change"}
{"market":"0x982eae4503214e5d7992668e93f48f42e4707b92e23bb45f8d52d321f643cbe3", "price_changes":[{"asset_id":"74913635031537477155015393896000154190746945075332596665612975928350948042868", "price":"0.79", "size":"93.19", "side":"BUY", "hash":"596d46f67593d4cff1b0b65daeb1c6a2f130330a", "best_bid":"0.81", "best_ask":"0.82"}, {"asset_id":"37613674580450069178400687025689415665506452565086963049482350052080099056186", "price":"0.21", "size":"93.19", "side":"SELL", "hash":"5d5fe1848876a6d1be6d0c0d2262e2b22c7c2eb6", "best_bid":"0.18", "best_ask":"0.19"}], "timestamp":"1784449597064", "event_type":"price_change"}
{"market":"0x982eae4503214e5d7992668e93f48f42e4707b92e23bb45f8d52d321f643cbe3", "price_changes":[{"asset_id":"37613674580450069178400687025689415665506452565086963049482350052080099056186", "price":"0.16", "size":"106.17", "side":"BUY", "hash":"3066c6281e0fb82a6c2c4a7eb4e5d0ec10406baa", "best_bid":"0.18", "best_ask":"0.19"}, {"asset_id":"74913635031537477155015393896000154190746945075332596665612975928350948042868", "price":"0.84", "size":"106.17", "side":"SELL", "hash":"359c9aa312299fb8b8fa43afe19e830759a373fa", "best_bid":"0.81", "best_ask":"0.82"}], "timestamp":"1784449597065", "event_type":"price_change"}
{"market":"0x982eae4503214e5d7992668e93f48f42e4707b92e23bb45f8d52d321f643cbe3", "price_changes":[{"asset_id":"74913635031537477155015393896000154190746945075332596665612975928350948042868", "price":"0.7", "size":"88.04", "side":"BUY", "hash":"9e95b5380b559311729628165f47d79fa68bb835", "best_bid":"0.81", "best_ask":"0.82"}, {"asset_id":"37613674580450069178400687025689415665506452565086963049482350052080099056186", "price":"0.3", "size":"88.04", "side":"SELL", "hash":"c450fd19c15310263ec49658b4576ed4a5812a52", "best_bid":"0.18", "best_ask":"0.19"}], "timestamp":"1784449597067", "event_type":"price_change"}
{"market":"0x982eae4503214e5d7992668e93f48f42e4707b92e23bb45f8d52d321f643cbe3", "price_changes":[{"asset_id":"37613674580450069178400687025689415665506452565086963049482350052080099056186", "price":"0.27", "size":"174.41", "side":"SELL", "hash":"bdc1e944d08fb341b87399980e46fd027ed657a2", "best_bid":"0.18", "best_ask":"0.19"}, {"asset_id":"74913635031537477155015393896000154190746945075332596665612975928350948042868", "price":"0.73", "size":"174.41", "side":"BUY", "hash":"3c666d898784f8628d2f58065675780dd783cc6c", "best_bid":"0.81", "best_ask":"0.82"}], "timestamp":"1784449597070", "event_type":"price_change"}
{"market":"0x982eae4503214e5d7992668e93f48f42e4707b92e23bb45f8d52d321f643cbe3", "asset_id":"74913635031537477155015393896000154190746945075332596665612975928350948042868", "price":"0.82", "size":"20", "fee_rate_bps":"0", "side":"BUY", "timestamp":"1784449597070", "event_type":"last_trade_price", "transaction_hash":"0x1a4bbd4c097b6340ddd63cf453351d53443747fabd6f42bbfefb6f62466dbbae"}
{"market":"0x982eae4503214e5d7992668e93f48f42e4707b92e23bb45f8d52d321f643cbe3", "price_changes":[{"asset_id":"74913635031537477155015393896000154190746945075332596665612975928350948042868", "price":"0.01", "size":"16799.14", "side":"BUY", "hash":"b42a1f015b475c0e6d083c65b17b0b87e16fad5c", "best_bid":"0.81", "best_ask":"0.82"}, {"asset_id":"37613674580450069178400687025689415665506452565086963049482350052080099056186", "price":"0.99", "size":"16799.14", "side":"SELL", "hash":"06221241a5837a1b31bab7c92ba9831ec509036a", "best_bid":"0.18", "best_ask":"0.19"}], "timestamp":"1784449597071", "event_type":"price_change"}
{"market":"0x982eae4503214e5d7992668e93f48f42e4707b92e23bb45f8d52d321f643cbe3", "price_changes":[{"asset_id":"37613674580450069178400687025689415665506452565086963049482350052080099056186", "price":"0.42", "size":"101.12", "side":"SELL", "hash":"9b127e7f8dcc85f6c3115506a270393701516559", "best_bid":"0.18", "best_ask":"0.19"}, {"asset_id":"74913635031537477155015393896000154190746945075332596665612975928350948042868", "price":"0.58", "size":"101.12", "side":"BUY", "hash":"17a17cc8048c3fb168c40b111202254a796bfd0b", "best_bid":"0.81", "best_ask":"0.82"}], "timestamp":"1784449597074", "event_type":"price_change"}
{"market":"0x982eae4503214e5d7992668e93f48f42e4707b92e23bb45f8d52d321f643cbe3", "price_changes":[{"asset_id":"74913635031537477155015393896000154190746945075332596665612975928350948042868", "price":"0.01", "size":"16794.14", "side":"BUY", "hash":"be1a7a7909be79053240fd7cfba0fbf0b1f228a2", "best_bid":"0.81", "best_ask":"0.82"}, {"asset_id":"37613674580450069178400687025689415665506452565086963049482350052080099056186", "price":"0.99", "size":"16794.14", "side":"SELL", "hash":"a0021ee60e6c0ab129c663c98a1ad30ee2d52b5c", "best_bid":"0.18", "best_ask":"0.19"}], "timestamp":"1784449597074", "event_type":"price_change"}
{"market":"0x982eae4503214e5d7992668e93f48f42e4707b92e23bb45f8d52d321f643cbe3", "price_changes":[{"asset_id":"74913635031537477155015393896000154190746945075332596665612975928350948042868", "price":"0.8", "size":"163.28", "side":"BUY", "hash":"d55f6b672d2cd5746075eb8cc1b51b9cde4c3a1c", "best_bid":"0.81", "best_ask":"0.82"}, {"asset_id":"37613674580450069178400687025689415665506452565086963049482350052080099056186", "price":"0.2", "size":"163.28", "side":"SELL", "hash":"003724e40b4c6ac8c294aa8261d859306faacfcb", "best_bid":"0.18", "best_ask":"0.19"}], "timestamp":"1784449597080", "event_type":"price_change"}
{"market":"0x982eae4503214e5d7992668e93f48f42e4707b92e23bb45f8d52d321f643cbe3", "price_changes":[{"asset_id":"37613674580450069178400687025689415665506452565086963049482350052080099056186", "price":"0.05", "size":"1803.6", "side":"BUY", "hash":"7d80a128f90f371ee0ac9b6dea137a204e4ae808", "best_bid":"0.18", "best_ask":"0.19"}, {"asset_id":"74913635031537477155015393896000154190746945075332596665612975928350948042868", "price":"0.95", "size":"1803.6", "side":"SELL", "hash":"339468c1e602a6828dd0000cf6aff7796e92ec2a", "best_bid":"0.81", "best_ask":"0.82"}], "timestamp":"1784449597088", "event_type":"price_change"}
{"market":"0x982eae4503214e5d7992668e93f48f42e4707b92e23bb45f8d52d321f643cbe3", "price_changes":[{"asset_id":"74913635031537477155015393896000154190746945075332596665612975928350948042868", "price":"0.01", "size":"16789.13", "side":"BUY", "hash":"72a68bd32f75a6922f48fd32038a69a783247cff", "best_bid":"0.81", "best_ask":"0.82"}, {"asset_id":"37613674580450069178400687025689415665506452565086963049482350052080099056186", "price":"0.99", "size":"16789.13", "side":"SELL", "hash":"aef2c0e31da644144371b0fe21d39ac300d4ebc3", "best_bid":"0.18", "best_ask":"0.19"}], "timestamp":"1784449597088", "event_type":"price_change"}
{"market":"0x982eae4503214e5d7992668e93f48f42e4707b92e23bb45f8d52d321f643cbe3", "price_changes":[{"asset_id":"37613674580450069178400687025689415665506452565086963049482350052080099056186", "price":"0.18", "size":"0", "side":"BUY", "hash":"c9ec6f634c0aa7017fc5acb51dc792bde25e2b2a", "best_bid":"0.17", "best_ask":"0.19"}, {"asset_id":"74913635031537477155015393896000154190746945075332596665612975928350948042868", "price":"0.82", "size":"0", "side":"SELL", "hash":"652df6a4dab6d21f20592c67673775f48aa9ebc7", "best_bid":"0.81", "best_ask":"0.83"}], "timestamp":"1784449597089", "event_type":"price_change"}
{"market":"0x982eae4503214e5d7992668e93f48f42e4707b92e23bb45f8d52d321f643cbe3", "price_changes":[{"asset_id":"74913635031537477155015393896000154190746945075332596665612975928350948042868", "price":"0.82", "size":"16.66", "side":"BUY", "hash":"82d905bf8d588c956130a5c4639bd2c05f4b03a9", "best_bid":"0.82", "best_ask":"0.83"}, {"asset_id":"37613674580450069178400687025689415665506452565086963049482350052080099056186", "price":"0.18", "size":"16.66", "side":"SELL", "hash":"9d4a1a9946e9705c5124bcbd4eddd394338cffae", "best_bid":"0.17", "best_ask":"0.18"}], "timestamp":"1784449597090", "event_type":"price_change"}
{"market":"0x982eae4503214e5d7992668e93f48f42e4707b92e23bb45f8d52d321f643cbe3", "price_changes":[{"asset_id":"74913635031537477155015393896000154190746945075332596665612975928350948042868", "price":"0.82", "size":"66.66", "side":"BUY", "hash":"28625f17226df76e65dd59a5dac7e4c934e21b16", "best_bid":"0.82", "best_ask":"0.83"}, {"asset_id":"37613674580450069178400687025689415665506452565086963049482350052080099056186", "price":"0.18", "size":"66.66", "side":"SELL", "hash":"6704747504d7fad6e43479c52686a9d53fd500f0", "best_bid":"0.17", "best_ask":"0.18"}], "timestamp":"1784449597090", "event_type":"price_change"}
{"market":"0x982eae4503214e5d7992668e93f48f42e4707b92e23bb45f8d52d321f643cbe3", "price_changes":[{"asset_id":"74913635031537477155015393896000154190746945075332596665612975928350948042868", "price":"0.82", "size":"79.99", "side":"BUY", "hash":"699187db39bb173f789fd0c7eddec3ee2df18abf", "best_bid":"0.82", "best_ask":"0.83"}, {"asset_id":"37613674580450069178400687025689415665506452565086963049482350052080099056186", "price":"0.18", "size":"79.99", "side":"SELL", "hash":"951ca53da1df02284b0103f89d25aeda5f06d550", "best_bid":"0.17", "best_ask":"0.18"}], "timestamp":"1784449597092", "event_type":"price_change"}
{"market":"0x982eae4503214e5d7992668e93f48f42e4707b92e23bb45f8d52d321f643cbe3", "price_changes":[{"asset_id":"74913635031537477155015393896000154190746945075332596665612975928350948042868", "price":"0.82", "size":"96.65", "side":"BUY", "hash":"2d7c3ccb287d31fa139707d441595b2de8e9153c", "best_bid":"0.82", "best_ask":"0.83"}, {"asset_id":"37613674580450069178400687025689415665506452565086963049482350052080099056186", "price":"0.18", "size":"96.65", "side":"SELL", "hash":"f87dd1643eb2a184a36cbb8a05a8e1daa2248584", "best_bid":"0.17", "best_ask":"0.18"}], "timestamp":"1784449597093", "event_type":"price_change"}
{"market":"0x982eae4503214e5d7992668e93f48f42e4707b92e23bb45f8d52d321f643cbe3", "price_changes":[{"asset_id":"74913635031537477155015393896000154190746945075332596665612975928350948042868", "price":"0.7", "size":"103.04", "side":"BUY", "hash":"ca1873f584c78ec71e5c2ea6cc7628f0a2103e53", "best_bid":"0.82", "best_ask":"0.83"}, {"asset_id":"37613674580450069178400687025689415665506452565086963049482350052080099056186", "price":"0.3", "size":"103.04", "side":"SELL", "hash":"adff94e8c20072aec7e8116773a7543493fbcf01", "best_bid":"0.17", "best_ask":"0.18"}], "timestamp":"1784449597096", "event_type":"price_change"}
{"market":"0x982eae4503214e5d7992668e93f48f42e4707b92e23bb45f8d52d321f643cbe3", "price_changes":[{"asset_id":"74913635031537477155015393896000154190746945075332596665612975928350948042868", "price":"0.73", "size":"179.41", "side":"BUY", "hash":"cb9c11f6c8928e2b8bcd18a0bebf5d8df075ba44", "best_bid":"0.82", "best_ask":"0.83"}, {"asset_id":"37613674580450069178400687025689415665506452565086963049482350052080099056186", "price":"0.27", "size":"179.41", "side":"SELL", "hash":"d2e57462f6397c99915c27c2cdcf8dd3540e6352", "best_bid":"0.17", "best_ask":"0.18"}], "timestamp":"1784449597098", "event_type":"price_change"}
{"market":"0x982eae4503214e5d7992668e93f48f42e4707b92e23bb45f8d52d321f643cbe3", "price_changes":[{"asset_id":"74913635031537477155015393896000154190746945075332596665612975928350948042868", "price":"0.01", "size":"16784.13", "side":"BUY", "hash":"02a13e1b50899207996b1cc6f7cfaed35d9fdfed", "best_bid":"0.82", "best_ask":"0.83"}, {"asset_id":"37613674580450069178400687025689415665506452565086963049482350052080099056186", "price":"0.99", "size":"16784.13", "side":"SELL", "hash":"6ee4ef8a3a68f39eeb4c6ccffa3d896d059a9db6", "best_bid":"0.17", "best_ask":"0.18"}], "timestamp":"1784449597104", "event_type":"price_change"}
{"market":"0x982eae4503214e5d7992668e93f48f42e4707b92e23bb45f8d52d321f643cbe3", "price_changes":[{"asset_id":"74913635031537477155015393896000154190746945075332596665612975928350948042868", "price":"0.01", "size":"16684.13", "side":"BUY", "hash":"0027aa3296c5fe4209621842e1fd34bff0092c27", "best_bid":"0.82", "best_ask":"0.83"}, {"asset_id":"37613674580450069178400687025689415665506452565086963049482350052080099056186", "price":"0.99", "size":"16684.13", "side":"SELL", "hash":"347f41fce72ba9738c17740c43b06f6c039cf9b8", "best_bid":"0.17", "best_ask":"0.18"}], "timestamp":"1784449597108", "event_type":"price_change"}
{"market":"0x982eae4503214e5d7992668e93f48f42e4707b92e23bb45f8d52d321f643cbe3", "price_changes":[{"asset_id":"74913635031537477155015393896000154190746945075332596665612975928350948042868", "price":"0.81", "size":"361.52", "side":"BUY", "hash":"864fd33f92b64c5b274f19e3234d29862ac7db2b", "best_bid":"0.82", "best_ask":"0.83"}, {"asset_id":"37613674580450069178400687025689415665506452565086963049482350052080099056186", "price":"0.19", "size":"361.52", "side":"SELL", "hash":"5eddac92d0982d94a17044056e6a36c254a90ce4", "best_bid":"0.17", "best_ask":"0.18"}], "timestamp":"1784449597109", "event_type":"price_change"}
{"market":"0x982eae4503214e5d7992668e93f48f42e4707b92e23bb45f8d52d321f643cbe3", "price_changes":[{"asset_id":"74913635031537477155015393896000154190746945075332596665612975928350948042868", "price":"0.81", "size":"355.75", "side":"BUY", "hash":"ec02b38883e8355cc92d2e177a88ad7f030cd669", "best_bid":"0.82", "best_ask":"0.83"}, {"asset_id":"37613674580450069178400687025689415665506452565086963049482350052080099056186", "price":"0.19", "size":"355.75", "side":"SELL", "hash":"ccc858f5295197ed6841e17064ea6e7ef9bc38c2", "best_bid":"0.17", "best_ask":"0.18"}], "timestamp":"1784449597110", "event_type":"price_change"}
{"market":"0x982eae4503214e5d7992668e93f48f42e4707b92e23bb45f8d52d321f643cbe3", "price_changes":[{"asset_id":"74913635031537477155015393896000154190746945075332596665612975928350948042868", "price":"0.72", "size":"283", "side":"BUY", "hash":"bd1a15ff3b284d3011dbeda6b6b21badad493d94", "best_bid":"0.82", "best_ask":"0.83"}, {"asset_id":"37613674580450069178400687025689415665506452565086963049482350052080099056186", "price":"0.28", "size":"283", "side":"SELL", "hash":"0d9e280b9ffe203315c9b2731448ae75dec4d87f", "best_bid":"0.17", "best_ask":"0.18"}], "timestamp":"1784449597111", "event_type":"price_change"}
{"market":"0x982eae4503214e5d7992668e93f48f42e4707b92e23bb45f8d52d321f643cbe3", "asset_id":"37613674580450069178400687025689415665506452565086963049482350052080099056186", "price":"0.19", "size":"5.263156", "fee_rate_bps":"0", "side":"BUY", "timestamp":"1784449597112", "event_type":"last_trade_price", "transaction_hash":"0x8a3543f581e133a589d6a3059f0bab31cda0d8ea8df364c06804202d0c0e3011"}
{"market":"0x982eae4503214e5d7992668e93f48f42e4707b92e23bb45f8d52d321f643cbe3", "price_changes":[{"asset_id":"74913635031537477155015393896000154190746945075332596665612975928350948042868", "price":"0.7", "size":"88.04", "side":"BUY", "hash":"ea67b2142cc95fbc53f7683cdcfc719c04ca476a", "best_bid":"0.82", "best_ask":"0.83"}, {"asset_id":"37613674580450069178400687025689415665506452565086963049482350052080099056186", "price":"0.3", "size":"88.04", "side":"SELL", "hash":"5f39ec09bcd501ab2d854f3fbc50e890630fad52", "best_bid":"0.17", "best_ask":"0.18"}], "timestamp":"1784449597116", "event_type":"price_change"}
{"market":"0x982eae4503214e5d7992668e93f48f42e4707b92e23bb45f8d52d321f643cbe3", "price_changes":[{"asset_id":"37613674580450069178400687025689415665506452565086963049482350052080099056186", "price":"0.19", "size":"350.75", "side":"SELL", "hash":"9757933049e5dae99539318d64bc7ac28f309811", "best_bid":"0.17", "best_ask":"0.18"}, {"asset_id":"74913635031537477155015393896000154190746945075332596665612975928350948042868", "price":"0.81", "size":"350.75", "side":"BUY", "hash":"c77bc09753e71de176ccee8b2106740152d5d8b9", "best_bid":"0.82", "best_ask":"0.83"}], "timestamp":"1784449597116", "event_type":"price_change"}
{"market":"0x982eae4503214e5d7992668e93f48f42e4707b92e23bb45f8d52d321f643cbe3", "price_changes":[{"asset_id":"74913635031537477155015393896000154190746945075332596665612975928350948042868", "price":"0.43", "size":"109.8", "side":"BUY", "hash":"459b54d4ed631a002d9e5e650631e777f4e11c22", "best_bid":"0.82", "best_ask":"0.83"}, {"asset_id":"37613674580450069178400687025689415665506452565086963049482350052080099056186", "price":"0.57", "size":"109.8", "side":"SELL", "hash":"d60cf62f244038c6c8bd632167ec47f556cbb703", "best_bid":"0.17", "best_ask":"0.18"}], "timestamp":"1784449597117", "event_type":"price_change"}
{"market":"0x982eae4503214e5d7992668e93f48f42e4707b92e23bb45f8d52d321f643cbe3", "price_changes":[{"asset_id":"74913635031537477155015393896000154190746945075332596665612975928350948042868", "price":"0.82", "size":"121.65", "side":"BUY", "hash":"e9087253bc9836c35b525d8af49c9131dafe9bd8", "best_bid":"0.82", "best_ask":"0.83"}, {"asset_id":"37613674580450069178400687025689415665506452565086963049482350052080099056186", "price":"0.18", "size":"121.65", "side":"SELL", "hash":"ee98aa612b91598e1e78d608e32a239357444926", "best_bid":"0.17", "best_ask":"0.18"}], "timestamp":"1784449597117", "event_type":"price_change"}
{"market":"0x982eae4503214e5d7992668e93f48f42e4707b92e23bb45f8d52d321f643cbe3", "price_changes":[{"asset_id":"74913635031537477155015393896000154190746945075332596665612975928350948042868", "price":"0.81", "size":"334.09", "side":"BUY", "hash":"80f048d8cdeba1f927b359d89e67f5a84e9057db", "best_bid":"0.82", "best_ask":"0.83"}, {"asset_id":"37613674580450069178400687025689415665506452565086963049482350052080099056186", "price":"0.19", "size":"334.09", "side":"SELL", "hash":"6d9ba81b339684f088f9ea837cc69066d4bb7663", "best_bid":"0.17", "best_ask":"0.18"}], "timestamp":"1784449597118", "event_type":"price_change"}
{"market":"0x982eae4503214e5d7992668e93f48f42e4707b92e23bb45f8d52d321f643cbe3", "price_changes":[{"asset_id":"74913635031537477155015393896000154190746945075332596665612975928350948042868", "price":"0.81", "size":"333.64", "side":"BUY", "hash":"b3b0ae233d244138946179dc07743da3272634f8", "best_bid":"0.82", "best_ask":"0.83"}, {"asset_id":"37613674580450069178400687025689415665506452565086963049482350052080099056186", "price":"0.19", "size":"333.64", "side":"SELL", "hash":"9ace22b182d0a3cb4116fe68e36eaf2a04c14708", "best_bid":"0.17", "best_ask":"0.18"}], "timestamp":"1784449597118", "event_type":"price_change"}
{"market":"0x982eae4503214e5d7992668e93f48f42e4707b92e23bb45f8d52d321f643cbe3", "price_changes":[{"asset_id":"37613674580450069178400687025689415665506452565086963049482350052080099056186", "price":"0.18", "size":"126.65", "side":"SELL", "hash":"199f26e1d665b73f4cee0602e91d5458613c2e14", "best_bid":"0.17", "best_ask":"0.18"}, {"asset_id":"74913635031537477155015393896000154190746945075332596665612975928350948042868", "price":"0.82", "size":"126.65", "side":"BUY", "hash":"19b91373077a17c05f15c22de39bb34b6ecd1f2d", "best_bid":"0.82", "best_ask":"0.83"}], "timestamp":"1784449597118", "event_type":"price_change"}
{"market":"0x982eae4503214e5d7992668e93f48f42e4707b92e23bb45f8d52d321f643cbe3", "price_changes":[{"asset_id":"37613674580450069178400687025689415665506452565086963049482350052080099056186", "price":"0.11", "size":"508.73", "side":"BUY", "hash":"ba4da879de5e2d590c42fab777b291271d24ed45", "best_bid":"0.17", "best_ask":"0.18"}, {"asset_id":"74913635031537477155015393896000154190746945075332596665612975928350948042868", "price":"0.89", "size":"508.73", "side":"SELL", "hash":"877ed6ed223f4965c7d37584e9a6029f1c34d870", "best_bid":"0.82", "best_ask":"0.83"}], "timestamp":"1784449597119", "event_type":"price_change"}
{"market":"0x982eae4503214e5d7992668e93f48f42e4707b92e23bb45f8d52d321f643cbe3", "price_changes":[{"asset_id":"37613674580450069178400687025689415665506452565086963049482350052080099056186", "price":"0.12", "size":"204.17", "side":"BUY", "hash":"72e6227163cb7ae816cc944a88d80ffe526bd7e4", "best_bid":"0.17", "best_ask":"0.18"}, {"asset_id":"74913635031537477155015393896000154190746945075332596665612975928350948042868", "price":"0.88", "size":"204.17", "side":"SELL", "hash":"d85e15bf80c4801bbc8dddb139981d1f3e87cd0b", "best_bid":"0.82", "best_ask":"0.83"}], "timestamp":"1784449597119", "event_type":"price_change"}
{"market":"0x982eae4503214e5d7992668e93f48f42e4707b92e23bb45f8d52d321f643cbe3", "price_changes":[{"asset_id":"37613674580450069178400687025689415665506452565086963049482350052080099056186", "price":"0.15", "size":"160.71", "side":"BUY", "hash":"72e6227163cb7ae816cc944a88d80ffe526bd7e4", "best_bid":"0.17", "best_ask":"0.18"}, {"asset_id":"74913635031537477155015393896000154190746945075332596665612975928350948042868", "price":"0.85", "size":"160.71", "side":"SELL", "hash":"d85e15bf80c4801bbc8dddb139981d1f3e87cd0b", "best_bid":"0.82", "best_ask":"0.83"}], "timestamp":"1784449597119", "event_type":"price_change"}
{"market":"0x982eae4503214e5d7992668e93f48f42e4707b92e23bb45f8d52d321f643cbe3", "price_changes":[{"asset_id":"37613674580450069178400687025689415665506452565086963049482350052080099056186", "price":"0.13", "size":"389.4", "side":"BUY", "hash":"72e6227163cb7ae816cc944a88d80ffe526bd7e4", "best_bid":"0.17", "best_ask":"0.18"}, {"asset_id":"74913635031537477155015393896000154190746945075332596665612975928350948042868", "price":"0.87", "size":"389.4", "side":"SELL", "hash":"d85e15bf80c4801bbc8dddb139981d1f3e87cd0b", "best_bid":"0.82", "best_ask":"0.83"}], "timestamp":"1784449597119", "event_type":"price_change"}
{"market":"0x982eae4503214e5d7992668e93f48f42e4707b92e23bb45f8d52d321f643cbe3", "price_changes":[{"asset_id":"37613674580450069178400687025689415665506452565086963049482350052080099056186", "price":"0.14", "size":"237.34", "side":"BUY", "hash":"72e6227163cb7ae816cc944a88d80ffe526bd7e4", "best_bid":"0.17", "best_ask":"0.18"}, {"asset_id":"74913635031537477155015393896000154190746945075332596665612975928350948042868", "price":"0.86", "size":"237.34", "side":"SELL", "hash":"d85e15bf80c4801bbc8dddb139981d1f3e87cd0b", "best_bid":"0.82", "best_ask":"0.83"}], "timestamp":"1784449597119", "event_type":"price_change"}
{"market":"0x982eae4503214e5d7992668e93f48f42e4707b92e23bb45f8d52d321f643cbe3", "price_changes":[{"asset_id":"74913635031537477155015393896000154190746945075332596665612975928350948042868", "price":"0.78", "size":"228.41", "side":"BUY", "hash":"6cb8c5fc8fb86a14ee3ea6820742eccf5bcf6151", "best_bid":"0.82", "best_ask":"0.83"}, {"asset_id":"37613674580450069178400687025689415665506452565086963049482350052080099056186", "price":"0.22", "size":"228.41", "side":"SELL", "hash":"cb1bf2b0172a070ffd5f5f00d8d15253f28d077c", "best_bid":"0.17", "best_ask":"0.18"}], "timestamp":"1784449597120", "event_type":"price_change"}
{"market":"0x982eae4503214e5d7992668e93f48f42e4707b92e23bb45f8d52d321f643cbe3", "price_changes":[{"asset_id":"74913635031537477155015393896000154190746945075332596665612975928350948042868", "price":"0.81", "size":"320.31", "side":"BUY", "hash":"2d8939732d78631e10cb137063d11264cb07006d", "best_bid":"0.82", "best_ask":"0.83"}, {"asset_id":"37613674580450069178400687025689415665506452565086963049482350052080099056186", "price":"0.19", "size":"320.31", "side":"SELL", "hash":"939159e6ab1d20df7da40642ed9e74441c3143f1", "best_bid":"0.17", "best_ask":"0.18"}], "timestamp":"1784449597120", "event_type":"price_change"}
{"market":"0x982eae4503214e5d7992668e93f48f42e4707b92e23bb45f8d52d321f643cbe3", "price_changes":[{"asset_id":"74913635031537477155015393896000154190746945075332596665612975928350948042868", "price":"0.82", "size":"133.07", "side":"BUY", "hash":"8c4f82d009868f68005f8abc3178b3edb6f01d7d", "best_bid":"0.82", "best_ask":"0.83"}, {"asset_id":"37613674580450069178400687025689415665506452565086963049482350052080099056186", "price":"0.18", "size":"133.07", "side":"SELL", "hash":"bdefa129db214e6f65973b2e65890cd46e16c144", "best_bid":"0.17", "best_ask":"0.18"}], "timestamp":"1784449597121", "event_type":"price_change"}
{"market":"0x982eae4503214e5d7992668e93f48f42e4707b92e23bb45f8d52d321f643cbe3", "price_changes":[{"asset_id":"37613674580450069178400687025689415665506452565086963049482350052080099056186", "price":"0.17", "size":"39.31", "side":"BUY", "hash":"3c2f03757efea3ab1f43aab5c701132eaaa5e390", "best_bid":"0.17", "best_ask":"0.18"}, {"asset_id":"74913635031537477155015393896000154190746945075332596665612975928350948042868", "price":"0.83", "size":"39.31", "side":"SELL", "hash":"4d7f9e0d8f1165a33301fa1886d3bf55cee18a53", "best_bid":"0.82", "best_ask":"0.83"}], "timestamp":"1784449597123", "event_type":"price_change"}
{"market":"0x982eae4503214e5d7992668e93f48f42e4707b92e23bb45f8d52d321f643cbe3", "price_changes":[{"asset_id":"74913635031537477155015393896000154190746945075332596665612975928350948042868", "price":"0.82", "size":"143.07", "side":"BUY", "hash":"632ba1b4eaefc59af164befa6cd8edf92182943e", "best_bid":"0.82", "best_ask":"0.83"}, {"asset_id":"37613674580450069178400687025689415665506452565086963049482350052080099056186", "price":"0.18", "size":"143.07", "side":"SELL", "hash":"d2fdf453c90b3ed8626b1c5ecdd6946e99f665a2", "best_bid":"0.17", "best_ask":"0.18"}], "timestamp":"1784449597125", "event_type":"price_change"}
{"market":"0x982eae4503214e5d7992668e93f48f42e4707b92e23bb45f8d52d321f643cbe3", "price_changes":[{"asset_id":"37613674580450069178400687025689415665506452565086963049482350052080099056186", "price":"0.13", "size":"397.4", "side":"BUY", "hash":"bce8d4d4210650aa0e75ecdf6731c72b2e946f22", "best_bid":"0.17", "best_ask":"0.18"}, {"asset_id":"74913635031537477155015393896000154190746945075332596665612975928350948042868", "price":"0.87", "size":"397.4", "side":"SELL", "hash":"4ab62f29ac857c735bb7d900f70089981643ad62", "best_bid":"0.82", "best_ask":"0.83"}], "timestamp":"1784449597125", "event_type":"price_change"}
{"market":"0x982eae4503214e5d7992668e93f48f42e4707b92e23bb45f8d52d321f643cbe3", "price_changes":[{"asset_id":"74913635031537477155015393896000154190746945075332596665612975928350948042868", "price":"0.73", "size":"174.41", "side":"BUY", "hash":"959f26ca261c62b373763d4d05150ca04b748da4", "best_bid":"0.82", "best_ask":"0.83"}, {"asset_id":"37613674580450069178400687025689415665506452565086963049482350052080099056186", "price":"0.27", "size":"174.41", "side":"SELL", "hash":"eef53078d976ab2fff2e35db6096622445014fa4", "best_bid":"0.17", "best_ask":"0.18"}], "timestamp":"1784449597126", "event_type":"price_change"}
{"market":"0x982eae4503214e5d7992668e93f48f42e4707b92e23bb45f8d52d321f643cbe3", "price_changes":[{"asset_id":"37613674580450069178400687025689415665506452565086963049482350052080099056186", "price":"0.14", "size":"242.34", "side":"BUY", "hash":"ff4f09f4b5d235220baae2c1ad6c3d468ab6cae4", "best_bid":"0.17", "best_ask":"0.18"}, {"asset_id":"74913635031537477155015393896000154190746945075332596665612975928350948042868", "price":"0.86", "size":"242.34", "side":"SELL", "hash":"56b2f53ceb92ae9a784f3b4471057c8c07328d8a", "best_bid":"0.82", "best_ask":"0.83"}], "timestamp":"1784449597127", "event_type":"price_change"}
{"market":"0x982eae4503214e5d7992668e93f48f42e4707b92e23bb45f8d52d321f643cbe3", "price_changes":[{"asset_id":"37613674580450069178400687025689415665506452565086963049482350052080099056186", "price":"0.12", "size":"216.17", "side":"BUY", "hash":"b4f31e669e509d8fb88016cc8864371202351b08", "best_bid":"0.17", "best_ask":"0.18"}, {"asset_id":"74913635031537477155015393896000154190746945075332596665612975928350948042868", "price":"0.88", "size":"216.17", "side":"SELL", "hash":"9286f00786b022f6d9b9360dda3d89576afe5a98", "best_bid":"0.82", "best_ask":"0.83"}], "timestamp":"1784449597127", "event_type":"price_change"}
{"market":"0x982eae4503214e5d7992668e93f48f42e4707b92e23bb45f8d52d321f643cbe3", "price_changes":[{"asset_id":"74913635031537477155015393896000154190746945075332596665612975928350948042868", "price":"0.01", "size":"16184.13", "side":"BUY", "hash":"d17ddc776d4b9c612e96d8ed5539d7bf0d8319e8", "best_bid":"0.82", "best_ask":"0.83"}, {"asset_id":"37613674580450069178400687025689415665506452565086963049482350052080099056186", "price":"0.99", "size":"16184.13", "side":"SELL", "hash":"03f0385a722b9f3318c4cb3278ff956537cc7e67", "best_bid":"0.17", "best_ask":"0.18"}], "timestamp":"1784449597131", "event_type":"price_change"}
{"market":"0x982eae4503214e5d7992668e93f48f42e4707b92e23bb45f8d52d321f643cbe3", "price_changes":[{"asset_id":"37613674580450069178400687025689415665506452565086963049482350052080099056186", "price":"0.16", "size":"91.17", "side":"BUY", "hash":"6526952aa82c1cd5c500c43dcd59336945375c4f", "best_bid":"0.17", "best_ask":"0.18"}, {"asset_id":"74913635031537477155015393896000154190746945075332596665612975928350948042868", "price":"0.84", "size":"91.17", "side":"SELL", "hash":"a5bc728a21743c8d976727b3ba8070b42166f9a9", "best_bid":"0.82", "best_ask":"0.83"}], "timestamp":"1784449597132", "event_type":"price_change"}
{"market":"0x982eae4503214e5d7992668e93f48f42e4707b92e23bb45f8d52d321f643cbe3", "price_changes":[{"asset_id":"37613674580450069178400687025689415665506452565086963049482350052080099056186", "price":"0.12", "size":"241.17", "side":"BUY", "hash":"4b760d00f700f461998ed06245888b5718426b2a", "best_bid":"0.17", "best_ask":"0.18"}, {"asset_id":"74913635031537477155015393896000154190746945075332596665612975928350948042868", "price":"0.88", "size":"241.17", "side":"SELL", "hash":"e1141c4f273a7bd2e125779d74f61734a6ea9398", "best_bid":"0.82", "best_ask":"0.83"}], "timestamp":"1784449597135", "event_type":"price_change"}
{"market":"0x982eae4503214e5d7992668e93f48f42e4707b92e23bb45f8d52d321f643cbe3", "price_changes":[{"asset_id":"74913635031537477155015393896000154190746945075332596665612975928350948042868", "price":"0.68", "size":"93.19", "side":"BUY", "hash":"76cabac0421b5b165bf318afc9a619c970754c44", "best_bid":"0.82", "best_ask":"0.83"}, {"asset_id":"37613674580450069178400687025689415665506452565086963049482350052080099056186", "price":"0.32", "size":"93.19", "side":"SELL", "hash":"09016869121ed40f56a6ab9bd7a647771573df7d", "best_bid":"0.17", "best_ask":"0.18"}], "timestamp":"1784449597137", "event_type":"price_change"}
{"market":"0x982eae4503214e5d7992668e93f48f42e4707b92e23bb45f8d52d321f643cbe3", "price_changes":[{"asset_id":"74913635031537477155015393896000154190746945075332596665612975928350948042868", "price":"0.81", "size":"335.31", "side":"BUY", "hash":"253ef720716dfb875841e5e6df631863bd409ad0", "best_bid":"0.82", "best_ask":"0.83"}, {"asset_id":"37613674580450069178400687025689415665506452565086963049482350052080099056186", "price":"0.19", "size":"335.31", "side":"SELL", "hash":"07757c0a9364cdb93d0d99ba5aad5c3405a16d5b", "best_bid":"0.17", "best_ask":"0.18"}], "timestamp":"1784449597140", "event_type":"price_change"}
{"market":"0x982eae4503214e5d7992668e93f48f42e4707b92e23bb45f8d52d321f643cbe3", "price_changes":[{"asset_id":"74913635031537477155015393896000154190746945075332596665612975928350948042868", "price":"0.02", "size":"3294.11", "side":"BUY", "hash":"406ae7b3560745d3cdbcfbe51ffb24b67af66b15", "best_bid":"0.82", "best_ask":"0.83"}, {"asset_id":"37613674580450069178400687025689415665506452565086963049482350052080099056186", "price":"0.98", "size":"3294.11", "side":"SELL", "hash":"6dccf270d3289607078051952f3e587234127e35", "best_bid":"0.17", "best_ask":"0.18"}], "timestamp":"1784449597140", "event_type":"price_change"}
{"market":"0x982eae4503214e5d7992668e93f48f42e4707b92e23bb45f8d52d321f643cbe3", "price_changes":[{"asset_id":"74913635031537477155015393896000154190746945075332596665612975928350948042868", "price":"0.82", "size":"118.07", "side":"BUY", "hash":"4dce7f253338ba48aad9b83c77218acd0f77b7c7", "best_bid":"0.82", "best_ask":"0.83"}, {"asset_id":"37613674580450069178400687025689415665506452565086963049482350052080099056186", "price":"0.18", "size":"118.07", "side":"SELL", "hash":"5a98cea54c8121910a0acc5ccf8281689aa74111", "best_bid":"0.17", "best_ask":"0.18"}], "timestamp":"1784449597143", "event_type":"price_change"}
{"market":"0x982eae4503214e5d7992668e93f48f42e4707b92e23bb45f8d52d321f643cbe3", "price_changes":[{"asset_id":"74913635031537477155015393896000154190746945075332596665612975928350948042868", "price":"0.01", "size":"16284.13", "side":"BUY", "hash":"c6c80993f5fe34cab52574a0d69a213542eaa5e5", "best_bid":"0.82", "best_ask":"0.83"}, {"asset_id":"37613674580450069178400687025689415665506452565086963049482350052080099056186", "price":"0.99", "size":"16284.13", "side":"SELL", "hash":"3c46e7026266bc9b388ffb2d133a8b302f7c30d0", "best_bid":"0.17", "best_ask":"0.18"}], "timestamp":"1784449597149", "event_type":"price_change"}
{"market":"0x982eae4503214e5d7992668e93f48f42e4707b92e23bb45f8d52d321f643cbe3", "price_changes":[{"asset_id":"74913635031537477155015393896000154190746945075332596665612975928350948042868", "price":"0.71", "size":"84", "side":"BUY", "hash":"a87f5b5c74bb542efcefb3154ec1d057b024495a", "best_bid":"0.82", "best_ask":"0.83"}, {"asset_id":"37613674580450069178400687025689415665506452565086963049482350052080099056186", "price":"0.29", "size":"84", "side":"SELL", "hash":"caef3d2f2f74405397d7b7f2e2cf841c7da8bddd", "best_bid":"0.17", "best_ask":"0.18"}], "timestamp":"1784449597151", "event_type":"price_change"}
{"market":"0x982eae4503214e5d7992668e93f48f42e4707b92e23bb45f8d52d321f643cbe3", "price_changes":[{"asset_id":"74913635031537477155015393896000154190746945075332596665612975928350948042868", "price":"0.69", "size":"116.9", "side":"BUY", "hash":"490d395b25fa1877f3c6499650beeda303a610c9", "best_bid":"0.82", "best_ask":"0.83"}, {"asset_id":"37613674580450069178400687025689415665506452565086963049482350052080099056186", "price":"0.31", "size":"116.9", "side":"SELL", "hash":"7a27af5a5e438b61f2ffd098e9036b2fa4f59b1b", "best_bid":"0.17", "best_ask":"0.18"}], "timestamp":"1784449597154", "event_type":"price_change"}
{"market":"0x982eae4503214e5d7992668e93f48f42e4707b92e23bb45f8d52d321f643cbe3", "price_changes":[{"asset_id":"37613674580450069178400687025689415665506452565086963049482350052080099056186", "price":"0.27", "size":"179.41", "side":"SELL", "hash":"a6f0139901179566551b2f64cbcdf708d9affa60", "best_bid":"0.17", "best_ask":"0.18"}, {"asset_id":"74913635031537477155015393896000154190746945075332596665612975928350948042868", "price":"0.73", "size":"179.41", "side":"BUY", "hash":"de131994da47a1e77e26c235a150e4964accdbd6", "best_bid":"0.82", "best_ask":"0.83"}], "timestamp":"1784449597155", "event_type":"price_change"}
{"market":"0x982eae4503214e5d7992668e93f48f42e4707b92e23bb45f8d52d321f643cbe3", "price_changes":[{"asset_id":"74913635031537477155015393896000154190746945075332596665612975928350948042868", "price":"0.76", "size":"160.24", "side":"BUY", "hash":"68022d9f7ca8ee6266c881c7ed0ed1ada8145f95", "best_bid":"0.82", "best_ask":"0.83"}, {"asset_id":"37613674580450069178400687025689415665506452565086963049482350052080099056186", "price":"0.24", "size":"160.24", "side":"SELL", "hash":"cb9ae59b9a2fd5eb3a607b09bdd3c2048eea6d51", "best_bid":"0.17", "best_ask":"0.18"}], "timestamp":"1784449597156", "event_type":"price_change"}
{"market":"0x982eae4503214e5d7992668e93f48f42e4707b92e23bb45f8d52d321f643cbe3", "price_changes":[{"asset_id":"74913635031537477155015393896000154190746945075332596665612975928350948042868", "price":"0.79", "size":"108.19", "side":"BUY", "hash":"725fad897821ade96239b8bc701525a636cd36cd", "best_bid":"0.82", "best_ask":"0.83"}, {"asset_id":"37613674580450069178400687025689415665506452565086963049482350052080099056186", "price":"0.21", "size":"108.19", "side":"SELL", "hash":"a1c95b29bb31066d1dd08730841033669f98c8a0", "best_bid":"0.17", "best_ask":"0.18"}], "timestamp":"1784449597157", "event_type":"price_change"}
{"market":"0x982eae4503214e5d7992668e93f48f42e4707b92e23bb45f8d52d321f643cbe3", "price_changes":[{"asset_id":"37613674580450069178400687025689415665506452565086963049482350052080099056186", "price":"0.01", "size":"17919.98", "side":"BUY", "hash":"5ed20fa815a34f022e100ce5b3ff2e6134135831", "best_bid":"0.17", "best_ask":"0.18"}, {"asset_id":"74913635031537477155015393896000154190746945075332596665612975928350948042868", "price":"0.99", "size":"17919.98", "side":"SELL", "hash":"156602f8648c1add73dc9d213a6c256ba7c3c797", "best_bid":"0.82", "best_ask":"0.83"}], "timestamp":"1784449597160", "event_type":"price_change"}
{"market":"0x982eae4503214e5d7992668e93f48f42e4707b92e23bb45f8d52d321f643cbe3", "price_changes":[{"asset_id":"37613674580450069178400687025689415665506452565086963049482350052080099056186", "price":"0.15", "size":"175.71", "side":"BUY", "hash":"0a2d99484bd1fac554a72450c35b242fa773efef", "best_bid":"0.17", "best_ask":"0.18"}, {"asset_id":"74913635031537477155015393896000154190746945075332596665612975928350948042868", "price":"0.85", "size":"175.71", "side":"SELL", "hash":"6937e10c511275bd7b5c02b241786d2fa4de5b27", "best_bid":"0.82", "best_ask":"0.83"}], "timestamp":"1784449597161", "event_type":"price_change"}
{"market":"0x982eae4503214e5d7992668e93f48f42e4707b92e23bb45f8d52d321f643cbe3", "price_changes":[{"asset_id":"37613674580450069178400687025689415665506452565086963049482350052080099056186", "price":"0.14", "size":"209.14", "side":"BUY", "hash":"2095318b3cbb613396cc0995f67b633498ffa817", "best_bid":"0.17", "best_ask":"0.18"}, {"asset_id":"74913635031537477155015393896000154190746945075332596665612975928350948042868", "price":"0.86", "size":"209.14", "side":"SELL", "hash":"52d2e940b2f0c34f7244087ccc0a668003988c0c", "best_bid":"0.82", "best_ask":"0.83"}], "timestamp":"1784449597165", "event_type":"price_change"}
{"market":"0x982eae4503214e5d7992668e93f48f42e4707b92e23bb45f8d52d321f643cbe3", "price_changes":[{"asset_id":"74913635031537477155015393896000154190746945075332596665612975928350948042868", "price":"0.82", "size":"143.07", "side":"BUY", "hash":"227f715f485e4070316c312c630117bd58970041", "best_bid":"0.82", "best_ask":"0.83"}, {"asset_id":"37613674580450069178400687025689415665506452565086963049482350052080099056186", "price":"0.18", "size":"143.07", "side":"SELL", "hash":"0a87caa6f00b86b5f326f22944f9a1a83c807e86", "best_bid":"0.17", "best_ask":"0.18"}], "timestamp":"1784449597168", "event_type":"price_change"}
{"market":"0x982eae4503214e5d7992668e93f48f42e4707b92e23bb45f8d52d321f643cbe3", "price_changes":[{"asset_id":"37613674580450069178400687025689415665506452565086963049482350052080099056186", "price":"0.11", "size":"503.73", "side":"BUY", "hash":"abf588db20853123dce05da35f73d4c9a0a5beb4", "best_bid":"0.17", "best_ask":"0.18"}, {"asset_id":"74913635031537477155015393896000154190746945075332596665612975928350948042868", "price":"0.89", "size":"503.73", "side":"SELL", "hash":"accae76c021cf0cee853614ce4fb3d36cde0f362", "best_bid":"0.82", "best_ask":"0.83"}], "timestamp":"1784449597169", "event_type":"price_change"}
{"market":"0x982eae4503214e5d7992668e93f48f42e4707b92e23bb45f8d52d321f643cbe3", "price_changes":[{"asset_id":"74913635031537477155015393896000154190746945075332596665612975928350948042868", "price":"0.81", "size":"285.31", "side":"BUY", "hash":"41eae2b5a5b75e13548f7c72da6a36e737c82059", "best_bid":"0.82", "best_ask":"0.83"}, {"asset_id":"37613674580450069178400687025689415665506452565086963049482350052080099056186", "price":"0.19", "size":"285.31", "side":"SELL", "hash":"a1b40c49e7e96717e99a6a7e001227d9fa45ef72", "best_bid":"0.17", "best_ask":"0.18"}], "timestamp":"1784449597177", "event_type":"price_change"}
{"market":"0x982eae4503214e5d7992668e93f48f42e4707b92e23bb45f8d52d321f643cbe3", "price_changes":[{"asset_id":"37613674580450069178400687025689415665506452565086963049482350052080099056186", "price":"0.16", "size":"104.17", "side":"BUY", "hash":"7f199a352568f222d10b8fba1114ea3463b69c70", "best_bid":"0.17", "best_ask":"0.18"}, {"asset_id":"74913635031537477155015393896000154190746945075332596665612975928350948042868", "price":"0.84", "size":"104.17", "side":"SELL", "hash":"77459a1e70c8350d519723902b436bae91917d00", "best_bid":"0.82", "best_ask":"0.83"}], "timestamp":"1784449597181", "event_type":"price_change"}
{"market":"0x982eae4503214e5d7992668e93f48f42e4707b92e23bb45f8d52d321f643cbe3", "price_changes":[{"asset_id":"74913635031537477155015393896000154190746945075332596665612975928350948042868", "price":"0.01", "size":"16184.13", "side":"BUY", "hash":"d3eee61ab464ccfa67b06947512401bb7185558a", "best_bid":"0.82", "best_ask":"0.83"}, {"asset_id":"37613674580450069178400687025689415665506452565086963049482350052080099056186", "price":"0.99", "size":"16184.13", "side":"SELL", "hash":"51efb8a37b0c7fac6c425f452868dc05e9204690", "best_bid":"0.17", "best_ask":"0.18"}], "timestamp":"1784449597185", "event_type":"price_change"}
{"market":"0x982eae4503214e5d7992668e93f48f42e4707b92e23bb45f8d52d321f643cbe3", "price_changes":[{"asset_id":"74913635031537477155015393896000154190746945075332596665612975928350948042868", "price":"0.02", "size":"3289.11", "side":"BUY", "hash":"4e18d5f544b17648d9895394f08abac6487a321b", "best_bid":"0.82", "best_ask":"0.83"}, {"asset_id":"37613674580450069178400687025689415665506452565086963049482350052080099056186", "price":"0.98", "size":"3289.11", "side":"SELL", "hash":"6847fca2ff65c02d48ad6b98610b60bcbe31453f", "best_bid":"0.17", "best_ask":"0.18"}], "timestamp":"1784449597191", "event_type":"price_change"}
{"market":"0x982eae4503214e5d7992668e93f48f42e4707b92e23bb45f8d52d321f643cbe3", "price_changes":[{"asset_id":"74913635031537477155015393896000154190746945075332596665612975928350948042868", "price":"0.82", "size":"118.07", "side":"BUY", "hash":"55ecbbfcbf6cea2533dc3925c66e1016b0e67984", "best_bid":"0.82", "best_ask":"0.83"}, {"asset_id":"37613674580450069178400687025689415665506452565086963049482350052080099056186", "price":"0.18", "size":"118.07", "side":"SELL", "hash":"0ee5ce583765a44206a6caf9839683e72c72d930", "best_bid":"0.17", "best_ask":"0.18"}], "timestamp":"1784449597198", "event_type":"price_change"}
{"market":"0x982eae4503214e5d7992668e93f48f42e4707b92e23bb45f8d52d321f643cbe3", "price_changes":[{"asset_id":"74913635031537477155015393896000154190746945075332596665612975928350948042868", "price":"0.01", "size":"16189.13", "side":"BUY", "hash":"8f1b04534d705e5c91615d36defd02ca8567ddfd", "best_bid":"0.82", "best_ask":"0.83"}, {"asset_id":"37613674580450069178400687025689415665506452565086963049482350052080099056186", "price":"0.99", "size":"16189.13", "side":"SELL", "hash":"fa0b311fc7f3a618456e08dd396b15412dc62339", "best_bid":"0.17", "best_ask":"0.18"}], "timestamp":"1784449597205", "event_type":"price_change"}
{"market":"0x982eae4503214e5d7992668e93f48f42e4707b92e23bb45f8d52d321f643cbe3", "price_changes":[{"asset_id":"74913635031537477155015393896000154190746945075332596665612975928350948042868", "price":"0.01", "size":"16194.13", "side":"BUY", "hash":"f0982e32518331db64a81f7fb0090c1429be759e", "best_bid":"0.82", "best_ask":"0.83"}, {"asset_id":"37613674580450069178400687025689415665506452565086963049482350052080099056186", "price":"0.99", "size":"16194.13", "side":"SELL", "hash":"085c080eb47d8850789c24a83acee72df6ff1542", "best_bid":"0.17", "best_ask":"0.18"}], "timestamp":"1784449597205", "event_type":"price_change"}
{"market":"0x982eae4503214e5d7992668e93f48f42e4707b92e23bb45f8d52d321f643cbe3", "price_changes":[{"asset_id":"74913635031537477155015393896000154190746945075332596665612975928350948042868", "price":"0.01", "size":"16199.13", "side":"BUY", "hash":"bc87b2a389824531d45154ef30018dd7c7101e88", "best_bid":"0.82", "best_ask":"0.83"}, {"asset_id":"37613674580450069178400687025689415665506452565086963049482350052080099056186", "price":"0.99", "size":"16199.13", "side":"SELL", "hash":"1a8d656e2816999a55847e467c5c8c1d0e5d28d2", "best_bid":"0.17", "best_ask":"0.18"}], "timestamp":"1784449597206", "event_type":"price_change"}
{"market":"0x982eae4503214e5d7992668e93f48f42e4707b92e23bb45f8d52d321f643cbe3", "price_changes":[{"asset_id":"74913635031537477155015393896000154190746945075332596665612975928350948042868", "price":"0.01", "size":"16699.13", "side":"BUY", "hash":"86654fcf5520943aa7294a72e8cc3be9e362f778", "best_bid":"0.82", "best_ask":"0.83"}, {"asset_id":"37613674580450069178400687025689415665506452565086963049482350052080099056186", "price":"0.99", "size":"16699.13", "side":"SELL", "hash":"75fe2a4487054a80f2f8cf649a983e90cacb9dab", "best_bid":"0.17", "best_ask":"0.18"}], "timestamp":"1784449597209", "event_type":"price_change"}
{"market":"0x982eae4503214e5d7992668e93f48f42e4707b92e23bb45f8d52d321f643cbe3", "price_changes":[{"asset_id":"37613674580450069178400687025689415665506452565086963049482350052080099056186", "price":"0.14", "size":"169.14", "side":"BUY", "hash":"9cb28506d4391e927d49e3ecd9b354d9d0ea1a25", "best_bid":"0.17", "best_ask":"0.18"}, {"asset_id":"74913635031537477155015393896000154190746945075332596665612975928350948042868", "price":"0.86", "size":"169.14", "side":"SELL", "hash":"28036a90226b6347801e8e11e4f9cdd763d481bb", "best_bid":"0.82", "best_ask":"0.83"}], "timestamp":"1784449597210", "event_type":"price_change"}
{"market":"0x982eae4503214e5d7992668e93f48f42e4707b92e23bb45f8d52d321f643cbe3", "price_changes":[{"asset_id":"74913635031537477155015393896000154190746945075332596665612975928350948042868", "price":"0.69", "size":"129.1", "side":"BUY", "hash":"980458ff052c7af837c359e4dda3755c278022ee", "best_bid":"0.82", "best_ask":"0.83"}, {"asset_id":"37613674580450069178400687025689415665506452565086963049482350052080099056186", "price":"0.31", "size":"129.1", "side":"SELL", "hash":"a28c6d389e78941c6a2333a4426e4ac41a7f39c8", "best_bid":"0.17", "best_ask":"0.18"}], "timestamp":"1784449597211", "event_type":"price_change"}
{"market":"0x982eae4503214e5d7992668e93f48f42e4707b92e23bb45f8d52d321f643cbe3", "price_changes":[{"asset_id":"74913635031537477155015393896000154190746945075332596665612975928350948042868", "price":"0.01", "size":"16694.13", "side":"BUY", "hash":"3c3c5c66de81710af659cd057defff9746800762", "best_bid":"0.82", "best_ask":"0.83"}, {"asset_id":"37613674580450069178400687025689415665506452565086963049482350052080099056186", "price":"0.99", "size":"16694.13", "side":"SELL", "hash":"abbec18b3f2632686af402ce5f116a72aa68b2ce", "best_bid":"0.17", "best_ask":"0.18"}], "timestamp":"1784449597213", "event_type":"price_change"}
{"market":"0x982eae4503214e5d7992668e93f48f42e4707b92e23bb45f8d52d321f643cbe3", "price_changes":[{"asset_id":"74913635031537477155015393896000154190746945075332596665612975928350948042868", "price":"0.01", "size":"16689.13", "side":"BUY", "hash":"f7b70ef4059cdff168031d7b69f59576da6bbdc6", "best_bid":"0.82", "best_ask":"0.83"}, {"asset_id":"37613674580450069178400687025689415665506452565086963049482350052080099056186", "price":"0.99", "size":"16689.13", "side":"SELL", "hash":"fe30f8e0696c5e7f08c23aa06fb021357991e5ce", "best_bid":"0.17", "best_ask":"0.18"}], "timestamp":"1784449597216", "event_type":"price_change"}
{"market":"0x982eae4503214e5d7992668e93f48f42e4707b92e23bb45f8d52d321f643cbe3", "price_changes":[{"asset_id":"74913635031537477155015393896000154190746945075332596665612975928350948042868", "price":"0.82", "size":"138.07", "side":"BUY", "hash":"6be0bbe99f4763fc10f6754bb94408a18f111383", "best_bid":"0.82", "best_ask":"0.83"}, {"asset_id":"37613674580450069178400687025689415665506452565086963049482350052080099056186", "price":"0.18", "size":"138.07", "side":"SELL", "hash":"0e96bc1f377d3e81c156869c8b28c0dec2e009ff", "best_bid":"0.17", "best_ask":"0.18"}], "timestamp":"1784449597216", "event_type":"price_change"}
{"market":"0x982eae4503214e5d7992668e93f48f42e4707b92e23bb45f8d52d321f643cbe3", "price_changes":[{"asset_id":"74913635031537477155015393896000154190746945075332596665612975928350948042868", "price":"0.79", "size":"88.19", "side":"BUY", "hash":"ecafe1b633a214a0ecda97ddf5b89193c9915ce3", "best_bid":"0.82", "best_ask":"0.83"}, {"asset_id":"37613674580450069178400687025689415665506452565086963049482350052080099056186", "price":"0.21", "size":"88.19", "side":"SELL", "hash":"c7aff87ecd8e41c7882fb6d1210579f87c3539b5", "best_bid":"0.17", "best_ask":"0.18"}], "timestamp":"1784449597217", "event_type":"price_change"}
{"market":"0x982eae4503214e5d7992668e93f48f42e4707b92e23bb45f8d52d321f643cbe3", "price_changes":[{"asset_id":"37613674580450069178400687025689415665506452565086963049482350052080099056186", "price":"0.15", "size":"155.71", "side":"BUY", "hash":"327ff7d449d635a7782ce649308e23f9b6552fa4", "best_bid":"0.17", "best_ask":"0.18"}, {"asset_id":"74913635031537477155015393896000154190746945075332596665612975928350948042868", "price":"0.85", "size":"155.71", "side":"SELL", "hash":"9afec15a769af5ced5038d7646ca041ad860924d", "best_bid":"0.82", "best_ask":"0.83"}], "timestamp":"1784449597220", "event_type":"price_change"}
{"market":"0x982eae4503214e5d7992668e93f48f42e4707b92e23bb45f8d52d321f643cbe3", "price_changes":[{"asset_id":"37613674580450069178400687025689415665506452565086963049482350052080099056186", "price":"0.01", "size":"17924.98", "side":"BUY", "hash":"3f0f3eedc81e96a65f7d62190a974b87613ba620", "best_bid":"0.17", "best_ask":"0.18"}, {"asset_id":"74913635031537477155015393896000154190746945075332596665612975928350948042868", "price":"0.99", "size":"17924.98", "side":"SELL", "hash":"4d80f71fba4f323c394380398ab241169334827d", "best_bid":"0.82", "best_ask":"0.83"}], "timestamp":"1784449597220", "event_type":"price_change"}
PONG
{"market":"0x982eae4503214e5d7992668e93f48f42e4707b92e23bb45f8d52d321f643cbe3", "price_changes":[{"asset_id":"37613674580450069178400687025689415665506452565086963049482350052080099056186", "price":"0.01", "size":"17929.98", "side":"BUY", "hash":"91857f39202e757065ab84487278a1bca703f881", "best_bid":"0.17", "best_ask":"0.18"}, {"asset_id":"74913635031537477155015393896000154190746945075332596665612975928350948042868", "price":"0.99", "size":"17929.98", "side":"SELL", "hash":"37b5bef3364d65adc70dbf370b97d52145ecb264", "best_bid":"0.82", "best_ask":"0.83"}], "timestamp":"1784449597223", "event_type":"price_change"}
{"market":"0x982eae4503214e5d7992668e93f48f42e4707b92e23bb45f8d52d321f643cbe3", "price_changes":[{"asset_id":"74913635031537477155015393896000154190746945075332596665612975928350948042868", "price":"0.01", "size":"16684.13", "side":"BUY", "hash":"bdaf45a613ccec5b6e7befdc179b19ae7992a827", "best_bid":"0.82", "best_ask":"0.83"}, {"asset_id":"37613674580450069178400687025689415665506452565086963049482350052080099056186", "price":"0.99", "size":"16684.13", "side":"SELL", "hash":"acd2e978b760fc90bba7b41875ab85383bcad91a", "best_bid":"0.17", "best_ask":"0.18"}], "timestamp":"1784449597227", "event_type":"price_change"}
{"market":"0x982eae4503214e5d7992668e93f48f42e4707b92e23bb45f8d52d321f643cbe3", "price_changes":[{"asset_id":"74913635031537477155015393896000154190746945075332596665612975928350948042868", "price":"0.01", "size":"16689.13", "side":"BUY", "hash":"ca735face5abf01f34566787a4cd62f14321fe54", "best_bid":"0.82", "best_ask":"0.83"}, {"asset_id":"37613674580450069178400687025689415665506452565086963049482350052080099056186", "price":"0.99", "size":"16689.13", "side":"SELL", "hash":"754605c30cce241ae048e50fbbb73500b8c150f2", "best_bid":"0.17", "best_ask":"0.18"}], "timestamp":"1784449597228", "event_type":"price_change"}
{"market":"0x982eae4503214e5d7992668e93f48f42e4707b92e23bb45f8d52d321f643cbe3", "price_changes":[{"asset_id":"37613674580450069178400687025689415665506452565086963049482350052080099056186", "price":"0.01", "size":"17934.98", "side":"BUY", "hash":"06253832db58a0340fdc9038f23597404113ae28", "best_bid":"0.17", "best_ask":"0.18"}, {"asset_id":"74913635031537477155015393896000154190746945075332596665612975928350948042868", "price":"0.99", "size":"17934.98", "side":"SELL", "hash":"994355dcdf5c2ec370119722dca1d1bf98048cc6", "best_bid":"0.82", "best_ask":"0.83"}], "timestamp":"1784449597229", "event_type":"price_change"}
{"market":"0x982eae4503214e5d7992668e93f48f42e4707b92e23bb45f8d52d321f643cbe3", "price_changes":[{"asset_id":"74913635031537477155015393896000154190746945075332596665612975928350948042868", "price":"0.01", "size":"16189.13", "side":"BUY", "hash":"c688e50ba498bece580b4d092a0783d41efb480f", "best_bid":"0.82", "best_ask":"0.83"}, {"asset_id":"37613674580450069178400687025689415665506452565086963049482350052080099056186", "price":"0.99", "size":"16189.13", "side":"SELL", "hash":"ab9104ce8fea521624a1d9b0a87529ee67c7b44e", "best_bid":"0.17", "best_ask":"0.18"}], "timestamp":"1784449597229", "event_type":"price_change"}
{"market":"0x982eae4503214e5d7992668e93f48f42e4707b92e23bb45f8d52d321f643cbe3", "price_changes":[{"asset_id":"74913635031537477155015393896000154190746945075332596665612975928350948042868", "price":"0.01", "size":"16289.13", "side":"BUY", "hash":"d0dae56d6e76381b305508517ffc5f9f7d48be04", "best_bid":"0.82", "best_ask":"0.83"}, {"asset_id":"37613674580450069178400687025689415665506452565086963049482350052080099056186", "price":"0.99", "size":"16289.13", "side":"SELL", "hash":"1f1646985b4a5ea8a606b2178b34c222aff8c11a", "best_bid":"0.17", "best_ask":"0.18"}], "timestamp":"1784449597231", "event_type":"price_change"}
{"market":"0x982eae4503214e5d7992668e93f48f42e4707b92e23bb45f8d52d321f643cbe3", "price_changes":[{"asset_id":"74913635031537477155015393896000154190746945075332596665612975928350948042868", "price":"0.69", "size":"104.1", "side":"BUY", "hash":"b50cad2a8177e2b9f387ffdbdf77c382ae5df95e", "best_bid":"0.82", "best_ask":"0.83"}, {"asset_id":"37613674580450069178400687025689415665506452565086963049482350052080099056186", "price":"0.31", "size":"104.1", "side":"SELL", "hash":"7407ffb107fd810a03f3f04d3aeaef6f0ea3026b", "best_bid":"0.17", "best_ask":"0.18"}], "timestamp":"1784449597232", "event_type":"price_change"}
{"market":"0x982eae4503214e5d7992668e93f48f42e4707b92e23bb45f8d52d321f643cbe3", "price_changes":[{"asset_id":"74913635031537477155015393896000154190746945075332596665612975928350948042868", "price":"0.01", "size":"16284.13", "side":"BUY", "hash":"fe1cce6ac6f1b7d10e5cd7afa90afacedb5d5dca", "best_bid":"0.82", "best_ask":"0.83"}, {"asset_id":"37613674580450069178400687025689415665506452565086963049482350052080099056186", "price":"0.99", "size":"16284.13", "side":"SELL", "hash":"8e49c3dc64bc9e0a107caafd0365da2ed5e60f76", "best_bid":"0.17", "best_ask":"0.18"}], "timestamp":"1784449597233", "event_type":"price_change"}
{"market":"0x982eae4503214e5d7992668e93f48f42e4707b92e23bb45f8d52d321f643cbe3", "price_changes":[{"asset_id":"74913635031537477155015393896000154190746945075332596665612975928350948042868", "price":"0.7", "size":"113.04", "side":"BUY", "hash":"3e7df35f86a727550f3d437edadf886e266609d5", "best_bid":"0.82", "best_ask":"0.83"}, {"asset_id":"37613674580450069178400687025689415665506452565086963049482350052080099056186", "price":"0.3", "size":"113.04", "side":"SELL", "hash":"ef995c8db26ce2c9db96eec5177292de506e6702", "best_bid":"0.17", "best_ask":"0.18"}], "timestamp":"1784449597236", "event_type":"price_change"}
{"market":"0x982eae4503214e5d7992668e93f48f42e4707b92e23bb45f8d52d321f643cbe3", "price_changes":[{"asset_id":"74913635031537477155015393896000154190746945075332596665612975928350948042868", "price":"0.01", "size":"16279.13", "side":"BUY", "hash":"42518b919c67710dce0fb1f185791f4b59c8ec0d", "best_bid":"0.82", "best_ask":"0.83"}, {"asset_id":"37613674580450069178400687025689415665506452565086963049482350052080099056186", "price":"0.99", "size":"16279.13", "side":"SELL", "hash":"9640cb21c8baf33e3d1c2a7e94b456e5c9af504a", "best_bid":"0.17", "best_ask":"0.18"}], "timestamp":"1784449597248", "event_type":"price_change"}
{"market":"0x982eae4503214e5d7992668e93f48f42e4707b92e23bb45f8d52d321f643cbe3", "price_changes":[{"asset_id":"74913635031537477155015393896000154190746945075332596665612975928350948042868", "price":"0.01", "size":"16274.13", "side":"BUY", "hash":"e5bf8bade02c505b54110c00391621796decbfab", "best_bid":"0.82", "best_ask":"0.83"}, {"asset_id":"37613674580450069178400687025689415665506452565086963049482350052080099056186", "price":"0.99", "size":"16274.13", "side":"SELL", "hash":"4a84f473ede8c66f3c7ae43ef461b932eada5a5c", "best_bid":"0.17", "best_ask":"0.18"}], "timestamp":"1784449597260", "event_type":"price_change"}
{"market":"0x982eae4503214e5d7992668e93f48f42e4707b92e23bb45f8d52d321f643cbe3", "price_changes":[{"asset_id":"74913635031537477155015393896000154190746945075332596665612975928350948042868", "price":"0.01", "size":"16279.14", "side":"BUY", "hash":"ba0532cbc2e7953ee09e560fbef5ecfb7c262217", "best_bid":"0.82", "best_ask":"0.83"}, {"asset_id":"37613674580450069178400687025689415665506452565086963049482350052080099056186", "price":"0.99", "size":"16279.14", "side":"SELL", "hash":"8af42545270ac2571f3c5a18ecd59ba512a8b5a1", "best_bid":"0.17", "best_ask":"0.18"}], "timestamp":"1784449597261", "event_type":"price_change"}
{"market":"0x982eae4503214e5d7992668e93f48f42e4707b92e23bb45f8d52d321f643cbe3", "price_changes":[{"asset_id":"74913635031537477155015393896000154190746945075332596665612975928350948042868", "price":"0.01", "size":"16179.14", "side":"BUY", "hash":"cd34f39450e6ae577d8c7e601a56c83d33e771a3", "best_bid":"0.82", "best_ask":"0.83"}, {"asset_id":"37613674580450069178400687025689415665506452565086963049482350052080099056186", "price":"0.99", "size":"16179.14", "side":"SELL", "hash":"fcdd5f1a2a417f73b5894dbc87581bbe9f017030", "best_bid":"0.17", "best_ask":"0.18"}], "timestamp":"1784449597266", "event_type":"price_change"}
{"market":"0x982eae4503214e5d7992668e93f48f42e4707b92e23bb45f8d52d321f643cbe3", "price_changes":[{"asset_id":"74913635031537477155015393896000154190746945075332596665612975928350948042868", "price":"0.8", "size":"58.58", "side":"BUY", "hash":"ce55971509f65f809c39342309ced2eac35e91cb", "best_bid":"0.8", "best_ask":"0.83"}, {"asset_id":"37613674580450069178400687025689415665506452565086963049482350052080099056186", "price":"0.2", "size":"58.58", "side":"SELL", "hash":"e7b0affdb4f4faeb39ff2f3c53c60502d03206ac", "best_bid":"0.17", "best_ask":"0.2"}], "timestamp":"1784449597275", "event_type":"price_change"}
{"market":"0x982eae4503214e5d7992668e93f48f42e4707b92e23bb45f8d52d321f643cbe3", "price_changes":[{"asset_id":"74913635031537477155015393896000154190746945075332596665612975928350948042868", "price":"0.82", "size":"0", "side":"BUY", "hash":"ce55971509f65f809c39342309ced2eac35e91cb", "best_bid":"0.8", "best_ask":"0.83"}, {"asset_id":"37613674580450069178400687025689415665506452565086963049482350052080099056186", "price":"0.18", "size":"0", "side":"SELL", "hash":"e7b0affdb4f4faeb39ff2f3c53c60502d03206ac", "best_bid":"0.17", "best_ask":"0.2"}], "timestamp":"1784449597275", "event_type":"price_change"}
{"market":"0x982eae4503214e5d7992668e93f48f42e4707b92e23bb45f8d52d321f643cbe3", "price_changes":[{"asset_id":"37613674580450069178400687025689415665506452565086963049482350052080099056186", "price":"0.18", "size":"0", "side":"SELL", "hash":"e7b0affdb4f4faeb39ff2f3c53c60502d03206ac", "best_bid":"0.17", "best_ask":"0.2"}, {"asset_id":"74913635031537477155015393896000154190746945075332596665612975928350948042868", "price":"0.82", "size":"0", "side":"BUY", "hash":"ce55971509f65f809c39342309ced2eac35e91cb", "best_bid":"0.8", "best_ask":"0.83"}], "timestamp":"1784449597275", "event_type":"price_change"}
{"market":"0x982eae4503214e5d7992668e93f48f42e4707b92e23bb45f8d52d321f643cbe3", "price_changes":[{"asset_id":"74913635031537477155015393896000154190746945075332596665612975928350948042868", "price":"0.81", "size":"0", "side":"BUY", "hash":"ce55971509f65f809c39342309ced2eac35e91cb", "best_bid":"0.8", "best_ask":"0.83"}, {"asset_id":"37613674580450069178400687025689415665506452565086963049482350052080099056186", "price":"0.19", "size":"0", "side":"SELL", "hash":"e7b0affdb4f4faeb39ff2f3c53c60502d03206ac", "best_bid":"0.17", "best_ask":"0.2"}], "timestamp":"1784449597275", "event_type":"price_change"}
{"market":"0x982eae4503214e5d7992668e93f48f42e4707b92e23bb45f8d52d321f643cbe3", "price_changes":[{"asset_id":"37613674580450069178400687025689415665506452565086963049482350052080099056186", "price":"0.19", "size":"0", "side":"SELL", "hash":"e7b0affdb4f4faeb39ff2f3c53c60502d03206ac", "best_bid":"0.17", "best_ask":"0.2"}, {"asset_id":"74913635031537477155015393896000154190746945075332596665612975928350948042868", "price":"0.81", "size":"0", "side":"BUY", "hash":"ce55971509f65f809c39342309ced2eac35e91cb", "best_bid":"0.8", "best_ask":"0.83"}], "timestamp":"1784449597275", "event_type":"price_change"}
